{"ts_recv":"2024-11-01T08:00:09.024470734Z","hd":{"ts_event":"2024-11-01T08:00:09.024304348Z","rtype":10,"publisher_id":2,"instrument_id":11667},"action":"A","side":"A","depth":3,"price":"135.400000000","size":10,"flags":130,"ts_in_delta":166386,"sequence":307725,"levels":[{"bid_px":"134.500000000","ask_px":"135.000000000","bid_sz":500,"ask_sz":38,"bid_ct":1,"ask_ct":3},{"bid_px":"134.440000000","ask_px":"135.230000000","bid_sz":100,"ask_sz":360,"bid_ct":1,"ask_ct":1},{"bid_px":"134.410000000","ask_px":"135.300000000","bid_sz":61,"ask_sz":1000,"bid_ct":2,"ask_ct":1},{"bid_px":"134.380000000","ask_px":"135.400000000","bid_sz":18,"ask_sz":10,"bid_ct":1,"ask_ct":1},{"bid_px":"134.210000000","ask_px":"135.420000000","bid_sz":20,"ask_sz":1,"bid_ct":1,"ask_ct":1},{"bid_px":"134.200000000","ask_px":"135.820000000","bid_sz":3,"ask_sz":1,"bid_ct":1,"ask_ct":1},{"bid_px":"133.160000000","ask_px":"135.990000000","bid_sz":1,"ask_sz":20,"bid_ct":1,"ask_ct":1},{"bid_px":"132.700000000","ask_px":"136.100000000","bid_sz":4,"ask_sz":1000,"bid_ct":1,"ask_ct":1},{"bid_px":"132.660000000","ask_px":"136.220000000","bid_sz":1,"ask_sz":1,"bid_ct":1,"ask_ct":1},{"bid_px":"132.160000000","ask_px":"136.400000000","bid_sz":1,"ask_sz":11,"bid_ct":1,"ask_ct":1}],"symbol":"NVDA"}
{"ts_recv":"2024-11-01T08:00:09.024590866Z","hd":{"ts_event":"2024-11-01T08:00:09.024424307Z","rtype":10,"publisher_id":2,"instrument_id":11667},"action":"A","side":"A","depth":0,"price":"134.990000000","size":10,"flags":130,"ts_in_delta":166559,"sequence":307726,"levels":[{"bid_px":"134.500000000","ask_px":"134.990000000","bid_sz":500,"ask_sz":10,"bid_ct":1,"ask_ct":1},{"bid_px":"134.440000000","ask_px":"135.000000000","bid_sz":100,"ask_sz":38,"bid_ct":1,"ask_ct":3},{"bid_px":"134.410000000","ask_px":"135.230000000","bid_sz":61,"ask_sz":360,"bid_ct":2,"ask_ct":1},{"bid_px":"134.380000000","ask_px":"135.300000000","bid_sz":18,"ask_sz":1000,"bid_ct":1,"ask_ct":1},{"bid_px":"134.210000000","ask_px":"135.400000000","bid_sz":20,"ask_sz":10,"bid_ct":1,"ask_ct":1},{"bid_px":"134.200000000","ask_px":"135.420000000","bid_sz":3,"ask_sz":1,"bid_ct":1,"ask_ct":1},{"bid_px":"133.160000000","ask_px":"135.820000000","bid_sz":1,"ask_sz":1,"bid_ct":1,"ask_ct":1},{"bid_px":"132.700000000","ask_px":"135.990000000","bid_sz":4,"ask_sz":20,"bid_ct":1,"ask_ct":1},{"bid_px":"132.660000000","ask_px":"136.100000000","bid_sz":1,"ask_sz":1000,"bid_ct":1,"ask_ct":1},{"bid_px":"132.160000000","ask_px":"136.220000000","bid_sz":1,"ask_sz":1,"bid_ct":1,"ask_ct":1}],"symbol":"NVDA"}
{"ts_recv":"2024-11-01T08:00:09.024710098Z","hd":{"ts_event":"2024-11-01T08:00:09.024543805Z","rtype":10,"publisher_id":2,"instrument_id":11667},"action":"A","side":"A","depth":2,"price":"135.100000000","size":10,"flags":130,"ts_in_delta":166293,"sequence":307727,"levels":[{"bid_px":"134.500000000","ask_px":"134.990000000","bid_sz":500,"ask_sz":10,"bid_ct":1,"ask_ct":1},{"bid_px":"134.440000000","ask_px":"135.000000000","bid_sz":100,"ask_sz":38,"bid_ct":1,"ask_ct":3},{"bid_px":"134.410000000","ask_px":"135.100000000","bid_sz":61,"ask_sz":10,"bid_ct":2,"ask_ct":1},{"bid_px":"134.380000000","ask_px":"135.230000000","bid_sz":18,"ask_sz":360,"bid_ct":1,"ask_ct":1},{"bid_px":"134.210000000","ask_px":"135.300000000","bid_sz":20,"ask_sz":1000,"bid_ct":1,"ask_ct":1},{"bid_px":"134.200000000","ask_px":"135.400000000","bid_sz":3,"ask_sz":10,"bid_ct":1,"ask_ct":1},{"bid_px":"133.160000000","ask_px":"135.420000000","bid_sz":1,"ask_sz":1,"bid_ct":1,"ask_ct":1},{"bid_px":"132.700000000","ask_px":"135.820000000","bid_sz":4,"ask_sz":1,"bid_ct":1,"ask_ct":1},{"bid_px":"132.660000000","ask_px":"135.990000000","bid_sz":1,"ask_sz":20,"bid_ct":1,"ask_ct":1},{"bid_px":"132.160000000","ask_px":"136.100000000","bid_sz":1,"ask_sz":1000,"bid_ct":1,"ask_ct":1}],"symbol":"NVDA"}
{"ts_recv":"2024-11-01T08:00:09.070231821Z","hd":{"ts_event":"2024-11-01T08:00:09.070065678Z","rtype":10,"publisher_id":2,"instrument_id":16244},"action":"A","side":"B","depth":9,"price":"246.000000000","size":4,"flags":130,"ts_in_delta":166143,"sequence":307784,"levels":[{"bid_px":"250.030000000","ask_px":"250.720000000","bid_sz":50,"ask_sz":100,"bid_ct":1,"ask_ct":1},{"bid_px":"249.930000000","ask_px":"250.760000000","bid_sz":10,"ask_sz":50,"bid_ct":1,"ask_ct":1},{"bid_px":"249.800000000","ask_px":"252.400000000","bid_sz":199,"ask_sz":1000,"bid_ct":1,"ask_ct":1},{"bid_px":"249.770000000","ask_px":"253.650000000","bid_sz":50,"ask_sz":400,"bid_ct":1,"ask_ct":1},{"bid_px":"249.600000000","ask_px":"255.000000000","bid_sz":1000,"ask_sz":10,"bid_ct":1,"ask_ct":1},{"bid_px":"249.500000000","ask_px":"260.000000000","bid_sz":1000,"ask_sz":48,"bid_ct":1,"ask_ct":1},{"bid_px":"249.400000000","ask_px":"262.660000000","bid_sz":1000,"ask_sz":56,"bid_ct":1,"ask_ct":1},{"bid_px":"247.700000000","ask_px":"264.940000000","bid_sz":1000,"ask_sz":7,"bid_ct":1,"ask_ct":1},{"bid_px":"247.150000000","ask_px":"265.000000000","bid_sz":400,"ask_sz":1,"bid_ct":1,"ask_ct":1},{"bid_px":"246.000000000","ask_px":"267.800000000","bid_sz":4,"ask_sz":30,"bid_ct":1,"ask_ct":1}],"symbol":"TSLA"}
{"ts_recv":"2024-11-01T08:00:09.105225849Z","hd":{"ts_event":"2024-11-01T08:00:09.105059506Z","rtype":10,"publisher_id":2,"instrument_id":11667},"action":"A","side":"B","depth":0,"price":"134.670000000","size":100,"flags":130,"ts_in_delta":166343,"sequence":307835,"levels":[{"bid_px":"134.670000000","ask_px":"134.990000000","bid_sz":100,"ask_sz":10,"bid_ct":1,"ask_ct":1},{"bid_px":"134.500000000","ask_px":"135.000000000","bid_sz":500,"ask_sz":38,"bid_ct":1,"ask_ct":3},{"bid_px":"134.410000000","ask_px":"135.100000000","bid_sz":61,"ask_sz":10,"bid_ct":2,"ask_ct":1},{"bid_px":"134.380000000","ask_px":"135.230000000","bid_sz":18,"ask_sz":360,"bid_ct":1,"ask_ct":1},{"bid_px":"134.210000000","ask_px":"135.300000000","bid_sz":20,"ask_sz":1000,"bid_ct":1,"ask_ct":1},{"bid_px":"134.200000000","ask_px":"135.400000000","bid_sz":3,"ask_sz":10,"bid_ct":1,"ask_ct":1},{"bid_px":"133.160000000","ask_px":"135.420000000","bid_sz":1,"ask_sz":1,"bid_ct":1,"ask_ct":1},{"bid_px":"132.700000000","ask_px":"135.820000000","bid_sz":4,"ask_sz":1,"bid_ct":1,"ask_ct":1},{"bid_px":"132.660000000","ask_px":"135.990000000","bid_sz":1,"ask_sz":20,"bid_ct":1,"ask_ct":1},{"bid_px":"132.160000000","ask_px":"136.100000000","bid_sz":1,"ask_sz":1000,"bid_ct":1,"ask_ct":1}],"symbol":"NVDA"}
{"ts_recv":"2024-11-01T08:00:09.184621728Z","hd":{"ts_event":"2024-11-01T08:00:09.184455471Z","rtype":10,"publisher_id":2,"instrument_id":16244},"action":"A","side":"B","depth":9,"price":"247.000000000","size":12,"flags":130,"ts_in_delta":166257,"sequence":307945,"levels":[{"bid_px":"250.030000000","ask_px":"250.720000000","bid_sz":50,"ask_sz":100,"bid_ct":1,"ask_ct":1},{"bid_px":"249.930000000","ask_px":"250.760000000","bid_sz":10,"ask_sz":50,"bid_ct":1,"ask_ct":1},{"bid_px":"249.800000000","ask_px":"252.400000000","bid_sz":199,"ask_sz":1000,"bid_ct":1,"ask_ct":1},{"bid_px":"249.770000000","ask_px":"253.650000000","bid_sz":50,"ask_sz":400,"bid_ct":1,"ask_ct":1},{"bid_px":"249.600000000","ask_px":"255.000000000","bid_sz":1000,"ask_sz":10,"bid_ct":1,"ask_ct":1},{"bid_px":"249.500000000","ask_px":"260.000000000","bid_sz":1000,"ask_sz":48,"bid_ct":1,"ask_ct":1},{"bid_px":"249.400000000","ask_px":"262.660000000","bid_sz":1000,"ask_sz":56,"bid_ct":1,"ask_ct":1},{"bid_px":"247.700000000","ask_px":"264.940000000","bid_sz":1000,"ask_sz":7,"bid_ct":1,"ask_ct":1},{"bid_px":"247.150000000","ask_px":"265.000000000","bid_sz":400,"ask_sz":1,"bid_ct":1,"ask_ct":1},{"bid_px":"247.000000000","ask_px":"267.800000000","bid_sz":12,"ask_sz":30,"bid_ct":1,"ask_ct":1}],"symbol":"TSLA"}
{"ts_recv":"2024-11-01T08:00:09.237350461Z","hd":{"ts_event":"2024-11-01T08:00:09.237184087Z","rtype":10,"publisher_id":2,"instrument_id":16244},"action":"A","side":"B","depth":1,"price":"250.000000000","size":1,"flags":130,"ts_in_delta":166374,"sequence":308002,"levels":[{"bid_px":"250.030000000","ask_px":"250.720000000","bid_sz":50,"ask_sz":100,"bid_ct":1,"ask_ct":1},{"bid_px":"250.000000000","ask_px":"250.760000000","bid_sz":1,"ask_sz":50,"bid_ct":1,"ask_ct":1},{"bid_px":"249.930000000","ask_px":"252.400000000","bid_sz":10,"ask_sz":1000,"bid_ct":1,"ask_ct":1},{"bid_px":"249.800000000","ask_px":"253.650000000","bid_sz":199,"ask_sz":400,"bid_ct":1,"ask_ct":1},{"bid_px":"249.770000000","ask_px":"255.000000000","bid_sz":50,"ask_sz":10,"bid_ct":1,"ask_ct":1},{"bid_px":"249.600000000","ask_px":"260.000000000","bid_sz":1000,"ask_sz":48,"bid_ct":1,"ask_ct":1},{"bid_px":"249.500000000","ask_px":"262.660000000","bid_sz":1000,"ask_sz":56,"bid_ct":1,"ask_ct":1},{"bid_px":"249.400000000","ask_px":"264.940000000","bid_sz":1000,"ask_sz":7,"bid_ct":1,"ask_ct":1},{"bid_px":"247.700000000","ask_px":"265.000000000","bid_sz":1000,"ask_sz":1,"bid_ct":1,"ask_ct":1},{"bid_px":"247.150000000","ask_px":"267.800000000","bid_sz":400,"ask_sz":30,"bid_ct":1,"ask_ct":1}],"symbol":"TSLA"}
{"ts_recv":"2024-11-01T08:00:09.238148826Z","hd":{"ts_event":"2024-11-01T08:00:09.237982939Z","rtype":10,"publisher_id":2,"instrument_id":16244},"action":"C","side":"B","depth":7,"price":"249.400000000","size":1000,"flags":130,"ts_in_delta":165887,"sequence":308003,"levels":[{"bid_px":"250.030000000","ask_px":"250.720000000","bid_sz":50,"ask_sz":100,"bid_ct":1,"ask_ct":1},{"bid_px":"250.000000000","ask_px":"250.760000000","bid_sz":1,"ask_sz":50,"bid_ct":1,"ask_ct":1},{"bid_px":"249.930000000","ask_px":"252.400000000","bid_sz":10,"ask_sz":1000,"bid_ct":1,"ask_ct":1},{"bid_px":"249.800000000","ask_px":"253.650000000","bid_sz":199,"ask_sz":400,"bid_ct":1,"ask_ct":1},{"bid_px":"249.770000000","ask_px":"255.000000000","bid_sz":50,"ask_sz":10,"bid_ct":1,"ask_ct":1},{"bid_px":"249.600000000","ask_px":"260.000000000","bid_sz":1000,"ask_sz":48,"bid_ct":1,"ask_ct":1},{"bid_px":"249.500000000","ask_px":"262.660000000","bid_sz":1000,"ask_sz":56,"bid_ct":1,"ask_ct":1},{"bid_px":"247.700000000","ask_px":"264.940000000","bid_sz":1000,"ask_sz":7,"bid_ct":1,"ask_ct":1},{"bid_px":"247.150000000","ask_px":"265.000000000","bid_sz":400,"ask_sz":1,"bid_ct":1,"ask_ct":1},{"bid_px":"247.000000000","ask_px":"267.800000000","bid_sz":12,"ask_sz":30,"bid_ct":1,"ask_ct":1}],"symbol":"TSLA"}
{"ts_recv":"2024-11-01T08:00:09.248919398Z","hd":{"ts_event":"2024-11-01T08:00:09.248753431Z","rtype":10,"publisher_id":2,"instrument_id":16244},"action":"A","side":"B","depth":7,"price":"248.600000000","size":1000,"flags":130,"ts_in_delta":165967,"sequence":308020,"levels":[{"bid_px":"250.030000000","ask_px":"250.720000000","bid_sz":50,"ask_sz":100,"bid_ct":1,"ask_ct":1},{"bid_px":"250.000000000","ask_px":"250.760000000","bid_sz":1,"ask_sz":50,"bid_ct":1,"ask_ct":1},{"bid_px":"249.930000000","ask_px":"252.400000000","bid_sz":10,"ask_sz":1000,"bid_ct":1,"ask_ct":1},{"bid_px":"249.800000000","ask_px":"253.650000000","bid_sz":199,"ask_sz":400,"bid_ct":1,"ask_ct":1},{"bid_px":"249.770000000","ask_px":"255.000000000","bid_sz":50,"ask_sz":10,"bid_ct":1,"ask_ct":1},{"bid_px":"249.600000000","ask_px":"260.000000000","bid_sz":1000,"ask_sz":48,"bid_ct":1,"ask_ct":1},{"bid_px":"249.500000000","ask_px":"262.660000000","bid_sz":1000,"ask_sz":56,"bid_ct":1,"ask_ct":1},{"bid_px":"248.600000000","ask_px":"264.940000000","bid_sz":1000,"ask_sz":7,"bid_ct":1,"ask_ct":1},{"bid_px":"247.700000000","ask_px":"265.000000000","bid_sz":1000,"ask_sz":1,"bid_ct":1,"ask_ct":1},{"bid_px":"247.150000000","ask_px":"267.800000000","bid_sz":400,"ask_sz":30,"bid_ct":1,"ask_ct":1}],"symbol":"TSLA"}
{"ts_recv":"2024-11-01T08:00:09.248957175Z","hd":{"ts_event":"2024-11-01T08:00:09.248791239Z","rtype":10,"publisher_id":2,"instrument_id":16244},"action":"C","side":"B","depth":8,"price":"247.700000000","size":1000,"flags":130,"ts_in_delta":165936,"sequence":308021,"levels":[{"bid_px":"250.030000000","ask_px":"250.720000000","bid_sz":50,"ask_sz":100,"bid_ct":1,"ask_ct":1},{"bid_px":"250.000000000","ask_px":"250.760000000","bid_sz":1,"ask_sz":50,"bid_ct":1,"ask_ct":1},{"bid_px":"249.930000000","ask_px":"252.400000000","bid_sz":10,"ask_sz":1000,"bid_ct":1,"ask_ct":1},{"bid_px":"249.800000000","ask_px":"253.650000000","bid_sz":199,"ask_sz":400,"bid_ct":1,"ask_ct":1},{"bid_px":"249.770000000","ask_px":"255.000000000","bid_sz":50,"ask_sz":10,"bid_ct":1,"ask_ct":1},{"bid_px":"249.600000000","ask_px":"260.000000000","bid_sz":1000,"ask_sz":48,"bid_ct":1,"ask_ct":1},{"bid_px":"249.500000000","ask_px":"262.660000000","bid_sz":1000,"ask_sz":56,"bid_ct":1,"ask_ct":1},{"bid_px":"248.600000000","ask_px":"264.940000000","bid_sz":1000,"ask_sz":7,"bid_ct":1,"ask_ct":1},{"bid_px":"247.150000000","ask_px":"265.000000000","bid_sz":400,"ask_sz":1,"bid_ct":1,"ask_ct":1},{"bid_px":"247.000000000","ask_px":"267.800000000","bid_sz":12,"ask_sz":30,"bid_ct":1,"ask_ct":1}],"symbol":"TSLA"}
{"ts_recv":"2024-11-01T08:00:09.277140273Z","hd":{"ts_event":"2024-11-01T08:00:09.276974348Z","rtype":10,"publisher_id":2,"instrument_id":10888},"action":"A","side":"A","depth":0,"price":"414.000000000","size":33,"flags":130,"ts_in_delta":165925,"sequence":308057,"levels":[{"bid_px":"410.000000000","ask_px":"414.000000000","bid_sz":1,"ask_sz":33,"bid_ct":1,"ask_ct":1},{"bid_px":"409.080000000","ask_px":"415.070000000","bid_sz":2,"ask_sz":246,"bid_ct":1,"ask_ct":1},{"bid_px":"408.970000000","ask_px":"420.000000000","bid_sz":12,"ask_sz":3,"bid_ct":1,"ask_ct":1},{"bid_px":"408.960000000","ask_px":"445.000000000","bid_sz":5,"ask_sz":25,"bid_ct":1,"ask_ct":1},{"bid_px":"407.600000000","ask_px":"445.680000000","bid_sz":16,"ask_sz":3,"bid_ct":1,"ask_ct":1},{"bid_px":"407.000000000","ask_px":"448.000000000","bid_sz":4,"ask_sz":15,"bid_ct":2,"ask_ct":2},{"bid_px":"406.350000000","ask_px":"450.000000000","bid_sz":2,"ask_sz":10,"bid_ct":1,"ask_ct":1},{"bid_px":"406.000000000","ask_px":"468.000000000","bid_sz":7,"ask_sz":65,"bid_ct":1,"ask_ct":1},{"bid_px":"405.000000000","ask_px":"472.000000000","bid_sz":15,"ask_sz":6,"bid_ct":2,"ask_ct":1},{"bid_px":"404.410000000","ask_px":null,"bid_sz":246,"ask_sz":0,"bid_ct":1,"ask_ct":0}],"symbol":"MSFT"}
{"ts_recv":"2024-11-01T08:00:09.308061326Z","hd":{"ts_event":"2024-11-01T08:00:09.307894586Z","rtype":10,"publisher_id":2,"instrument_id":11667},"action":"A","side":"B","depth":1,"price":"134.500000000","size":20,"flags":130,"ts_in_delta":166740,"sequence":308102,"levels":[{"bid_px":"134.670000000","ask_px":"134.990000000","bid_sz":100,"ask_sz":10,"bid_ct":1,"ask_ct":1},{"bid_px":"134.500000000","ask_px":"135.000000000","bid_sz":520,"ask_sz":38,"bid_ct":2,"ask_ct":3},{"bid_px":"134.410000000","ask_px":"135.100000000","bid_sz":61,"ask_sz":10,"bid_ct":2,"ask_ct":1},{"bid_px":"134.380000000","ask_px":"135.230000000","bid_sz":18,"ask_sz":360,"bid_ct":1,"ask_ct":1},{"bid_px":"134.210000000","ask_px":"135.300000000","bid_sz":20,"ask_sz":1000,"bid_ct":1,"ask_ct":1},{"bid_px":"134.200000000","ask_px":"135.400000000","bid_sz":3,"ask_sz":10,"bid_ct":1,"ask_ct":1},{"bid_px":"133.160000000","ask_px":"135.420000000","bid_sz":1,"ask_sz":1,"bid_ct":1,"ask_ct":1},{"bid_px":"132.700000000","ask_px":"135.820000000","bid_sz":4,"ask_sz":1,"bid_ct":1,"ask_ct":1},{"bid_px":"132.660000000","ask_px":"135.990000000","bid_sz":1,"ask_sz":20,"bid_ct":1,"ask_ct":1},{"bid_px":"132.160000000","ask_px":"136.100000000","bid_sz":1,"ask_sz":1000,"bid_ct":1,"ask_ct":1}],"symbol":"NVDA"}
{"ts_recv":"2024-11-01T08:00:09.310782807Z","hd":{"ts_event":"2024-11-01T08:00:09.310616621Z","rtype":10,"publisher_id":2,"instrument_id":16244},"action":"A","side":"A","depth":4,"price":"255.000000000","size":75,"flags":130,"ts_in_delta":166186,"sequence":308109,"levels":[{"bid_px":"250.030000000","ask_px":"250.720000000","bid_sz":50,"ask_sz":100,"bid_ct":1,"ask_ct":1},{"bid_px":"250.000000000","ask_px":"250.760000000","bid_sz":1,"ask_sz":50,"bid_ct":1,"ask_ct":1},{"bid_px":"249.930000000","ask_px":"252.400000000","bid_sz":10,"ask_sz":1000,"bid_ct":1,"ask_ct":1},{"bid_px":"249.800000000","ask_px":"253.650000000","bid_sz":199,"ask_sz":400,"bid_ct":1,"ask_ct":1},{"bid_px":"249.770000000","ask_px":"255.000000000","bid_sz":50,"ask_sz":85,"bid_ct":1,"ask_ct":2},{"bid_px":"249.600000000","ask_px":"260.000000000","bid_sz":1000,"ask_sz":48,"bid_ct":1,"ask_ct":1},{"bid_px":"249.500000000","ask_px":"262.660000000","bid_sz":1000,"ask_sz":56,"bid_ct":1,"ask_ct":1},{"bid_px":"248.600000000","ask_px":"264.940000000","bid_sz":1000,"ask_sz":7,"bid_ct":1,"ask_ct":1},{"bid_px":"247.150000000","ask_px":"265.000000000","bid_sz":400,"ask_sz":1,"bid_ct":1,"ask_ct":1},{"bid_px":"247.000000000","ask_px":"267.800000000","bid_sz":12,"ask_sz":30,"bid_ct":1,"ask_ct":1}],"symbol":"TSLA"}
{"ts_recv":"2024-11-01T08:00:09.375551471Z","hd":{"ts_event":"2024-11-01T08:00:09.375379710Z","rtype":10,"publisher_id":2,"instrument_id":38},"action":"A","side":"A","depth":1,"price":"225.000000000","size":1,"flags":130,"ts_in_delta":171761,"sequence":308238,"levels":[{"bid_px":"221.100000000","ask_px":"224.400000000","bid_sz":1000,"ask_sz":1000,"bid_ct":1,"ask_ct":1},{"bid_px":"220.000000000","ask_px":"225.000000000","bid_sz":2,"ask_sz":1,"bid_ct":1,"ask_ct":1},{"bid_px":"219.690000000","ask_px":"225.360000000","bid_sz":442,"ask_sz":1,"bid_ct":1,"ask_ct":1},{"bid_px":"217.000000000","ask_px":"225.490000000","bid_sz":1525,"ask_sz":442,"bid_ct":1,"ask_ct":1},{"bid_px":"200.000000000","ask_px":"225.900000000","bid_sz":30,"ask_sz":32,"bid_ct":1,"ask_ct":2},{"bid_px":"190.000000000","ask_px":"229.330000000","bid_sz":1,"ask_sz":9,"bid_ct":1,"ask_ct":2},{"bid_px":"180.000000000","ask_px":"233.670000000","bid_sz":1,"ask_sz":5,"bid_ct":1,"ask_ct":1},{"bid_px":"100.000000000","ask_px":"234.000000000","bid_sz":1,"ask_sz":20,"bid_ct":1,"ask_ct":1},{"bid_px":null,"ask_px":"235.000000000","bid_sz":0,"ask_sz":2,"bid_ct":0,"ask_ct":1},{"bid_px":null,"ask_px":"238.760000000","bid_sz":0,"ask_sz":150,"bid_ct":0,"ask_ct":1}],"symbol":"AAPL"}
{"ts_recv":"2024-11-01T08:00:09.376139884Z","hd":{"ts_event":"2024-11-01T08:00:09.375973484Z","rtype":10,"publisher_id":2,"instrument_id":16727},"action":"A","side":"N","depth":0,"price":"305.000000000","size":1,"flags":130,"ts_in_delta":166400,"sequence":308239,"levels":[{"bid_px":null,"ask_px":"305.000000000","bid_sz":0,"ask_sz":1,"bid_ct":0,"ask_ct":1},{"bid_px":null,"ask_px":null,"bid_sz":0,"ask_sz":0,"bid_ct":0,"ask_ct":0},{"bid_px":null,"ask_px":null,"bid_sz":0,"ask_sz":0,"bid_ct":0,"ask_ct":0},{"bid_px":null,"ask_px":null,"bid_sz":0,"ask_sz":0,"bid_ct":0,"ask_ct":0},{"bid_px":null,"ask_px":null,"bid_sz":0,"ask_sz":0,"bid_ct":0,"ask_ct":0},{"bid_px":null,"ask_px":null,"bid_sz":0,"ask_sz":0,"bid_ct":0,"ask_ct":0},{"bid_px":null,"ask_px":null,"bid_sz":0,"ask_sz":0,"bid_ct":0,"ask_ct":0},{"bid_px":null,"ask_px":null,"bid_sz":0,"ask_sz":0,"bid_ct":0,"ask_ct":0},{"bid_px":null,"ask_px":null,"bid_sz":0,"ask_sz":0,"bid_ct":0,"ask_ct":0},{"bid_px":null,"ask_px":null,"bid_sz":0,"ask_sz":0,"bid_ct":0,"ask_ct":0}],"symbol":"V"}
{"ts_recv":"2024-11-01T08:00:09.418377932Z","hd":{"ts_event":"2024-11-01T08:00:09.418212103Z","rtype":10,"publisher_id":2,"instrument_id":16244},"action":"C","side":"A","depth":1,"price":"250.760000000","size":50,"flags":130,"ts_in_delta":165829,"sequence":308333,"levels":[{"bid_px":"250.030000000","ask_px":"250.720000000","bid_sz":50,"ask_sz":100,"bid_ct":1,"ask_ct":1},{"bid_px":"250.000000000","ask_px":"252.400000000","bid_sz":1,"ask_sz":1000,"bid_ct":1,"ask_ct":1},{"bid_px":"249.930000000","ask_px":"253.650000000","bid_sz":10,"ask_sz":400,"bid_ct":1,"ask_ct":1},{"bid_px":"249.800000000","ask_px":"255.000000000","bid_sz":199,"ask_sz":85,"bid_ct":1,"ask_ct":2},{"bid_px":"249.770000000","ask_px":"260.000000000","bid_sz":50,"ask_sz":48,"bid_ct":1,"ask_ct":1},{"bid_px":"249.600000000","ask_px":"262.660000000","bid_sz":1000,"ask_sz":56,"bid_ct":1,"ask_ct":1},{"bid_px":"249.500000000","ask_px":"264.940000000","bid_sz":1000,"ask_sz":7,"bid_ct":1,"ask_ct":1},{"bid_px":"248.600000000","ask_px":"265.000000000","bid_sz":1000,"ask_sz":1,"bid_ct":1,"ask_ct":1},{"bid_px":"247.150000000","ask_px":"267.800000000","bid_sz":400,"ask_sz":30,"bid_ct":1,"ask_ct":1},{"bid_px":"247.000000000","ask_px":"268.670000000","bid_sz":12,"ask_sz":100,"bid_ct":1,"ask_ct":1}],"symbol":"TSLA"}
{"ts_recv":"2024-11-01T08:00:09.418389580Z","hd":{"ts_event":"2024-11-01T08:00:09.418223858Z","rtype":10,"publisher_id":2,"instrument_id":16244},"action":"A","side":"A","depth":1,"price":"250.850000000","size":50,"flags":130,"ts_in_delta":165722,"sequence":308334,"levels":[{"bid_px":"250.030000000","ask_px":"250.720000000","bid_sz":50,"ask_sz":100,"bid_ct":1,"ask_ct":1},{"bid_px":"250.000000000","ask_px":"250.850000000","bid_sz":1,"ask_sz":50,"bid_ct":1,"ask_ct":1},{"bid_px":"249.930000000","ask_px":"252.400000000","bid_sz":10,"ask_sz":1000,"bid_ct":1,"ask_ct":1},{"bid_px":"249.800000000","ask_px":"253.650000000","bid_sz":199,"ask_sz":400,"bid_ct":1,"ask_ct":1},{"bid_px":"249.770000000","ask_px":"255.000000000","bid_sz":50,"ask_sz":85,"bid_ct":1,"ask_ct":2},{"bid_px":"249.600000000","ask_px":"260.000000000","bid_sz":1000,"ask_sz":48,"bid_ct":1,"ask_ct":1},{"bid_px":"249.500000000","ask_px":"262.660000000","bid_sz":1000,"ask_sz":56,"bid_ct":1,"ask_ct":1},{"bid_px":"248.600000000","ask_px":"264.940000000","bid_sz":1000,"ask_sz":7,"bid_ct":1,"ask_ct":1},{"bid_px":"247.150000000","ask_px":"265.000000000","bid_sz":400,"ask_sz":1,"bid_ct":1,"ask_ct":1},{"bid_px":"247.000000000","ask_px":"267.800000000","bid_sz":12,"ask_sz":30,"bid_ct":1,"ask_ct":1}],"symbol":"TSLA"}
{"ts_recv":"2024-11-01T08:00:09.418425546Z","hd":{"ts_event":"2024-11-01T08:00:09.418259940Z","rtype":10,"publisher_id":2,"instrument_id":16244},"action":"C","side":"A","depth":1,"price":"250.850000000","size":50,"flags":130,"ts_in_delta":165606,"sequence":308335,"levels":[{"bid_px":"250.030000000","ask_px":"250.720000000","bid_sz":50,"ask_sz":100,"bid_ct":1,"ask_ct":1},{"bid_px":"250.000000000","ask_px":"252.400000000","bid_sz":1,"ask_sz":1000,"bid_ct":1,"ask_ct":1},{"bid_px":"249.930000000","ask_px":"253.650000000","bid_sz":10,"ask_sz":400,"bid_ct":1,"ask_ct":1},{"bid_px":"249.800000000","ask_px":"255.000000000","bid_sz":199,"ask_sz":85,"bid_ct":1,"ask_ct":2},{"bid_px":"249.770000000","ask_px":"260.000000000","bid_sz":50,"ask_sz":48,"bid_ct":1,"ask_ct":1},{"bid_px":"249.600000000","ask_px":"262.660000000","bid_sz":1000,"ask_sz":56,"bid_ct":1,"ask_ct":1},{"bid_px":"249.500000000","ask_px":"264.940000000","bid_sz":1000,"ask_sz":7,"bid_ct":1,"ask_ct":1},{"bid_px":"248.600000000","ask_px":"265.000000000","bid_sz":1000,"ask_sz":1,"bid_ct":1,"ask_ct":1},{"bid_px":"247.150000000","ask_px":"267.800000000","bid_sz":400,"ask_sz":30,"bid_ct":1,"ask_ct":1},{"bid_px":"247.000000000","ask_px":"268.670000000","bid_sz":12,"ask_sz":100,"bid_ct":1,"ask_ct":1}],"symbol":"TSLA"}
{"ts_recv":"2024-11-01T08:00:09.418520594Z","hd":{"ts_event":"2024-11-01T08:00:09.418354592Z","rtype":10,"publisher_id":2,"instrument_id":16244},"action":"A","side":"A","depth":1,"price":"251.090000000","size":50,"flags":130,"ts_in_delta":166002,"sequence":308336,"levels":[{"bid_px":"250.030000000","ask_px":"250.720000000","bid_sz":50,"ask_sz":100,"bid_ct":1,"ask_ct":1},{"bid_px":"250.000000000","ask_px":"251.090000000","bid_sz":1,"ask_sz":50,"bid_ct":1,"ask_ct":1},{"bid_px":"249.930000000","ask_px":"252.400000000","bid_sz":10,"ask_sz":1000,"bid_ct":1,"ask_ct":1},{"bid_px":"249.800000000","ask_px":"253.650000000","bid_sz":199,"ask_sz":400,"bid_ct":1,"ask_ct":1},{"bid_px":"249.770000000","ask_px":"255.000000000","bid_sz":50,"ask_sz":85,"bid_ct":1,"ask_ct":2},{"bid_px":"249.600000000","ask_px":"260.000000000","bid_sz":1000,"ask_sz":48,"bid_ct":1,"ask_ct":1},{"bid_px":"249.500000000","ask_px":"262.660000000","bid_sz":1000,"ask_sz":56,"bid_ct":1,"ask_ct":1},{"bid_px":"248.600000000","ask_px":"264.940000000","bid_sz":1000,"ask_sz":7,"bid_ct":1,"ask_ct":1},{"bid_px":"247.150000000","ask_px":"265.000000000","bid_sz":400,"ask_sz":1,"bid_ct":1,"ask_ct":1},{"bid_px":"247.000000000","ask_px":"267.800000000","bid_sz":12,"ask_sz":30,"bid_ct":1,"ask_ct":1}],"symbol":"TSLA"}
{"ts_recv":"2024-11-01T08:00:09.418532243Z","hd":{"ts_event":"2024-11-01T08:00:09.418366536Z","rtype":10,"publisher_id":2,"instrument_id":16244},"action":"C","side":"B","depth":0,"price":"250.030000000","size":50,"flags":130,"ts_in_delta":165707,"sequence":308337,"levels":[{"bid_px":"250.000000000","ask_px":"250.720000000","bid_sz":1,"ask_sz":100,"bid_ct":1,"ask_ct":1},{"bid_px":"249.930000000","ask_px":"251.090000000","bid_sz":10,"ask_sz":50,"bid_ct":1,"ask_ct":1},{"bid_px":"249.800000000","ask_px":"252.400000000","bid_sz":199,"ask_sz":1000,"bid_ct":1,"ask_ct":1},{"bid_px":"249.770000000","ask_px":"253.650000000","bid_sz":50,"ask_sz":400,"bid_ct":1,"ask_ct":1},{"bid_px":"249.600000000","ask_px":"255.000000000","bid_sz":1000,"ask_sz":85,"bid_ct":1,"ask_ct":2},{"bid_px":"249.500000000","ask_px":"260.000000000","bid_sz":1000,"ask_sz":48,"bid_ct":1,"ask_ct":1},{"bid_px":"248.600000000","ask_px":"262.660000000","bid_sz":1000,"ask_sz":56,"bid_ct":1,"ask_ct":1},{"bid_px":"247.150000000","ask_px":"264.940000000","bid_sz":400,"ask_sz":7,"bid_ct":1,"ask_ct":1},{"bid_px":"247.000000000","ask_px":"265.000000000","bid_sz":12,"ask_sz":1,"bid_ct":1,"ask_ct":1},{"bid_px":"246.000000000","ask_px":"267.800000000","bid_sz":4,"ask_sz":30,"bid_ct":1,"ask_ct":1}],"symbol":"TSLA"}
{"ts_recv":"2024-11-01T08:00:09.418543180Z","hd":{"ts_event":"2024-11-01T08:00:09.418377438Z","rtype":10,"publisher_id":2,"instrument_id":16244},"action":"A","side":"B","depth":1,"price":"249.980000000","size":50,"flags":130,"ts_in_delta":165742,"sequence":308338,"levels":[{"bid_px":"250.000000000","ask_px":"250.720000000","bid_sz":1,"ask_sz":100,"bid_ct":1,"ask_ct":1},{"bid_px":"249.980000000","ask_px":"251.090000000","bid_sz":50,"ask_sz":50,"bid_ct":1,"ask_ct":1},{"bid_px":"249.930000000","ask_px":"252.400000000","bid_sz":10,"ask_sz":1000,"bid_ct":1,"ask_ct":1},{"bid_px":"249.800000000","ask_px":"253.650000000","bid_sz":199,"ask_sz":400,"bid_ct":1,"ask_ct":1},{"bid_px":"249.770000000","ask_px":"255.000000000","bid_sz":50,"ask_sz":85,"bid_ct":1,"ask_ct":2},{"bid_px":"249.600000000","ask_px":"260.000000000","bid_sz":1000,"ask_sz":48,"bid_ct":1,"ask_ct":1},{"bid_px":"249.500000000","ask_px":"262.660000000","bid_sz":1000,"ask_sz":56,"bid_ct":1,"ask_ct":1},{"bid_px":"248.600000000","ask_px":"264.940000000","bid_sz":1000,"ask_sz":7,"bid_ct":1,"ask_ct":1},{"bid_px":"247.150000000","ask_px":"265.000000000","bid_sz":400,"ask_sz":1,"bid_ct":1,"ask_ct":1},{"bid_px":"247.000000000","ask_px":"267.800000000","bid_sz":12,"ask_sz":30,"bid_ct":1,"ask_ct":1}],"symbol":"TSLA"}
{"ts_recv":"2024-11-01T08:00:09.418593088Z","hd":{"ts_event":"2024-11-01T08:00:09.418426750Z","rtype":10,"publisher_id":2,"instrument_id":16244},"action":"C","side":"B","depth":1,"price":"249.980000000","size":50,"flags":130,"ts_in_delta":166338,"sequence":308339,"levels":[{"bid_px":"250.000000000","ask_px":"250.720000000","bid_sz":1,"ask_sz":100,"bid_ct":1,"ask_ct":1},{"bid_px":"249.930000000","ask_px":"251.090000000","bid_sz":10,"ask_sz":50,"bid_ct":1,"ask_ct":1},{"bid_px":"249.800000000","ask_px":"252.400000000","bid_sz":199,"ask_sz":1000,"bid_ct":1,"ask_ct":1},{"bid_px":"249.770000000","ask_px":"253.650000000","bid_sz":50,"ask_sz":400,"bid_ct":1,"ask_ct":1},{"bid_px":"249.600000000","ask_px":"255.000000000","bid_sz":1000,"ask_sz":85,"bid_ct":1,"ask_ct":2},{"bid_px":"249.500000000","ask_px":"260.000000000","bid_sz":1000,"ask_sz":48,"bid_ct":1,"ask_ct":1},{"bid_px":"248.600000000","ask_px":"262.660000000","bid_sz":1000,"ask_sz":56,"bid_ct":1,"ask_ct":1},{"bid_px":"247.150000000","ask_px":"264.940000000","bid_sz":400,"ask_sz":7,"bid_ct":1,"ask_ct":1},{"bid_px":"247.000000000","ask_px":"265.000000000","bid_sz":12,"ask_sz":1,"bid_ct":1,"ask_ct":1},{"bid_px":"246.000000000","ask_px":"267.800000000","bid_sz":4,"ask_sz":30,"bid_ct":1,"ask_ct":1}],"symbol":"TSLA"}
{"ts_recv":"2024-11-01T08:00:09.418640702Z","hd":{"ts_event":"2024-11-01T08:00:09.418474852Z","rtype":10,"publisher_id":2,"instrument_id":16244},"action":"A","side":"B","depth":2,"price":"249.920000000","size":50,"flags":130,"ts_in_delta":165850,"sequence":308340,"levels":[{"bid_px":"250.000000000","ask_px":"250.720000000","bid_sz":1,"ask_sz":100,"bid_ct":1,"ask_ct":1},{"bid_px":"249.930000000","ask_px":"251.090000000","bid_sz":10,"ask_sz":50,"bid_ct":1,"ask_ct":1},{"bid_px":"249.920000000","ask_px":"252.400000000","bid_sz":50,"ask_sz":1000,"bid_ct":1,"ask_ct":1},{"bid_px":"249.800000000","ask_px":"253.650000000","bid_sz":199,"ask_sz":400,"bid_ct":1,"ask_ct":1},{"bid_px":"249.770000000","ask_px":"255.000000000","bid_sz":50,"ask_sz":85,"bid_ct":1,"ask_ct":2},{"bid_px":"249.600000000","ask_px":"260.000000000","bid_sz":1000,"ask_sz":48,"bid_ct":1,"ask_ct":1},{"bid_px":"249.500000000","ask_px":"262.660000000","bid_sz":1000,"ask_sz":56,"bid_ct":1,"ask_ct":1},{"bid_px":"248.600000000","ask_px":"264.940000000","bid_sz":1000,"ask_sz":7,"bid_ct":1,"ask_ct":1},{"bid_px":"247.150000000","ask_px":"265.000000000","bid_sz":400,"ask_sz":1,"bid_ct":1,"ask_ct":1},{"bid_px":"247.000000000","ask_px":"267.800000000","bid_sz":12,"ask_sz":30,"bid_ct":1,"ask_ct":1}],"symbol":"TSLA"}
{"ts_recv":"2024-11-01T08:00:09.445856807Z","hd":{"ts_event":"2024-11-01T08:00:09.445690849Z","rtype":10,"publisher_id":2,"instrument_id":10888},"action":"A","side":"B","depth":1,"price":"409.750000000","size":3,"flags":130,"ts_in_delta":165958,"sequence":308395,"levels":[{"bid_px":"410.000000000","ask_px":"414.000000000","bid_sz":1,"ask_sz":33,"bid_ct":1,"ask_ct":1},{"bid_px":"409.750000000","ask_px":"415.070000000","bid_sz":3,"ask_sz":246,"bid_ct":1,"ask_ct":1},{"bid_px":"409.080000000","ask_px":"420.000000000","bid_sz":2,"ask_sz":3,"bid_ct":1,"ask_ct":1},{"bid_px":"408.970000000","ask_px":"445.000000000","bid_sz":12,"ask_sz":25,"bid_ct":1,"ask_ct":1},{"bid_px":"408.960000000","ask_px":"445.680000000","bid_sz":5,"ask_sz":3,"bid_ct":1,"ask_ct":1},{"bid_px":"407.600000000","ask_px":"448.000000000","bid_sz":16,"ask_sz":15,"bid_ct":1,"ask_ct":2},{"bid_px":"407.000000000","ask_px":"450.000000000","bid_sz":4,"ask_sz":10,"bid_ct":2,"ask_ct":1},{"bid_px":"406.350000000","ask_px":"468.000000000","bid_sz":2,"ask_sz":65,"bid_ct":1,"ask_ct":1},{"bid_px":"406.000000000","ask_px":"472.000000000","bid_sz":7,"ask_sz":6,"bid_ct":1,"ask_ct":1},{"bid_px":"405.000000000","ask_px":null,"bid_sz":15,"ask_sz":0,"bid_ct":2,"ask_ct":0}],"symbol":"MSFT"}
{"ts_recv":"2024-11-01T08:00:09.517904343Z","hd":{"ts_event":"2024-11-01T08:00:09.517738185Z","rtype":10,"publisher_id":2,"instrument_id":10888},"action":"A","side":"B","depth":7,"price":"406.350000000","size":80,"flags":130,"ts_in_delta":166158,"sequence":308484,"levels":[{"bid_px":"410.000000000","ask_px":"414.000000000","bid_sz":1,"ask_sz":33,"bid_ct":1,"ask_ct":1},{"bid_px":"409.750000000","ask_px":"415.070000000","bid_sz":3,"ask_sz":246,"bid_ct":1,"ask_ct":1},{"bid_px":"409.080000000","ask_px":"420.000000000","bid_sz":2,"ask_sz":3,"bid_ct":1,"ask_ct":1},{"bid_px":"408.970000000","ask_px":"445.000000000","bid_sz":12,"ask_sz":25,"bid_ct":1,"ask_ct":1},{"bid_px":"408.960000000","ask_px":"445.680000000","bid_sz":5,"ask_sz":3,"bid_ct":1,"ask_ct":1},{"bid_px":"407.600000000","ask_px":"448.000000000","bid_sz":16,"ask_sz":15,"bid_ct":1,"ask_ct":2},{"bid_px":"407.000000000","ask_px":"450.000000000","bid_sz":4,"ask_sz":10,"bid_ct":2,"ask_ct":1},{"bid_px":"406.350000000","ask_px":"468.000000000","bid_sz":82,"ask_sz":65,"bid_ct":2,"ask_ct":1},{"bid_px":"406.000000000","ask_px":"472.000000000","bid_sz":7,"ask_sz":6,"bid_ct":1,"ask_ct":1},{"bid_px":"405.000000000","ask_px":null,"bid_sz":15,"ask_sz":0,"bid_ct":2,"ask_ct":0}],"symbol":"MSFT"}
{"ts_recv":"2024-11-01T08:00:09.535022669Z","hd":{"ts_event":"2024-11-01T08:00:09.534856493Z","rtype":10,"publisher_id":2,"instrument_id":38},"action":"A","side":"B","depth":4,"price":"213.000000000","size":5,"flags":130,"ts_in_delta":166176,"sequence":308531,"levels":[{"bid_px":"221.100000000","ask_px":"224.400000000","bid_sz":1000,"ask_sz":1000,"bid_ct":1,"ask_ct":1},{"bid_px":"220.000000000","ask_px":"225.000000000","bid_sz":2,"ask_sz":1,"bid_ct":1,"ask_ct":1},{"bid_px":"219.690000000","ask_px":"225.360000000","bid_sz":442,"ask_sz":1,"bid_ct":1,"ask_ct":1},{"bid_px":"217.000000000","ask_px":"225.490000000","bid_sz":1525,"ask_sz":442,"bid_ct":1,"ask_ct":1},{"bid_px":"213.000000000","ask_px":"225.900000000","bid_sz":5,"ask_sz":32,"bid_ct":1,"ask_ct":2},{"bid_px":"200.000000000","ask_px":"229.330000000","bid_sz":30,"ask_sz":9,"bid_ct":1,"ask_ct":2},{"bid_px":"190.000000000","ask_px":"233.670000000","bid_sz":1,"ask_sz":5,"bid_ct":1,"ask_ct":1},{"bid_px":"180.000000000","ask_px":"234.000000000","bid_sz":1,"ask_sz":20,"bid_ct":1,"ask_ct":1},{"bid_px":"100.000000000","ask_px":"235.000000000","bid_sz":1,"ask_sz":2,"bid_ct":1,"ask_ct":1},{"bid_px":null,"ask_px":"238.760000000","bid_sz":0,"ask_sz":150,"bid_ct":0,"ask_ct":1}],"symbol":"AAPL"}
{"ts_recv":"2024-11-01T08:00:09.552701395Z","hd":{"ts_event":"2024-11-01T08:00:09.552535219Z","rtype":10,"publisher_id":2,"instrument_id":38},"action":"A","side":"B","depth":5,"price":"210.000000000","size":1,"flags":130,"ts_in_delta":166176,"sequence":308600,"levels":[{"bid_px":"221.100000000","ask_px":"224.400000000","bid_sz":1000,"ask_sz":1000,"bid_ct":1,"ask_ct":1},{"bid_px":"220.000000000","ask_px":"225.000000000","bid_sz":2,"ask_sz":1,"bid_ct":1,"ask_ct":1},{"bid_px":"219.690000000","ask_px":"225.360000000","bid_sz":442,"ask_sz":1,"bid_ct":1,"ask_ct":1},{"bid_px":"217.000000000","ask_px":"225.490000000","bid_sz":1525,"ask_sz":442,"bid_ct":1,"ask_ct":1},{"bid_px":"213.000000000","ask_px":"225.900000000","bid_sz":5,"ask_sz":32,"bid_ct":1,"ask_ct":2},{"bid_px":"210.000000000","ask_px":"229.330000000","bid_sz":1,"ask_sz":9,"bid_ct":1,"ask_ct":2},{"bid_px":"200.000000000","ask_px":"233.670000000","bid_sz":30,"ask_sz":5,"bid_ct":1,"ask_ct":1},{"bid_px":"190.000000000","ask_px":"234.000000000","bid_sz":1,"ask_sz":20,"bid_ct":1,"ask_ct":1},{"bid_px":"180.000000000","ask_px":"235.000000000","bid_sz":1,"ask_sz":2,"bid_ct":1,"ask_ct":1},{"bid_px":"100.000000000","ask_px":"238.760000000","bid_sz":1,"ask_sz":150,"bid_ct":1,"ask_ct":1}],"symbol":"AAPL"}
{"ts_recv":"2024-11-01T08:00:09.572901021Z","hd":{"ts_event":"2024-11-01T08:00:09.572735201Z","rtype":10,"publisher_id":2,"instrument_id":38},"action":"C","side":"B","depth":0,"price":"221.100000000","size":1000,"flags":130,"ts_in_delta":165820,"sequence":308655,"levels":[{"bid_px":"220.000000000","ask_px":"224.400000000","bid_sz":2,"ask_sz":1000,"bid_ct":1,"ask_ct":1},{"bid_px":"219.690000000","ask_px":"225.000000000","bid_sz":442,"ask_sz":1,"bid_ct":1,"ask_ct":1},{"bid_px":"217.000000000","ask_px":"225.360000000","bid_sz":1525,"ask_sz":1,"bid_ct":1,"ask_ct":1},{"bid_px":"213.000000000","ask_px":"225.490000000","bid_sz":5,"ask_sz":442,"bid_ct":1,"ask_ct":1},{"bid_px":"210.000000000","ask_px":"225.900000000","bid_sz":1,"ask_sz":32,"bid_ct":1,"ask_ct":2},{"bid_px":"200.000000000","ask_px":"229.330000000","bid_sz":30,"ask_sz":9,"bid_ct":1,"ask_ct":2},{"bid_px":"190.000000000","ask_px":"233.670000000","bid_sz":1,"ask_sz":5,"bid_ct":1,"ask_ct":1},{"bid_px":"180.000000000","ask_px":"234.000000000","bid_sz":1,"ask_sz":20,"bid_ct":1,"ask_ct":1},{"bid_px":"100.000000000","ask_px":"235.000000000","bid_sz":1,"ask_sz":2,"bid_ct":1,"ask_ct":1},{"bid_px":null,"ask_px":"238.760000000","bid_sz":0,"ask_sz":150,"bid_ct":0,"ask_ct":1}],"symbol":"AAPL"}
{"ts_recv":"2024-11-01T08:00:09.608484297Z","hd":{"ts_event":"2024-11-01T08:00:09.608317265Z","rtype":10,"publisher_id":2,"instrument_id":38},"action":"A","side":"B","depth":0,"price":"221.300000000","size":1000,"flags":130,"ts_in_delta":167032,"sequence":308822,"levels":[{"bid_px":"221.300000000","ask_px":"224.400000000","bid_sz":1000,"ask_sz":1000,"bid_ct":1,"ask_ct":1},{"bid_px":"220.000000000","ask_px":"225.000000000","bid_sz":2,"ask_sz":1,"bid_ct":1,"ask_ct":1},{"bid_px":"219.690000000","ask_px":"225.360000000","bid_sz":442,"ask_sz":1,"bid_ct":1,"ask_ct":1},{"bid_px":"217.000000000","ask_px":"225.490000000","bid_sz":1525,"ask_sz":442,"bid_ct":1,"ask_ct":1},{"bid_px":"213.000000000","ask_px":"225.900000000","bid_sz":5,"ask_sz":32,"bid_ct":1,"ask_ct":2},{"bid_px":"210.000000000","ask_px":"229.330000000","bid_sz":1,"ask_sz":9,"bid_ct":1,"ask_ct":2},{"bid_px":"200.000000000","ask_px":"233.670000000","bid_sz":30,"ask_sz":5,"bid_ct":1,"ask_ct":1},{"bid_px":"190.000000000","ask_px":"234.000000000","bid_sz":1,"ask_sz":20,"bid_ct":1,"ask_ct":1},{"bid_px":"180.000000000","ask_px":"235.000000000","bid_sz":1,"ask_sz":2,"bid_ct":1,"ask_ct":1},{"bid_px":"100.000000000","ask_px":"238.760000000","bid_sz":1,"ask_sz":150,"bid_ct":1,"ask_ct":1}],"symbol":"AAPL"}
{"ts_recv":"2024-11-01T08:00:09.622940156Z","hd":{"ts_event":"2024-11-01T08:00:09.622774366Z","rtype":10,"publisher_id":2,"instrument_id":38},"action":"A","side":"B","depth":3,"price":"219.000000000","size":1,"flags":130,"ts_in_delta":165790,"sequence":308901,"levels":[{"bid_px":"221.300000000","ask_px":"224.400000000","bid_sz":1000,"ask_sz":1000,"bid_ct":1,"ask_ct":1},{"bid_px":"220.000000000","ask_px":"225.000000000","bid_sz":2,"ask_sz":1,"bid_ct":1,"ask_ct":1},{"bid_px":"219.690000000","ask_px":"225.360000000","bid_sz":442,"ask_sz":1,"bid_ct":1,"ask_ct":1},{"bid_px":"219.000000000","ask_px":"225.490000000","bid_sz":1,"ask_sz":442,"bid_ct":1,"ask_ct":1},{"bid_px":"217.000000000","ask_px":"225.900000000","bid_sz":1525,"ask_sz":32,"bid_ct":1,"ask_ct":2},{"bid_px":"213.000000000","ask_px":"229.330000000","bid_sz":5,"ask_sz":9,"bid_ct":1,"ask_ct":2},{"bid_px":"210.000000000","ask_px":"233.670000000","bid_sz":1,"ask_sz":5,"bid_ct":1,"ask_ct":1},{"bid_px":"200.000000000","ask_px":"234.000000000","bid_sz":30,"ask_sz":20,"bid_ct":1,"ask_ct":1},{"bid_px":"190.000000000","ask_px":"235.000000000","bid_sz":1,"ask_sz":2,"bid_ct":1,"ask_ct":1},{"bid_px":"180.000000000","ask_px":"238.760000000","bid_sz":1,"ask_sz":150,"bid_ct":1,"ask_ct":1}],"symbol":"AAPL"}
{"ts_recv":"2024-11-01T08:00:09.643218540Z","hd":{"ts_event":"2024-11-01T08:00:09.643052065Z","rtype":10,"publisher_id":2,"instrument_id":11667},"action":"A","side":"B","depth":7,"price":"132.760000000","size":100,"flags":130,"ts_in_delta":166475,"sequence":308999,"levels":[{"bid_px":"134.670000000","ask_px":"134.990000000","bid_sz":100,"ask_sz":10,"bid_ct":1,"ask_ct":1},{"bid_px":"134.500000000","ask_px":"135.000000000","bid_sz":520,"ask_sz":38,"bid_ct":2,"ask_ct":3},{"bid_px":"134.410000000","ask_px":"135.100000000","bid_sz":61,"ask_sz":10,"bid_ct":2,"ask_ct":1},{"bid_px":"134.380000000","ask_px":"135.230000000","bid_sz":18,"ask_sz":360,"bid_ct":1,"ask_ct":1},{"bid_px":"134.210000000","ask_px":"135.300000000","bid_sz":20,"ask_sz":1000,"bid_ct":1,"ask_ct":1},{"bid_px":"134.200000000","ask_px":"135.400000000","bid_sz":3,"ask_sz":10,"bid_ct":1,"ask_ct":1},{"bid_px":"133.160000000","ask_px":"135.420000000","bid_sz":1,"ask_sz":1,"bid_ct":1,"ask_ct":1},{"bid_px":"132.760000000","ask_px":"135.820000000","bid_sz":100,"ask_sz":1,"bid_ct":1,"ask_ct":1},{"bid_px":"132.700000000","ask_px":"135.990000000","bid_sz":4,"ask_sz":20,"bid_ct":1,"ask_ct":1},{"bid_px":"132.660000000","ask_px":"136.100000000","bid_sz":1,"ask_sz":1000,"bid_ct":1,"ask_ct":1}],"symbol":"NVDA"}
{"ts_recv":"2024-11-01T08:00:09.696356146Z","hd":{"ts_event":"2024-11-01T08:00:09.696189765Z","rtype":10,"publisher_id":2,"instrument_id":16244},"action":"A","side":"B","depth":1,"price":"249.970000000","size":50,"flags":130,"ts_in_delta":166381,"sequence":309221,"levels":[{"bid_px":"250.000000000","ask_px":"250.720000000","bid_sz":1,"ask_sz":100,"bid_ct":1,"ask_ct":1},{"bid_px":"249.970000000","ask_px":"251.090000000","bid_sz":50,"ask_sz":50,"bid_ct":1,"ask_ct":1},{"bid_px":"249.930000000","ask_px":"252.400000000","bid_sz":10,"ask_sz":1000,"bid_ct":1,"ask_ct":1},{"bid_px":"249.800000000","ask_px":"253.650000000","bid_sz":199,"ask_sz":400,"bid_ct":1,"ask_ct":1},{"bid_px":"249.770000000","ask_px":"255.000000000","bid_sz":50,"ask_sz":85,"bid_ct":1,"ask_ct":2},{"bid_px":"249.600000000","ask_px":"260.000000000","bid_sz":1000,"ask_sz":48,"bid_ct":1,"ask_ct":1},{"bid_px":"249.500000000","ask_px":"262.660000000","bid_sz":1000,"ask_sz":56,"bid_ct":1,"ask_ct":1},{"bid_px":"248.600000000","ask_px":"264.940000000","bid_sz":1000,"ask_sz":7,"bid_ct":1,"ask_ct":1},{"bid_px":"247.150000000","ask_px":"265.000000000","bid_sz":400,"ask_sz":1,"bid_ct":1,"ask_ct":1},{"bid_px":"247.000000000","ask_px":"267.800000000","bid_sz":12,"ask_sz":30,"bid_ct":1,"ask_ct":1}],"symbol":"TSLA"}
{"ts_recv":"2024-11-01T08:00:09.738821655Z","hd":{"ts_event":"2024-11-01T08:00:09.738655371Z","rtype":10,"publisher_id":2,"instrument_id":10888},"action":"A","side":"B","depth":6,"price":"407.000000000","size":13,"flags":130,"ts_in_delta":166284,"sequence":309298,"levels":[{"bid_px":"410.000000000","ask_px":"414.000000000","bid_sz":1,"ask_sz":33,"bid_ct":1,"ask_ct":1},{"bid_px":"409.750000000","ask_px":"415.070000000","bid_sz":3,"ask_sz":246,"bid_ct":1,"ask_ct":1},{"bid_px":"409.080000000","ask_px":"420.000000000","bid_sz":2,"ask_sz":3,"bid_ct":1,"ask_ct":1},{"bid_px":"408.970000000","ask_px":"445.000000000","bid_sz":12,"ask_sz":25,"bid_ct":1,"ask_ct":1},{"bid_px":"408.960000000","ask_px":"445.680000000","bid_sz":5,"ask_sz":3,"bid_ct":1,"ask_ct":1},{"bid_px":"407.600000000","ask_px":"448.000000000","bid_sz":16,"ask_sz":15,"bid_ct":1,"ask_ct":2},{"bid_px":"407.000000000","ask_px":"450.000000000","bid_sz":17,"ask_sz":10,"bid_ct":3,"ask_ct":1},{"bid_px":"406.350000000","ask_px":"468.000000000","bid_sz":82,"ask_sz":65,"bid_ct":2,"ask_ct":1},{"bid_px":"406.000000000","ask_px":"472.000000000","bid_sz":7,"ask_sz":6,"bid_ct":1,"ask_ct":1},{"bid_px":"405.000000000","ask_px":null,"bid_sz":15,"ask_sz":0,"bid_ct":2,"ask_ct":0}],"symbol":"MSFT"}
{"ts_recv":"2024-11-01T08:00:09.784828619Z","hd":{"ts_event":"2024-11-01T08:00:09.784663053Z","rtype":10,"publisher_id":2,"instrument_id":16244},"action":"C","side":"A","depth":0,"price":"250.720000000","size":100,"flags":130,"ts_in_delta":165566,"sequence":309442,"levels":[{"bid_px":"250.000000000","ask_px":"251.090000000","bid_sz":1,"ask_sz":50,"bid_ct":1,"ask_ct":1},{"bid_px":"249.970000000","ask_px":"252.400000000","bid_sz":50,"ask_sz":1000,"bid_ct":1,"ask_ct":1},{"bid_px":"249.930000000","ask_px":"253.650000000","bid_sz":10,"ask_sz":400,"bid_ct":1,"ask_ct":1},{"bid_px":"249.800000000","ask_px":"255.000000000","bid_sz":199,"ask_sz":85,"bid_ct":1,"ask_ct":2},{"bid_px":"249.770000000","ask_px":"260.000000000","bid_sz":50,"ask_sz":48,"bid_ct":1,"ask_ct":1},{"bid_px":"249.600000000","ask_px":"262.660000000","bid_sz":1000,"ask_sz":56,"bid_ct":1,"ask_ct":1},{"bid_px":"249.500000000","ask_px":"264.940000000","bid_sz":1000,"ask_sz":7,"bid_ct":1,"ask_ct":1},{"bid_px":"248.600000000","ask_px":"265.000000000","bid_sz":1000,"ask_sz":1,"bid_ct":1,"ask_ct":1},{"bid_px":"247.150000000","ask_px":"267.800000000","bid_sz":400,"ask_sz":30,"bid_ct":1,"ask_ct":1},{"bid_px":"247.000000000","ask_px":"268.670000000","bid_sz":12,"ask_sz":100,"bid_ct":1,"ask_ct":1}],"symbol":"TSLA"}
{"ts_recv":"2024-11-01T08:00:09.784842070Z","hd":{"ts_event":"2024-11-01T08:00:09.784676131Z","rtype":10,"publisher_id":2,"instrument_id":16244},"action":"A","side":"A","depth":0,"price":"250.740000000","size":100,"flags":130,"ts_in_delta":165939,"sequence":309443,"levels":[{"bid_px":"250.000000000","ask_px":"250.740000000","bid_sz":1,"ask_sz":100,"bid_ct":1,"ask_ct":1},{"bid_px":"249.970000000","ask_px":"251.090000000","bid_sz":50,"ask_sz":50,"bid_ct":1,"ask_ct":1},{"bid_px":"249.930000000","ask_px":"252.400000000","bid_sz":10,"ask_sz":1000,"bid_ct":1,"ask_ct":1},{"bid_px":"249.800000000","ask_px":"253.650000000","bid_sz":199,"ask_sz":400,"bid_ct":1,"ask_ct":1},{"bid_px":"249.770000000","ask_px":"255.000000000","bid_sz":50,"ask_sz":85,"bid_ct":1,"ask_ct":2},{"bid_px":"249.600000000","ask_px":"260.000000000","bid_sz":1000,"ask_sz":48,"bid_ct":1,"ask_ct":1},{"bid_px":"249.500000000","ask_px":"262.660000000","bid_sz":1000,"ask_sz":56,"bid_ct":1,"ask_ct":1},{"bid_px":"248.600000000","ask_px":"264.940000000","bid_sz":1000,"ask_sz":7,"bid_ct":1,"ask_ct":1},{"bid_px":"247.150000000","ask_px":"265.000000000","bid_sz":400,"ask_sz":1,"bid_ct":1,"ask_ct":1},{"bid_px":"247.000000000","ask_px":"267.800000000","bid_sz":12,"ask_sz":30,"bid_ct":1,"ask_ct":1}],"symbol":"TSLA"}
{"ts_recv":"2024-11-01T08:00:09.784885483Z","hd":{"ts_event":"2024-11-01T08:00:09.784719694Z","rtype":10,"publisher_id":2,"instrument_id":16244},"action":"C","side":"A","depth":0,"price":"250.740000000","size":100,"flags":130,"ts_in_delta":165789,"sequence":309444,"levels":[{"bid_px":"250.000000000","ask_px":"251.090000000","bid_sz":1,"ask_sz":50,"bid_ct":1,"ask_ct":1},{"bid_px":"249.970000000","ask_px":"252.400000000","bid_sz":50,"ask_sz":1000,"bid_ct":1,"ask_ct":1},{"bid_px":"249.930000000","ask_px":"253.650000000","bid_sz":10,"ask_sz":400,"bid_ct":1,"ask_ct":1},{"bid_px":"249.800000000","ask_px":"255.000000000","bid_sz":199,"ask_sz":85,"bid_ct":1,"ask_ct":2},{"bid_px":"249.770000000","ask_px":"260.000000000","bid_sz":50,"ask_sz":48,"bid_ct":1,"ask_ct":1},{"bid_px":"249.600000000","ask_px":"262.660000000","bid_sz":1000,"ask_sz":56,"bid_ct":1,"ask_ct":1},{"bid_px":"249.500000000","ask_px":"264.940000000","bid_sz":1000,"ask_sz":7,"bid_ct":1,"ask_ct":1},{"bid_px":"248.600000000","ask_px":"265.000000000","bid_sz":1000,"ask_sz":1,"bid_ct":1,"ask_ct":1},{"bid_px":"247.150000000","ask_px":"267.800000000","bid_sz":400,"ask_sz":30,"bid_ct":1,"ask_ct":1},{"bid_px":"247.000000000","ask_px":"268.670000000","bid_sz":12,"ask_sz":100,"bid_ct":1,"ask_ct":1}],"symbol":"TSLA"}
{"ts_recv":"2024-11-01T08:00:09.784946250Z","hd":{"ts_event":"2024-11-01T08:00:09.784779245Z","rtype":10,"publisher_id":2,"instrument_id":16244},"action":"A","side":"A","depth":0,"price":"250.800000000","size":100,"flags":130,"ts_in_delta":167005,"sequence":309445,"levels":[{"bid_px":"250.000000000","ask_px":"250.800000000","bid_sz":1,"ask_sz":100,"bid_ct":1,"ask_ct":1},{"bid_px":"249.970000000","ask_px":"251.090000000","bid_sz":50,"ask_sz":50,"bid_ct":1,"ask_ct":1},{"bid_px":"249.930000000","ask_px":"252.400000000","bid_sz":10,"ask_sz":1000,"bid_ct":1,"ask_ct":1},{"bid_px":"249.800000000","ask_px":"253.650000000","bid_sz":199,"ask_sz":400,"bid_ct":1,"ask_ct":1},{"bid_px":"249.770000000","ask_px":"255.000000000","bid_sz":50,"ask_sz":85,"bid_ct":1,"ask_ct":2},{"bid_px":"249.600000000","ask_px":"260.000000000","bid_sz":1000,"ask_sz":48,"bid_ct":1,"ask_ct":1},{"bid_px":"249.500000000","ask_px":"262.660000000","bid_sz":1000,"ask_sz":56,"bid_ct":1,"ask_ct":1},{"bid_px":"248.600000000","ask_px":"264.940000000","bid_sz":1000,"ask_sz":7,"bid_ct":1,"ask_ct":1},{"bid_px":"247.150000000","ask_px":"265.000000000","bid_sz":400,"ask_sz":1,"bid_ct":1,"ask_ct":1},{"bid_px":"247.000000000","ask_px":"267.800000000","bid_sz":12,"ask_sz":30,"bid_ct":1,"ask_ct":1}],"symbol":"TSLA"}
{"ts_recv":"2024-11-01T08:00:09.785109969Z","hd":{"ts_event":"2024-11-01T08:00:09.784944294Z","rtype":10,"publisher_id":2,"instrument_id":16244},"action":"C","side":"A","depth":0,"price":"250.800000000","size":100,"flags":130,"ts_in_delta":165675,"sequence":309446,"levels":[{"bid_px":"250.000000000","ask_px":"251.090000000","bid_sz":1,"ask_sz":50,"bid_ct":1,"ask_ct":1},{"bid_px":"249.970000000","ask_px":"252.400000000","bid_sz":50,"ask_sz":1000,"bid_ct":1,"ask_ct":1},{"bid_px":"249.930000000","ask_px":"253.650000000","bid_sz":10,"ask_sz":400,"bid_ct":1,"ask_ct":1},{"bid_px":"249.800000000","ask_px":"255.000000000","bid_sz":199,"ask_sz":85,"bid_ct":1,"ask_ct":2},{"bid_px":"249.770000000","ask_px":"260.000000000","bid_sz":50,"ask_sz":48,"bid_ct":1,"ask_ct":1},{"bid_px":"249.600000000","ask_px":"262.660000000","bid_sz":1000,"ask_sz":56,"bid_ct":1,"ask_ct":1},{"bid_px":"249.500000000","ask_px":"264.940000000","bid_sz":1000,"ask_sz":7,"bid_ct":1,"ask_ct":1},{"bid_px":"248.600000000","ask_px":"265.000000000","bid_sz":1000,"ask_sz":1,"bid_ct":1,"ask_ct":1},{"bid_px":"247.150000000","ask_px":"267.800000000","bid_sz":400,"ask_sz":30,"bid_ct":1,"ask_ct":1},{"bid_px":"247.000000000","ask_px":"268.670000000","bid_sz":12,"ask_sz":100,"bid_ct":1,"ask_ct":1}],"symbol":"TSLA"}
{"ts_recv":"2024-11-01T08:00:09.785121862Z","hd":{"ts_event":"2024-11-01T08:00:09.784955737Z","rtype":10,"publisher_id":2,"instrument_id":16244},"action":"A","side":"A","depth":0,"price":"251.010000000","size":100,"flags":130,"ts_in_delta":166125,"sequence":309447,"levels":[{"bid_px":"250.000000000","ask_px":"251.010000000","bid_sz":1,"ask_sz":100,"bid_ct":1,"ask_ct":1},{"bid_px":"249.970000000","ask_px":"251.090000000","bid_sz":50,"ask_sz":50,"bid_ct":1,"ask_ct":1},{"bid_px":"249.930000000","ask_px":"252.400000000","bid_sz":10,"ask_sz":1000,"bid_ct":1,"ask_ct":1},{"bid_px":"249.800000000","ask_px":"253.650000000","bid_sz":199,"ask_sz":400,"bid_ct":1,"ask_ct":1},{"bid_px":"249.770000000","ask_px":"255.000000000","bid_sz":50,"ask_sz":85,"bid_ct":1,"ask_ct":2},{"bid_px":"249.600000000","ask_px":"260.000000000","bid_sz":1000,"ask_sz":48,"bid_ct":1,"ask_ct":1},{"bid_px":"249.500000000","ask_px":"262.660000000","bid_sz":1000,"ask_sz":56,"bid_ct":1,"ask_ct":1},{"bid_px":"248.600000000","ask_px":"264.940000000","bid_sz":1000,"ask_sz":7,"bid_ct":1,"ask_ct":1},{"bid_px":"247.150000000","ask_px":"265.000000000","bid_sz":400,"ask_sz":1,"bid_ct":1,"ask_ct":1},{"bid_px":"247.000000000","ask_px":"267.800000000","bid_sz":12,"ask_sz":30,"bid_ct":1,"ask_ct":1}],"symbol":"TSLA"}
{"ts_recv":"2024-11-01T08:00:09.786503869Z","hd":{"ts_event":"2024-11-01T08:00:09.786337768Z","rtype":10,"publisher_id":2,"instrument_id":16244},"action":"C","side":"A","depth":0,"price":"251.010000000","size":100,"flags":130,"ts_in_delta":166101,"sequence":309452,"levels":[{"bid_px":"250.000000000","ask_px":"251.090000000","bid_sz":1,"ask_sz":50,"bid_ct":1,"ask_ct":1},{"bid_px":"249.970000000","ask_px":"252.400000000","bid_sz":50,"ask_sz":1000,"bid_ct":1,"ask_ct":1},{"bid_px":"249.930000000","ask_px":"253.650000000","bid_sz":10,"ask_sz":400,"bid_ct":1,"ask_ct":1},{"bid_px":"249.800000000","ask_px":"255.000000000","bid_sz":199,"ask_sz":85,"bid_ct":1,"ask_ct":2},{"bid_px":"249.770000000","ask_px":"260.000000000","bid_sz":50,"ask_sz":48,"bid_ct":1,"ask_ct":1},{"bid_px":"249.600000000","ask_px":"262.660000000","bid_sz":1000,"ask_sz":56,"bid_ct":1,"ask_ct":1},{"bid_px":"249.500000000","ask_px":"264.940000000","bid_sz":1000,"ask_sz":7,"bid_ct":1,"ask_ct":1},{"bid_px":"248.600000000","ask_px":"265.000000000","bid_sz":1000,"ask_sz":1,"bid_ct":1,"ask_ct":1},{"bid_px":"247.150000000","ask_px":"267.800000000","bid_sz":400,"ask_sz":30,"bid_ct":1,"ask_ct":1},{"bid_px":"247.000000000","ask_px":"268.670000000","bid_sz":12,"ask_sz":100,"bid_ct":1,"ask_ct":1}],"symbol":"TSLA"}
{"ts_recv":"2024-11-01T08:00:09.786515173Z","hd":{"ts_event":"2024-11-01T08:00:09.786349334Z","rtype":10,"publisher_id":2,"instrument_id":16244},"action":"A","side":"A","depth":0,"price":"251.030000000","size":100,"flags":130,"ts_in_delta":165839,"sequence":309453,"levels":[{"bid_px":"250.000000000","ask_px":"251.030000000","bid_sz":1,"ask_sz":100,"bid_ct":1,"ask_ct":1},{"bid_px":"249.970000000","ask_px":"251.090000000","bid_sz":50,"ask_sz":50,"bid_ct":1,"ask_ct":1},{"bid_px":"249.930000000","ask_px":"252.400000000","bid_sz":10,"ask_sz":1000,"bid_ct":1,"ask_ct":1},{"bid_px":"249.800000000","ask_px":"253.650000000","bid_sz":199,"ask_sz":400,"bid_ct":1,"ask_ct":1},{"bid_px":"249.770000000","ask_px":"255.000000000","bid_sz":50,"ask_sz":85,"bid_ct":1,"ask_ct":2},{"bid_px":"249.600000000","ask_px":"260.000000000","bid_sz":1000,"ask_sz":48,"bid_ct":1,"ask_ct":1},{"bid_px":"249.500000000","ask_px":"262.660000000","bid_sz":1000,"ask_sz":56,"bid_ct":1,"ask_ct":1},{"bid_px":"248.600000000","ask_px":"264.940000000","bid_sz":1000,"ask_sz":7,"bid_ct":1,"ask_ct":1},{"bid_px":"247.150000000","ask_px":"265.000000000","bid_sz":400,"ask_sz":1,"bid_ct":1,"ask_ct":1},{"bid_px":"247.000000000","ask_px":"267.800000000","bid_sz":12,"ask_sz":30,"bid_ct":1,"ask_ct":1}],"symbol":"TSLA"}
{"ts_recv":"2024-11-01T08:00:09.786563838Z","hd":{"ts_event":"2024-11-01T08:00:09.786398263Z","rtype":10,"publisher_id":2,"instrument_id":16244},"action":"C","side":"A","depth":0,"price":"251.030000000","size":100,"flags":130,"ts_in_delta":165575,"sequence":309455,"levels":[{"bid_px":"250.000000000","ask_px":"251.090000000","bid_sz":1,"ask_sz":50,"bid_ct":1,"ask_ct":1},{"bid_px":"249.970000000","ask_px":"252.400000000","bid_sz":50,"ask_sz":1000,"bid_ct":1,"ask_ct":1},{"bid_px":"249.930000000","ask_px":"253.650000000","bid_sz":10,"ask_sz":400,"bid_ct":1,"ask_ct":1},{"bid_px":"249.800000000","ask_px":"255.000000000","bid_sz":199,"ask_sz":85,"bid_ct":1,"ask_ct":2},{"bid_px":"249.770000000","ask_px":"260.000000000","bid_sz":50,"ask_sz":48,"bid_ct":1,"ask_ct":1},{"bid_px":"249.600000000","ask_px":"262.660000000","bid_sz":1000,"ask_sz":56,"bid_ct":1,"ask_ct":1},{"bid_px":"249.500000000","ask_px":"264.940000000","bid_sz":1000,"ask_sz":7,"bid_ct":1,"ask_ct":1},{"bid_px":"248.600000000","ask_px":"265.000000000","bid_sz":1000,"ask_sz":1,"bid_ct":1,"ask_ct":1},{"bid_px":"247.150000000","ask_px":"267.800000000","bid_sz":400,"ask_sz":30,"bid_ct":1,"ask_ct":1},{"bid_px":"247.000000000","ask_px":"268.670000000","bid_sz":12,"ask_sz":100,"bid_ct":1,"ask_ct":1}],"symbol":"TSLA"}
{"ts_recv":"2024-11-01T08:00:09.786625105Z","hd":{"ts_event":"2024-11-01T08:00:09.786459035Z","rtype":10,"publisher_id":2,"instrument_id":16244},"action":"A","side":"A","depth":0,"price":"251.050000000","size":100,"flags":130,"ts_in_delta":166070,"sequence":309456,"levels":[{"bid_px":"250.000000000","ask_px":"251.050000000","bid_sz":1,"ask_sz":100,"bid_ct":1,"ask_ct":1},{"bid_px":"249.970000000","ask_px":"251.090000000","bid_sz":50,"ask_sz":50,"bid_ct":1,"ask_ct":1},{"bid_px":"249.930000000","ask_px":"252.400000000","bid_sz":10,"ask_sz":1000,"bid_ct":1,"ask_ct":1},{"bid_px":"249.800000000","ask_px":"253.650000000","bid_sz":199,"ask_sz":400,"bid_ct":1,"ask_ct":1},{"bid_px":"249.770000000","ask_px":"255.000000000","bid_sz":50,"ask_sz":85,"bid_ct":1,"ask_ct":2},{"bid_px":"249.600000000","ask_px":"260.000000000","bid_sz":1000,"ask_sz":48,"bid_ct":1,"ask_ct":1},{"bid_px":"249.500000000","ask_px":"262.660000000","bid_sz":1000,"ask_sz":56,"bid_ct":1,"ask_ct":1},{"bid_px":"248.600000000","ask_px":"264.940000000","bid_sz":1000,"ask_sz":7,"bid_ct":1,"ask_ct":1},{"bid_px":"247.150000000","ask_px":"265.000000000","bid_sz":400,"ask_sz":1,"bid_ct":1,"ask_ct":1},{"bid_px":"247.000000000","ask_px":"267.800000000","bid_sz":12,"ask_sz":30,"bid_ct":1,"ask_ct":1}],"symbol":"TSLA"}
{"ts_recv":"2024-11-01T08:00:09.786809862Z","hd":{"ts_event":"2024-11-01T08:00:09.786643807Z","rtype":10,"publisher_id":2,"instrument_id":16244},"action":"C","side":"A","depth":0,"price":"251.050000000","size":100,"flags":130,"ts_in_delta":166055,"sequence":309457,"levels":[{"bid_px":"250.000000000","ask_px":"251.090000000","bid_sz":1,"ask_sz":50,"bid_ct":1,"ask_ct":1},{"bid_px":"249.970000000","ask_px":"252.400000000","bid_sz":50,"ask_sz":1000,"bid_ct":1,"ask_ct":1},{"bid_px":"249.930000000","ask_px":"253.650000000","bid_sz":10,"ask_sz":400,"bid_ct":1,"ask_ct":1},{"bid_px":"249.800000000","ask_px":"255.000000000","bid_sz":199,"ask_sz":85,"bid_ct":1,"ask_ct":2},{"bid_px":"249.770000000","ask_px":"260.000000000","bid_sz":50,"ask_sz":48,"bid_ct":1,"ask_ct":1},{"bid_px":"249.600000000","ask_px":"262.660000000","bid_sz":1000,"ask_sz":56,"bid_ct":1,"ask_ct":1},{"bid_px":"249.500000000","ask_px":"264.940000000","bid_sz":1000,"ask_sz":7,"bid_ct":1,"ask_ct":1},{"bid_px":"248.600000000","ask_px":"265.000000000","bid_sz":1000,"ask_sz":1,"bid_ct":1,"ask_ct":1},{"bid_px":"247.150000000","ask_px":"267.800000000","bid_sz":400,"ask_sz":30,"bid_ct":1,"ask_ct":1},{"bid_px":"247.000000000","ask_px":"268.670000000","bid_sz":12,"ask_sz":100,"bid_ct":1,"ask_ct":1}],"symbol":"TSLA"}
{"ts_recv":"2024-11-01T08:00:09.786821100Z","hd":{"ts_event":"2024-11-01T08:00:09.786654970Z","rtype":10,"publisher_id":2,"instrument_id":16244},"action":"A","side":"A","depth":0,"price":"251.070000000","size":100,"flags":130,"ts_in_delta":166130,"sequence":309458,"levels":[{"bid_px":"250.000000000","ask_px":"251.070000000","bid_sz":1,"ask_sz":100,"bid_ct":1,"ask_ct":1},{"bid_px":"249.970000000","ask_px":"251.090000000","bid_sz":50,"ask_sz":50,"bid_ct":1,"ask_ct":1},{"bid_px":"249.930000000","ask_px":"252.400000000","bid_sz":10,"ask_sz":1000,"bid_ct":1,"ask_ct":1},{"bid_px":"249.800000000","ask_px":"253.650000000","bid_sz":199,"ask_sz":400,"bid_ct":1,"ask_ct":1},{"bid_px":"249.770000000","ask_px":"255.000000000","bid_sz":50,"ask_sz":85,"bid_ct":1,"ask_ct":2},{"bid_px":"249.600000000","ask_px":"260.000000000","bid_sz":1000,"ask_sz":48,"bid_ct":1,"ask_ct":1},{"bid_px":"249.500000000","ask_px":"262.660000000","bid_sz":1000,"ask_sz":56,"bid_ct":1,"ask_ct":1},{"bid_px":"248.600000000","ask_px":"264.940000000","bid_sz":1000,"ask_sz":7,"bid_ct":1,"ask_ct":1},{"bid_px":"247.150000000","ask_px":"265.000000000","bid_sz":400,"ask_sz":1,"bid_ct":1,"ask_ct":1},{"bid_px":"247.000000000","ask_px":"267.800000000","bid_sz":12,"ask_sz":30,"bid_ct":1,"ask_ct":1}],"symbol":"TSLA"}
{"ts_recv":"2024-11-01T08:00:09.788788085Z","hd":{"ts_event":"2024-11-01T08:00:09.788621861Z","rtype":10,"publisher_id":2,"instrument_id":16244},"action":"C","side":"B","depth":1,"price":"249.970000000","size":50,"flags":130,"ts_in_delta":166224,"sequence":309459,"levels":[{"bid_px":"250.000000000","ask_px":"251.070000000","bid_sz":1,"ask_sz":100,"bid_ct":1,"ask_ct":1},{"bid_px":"249.930000000","ask_px":"251.090000000","bid_sz":10,"ask_sz":50,"bid_ct":1,"ask_ct":1},{"bid_px":"249.800000000","ask_px":"252.400000000","bid_sz":199,"ask_sz":1000,"bid_ct":1,"ask_ct":1},{"bid_px":"249.770000000","ask_px":"253.650000000","bid_sz":50,"ask_sz":400,"bid_ct":1,"ask_ct":1},{"bid_px":"249.600000000","ask_px":"255.000000000","bid_sz":1000,"ask_sz":85,"bid_ct":1,"ask_ct":2},{"bid_px":"249.500000000","ask_px":"260.000000000","bid_sz":1000,"ask_sz":48,"bid_ct":1,"ask_ct":1},{"bid_px":"248.600000000","ask_px":"262.660000000","bid_sz":1000,"ask_sz":56,"bid_ct":1,"ask_ct":1},{"bid_px":"247.150000000","ask_px":"264.940000000","bid_sz":400,"ask_sz":7,"bid_ct":1,"ask_ct":1},{"bid_px":"247.000000000","ask_px":"265.000000000","bid_sz":12,"ask_sz":1,"bid_ct":1,"ask_ct":1},{"bid_px":"246.000000000","ask_px":"267.800000000","bid_sz":4,"ask_sz":30,"bid_ct":1,"ask_ct":1}],"symbol":"TSLA"}
{"ts_recv":"2024-11-01T08:00:09.789806388Z","hd":{"ts_event":"2024-11-01T08:00:09.789640391Z","rtype":10,"publisher_id":2,"instrument_id":16244},"action":"A","side":"A","depth":0,"price":"251.070000000","size":100,"flags":130,"ts_in_delta":165997,"sequence":309463,"levels":[{"bid_px":"250.000000000","ask_px":"251.070000000","bid_sz":1,"ask_sz":200,"bid_ct":1,"ask_ct":2},{"bid_px":"249.930000000","ask_px":"251.090000000","bid_sz":10,"ask_sz":50,"bid_ct":1,"ask_ct":1},{"bid_px":"249.800000000","ask_px":"252.400000000","bid_sz":199,"ask_sz":1000,"bid_ct":1,"ask_ct":1},{"bid_px":"249.770000000","ask_px":"253.650000000","bid_sz":50,"ask_sz":400,"bid_ct":1,"ask_ct":1},{"bid_px":"249.600000000","ask_px":"255.000000000","bid_sz":1000,"ask_sz":85,"bid_ct":1,"ask_ct":2},{"bid_px":"249.500000000","ask_px":"260.000000000","bid_sz":1000,"ask_sz":48,"bid_ct":1,"ask_ct":1},{"bid_px":"248.600000000","ask_px":"262.660000000","bid_sz":1000,"ask_sz":56,"bid_ct":1,"ask_ct":1},{"bid_px":"247.150000000","ask_px":"264.940000000","bid_sz":400,"ask_sz":7,"bid_ct":1,"ask_ct":1},{"bid_px":"247.000000000","ask_px":"265.000000000","bid_sz":12,"ask_sz":1,"bid_ct":1,"ask_ct":1},{"bid_px":"246.000000000","ask_px":"267.800000000","bid_sz":4,"ask_sz":30,"bid_ct":1,"ask_ct":1}],"symbol":"TSLA"}
{"ts_recv":"2024-11-01T08:00:09.801041263Z","hd":{"ts_event":"2024-11-01T08:00:09.800874905Z","rtype":10,"publisher_id":2,"instrument_id":16244},"action":"A","side":"B","depth":0,"price":"250.000000000","size":1,"flags":130,"ts_in_delta":166358,"sequence":309488,"levels":[{"bid_px":"250.000000000","ask_px":"251.070000000","bid_sz":2,"ask_sz":200,"bid_ct":2,"ask_ct":2},{"bid_px":"249.930000000","ask_px":"251.090000000","bid_sz":10,"ask_sz":50,"bid_ct":1,"ask_ct":1},{"bid_px":"249.800000000","ask_px":"252.400000000","bid_sz":199,"ask_sz":1000,"bid_ct":1,"ask_ct":1},{"bid_px":"249.770000000","ask_px":"253.650000000","bid_sz":50,"ask_sz":400,"bid_ct":1,"ask_ct":1},{"bid_px":"249.600000000","ask_px":"255.000000000","bid_sz":1000,"ask_sz":85,"bid_ct":1,"ask_ct":2},{"bid_px":"249.500000000","ask_px":"260.000000000","bid_sz":1000,"ask_sz":48,"bid_ct":1,"ask_ct":1},{"bid_px":"248.600000000","ask_px":"262.660000000","bid_sz":1000,"ask_sz":56,"bid_ct":1,"ask_ct":1},{"bid_px":"247.150000000","ask_px":"264.940000000","bid_sz":400,"ask_sz":7,"bid_ct":1,"ask_ct":1},{"bid_px":"247.000000000","ask_px":"265.000000000","bid_sz":12,"ask_sz":1,"bid_ct":1,"ask_ct":1},{"bid_px":"246.000000000","ask_px":"267.800000000","bid_sz":4,"ask_sz":30,"bid_ct":1,"ask_ct":1}],"symbol":"TSLA"}
{"ts_recv":"2024-11-01T08:00:09.844640477Z","hd":{"ts_event":"2024-11-01T08:00:09.844474368Z","rtype":10,"publisher_id":2,"instrument_id":16244},"action":"C","side":"A","depth":1,"price":"251.090000000","size":50,"flags":130,"ts_in_delta":166109,"sequence":309590,"levels":[{"bid_px":"250.000000000","ask_px":"251.070000000","bid_sz":2,"ask_sz":200,"bid_ct":2,"ask_ct":2},{"bid_px":"249.930000000","ask_px":"252.400000000","bid_sz":10,"ask_sz":1000,"bid_ct":1,"ask_ct":1},{"bid_px":"249.800000000","ask_px":"253.650000000","bid_sz":199,"ask_sz":400,"bid_ct":1,"ask_ct":1},{"bid_px":"249.770000000","ask_px":"255.000000000","bid_sz":50,"ask_sz":85,"bid_ct":1,"ask_ct":2},{"bid_px":"249.600000000","ask_px":"260.000000000","bid_sz":1000,"ask_sz":48,"bid_ct":1,"ask_ct":1},{"bid_px":"249.500000000","ask_px":"262.660000000","bid_sz":1000,"ask_sz":56,"bid_ct":1,"ask_ct":1},{"bid_px":"248.600000000","ask_px":"264.940000000","bid_sz":1000,"ask_sz":7,"bid_ct":1,"ask_ct":1},{"bid_px":"247.150000000","ask_px":"265.000000000","bid_sz":400,"ask_sz":1,"bid_ct":1,"ask_ct":1},{"bid_px":"247.000000000","ask_px":"267.800000000","bid_sz":12,"ask_sz":30,"bid_ct":1,"ask_ct":1},{"bid_px":"246.000000000","ask_px":"268.670000000","bid_sz":4,"ask_sz":100,"bid_ct":1,"ask_ct":1}],"symbol":"TSLA"}
{"ts_recv":"2024-11-01T08:00:09.844701754Z","hd":{"ts_event":"2024-11-01T08:00:09.844532194Z","rtype":10,"publisher_id":2,"instrument_id":16244},"action":"A","side":"B","depth":1,"price":"249.970000000","size":50,"flags":130,"ts_in_delta":169560,"sequence":309591,"levels":[{"bid_px":"250.000000000","ask_px":"251.070000000","bid_sz":2,"ask_sz":200,"bid_ct":2,"ask_ct":2},{"bid_px":"249.970000000","ask_px":"252.400000000","bid_sz":50,"ask_sz":1000,"bid_ct":1,"ask_ct":1},{"bid_px":"249.930000000","ask_px":"253.650000000","bid_sz":10,"ask_sz":400,"bid_ct":1,"ask_ct":1},{"bid_px":"249.800000000","ask_px":"255.000000000","bid_sz":199,"ask_sz":85,"bid_ct":1,"ask_ct":2},{"bid_px":"249.770000000","ask_px":"260.000000000","bid_sz":50,"ask_sz":48,"bid_ct":1,"ask_ct":1},{"bid_px":"249.600000000","ask_px":"262.660000000","bid_sz":1000,"ask_sz":56,"bid_ct":1,"ask_ct":1},{"bid_px":"249.500000000","ask_px":"264.940000000","bid_sz":1000,"ask_sz":7,"bid_ct":1,"ask_ct":1},{"bid_px":"248.600000000","ask_px":"265.000000000","bid_sz":1000,"ask_sz":1,"bid_ct":1,"ask_ct":1},{"bid_px":"247.150000000","ask_px":"267.800000000","bid_sz":400,"ask_sz":30,"bid_ct":1,"ask_ct":1},{"bid_px":"247.000000000","ask_px":"268.670000000","bid_sz":12,"ask_sz":100,"bid_ct":1,"ask_ct":1}],"symbol":"TSLA"}
{"ts_recv":"2024-11-01T08:00:09.844728634Z","hd":{"ts_event":"2024-11-01T08:00:09.844562361Z","rtype":10,"publisher_id":2,"instrument_id":16244},"action":"A","side":"A","depth":1,"price":"251.150000000","size":50,"flags":130,"ts_in_delta":166273,"sequence":309592,"levels":[{"bid_px":"250.000000000","ask_px":"251.070000000","bid_sz":2,"ask_sz":200,"bid_ct":2,"ask_ct":2},{"bid_px":"249.970000000","ask_px":"251.150000000","bid_sz":50,"ask_sz":50,"bid_ct":1,"ask_ct":1},{"bid_px":"249.930000000","ask_px":"252.400000000","bid_sz":10,"ask_sz":1000,"bid_ct":1,"ask_ct":1},{"bid_px":"249.800000000","ask_px":"253.650000000","bid_sz":199,"ask_sz":400,"bid_ct":1,"ask_ct":1},{"bid_px":"249.770000000","ask_px":"255.000000000","bid_sz":50,"ask_sz":85,"bid_ct":1,"ask_ct":2},{"bid_px":"249.600000000","ask_px":"260.000000000","bid_sz":1000,"ask_sz":48,"bid_ct":1,"ask_ct":1},{"bid_px":"249.500000000","ask_px":"262.660000000","bid_sz":1000,"ask_sz":56,"bid_ct":1,"ask_ct":1},{"bid_px":"248.600000000","ask_px":"264.940000000","bid_sz":1000,"ask_sz":7,"bid_ct":1,"ask_ct":1},{"bid_px":"247.150000000","ask_px":"265.000000000","bid_sz":400,"ask_sz":1,"bid_ct":1,"ask_ct":1},{"bid_px":"247.000000000","ask_px":"267.800000000","bid_sz":12,"ask_sz":30,"bid_ct":1,"ask_ct":1}],"symbol":"TSLA"}
{"ts_recv":"2024-11-01T08:00:09.848533907Z","hd":{"ts_event":"2024-11-01T08:00:09.848366265Z","rtype":10,"publisher_id":2,"instrument_id":16244},"action":"A","side":"A","depth":1,"price":"251.150000000","size":50,"flags":130,"ts_in_delta":167642,"sequence":309595,"levels":[{"bid_px":"250.000000000","ask_px":"251.070000000","bid_sz":2,"ask_sz":200,"bid_ct":2,"ask_ct":2},{"bid_px":"249.970000000","ask_px":"251.150000000","bid_sz":50,"ask_sz":100,"bid_ct":1,"ask_ct":2},{"bid_px":"249.930000000","ask_px":"252.400000000","bid_sz":10,"ask_sz":1000,"bid_ct":1,"ask_ct":1},{"bid_px":"249.800000000","ask_px":"253.650000000","bid_sz":199,"ask_sz":400,"bid_ct":1,"ask_ct":1},{"bid_px":"249.770000000","ask_px":"255.000000000","bid_sz":50,"ask_sz":85,"bid_ct":1,"ask_ct":2},{"bid_px":"249.600000000","ask_px":"260.000000000","bid_sz":1000,"ask_sz":48,"bid_ct":1,"ask_ct":1},{"bid_px":"249.500000000","ask_px":"262.660000000","bid_sz":1000,"ask_sz":56,"bid_ct":1,"ask_ct":1},{"bid_px":"248.600000000","ask_px":"264.940000000","bid_sz":1000,"ask_sz":7,"bid_ct":1,"ask_ct":1},{"bid_px":"247.150000000","ask_px":"265.000000000","bid_sz":400,"ask_sz":1,"bid_ct":1,"ask_ct":1},{"bid_px":"247.000000000","ask_px":"267.800000000","bid_sz":12,"ask_sz":30,"bid_ct":1,"ask_ct":1}],"symbol":"TSLA"}
{"ts_recv":"2024-11-01T08:00:09.848579974Z","hd":{"ts_event":"2024-11-01T08:00:09.848414050Z","rtype":10,"publisher_id":2,"instrument_id":16244},"action":"C","side":"B","depth":1,"price":"249.970000000","size":50,"flags":130,"ts_in_delta":165924,"sequence":309596,"levels":[{"bid_px":"250.000000000","ask_px":"251.070000000","bid_sz":2,"ask_sz":200,"bid_ct":2,"ask_ct":2},{"bid_px":"249.930000000","ask_px":"251.150000000","bid_sz":10,"ask_sz":100,"bid_ct":1,"ask_ct":2},{"bid_px":"249.800000000","ask_px":"252.400000000","bid_sz":199,"ask_sz":1000,"bid_ct":1,"ask_ct":1},{"bid_px":"249.770000000","ask_px":"253.650000000","bid_sz":50,"ask_sz":400,"bid_ct":1,"ask_ct":1},{"bid_px":"249.600000000","ask_px":"255.000000000","bid_sz":1000,"ask_sz":85,"bid_ct":1,"ask_ct":2},{"bid_px":"249.500000000","ask_px":"260.000000000","bid_sz":1000,"ask_sz":48,"bid_ct":1,"ask_ct":1},{"bid_px":"248.600000000","ask_px":"262.660000000","bid_sz":1000,"ask_sz":56,"bid_ct":1,"ask_ct":1},{"bid_px":"247.150000000","ask_px":"264.940000000","bid_sz":400,"ask_sz":7,"bid_ct":1,"ask_ct":1},{"bid_px":"247.000000000","ask_px":"265.000000000","bid_sz":12,"ask_sz":1,"bid_ct":1,"ask_ct":1},{"bid_px":"246.000000000","ask_px":"267.800000000","bid_sz":4,"ask_sz":30,"bid_ct":1,"ask_ct":1}],"symbol":"TSLA"}
{"ts_recv":"2024-11-01T08:00:09.855243663Z","hd":{"ts_event":"2024-11-01T08:00:09.855077638Z","rtype":10,"publisher_id":2,"instrument_id":16244},"action":"C","side":"A","depth":0,"price":"251.070000000","size":100,"flags":130,"ts_in_delta":166025,"sequence":309599,"levels":[{"bid_px":"250.000000000","ask_px":"251.070000000","bid_sz":2,"ask_sz":100,"bid_ct":2,"ask_ct":1},{"bid_px":"249.930000000","ask_px":"251.150000000","bid_sz":10,"ask_sz":100,"bid_ct":1,"ask_ct":2},{"bid_px":"249.800000000","ask_px":"252.400000000","bid_sz":199,"ask_sz":1000,"bid_ct":1,"ask_ct":1},{"bid_px":"249.770000000","ask_px":"253.650000000","bid_sz":50,"ask_sz":400,"bid_ct":1,"ask_ct":1},{"bid_px":"249.600000000","ask_px":"255.000000000","bid_sz":1000,"ask_sz":85,"bid_ct":1,"ask_ct":2},{"bid_px":"249.500000000","ask_px":"260.000000000","bid_sz":1000,"ask_sz":48,"bid_ct":1,"ask_ct":1},{"bid_px":"248.600000000","ask_px":"262.660000000","bid_sz":1000,"ask_sz":56,"bid_ct":1,"ask_ct":1},{"bid_px":"247.150000000","ask_px":"264.940000000","bid_sz":400,"ask_sz":7,"bid_ct":1,"ask_ct":1},{"bid_px":"247.000000000","ask_px":"265.000000000","bid_sz":12,"ask_sz":1,"bid_ct":1,"ask_ct":1},{"bid_px":"246.000000000","ask_px":"267.800000000","bid_sz":4,"ask_sz":30,"bid_ct":1,"ask_ct":1}],"symbol":"TSLA"}
{"ts_recv":"2024-11-01T08:00:09.855256729Z","hd":{"ts_event":"2024-11-01T08:00:09.855090665Z","rtype":10,"publisher_id":2,"instrument_id":16244},"action":"A","side":"A","depth":0,"price":"250.940000000","size":100,"flags":130,"ts_in_delta":166064,"sequence":309600,"levels":[{"bid_px":"250.000000000","ask_px":"250.940000000","bid_sz":2,"ask_sz":100,"bid_ct":2,"ask_ct":1},{"bid_px":"249.930000000","ask_px":"251.150000000","bid_sz":10,"ask_sz":100,"bid_ct":1,"ask_ct":2},{"bid_px":"249.800000000","ask_px":"252.400000000","bid_sz":199,"ask_sz":1000,"bid_ct":1,"ask_ct":1},{"bid_px":"249.770000000","ask_px":"253.650000000","bid_sz":50,"ask_sz":400,"bid_ct":1,"ask_ct":1},{"bid_px":"249.600000000","ask_px":"255.000000000","bid_sz":1000,"ask_sz":85,"bid_ct":1,"ask_ct":2},{"bid_px":"249.500000000","ask_px":"260.000000000","bid_sz":1000,"ask_sz":48,"bid_ct":1,"ask_ct":1},{"bid_px":"248.600000000","ask_px":"262.660000000","bid_sz":1000,"ask_sz":56,"bid_ct":1,"ask_ct":1},{"bid_px":"247.150000000","ask_px":"264.940000000","bid_sz":400,"ask_sz":7,"bid_ct":1,"ask_ct":1},{"bid_px":"247.000000000","ask_px":"265.000000000","bid_sz":12,"ask_sz":1,"bid_ct":1,"ask_ct":1},{"bid_px":"246.000000000","ask_px":"267.800000000","bid_sz":4,"ask_sz":30,"bid_ct":1,"ask_ct":1}],"symbol":"TSLA"}
{"ts_recv":"2024-11-01T08:00:09.891408749Z","hd":{"ts_event":"2024-11-01T08:00:09.891242517Z","rtype":10,"publisher_id":2,"instrument_id":16244},"action":"A","side":"B","depth":2,"price":"249.920000000","size":50,"flags":130,"ts_in_delta":166232,"sequence":309785,"levels":[{"bid_px":"250.000000000","ask_px":"250.940000000","bid_sz":2,"ask_sz":100,"bid_ct":2,"ask_ct":1},{"bid_px":"249.930000000","ask_px":"251.150000000","bid_sz":10,"ask_sz":100,"bid_ct":1,"ask_ct":2},{"bid_px":"249.920000000","ask_px":"252.400000000","bid_sz":50,"ask_sz":1000,"bid_ct":1,"ask_ct":1},{"bid_px":"249.800000000","ask_px":"253.650000000","bid_sz":199,"ask_sz":400,"bid_ct":1,"ask_ct":1},{"bid_px":"249.770000000","ask_px":"255.000000000","bid_sz":50,"ask_sz":85,"bid_ct":1,"ask_ct":2},{"bid_px":"249.600000000","ask_px":"260.000000000","bid_sz":1000,"ask_sz":48,"bid_ct":1,"ask_ct":1},{"bid_px":"249.500000000","ask_px":"262.660000000","bid_sz":1000,"ask_sz":56,"bid_ct":1,"ask_ct":1},{"bid_px":"248.600000000","ask_px":"264.940000000","bid_sz":1000,"ask_sz":7,"bid_ct":1,"ask_ct":1},{"bid_px":"247.150000000","ask_px":"265.000000000","bid_sz":400,"ask_sz":1,"bid_ct":1,"ask_ct":1},{"bid_px":"247.000000000","ask_px":"267.800000000","bid_sz":12,"ask_sz":30,"bid_ct":1,"ask_ct":1}],"symbol":"TSLA"}
{"ts_recv":"2024-11-01T08:00:09.900875098Z","hd":{"ts_event":"2024-11-01T08:00:09.900709507Z","rtype":10,"publisher_id":2,"instrument_id":16244},"action":"C","side":"A","depth":1,"price":"251.150000000","size":50,"flags":130,"ts_in_delta":165591,"sequence":309911,"levels":[{"bid_px":"250.000000000","ask_px":"250.940000000","bid_sz":2,"ask_sz":100,"bid_ct":2,"ask_ct":1},{"bid_px":"249.930000000","ask_px":"251.150000000","bid_sz":10,"ask_sz":50,"bid_ct":1,"ask_ct":1},{"bid_px":"249.920000000","ask_px":"252.400000000","bid_sz":50,"ask_sz":1000,"bid_ct":1,"ask_ct":1},{"bid_px":"249.800000000","ask_px":"253.650000000","bid_sz":199,"ask_sz":400,"bid_ct":1,"ask_ct":1},{"bid_px":"249.770000000","ask_px":"255.000000000","bid_sz":50,"ask_sz":85,"bid_ct":1,"ask_ct":2},{"bid_px":"249.600000000","ask_px":"260.000000000","bid_sz":1000,"ask_sz":48,"bid_ct":1,"ask_ct":1},{"bid_px":"249.500000000","ask_px":"262.660000000","bid_sz":1000,"ask_sz":56,"bid_ct":1,"ask_ct":1},{"bid_px":"248.600000000","ask_px":"264.940000000","bid_sz":1000,"ask_sz":7,"bid_ct":1,"ask_ct":1},{"bid_px":"247.150000000","ask_px":"265.000000000","bid_sz":400,"ask_sz":1,"bid_ct":1,"ask_ct":1},{"bid_px":"247.000000000","ask_px":"267.800000000","bid_sz":12,"ask_sz":30,"bid_ct":1,"ask_ct":1}],"symbol":"TSLA"}
{"ts_recv":"2024-11-01T08:00:09.900889623Z","hd":{"ts_event":"2024-11-01T08:00:09.900723380Z","rtype":10,"publisher_id":2,"instrument_id":16244},"action":"A","side":"A","depth":1,"price":"251.090000000","size":50,"flags":130,"ts_in_delta":166243,"sequence":309912,"levels":[{"bid_px":"250.000000000","ask_px":"250.940000000","bid_sz":2,"ask_sz":100,"bid_ct":2,"ask_ct":1},{"bid_px":"249.930000000","ask_px":"251.090000000","bid_sz":10,"ask_sz":50,"bid_ct":1,"ask_ct":1},{"bid_px":"249.920000000","ask_px":"252.400000000","bid_sz":50,"ask_sz":1000,"bid_ct":1,"ask_ct":1},{"bid_px":"249.800000000","ask_px":"253.650000000","bid_sz":199,"ask_sz":400,"bid_ct":1,"ask_ct":1},{"bid_px":"249.770000000","ask_px":"255.000000000","bid_sz":50,"ask_sz":85,"bid_ct":1,"ask_ct":2},{"bid_px":"249.600000000","ask_px":"260.000000000","bid_sz":1000,"ask_sz":48,"bid_ct":1,"ask_ct":1},{"bid_px":"249.500000000","ask_px":"262.660000000","bid_sz":1000,"ask_sz":56,"bid_ct":1,"ask_ct":1},{"bid_px":"248.600000000","ask_px":"264.940000000","bid_sz":1000,"ask_sz":7,"bid_ct":1,"ask_ct":1},{"bid_px":"247.150000000","ask_px":"265.000000000","bid_sz":400,"ask_sz":1,"bid_ct":1,"ask_ct":1},{"bid_px":"247.000000000","ask_px":"267.800000000","bid_sz":12,"ask_sz":30,"bid_ct":1,"ask_ct":1}],"symbol":"TSLA"}
{"ts_recv":"2024-11-01T08:00:09.932269707Z","hd":{"ts_event":"2024-11-01T08:00:09.932103494Z","rtype":10,"publisher_id":2,"instrument_id":16244},"action":"A","side":"B","depth":8,"price":"248.500000000","size":40,"flags":130,"ts_in_delta":166213,"sequence":310073,"levels":[{"bid_px":"250.000000000","ask_px":"250.940000000","bid_sz":2,"ask_sz":100,"bid_ct":2,"ask_ct":1},{"bid_px":"249.930000000","ask_px":"251.090000000","bid_sz":10,"ask_sz":50,"bid_ct":1,"ask_ct":1},{"bid_px":"249.920000000","ask_px":"252.400000000","bid_sz":50,"ask_sz":1000,"bid_ct":1,"ask_ct":1},{"bid_px":"249.800000000","ask_px":"253.650000000","bid_sz":199,"ask_sz":400,"bid_ct":1,"ask_ct":1},{"bid_px":"249.770000000","ask_px":"255.000000000","bid_sz":50,"ask_sz":85,"bid_ct":1,"ask_ct":2},{"bid_px":"249.600000000","ask_px":"260.000000000","bid_sz":1000,"ask_sz":48,"bid_ct":1,"ask_ct":1},{"bid_px":"249.500000000","ask_px":"262.660000000","bid_sz":1000,"ask_sz":56,"bid_ct":1,"ask_ct":1},{"bid_px":"248.600000000","ask_px":"264.940000000","bid_sz":1000,"ask_sz":7,"bid_ct":1,"ask_ct":1},{"bid_px":"248.500000000","ask_px":"265.000000000","bid_sz":40,"ask_sz":1,"bid_ct":1,"ask_ct":1},{"bid_px":"247.150000000","ask_px":"267.800000000","bid_sz":400,"ask_sz":30,"bid_ct":1,"ask_ct":1}],"symbol":"TSLA"}
{"ts_recv":"2024-11-01T08:00:10.038422082Z","hd":{"ts_event":"2024-11-01T08:00:10.038255545Z","rtype":10,"publisher_id":2,"instrument_id":38},"action":"A","side":"B","depth":7,"price":"204.500000000","size":2,"flags":130,"ts_in_delta":166537,"sequence":310212,"levels":[{"bid_px":"221.300000000","ask_px":"224.400000000","bid_sz":1000,"ask_sz":1000,"bid_ct":1,"ask_ct":1},{"bid_px":"220.000000000","ask_px":"225.000000000","bid_sz":2,"ask_sz":1,"bid_ct":1,"ask_ct":1},{"bid_px":"219.690000000","ask_px":"225.360000000","bid_sz":442,"ask_sz":1,"bid_ct":1,"ask_ct":1},{"bid_px":"219.000000000","ask_px":"225.490000000","bid_sz":1,"ask_sz":442,"bid_ct":1,"ask_ct":1},{"bid_px":"217.000000000","ask_px":"225.900000000","bid_sz":1525,"ask_sz":32,"bid_ct":1,"ask_ct":2},{"bid_px":"213.000000000","ask_px":"229.330000000","bid_sz":5,"ask_sz":9,"bid_ct":1,"ask_ct":2},{"bid_px":"210.000000000","ask_px":"233.670000000","bid_sz":1,"ask_sz":5,"bid_ct":1,"ask_ct":1},{"bid_px":"204.500000000","ask_px":"234.000000000","bid_sz":2,"ask_sz":20,"bid_ct":1,"ask_ct":1},{"bid_px":"200.000000000","ask_px":"235.000000000","bid_sz":30,"ask_sz":2,"bid_ct":1,"ask_ct":1},{"bid_px":"190.000000000","ask_px":"238.760000000","bid_sz":1,"ask_sz":150,"bid_ct":1,"ask_ct":1}],"symbol":"AAPL"}
{"ts_recv":"2024-11-01T08:00:10.097591952Z","hd":{"ts_event":"2024-11-01T08:00:10.097425474Z","rtype":10,"publisher_id":2,"instrument_id":16244},"action":"A","side":"A","depth":1,"price":"251.090000000","size":50,"flags":130,"ts_in_delta":166478,"sequence":310304,"levels":[{"bid_px":"250.000000000","ask_px":"250.940000000","bid_sz":2,"ask_sz":100,"bid_ct":2,"ask_ct":1},{"bid_px":"249.930000000","ask_px":"251.090000000","bid_sz":10,"ask_sz":100,"bid_ct":1,"ask_ct":2},{"bid_px":"249.920000000","ask_px":"252.400000000","bid_sz":50,"ask_sz":1000,"bid_ct":1,"ask_ct":1},{"bid_px":"249.800000000","ask_px":"253.650000000","bid_sz":199,"ask_sz":400,"bid_ct":1,"ask_ct":1},{"bid_px":"249.770000000","ask_px":"255.000000000","bid_sz":50,"ask_sz":85,"bid_ct":1,"ask_ct":2},{"bid_px":"249.600000000","ask_px":"260.000000000","bid_sz":1000,"ask_sz":48,"bid_ct":1,"ask_ct":1},{"bid_px":"249.500000000","ask_px":"262.660000000","bid_sz":1000,"ask_sz":56,"bid_ct":1,"ask_ct":1},{"bid_px":"248.600000000","ask_px":"264.940000000","bid_sz":1000,"ask_sz":7,"bid_ct":1,"ask_ct":1},{"bid_px":"248.500000000","ask_px":"265.000000000","bid_sz":40,"ask_sz":1,"bid_ct":1,"ask_ct":1},{"bid_px":"247.150000000","ask_px":"267.800000000","bid_sz":400,"ask_sz":30,"bid_ct":1,"ask_ct":1}],"symbol":"TSLA"}
{"ts_recv":"2024-11-01T08:00:10.097635281Z","hd":{"ts_event":"2024-11-01T08:00:10.097469401Z","rtype":10,"publisher_id":2,"instrument_id":16244},"action":"C","side":"B","depth":2,"price":"249.920000000","size":50,"flags":130,"ts_in_delta":165880,"sequence":310305,"levels":[{"bid_px":"250.000000000","ask_px":"250.940000000","bid_sz":2,"ask_sz":100,"bid_ct":2,"ask_ct":1},{"bid_px":"249.930000000","ask_px":"251.090000000","bid_sz":10,"ask_sz":100,"bid_ct":1,"ask_ct":2},{"bid_px":"249.800000000","ask_px":"252.400000000","bid_sz":199,"ask_sz":1000,"bid_ct":1,"ask_ct":1},{"bid_px":"249.770000000","ask_px":"253.650000000","bid_sz":50,"ask_sz":400,"bid_ct":1,"ask_ct":1},{"bid_px":"249.600000000","ask_px":"255.000000000","bid_sz":1000,"ask_sz":85,"bid_ct":1,"ask_ct":2},{"bid_px":"249.500000000","ask_px":"260.000000000","bid_sz":1000,"ask_sz":48,"bid_ct":1,"ask_ct":1},{"bid_px":"248.600000000","ask_px":"262.660000000","bid_sz":1000,"ask_sz":56,"bid_ct":1,"ask_ct":1},{"bid_px":"248.500000000","ask_px":"264.940000000","bid_sz":40,"ask_sz":7,"bid_ct":1,"ask_ct":1},{"bid_px":"247.150000000","ask_px":"265.000000000","bid_sz":400,"ask_sz":1,"bid_ct":1,"ask_ct":1},{"bid_px":"247.000000000","ask_px":"267.800000000","bid_sz":12,"ask_sz":30,"bid_ct":1,"ask_ct":1}],"symbol":"TSLA"}
{"ts_recv":"2024-11-01T08:00:10.097648012Z","hd":{"ts_event":"2024-11-01T08:00:10.097481745Z","rtype":10,"publisher_id":2,"instrument_id":16244},"action":"A","side":"B","depth":2,"price":"249.890000000","size":50,"flags":130,"ts_in_delta":166267,"sequence":310306,"levels":[{"bid_px":"250.000000000","ask_px":"250.940000000","bid_sz":2,"ask_sz":100,"bid_ct":2,"ask_ct":1},{"bid_px":"249.930000000","ask_px":"251.090000000","bid_sz":10,"ask_sz":100,"bid_ct":1,"ask_ct":2},{"bid_px":"249.890000000","ask_px":"252.400000000","bid_sz":50,"ask_sz":1000,"bid_ct":1,"ask_ct":1},{"bid_px":"249.800000000","ask_px":"253.650000000","bid_sz":199,"ask_sz":400,"bid_ct":1,"ask_ct":1},{"bid_px":"249.770000000","ask_px":"255.000000000","bid_sz":50,"ask_sz":85,"bid_ct":1,"ask_ct":2},{"bid_px":"249.600000000","ask_px":"260.000000000","bid_sz":1000,"ask_sz":48,"bid_ct":1,"ask_ct":1},{"bid_px":"249.500000000","ask_px":"262.660000000","bid_sz":1000,"ask_sz":56,"bid_ct":1,"ask_ct":1},{"bid_px":"248.600000000","ask_px":"264.940000000","bid_sz":1000,"ask_sz":7,"bid_ct":1,"ask_ct":1},{"bid_px":"248.500000000","ask_px":"265.000000000","bid_sz":40,"ask_sz":1,"bid_ct":1,"ask_ct":1},{"bid_px":"247.150000000","ask_px":"267.800000000","bid_sz":400,"ask_sz":30,"bid_ct":1,"ask_ct":1}],"symbol":"TSLA"}
{"ts_recv":"2024-11-01T08:00:10.148750553Z","hd":{"ts_event":"2024-11-01T08:00:10.148584206Z","rtype":10,"publisher_id":2,"instrument_id":16244},"action":"C","side":"A","depth":1,"price":"251.090000000","size":50,"flags":130,"ts_in_delta":166347,"sequence":310376,"levels":[{"bid_px":"250.000000000","ask_px":"250.940000000","bid_sz":2,"ask_sz":100,"bid_ct":2,"ask_ct":1},{"bid_px":"249.930000000","ask_px":"251.090000000","bid_sz":10,"ask_sz":50,"bid_ct":1,"ask_ct":1},{"bid_px":"249.890000000","ask_px":"252.400000000","bid_sz":50,"ask_sz":1000,"bid_ct":1,"ask_ct":1},{"bid_px":"249.800000000","ask_px":"253.650000000","bid_sz":199,"ask_sz":400,"bid_ct":1,"ask_ct":1},{"bid_px":"249.770000000","ask_px":"255.000000000","bid_sz":50,"ask_sz":85,"bid_ct":1,"ask_ct":2},{"bid_px":"249.600000000","ask_px":"260.000000000","bid_sz":1000,"ask_sz":48,"bid_ct":1,"ask_ct":1},{"bid_px":"249.500000000","ask_px":"262.660000000","bid_sz":1000,"ask_sz":56,"bid_ct":1,"ask_ct":1},{"bid_px":"248.600000000","ask_px":"264.940000000","bid_sz":1000,"ask_sz":7,"bid_ct":1,"ask_ct":1},{"bid_px":"248.500000000","ask_px":"265.000000000","bid_sz":40,"ask_sz":1,"bid_ct":1,"ask_ct":1},{"bid_px":"247.150000000","ask_px":"267.800000000","bid_sz":400,"ask_sz":30,"bid_ct":1,"ask_ct":1}],"symbol":"TSLA"}
{"ts_recv":"2024-11-01T08:00:10.148764513Z","hd":{"ts_event":"2024-11-01T08:00:10.148598171Z","rtype":10,"publisher_id":2,"instrument_id":16244},"action":"A","side":"A","depth":1,"price":"250.990000000","size":50,"flags":130,"ts_in_delta":166342,"sequence":310377,"levels":[{"bid_px":"250.000000000","ask_px":"250.940000000","bid_sz":2,"ask_sz":100,"bid_ct":2,"ask_ct":1},{"bid_px":"249.930000000","ask_px":"250.990000000","bid_sz":10,"ask_sz":50,"bid_ct":1,"ask_ct":1},{"bid_px":"249.890000000","ask_px":"252.400000000","bid_sz":50,"ask_sz":1000,"bid_ct":1,"ask_ct":1},{"bid_px":"249.800000000","ask_px":"253.650000000","bid_sz":199,"ask_sz":400,"bid_ct":1,"ask_ct":1},{"bid_px":"249.770000000","ask_px":"255.000000000","bid_sz":50,"ask_sz":85,"bid_ct":1,"ask_ct":2},{"bid_px":"249.600000000","ask_px":"260.000000000","bid_sz":1000,"ask_sz":48,"bid_ct":1,"ask_ct":1},{"bid_px":"249.500000000","ask_px":"262.660000000","bid_sz":1000,"ask_sz":56,"bid_ct":1,"ask_ct":1},{"bid_px":"248.600000000","ask_px":"264.940000000","bid_sz":1000,"ask_sz":7,"bid_ct":1,"ask_ct":1},{"bid_px":"248.500000000","ask_px":"265.000000000","bid_sz":40,"ask_sz":1,"bid_ct":1,"ask_ct":1},{"bid_px":"247.150000000","ask_px":"267.800000000","bid_sz":400,"ask_sz":30,"bid_ct":1,"ask_ct":1}],"symbol":"TSLA"}
{"ts_recv":"2024-11-01T08:00:10.168606294Z","hd":{"ts_event":"2024-11-01T08:00:10.168439956Z","rtype":10,"publisher_id":2,"instrument_id":16244},"action":"A","side":"B","depth":2,"price":"249.910000000","size":50,"flags":130,"ts_in_delta":166338,"sequence":310404,"levels":[{"bid_px":"250.000000000","ask_px":"250.940000000","bid_sz":2,"ask_sz":100,"bid_ct":2,"ask_ct":1},{"bid_px":"249.930000000","ask_px":"250.990000000","bid_sz":10,"ask_sz":50,"bid_ct":1,"ask_ct":1},{"bid_px":"249.910000000","ask_px":"252.400000000","bid_sz":50,"ask_sz":1000,"bid_ct":1,"ask_ct":1},{"bid_px":"249.800000000","ask_px":"253.650000000","bid_sz":199,"ask_sz":400,"bid_ct":1,"ask_ct":1},{"bid_px":"249.770000000","ask_px":"255.000000000","bid_sz":50,"ask_sz":85,"bid_ct":1,"ask_ct":2},{"bid_px":"249.600000000","ask_px":"260.000000000","bid_sz":1000,"ask_sz":48,"bid_ct":1,"ask_ct":1},{"bid_px":"249.500000000","ask_px":"262.660000000","bid_sz":1000,"ask_sz":56,"bid_ct":1,"ask_ct":1},{"bid_px":"248.600000000","ask_px":"264.940000000","bid_sz":1000,"ask_sz":7,"bid_ct":1,"ask_ct":1},{"bid_px":"248.500000000","ask_px":"265.000000000","bid_sz":40,"ask_sz":1,"bid_ct":1,"ask_ct":1},{"bid_px":"247.150000000","ask_px":"267.800000000","bid_sz":400,"ask_sz":30,"bid_ct":1,"ask_ct":1}],"symbol":"TSLA"}
{"ts_recv":"2024-11-01T08:00:10.171564993Z","hd":{"ts_event":"2024-11-01T08:00:10.171397591Z","rtype":10,"publisher_id":2,"instrument_id":9155},"action":"A","side":"B","depth":2,"price":"218.080000000","size":100,"flags":130,"ts_in_delta":167402,"sequence":310417,"levels":[{"bid_px":"221.850000000","ask_px":"224.940000000","bid_sz":3,"ask_sz":450,"bid_ct":1,"ask_ct":1},{"bid_px":"219.160000000","ask_px":"226.800000000","bid_sz":450,"ask_sz":100,"bid_ct":1,"ask_ct":1},{"bid_px":"218.080000000","ask_px":null,"bid_sz":100,"ask_sz":0,"bid_ct":1,"ask_ct":0},{"bid_px":null,"ask_px":null,"bid_sz":0,"ask_sz":0,"bid_ct":0,"ask_ct":0},{"bid_px":null,"ask_px":null,"bid_sz":0,"ask_sz":0,"bid_ct":0,"ask_ct":0},{"bid_px":null,"ask_px":null,"bid_sz":0,"ask_sz":0,"bid_ct":0,"ask_ct":0},{"bid_px":null,"ask_px":null,"bid_sz":0,"ask_sz":0,"bid_ct":0,"ask_ct":0},{"bid_px":null,"ask_px":null,"bid_sz":0,"ask_sz":0,"bid_ct":0,"ask_ct":0},{"bid_px":null,"ask_px":null,"bid_sz":0,"ask_sz":0,"bid_ct":0,"ask_ct":0},{"bid_px":null,"ask_px":null,"bid_sz":0,"ask_sz":0,"bid_ct":0,"ask_ct":0}],"symbol":"JPM"}
{"ts_recv":"2024-11-01T08:00:10.178995283Z","hd":{"ts_event":"2024-11-01T08:00:10.178829435Z","rtype":10,"publisher_id":2,"instrument_id":16244},"action":"C","side":"B","depth":7,"price":"248.600000000","size":1000,"flags":130,"ts_in_delta":165848,"sequence":310428,"levels":[{"bid_px":"250.000000000","ask_px":"250.940000000","bid_sz":2,"ask_sz":100,"bid_ct":2,"ask_ct":1},{"bid_px":"249.930000000","ask_px":"250.990000000","bid_sz":10,"ask_sz":50,"bid_ct":1,"ask_ct":1},{"bid_px":"249.910000000","ask_px":"252.400000000","bid_sz":50,"ask_sz":1000,"bid_ct":1,"ask_ct":1},{"bid_px":"249.800000000","ask_px":"253.650000000","bid_sz":199,"ask_sz":400,"bid_ct":1,"ask_ct":1},{"bid_px":"249.770000000","ask_px":"255.000000000","bid_sz":50,"ask_sz":85,"bid_ct":1,"ask_ct":2},{"bid_px":"249.600000000","ask_px":"260.000000000","bid_sz":1000,"ask_sz":48,"bid_ct":1,"ask_ct":1},{"bid_px":"249.500000000","ask_px":"262.660000000","bid_sz":1000,"ask_sz":56,"bid_ct":1,"ask_ct":1},{"bid_px":"248.500000000","ask_px":"264.940000000","bid_sz":40,"ask_sz":7,"bid_ct":1,"ask_ct":1},{"bid_px":"247.150000000","ask_px":"265.000000000","bid_sz":400,"ask_sz":1,"bid_ct":1,"ask_ct":1},{"bid_px":"247.000000000","ask_px":"267.800000000","bid_sz":12,"ask_sz":30,"bid_ct":1,"ask_ct":1}],"symbol":"TSLA"}
{"ts_recv":"2024-11-01T08:00:10.189419686Z","hd":{"ts_event":"2024-11-01T08:00:10.189253300Z","rtype":10,"publisher_id":2,"instrument_id":16244},"action":"A","side":"B","depth":5,"price":"249.700000000","size":1000,"flags":130,"ts_in_delta":166386,"sequence":310444,"levels":[{"bid_px":"250.000000000","ask_px":"250.940000000","bid_sz":2,"ask_sz":100,"bid_ct":2,"ask_ct":1},{"bid_px":"249.930000000","ask_px":"250.990000000","bid_sz":10,"ask_sz":50,"bid_ct":1,"ask_ct":1},{"bid_px":"249.910000000","ask_px":"252.400000000","bid_sz":50,"ask_sz":1000,"bid_ct":1,"ask_ct":1},{"bid_px":"249.800000000","ask_px":"253.650000000","bid_sz":199,"ask_sz":400,"bid_ct":1,"ask_ct":1},{"bid_px":"249.770000000","ask_px":"255.000000000","bid_sz":50,"ask_sz":85,"bid_ct":1,"ask_ct":2},{"bid_px":"249.700000000","ask_px":"260.000000000","bid_sz":1000,"ask_sz":48,"bid_ct":1,"ask_ct":1},{"bid_px":"249.600000000","ask_px":"262.660000000","bid_sz":1000,"ask_sz":56,"bid_ct":1,"ask_ct":1},{"bid_px":"249.500000000","ask_px":"264.940000000","bid_sz":1000,"ask_sz":7,"bid_ct":1,"ask_ct":1},{"bid_px":"248.500000000","ask_px":"265.000000000","bid_sz":40,"ask_sz":1,"bid_ct":1,"ask_ct":1},{"bid_px":"247.150000000","ask_px":"267.800000000","bid_sz":400,"ask_sz":30,"bid_ct":1,"ask_ct":1}],"symbol":"TSLA"}
{"ts_recv":"2024-11-01T08:00:10.189446830Z","hd":{"ts_event":"2024-11-01T08:00:10.189280846Z","rtype":10,"publisher_id":2,"instrument_id":16244},"action":"C","side":"B","depth":7,"price":"249.500000000","size":1000,"flags":130,"ts_in_delta":165984,"sequence":310445,"levels":[{"bid_px":"250.000000000","ask_px":"250.940000000","bid_sz":2,"ask_sz":100,"bid_ct":2,"ask_ct":1},{"bid_px":"249.930000000","ask_px":"250.990000000","bid_sz":10,"ask_sz":50,"bid_ct":1,"ask_ct":1},{"bid_px":"249.910000000","ask_px":"252.400000000","bid_sz":50,"ask_sz":1000,"bid_ct":1,"ask_ct":1},{"bid_px":"249.800000000","ask_px":"253.650000000","bid_sz":199,"ask_sz":400,"bid_ct":1,"ask_ct":1},{"bid_px":"249.770000000","ask_px":"255.000000000","bid_sz":50,"ask_sz":85,"bid_ct":1,"ask_ct":2},{"bid_px":"249.700000000","ask_px":"260.000000000","bid_sz":1000,"ask_sz":48,"bid_ct":1,"ask_ct":1},{"bid_px":"249.600000000","ask_px":"262.660000000","bid_sz":1000,"ask_sz":56,"bid_ct":1,"ask_ct":1},{"bid_px":"248.500000000","ask_px":"264.940000000","bid_sz":40,"ask_sz":7,"bid_ct":1,"ask_ct":1},{"bid_px":"247.150000000","ask_px":"265.000000000","bid_sz":400,"ask_sz":1,"bid_ct":1,"ask_ct":1},{"bid_px":"247.000000000","ask_px":"267.800000000","bid_sz":12,"ask_sz":30,"bid_ct":1,"ask_ct":1}],"symbol":"TSLA"}
{"ts_recv":"2024-11-01T08:00:10.200968842Z","hd":{"ts_event":"2024-11-01T08:00:10.200802660Z","rtype":10,"publisher_id":2,"instrument_id":16244},"action":"A","side":"B","depth":8,"price":"248.200000000","size":1000,"flags":130,"ts_in_delta":166182,"sequence":310455,"levels":[{"bid_px":"250.000000000","ask_px":"250.940000000","bid_sz":2,"ask_sz":100,"bid_ct":2,"ask_ct":1},{"bid_px":"249.930000000","ask_px":"250.990000000","bid_sz":10,"ask_sz":50,"bid_ct":1,"ask_ct":1},{"bid_px":"249.910000000","ask_px":"252.400000000","bid_sz":50,"ask_sz":1000,"bid_ct":1,"ask_ct":1},{"bid_px":"249.800000000","ask_px":"253.650000000","bid_sz":199,"ask_sz":400,"bid_ct":1,"ask_ct":1},{"bid_px":"249.770000000","ask_px":"255.000000000","bid_sz":50,"ask_sz":85,"bid_ct":1,"ask_ct":2},{"bid_px":"249.700000000","ask_px":"260.000000000","bid_sz":1000,"ask_sz":48,"bid_ct":1,"ask_ct":1},{"bid_px":"249.600000000","ask_px":"262.660000000","bid_sz":1000,"ask_sz":56,"bid_ct":1,"ask_ct":1},{"bid_px":"248.500000000","ask_px":"264.940000000","bid_sz":40,"ask_sz":7,"bid_ct":1,"ask_ct":1},{"bid_px":"248.200000000","ask_px":"265.000000000","bid_sz":1000,"ask_sz":1,"bid_ct":1,"ask_ct":1},{"bid_px":"247.150000000","ask_px":"267.800000000","bid_sz":400,"ask_sz":30,"bid_ct":1,"ask_ct":1}],"symbol":"TSLA"}
{"ts_recv":"2024-11-01T08:00:10.250667584Z","hd":{"ts_event":"2024-11-01T08:00:10.250500971Z","rtype":10,"publisher_id":2,"instrument_id":11667},"action":"A","side":"B","depth":0,"price":"134.680000000","size":100,"flags":130,"ts_in_delta":166613,"sequence":310528,"levels":[{"bid_px":"134.680000000","ask_px":"134.990000000","bid_sz":100,"ask_sz":10,"bid_ct":1,"ask_ct":1},{"bid_px":"134.500000000","ask_px":"135.000000000","bid_sz":520,"ask_sz":38,"bid_ct":2,"ask_ct":3},{"bid_px":"134.410000000","ask_px":"135.100000000","bid_sz":61,"ask_sz":10,"bid_ct":2,"ask_ct":1},{"bid_px":"134.380000000","ask_px":"135.230000000","bid_sz":18,"ask_sz":360,"bid_ct":1,"ask_ct":1},{"bid_px":"134.210000000","ask_px":"135.300000000","bid_sz":20,"ask_sz":1000,"bid_ct":1,"ask_ct":1},{"bid_px":"134.200000000","ask_px":"135.400000000","bid_sz":3,"ask_sz":10,"bid_ct":1,"ask_ct":1},{"bid_px":"133.160000000","ask_px":"135.420000000","bid_sz":1,"ask_sz":1,"bid_ct":1,"ask_ct":1},{"bid_px":"132.760000000","ask_px":"135.820000000","bid_sz":100,"ask_sz":1,"bid_ct":1,"ask_ct":1},{"bid_px":"132.700000000","ask_px":"135.990000000","bid_sz":4,"ask_sz":20,"bid_ct":1,"ask_ct":1},{"bid_px":"132.660000000","ask_px":"136.100000000","bid_sz":1,"ask_sz":1000,"bid_ct":1,"ask_ct":1}],"symbol":"NVDA"}
{"ts_recv":"2024-11-01T08:00:10.264778366Z","hd":{"ts_event":"2024-11-01T08:00:10.264611611Z","rtype":10,"publisher_id":2,"instrument_id":16244},"action":"C","side":"B","depth":2,"price":"249.910000000","size":50,"flags":130,"ts_in_delta":166755,"sequence":310554,"levels":[{"bid_px":"250.000000000","ask_px":"250.940000000","bid_sz":2,"ask_sz":100,"bid_ct":2,"ask_ct":1},{"bid_px":"249.930000000","ask_px":"250.990000000","bid_sz":10,"ask_sz":50,"bid_ct":1,"ask_ct":1},{"bid_px":"249.800000000","ask_px":"252.400000000","bid_sz":199,"ask_sz":1000,"bid_ct":1,"ask_ct":1},{"bid_px":"249.770000000","ask_px":"253.650000000","bid_sz":50,"ask_sz":400,"bid_ct":1,"ask_ct":1},{"bid_px":"249.700000000","ask_px":"255.000000000","bid_sz":1000,"ask_sz":85,"bid_ct":1,"ask_ct":2},{"bid_px":"249.600000000","ask_px":"260.000000000","bid_sz":1000,"ask_sz":48,"bid_ct":1,"ask_ct":1},{"bid_px":"248.500000000","ask_px":"262.660000000","bid_sz":40,"ask_sz":56,"bid_ct":1,"ask_ct":1},{"bid_px":"248.200000000","ask_px":"264.940000000","bid_sz":1000,"ask_sz":7,"bid_ct":1,"ask_ct":1},{"bid_px":"247.150000000","ask_px":"265.000000000","bid_sz":400,"ask_sz":1,"bid_ct":1,"ask_ct":1},{"bid_px":"247.000000000","ask_px":"267.800000000","bid_sz":12,"ask_sz":30,"bid_ct":1,"ask_ct":1}],"symbol":"TSLA"}
{"ts_recv":"2024-11-01T08:00:10.366826490Z","hd":{"ts_event":"2024-11-01T08:00:10.366660191Z","rtype":10,"publisher_id":2,"instrument_id":38},"action":"A","side":"B","depth":5,"price":"215.000000000","size":5,"flags":130,"ts_in_delta":166299,"sequence":310747,"levels":[{"bid_px":"221.300000000","ask_px":"224.400000000","bid_sz":1000,"ask_sz":1000,"bid_ct":1,"ask_ct":1},{"bid_px":"220.000000000","ask_px":"225.000000000","bid_sz":2,"ask_sz":1,"bid_ct":1,"ask_ct":1},{"bid_px":"219.690000000","ask_px":"225.360000000","bid_sz":442,"ask_sz":1,"bid_ct":1,"ask_ct":1},{"bid_px":"219.000000000","ask_px":"225.490000000","bid_sz":1,"ask_sz":442,"bid_ct":1,"ask_ct":1},{"bid_px":"217.000000000","ask_px":"225.900000000","bid_sz":1525,"ask_sz":32,"bid_ct":1,"ask_ct":2},{"bid_px":"215.000000000","ask_px":"229.330000000","bid_sz":5,"ask_sz":9,"bid_ct":1,"ask_ct":2},{"bid_px":"213.000000000","ask_px":"233.670000000","bid_sz":5,"ask_sz":5,"bid_ct":1,"ask_ct":1},{"bid_px":"210.000000000","ask_px":"234.000000000","bid_sz":1,"ask_sz":20,"bid_ct":1,"ask_ct":1},{"bid_px":"204.500000000","ask_px":"235.000000000","bid_sz":2,"ask_sz":2,"bid_ct":1,"ask_ct":1},{"bid_px":"200.000000000","ask_px":"238.760000000","bid_sz":30,"ask_sz":150,"bid_ct":1,"ask_ct":1}],"symbol":"AAPL"}
{"ts_recv":"2024-11-01T08:00:10.445872888Z","hd":{"ts_event":"2024-11-01T08:00:10.445705898Z","rtype":10,"publisher_id":2,"instrument_id":16244},"action":"A","side":"B","depth":0,"price":"250.150000000","size":50,"flags":130,"ts_in_delta":166990,"sequence":310826,"levels":[{"bid_px":"250.150000000","ask_px":"250.940000000","bid_sz":50,"ask_sz":100,"bid_ct":1,"ask_ct":1},{"bid_px":"250.000000000","ask_px":"250.990000000","bid_sz":2,"ask_sz":50,"bid_ct":2,"ask_ct":1},{"bid_px":"249.930000000","ask_px":"252.400000000","bid_sz":10,"ask_sz":1000,"bid_ct":1,"ask_ct":1},{"bid_px":"249.800000000","ask_px":"253.650000000","bid_sz":199,"ask_sz":400,"bid_ct":1,"ask_ct":1},{"bid_px":"249.770000000","ask_px":"255.000000000","bid_sz":50,"ask_sz":85,"bid_ct":1,"ask_ct":2},{"bid_px":"249.700000000","ask_px":"260.000000000","bid_sz":1000,"ask_sz":48,"bid_ct":1,"ask_ct":1},{"bid_px":"249.600000000","ask_px":"262.660000000","bid_sz":1000,"ask_sz":56,"bid_ct":1,"ask_ct":1},{"bid_px":"248.500000000","ask_px":"264.940000000","bid_sz":40,"ask_sz":7,"bid_ct":1,"ask_ct":1},{"bid_px":"248.200000000","ask_px":"265.000000000","bid_sz":1000,"ask_sz":1,"bid_ct":1,"ask_ct":1},{"bid_px":"247.150000000","ask_px":"267.800000000","bid_sz":400,"ask_sz":30,"bid_ct":1,"ask_ct":1}],"symbol":"TSLA"}
{"ts_recv":"2024-11-01T08:00:10.540662144Z","hd":{"ts_event":"2024-11-01T08:00:10.540496378Z","rtype":10,"publisher_id":2,"instrument_id":10888},"action":"A","side":"A","depth":3,"price":"440.000000000","size":35,"flags":130,"ts_in_delta":165766,"sequence":311211,"levels":[{"bid_px":"410.000000000","ask_px":"414.000000000","bid_sz":1,"ask_sz":33,"bid_ct":1,"ask_ct":1},{"bid_px":"409.750000000","ask_px":"415.070000000","bid_sz":3,"ask_sz":246,"bid_ct":1,"ask_ct":1},{"bid_px":"409.080000000","ask_px":"420.000000000","bid_sz":2,"ask_sz":3,"bid_ct":1,"ask_ct":1},{"bid_px":"408.970000000","ask_px":"440.000000000","bid_sz":12,"ask_sz":35,"bid_ct":1,"ask_ct":1},{"bid_px":"408.960000000","ask_px":"445.000000000","bid_sz":5,"ask_sz":25,"bid_ct":1,"ask_ct":1},{"bid_px":"407.600000000","ask_px":"445.680000000","bid_sz":16,"ask_sz":3,"bid_ct":1,"ask_ct":1},{"bid_px":"407.000000000","ask_px":"448.000000000","bid_sz":17,"ask_sz":15,"bid_ct":3,"ask_ct":2},{"bid_px":"406.350000000","ask_px":"450.000000000","bid_sz":82,"ask_sz":10,"bid_ct":2,"ask_ct":1},{"bid_px":"406.000000000","ask_px":"468.000000000","bid_sz":7,"ask_sz":65,"bid_ct":1,"ask_ct":1},{"bid_px":"405.000000000","ask_px":"472.000000000","bid_sz":15,"ask_sz":6,"bid_ct":2,"ask_ct":1}],"symbol":"MSFT"}
{"ts_recv":"2024-11-01T08:00:10.622856667Z","hd":{"ts_event":"2024-11-01T08:00:10.622690498Z","rtype":10,"publisher_id":2,"instrument_id":16244},"action":"A","side":"A","depth":8,"price":"265.000000000","size":1,"flags":130,"ts_in_delta":166169,"sequence":311375,"levels":[{"bid_px":"250.150000000","ask_px":"250.940000000","bid_sz":50,"ask_sz":100,"bid_ct":1,"ask_ct":1},{"bid_px":"250.000000000","ask_px":"250.990000000","bid_sz":2,"ask_sz":50,"bid_ct":2,"ask_ct":1},{"bid_px":"249.930000000","ask_px":"252.400000000","bid_sz":10,"ask_sz":1000,"bid_ct":1,"ask_ct":1},{"bid_px":"249.800000000","ask_px":"253.650000000","bid_sz":199,"ask_sz":400,"bid_ct":1,"ask_ct":1},{"bid_px":"249.770000000","ask_px":"255.000000000","bid_sz":50,"ask_sz":85,"bid_ct":1,"ask_ct":2},{"bid_px":"249.700000000","ask_px":"260.000000000","bid_sz":1000,"ask_sz":48,"bid_ct":1,"ask_ct":1},{"bid_px":"249.600000000","ask_px":"262.660000000","bid_sz":1000,"ask_sz":56,"bid_ct":1,"ask_ct":1},{"bid_px":"248.500000000","ask_px":"264.940000000","bid_sz":40,"ask_sz":7,"bid_ct":1,"ask_ct":1},{"bid_px":"248.200000000","ask_px":"265.000000000","bid_sz":1000,"ask_sz":2,"bid_ct":1,"ask_ct":2},{"bid_px":"247.150000000","ask_px":"267.800000000","bid_sz":400,"ask_sz":30,"bid_ct":1,"ask_ct":1}],"symbol":"TSLA"}
{"ts_recv":"2024-11-01T08:00:10.625500963Z","hd":{"ts_event":"2024-11-01T08:00:10.625335069Z","rtype":10,"publisher_id":2,"instrument_id":16244},"action":"A","side":"A","depth":1,"price":"250.980000000","size":50,"flags":130,"ts_in_delta":165894,"sequence":311383,"levels":[{"bid_px":"250.150000000","ask_px":"250.940000000","bid_sz":50,"ask_sz":100,"bid_ct":1,"ask_ct":1},{"bid_px":"250.000000000","ask_px":"250.980000000","bid_sz":2,"ask_sz":50,"bid_ct":2,"ask_ct":1},{"bid_px":"249.930000000","ask_px":"252.400000000","bid_sz":10,"ask_sz":1000,"bid_ct":1,"ask_ct":1},{"bid_px":"249.800000000","ask_px":"253.650000000","bid_sz":199,"ask_sz":400,"bid_ct":1,"ask_ct":1},{"bid_px":"249.770000000","ask_px":"255.000000000","bid_sz":50,"ask_sz":85,"bid_ct":1,"ask_ct":2},{"bid_px":"249.700000000","ask_px":"260.000000000","bid_sz":1000,"ask_sz":48,"bid_ct":1,"ask_ct":1},{"bid_px":"249.600000000","ask_px":"262.660000000","bid_sz":1000,"ask_sz":56,"bid_ct":1,"ask_ct":1},{"bid_px":"248.500000000","ask_px":"264.940000000","bid_sz":40,"ask_sz":7,"bid_ct":1,"ask_ct":1},{"bid_px":"248.200000000","ask_px":"265.000000000","bid_sz":1000,"ask_sz":2,"bid_ct":1,"ask_ct":2},{"bid_px":"247.150000000","ask_px":"267.800000000","bid_sz":400,"ask_sz":30,"bid_ct":1,"ask_ct":1}],"symbol":"TSLA"}
{"ts_recv":"2024-11-01T08:00:10.801822731Z","hd":{"ts_event":"2024-11-01T08:00:10.801656638Z","rtype":10,"publisher_id":2,"instrument_id":10888},"action":"A","side":"B","depth":3,"price":"409.000000000","size":2,"flags":130,"ts_in_delta":166093,"sequence":311853,"levels":[{"bid_px":"410.000000000","ask_px":"414.000000000","bid_sz":1,"ask_sz":33,"bid_ct":1,"ask_ct":1},{"bid_px":"409.750000000","ask_px":"415.070000000","bid_sz":3,"ask_sz":246,"bid_ct":1,"ask_ct":1},{"bid_px":"409.080000000","ask_px":"420.000000000","bid_sz":2,"ask_sz":3,"bid_ct":1,"ask_ct":1},{"bid_px":"409.000000000","ask_px":"440.000000000","bid_sz":2,"ask_sz":35,"bid_ct":1,"ask_ct":1},{"bid_px":"408.970000000","ask_px":"445.000000000","bid_sz":12,"ask_sz":25,"bid_ct":1,"ask_ct":1},{"bid_px":"408.960000000","ask_px":"445.680000000","bid_sz":5,"ask_sz":3,"bid_ct":1,"ask_ct":1},{"bid_px":"407.600000000","ask_px":"448.000000000","bid_sz":16,"ask_sz":15,"bid_ct":1,"ask_ct":2},{"bid_px":"407.000000000","ask_px":"450.000000000","bid_sz":17,"ask_sz":10,"bid_ct":3,"ask_ct":1},{"bid_px":"406.350000000","ask_px":"468.000000000","bid_sz":82,"ask_sz":65,"bid_ct":2,"ask_ct":1},{"bid_px":"406.000000000","ask_px":"472.000000000","bid_sz":7,"ask_sz":6,"bid_ct":1,"ask_ct":1}],"symbol":"MSFT"}
{"ts_recv":"2024-11-01T08:00:10.852043842Z","hd":{"ts_event":"2024-11-01T08:00:10.851877543Z","rtype":10,"publisher_id":2,"instrument_id":16244},"action":"A","side":"A","depth":8,"price":"265.000000000","size":100,"flags":130,"ts_in_delta":166299,"sequence":311997,"levels":[{"bid_px":"250.150000000","ask_px":"250.940000000","bid_sz":50,"ask_sz":100,"bid_ct":1,"ask_ct":1},{"bid_px":"250.000000000","ask_px":"250.980000000","bid_sz":2,"ask_sz":50,"bid_ct":2,"ask_ct":1},{"bid_px":"249.930000000","ask_px":"252.400000000","bid_sz":10,"ask_sz":1000,"bid_ct":1,"ask_ct":1},{"bid_px":"249.800000000","ask_px":"253.650000000","bid_sz":199,"ask_sz":400,"bid_ct":1,"ask_ct":1},{"bid_px":"249.770000000","ask_px":"255.000000000","bid_sz":50,"ask_sz":85,"bid_ct":1,"ask_ct":2},{"bid_px":"249.700000000","ask_px":"260.000000000","bid_sz":1000,"ask_sz":48,"bid_ct":1,"ask_ct":1},{"bid_px":"249.600000000","ask_px":"262.660000000","bid_sz":1000,"ask_sz":56,"bid_ct":1,"ask_ct":1},{"bid_px":"248.500000000","ask_px":"264.940000000","bid_sz":40,"ask_sz":7,"bid_ct":1,"ask_ct":1},{"bid_px":"248.200000000","ask_px":"265.000000000","bid_sz":1000,"ask_sz":102,"bid_ct":1,"ask_ct":3},{"bid_px":"247.150000000","ask_px":"267.800000000","bid_sz":400,"ask_sz":30,"bid_ct":1,"ask_ct":1}],"symbol":"TSLA"}
{"ts_recv":"2024-11-01T08:00:10.963661271Z","hd":{"ts_event":"2024-11-01T08:00:10.963495230Z","rtype":10,"publisher_id":2,"instrument_id":16244},"action":"C","side":"A","depth":1,"price":"250.980000000","size":50,"flags":130,"ts_in_delta":166041,"sequence":312130,"levels":[{"bid_px":"250.150000000","ask_px":"250.940000000","bid_sz":50,"ask_sz":100,"bid_ct":1,"ask_ct":1},{"bid_px":"250.000000000","ask_px":"252.400000000","bid_sz":2,"ask_sz":1000,"bid_ct":2,"ask_ct":1},{"bid_px":"249.930000000","ask_px":"253.650000000","bid_sz":10,"ask_sz":400,"bid_ct":1,"ask_ct":1},{"bid_px":"249.800000000","ask_px":"255.000000000","bid_sz":199,"ask_sz":85,"bid_ct":1,"ask_ct":2},{"bid_px":"249.770000000","ask_px":"260.000000000","bid_sz":50,"ask_sz":48,"bid_ct":1,"ask_ct":1},{"bid_px":"249.700000000","ask_px":"262.660000000","bid_sz":1000,"ask_sz":56,"bid_ct":1,"ask_ct":1},{"bid_px":"249.600000000","ask_px":"264.940000000","bid_sz":1000,"ask_sz":7,"bid_ct":1,"ask_ct":1},{"bid_px":"248.500000000","ask_px":"265.000000000","bid_sz":40,"ask_sz":102,"bid_ct":1,"ask_ct":3},{"bid_px":"248.200000000","ask_px":"267.800000000","bid_sz":1000,"ask_sz":30,"bid_ct":1,"ask_ct":1},{"bid_px":"247.150000000","ask_px":"268.670000000","bid_sz":400,"ask_sz":100,"bid_ct":1,"ask_ct":1}],"symbol":"TSLA"}
{"ts_recv":"2024-11-01T08:00:10.982302215Z","hd":{"ts_event":"2024-11-01T08:00:10.982135958Z","rtype":10,"publisher_id":2,"instrument_id":10888},"action":"A","side":"A","depth":8,"price":"467.560000000","size":5,"flags":130,"ts_in_delta":166257,"sequence":312178,"levels":[{"bid_px":"410.000000000","ask_px":"414.000000000","bid_sz":1,"ask_sz":33,"bid_ct":1,"ask_ct":1},{"bid_px":"409.750000000","ask_px":"415.070000000","bid_sz":3,"ask_sz":246,"bid_ct":1,"ask_ct":1},{"bid_px":"409.080000000","ask_px":"420.000000000","bid_sz":2,"ask_sz":3,"bid_ct":1,"ask_ct":1},{"bid_px":"409.000000000","ask_px":"440.000000000","bid_sz":2,"ask_sz":35,"bid_ct":1,"ask_ct":1},{"bid_px":"408.970000000","ask_px":"445.000000000","bid_sz":12,"ask_sz":25,"bid_ct":1,"ask_ct":1},{"bid_px":"408.960000000","ask_px":"445.680000000","bid_sz":5,"ask_sz":3,"bid_ct":1,"ask_ct":1},{"bid_px":"407.600000000","ask_px":"448.000000000","bid_sz":16,"ask_sz":15,"bid_ct":1,"ask_ct":2},{"bid_px":"407.000000000","ask_px":"450.000000000","bid_sz":17,"ask_sz":10,"bid_ct":3,"ask_ct":1},{"bid_px":"406.350000000","ask_px":"467.560000000","bid_sz":82,"ask_sz":5,"bid_ct":2,"ask_ct":1},{"bid_px":"406.000000000","ask_px":"468.000000000","bid_sz":7,"ask_sz":65,"bid_ct":1,"ask_ct":1}],"symbol":"MSFT"}
{"ts_recv":"2024-11-01T08:00:11.008861505Z","hd":{"ts_event":"2024-11-01T08:00:11.008695339Z","rtype":10,"publisher_id":2,"instrument_id":11667},"action":"A","side":"B","depth":6,"price":"134.000000000","size":1,"flags":130,"ts_in_delta":166166,"sequence":312250,"levels":[{"bid_px":"134.680000000","ask_px":"134.990000000","bid_sz":100,"ask_sz":10,"bid_ct":1,"ask_ct":1},{"bid_px":"134.500000000","ask_px":"135.000000000","bid_sz":520,"ask_sz":38,"bid_ct":2,"ask_ct":3},{"bid_px":"134.410000000","ask_px":"135.100000000","bid_sz":61,"ask_sz":10,"bid_ct":2,"ask_ct":1},{"bid_px":"134.380000000","ask_px":"135.230000000","bid_sz":18,"ask_sz":360,"bid_ct":1,"ask_ct":1},{"bid_px":"134.210000000","ask_px":"135.300000000","bid_sz":20,"ask_sz":1000,"bid_ct":1,"ask_ct":1},{"bid_px":"134.200000000","ask_px":"135.400000000","bid_sz":3,"ask_sz":10,"bid_ct":1,"ask_ct":1},{"bid_px":"134.000000000","ask_px":"135.420000000","bid_sz":1,"ask_sz":1,"bid_ct":1,"ask_ct":1},{"bid_px":"133.160000000","ask_px":"135.820000000","bid_sz":1,"ask_sz":1,"bid_ct":1,"ask_ct":1},{"bid_px":"132.760000000","ask_px":"135.990000000","bid_sz":100,"ask_sz":20,"bid_ct":1,"ask_ct":1},{"bid_px":"132.700000000","ask_px":"136.100000000","bid_sz":4,"ask_sz":1000,"bid_ct":1,"ask_ct":1}],"symbol":"NVDA"}
{"ts_recv":"2024-11-01T08:00:11.035334462Z","hd":{"ts_event":"2024-11-01T08:00:11.035168252Z","rtype":10,"publisher_id":2,"instrument_id":16244},"action":"A","side":"A","depth":1,"price":"250.990000000","size":50,"flags":130,"ts_in_delta":166210,"sequence":312363,"levels":[{"bid_px":"250.150000000","ask_px":"250.940000000","bid_sz":50,"ask_sz":100,"bid_ct":1,"ask_ct":1},{"bid_px":"250.000000000","ask_px":"250.990000000","bid_sz":2,"ask_sz":50,"bid_ct":2,"ask_ct":1},{"bid_px":"249.930000000","ask_px":"252.400000000","bid_sz":10,"ask_sz":1000,"bid_ct":1,"ask_ct":1},{"bid_px":"249.800000000","ask_px":"253.650000000","bid_sz":199,"ask_sz":400,"bid_ct":1,"ask_ct":1},{"bid_px":"249.770000000","ask_px":"255.000000000","bid_sz":50,"ask_sz":85,"bid_ct":1,"ask_ct":2},{"bid_px":"249.700000000","ask_px":"260.000000000","bid_sz":1000,"ask_sz":48,"bid_ct":1,"ask_ct":1},{"bid_px":"249.600000000","ask_px":"262.660000000","bid_sz":1000,"ask_sz":56,"bid_ct":1,"ask_ct":1},{"bid_px":"248.500000000","ask_px":"264.940000000","bid_sz":40,"ask_sz":7,"bid_ct":1,"ask_ct":1},{"bid_px":"248.200000000","ask_px":"265.000000000","bid_sz":1000,"ask_sz":102,"bid_ct":1,"ask_ct":3},{"bid_px":"247.150000000","ask_px":"267.800000000","bid_sz":400,"ask_sz":30,"bid_ct":1,"ask_ct":1}],"symbol":"TSLA"}
{"ts_recv":"2024-11-01T08:00:11.128548275Z","hd":{"ts_event":"2024-11-01T08:00:11.128382259Z","rtype":10,"publisher_id":2,"instrument_id":16244},"action":"C","side":"B","depth":0,"price":"250.150000000","size":50,"flags":130,"ts_in_delta":166016,"sequence":312644,"levels":[{"bid_px":"250.000000000","ask_px":"250.940000000","bid_sz":2,"ask_sz":100,"bid_ct":2,"ask_ct":1},{"bid_px":"249.930000000","ask_px":"250.990000000","bid_sz":10,"ask_sz":50,"bid_ct":1,"ask_ct":1},{"bid_px":"249.800000000","ask_px":"252.400000000","bid_sz":199,"ask_sz":1000,"bid_ct":1,"ask_ct":1},{"bid_px":"249.770000000","ask_px":"253.650000000","bid_sz":50,"ask_sz":400,"bid_ct":1,"ask_ct":1},{"bid_px":"249.700000000","ask_px":"255.000000000","bid_sz":1000,"ask_sz":85,"bid_ct":1,"ask_ct":2},{"bid_px":"249.600000000","ask_px":"260.000000000","bid_sz":1000,"ask_sz":48,"bid_ct":1,"ask_ct":1},{"bid_px":"248.500000000","ask_px":"262.660000000","bid_sz":40,"ask_sz":56,"bid_ct":1,"ask_ct":1},{"bid_px":"248.200000000","ask_px":"264.940000000","bid_sz":1000,"ask_sz":7,"bid_ct":1,"ask_ct":1},{"bid_px":"247.150000000","ask_px":"265.000000000","bid_sz":400,"ask_sz":102,"bid_ct":1,"ask_ct":3},{"bid_px":"247.000000000","ask_px":"267.800000000","bid_sz":12,"ask_sz":30,"bid_ct":1,"ask_ct":1}],"symbol":"TSLA"}
{"ts_recv":"2024-11-01T08:00:11.128560599Z","hd":{"ts_event":"2024-11-01T08:00:11.128394620Z","rtype":10,"publisher_id":2,"instrument_id":16244},"action":"A","side":"B","depth":0,"price":"250.110000000","size":50,"flags":130,"ts_in_delta":165979,"sequence":312645,"levels":[{"bid_px":"250.110000000","ask_px":"250.940000000","bid_sz":50,"ask_sz":100,"bid_ct":1,"ask_ct":1},{"bid_px":"250.000000000","ask_px":"250.990000000","bid_sz":2,"ask_sz":50,"bid_ct":2,"ask_ct":1},{"bid_px":"249.930000000","ask_px":"252.400000000","bid_sz":10,"ask_sz":1000,"bid_ct":1,"ask_ct":1},{"bid_px":"249.800000000","ask_px":"253.650000000","bid_sz":199,"ask_sz":400,"bid_ct":1,"ask_ct":1},{"bid_px":"249.770000000","ask_px":"255.000000000","bid_sz":50,"ask_sz":85,"bid_ct":1,"ask_ct":2},{"bid_px":"249.700000000","ask_px":"260.000000000","bid_sz":1000,"ask_sz":48,"bid_ct":1,"ask_ct":1},{"bid_px":"249.600000000","ask_px":"262.660000000","bid_sz":1000,"ask_sz":56,"bid_ct":1,"ask_ct":1},{"bid_px":"248.500000000","ask_px":"264.940000000","bid_sz":40,"ask_sz":7,"bid_ct":1,"ask_ct":1},{"bid_px":"248.200000000","ask_px":"265.000000000","bid_sz":1000,"ask_sz":102,"bid_ct":1,"ask_ct":3},{"bid_px":"247.150000000","ask_px":"267.800000000","bid_sz":400,"ask_sz":30,"bid_ct":1,"ask_ct":1}],"symbol":"TSLA"}
{"ts_recv":"2024-11-01T08:00:11.199620873Z","hd":{"ts_event":"2024-11-01T08:00:11.199454684Z","rtype":10,"publisher_id":2,"instrument_id":10888},"action":"A","side":"A","depth":0,"price":"414.000000000","size":435,"flags":130,"ts_in_delta":166189,"sequence":312861,"levels":[{"bid_px":"410.000000000","ask_px":"414.000000000","bid_sz":1,"ask_sz":468,"bid_ct":1,"ask_ct":2},{"bid_px":"409.750000000","ask_px":"415.070000000","bid_sz":3,"ask_sz":246,"bid_ct":1,"ask_ct":1},{"bid_px":"409.080000000","ask_px":"420.000000000","bid_sz":2,"ask_sz":3,"bid_ct":1,"ask_ct":1},{"bid_px":"409.000000000","ask_px":"440.000000000","bid_sz":2,"ask_sz":35,"bid_ct":1,"ask_ct":1},{"bid_px":"408.970000000","ask_px":"445.000000000","bid_sz":12,"ask_sz":25,"bid_ct":1,"ask_ct":1},{"bid_px":"408.960000000","ask_px":"445.680000000","bid_sz":5,"ask_sz":3,"bid_ct":1,"ask_ct":1},{"bid_px":"407.600000000","ask_px":"448.000000000","bid_sz":16,"ask_sz":15,"bid_ct":1,"ask_ct":2},{"bid_px":"407.000000000","ask_px":"450.000000000","bid_sz":17,"ask_sz":10,"bid_ct":3,"ask_ct":1},{"bid_px":"406.350000000","ask_px":"467.560000000","bid_sz":82,"ask_sz":5,"bid_ct":2,"ask_ct":1},{"bid_px":"406.000000000","ask_px":"468.000000000","bid_sz":7,"ask_sz":65,"bid_ct":1,"ask_ct":1}],"symbol":"MSFT"}
{"ts_recv":"2024-11-01T08:00:11.202384331Z","hd":{"ts_event":"2024-11-01T08:00:11.202218198Z","rtype":10,"publisher_id":2,"instrument_id":38},"action":"A","side":"A","depth":8,"price":"234.750000000","size":50,"flags":130,"ts_in_delta":166133,"sequence":312865,"levels":[{"bid_px":"221.300000000","ask_px":"224.400000000","bid_sz":1000,"ask_sz":1000,"bid_ct":1,"ask_ct":1},{"bid_px":"220.000000000","ask_px":"225.000000000","bid_sz":2,"ask_sz":1,"bid_ct":1,"ask_ct":1},{"bid_px":"219.690000000","ask_px":"225.360000000","bid_sz":442,"ask_sz":1,"bid_ct":1,"ask_ct":1},{"bid_px":"219.000000000","ask_px":"225.490000000","bid_sz":1,"ask_sz":442,"bid_ct":1,"ask_ct":1},{"bid_px":"217.000000000","ask_px":"225.900000000","bid_sz":1525,"ask_sz":32,"bid_ct":1,"ask_ct":2},{"bid_px":"215.000000000","ask_px":"229.330000000","bid_sz":5,"ask_sz":9,"bid_ct":1,"ask_ct":2},{"bid_px":"213.000000000","ask_px":"233.670000000","bid_sz":5,"ask_sz":5,"bid_ct":1,"ask_ct":1},{"bid_px":"210.000000000","ask_px":"234.000000000","bid_sz":1,"ask_sz":20,"bid_ct":1,"ask_ct":1},{"bid_px":"204.500000000","ask_px":"234.750000000","bid_sz":2,"ask_sz":50,"bid_ct":1,"ask_ct":1},{"bid_px":"200.000000000","ask_px":"235.000000000","bid_sz":30,"ask_sz":2,"bid_ct":1,"ask_ct":1}],"symbol":"AAPL"}
{"ts_recv":"2024-11-01T08:00:11.207334983Z","hd":{"ts_event":"2024-11-01T08:00:11.207168883Z","rtype":10,"publisher_id":2,"instrument_id":38},"action":"A","side":"B","depth":0,"price":"221.400000000","size":1000,"flags":130,"ts_in_delta":166100,"sequence":312871,"levels":[{"bid_px":"221.400000000","ask_px":"224.400000000","bid_sz":1000,"ask_sz":1000,"bid_ct":1,"ask_ct":1},{"bid_px":"221.300000000","ask_px":"225.000000000","bid_sz":1000,"ask_sz":1,"bid_ct":1,"ask_ct":1},{"bid_px":"220.000000000","ask_px":"225.360000000","bid_sz":2,"ask_sz":1,"bid_ct":1,"ask_ct":1},{"bid_px":"219.690000000","ask_px":"225.490000000","bid_sz":442,"ask_sz":442,"bid_ct":1,"ask_ct":1},{"bid_px":"219.000000000","ask_px":"225.900000000","bid_sz":1,"ask_sz":32,"bid_ct":1,"ask_ct":2},{"bid_px":"217.000000000","ask_px":"229.330000000","bid_sz":1525,"ask_sz":9,"bid_ct":1,"ask_ct":2},{"bid_px":"215.000000000","ask_px":"233.670000000","bid_sz":5,"ask_sz":5,"bid_ct":1,"ask_ct":1},{"bid_px":"213.000000000","ask_px":"234.000000000","bid_sz":5,"ask_sz":20,"bid_ct":1,"ask_ct":1},{"bid_px":"210.000000000","ask_px":"234.750000000","bid_sz":1,"ask_sz":50,"bid_ct":1,"ask_ct":1},{"bid_px":"204.500000000","ask_px":"235.000000000","bid_sz":2,"ask_sz":2,"bid_ct":1,"ask_ct":1}],"symbol":"AAPL"}
{"ts_recv":"2024-11-01T08:00:11.207391361Z","hd":{"ts_event":"2024-11-01T08:00:11.207225273Z","rtype":10,"publisher_id":2,"instrument_id":38},"action":"C","side":"B","depth":1,"price":"221.300000000","size":1000,"flags":130,"ts_in_delta":166088,"sequence":312872,"levels":[{"bid_px":"221.400000000","ask_px":"224.400000000","bid_sz":1000,"ask_sz":1000,"bid_ct":1,"ask_ct":1},{"bid_px":"220.000000000","ask_px":"225.000000000","bid_sz":2,"ask_sz":1,"bid_ct":1,"ask_ct":1},{"bid_px":"219.690000000","ask_px":"225.360000000","bid_sz":442,"ask_sz":1,"bid_ct":1,"ask_ct":1},{"bid_px":"219.000000000","ask_px":"225.490000000","bid_sz":1,"ask_sz":442,"bid_ct":1,"ask_ct":1},{"bid_px":"217.000000000","ask_px":"225.900000000","bid_sz":1525,"ask_sz":32,"bid_ct":1,"ask_ct":2},{"bid_px":"215.000000000","ask_px":"229.330000000","bid_sz":5,"ask_sz":9,"bid_ct":1,"ask_ct":2},{"bid_px":"213.000000000","ask_px":"233.670000000","bid_sz":5,"ask_sz":5,"bid_ct":1,"ask_ct":1},{"bid_px":"210.000000000","ask_px":"234.000000000","bid_sz":1,"ask_sz":20,"bid_ct":1,"ask_ct":1},{"bid_px":"204.500000000","ask_px":"234.750000000","bid_sz":2,"ask_sz":50,"bid_ct":1,"ask_ct":1},{"bid_px":"200.000000000","ask_px":"235.000000000","bid_sz":30,"ask_sz":2,"bid_ct":1,"ask_ct":1}],"symbol":"AAPL"}
{"ts_recv":"2024-11-01T08:00:11.278220909Z","hd":{"ts_event":"2024-11-01T08:00:11.278054242Z","rtype":10,"publisher_id":2,"instrument_id":38},"action":"A","side":"B","depth":7,"price":"212.340000000","size":5,"flags":130,"ts_in_delta":166667,"sequence":313152,"levels":[{"bid_px":"221.400000000","ask_px":"224.400000000","bid_sz":1000,"ask_sz":1000,"bid_ct":1,"ask_ct":1},{"bid_px":"220.000000000","ask_px":"225.000000000","bid_sz":2,"ask_sz":1,"bid_ct":1,"ask_ct":1},{"bid_px":"219.690000000","ask_px":"225.360000000","bid_sz":442,"ask_sz":1,"bid_ct":1,"ask_ct":1},{"bid_px":"219.000000000","ask_px":"225.490000000","bid_sz":1,"ask_sz":442,"bid_ct":1,"ask_ct":1},{"bid_px":"217.000000000","ask_px":"225.900000000","bid_sz":1525,"ask_sz":32,"bid_ct":1,"ask_ct":2},{"bid_px":"215.000000000","ask_px":"229.330000000","bid_sz":5,"ask_sz":9,"bid_ct":1,"ask_ct":2},{"bid_px":"213.000000000","ask_px":"233.670000000","bid_sz":5,"ask_sz":5,"bid_ct":1,"ask_ct":1},{"bid_px":"212.340000000","ask_px":"234.000000000","bid_sz":5,"ask_sz":20,"bid_ct":1,"ask_ct":1},{"bid_px":"210.000000000","ask_px":"234.750000000","bid_sz":1,"ask_sz":50,"bid_ct":1,"ask_ct":1},{"bid_px":"204.500000000","ask_px":"235.000000000","bid_sz":2,"ask_sz":2,"bid_ct":1,"ask_ct":1}],"symbol":"AAPL"}
{"ts_recv":"2024-11-01T08:00:11.346660469Z","hd":{"ts_event":"2024-11-01T08:00:11.346493771Z","rtype":10,"publisher_id":2,"instrument_id":38},"action":"A","side":"B","depth":0,"price":"221.700000000","size":10,"flags":130,"ts_in_delta":166698,"sequence":313649,"levels":[{"bid_px":"221.700000000","ask_px":"224.400000000","bid_sz":10,"ask_sz":1000,"bid_ct":1,"ask_ct":1},{"bid_px":"221.400000000","ask_px":"225.000000000","bid_sz":1000,"ask_sz":1,"bid_ct":1,"ask_ct":1},{"bid_px":"220.000000000","ask_px":"225.360000000","bid_sz":2,"ask_sz":1,"bid_ct":1,"ask_ct":1},{"bid_px":"219.690000000","ask_px":"225.490000000","bid_sz":442,"ask_sz":442,"bid_ct":1,"ask_ct":1},{"bid_px":"219.000000000","ask_px":"225.900000000","bid_sz":1,"ask_sz":32,"bid_ct":1,"ask_ct":2},{"bid_px":"217.000000000","ask_px":"229.330000000","bid_sz":1525,"ask_sz":9,"bid_ct":1,"ask_ct":2},{"bid_px":"215.000000000","ask_px":"233.670000000","bid_sz":5,"ask_sz":5,"bid_ct":1,"ask_ct":1},{"bid_px":"213.000000000","ask_px":"234.000000000","bid_sz":5,"ask_sz":20,"bid_ct":1,"ask_ct":1},{"bid_px":"212.340000000","ask_px":"234.750000000","bid_sz":5,"ask_sz":50,"bid_ct":1,"ask_ct":1},{"bid_px":"210.000000000","ask_px":"235.000000000","bid_sz":1,"ask_sz":2,"bid_ct":1,"ask_ct":1}],"symbol":"AAPL"}
{"ts_recv":"2024-11-01T08:00:11.410487817Z","hd":{"ts_event":"2024-11-01T08:00:11.410321560Z","rtype":10,"publisher_id":2,"instrument_id":16244},"action":"A","side":"A","depth":2,"price":"252.300000000","size":1000,"flags":130,"ts_in_delta":166257,"sequence":313780,"levels":[{"bid_px":"250.110000000","ask_px":"250.940000000","bid_sz":50,"ask_sz":100,"bid_ct":1,"ask_ct":1},{"bid_px":"250.000000000","ask_px":"250.990000000","bid_sz":2,"ask_sz":50,"bid_ct":2,"ask_ct":1},{"bid_px":"249.930000000","ask_px":"252.300000000","bid_sz":10,"ask_sz":1000,"bid_ct":1,"ask_ct":1},{"bid_px":"249.800000000","ask_px":"252.400000000","bid_sz":199,"ask_sz":1000,"bid_ct":1,"ask_ct":1},{"bid_px":"249.770000000","ask_px":"253.650000000","bid_sz":50,"ask_sz":400,"bid_ct":1,"ask_ct":1},{"bid_px":"249.700000000","ask_px":"255.000000000","bid_sz":1000,"ask_sz":85,"bid_ct":1,"ask_ct":2},{"bid_px":"249.600000000","ask_px":"260.000000000","bid_sz":1000,"ask_sz":48,"bid_ct":1,"ask_ct":1},{"bid_px":"248.500000000","ask_px":"262.660000000","bid_sz":40,"ask_sz":56,"bid_ct":1,"ask_ct":1},{"bid_px":"248.200000000","ask_px":"264.940000000","bid_sz":1000,"ask_sz":7,"bid_ct":1,"ask_ct":1},{"bid_px":"247.150000000","ask_px":"265.000000000","bid_sz":400,"ask_sz":102,"bid_ct":1,"ask_ct":3}],"symbol":"TSLA"}
{"ts_recv":"2024-11-01T08:00:11.410540052Z","hd":{"ts_event":"2024-11-01T08:00:11.410374270Z","rtype":10,"publisher_id":2,"instrument_id":16244},"action":"C","side":"A","depth":3,"price":"252.400000000","size":1000,"flags":130,"ts_in_delta":165782,"sequence":313781,"levels":[{"bid_px":"250.110000000","ask_px":"250.940000000","bid_sz":50,"ask_sz":100,"bid_ct":1,"ask_ct":1},{"bid_px":"250.000000000","ask_px":"250.990000000","bid_sz":2,"ask_sz":50,"bid_ct":2,"ask_ct":1},{"bid_px":"249.930000000","ask_px":"252.300000000","bid_sz":10,"ask_sz":1000,"bid_ct":1,"ask_ct":1},{"bid_px":"249.800000000","ask_px":"253.650000000","bid_sz":199,"ask_sz":400,"bid_ct":1,"ask_ct":1},{"bid_px":"249.770000000","ask_px":"255.000000000","bid_sz":50,"ask_sz":85,"bid_ct":1,"ask_ct":2},{"bid_px":"249.700000000","ask_px":"260.000000000","bid_sz":1000,"ask_sz":48,"bid_ct":1,"ask_ct":1},{"bid_px":"249.600000000","ask_px":"262.660000000","bid_sz":1000,"ask_sz":56,"bid_ct":1,"ask_ct":1},{"bid_px":"248.500000000","ask_px":"264.940000000","bid_sz":40,"ask_sz":7,"bid_ct":1,"ask_ct":1},{"bid_px":"248.200000000","ask_px":"265.000000000","bid_sz":1000,"ask_sz":102,"bid_ct":1,"ask_ct":3},{"bid_px":"247.150000000","ask_px":"267.800000000","bid_sz":400,"ask_sz":30,"bid_ct":1,"ask_ct":1}],"symbol":"TSLA"}
{"ts_recv":"2024-11-01T08:00:11.515403085Z","hd":{"ts_event":"2024-11-01T08:00:11.515236364Z","rtype":10,"publisher_id":2,"instrument_id":10888},"action":"A","side":"A","depth":2,"price":"415.350000000","size":59,"flags":130,"ts_in_delta":166721,"sequence":313949,"levels":[{"bid_px":"410.000000000","ask_px":"414.000000000","bid_sz":1,"ask_sz":468,"bid_ct":1,"ask_ct":2},{"bid_px":"409.750000000","ask_px":"415.070000000","bid_sz":3,"ask_sz":246,"bid_ct":1,"ask_ct":1},{"bid_px":"409.080000000","ask_px":"415.350000000","bid_sz":2,"ask_sz":59,"bid_ct":1,"ask_ct":1},{"bid_px":"409.000000000","ask_px":"420.000000000","bid_sz":2,"ask_sz":3,"bid_ct":1,"ask_ct":1},{"bid_px":"408.970000000","ask_px":"440.000000000","bid_sz":12,"ask_sz":35,"bid_ct":1,"ask_ct":1},{"bid_px":"408.960000000","ask_px":"445.000000000","bid_sz":5,"ask_sz":25,"bid_ct":1,"ask_ct":1},{"bid_px":"407.600000000","ask_px":"445.680000000","bid_sz":16,"ask_sz":3,"bid_ct":1,"ask_ct":1},{"bid_px":"407.000000000","ask_px":"448.000000000","bid_sz":17,"ask_sz":15,"bid_ct":3,"ask_ct":2},{"bid_px":"406.350000000","ask_px":"450.000000000","bid_sz":82,"ask_sz":10,"bid_ct":2,"ask_ct":1},{"bid_px":"406.000000000","ask_px":"467.560000000","bid_sz":7,"ask_sz":5,"bid_ct":1,"ask_ct":1}],"symbol":"MSFT"}
{"ts_recv":"2024-11-01T08:00:11.521203105Z","hd":{"ts_event":"2024-11-01T08:00:11.521036945Z","rtype":10,"publisher_id":2,"instrument_id":10888},"action":"A","side":"A","depth":2,"price":"415.350000000","size":25,"flags":130,"ts_in_delta":166160,"sequence":313978,"levels":[{"bid_px":"410.000000000","ask_px":"414.000000000","bid_sz":1,"ask_sz":468,"bid_ct":1,"ask_ct":2},{"bid_px":"409.750000000","ask_px":"415.070000000","bid_sz":3,"ask_sz":246,"bid_ct":1,"ask_ct":1},{"bid_px":"409.080000000","ask_px":"415.350000000","bid_sz":2,"ask_sz":84,"bid_ct":1,"ask_ct":2},{"bid_px":"409.000000000","ask_px":"420.000000000","bid_sz":2,"ask_sz":3,"bid_ct":1,"ask_ct":1},{"bid_px":"408.970000000","ask_px":"440.000000000","bid_sz":12,"ask_sz":35,"bid_ct":1,"ask_ct":1},{"bid_px":"408.960000000","ask_px":"445.000000000","bid_sz":5,"ask_sz":25,"bid_ct":1,"ask_ct":1},{"bid_px":"407.600000000","ask_px":"445.680000000","bid_sz":16,"ask_sz":3,"bid_ct":1,"ask_ct":1},{"bid_px":"407.000000000","ask_px":"448.000000000","bid_sz":17,"ask_sz":15,"bid_ct":3,"ask_ct":2},{"bid_px":"406.350000000","ask_px":"450.000000000","bid_sz":82,"ask_sz":10,"bid_ct":2,"ask_ct":1},{"bid_px":"406.000000000","ask_px":"467.560000000","bid_sz":7,"ask_sz":5,"bid_ct":1,"ask_ct":1}],"symbol":"MSFT"}
{"ts_recv":"2024-11-01T08:00:11.521809062Z","hd":{"ts_event":"2024-11-01T08:00:11.521642932Z","rtype":10,"publisher_id":2,"instrument_id":10888},"action":"A","side":"B","depth":9,"price":"406.080000000","size":5,"flags":130,"ts_in_delta":166130,"sequence":313979,"levels":[{"bid_px":"410.000000000","ask_px":"414.000000000","bid_sz":1,"ask_sz":468,"bid_ct":1,"ask_ct":2},{"bid_px":"409.750000000","ask_px":"415.070000000","bid_sz":3,"ask_sz":246,"bid_ct":1,"ask_ct":1},{"bid_px":"409.080000000","ask_px":"415.350000000","bid_sz":2,"ask_sz":84,"bid_ct":1,"ask_ct":2},{"bid_px":"409.000000000","ask_px":"420.000000000","bid_sz":2,"ask_sz":3,"bid_ct":1,"ask_ct":1},{"bid_px":"408.970000000","ask_px":"440.000000000","bid_sz":12,"ask_sz":35,"bid_ct":1,"ask_ct":1},{"bid_px":"408.960000000","ask_px":"445.000000000","bid_sz":5,"ask_sz":25,"bid_ct":1,"ask_ct":1},{"bid_px":"407.600000000","ask_px":"445.680000000","bid_sz":16,"ask_sz":3,"bid_ct":1,"ask_ct":1},{"bid_px":"407.000000000","ask_px":"448.000000000","bid_sz":17,"ask_sz":15,"bid_ct":3,"ask_ct":2},{"bid_px":"406.350000000","ask_px":"450.000000000","bid_sz":82,"ask_sz":10,"bid_ct":2,"ask_ct":1},{"bid_px":"406.080000000","ask_px":"467.560000000","bid_sz":5,"ask_sz":5,"bid_ct":1,"ask_ct":1}],"symbol":"MSFT"}
{"ts_recv":"2024-11-01T08:00:11.588640971Z","hd":{"ts_event":"2024-11-01T08:00:11.588474530Z","rtype":10,"publisher_id":2,"instrument_id":16244},"action":"A","side":"A","depth":5,"price":"260.000000000","size":100,"flags":130,"ts_in_delta":166441,"sequence":314051,"levels":[{"bid_px":"250.110000000","ask_px":"250.940000000","bid_sz":50,"ask_sz":100,"bid_ct":1,"ask_ct":1},{"bid_px":"250.000000000","ask_px":"250.990000000","bid_sz":2,"ask_sz":50,"bid_ct":2,"ask_ct":1},{"bid_px":"249.930000000","ask_px":"252.300000000","bid_sz":10,"ask_sz":1000,"bid_ct":1,"ask_ct":1},{"bid_px":"249.800000000","ask_px":"253.650000000","bid_sz":199,"ask_sz":400,"bid_ct":1,"ask_ct":1},{"bid_px":"249.770000000","ask_px":"255.000000000","bid_sz":50,"ask_sz":85,"bid_ct":1,"ask_ct":2},{"bid_px":"249.700000000","ask_px":"260.000000000","bid_sz":1000,"ask_sz":148,"bid_ct":1,"ask_ct":2},{"bid_px":"249.600000000","ask_px":"262.660000000","bid_sz":1000,"ask_sz":56,"bid_ct":1,"ask_ct":1},{"bid_px":"248.500000000","ask_px":"264.940000000","bid_sz":40,"ask_sz":7,"bid_ct":1,"ask_ct":1},{"bid_px":"248.200000000","ask_px":"265.000000000","bid_sz":1000,"ask_sz":102,"bid_ct":1,"ask_ct":3},{"bid_px":"247.150000000","ask_px":"267.800000000","bid_sz":400,"ask_sz":30,"bid_ct":1,"ask_ct":1}],"symbol":"TSLA"}
{"ts_recv":"2024-11-01T08:00:11.625867129Z","hd":{"ts_event":"2024-11-01T08:00:11.625700885Z","rtype":10,"publisher_id":2,"instrument_id":780},"action":"A","side":"B","depth":0,"price":"308.380000000","size":25,"flags":130,"ts_in_delta":166244,"sequence":314118,"levels":[{"bid_px":"308.380000000","ask_px":"330.140000000","bid_sz":25,"ask_sz":25,"bid_ct":1,"ask_ct":1},{"bid_px":null,"ask_px":null,"bid_sz":0,"ask_sz":0,"bid_ct":0,"ask_ct":0},{"bid_px":null,"ask_px":null,"bid_sz":0,"ask_sz":0,"bid_ct":0,"ask_ct":0},{"bid_px":null,"ask_px":null,"bid_sz":0,"ask_sz":0,"bid_ct":0,"ask_ct":0},{"bid_px":null,"ask_px":null,"bid_sz":0,"ask_sz":0,"bid_ct":0,"ask_ct":0},{"bid_px":null,"ask_px":null,"bid_sz":0,"ask_sz":0,"bid_ct":0,"ask_ct":0},{"bid_px":null,"ask_px":null,"bid_sz":0,"ask_sz":0,"bid_ct":0,"ask_ct":0},{"bid_px":null,"ask_px":null,"bid_sz":0,"ask_sz":0,"bid_ct":0,"ask_ct":0},{"bid_px":null,"ask_px":null,"bid_sz":0,"ask_sz":0,"bid_ct":0,"ask_ct":0},{"bid_px":null,"ask_px":null,"bid_sz":0,"ask_sz":0,"bid_ct":0,"ask_ct":0}],"symbol":"AMGN"}
{"ts_recv":"2024-11-01T08:00:11.716180528Z","hd":{"ts_event":"2024-11-01T08:00:11.716014319Z","rtype":10,"publisher_id":2,"instrument_id":16244},"action":"A","side":"A","depth":5,"price":"260.000000000","size":20,"flags":130,"ts_in_delta":166209,"sequence":314250,"levels":[{"bid_px":"250.110000000","ask_px":"250.940000000","bid_sz":50,"ask_sz":100,"bid_ct":1,"ask_ct":1},{"bid_px":"250.000000000","ask_px":"250.990000000","bid_sz":2,"ask_sz":50,"bid_ct":2,"ask_ct":1},{"bid_px":"249.930000000","ask_px":"252.300000000","bid_sz":10,"ask_sz":1000,"bid_ct":1,"ask_ct":1},{"bid_px":"249.800000000","ask_px":"253.650000000","bid_sz":199,"ask_sz":400,"bid_ct":1,"ask_ct":1},{"bid_px":"249.770000000","ask_px":"255.000000000","bid_sz":50,"ask_sz":85,"bid_ct":1,"ask_ct":2},{"bid_px":"249.700000000","ask_px":"260.000000000","bid_sz":1000,"ask_sz":168,"bid_ct":1,"ask_ct":3},{"bid_px":"249.600000000","ask_px":"262.660000000","bid_sz":1000,"ask_sz":56,"bid_ct":1,"ask_ct":1},{"bid_px":"248.500000000","ask_px":"264.940000000","bid_sz":40,"ask_sz":7,"bid_ct":1,"ask_ct":1},{"bid_px":"248.200000000","ask_px":"265.000000000","bid_sz":1000,"ask_sz":102,"bid_ct":1,"ask_ct":3},{"bid_px":"247.150000000","ask_px":"267.800000000","bid_sz":400,"ask_sz":30,"bid_ct":1,"ask_ct":1}],"symbol":"TSLA"}
{"ts_recv":"2024-11-01T08:00:11.744818545Z","hd":{"ts_event":"2024-11-01T08:00:11.744652546Z","rtype":10,"publisher_id":2,"instrument_id":16244},"action":"C","side":"B","depth":0,"price":"250.110000000","size":50,"flags":130,"ts_in_delta":165999,"sequence":314271,"levels":[{"bid_px":"250.000000000","ask_px":"250.940000000","bid_sz":2,"ask_sz":100,"bid_ct":2,"ask_ct":1},{"bid_px":"249.930000000","ask_px":"250.990000000","bid_sz":10,"ask_sz":50,"bid_ct":1,"ask_ct":1},{"bid_px":"249.800000000","ask_px":"252.300000000","bid_sz":199,"ask_sz":1000,"bid_ct":1,"ask_ct":1},{"bid_px":"249.770000000","ask_px":"253.650000000","bid_sz":50,"ask_sz":400,"bid_ct":1,"ask_ct":1},{"bid_px":"249.700000000","ask_px":"255.000000000","bid_sz":1000,"ask_sz":85,"bid_ct":1,"ask_ct":2},{"bid_px":"249.600000000","ask_px":"260.000000000","bid_sz":1000,"ask_sz":168,"bid_ct":1,"ask_ct":3},{"bid_px":"248.500000000","ask_px":"262.660000000","bid_sz":40,"ask_sz":56,"bid_ct":1,"ask_ct":1},{"bid_px":"248.200000000","ask_px":"264.940000000","bid_sz":1000,"ask_sz":7,"bid_ct":1,"ask_ct":1},{"bid_px":"247.150000000","ask_px":"265.000000000","bid_sz":400,"ask_sz":102,"bid_ct":1,"ask_ct":3},{"bid_px":"247.000000000","ask_px":"267.800000000","bid_sz":12,"ask_sz":30,"bid_ct":1,"ask_ct":1}],"symbol":"TSLA"}
{"ts_recv":"2024-11-01T08:00:11.744831009Z","hd":{"ts_event":"2024-11-01T08:00:11.744664963Z","rtype":10,"publisher_id":2,"instrument_id":16244},"action":"A","side":"B","depth":0,"price":"250.060000000","size":50,"flags":130,"ts_in_delta":166046,"sequence":314272,"levels":[{"bid_px":"250.060000000","ask_px":"250.940000000","bid_sz":50,"ask_sz":100,"bid_ct":1,"ask_ct":1},{"bid_px":"250.000000000","ask_px":"250.990000000","bid_sz":2,"ask_sz":50,"bid_ct":2,"ask_ct":1},{"bid_px":"249.930000000","ask_px":"252.300000000","bid_sz":10,"ask_sz":1000,"bid_ct":1,"ask_ct":1},{"bid_px":"249.800000000","ask_px":"253.650000000","bid_sz":199,"ask_sz":400,"bid_ct":1,"ask_ct":1},{"bid_px":"249.770000000","ask_px":"255.000000000","bid_sz":50,"ask_sz":85,"bid_ct":1,"ask_ct":2},{"bid_px":"249.700000000","ask_px":"260.000000000","bid_sz":1000,"ask_sz":168,"bid_ct":1,"ask_ct":3},{"bid_px":"249.600000000","ask_px":"262.660000000","bid_sz":1000,"ask_sz":56,"bid_ct":1,"ask_ct":1},{"bid_px":"248.500000000","ask_px":"264.940000000","bid_sz":40,"ask_sz":7,"bid_ct":1,"ask_ct":1},{"bid_px":"248.200000000","ask_px":"265.000000000","bid_sz":1000,"ask_sz":102,"bid_ct":1,"ask_ct":3},{"bid_px":"247.150000000","ask_px":"267.800000000","bid_sz":400,"ask_sz":30,"bid_ct":1,"ask_ct":1}],"symbol":"TSLA"}
{"ts_recv":"2024-11-01T08:00:11.744846096Z","hd":{"ts_event":"2024-11-01T08:00:11.744679696Z","rtype":10,"publisher_id":2,"instrument_id":16244},"action":"C","side":"B","depth":0,"price":"250.060000000","size":50,"flags":130,"ts_in_delta":166400,"sequence":314273,"levels":[{"bid_px":"250.000000000","ask_px":"250.940000000","bid_sz":2,"ask_sz":100,"bid_ct":2,"ask_ct":1},{"bid_px":"249.930000000","ask_px":"250.990000000","bid_sz":10,"ask_sz":50,"bid_ct":1,"ask_ct":1},{"bid_px":"249.800000000","ask_px":"252.300000000","bid_sz":199,"ask_sz":1000,"bid_ct":1,"ask_ct":1},{"bid_px":"249.770000000","ask_px":"253.650000000","bid_sz":50,"ask_sz":400,"bid_ct":1,"ask_ct":1},{"bid_px":"249.700000000","ask_px":"255.000000000","bid_sz":1000,"ask_sz":85,"bid_ct":1,"ask_ct":2},{"bid_px":"249.600000000","ask_px":"260.000000000","bid_sz":1000,"ask_sz":168,"bid_ct":1,"ask_ct":3},{"bid_px":"248.500000000","ask_px":"262.660000000","bid_sz":40,"ask_sz":56,"bid_ct":1,"ask_ct":1},{"bid_px":"248.200000000","ask_px":"264.940000000","bid_sz":1000,"ask_sz":7,"bid_ct":1,"ask_ct":1},{"bid_px":"247.150000000","ask_px":"265.000000000","bid_sz":400,"ask_sz":102,"bid_ct":1,"ask_ct":3},{"bid_px":"247.000000000","ask_px":"267.800000000","bid_sz":12,"ask_sz":30,"bid_ct":1,"ask_ct":1}],"symbol":"TSLA"}
{"ts_recv":"2024-11-01T08:00:11.798934057Z","hd":{"ts_event":"2024-11-01T08:00:11.798767560Z","rtype":10,"publisher_id":2,"instrument_id":16244},"action":"A","side":"B","depth":0,"price":"250.020000000","size":50,"flags":130,"ts_in_delta":166497,"sequence":314386,"levels":[{"bid_px":"250.020000000","ask_px":"250.940000000","bid_sz":50,"ask_sz":100,"bid_ct":1,"ask_ct":1},{"bid_px":"250.000000000","ask_px":"250.990000000","bid_sz":2,"ask_sz":50,"bid_ct":2,"ask_ct":1},{"bid_px":"249.930000000","ask_px":"252.300000000","bid_sz":10,"ask_sz":1000,"bid_ct":1,"ask_ct":1},{"bid_px":"249.800000000","ask_px":"253.650000000","bid_sz":199,"ask_sz":400,"bid_ct":1,"ask_ct":1},{"bid_px":"249.770000000","ask_px":"255.000000000","bid_sz":50,"ask_sz":85,"bid_ct":1,"ask_ct":2},{"bid_px":"249.700000000","ask_px":"260.000000000","bid_sz":1000,"ask_sz":168,"bid_ct":1,"ask_ct":3},{"bid_px":"249.600000000","ask_px":"262.660000000","bid_sz":1000,"ask_sz":56,"bid_ct":1,"ask_ct":1},{"bid_px":"248.500000000","ask_px":"264.940000000","bid_sz":40,"ask_sz":7,"bid_ct":1,"ask_ct":1},{"bid_px":"248.200000000","ask_px":"265.000000000","bid_sz":1000,"ask_sz":102,"bid_ct":1,"ask_ct":3},{"bid_px":"247.150000000","ask_px":"267.800000000","bid_sz":400,"ask_sz":30,"bid_ct":1,"ask_ct":1}],"symbol":"TSLA"}
{"ts_recv":"2024-11-01T08:00:11.814157748Z","hd":{"ts_event":"2024-11-01T08:00:11.813991242Z","rtype":10,"publisher_id":2,"instrument_id":11667},"action":"A","side":"B","depth":8,"price":"132.760000000","size":4,"flags":130,"ts_in_delta":166506,"sequence":314398,"levels":[{"bid_px":"134.680000000","ask_px":"134.990000000","bid_sz":100,"ask_sz":10,"bid_ct":1,"ask_ct":1},{"bid_px":"134.500000000","ask_px":"135.000000000","bid_sz":520,"ask_sz":38,"bid_ct":2,"ask_ct":3},{"bid_px":"134.410000000","ask_px":"135.100000000","bid_sz":61,"ask_sz":10,"bid_ct":2,"ask_ct":1},{"bid_px":"134.380000000","ask_px":"135.230000000","bid_sz":18,"ask_sz":360,"bid_ct":1,"ask_ct":1},{"bid_px":"134.210000000","ask_px":"135.300000000","bid_sz":20,"ask_sz":1000,"bid_ct":1,"ask_ct":1},{"bid_px":"134.200000000","ask_px":"135.400000000","bid_sz":3,"ask_sz":10,"bid_ct":1,"ask_ct":1},{"bid_px":"134.000000000","ask_px":"135.420000000","bid_sz":1,"ask_sz":1,"bid_ct":1,"ask_ct":1},{"bid_px":"133.160000000","ask_px":"135.820000000","bid_sz":1,"ask_sz":1,"bid_ct":1,"ask_ct":1},{"bid_px":"132.760000000","ask_px":"135.990000000","bid_sz":104,"ask_sz":20,"bid_ct":2,"ask_ct":1},{"bid_px":"132.700000000","ask_px":"136.100000000","bid_sz":4,"ask_sz":1000,"bid_ct":1,"ask_ct":1}],"symbol":"NVDA"}
{"ts_recv":"2024-11-01T08:00:11.838828055Z","hd":{"ts_event":"2024-11-01T08:00:11.838662245Z","rtype":10,"publisher_id":2,"instrument_id":16244},"action":"C","side":"A","depth":1,"price":"250.990000000","size":50,"flags":130,"ts_in_delta":165810,"sequence":314431,"levels":[{"bid_px":"250.020000000","ask_px":"250.940000000","bid_sz":50,"ask_sz":100,"bid_ct":1,"ask_ct":1},{"bid_px":"250.000000000","ask_px":"252.300000000","bid_sz":2,"ask_sz":1000,"bid_ct":2,"ask_ct":1},{"bid_px":"249.930000000","ask_px":"253.650000000","bid_sz":10,"ask_sz":400,"bid_ct":1,"ask_ct":1},{"bid_px":"249.800000000","ask_px":"255.000000000","bid_sz":199,"ask_sz":85,"bid_ct":1,"ask_ct":2},{"bid_px":"249.770000000","ask_px":"260.000000000","bid_sz":50,"ask_sz":168,"bid_ct":1,"ask_ct":3},{"bid_px":"249.700000000","ask_px":"262.660000000","bid_sz":1000,"ask_sz":56,"bid_ct":1,"ask_ct":1},{"bid_px":"249.600000000","ask_px":"264.940000000","bid_sz":1000,"ask_sz":7,"bid_ct":1,"ask_ct":1},{"bid_px":"248.500000000","ask_px":"265.000000000","bid_sz":40,"ask_sz":102,"bid_ct":1,"ask_ct":3},{"bid_px":"248.200000000","ask_px":"267.800000000","bid_sz":1000,"ask_sz":30,"bid_ct":1,"ask_ct":1},{"bid_px":"247.150000000","ask_px":"268.670000000","bid_sz":400,"ask_sz":100,"bid_ct":1,"ask_ct":1}],"symbol":"TSLA"}
{"ts_recv":"2024-11-01T08:00:11.839112275Z","hd":{"ts_event":"2024-11-01T08:00:11.838946435Z","rtype":10,"publisher_id":2,"instrument_id":16244},"action":"C","side":"A","depth":1,"price":"252.300000000","size":1000,"flags":130,"ts_in_delta":165840,"sequence":314437,"levels":[{"bid_px":"250.020000000","ask_px":"250.940000000","bid_sz":50,"ask_sz":100,"bid_ct":1,"ask_ct":1},{"bid_px":"250.000000000","ask_px":"253.650000000","bid_sz":2,"ask_sz":400,"bid_ct":2,"ask_ct":1},{"bid_px":"249.930000000","ask_px":"255.000000000","bid_sz":10,"ask_sz":85,"bid_ct":1,"ask_ct":2},{"bid_px":"249.800000000","ask_px":"260.000000000","bid_sz":199,"ask_sz":168,"bid_ct":1,"ask_ct":3},{"bid_px":"249.770000000","ask_px":"262.660000000","bid_sz":50,"ask_sz":56,"bid_ct":1,"ask_ct":1},{"bid_px":"249.700000000","ask_px":"264.940000000","bid_sz":1000,"ask_sz":7,"bid_ct":1,"ask_ct":1},{"bid_px":"249.600000000","ask_px":"265.000000000","bid_sz":1000,"ask_sz":102,"bid_ct":1,"ask_ct":3},{"bid_px":"248.500000000","ask_px":"267.800000000","bid_sz":40,"ask_sz":30,"bid_ct":1,"ask_ct":1},{"bid_px":"248.200000000","ask_px":"268.670000000","bid_sz":1000,"ask_sz":100,"bid_ct":1,"ask_ct":1},{"bid_px":"247.150000000","ask_px":"269.580000000","bid_sz":400,"ask_sz":100,"bid_ct":1,"ask_ct":1}],"symbol":"TSLA"}
{"ts_recv":"2024-11-01T08:00:11.839138765Z","hd":{"ts_event":"2024-11-01T08:00:11.838973149Z","rtype":10,"publisher_id":2,"instrument_id":16244},"action":"C","side":"B","depth":0,"price":"250.020000000","size":50,"flags":130,"ts_in_delta":165616,"sequence":314438,"levels":[{"bid_px":"250.000000000","ask_px":"250.940000000","bid_sz":2,"ask_sz":100,"bid_ct":2,"ask_ct":1},{"bid_px":"249.930000000","ask_px":"253.650000000","bid_sz":10,"ask_sz":400,"bid_ct":1,"ask_ct":1},{"bid_px":"249.800000000","ask_px":"255.000000000","bid_sz":199,"ask_sz":85,"bid_ct":1,"ask_ct":2},{"bid_px":"249.770000000","ask_px":"260.000000000","bid_sz":50,"ask_sz":168,"bid_ct":1,"ask_ct":3},{"bid_px":"249.700000000","ask_px":"262.660000000","bid_sz":1000,"ask_sz":56,"bid_ct":1,"ask_ct":1},{"bid_px":"249.600000000","ask_px":"264.940000000","bid_sz":1000,"ask_sz":7,"bid_ct":1,"ask_ct":1},{"bid_px":"248.500000000","ask_px":"265.000000000","bid_sz":40,"ask_sz":102,"bid_ct":1,"ask_ct":3},{"bid_px":"248.200000000","ask_px":"267.800000000","bid_sz":1000,"ask_sz":30,"bid_ct":1,"ask_ct":1},{"bid_px":"247.150000000","ask_px":"268.670000000","bid_sz":400,"ask_sz":100,"bid_ct":1,"ask_ct":1},{"bid_px":"247.000000000","ask_px":"269.580000000","bid_sz":12,"ask_sz":100,"bid_ct":1,"ask_ct":1}],"symbol":"TSLA"}
{"ts_recv":"2024-11-01T08:00:11.839607412Z","hd":{"ts_event":"2024-11-01T08:00:11.839441795Z","rtype":10,"publisher_id":2,"instrument_id":16244},"action":"C","side":"A","depth":0,"price":"250.940000000","size":100,"flags":130,"ts_in_delta":165617,"sequence":314441,"levels":[{"bid_px":"250.000000000","ask_px":"253.650000000","bid_sz":2,"ask_sz":400,"bid_ct":2,"ask_ct":1},{"bid_px":"249.930000000","ask_px":"255.000000000","bid_sz":10,"ask_sz":85,"bid_ct":1,"ask_ct":2},{"bid_px":"249.800000000","ask_px":"260.000000000","bid_sz":199,"ask_sz":168,"bid_ct":1,"ask_ct":3},{"bid_px":"249.770000000","ask_px":"262.660000000","bid_sz":50,"ask_sz":56,"bid_ct":1,"ask_ct":1},{"bid_px":"249.700000000","ask_px":"264.940000000","bid_sz":1000,"ask_sz":7,"bid_ct":1,"ask_ct":1},{"bid_px":"249.600000000","ask_px":"265.000000000","bid_sz":1000,"ask_sz":102,"bid_ct":1,"ask_ct":3},{"bid_px":"248.500000000","ask_px":"267.800000000","bid_sz":40,"ask_sz":30,"bid_ct":1,"ask_ct":1},{"bid_px":"248.200000000","ask_px":"268.670000000","bid_sz":1000,"ask_sz":100,"bid_ct":1,"ask_ct":1},{"bid_px":"247.150000000","ask_px":"269.580000000","bid_sz":400,"ask_sz":100,"bid_ct":1,"ask_ct":1},{"bid_px":"247.000000000","ask_px":"270.000000000","bid_sz":12,"ask_sz":118,"bid_ct":1,"ask_ct":3}],"symbol":"TSLA"}
{"ts_recv":"2024-11-01T08:00:11.839620531Z","hd":{"ts_event":"2024-11-01T08:00:11.839454020Z","rtype":10,"publisher_id":2,"instrument_id":16244},"action":"A","side":"A","depth":0,"price":"250.980000000","size":100,"flags":130,"ts_in_delta":166511,"sequence":314442,"levels":[{"bid_px":"250.000000000","ask_px":"250.980000000","bid_sz":2,"ask_sz":100,"bid_ct":2,"ask_ct":1},{"bid_px":"249.930000000","ask_px":"253.650000000","bid_sz":10,"ask_sz":400,"bid_ct":1,"ask_ct":1},{"bid_px":"249.800000000","ask_px":"255.000000000","bid_sz":199,"ask_sz":85,"bid_ct":1,"ask_ct":2},{"bid_px":"249.770000000","ask_px":"260.000000000","bid_sz":50,"ask_sz":168,"bid_ct":1,"ask_ct":3},{"bid_px":"249.700000000","ask_px":"262.660000000","bid_sz":1000,"ask_sz":56,"bid_ct":1,"ask_ct":1},{"bid_px":"249.600000000","ask_px":"264.940000000","bid_sz":1000,"ask_sz":7,"bid_ct":1,"ask_ct":1},{"bid_px":"248.500000000","ask_px":"265.000000000","bid_sz":40,"ask_sz":102,"bid_ct":1,"ask_ct":3},{"bid_px":"248.200000000","ask_px":"267.800000000","bid_sz":1000,"ask_sz":30,"bid_ct":1,"ask_ct":1},{"bid_px":"247.150000000","ask_px":"268.670000000","bid_sz":400,"ask_sz":100,"bid_ct":1,"ask_ct":1},{"bid_px":"247.000000000","ask_px":"269.580000000","bid_sz":12,"ask_sz":100,"bid_ct":1,"ask_ct":1}],"symbol":"TSLA"}
{"ts_recv":"2024-11-01T08:00:11.839848675Z","hd":{"ts_event":"2024-11-01T08:00:11.839683089Z","rtype":10,"publisher_id":2,"instrument_id":16244},"action":"C","side":"A","depth":0,"price":"250.980000000","size":100,"flags":130,"ts_in_delta":165586,"sequence":314443,"levels":[{"bid_px":"250.000000000","ask_px":"253.650000000","bid_sz":2,"ask_sz":400,"bid_ct":2,"ask_ct":1},{"bid_px":"249.930000000","ask_px":"255.000000000","bid_sz":10,"ask_sz":85,"bid_ct":1,"ask_ct":2},{"bid_px":"249.800000000","ask_px":"260.000000000","bid_sz":199,"ask_sz":168,"bid_ct":1,"ask_ct":3},{"bid_px":"249.770000000","ask_px":"262.660000000","bid_sz":50,"ask_sz":56,"bid_ct":1,"ask_ct":1},{"bid_px":"249.700000000","ask_px":"264.940000000","bid_sz":1000,"ask_sz":7,"bid_ct":1,"ask_ct":1},{"bid_px":"249.600000000","ask_px":"265.000000000","bid_sz":1000,"ask_sz":102,"bid_ct":1,"ask_ct":3},{"bid_px":"248.500000000","ask_px":"267.800000000","bid_sz":40,"ask_sz":30,"bid_ct":1,"ask_ct":1},{"bid_px":"248.200000000","ask_px":"268.670000000","bid_sz":1000,"ask_sz":100,"bid_ct":1,"ask_ct":1},{"bid_px":"247.150000000","ask_px":"269.580000000","bid_sz":400,"ask_sz":100,"bid_ct":1,"ask_ct":1},{"bid_px":"247.000000000","ask_px":"270.000000000","bid_sz":12,"ask_sz":118,"bid_ct":1,"ask_ct":3}],"symbol":"TSLA"}
{"ts_recv":"2024-11-01T08:00:11.839861372Z","hd":{"ts_event":"2024-11-01T08:00:11.839695448Z","rtype":10,"publisher_id":2,"instrument_id":16244},"action":"A","side":"A","depth":0,"price":"251.010000000","size":100,"flags":130,"ts_in_delta":165924,"sequence":314444,"levels":[{"bid_px":"250.000000000","ask_px":"251.010000000","bid_sz":2,"ask_sz":100,"bid_ct":2,"ask_ct":1},{"bid_px":"249.930000000","ask_px":"253.650000000","bid_sz":10,"ask_sz":400,"bid_ct":1,"ask_ct":1},{"bid_px":"249.800000000","ask_px":"255.000000000","bid_sz":199,"ask_sz":85,"bid_ct":1,"ask_ct":2},{"bid_px":"249.770000000","ask_px":"260.000000000","bid_sz":50,"ask_sz":168,"bid_ct":1,"ask_ct":3},{"bid_px":"249.700000000","ask_px":"262.660000000","bid_sz":1000,"ask_sz":56,"bid_ct":1,"ask_ct":1},{"bid_px":"249.600000000","ask_px":"264.940000000","bid_sz":1000,"ask_sz":7,"bid_ct":1,"ask_ct":1},{"bid_px":"248.500000000","ask_px":"265.000000000","bid_sz":40,"ask_sz":102,"bid_ct":1,"ask_ct":3},{"bid_px":"248.200000000","ask_px":"267.800000000","bid_sz":1000,"ask_sz":30,"bid_ct":1,"ask_ct":1},{"bid_px":"247.150000000","ask_px":"268.670000000","bid_sz":400,"ask_sz":100,"bid_ct":1,"ask_ct":1},{"bid_px":"247.000000000","ask_px":"269.580000000","bid_sz":12,"ask_sz":100,"bid_ct":1,"ask_ct":1}],"symbol":"TSLA"}
{"ts_recv":"2024-11-01T08:00:11.840870983Z","hd":{"ts_event":"2024-11-01T08:00:11.840705256Z","rtype":10,"publisher_id":2,"instrument_id":16244},"action":"C","side":"A","depth":0,"price":"251.010000000","size":100,"flags":130,"ts_in_delta":165727,"sequence":314447,"levels":[{"bid_px":"250.000000000","ask_px":"253.650000000","bid_sz":2,"ask_sz":400,"bid_ct":2,"ask_ct":1},{"bid_px":"249.930000000","ask_px":"255.000000000","bid_sz":10,"ask_sz":85,"bid_ct":1,"ask_ct":2},{"bid_px":"249.800000000","ask_px":"260.000000000","bid_sz":199,"ask_sz":168,"bid_ct":1,"ask_ct":3},{"bid_px":"249.770000000","ask_px":"262.660000000","bid_sz":50,"ask_sz":56,"bid_ct":1,"ask_ct":1},{"bid_px":"249.700000000","ask_px":"264.940000000","bid_sz":1000,"ask_sz":7,"bid_ct":1,"ask_ct":1},{"bid_px":"249.600000000","ask_px":"265.000000000","bid_sz":1000,"ask_sz":102,"bid_ct":1,"ask_ct":3},{"bid_px":"248.500000000","ask_px":"267.800000000","bid_sz":40,"ask_sz":30,"bid_ct":1,"ask_ct":1},{"bid_px":"248.200000000","ask_px":"268.670000000","bid_sz":1000,"ask_sz":100,"bid_ct":1,"ask_ct":1},{"bid_px":"247.150000000","ask_px":"269.580000000","bid_sz":400,"ask_sz":100,"bid_ct":1,"ask_ct":1},{"bid_px":"247.000000000","ask_px":"270.000000000","bid_sz":12,"ask_sz":118,"bid_ct":1,"ask_ct":3}],"symbol":"TSLA"}
{"ts_recv":"2024-11-01T08:00:11.840884133Z","hd":{"ts_event":"2024-11-01T08:00:11.840718163Z","rtype":10,"publisher_id":2,"instrument_id":16244},"action":"A","side":"A","depth":0,"price":"251.040000000","size":100,"flags":130,"ts_in_delta":165970,"sequence":314448,"levels":[{"bid_px":"250.000000000","ask_px":"251.040000000","bid_sz":2,"ask_sz":100,"bid_ct":2,"ask_ct":1},{"bid_px":"249.930000000","ask_px":"253.650000000","bid_sz":10,"ask_sz":400,"bid_ct":1,"ask_ct":1},{"bid_px":"249.800000000","ask_px":"255.000000000","bid_sz":199,"ask_sz":85,"bid_ct":1,"ask_ct":2},{"bid_px":"249.770000000","ask_px":"260.000000000","bid_sz":50,"ask_sz":168,"bid_ct":1,"ask_ct":3},{"bid_px":"249.700000000","ask_px":"262.660000000","bid_sz":1000,"ask_sz":56,"bid_ct":1,"ask_ct":1},{"bid_px":"249.600000000","ask_px":"264.940000000","bid_sz":1000,"ask_sz":7,"bid_ct":1,"ask_ct":1},{"bid_px":"248.500000000","ask_px":"265.000000000","bid_sz":40,"ask_sz":102,"bid_ct":1,"ask_ct":3},{"bid_px":"248.200000000","ask_px":"267.800000000","bid_sz":1000,"ask_sz":30,"bid_ct":1,"ask_ct":1},{"bid_px":"247.150000000","ask_px":"268.670000000","bid_sz":400,"ask_sz":100,"bid_ct":1,"ask_ct":1},{"bid_px":"247.000000000","ask_px":"269.580000000","bid_sz":12,"ask_sz":100,"bid_ct":1,"ask_ct":1}],"symbol":"TSLA"}
{"ts_recv":"2024-11-01T08:00:11.841111394Z","hd":{"ts_event":"2024-11-01T08:00:11.840944632Z","rtype":10,"publisher_id":2,"instrument_id":16244},"action":"C","side":"A","depth":0,"price":"251.040000000","size":100,"flags":130,"ts_in_delta":166762,"sequence":314451,"levels":[{"bid_px":"250.000000000","ask_px":"253.650000000","bid_sz":2,"ask_sz":400,"bid_ct":2,"ask_ct":1},{"bid_px":"249.930000000","ask_px":"255.000000000","bid_sz":10,"ask_sz":85,"bid_ct":1,"ask_ct":2},{"bid_px":"249.800000000","ask_px":"260.000000000","bid_sz":199,"ask_sz":168,"bid_ct":1,"ask_ct":3},{"bid_px":"249.770000000","ask_px":"262.660000000","bid_sz":50,"ask_sz":56,"bid_ct":1,"ask_ct":1},{"bid_px":"249.700000000","ask_px":"264.940000000","bid_sz":1000,"ask_sz":7,"bid_ct":1,"ask_ct":1},{"bid_px":"249.600000000","ask_px":"265.000000000","bid_sz":1000,"ask_sz":102,"bid_ct":1,"ask_ct":3},{"bid_px":"248.500000000","ask_px":"267.800000000","bid_sz":40,"ask_sz":30,"bid_ct":1,"ask_ct":1},{"bid_px":"248.200000000","ask_px":"268.670000000","bid_sz":1000,"ask_sz":100,"bid_ct":1,"ask_ct":1},{"bid_px":"247.150000000","ask_px":"269.580000000","bid_sz":400,"ask_sz":100,"bid_ct":1,"ask_ct":1},{"bid_px":"247.000000000","ask_px":"270.000000000","bid_sz":12,"ask_sz":118,"bid_ct":1,"ask_ct":3}],"symbol":"TSLA"}
{"ts_recv":"2024-11-01T08:00:11.841122521Z","hd":{"ts_event":"2024-11-01T08:00:11.840956689Z","rtype":10,"publisher_id":2,"instrument_id":16244},"action":"A","side":"A","depth":0,"price":"251.070000000","size":100,"flags":130,"ts_in_delta":165832,"sequence":314452,"levels":[{"bid_px":"250.000000000","ask_px":"251.070000000","bid_sz":2,"ask_sz":100,"bid_ct":2,"ask_ct":1},{"bid_px":"249.930000000","ask_px":"253.650000000","bid_sz":10,"ask_sz":400,"bid_ct":1,"ask_ct":1},{"bid_px":"249.800000000","ask_px":"255.000000000","bid_sz":199,"ask_sz":85,"bid_ct":1,"ask_ct":2},{"bid_px":"249.770000000","ask_px":"260.000000000","bid_sz":50,"ask_sz":168,"bid_ct":1,"ask_ct":3},{"bid_px":"249.700000000","ask_px":"262.660000000","bid_sz":1000,"ask_sz":56,"bid_ct":1,"ask_ct":1},{"bid_px":"249.600000000","ask_px":"264.940000000","bid_sz":1000,"ask_sz":7,"bid_ct":1,"ask_ct":1},{"bid_px":"248.500000000","ask_px":"265.000000000","bid_sz":40,"ask_sz":102,"bid_ct":1,"ask_ct":3},{"bid_px":"248.200000000","ask_px":"267.800000000","bid_sz":1000,"ask_sz":30,"bid_ct":1,"ask_ct":1},{"bid_px":"247.150000000","ask_px":"268.670000000","bid_sz":400,"ask_sz":100,"bid_ct":1,"ask_ct":1},{"bid_px":"247.000000000","ask_px":"269.580000000","bid_sz":12,"ask_sz":100,"bid_ct":1,"ask_ct":1}],"symbol":"TSLA"}
{"ts_recv":"2024-11-01T08:00:11.841196323Z","hd":{"ts_event":"2024-11-01T08:00:11.841030767Z","rtype":10,"publisher_id":2,"instrument_id":16244},"action":"C","side":"A","depth":0,"price":"251.070000000","size":100,"flags":130,"ts_in_delta":165556,"sequence":314455,"levels":[{"bid_px":"250.000000000","ask_px":"253.650000000","bid_sz":2,"ask_sz":400,"bid_ct":2,"ask_ct":1},{"bid_px":"249.930000000","ask_px":"255.000000000","bid_sz":10,"ask_sz":85,"bid_ct":1,"ask_ct":2},{"bid_px":"249.800000000","ask_px":"260.000000000","bid_sz":199,"ask_sz":168,"bid_ct":1,"ask_ct":3},{"bid_px":"249.770000000","ask_px":"262.660000000","bid_sz":50,"ask_sz":56,"bid_ct":1,"ask_ct":1},{"bid_px":"249.700000000","ask_px":"264.940000000","bid_sz":1000,"ask_sz":7,"bid_ct":1,"ask_ct":1},{"bid_px":"249.600000000","ask_px":"265.000000000","bid_sz":1000,"ask_sz":102,"bid_ct":1,"ask_ct":3},{"bid_px":"248.500000000","ask_px":"267.800000000","bid_sz":40,"ask_sz":30,"bid_ct":1,"ask_ct":1},{"bid_px":"248.200000000","ask_px":"268.670000000","bid_sz":1000,"ask_sz":100,"bid_ct":1,"ask_ct":1},{"bid_px":"247.150000000","ask_px":"269.580000000","bid_sz":400,"ask_sz":100,"bid_ct":1,"ask_ct":1},{"bid_px":"247.000000000","ask_px":"270.000000000","bid_sz":12,"ask_sz":118,"bid_ct":1,"ask_ct":3}],"symbol":"TSLA"}
{"ts_recv":"2024-11-01T08:00:11.841209194Z","hd":{"ts_event":"2024-11-01T08:00:11.841043022Z","rtype":10,"publisher_id":2,"instrument_id":16244},"action":"A","side":"A","depth":0,"price":"251.100000000","size":100,"flags":130,"ts_in_delta":166172,"sequence":314456,"levels":[{"bid_px":"250.000000000","ask_px":"251.100000000","bid_sz":2,"ask_sz":100,"bid_ct":2,"ask_ct":1},{"bid_px":"249.930000000","ask_px":"253.650000000","bid_sz":10,"ask_sz":400,"bid_ct":1,"ask_ct":1},{"bid_px":"249.800000000","ask_px":"255.000000000","bid_sz":199,"ask_sz":85,"bid_ct":1,"ask_ct":2},{"bid_px":"249.770000000","ask_px":"260.000000000","bid_sz":50,"ask_sz":168,"bid_ct":1,"ask_ct":3},{"bid_px":"249.700000000","ask_px":"262.660000000","bid_sz":1000,"ask_sz":56,"bid_ct":1,"ask_ct":1},{"bid_px":"249.600000000","ask_px":"264.940000000","bid_sz":1000,"ask_sz":7,"bid_ct":1,"ask_ct":1},{"bid_px":"248.500000000","ask_px":"265.000000000","bid_sz":40,"ask_sz":102,"bid_ct":1,"ask_ct":3},{"bid_px":"248.200000000","ask_px":"267.800000000","bid_sz":1000,"ask_sz":30,"bid_ct":1,"ask_ct":1},{"bid_px":"247.150000000","ask_px":"268.670000000","bid_sz":400,"ask_sz":100,"bid_ct":1,"ask_ct":1},{"bid_px":"247.000000000","ask_px":"269.580000000","bid_sz":12,"ask_sz":100,"bid_ct":1,"ask_ct":1}],"symbol":"TSLA"}
{"ts_recv":"2024-11-01T08:00:11.841459071Z","hd":{"ts_event":"2024-11-01T08:00:11.841293294Z","rtype":10,"publisher_id":2,"instrument_id":16244},"action":"C","side":"A","depth":0,"price":"251.100000000","size":100,"flags":130,"ts_in_delta":165777,"sequence":314457,"levels":[{"bid_px":"250.000000000","ask_px":"253.650000000","bid_sz":2,"ask_sz":400,"bid_ct":2,"ask_ct":1},{"bid_px":"249.930000000","ask_px":"255.000000000","bid_sz":10,"ask_sz":85,"bid_ct":1,"ask_ct":2},{"bid_px":"249.800000000","ask_px":"260.000000000","bid_sz":199,"ask_sz":168,"bid_ct":1,"ask_ct":3},{"bid_px":"249.770000000","ask_px":"262.660000000","bid_sz":50,"ask_sz":56,"bid_ct":1,"ask_ct":1},{"bid_px":"249.700000000","ask_px":"264.940000000","bid_sz":1000,"ask_sz":7,"bid_ct":1,"ask_ct":1},{"bid_px":"249.600000000","ask_px":"265.000000000","bid_sz":1000,"ask_sz":102,"bid_ct":1,"ask_ct":3},{"bid_px":"248.500000000","ask_px":"267.800000000","bid_sz":40,"ask_sz":30,"bid_ct":1,"ask_ct":1},{"bid_px":"248.200000000","ask_px":"268.670000000","bid_sz":1000,"ask_sz":100,"bid_ct":1,"ask_ct":1},{"bid_px":"247.150000000","ask_px":"269.580000000","bid_sz":400,"ask_sz":100,"bid_ct":1,"ask_ct":1},{"bid_px":"247.000000000","ask_px":"270.000000000","bid_sz":12,"ask_sz":118,"bid_ct":1,"ask_ct":3}],"symbol":"TSLA"}
{"ts_recv":"2024-11-01T08:00:11.841471325Z","hd":{"ts_event":"2024-11-01T08:00:11.841304887Z","rtype":10,"publisher_id":2,"instrument_id":16244},"action":"A","side":"A","depth":0,"price":"251.120000000","size":100,"flags":130,"ts_in_delta":166438,"sequence":314458,"levels":[{"bid_px":"250.000000000","ask_px":"251.120000000","bid_sz":2,"ask_sz":100,"bid_ct":2,"ask_ct":1},{"bid_px":"249.930000000","ask_px":"253.650000000","bid_sz":10,"ask_sz":400,"bid_ct":1,"ask_ct":1},{"bid_px":"249.800000000","ask_px":"255.000000000","bid_sz":199,"ask_sz":85,"bid_ct":1,"ask_ct":2},{"bid_px":"249.770000000","ask_px":"260.000000000","bid_sz":50,"ask_sz":168,"bid_ct":1,"ask_ct":3},{"bid_px":"249.700000000","ask_px":"262.660000000","bid_sz":1000,"ask_sz":56,"bid_ct":1,"ask_ct":1},{"bid_px":"249.600000000","ask_px":"264.940000000","bid_sz":1000,"ask_sz":7,"bid_ct":1,"ask_ct":1},{"bid_px":"248.500000000","ask_px":"265.000000000","bid_sz":40,"ask_sz":102,"bid_ct":1,"ask_ct":3},{"bid_px":"248.200000000","ask_px":"267.800000000","bid_sz":1000,"ask_sz":30,"bid_ct":1,"ask_ct":1},{"bid_px":"247.150000000","ask_px":"268.670000000","bid_sz":400,"ask_sz":100,"bid_ct":1,"ask_ct":1},{"bid_px":"247.000000000","ask_px":"269.580000000","bid_sz":12,"ask_sz":100,"bid_ct":1,"ask_ct":1}],"symbol":"TSLA"}
{"ts_recv":"2024-11-01T08:00:11.849201522Z","hd":{"ts_event":"2024-11-01T08:00:11.849035558Z","rtype":10,"publisher_id":2,"instrument_id":16244},"action":"A","side":"B","depth":6,"price":"248.800000000","size":1000,"flags":130,"ts_in_delta":165964,"sequence":314473,"levels":[{"bid_px":"250.000000000","ask_px":"251.120000000","bid_sz":2,"ask_sz":100,"bid_ct":2,"ask_ct":1},{"bid_px":"249.930000000","ask_px":"253.650000000","bid_sz":10,"ask_sz":400,"bid_ct":1,"ask_ct":1},{"bid_px":"249.800000000","ask_px":"255.000000000","bid_sz":199,"ask_sz":85,"bid_ct":1,"ask_ct":2},{"bid_px":"249.770000000","ask_px":"260.000000000","bid_sz":50,"ask_sz":168,"bid_ct":1,"ask_ct":3},{"bid_px":"249.700000000","ask_px":"262.660000000","bid_sz":1000,"ask_sz":56,"bid_ct":1,"ask_ct":1},{"bid_px":"249.600000000","ask_px":"264.940000000","bid_sz":1000,"ask_sz":7,"bid_ct":1,"ask_ct":1},{"bid_px":"248.800000000","ask_px":"265.000000000","bid_sz":1000,"ask_sz":102,"bid_ct":1,"ask_ct":3},{"bid_px":"248.500000000","ask_px":"267.800000000","bid_sz":40,"ask_sz":30,"bid_ct":1,"ask_ct":1},{"bid_px":"248.200000000","ask_px":"268.670000000","bid_sz":1000,"ask_sz":100,"bid_ct":1,"ask_ct":1},{"bid_px":"247.150000000","ask_px":"269.580000000","bid_sz":400,"ask_sz":100,"bid_ct":1,"ask_ct":1}],"symbol":"TSLA"}
{"ts_recv":"2024-11-01T08:00:11.849228369Z","hd":{"ts_event":"2024-11-01T08:00:11.849062607Z","rtype":10,"publisher_id":2,"instrument_id":16244},"action":"C","side":"B","depth":8,"price":"248.200000000","size":1000,"flags":130,"ts_in_delta":165762,"sequence":314474,"levels":[{"bid_px":"250.000000000","ask_px":"251.120000000","bid_sz":2,"ask_sz":100,"bid_ct":2,"ask_ct":1},{"bid_px":"249.930000000","ask_px":"253.650000000","bid_sz":10,"ask_sz":400,"bid_ct":1,"ask_ct":1},{"bid_px":"249.800000000","ask_px":"255.000000000","bid_sz":199,"ask_sz":85,"bid_ct":1,"ask_ct":2},{"bid_px":"249.770000000","ask_px":"260.000000000","bid_sz":50,"ask_sz":168,"bid_ct":1,"ask_ct":3},{"bid_px":"249.700000000","ask_px":"262.660000000","bid_sz":1000,"ask_sz":56,"bid_ct":1,"ask_ct":1},{"bid_px":"249.600000000","ask_px":"264.940000000","bid_sz":1000,"ask_sz":7,"bid_ct":1,"ask_ct":1},{"bid_px":"248.800000000","ask_px":"265.000000000","bid_sz":1000,"ask_sz":102,"bid_ct":1,"ask_ct":3},{"bid_px":"248.500000000","ask_px":"267.800000000","bid_sz":40,"ask_sz":30,"bid_ct":1,"ask_ct":1},{"bid_px":"247.150000000","ask_px":"268.670000000","bid_sz":400,"ask_sz":100,"bid_ct":1,"ask_ct":1},{"bid_px":"247.000000000","ask_px":"269.580000000","bid_sz":12,"ask_sz":100,"bid_ct":1,"ask_ct":1}],"symbol":"TSLA"}
{"ts_recv":"2024-11-01T08:00:11.849293502Z","hd":{"ts_event":"2024-11-01T08:00:11.849127303Z","rtype":10,"publisher_id":2,"instrument_id":16244},"action":"A","side":"A","depth":1,"price":"252.400000000","size":1000,"flags":130,"ts_in_delta":166199,"sequence":314475,"levels":[{"bid_px":"250.000000000","ask_px":"251.120000000","bid_sz":2,"ask_sz":100,"bid_ct":2,"ask_ct":1},{"bid_px":"249.930000000","ask_px":"252.400000000","bid_sz":10,"ask_sz":1000,"bid_ct":1,"ask_ct":1},{"bid_px":"249.800000000","ask_px":"253.650000000","bid_sz":199,"ask_sz":400,"bid_ct":1,"ask_ct":1},{"bid_px":"249.770000000","ask_px":"255.000000000","bid_sz":50,"ask_sz":85,"bid_ct":1,"ask_ct":2},{"bid_px":"249.700000000","ask_px":"260.000000000","bid_sz":1000,"ask_sz":168,"bid_ct":1,"ask_ct":3},{"bid_px":"249.600000000","ask_px":"262.660000000","bid_sz":1000,"ask_sz":56,"bid_ct":1,"ask_ct":1},{"bid_px":"248.800000000","ask_px":"264.940000000","bid_sz":1000,"ask_sz":7,"bid_ct":1,"ask_ct":1},{"bid_px":"248.500000000","ask_px":"265.000000000","bid_sz":40,"ask_sz":102,"bid_ct":1,"ask_ct":3},{"bid_px":"247.150000000","ask_px":"267.800000000","bid_sz":400,"ask_sz":30,"bid_ct":1,"ask_ct":1},{"bid_px":"247.000000000","ask_px":"268.670000000","bid_sz":12,"ask_sz":100,"bid_ct":1,"ask_ct":1}],"symbol":"TSLA"}
{"ts_recv":"2024-11-01T08:00:11.876397328Z","hd":{"ts_event":"2024-11-01T08:00:11.876231653Z","rtype":10,"publisher_id":2,"instrument_id":16244},"action":"C","side":"B","depth":6,"price":"248.800000000","size":1000,"flags":130,"ts_in_delta":165675,"sequence":314499,"levels":[{"bid_px":"250.000000000","ask_px":"251.120000000","bid_sz":2,"ask_sz":100,"bid_ct":2,"ask_ct":1},{"bid_px":"249.930000000","ask_px":"252.400000000","bid_sz":10,"ask_sz":1000,"bid_ct":1,"ask_ct":1},{"bid_px":"249.800000000","ask_px":"253.650000000","bid_sz":199,"ask_sz":400,"bid_ct":1,"ask_ct":1},{"bid_px":"249.770000000","ask_px":"255.000000000","bid_sz":50,"ask_sz":85,"bid_ct":1,"ask_ct":2},{"bid_px":"249.700000000","ask_px":"260.000000000","bid_sz":1000,"ask_sz":168,"bid_ct":1,"ask_ct":3},{"bid_px":"249.600000000","ask_px":"262.660000000","bid_sz":1000,"ask_sz":56,"bid_ct":1,"ask_ct":1},{"bid_px":"248.500000000","ask_px":"264.940000000","bid_sz":40,"ask_sz":7,"bid_ct":1,"ask_ct":1},{"bid_px":"247.150000000","ask_px":"265.000000000","bid_sz":400,"ask_sz":102,"bid_ct":1,"ask_ct":3},{"bid_px":"247.000000000","ask_px":"267.800000000","bid_sz":12,"ask_sz":30,"bid_ct":1,"ask_ct":1},{"bid_px":"246.000000000","ask_px":"268.670000000","bid_sz":4,"ask_sz":100,"bid_ct":1,"ask_ct":1}],"symbol":"TSLA"}
{"ts_recv":"2024-11-01T08:00:11.876545666Z","hd":{"ts_event":"2024-11-01T08:00:11.876379447Z","rtype":10,"publisher_id":2,"instrument_id":16244},"action":"C","side":"B","depth":4,"price":"249.600000000","size":1000,"flags":130,"ts_in_delta":166219,"sequence":314501,"levels":[{"bid_px":"250.000000000","ask_px":"251.120000000","bid_sz":2,"ask_sz":100,"bid_ct":2,"ask_ct":1},{"bid_px":"249.930000000","ask_px":"252.400000000","bid_sz":10,"ask_sz":1000,"bid_ct":1,"ask_ct":1},{"bid_px":"249.800000000","ask_px":"253.650000000","bid_sz":199,"ask_sz":400,"bid_ct":1,"ask_ct":1},{"bid_px":"249.770000000","ask_px":"255.000000000","bid_sz":50,"ask_sz":85,"bid_ct":1,"ask_ct":2},{"bid_px":"248.500000000","ask_px":"260.000000000","bid_sz":40,"ask_sz":168,"bid_ct":1,"ask_ct":3},{"bid_px":"247.150000000","ask_px":"262.660000000","bid_sz":400,"ask_sz":56,"bid_ct":1,"ask_ct":1},{"bid_px":"247.000000000","ask_px":"264.940000000","bid_sz":12,"ask_sz":7,"bid_ct":1,"ask_ct":1},{"bid_px":"246.000000000","ask_px":"265.000000000","bid_sz":4,"ask_sz":102,"bid_ct":1,"ask_ct":3},{"bid_px":"245.000000000","ask_px":"267.800000000","bid_sz":115,"ask_sz":30,"bid_ct":3,"ask_ct":1},{"bid_px":"243.200000000","ask_px":"268.670000000","bid_sz":15,"ask_sz":100,"bid_ct":1,"ask_ct":1}],"symbol":"TSLA"}
{"ts_recv":"2024-11-01T08:00:11.887224459Z","hd":{"ts_event":"2024-11-01T08:00:11.887058146Z","rtype":10,"publisher_id":2,"instrument_id":16244},"action":"A","side":"B","depth":4,"price":"249.700000000","size":1000,"flags":130,"ts_in_delta":166313,"sequence":314532,"levels":[{"bid_px":"250.000000000","ask_px":"251.120000000","bid_sz":2,"ask_sz":100,"bid_ct":2,"ask_ct":1},{"bid_px":"249.930000000","ask_px":"252.400000000","bid_sz":10,"ask_sz":1000,"bid_ct":1,"ask_ct":1},{"bid_px":"249.800000000","ask_px":"253.650000000","bid_sz":199,"ask_sz":400,"bid_ct":1,"ask_ct":1},{"bid_px":"249.770000000","ask_px":"255.000000000","bid_sz":50,"ask_sz":85,"bid_ct":1,"ask_ct":2},{"bid_px":"249.700000000","ask_px":"260.000000000","bid_sz":1000,"ask_sz":168,"bid_ct":1,"ask_ct":3},{"bid_px":"248.500000000","ask_px":"262.660000000","bid_sz":40,"ask_sz":56,"bid_ct":1,"ask_ct":1},{"bid_px":"247.150000000","ask_px":"264.940000000","bid_sz":400,"ask_sz":7,"bid_ct":1,"ask_ct":1},{"bid_px":"247.000000000","ask_px":"265.000000000","bid_sz":12,"ask_sz":102,"bid_ct":1,"ask_ct":3},{"bid_px":"246.000000000","ask_px":"267.800000000","bid_sz":4,"ask_sz":30,"bid_ct":1,"ask_ct":1},{"bid_px":"245.000000000","ask_px":"268.670000000","bid_sz":115,"ask_sz":100,"bid_ct":3,"ask_ct":1}],"symbol":"TSLA"}
{"ts_recv":"2024-11-01T08:00:11.900500040Z","hd":{"ts_event":"2024-11-01T08:00:11.900334458Z","rtype":10,"publisher_id":2,"instrument_id":16244},"action":"C","side":"B","depth":4,"price":"249.700000000","size":1000,"flags":130,"ts_in_delta":165582,"sequence":314541,"levels":[{"bid_px":"250.000000000","ask_px":"251.120000000","bid_sz":2,"ask_sz":100,"bid_ct":2,"ask_ct":1},{"bid_px":"249.930000000","ask_px":"252.400000000","bid_sz":10,"ask_sz":1000,"bid_ct":1,"ask_ct":1},{"bid_px":"249.800000000","ask_px":"253.650000000","bid_sz":199,"ask_sz":400,"bid_ct":1,"ask_ct":1},{"bid_px":"249.770000000","ask_px":"255.000000000","bid_sz":50,"ask_sz":85,"bid_ct":1,"ask_ct":2},{"bid_px":"248.500000000","ask_px":"260.000000000","bid_sz":40,"ask_sz":168,"bid_ct":1,"ask_ct":3},{"bid_px":"247.150000000","ask_px":"262.660000000","bid_sz":400,"ask_sz":56,"bid_ct":1,"ask_ct":1},{"bid_px":"247.000000000","ask_px":"264.940000000","bid_sz":12,"ask_sz":7,"bid_ct":1,"ask_ct":1},{"bid_px":"246.000000000","ask_px":"265.000000000","bid_sz":4,"ask_sz":102,"bid_ct":1,"ask_ct":3},{"bid_px":"245.000000000","ask_px":"267.800000000","bid_sz":115,"ask_sz":30,"bid_ct":3,"ask_ct":1},{"bid_px":"243.200000000","ask_px":"268.670000000","bid_sz":15,"ask_sz":100,"bid_ct":1,"ask_ct":1}],"symbol":"TSLA"}
{"ts_recv":"2024-11-01T08:00:11.903869386Z","hd":{"ts_event":"2024-11-01T08:00:11.903702368Z","rtype":10,"publisher_id":2,"instrument_id":11667},"action":"A","side":"B","depth":7,"price":"133.800000000","size":5,"flags":130,"ts_in_delta":167018,"sequence":314545,"levels":[{"bid_px":"134.680000000","ask_px":"134.990000000","bid_sz":100,"ask_sz":10,"bid_ct":1,"ask_ct":1},{"bid_px":"134.500000000","ask_px":"135.000000000","bid_sz":520,"ask_sz":38,"bid_ct":2,"ask_ct":3},{"bid_px":"134.410000000","ask_px":"135.100000000","bid_sz":61,"ask_sz":10,"bid_ct":2,"ask_ct":1},{"bid_px":"134.380000000","ask_px":"135.230000000","bid_sz":18,"ask_sz":360,"bid_ct":1,"ask_ct":1},{"bid_px":"134.210000000","ask_px":"135.300000000","bid_sz":20,"ask_sz":1000,"bid_ct":1,"ask_ct":1},{"bid_px":"134.200000000","ask_px":"135.400000000","bid_sz":3,"ask_sz":10,"bid_ct":1,"ask_ct":1},{"bid_px":"134.000000000","ask_px":"135.420000000","bid_sz":1,"ask_sz":1,"bid_ct":1,"ask_ct":1},{"bid_px":"133.800000000","ask_px":"135.820000000","bid_sz":5,"ask_sz":1,"bid_ct":1,"ask_ct":1},{"bid_px":"133.160000000","ask_px":"135.990000000","bid_sz":1,"ask_sz":20,"bid_ct":1,"ask_ct":1},{"bid_px":"132.760000000","ask_px":"136.100000000","bid_sz":104,"ask_sz":1000,"bid_ct":2,"ask_ct":1}],"symbol":"NVDA"}
{"ts_recv":"2024-11-01T08:00:11.909754193Z","hd":{"ts_event":"2024-11-01T08:00:11.909587907Z","rtype":10,"publisher_id":2,"instrument_id":16244},"action":"A","side":"A","depth":0,"price":"251.100000000","size":100,"flags":130,"ts_in_delta":166286,"sequence":314557,"levels":[{"bid_px":"250.000000000","ask_px":"251.100000000","bid_sz":2,"ask_sz":100,"bid_ct":2,"ask_ct":1},{"bid_px":"249.930000000","ask_px":"252.400000000","bid_sz":10,"ask_sz":1000,"bid_ct":1,"ask_ct":1},{"bid_px":"249.800000000","ask_px":"253.650000000","bid_sz":199,"ask_sz":400,"bid_ct":1,"ask_ct":1},{"bid_px":"249.770000000","ask_px":"255.000000000","bid_sz":50,"ask_sz":85,"bid_ct":1,"ask_ct":2},{"bid_px":"248.500000000","ask_px":"260.000000000","bid_sz":40,"ask_sz":168,"bid_ct":1,"ask_ct":3},{"bid_px":"247.150000000","ask_px":"262.660000000","bid_sz":400,"ask_sz":56,"bid_ct":1,"ask_ct":1},{"bid_px":"247.000000000","ask_px":"264.940000000","bid_sz":12,"ask_sz":7,"bid_ct":1,"ask_ct":1},{"bid_px":"246.000000000","ask_px":"265.000000000","bid_sz":4,"ask_sz":102,"bid_ct":1,"ask_ct":3},{"bid_px":"245.000000000","ask_px":"267.800000000","bid_sz":115,"ask_sz":30,"bid_ct":3,"ask_ct":1},{"bid_px":"243.200000000","ask_px":"268.670000000","bid_sz":15,"ask_sz":100,"bid_ct":1,"ask_ct":1}],"symbol":"TSLA"}
{"ts_recv":"2024-11-01T08:00:11.911317254Z","hd":{"ts_event":"2024-11-01T08:00:11.911151222Z","rtype":10,"publisher_id":2,"instrument_id":16244},"action":"A","side":"B","depth":4,"price":"249.400000000","size":1000,"flags":130,"ts_in_delta":166032,"sequence":314559,"levels":[{"bid_px":"250.000000000","ask_px":"251.100000000","bid_sz":2,"ask_sz":100,"bid_ct":2,"ask_ct":1},{"bid_px":"249.930000000","ask_px":"252.400000000","bid_sz":10,"ask_sz":1000,"bid_ct":1,"ask_ct":1},{"bid_px":"249.800000000","ask_px":"253.650000000","bid_sz":199,"ask_sz":400,"bid_ct":1,"ask_ct":1},{"bid_px":"249.770000000","ask_px":"255.000000000","bid_sz":50,"ask_sz":85,"bid_ct":1,"ask_ct":2},{"bid_px":"249.400000000","ask_px":"260.000000000","bid_sz":1000,"ask_sz":168,"bid_ct":1,"ask_ct":3},{"bid_px":"248.500000000","ask_px":"262.660000000","bid_sz":40,"ask_sz":56,"bid_ct":1,"ask_ct":1},{"bid_px":"247.150000000","ask_px":"264.940000000","bid_sz":400,"ask_sz":7,"bid_ct":1,"ask_ct":1},{"bid_px":"247.000000000","ask_px":"265.000000000","bid_sz":12,"ask_sz":102,"bid_ct":1,"ask_ct":3},{"bid_px":"246.000000000","ask_px":"267.800000000","bid_sz":4,"ask_sz":30,"bid_ct":1,"ask_ct":1},{"bid_px":"245.000000000","ask_px":"268.670000000","bid_sz":115,"ask_sz":100,"bid_ct":3,"ask_ct":1}],"symbol":"TSLA"}
{"ts_recv":"2024-11-01T08:00:11.932580018Z","hd":{"ts_event":"2024-11-01T08:00:11.932413732Z","rtype":10,"publisher_id":2,"instrument_id":10888},"action":"A","side":"B","depth":2,"price":"409.430000000","size":5,"flags":130,"ts_in_delta":166286,"sequence":314566,"levels":[{"bid_px":"410.000000000","ask_px":"414.000000000","bid_sz":1,"ask_sz":468,"bid_ct":1,"ask_ct":2},{"bid_px":"409.750000000","ask_px":"415.070000000","bid_sz":3,"ask_sz":246,"bid_ct":1,"ask_ct":1},{"bid_px":"409.430000000","ask_px":"415.350000000","bid_sz":5,"ask_sz":84,"bid_ct":1,"ask_ct":2},{"bid_px":"409.080000000","ask_px":"420.000000000","bid_sz":2,"ask_sz":3,"bid_ct":1,"ask_ct":1},{"bid_px":"409.000000000","ask_px":"440.000000000","bid_sz":2,"ask_sz":35,"bid_ct":1,"ask_ct":1},{"bid_px":"408.970000000","ask_px":"445.000000000","bid_sz":12,"ask_sz":25,"bid_ct":1,"ask_ct":1},{"bid_px":"408.960000000","ask_px":"445.680000000","bid_sz":5,"ask_sz":3,"bid_ct":1,"ask_ct":1},{"bid_px":"407.600000000","ask_px":"448.000000000","bid_sz":16,"ask_sz":15,"bid_ct":1,"ask_ct":2},{"bid_px":"407.000000000","ask_px":"450.000000000","bid_sz":17,"ask_sz":10,"bid_ct":3,"ask_ct":1},{"bid_px":"406.350000000","ask_px":"467.560000000","bid_sz":82,"ask_sz":5,"bid_ct":2,"ask_ct":1}],"symbol":"MSFT"}
{"ts_recv":"2024-11-01T08:00:11.932656290Z","hd":{"ts_event":"2024-11-01T08:00:11.932490158Z","rtype":10,"publisher_id":2,"instrument_id":10888},"action":"A","side":"B","depth":2,"price":"409.670000000","size":100,"flags":130,"ts_in_delta":166132,"sequence":314567,"levels":[{"bid_px":"410.000000000","ask_px":"414.000000000","bid_sz":1,"ask_sz":468,"bid_ct":1,"ask_ct":2},{"bid_px":"409.750000000","ask_px":"415.070000000","bid_sz":3,"ask_sz":246,"bid_ct":1,"ask_ct":1},{"bid_px":"409.670000000","ask_px":"415.350000000","bid_sz":100,"ask_sz":84,"bid_ct":1,"ask_ct":2},{"bid_px":"409.430000000","ask_px":"420.000000000","bid_sz":5,"ask_sz":3,"bid_ct":1,"ask_ct":1},{"bid_px":"409.080000000","ask_px":"440.000000000","bid_sz":2,"ask_sz":35,"bid_ct":1,"ask_ct":1},{"bid_px":"409.000000000","ask_px":"445.000000000","bid_sz":2,"ask_sz":25,"bid_ct":1,"ask_ct":1},{"bid_px":"408.970000000","ask_px":"445.680000000","bid_sz":12,"ask_sz":3,"bid_ct":1,"ask_ct":1},{"bid_px":"408.960000000","ask_px":"448.000000000","bid_sz":5,"ask_sz":15,"bid_ct":1,"ask_ct":2},{"bid_px":"407.600000000","ask_px":"450.000000000","bid_sz":16,"ask_sz":10,"bid_ct":1,"ask_ct":1},{"bid_px":"407.000000000","ask_px":"467.560000000","bid_sz":17,"ask_sz":5,"bid_ct":3,"ask_ct":1}],"symbol":"MSFT"}
{"ts_recv":"2024-11-01T08:00:11.940234616Z","hd":{"ts_event":"2024-11-01T08:00:11.940068402Z","rtype":10,"publisher_id":2,"instrument_id":16244},"action":"A","side":"A","depth":0,"price":"251.100000000","size":50,"flags":130,"ts_in_delta":166214,"sequence":314579,"levels":[{"bid_px":"250.000000000","ask_px":"251.100000000","bid_sz":2,"ask_sz":150,"bid_ct":2,"ask_ct":2},{"bid_px":"249.930000000","ask_px":"252.400000000","bid_sz":10,"ask_sz":1000,"bid_ct":1,"ask_ct":1},{"bid_px":"249.800000000","ask_px":"253.650000000","bid_sz":199,"ask_sz":400,"bid_ct":1,"ask_ct":1},{"bid_px":"249.770000000","ask_px":"255.000000000","bid_sz":50,"ask_sz":85,"bid_ct":1,"ask_ct":2},{"bid_px":"249.400000000","ask_px":"260.000000000","bid_sz":1000,"ask_sz":168,"bid_ct":1,"ask_ct":3},{"bid_px":"248.500000000","ask_px":"262.660000000","bid_sz":40,"ask_sz":56,"bid_ct":1,"ask_ct":1},{"bid_px":"247.150000000","ask_px":"264.940000000","bid_sz":400,"ask_sz":7,"bid_ct":1,"ask_ct":1},{"bid_px":"247.000000000","ask_px":"265.000000000","bid_sz":12,"ask_sz":102,"bid_ct":1,"ask_ct":3},{"bid_px":"246.000000000","ask_px":"267.800000000","bid_sz":4,"ask_sz":30,"bid_ct":1,"ask_ct":1},{"bid_px":"245.000000000","ask_px":"268.670000000","bid_sz":115,"ask_sz":100,"bid_ct":3,"ask_ct":1}],"symbol":"TSLA"}
{"ts_recv":"2024-11-01T08:00:11.942622212Z","hd":{"ts_event":"2024-11-01T08:00:11.942456002Z","rtype":10,"publisher_id":2,"instrument_id":10888},"action":"A","side":"A","depth":8,"price":"450.000000000","size":2,"flags":130,"ts_in_delta":166210,"sequence":314581,"levels":[{"bid_px":"410.000000000","ask_px":"414.000000000","bid_sz":1,"ask_sz":468,"bid_ct":1,"ask_ct":2},{"bid_px":"409.750000000","ask_px":"415.070000000","bid_sz":3,"ask_sz":246,"bid_ct":1,"ask_ct":1},{"bid_px":"409.670000000","ask_px":"415.350000000","bid_sz":100,"ask_sz":84,"bid_ct":1,"ask_ct":2},{"bid_px":"409.430000000","ask_px":"420.000000000","bid_sz":5,"ask_sz":3,"bid_ct":1,"ask_ct":1},{"bid_px":"409.080000000","ask_px":"440.000000000","bid_sz":2,"ask_sz":35,"bid_ct":1,"ask_ct":1},{"bid_px":"409.000000000","ask_px":"445.000000000","bid_sz":2,"ask_sz":25,"bid_ct":1,"ask_ct":1},{"bid_px":"408.970000000","ask_px":"445.680000000","bid_sz":12,"ask_sz":3,"bid_ct":1,"ask_ct":1},{"bid_px":"408.960000000","ask_px":"448.000000000","bid_sz":5,"ask_sz":15,"bid_ct":1,"ask_ct":2},{"bid_px":"407.600000000","ask_px":"450.000000000","bid_sz":16,"ask_sz":12,"bid_ct":1,"ask_ct":2},{"bid_px":"407.000000000","ask_px":"467.560000000","bid_sz":17,"ask_sz":5,"bid_ct":3,"ask_ct":1}],"symbol":"MSFT"}
{"ts_recv":"2024-11-01T08:00:11.968084332Z","hd":{"ts_event":"2024-11-01T08:00:11.967918487Z","rtype":10,"publisher_id":2,"instrument_id":6905},"action":"C","side":"B","depth":0,"price":"84.040000000","size":100,"flags":130,"ts_in_delta":165845,"sequence":314596,"levels":[{"bid_px":null,"ask_px":"91.880000000","bid_sz":0,"ask_sz":100,"bid_ct":0,"ask_ct":1},{"bid_px":null,"ask_px":null,"bid_sz":0,"ask_sz":0,"bid_ct":0,"ask_ct":0},{"bid_px":null,"ask_px":null,"bid_sz":0,"ask_sz":0,"bid_ct":0,"ask_ct":0},{"bid_px":null,"ask_px":null,"bid_sz":0,"ask_sz":0,"bid_ct":0,"ask_ct":0},{"bid_px":null,"ask_px":null,"bid_sz":0,"ask_sz":0,"bid_ct":0,"ask_ct":0},{"bid_px":null,"ask_px":null,"bid_sz":0,"ask_sz":0,"bid_ct":0,"ask_ct":0},{"bid_px":null,"ask_px":null,"bid_sz":0,"ask_sz":0,"bid_ct":0,"ask_ct":0},{"bid_px":null,"ask_px":null,"bid_sz":0,"ask_sz":0,"bid_ct":0,"ask_ct":0},{"bid_px":null,"ask_px":null,"bid_sz":0,"ask_sz":0,"bid_ct":0,"ask_ct":0},{"bid_px":null,"ask_px":null,"bid_sz":0,"ask_sz":0,"bid_ct":0,"ask_ct":0}],"symbol":"GILD"}
{"ts_recv":"2024-11-01T08:00:11.980261074Z","hd":{"ts_event":"2024-11-01T08:00:11.980094588Z","rtype":10,"publisher_id":2,"instrument_id":16244},"action":"A","side":"B","depth":0,"price":"250.020000000","size":50,"flags":130,"ts_in_delta":166486,"sequence":314604,"levels":[{"bid_px":"250.020000000","ask_px":"251.100000000","bid_sz":50,"ask_sz":150,"bid_ct":1,"ask_ct":2},{"bid_px":"250.000000000","ask_px":"252.400000000","bid_sz":2,"ask_sz":1000,"bid_ct":2,"ask_ct":1},{"bid_px":"249.930000000","ask_px":"253.650000000","bid_sz":10,"ask_sz":400,"bid_ct":1,"ask_ct":1},{"bid_px":"249.800000000","ask_px":"255.000000000","bid_sz":199,"ask_sz":85,"bid_ct":1,"ask_ct":2},{"bid_px":"249.770000000","ask_px":"260.000000000","bid_sz":50,"ask_sz":168,"bid_ct":1,"ask_ct":3},{"bid_px":"249.400000000","ask_px":"262.660000000","bid_sz":1000,"ask_sz":56,"bid_ct":1,"ask_ct":1},{"bid_px":"248.500000000","ask_px":"264.940000000","bid_sz":40,"ask_sz":7,"bid_ct":1,"ask_ct":1},{"bid_px":"247.150000000","ask_px":"265.000000000","bid_sz":400,"ask_sz":102,"bid_ct":1,"ask_ct":3},{"bid_px":"247.000000000","ask_px":"267.800000000","bid_sz":12,"ask_sz":30,"bid_ct":1,"ask_ct":1},{"bid_px":"246.000000000","ask_px":"268.670000000","bid_sz":4,"ask_sz":100,"bid_ct":1,"ask_ct":1}],"symbol":"TSLA"}
{"ts_recv":"2024-11-01T08:00:12.010298851Z","hd":{"ts_event":"2024-11-01T08:00:12.010132491Z","rtype":10,"publisher_id":2,"instrument_id":16244},"action":"A","side":"B","depth":0,"price":"250.110000000","size":50,"flags":130,"ts_in_delta":166360,"sequence":314644,"levels":[{"bid_px":"250.110000000","ask_px":"251.100000000","bid_sz":50,"ask_sz":150,"bid_ct":1,"ask_ct":2},{"bid_px":"250.000000000","ask_px":"252.400000000","bid_sz":2,"ask_sz":1000,"bid_ct":2,"ask_ct":1},{"bid_px":"249.930000000","ask_px":"253.650000000","bid_sz":10,"ask_sz":400,"bid_ct":1,"ask_ct":1},{"bid_px":"249.800000000","ask_px":"255.000000000","bid_sz":199,"ask_sz":85,"bid_ct":1,"ask_ct":2},{"bid_px":"249.770000000","ask_px":"260.000000000","bid_sz":50,"ask_sz":168,"bid_ct":1,"ask_ct":3},{"bid_px":"249.400000000","ask_px":"262.660000000","bid_sz":1000,"ask_sz":56,"bid_ct":1,"ask_ct":1},{"bid_px":"248.500000000","ask_px":"264.940000000","bid_sz":40,"ask_sz":7,"bid_ct":1,"ask_ct":1},{"bid_px":"247.150000000","ask_px":"265.000000000","bid_sz":400,"ask_sz":102,"bid_ct":1,"ask_ct":3},{"bid_px":"247.000000000","ask_px":"267.800000000","bid_sz":12,"ask_sz":30,"bid_ct":1,"ask_ct":1},{"bid_px":"246.000000000","ask_px":"268.670000000","bid_sz":4,"ask_sz":100,"bid_ct":1,"ask_ct":1}],"symbol":"TSLA"}
{"ts_recv":"2024-11-01T08:00:12.023033525Z","hd":{"ts_event":"2024-11-01T08:00:12.022866931Z","rtype":10,"publisher_id":2,"instrument_id":6905},"action":"A","side":"B","depth":0,"price":"84.040000000","size":100,"flags":130,"ts_in_delta":166594,"sequence":314659,"levels":[{"bid_px":"84.040000000","ask_px":"91.880000000","bid_sz":100,"ask_sz":100,"bid_ct":1,"ask_ct":1},{"bid_px":null,"ask_px":null,"bid_sz":0,"ask_sz":0,"bid_ct":0,"ask_ct":0},{"bid_px":null,"ask_px":null,"bid_sz":0,"ask_sz":0,"bid_ct":0,"ask_ct":0},{"bid_px":null,"ask_px":null,"bid_sz":0,"ask_sz":0,"bid_ct":0,"ask_ct":0},{"bid_px":null,"ask_px":null,"bid_sz":0,"ask_sz":0,"bid_ct":0,"ask_ct":0},{"bid_px":null,"ask_px":null,"bid_sz":0,"ask_sz":0,"bid_ct":0,"ask_ct":0},{"bid_px":null,"ask_px":null,"bid_sz":0,"ask_sz":0,"bid_ct":0,"ask_ct":0},{"bid_px":null,"ask_px":null,"bid_sz":0,"ask_sz":0,"bid_ct":0,"ask_ct":0},{"bid_px":null,"ask_px":null,"bid_sz":0,"ask_sz":0,"bid_ct":0,"ask_ct":0},{"bid_px":null,"ask_px":null,"bid_sz":0,"ask_sz":0,"bid_ct":0,"ask_ct":0}],"symbol":"GILD"}
{"ts_recv":"2024-11-01T08:00:12.051837828Z","hd":{"ts_event":"2024-11-01T08:00:12.051671871Z","rtype":10,"publisher_id":2,"instrument_id":16244},"action":"C","side":"A","depth":0,"price":"251.100000000","size":50,"flags":130,"ts_in_delta":165957,"sequence":314734,"levels":[{"bid_px":"250.110000000","ask_px":"251.100000000","bid_sz":50,"ask_sz":100,"bid_ct":1,"ask_ct":1},{"bid_px":"250.000000000","ask_px":"252.400000000","bid_sz":2,"ask_sz":1000,"bid_ct":2,"ask_ct":1},{"bid_px":"249.930000000","ask_px":"253.650000000","bid_sz":10,"ask_sz":400,"bid_ct":1,"ask_ct":1},{"bid_px":"249.800000000","ask_px":"255.000000000","bid_sz":199,"ask_sz":85,"bid_ct":1,"ask_ct":2},{"bid_px":"249.770000000","ask_px":"260.000000000","bid_sz":50,"ask_sz":168,"bid_ct":1,"ask_ct":3},{"bid_px":"249.400000000","ask_px":"262.660000000","bid_sz":1000,"ask_sz":56,"bid_ct":1,"ask_ct":1},{"bid_px":"248.500000000","ask_px":"264.940000000","bid_sz":40,"ask_sz":7,"bid_ct":1,"ask_ct":1},{"bid_px":"247.150000000","ask_px":"265.000000000","bid_sz":400,"ask_sz":102,"bid_ct":1,"ask_ct":3},{"bid_px":"247.000000000","ask_px":"267.800000000","bid_sz":12,"ask_sz":30,"bid_ct":1,"ask_ct":1},{"bid_px":"246.000000000","ask_px":"268.670000000","bid_sz":4,"ask_sz":100,"bid_ct":1,"ask_ct":1}],"symbol":"TSLA"}
{"ts_recv":"2024-11-01T08:00:12.052652034Z","hd":{"ts_event":"2024-11-01T08:00:12.052486477Z","rtype":10,"publisher_id":2,"instrument_id":16244},"action":"C","side":"A","depth":0,"price":"251.100000000","size":100,"flags":130,"ts_in_delta":165557,"sequence":314740,"levels":[{"bid_px":"250.110000000","ask_px":"252.400000000","bid_sz":50,"ask_sz":1000,"bid_ct":1,"ask_ct":1},{"bid_px":"250.000000000","ask_px":"253.650000000","bid_sz":2,"ask_sz":400,"bid_ct":2,"ask_ct":1},{"bid_px":"249.930000000","ask_px":"255.000000000","bid_sz":10,"ask_sz":85,"bid_ct":1,"ask_ct":2},{"bid_px":"249.800000000","ask_px":"260.000000000","bid_sz":199,"ask_sz":168,"bid_ct":1,"ask_ct":3},{"bid_px":"249.770000000","ask_px":"262.660000000","bid_sz":50,"ask_sz":56,"bid_ct":1,"ask_ct":1},{"bid_px":"249.400000000","ask_px":"264.940000000","bid_sz":1000,"ask_sz":7,"bid_ct":1,"ask_ct":1},{"bid_px":"248.500000000","ask_px":"265.000000000","bid_sz":40,"ask_sz":102,"bid_ct":1,"ask_ct":3},{"bid_px":"247.150000000","ask_px":"267.800000000","bid_sz":400,"ask_sz":30,"bid_ct":1,"ask_ct":1},{"bid_px":"247.000000000","ask_px":"268.670000000","bid_sz":12,"ask_sz":100,"bid_ct":1,"ask_ct":1},{"bid_px":"246.000000000","ask_px":"269.580000000","bid_sz":4,"ask_sz":100,"bid_ct":1,"ask_ct":1}],"symbol":"TSLA"}
{"ts_recv":"2024-11-01T08:00:12.052664746Z","hd":{"ts_event":"2024-11-01T08:00:12.052498638Z","rtype":10,"publisher_id":2,"instrument_id":16244},"action":"A","side":"A","depth":0,"price":"251.120000000","size":100,"flags":130,"ts_in_delta":166108,"sequence":314741,"levels":[{"bid_px":"250.110000000","ask_px":"251.120000000","bid_sz":50,"ask_sz":100,"bid_ct":1,"ask_ct":1},{"bid_px":"250.000000000","ask_px":"252.400000000","bid_sz":2,"ask_sz":1000,"bid_ct":2,"ask_ct":1},{"bid_px":"249.930000000","ask_px":"253.650000000","bid_sz":10,"ask_sz":400,"bid_ct":1,"ask_ct":1},{"bid_px":"249.800000000","ask_px":"255.000000000","bid_sz":199,"ask_sz":85,"bid_ct":1,"ask_ct":2},{"bid_px":"249.770000000","ask_px":"260.000000000","bid_sz":50,"ask_sz":168,"bid_ct":1,"ask_ct":3},{"bid_px":"249.400000000","ask_px":"262.660000000","bid_sz":1000,"ask_sz":56,"bid_ct":1,"ask_ct":1},{"bid_px":"248.500000000","ask_px":"264.940000000","bid_sz":40,"ask_sz":7,"bid_ct":1,"ask_ct":1},{"bid_px":"247.150000000","ask_px":"265.000000000","bid_sz":400,"ask_sz":102,"bid_ct":1,"ask_ct":3},{"bid_px":"247.000000000","ask_px":"267.800000000","bid_sz":12,"ask_sz":30,"bid_ct":1,"ask_ct":1},{"bid_px":"246.000000000","ask_px":"268.670000000","bid_sz":4,"ask_sz":100,"bid_ct":1,"ask_ct":1}],"symbol":"TSLA"}
{"ts_recv":"2024-11-01T08:00:12.052943030Z","hd":{"ts_event":"2024-11-01T08:00:12.052777371Z","rtype":10,"publisher_id":2,"instrument_id":16244},"action":"C","side":"A","depth":0,"price":"251.120000000","size":100,"flags":130,"ts_in_delta":165659,"sequence":314742,"levels":[{"bid_px":"250.110000000","ask_px":"252.400000000","bid_sz":50,"ask_sz":1000,"bid_ct":1,"ask_ct":1},{"bid_px":"250.000000000","ask_px":"253.650000000","bid_sz":2,"ask_sz":400,"bid_ct":2,"ask_ct":1},{"bid_px":"249.930000000","ask_px":"255.000000000","bid_sz":10,"ask_sz":85,"bid_ct":1,"ask_ct":2},{"bid_px":"249.800000000","ask_px":"260.000000000","bid_sz":199,"ask_sz":168,"bid_ct":1,"ask_ct":3},{"bid_px":"249.770000000","ask_px":"262.660000000","bid_sz":50,"ask_sz":56,"bid_ct":1,"ask_ct":1},{"bid_px":"249.400000000","ask_px":"264.940000000","bid_sz":1000,"ask_sz":7,"bid_ct":1,"ask_ct":1},{"bid_px":"248.500000000","ask_px":"265.000000000","bid_sz":40,"ask_sz":102,"bid_ct":1,"ask_ct":3},{"bid_px":"247.150000000","ask_px":"267.800000000","bid_sz":400,"ask_sz":30,"bid_ct":1,"ask_ct":1},{"bid_px":"247.000000000","ask_px":"268.670000000","bid_sz":12,"ask_sz":100,"bid_ct":1,"ask_ct":1},{"bid_px":"246.000000000","ask_px":"269.580000000","bid_sz":4,"ask_sz":100,"bid_ct":1,"ask_ct":1}],"symbol":"TSLA"}
{"ts_recv":"2024-11-01T08:00:12.052955594Z","hd":{"ts_event":"2024-11-01T08:00:12.052789609Z","rtype":10,"publisher_id":2,"instrument_id":16244},"action":"A","side":"A","depth":0,"price":"251.150000000","size":100,"flags":130,"ts_in_delta":165985,"sequence":314743,"levels":[{"bid_px":"250.110000000","ask_px":"251.150000000","bid_sz":50,"ask_sz":100,"bid_ct":1,"ask_ct":1},{"bid_px":"250.000000000","ask_px":"252.400000000","bid_sz":2,"ask_sz":1000,"bid_ct":2,"ask_ct":1},{"bid_px":"249.930000000","ask_px":"253.650000000","bid_sz":10,"ask_sz":400,"bid_ct":1,"ask_ct":1},{"bid_px":"249.800000000","ask_px":"255.000000000","bid_sz":199,"ask_sz":85,"bid_ct":1,"ask_ct":2},{"bid_px":"249.770000000","ask_px":"260.000000000","bid_sz":50,"ask_sz":168,"bid_ct":1,"ask_ct":3},{"bid_px":"249.400000000","ask_px":"262.660000000","bid_sz":1000,"ask_sz":56,"bid_ct":1,"ask_ct":1},{"bid_px":"248.500000000","ask_px":"264.940000000","bid_sz":40,"ask_sz":7,"bid_ct":1,"ask_ct":1},{"bid_px":"247.150000000","ask_px":"265.000000000","bid_sz":400,"ask_sz":102,"bid_ct":1,"ask_ct":3},{"bid_px":"247.000000000","ask_px":"267.800000000","bid_sz":12,"ask_sz":30,"bid_ct":1,"ask_ct":1},{"bid_px":"246.000000000","ask_px":"268.670000000","bid_sz":4,"ask_sz":100,"bid_ct":1,"ask_ct":1}],"symbol":"TSLA"}
{"ts_recv":"2024-11-01T08:00:12.062944714Z","hd":{"ts_event":"2024-11-01T08:00:12.062778567Z","rtype":10,"publisher_id":2,"instrument_id":10888},"action":"A","side":"A","depth":9,"price":"455.000000000","size":5,"flags":130,"ts_in_delta":166147,"sequence":314751,"levels":[{"bid_px":"410.000000000","ask_px":"414.000000000","bid_sz":1,"ask_sz":468,"bid_ct":1,"ask_ct":2},{"bid_px":"409.750000000","ask_px":"415.070000000","bid_sz":3,"ask_sz":246,"bid_ct":1,"ask_ct":1},{"bid_px":"409.670000000","ask_px":"415.350000000","bid_sz":100,"ask_sz":84,"bid_ct":1,"ask_ct":2},{"bid_px":"409.430000000","ask_px":"420.000000000","bid_sz":5,"ask_sz":3,"bid_ct":1,"ask_ct":1},{"bid_px":"409.080000000","ask_px":"440.000000000","bid_sz":2,"ask_sz":35,"bid_ct":1,"ask_ct":1},{"bid_px":"409.000000000","ask_px":"445.000000000","bid_sz":2,"ask_sz":25,"bid_ct":1,"ask_ct":1},{"bid_px":"408.970000000","ask_px":"445.680000000","bid_sz":12,"ask_sz":3,"bid_ct":1,"ask_ct":1},{"bid_px":"408.960000000","ask_px":"448.000000000","bid_sz":5,"ask_sz":15,"bid_ct":1,"ask_ct":2},{"bid_px":"407.600000000","ask_px":"450.000000000","bid_sz":16,"ask_sz":12,"bid_ct":1,"ask_ct":2},{"bid_px":"407.000000000","ask_px":"455.000000000","bid_sz":17,"ask_sz":5,"bid_ct":3,"ask_ct":1}],"symbol":"MSFT"}
{"ts_recv":"2024-11-01T08:00:12.072038689Z","hd":{"ts_event":"2024-11-01T08:00:12.071872261Z","rtype":10,"publisher_id":2,"instrument_id":16244},"action":"A","side":"B","depth":0,"price":"250.150000000","size":50,"flags":130,"ts_in_delta":166428,"sequence":314755,"levels":[{"bid_px":"250.150000000","ask_px":"251.150000000","bid_sz":50,"ask_sz":100,"bid_ct":1,"ask_ct":1},{"bid_px":"250.000000000","ask_px":"252.400000000","bid_sz":2,"ask_sz":1000,"bid_ct":2,"ask_ct":1},{"bid_px":"249.930000000","ask_px":"253.650000000","bid_sz":10,"ask_sz":400,"bid_ct":1,"ask_ct":1},{"bid_px":"249.800000000","ask_px":"255.000000000","bid_sz":199,"ask_sz":85,"bid_ct":1,"ask_ct":2},{"bid_px":"249.770000000","ask_px":"260.000000000","bid_sz":50,"ask_sz":168,"bid_ct":1,"ask_ct":3},{"bid_px":"249.400000000","ask_px":"262.660000000","bid_sz":1000,"ask_sz":56,"bid_ct":1,"ask_ct":1},{"bid_px":"248.500000000","ask_px":"264.940000000","bid_sz":40,"ask_sz":7,"bid_ct":1,"ask_ct":1},{"bid_px":"247.150000000","ask_px":"265.000000000","bid_sz":400,"ask_sz":102,"bid_ct":1,"ask_ct":3},{"bid_px":"247.000000000","ask_px":"267.800000000","bid_sz":12,"ask_sz":30,"bid_ct":1,"ask_ct":1},{"bid_px":"246.000000000","ask_px":"268.670000000","bid_sz":4,"ask_sz":100,"bid_ct":1,"ask_ct":1}],"symbol":"TSLA"}
{"ts_recv":"2024-11-01T08:00:12.072262589Z","hd":{"ts_event":"2024-11-01T08:00:12.072096208Z","rtype":10,"publisher_id":2,"instrument_id":16244},"action":"A","side":"B","depth":3,"price":"249.880000000","size":4,"flags":130,"ts_in_delta":166381,"sequence":314756,"levels":[{"bid_px":"250.150000000","ask_px":"251.150000000","bid_sz":50,"ask_sz":100,"bid_ct":1,"ask_ct":1},{"bid_px":"250.000000000","ask_px":"252.400000000","bid_sz":2,"ask_sz":1000,"bid_ct":2,"ask_ct":1},{"bid_px":"249.930000000","ask_px":"253.650000000","bid_sz":10,"ask_sz":400,"bid_ct":1,"ask_ct":1},{"bid_px":"249.880000000","ask_px":"255.000000000","bid_sz":4,"ask_sz":85,"bid_ct":1,"ask_ct":2},{"bid_px":"249.800000000","ask_px":"260.000000000","bid_sz":199,"ask_sz":168,"bid_ct":1,"ask_ct":3},{"bid_px":"249.770000000","ask_px":"262.660000000","bid_sz":50,"ask_sz":56,"bid_ct":1,"ask_ct":1},{"bid_px":"249.400000000","ask_px":"264.940000000","bid_sz":1000,"ask_sz":7,"bid_ct":1,"ask_ct":1},{"bid_px":"248.500000000","ask_px":"265.000000000","bid_sz":40,"ask_sz":102,"bid_ct":1,"ask_ct":3},{"bid_px":"247.150000000","ask_px":"267.800000000","bid_sz":400,"ask_sz":30,"bid_ct":1,"ask_ct":1},{"bid_px":"247.000000000","ask_px":"268.670000000","bid_sz":12,"ask_sz":100,"bid_ct":1,"ask_ct":1}],"symbol":"TSLA"}
{"ts_recv":"2024-11-01T08:00:12.083344521Z","hd":{"ts_event":"2024-11-01T08:00:12.083178480Z","rtype":10,"publisher_id":2,"instrument_id":16244},"action":"A","side":"B","depth":0,"price":"250.150000000","size":50,"flags":130,"ts_in_delta":166041,"sequence":314776,"levels":[{"bid_px":"250.150000000","ask_px":"251.150000000","bid_sz":100,"ask_sz":100,"bid_ct":2,"ask_ct":1},{"bid_px":"250.000000000","ask_px":"252.400000000","bid_sz":2,"ask_sz":1000,"bid_ct":2,"ask_ct":1},{"bid_px":"249.930000000","ask_px":"253.650000000","bid_sz":10,"ask_sz":400,"bid_ct":1,"ask_ct":1},{"bid_px":"249.880000000","ask_px":"255.000000000","bid_sz":4,"ask_sz":85,"bid_ct":1,"ask_ct":2},{"bid_px":"249.800000000","ask_px":"260.000000000","bid_sz":199,"ask_sz":168,"bid_ct":1,"ask_ct":3},{"bid_px":"249.770000000","ask_px":"262.660000000","bid_sz":50,"ask_sz":56,"bid_ct":1,"ask_ct":1},{"bid_px":"249.400000000","ask_px":"264.940000000","bid_sz":1000,"ask_sz":7,"bid_ct":1,"ask_ct":1},{"bid_px":"248.500000000","ask_px":"265.000000000","bid_sz":40,"ask_sz":102,"bid_ct":1,"ask_ct":3},{"bid_px":"247.150000000","ask_px":"267.800000000","bid_sz":400,"ask_sz":30,"bid_ct":1,"ask_ct":1},{"bid_px":"247.000000000","ask_px":"268.670000000","bid_sz":12,"ask_sz":100,"bid_ct":1,"ask_ct":1}],"symbol":"TSLA"}
{"ts_recv":"2024-11-01T08:00:12.124543568Z","hd":{"ts_event":"2024-11-01T08:00:12.124377080Z","rtype":10,"publisher_id":2,"instrument_id":10888},"action":"A","side":"B","depth":9,"price":"407.000000000","size":2,"flags":130,"ts_in_delta":166488,"sequence":314875,"levels":[{"bid_px":"410.000000000","ask_px":"414.000000000","bid_sz":1,"ask_sz":468,"bid_ct":1,"ask_ct":2},{"bid_px":"409.750000000","ask_px":"415.070000000","bid_sz":3,"ask_sz":246,"bid_ct":1,"ask_ct":1},{"bid_px":"409.670000000","ask_px":"415.350000000","bid_sz":100,"ask_sz":84,"bid_ct":1,"ask_ct":2},{"bid_px":"409.430000000","ask_px":"420.000000000","bid_sz":5,"ask_sz":3,"bid_ct":1,"ask_ct":1},{"bid_px":"409.080000000","ask_px":"440.000000000","bid_sz":2,"ask_sz":35,"bid_ct":1,"ask_ct":1},{"bid_px":"409.000000000","ask_px":"445.000000000","bid_sz":2,"ask_sz":25,"bid_ct":1,"ask_ct":1},{"bid_px":"408.970000000","ask_px":"445.680000000","bid_sz":12,"ask_sz":3,"bid_ct":1,"ask_ct":1},{"bid_px":"408.960000000","ask_px":"448.000000000","bid_sz":5,"ask_sz":15,"bid_ct":1,"ask_ct":2},{"bid_px":"407.600000000","ask_px":"450.000000000","bid_sz":16,"ask_sz":12,"bid_ct":1,"ask_ct":2},{"bid_px":"407.000000000","ask_px":"455.000000000","bid_sz":19,"ask_sz":5,"bid_ct":4,"ask_ct":1}],"symbol":"MSFT"}
{"ts_recv":"2024-11-01T08:00:12.137337594Z","hd":{"ts_event":"2024-11-01T08:00:12.137171993Z","rtype":10,"publisher_id":2,"instrument_id":16244},"action":"C","side":"B","depth":0,"price":"250.150000000","size":50,"flags":130,"ts_in_delta":165601,"sequence":314909,"levels":[{"bid_px":"250.150000000","ask_px":"251.150000000","bid_sz":50,"ask_sz":100,"bid_ct":1,"ask_ct":1},{"bid_px":"250.000000000","ask_px":"252.400000000","bid_sz":2,"ask_sz":1000,"bid_ct":2,"ask_ct":1},{"bid_px":"249.930000000","ask_px":"253.650000000","bid_sz":10,"ask_sz":400,"bid_ct":1,"ask_ct":1},{"bid_px":"249.880000000","ask_px":"255.000000000","bid_sz":4,"ask_sz":85,"bid_ct":1,"ask_ct":2},{"bid_px":"249.800000000","ask_px":"260.000000000","bid_sz":199,"ask_sz":168,"bid_ct":1,"ask_ct":3},{"bid_px":"249.770000000","ask_px":"262.660000000","bid_sz":50,"ask_sz":56,"bid_ct":1,"ask_ct":1},{"bid_px":"249.400000000","ask_px":"264.940000000","bid_sz":1000,"ask_sz":7,"bid_ct":1,"ask_ct":1},{"bid_px":"248.500000000","ask_px":"265.000000000","bid_sz":40,"ask_sz":102,"bid_ct":1,"ask_ct":3},{"bid_px":"247.150000000","ask_px":"267.800000000","bid_sz":400,"ask_sz":30,"bid_ct":1,"ask_ct":1},{"bid_px":"247.000000000","ask_px":"268.670000000","bid_sz":12,"ask_sz":100,"bid_ct":1,"ask_ct":1}],"symbol":"TSLA"}
{"ts_recv":"2024-11-01T08:00:12.137351725Z","hd":{"ts_event":"2024-11-01T08:00:12.137185661Z","rtype":10,"publisher_id":2,"instrument_id":16244},"action":"A","side":"B","depth":0,"price":"250.170000000","size":100,"flags":130,"ts_in_delta":166064,"sequence":314910,"levels":[{"bid_px":"250.170000000","ask_px":"251.150000000","bid_sz":100,"ask_sz":100,"bid_ct":1,"ask_ct":1},{"bid_px":"250.000000000","ask_px":"252.400000000","bid_sz":2,"ask_sz":1000,"bid_ct":2,"ask_ct":1},{"bid_px":"249.930000000","ask_px":"253.650000000","bid_sz":10,"ask_sz":400,"bid_ct":1,"ask_ct":1},{"bid_px":"249.880000000","ask_px":"255.000000000","bid_sz":4,"ask_sz":85,"bid_ct":1,"ask_ct":2},{"bid_px":"249.800000000","ask_px":"260.000000000","bid_sz":199,"ask_sz":168,"bid_ct":1,"ask_ct":3},{"bid_px":"249.770000000","ask_px":"262.660000000","bid_sz":50,"ask_sz":56,"bid_ct":1,"ask_ct":1},{"bid_px":"249.400000000","ask_px":"264.940000000","bid_sz":1000,"ask_sz":7,"bid_ct":1,"ask_ct":1},{"bid_px":"248.500000000","ask_px":"265.000000000","bid_sz":40,"ask_sz":102,"bid_ct":1,"ask_ct":3},{"bid_px":"247.150000000","ask_px":"267.800000000","bid_sz":400,"ask_sz":30,"bid_ct":1,"ask_ct":1},{"bid_px":"247.000000000","ask_px":"268.670000000","bid_sz":12,"ask_sz":100,"bid_ct":1,"ask_ct":1}],"symbol":"TSLA"}
{"ts_recv":"2024-11-01T08:00:12.151819356Z","hd":{"ts_event":"2024-11-01T08:00:12.151652685Z","rtype":10,"publisher_id":2,"instrument_id":10888},"action":"A","side":"B","depth":8,"price":"408.000000000","size":7,"flags":130,"ts_in_delta":166671,"sequence":315012,"levels":[{"bid_px":"410.000000000","ask_px":"414.000000000","bid_sz":1,"ask_sz":468,"bid_ct":1,"ask_ct":2},{"bid_px":"409.750000000","ask_px":"415.070000000","bid_sz":3,"ask_sz":246,"bid_ct":1,"ask_ct":1},{"bid_px":"409.670000000","ask_px":"415.350000000","bid_sz":100,"ask_sz":84,"bid_ct":1,"ask_ct":2},{"bid_px":"409.430000000","ask_px":"420.000000000","bid_sz":5,"ask_sz":3,"bid_ct":1,"ask_ct":1},{"bid_px":"409.080000000","ask_px":"440.000000000","bid_sz":2,"ask_sz":35,"bid_ct":1,"ask_ct":1},{"bid_px":"409.000000000","ask_px":"445.000000000","bid_sz":2,"ask_sz":25,"bid_ct":1,"ask_ct":1},{"bid_px":"408.970000000","ask_px":"445.680000000","bid_sz":12,"ask_sz":3,"bid_ct":1,"ask_ct":1},{"bid_px":"408.960000000","ask_px":"448.000000000","bid_sz":5,"ask_sz":15,"bid_ct":1,"ask_ct":2},{"bid_px":"408.000000000","ask_px":"450.000000000","bid_sz":7,"ask_sz":12,"bid_ct":1,"ask_ct":2},{"bid_px":"407.600000000","ask_px":"455.000000000","bid_sz":16,"ask_sz":5,"bid_ct":1,"ask_ct":1}],"symbol":"MSFT"}
{"ts_recv":"2024-11-01T08:00:12.168886635Z","hd":{"ts_event":"2024-11-01T08:00:12.168720539Z","rtype":10,"publisher_id":2,"instrument_id":12463},"action":"A","side":"B","depth":0,"price":"163.350000000","size":100,"flags":130,"ts_in_delta":166096,"sequence":315079,"levels":[{"bid_px":"163.350000000","ask_px":"171.810000000","bid_sz":100,"ask_sz":100,"bid_ct":1,"ask_ct":1},{"bid_px":null,"ask_px":"180.000000000","bid_sz":0,"ask_sz":20,"bid_ct":0,"ask_ct":1},{"bid_px":null,"ask_px":null,"bid_sz":0,"ask_sz":0,"bid_ct":0,"ask_ct":0},{"bid_px":null,"ask_px":null,"bid_sz":0,"ask_sz":0,"bid_ct":0,"ask_ct":0},{"bid_px":null,"ask_px":null,"bid_sz":0,"ask_sz":0,"bid_ct":0,"ask_ct":0},{"bid_px":null,"ask_px":null,"bid_sz":0,"ask_sz":0,"bid_ct":0,"ask_ct":0},{"bid_px":null,"ask_px":null,"bid_sz":0,"ask_sz":0,"bid_ct":0,"ask_ct":0},{"bid_px":null,"ask_px":null,"bid_sz":0,"ask_sz":0,"bid_ct":0,"ask_ct":0},{"bid_px":null,"ask_px":null,"bid_sz":0,"ask_sz":0,"bid_ct":0,"ask_ct":0},{"bid_px":null,"ask_px":null,"bid_sz":0,"ask_sz":0,"bid_ct":0,"ask_ct":0}],"symbol":"PEP"}
{"ts_recv":"2024-11-01T08:00:12.179037891Z","hd":{"ts_event":"2024-11-01T08:00:12.178871744Z","rtype":10,"publisher_id":2,"instrument_id":11667},"action":"A","side":"B","depth":9,"price":"132.800000000","size":89,"flags":130,"ts_in_delta":166147,"sequence":315115,"levels":[{"bid_px":"134.680000000","ask_px":"134.990000000","bid_sz":100,"ask_sz":10,"bid_ct":1,"ask_ct":1},{"bid_px":"134.500000000","ask_px":"135.000000000","bid_sz":520,"ask_sz":38,"bid_ct":2,"ask_ct":3},{"bid_px":"134.410000000","ask_px":"135.100000000","bid_sz":61,"ask_sz":10,"bid_ct":2,"ask_ct":1},{"bid_px":"134.380000000","ask_px":"135.230000000","bid_sz":18,"ask_sz":360,"bid_ct":1,"ask_ct":1},{"bid_px":"134.210000000","ask_px":"135.300000000","bid_sz":20,"ask_sz":1000,"bid_ct":1,"ask_ct":1},{"bid_px":"134.200000000","ask_px":"135.400000000","bid_sz":3,"ask_sz":10,"bid_ct":1,"ask_ct":1},{"bid_px":"134.000000000","ask_px":"135.420000000","bid_sz":1,"ask_sz":1,"bid_ct":1,"ask_ct":1},{"bid_px":"133.800000000","ask_px":"135.820000000","bid_sz":5,"ask_sz":1,"bid_ct":1,"ask_ct":1},{"bid_px":"133.160000000","ask_px":"135.990000000","bid_sz":1,"ask_sz":20,"bid_ct":1,"ask_ct":1},{"bid_px":"132.800000000","ask_px":"136.100000000","bid_sz":89,"ask_sz":1000,"bid_ct":1,"ask_ct":1}],"symbol":"NVDA"}
{"ts_recv":"2024-11-01T08:00:12.248002240Z","hd":{"ts_event":"2024-11-01T08:00:12.247834610Z","rtype":10,"publisher_id":2,"instrument_id":12463},"action":"A","side":"B","depth":0,"price":"163.440000000","size":100,"flags":130,"ts_in_delta":167630,"sequence":315222,"levels":[{"bid_px":"163.440000000","ask_px":"171.810000000","bid_sz":100,"ask_sz":100,"bid_ct":1,"ask_ct":1},{"bid_px":null,"ask_px":"180.000000000","bid_sz":0,"ask_sz":20,"bid_ct":0,"ask_ct":1},{"bid_px":null,"ask_px":null,"bid_sz":0,"ask_sz":0,"bid_ct":0,"ask_ct":0},{"bid_px":null,"ask_px":null,"bid_sz":0,"ask_sz":0,"bid_ct":0,"ask_ct":0},{"bid_px":null,"ask_px":null,"bid_sz":0,"ask_sz":0,"bid_ct":0,"ask_ct":0},{"bid_px":null,"ask_px":null,"bid_sz":0,"ask_sz":0,"bid_ct":0,"ask_ct":0},{"bid_px":null,"ask_px":null,"bid_sz":0,"ask_sz":0,"bid_ct":0,"ask_ct":0},{"bid_px":null,"ask_px":null,"bid_sz":0,"ask_sz":0,"bid_ct":0,"ask_ct":0},{"bid_px":null,"ask_px":null,"bid_sz":0,"ask_sz":0,"bid_ct":0,"ask_ct":0},{"bid_px":null,"ask_px":null,"bid_sz":0,"ask_sz":0,"bid_ct":0,"ask_ct":0}],"symbol":"PEP"}
{"ts_recv":"2024-11-01T08:00:12.259106789Z","hd":{"ts_event":"2024-11-01T08:00:12.258940574Z","rtype":10,"publisher_id":2,"instrument_id":16244},"action":"A","side":"A","depth":1,"price":"251.500000000","size":50,"flags":130,"ts_in_delta":166215,"sequence":315240,"levels":[{"bid_px":"250.170000000","ask_px":"251.150000000","bid_sz":100,"ask_sz":100,"bid_ct":1,"ask_ct":1},{"bid_px":"250.000000000","ask_px":"251.500000000","bid_sz":2,"ask_sz":50,"bid_ct":2,"ask_ct":1},{"bid_px":"249.930000000","ask_px":"252.400000000","bid_sz":10,"ask_sz":1000,"bid_ct":1,"ask_ct":1},{"bid_px":"249.880000000","ask_px":"253.650000000","bid_sz":4,"ask_sz":400,"bid_ct":1,"ask_ct":1},{"bid_px":"249.800000000","ask_px":"255.000000000","bid_sz":199,"ask_sz":85,"bid_ct":1,"ask_ct":2},{"bid_px":"249.770000000","ask_px":"260.000000000","bid_sz":50,"ask_sz":168,"bid_ct":1,"ask_ct":3},{"bid_px":"249.400000000","ask_px":"262.660000000","bid_sz":1000,"ask_sz":56,"bid_ct":1,"ask_ct":1},{"bid_px":"248.500000000","ask_px":"264.940000000","bid_sz":40,"ask_sz":7,"bid_ct":1,"ask_ct":1},{"bid_px":"247.150000000","ask_px":"265.000000000","bid_sz":400,"ask_sz":102,"bid_ct":1,"ask_ct":3},{"bid_px":"247.000000000","ask_px":"267.800000000","bid_sz":12,"ask_sz":30,"bid_ct":1,"ask_ct":1}],"symbol":"TSLA"}
{"ts_recv":"2024-11-01T08:00:12.278103756Z","hd":{"ts_event":"2024-11-01T08:00:12.277937537Z","rtype":10,"publisher_id":2,"instrument_id":16244},"action":"A","side":"A","depth":1,"price":"251.500000000","size":50,"flags":130,"ts_in_delta":166219,"sequence":315276,"levels":[{"bid_px":"250.170000000","ask_px":"251.150000000","bid_sz":100,"ask_sz":100,"bid_ct":1,"ask_ct":1},{"bid_px":"250.000000000","ask_px":"251.500000000","bid_sz":2,"ask_sz":100,"bid_ct":2,"ask_ct":2},{"bid_px":"249.930000000","ask_px":"252.400000000","bid_sz":10,"ask_sz":1000,"bid_ct":1,"ask_ct":1},{"bid_px":"249.880000000","ask_px":"253.650000000","bid_sz":4,"ask_sz":400,"bid_ct":1,"ask_ct":1},{"bid_px":"249.800000000","ask_px":"255.000000000","bid_sz":199,"ask_sz":85,"bid_ct":1,"ask_ct":2},{"bid_px":"249.770000000","ask_px":"260.000000000","bid_sz":50,"ask_sz":168,"bid_ct":1,"ask_ct":3},{"bid_px":"249.400000000","ask_px":"262.660000000","bid_sz":1000,"ask_sz":56,"bid_ct":1,"ask_ct":1},{"bid_px":"248.500000000","ask_px":"264.940000000","bid_sz":40,"ask_sz":7,"bid_ct":1,"ask_ct":1},{"bid_px":"247.150000000","ask_px":"265.000000000","bid_sz":400,"ask_sz":102,"bid_ct":1,"ask_ct":3},{"bid_px":"247.000000000","ask_px":"267.800000000","bid_sz":12,"ask_sz":30,"bid_ct":1,"ask_ct":1}],"symbol":"TSLA"}
{"ts_recv":"2024-11-01T08:00:12.311466890Z","hd":{"ts_event":"2024-11-01T08:00:12.311300895Z","rtype":10,"publisher_id":2,"instrument_id":16244},"action":"C","side":"A","depth":1,"price":"251.500000000","size":50,"flags":130,"ts_in_delta":165995,"sequence":315376,"levels":[{"bid_px":"250.170000000","ask_px":"251.150000000","bid_sz":100,"ask_sz":100,"bid_ct":1,"ask_ct":1},{"bid_px":"250.000000000","ask_px":"251.500000000","bid_sz":2,"ask_sz":50,"bid_ct":2,"ask_ct":1},{"bid_px":"249.930000000","ask_px":"252.400000000","bid_sz":10,"ask_sz":1000,"bid_ct":1,"ask_ct":1},{"bid_px":"249.880000000","ask_px":"253.650000000","bid_sz":4,"ask_sz":400,"bid_ct":1,"ask_ct":1},{"bid_px":"249.800000000","ask_px":"255.000000000","bid_sz":199,"ask_sz":85,"bid_ct":1,"ask_ct":2},{"bid_px":"249.770000000","ask_px":"260.000000000","bid_sz":50,"ask_sz":168,"bid_ct":1,"ask_ct":3},{"bid_px":"249.400000000","ask_px":"262.660000000","bid_sz":1000,"ask_sz":56,"bid_ct":1,"ask_ct":1},{"bid_px":"248.500000000","ask_px":"264.940000000","bid_sz":40,"ask_sz":7,"bid_ct":1,"ask_ct":1},{"bid_px":"247.150000000","ask_px":"265.000000000","bid_sz":400,"ask_sz":102,"bid_ct":1,"ask_ct":3},{"bid_px":"247.000000000","ask_px":"267.800000000","bid_sz":12,"ask_sz":30,"bid_ct":1,"ask_ct":1}],"symbol":"TSLA"}
