ts_recv,ts_event,rtype,publisher_id,instrument_id,action,side,depth,price,size,flags,ts_in_delta,sequence,bid_px_00,ask_px_00,bid_sz_00,ask_sz_00,bid_ct_00,ask_ct_00,bid_px_01,ask_px_01,bid_sz_01,ask_sz_01,bid_ct_01,ask_ct_01,bid_px_02,ask_px_02,bid_sz_02,ask_sz_02,bid_ct_02,ask_ct_02,bid_px_03,ask_px_03,bid_sz_03,ask_sz_03,bid_ct_03,ask_ct_03,bid_px_04,ask_px_04,bid_sz_04,ask_sz_04,bid_ct_04,ask_ct_04,bid_px_05,ask_px_05,bid_sz_05,ask_sz_05,bid_ct_05,ask_ct_05,bid_px_06,ask_px_06,bid_sz_06,ask_sz_06,bid_ct_06,ask_ct_06,bid_px_07,ask_px_07,bid_sz_07,ask_sz_07,bid_ct_07,ask_ct_07,bid_px_08,ask_px_08,bid_sz_08,ask_sz_08,bid_ct_08,ask_ct_08,bid_px_09,ask_px_09,bid_sz_09,ask_sz_09,bid_ct_09,ask_ct_09,symbol
2024-11-01T08:00:09.070231821Z,2024-11-01T08:00:09.070065678Z,10,2,16244,A,B,9,246.000000000,4,130,166143,307784,250.030000000,250.720000000,50,100,1,1,249.930000000,250.760000000,10,50,1,1,249.800000000,252.400000000,199,1000,1,1,249.770000000,253.650000000,50,400,1,1,249.600000000,255.000000000,1000,10,1,1,249.500000000,260.000000000,1000,48,1,1,249.400000000,262.660000000,1000,56,1,1,247.700000000,264.940000000,1000,7,1,1,247.150000000,265.000000000,400,1,1,1,246.000000000,267.800000000,4,30,1,1,TSLA
2024-11-01T08:00:09.105225849Z,2024-11-01T08:00:09.105059506Z,10,2,11667,A,B,0,134.670000000,100,130,166343,307835,134.670000000,134.990000000,100,10,1,1,134.500000000,135.000000000,500,38,1,3,134.410000000,135.100000000,61,10,2,1,134.380000000,135.230000000,18,360,1,1,134.210000000,135.300000000,20,1000,1,1,134.200000000,135.400000000,3,10,1,1,133.160000000,135.420000000,1,1,1,1,132.700000000,135.820000000,4,1,1,1,132.660000000,135.990000000,1,20,1,1,132.160000000,136.100000000,1,1000,1,1,NVDA
2024-11-01T08:00:09.184621728Z,2024-11-01T08:00:09.184455471Z,10,2,16244,A,B,9,247.000000000,12,130,166257,307945,250.030000000,250.720000000,50,100,1,1,249.930000000,250.760000000,10,50,1,1,249.800000000,252.400000000,199,1000,1,1,249.770000000,253.650000000,50,400,1,1,249.600000000,255.000000000,1000,10,1,1,249.500000000,260.000000000,1000,48,1,1,249.400000000,262.660000000,1000,56,1,1,247.700000000,264.940000000,1000,7,1,1,247.150000000,265.000000000,400,1,1,1,247.000000000,267.800000000,12,30,1,1,TSLA
2024-11-01T08:00:09.237350461Z,2024-11-01T08:00:09.237184087Z,10,2,16244,A,B,1,250.000000000,1,130,166374,308002,250.030000000,250.720000000,50,100,1,1,250.000000000,250.760000000,1,50,1,1,249.930000000,252.400000000,10,1000,1,1,249.800000000,253.650000000,199,400,1,1,249.770000000,255.000000000,50,10,1,1,249.600000000,260.000000000,1000,48,1,1,249.500000000,262.660000000,1000,56,1,1,249.400000000,264.940000000,1000,7,1,1,247.700000000,265.000000000,1000,1,1,1,247.150000000,267.800000000,400,30,1,1,TSLA
2024-11-01T08:00:09.238148826Z,2024-11-01T08:00:09.237982939Z,10,2,16244,C,B,7,249.400000000,1000,130,165887,308003,250.030000000,250.720000000,50,100,1,1,250.000000000,250.760000000,1,50,1,1,249.930000000,252.400000000,10,1000,1,1,249.800000000,253.650000000,199,400,1,1,249.770000000,255.000000000,50,10,1,1,249.600000000,260.000000000,1000,48,1,1,249.500000000,262.660000000,1000,56,1,1,247.700000000,264.940000000,1000,7,1,1,247.150000000,265.000000000,400,1,1,1,247.000000000,267.800000000,12,30,1,1,TSLA
2024-11-01T08:00:09.248919398Z,2024-11-01T08:00:09.248753431Z,10,2,16244,A,B,7,248.600000000,1000,130,165967,308020,250.030000000,250.720000000,50,100,1,1,250.000000000,250.760000000,1,50,1,1,249.930000000,252.400000000,10,1000,1,1,249.800000000,253.650000000,199,400,1,1,249.770000000,255.000000000,50,10,1,1,249.600000000,260.000000000,1000,48,1,1,249.500000000,262.660000000,1000,56,1,1,248.600000000,264.940000000,1000,7,1,1,247.700000000,265.000000000,1000,1,1,1,247.150000000,267.800000000,400,30,1,1,TSLA
2024-11-01T08:00:09.248957175Z,2024-11-01T08:00:09.248791239Z,10,2,16244,C,B,8,247.700000000,1000,130,165936,308021,250.030000000,250.720000000,50,100,1,1,250.000000000,250.760000000,1,50,1,1,249.930000000,252.400000000,10,1000,1,1,249.800000000,253.650000000,199,400,1,1,249.770000000,255.000000000,50,10,1,1,249.600000000,260.000000000,1000,48,1,1,249.500000000,262.660000000,1000,56,1,1,248.600000000,264.940000000,1000,7,1,1,247.150000000,265.000000000,400,1,1,1,247.000000000,267.800000000,12,30,1,1,TSLA
2024-11-01T08:00:09.277140273Z,2024-11-01T08:00:09.276974348Z,10,2,10888,A,A,0,414.000000000,33,130,165925,308057,410.000000000,414.000000000,1,33,1,1,409.080000000,415.070000000,2,246,1,1,408.970000000,420.000000000,12,3,1,1,408.960000000,445.000000000,5,25,1,1,407.600000000,445.680000000,16,3,1,1,407.000000000,448.000000000,4,15,2,2,406.350000000,450.000000000,2,10,1,1,406.000000000,468.000000000,7,65,1,1,405.000000000,472.000000000,15,6,2,1,404.410000000,,246,0,1,0,MSFT
2024-11-01T08:00:09.308061326Z,2024-11-01T08:00:09.307894586Z,10,2,11667,A,B,1,134.500000000,20,130,166740,308102,134.670000000,134.990000000,100,10,1,1,134.500000000,135.000000000,520,38,2,3,134.410000000,135.100000000,61,10,2,1,134.380000000,135.230000000,18,360,1,1,134.210000000,135.300000000,20,1000,1,1,134.200000000,135.400000000,3,10,1,1,133.160000000,135.420000000,1,1,1,1,132.700000000,135.820000000,4,1,1,1,132.660000000,135.990000000,1,20,1,1,132.160000000,136.100000000,1,1000,1,1,NVDA
2024-11-01T08:00:09.310782807Z,2024-11-01T08:00:09.310616621Z,10,2,16244,A,A,4,255.000000000,75,130,166186,308109,250.030000000,250.720000000,50,100,1,1,250.000000000,250.760000000,1,50,1,1,249.930000000,252.400000000,10,1000,1,1,249.800000000,253.650000000,199,400,1,1,249.770000000,255.000000000,50,85,1,2,249.600000000,260.000000000,1000,48,1,1,249.500000000,262.660000000,1000,56,1,1,248.600000000,264.940000000,1000,7,1,1,247.150000000,265.000000000,400,1,1,1,247.000000000,267.800000000,12,30,1,1,TSLA
2024-11-01T08:00:09.375551471Z,2024-11-01T08:00:09.375379710Z,10,2,38,A,A,1,225.000000000,1,130,171761,308238,221.100000000,224.400000000,1000,1000,1,1,220.000000000,225.000000000,2,1,1,1,219.690000000,225.360000000,442,1,1,1,217.000000000,225.490000000,1525,442,1,1,200.000000000,225.900000000,30,32,1,2,190.000000000,229.330000000,1,9,1,2,180.000000000,233.670000000,1,5,1,1,100.000000000,234.000000000,1,20,1,1,,235.000000000,0,2,0,1,,238.760000000,0,150,0,1,AAPL
2024-11-01T08:00:09.376139884Z,2024-11-01T08:00:09.375973484Z,10,2,16727,A,N,0,305.000000000,1,130,166400,308239,,305.000000000,0,1,0,1,,,0,0,0,0,,,0,0,0,0,,,0,0,0,0,,,0,0,0,0,,,0,0,0,0,,,0,0,0,0,,,0,0,0,0,,,0,0,0,0,,,0,0,0,0,V
2024-11-01T08:00:09.418377932Z,2024-11-01T08:00:09.418212103Z,10,2,16244,C,A,1,250.760000000,50,130,165829,308333,250.030000000,250.720000000,50,100,1,1,250.000000000,252.400000000,1,1000,1,1,249.930000000,253.650000000,10,400,1,1,249.800000000,255.000000000,199,85,1,2,249.770000000,260.000000000,50,48,1,1,249.600000000,262.660000000,1000,56,1,1,249.500000000,264.940000000,1000,7,1,1,248.600000000,265.000000000,1000,1,1,1,247.150000000,267.800000000,400,30,1,1,247.000000000,268.670000000,12,100,1,1,TSLA
2024-11-01T08:00:09.418389580Z,2024-11-01T08:00:09.418223858Z,10,2,16244,A,A,1,250.850000000,50,130,165722,308334,250.030000000,250.720000000,50,100,1,1,250.000000000,250.850000000,1,50,1,1,249.930000000,252.400000000,10,1000,1,1,249.800000000,253.650000000,199,400,1,1,249.770000000,255.000000000,50,85,1,2,249.600000000,260.000000000,1000,48,1,1,249.500000000,262.660000000,1000,56,1,1,248.600000000,264.940000000,1000,7,1,1,247.150000000,265.000000000,400,1,1,1,247.000000000,267.800000000,12,30,1,1,TSLA
2024-11-01T08:00:09.418425546Z,2024-11-01T08:00:09.418259940Z,10,2,16244,C,A,1,250.850000000,50,130,165606,308335,250.030000000,250.720000000,50,100,1,1,250.000000000,252.400000000,1,1000,1,1,249.930000000,253.650000000,10,400,1,1,249.800000000,255.000000000,199,85,1,2,249.770000000,260.000000000,50,48,1,1,249.600000000,262.660000000,1000,56,1,1,249.500000000,264.940000000,1000,7,1,1,248.600000000,265.000000000,1000,1,1,1,247.150000000,267.800000000,400,30,1,1,247.000000000,268.670000000,12,100,1,1,TSLA
2024-11-01T08:00:09.418520594Z,2024-11-01T08:00:09.418354592Z,10,2,16244,A,A,1,251.090000000,50,130,166002,308336,250.030000000,250.720000000,50,100,1,1,250.000000000,251.090000000,1,50,1,1,249.930000000,252.400000000,10,1000,1,1,249.800000000,253.650000000,199,400,1,1,249.770000000,255.000000000,50,85,1,2,249.600000000,260.000000000,1000,48,1,1,249.500000000,262.660000000,1000,56,1,1,248.600000000,264.940000000,1000,7,1,1,247.150000000,265.000000000,400,1,1,1,247.000000000,267.800000000,12,30,1,1,TSLA
2024-11-01T08:00:09.418532243Z,2024-11-01T08:00:09.418366536Z,10,2,16244,C,B,0,250.030000000,50,130,165707,308337,250.000000000,250.720000000,1,100,1,1,249.930000000,251.090000000,10,50,1,1,249.800000000,252.400000000,199,1000,1,1,249.770000000,253.650000000,50,400,1,1,249.600000000,255.000000000,1000,85,1,2,249.500000000,260.000000000,1000,48,1,1,248.600000000,262.660000000,1000,56,1,1,247.150000000,264.940000000,400,7,1,1,247.000000000,265.000000000,12,1,1,1,246.000000000,267.800000000,4,30,1,1,TSLA
2024-11-01T08:00:09.418543180Z,2024-11-01T08:00:09.418377438Z,10,2,16244,A,B,1,249.980000000,50,130,165742,308338,250.000000000,250.720000000,1,100,1,1,249.980000000,251.090000000,50,50,1,1,249.930000000,252.400000000,10,1000,1,1,249.800000000,253.650000000,199,400,1,1,249.770000000,255.000000000,50,85,1,2,249.600000000,260.000000000,1000,48,1,1,249.500000000,262.660000000,1000,56,1,1,248.600000000,264.940000000,1000,7,1,1,247.150000000,265.000000000,400,1,1,1,247.000000000,267.800000000,12,30,1,1,TSLA
2024-11-01T08:00:09.418593088Z,2024-11-01T08:00:09.418426750Z,10,2,16244,C,B,1,249.980000000,50,130,166338,308339,250.000000000,250.720000000,1,100,1,1,249.930000000,251.090000000,10,50,1,1,249.800000000,252.400000000,199,1000,1,1,249.770000000,253.650000000,50,400,1,1,249.600000000,255.000000000,1000,85,1,2,249.500000000,260.000000000,1000,48,1,1,248.600000000,262.660000000,1000,56,1,1,247.150000000,264.940000000,400,7,1,1,247.000000000,265.000000000,12,1,1,1,246.000000000,267.800000000,4,30,1,1,TSLA
2024-11-01T08:00:09.418640702Z,2024-11-01T08:00:09.418474852Z,10,2,16244,A,B,2,249.920000000,50,130,165850,308340,250.000000000,250.720000000,1,100,1,1,249.930000000,251.090000000,10,50,1,1,249.920000000,252.400000000,50,1000,1,1,249.800000000,253.650000000,199,400,1,1,249.770000000,255.000000000,50,85,1,2,249.600000000,260.000000000,1000,48,1,1,249.500000000,262.660000000,1000,56,1,1,248.600000000,264.940000000,1000,7,1,1,247.150000000,265.000000000,400,1,1,1,247.000000000,267.800000000,12,30,1,1,TSLA
2024-11-01T08:00:09.445856807Z,2024-11-01T08:00:09.445690849Z,10,2,10888,A,B,1,409.750000000,3,130,165958,308395,410.000000000,414.000000000,1,33,1,1,409.750000000,415.070000000,3,246,1,1,409.080000000,420.000000000,2,3,1,1,408.970000000,445.000000000,12,25,1,1,408.960000000,445.680000000,5,3,1,1,407.600000000,448.000000000,16,15,1,2,407.000000000,450.000000000,4,10,2,1,406.350000000,468.000000000,2,65,1,1,406.000000000,472.000000000,7,6,1,1,405.000000000,,15,0,2,0,MSFT
2024-11-01T08:00:09.517904343Z,2024-11-01T08:00:09.517738185Z,10,2,10888,A,B,7,406.350000000,80,130,166158,308484,410.000000000,414.000000000,1,33,1,1,409.750000000,415.070000000,3,246,1,1,409.080000000,420.000000000,2,3,1,1,408.970000000,445.000000000,12,25,1,1,408.960000000,445.680000000,5,3,1,1,407.600000000,448.000000000,16,15,1,2,407.000000000,450.000000000,4,10,2,1,406.350000000,468.000000000,82,65,2,1,406.000000000,472.000000000,7,6,1,1,405.000000000,,15,0,2,0,MSFT
2024-11-01T08:00:09.535022669Z,2024-11-01T08:00:09.534856493Z,10,2,38,A,B,4,213.000000000,5,130,166176,308531,221.100000000,224.400000000,1000,1000,1,1,220.000000000,225.000000000,2,1,1,1,219.690000000,225.360000000,442,1,1,1,217.000000000,225.490000000,1525,442,1,1,213.000000000,225.900000000,5,32,1,2,200.000000000,229.330000000,30,9,1,2,190.000000000,233.670000000,1,5,1,1,180.000000000,234.000000000,1,20,1,1,100.000000000,235.000000000,1,2,1,1,,238.760000000,0,150,0,1,AAPL
2024-11-01T08:00:09.552701395Z,2024-11-01T08:00:09.552535219Z,10,2,38,A,B,5,210.000000000,1,130,166176,308600,221.100000000,224.400000000,1000,1000,1,1,220.000000000,225.000000000,2,1,1,1,219.690000000,225.360000000,442,1,1,1,217.000000000,225.490000000,1525,442,1,1,213.000000000,225.900000000,5,32,1,2,210.000000000,229.330000000,1,9,1,2,200.000000000,233.670000000,30,5,1,1,190.000000000,234.000000000,1,20,1,1,180.000000000,235.000000000,1,2,1,1,100.000000000,238.760000000,1,150,1,1,AAPL
2024-11-01T08:00:09.572901021Z,2024-11-01T08:00:09.572735201Z,10,2,38,C,B,0,221.100000000,1000,130,165820,308655,220.000000000,224.400000000,2,1000,1,1,219.690000000,225.000000000,442,1,1,1,217.000000000,225.360000000,1525,1,1,1,213.000000000,225.490000000,5,442,1,1,210.000000000,225.900000000,1,32,1,2,200.000000000,229.330000000,30,9,1,2,190.000000000,233.670000000,1,5,1,1,180.000000000,234.000000000,1,20,1,1,100.000000000,235.000000000,1,2,1,1,,238.760000000,0,150,0,1,AAPL
2024-11-01T08:00:09.608484297Z,2024-11-01T08:00:09.608317265Z,10,2,38,A,B,0,221.300000000,1000,130,167032,308822,221.300000000,224.400000000,1000,1000,1,1,220.000000000,225.000000000,2,1,1,1,219.690000000,225.360000000,442,1,1,1,217.000000000,225.490000000,1525,442,1,1,213.000000000,225.900000000,5,32,1,2,210.000000000,229.330000000,1,9,1,2,200.000000000,233.670000000,30,5,1,1,190.000000000,234.000000000,1,20,1,1,180.000000000,235.000000000,1,2,1,1,100.000000000,238.760000000,1,150,1,1,AAPL
2024-11-01T08:00:09.622940156Z,2024-11-01T08:00:09.622774366Z,10,2,38,A,B,3,219.000000000,1,130,165790,308901,221.300000000,224.400000000,1000,1000,1,1,220.000000000,225.000000000,2,1,1,1,219.690000000,225.360000000,442,1,1,1,219.000000000,225.490000000,1,442,1,1,217.000000000,225.900000000,1525,32,1,2,213.000000000,229.330000000,5,9,1,2,210.000000000,233.670000000,1,5,1,1,200.000000000,234.000000000,30,20,1,1,190.000000000,235.000000000,1,2,1,1,180.000000000,238.760000000,1,150,1,1,AAPL
2024-11-01T08:00:09.643218540Z,2024-11-01T08:00:09.643052065Z,10,2,11667,A,B,7,132.760000000,100,130,166475,308999,134.670000000,134.990000000,100,10,1,1,134.500000000,135.000000000,520,38,2,3,134.410000000,135.100000000,61,10,2,1,134.380000000,135.230000000,18,360,1,1,134.210000000,135.300000000,20,1000,1,1,134.200000000,135.400000000,3,10,1,1,133.160000000,135.420000000,1,1,1,1,132.760000000,135.820000000,100,1,1,1,132.700000000,135.990000000,4,20,1,1,132.660000000,136.100000000,1,1000,1,1,NVDA
2024-11-01T08:00:09.696356146Z,2024-11-01T08:00:09.696189765Z,10,2,16244,A,B,1,249.970000000,50,130,166381,309221,250.000000000,250.720000000,1,100,1,1,249.970000000,251.090000000,50,50,1,1,249.930000000,252.400000000,10,1000,1,1,249.800000000,253.650000000,199,400,1,1,249.770000000,255.000000000,50,85,1,2,249.600000000,260.000000000,1000,48,1,1,249.500000000,262.660000000,1000,56,1,1,248.600000000,264.940000000,1000,7,1,1,247.150000000,265.000000000,400,1,1,1,247.000000000,267.800000000,12,30,1,1,TSLA
2024-11-01T08:00:09.738821655Z,2024-11-01T08:00:09.738655371Z,10,2,10888,A,B,6,407.000000000,13,130,166284,309298,410.000000000,414.000000000,1,33,1,1,409.750000000,415.070000000,3,246,1,1,409.080000000,420.000000000,2,3,1,1,408.970000000,445.000000000,12,25,1,1,408.960000000,445.680000000,5,3,1,1,407.600000000,448.000000000,16,15,1,2,407.000000000,450.000000000,17,10,3,1,406.350000000,468.000000000,82,65,2,1,406.000000000,472.000000000,7,6,1,1,405.000000000,,15,0,2,0,MSFT
2024-11-01T08:00:09.784828619Z,2024-11-01T08:00:09.784663053Z,10,2,16244,C,A,0,250.720000000,100,130,165566,309442,250.000000000,251.090000000,1,50,1,1,249.970000000,252.400000000,50,1000,1,1,249.930000000,253.650000000,10,400,1,1,249.800000000,255.000000000,199,85,1,2,249.770000000,260.000000000,50,48,1,1,249.600000000,262.660000000,1000,56,1,1,249.500000000,264.940000000,1000,7,1,1,248.600000000,265.000000000,1000,1,1,1,247.150000000,267.800000000,400,30,1,1,247.000000000,268.670000000,12,100,1,1,TSLA
2024-11-01T08:00:09.784842070Z,2024-11-01T08:00:09.784676131Z,10,2,16244,A,A,0,250.740000000,100,130,165939,309443,250.000000000,250.740000000,1,100,1,1,249.970000000,251.090000000,50,50,1,1,249.930000000,252.400000000,10,1000,1,1,249.800000000,253.650000000,199,400,1,1,249.770000000,255.000000000,50,85,1,2,249.600000000,260.000000000,1000,48,1,1,249.500000000,262.660000000,1000,56,1,1,248.600000000,264.940000000,1000,7,1,1,247.150000000,265.000000000,400,1,1,1,247.000000000,267.800000000,12,30,1,1,TSLA
2024-11-01T08:00:09.784885483Z,2024-11-01T08:00:09.784719694Z,10,2,16244,C,A,0,250.740000000,100,130,165789,309444,250.000000000,251.090000000,1,50,1,1,249.970000000,252.400000000,50,1000,1,1,249.930000000,253.650000000,10,400,1,1,249.800000000,255.000000000,199,85,1,2,249.770000000,260.000000000,50,48,1,1,249.600000000,262.660000000,1000,56,1,1,249.500000000,264.940000000,1000,7,1,1,248.600000000,265.000000000,1000,1,1,1,247.150000000,267.800000000,400,30,1,1,247.000000000,268.670000000,12,100,1,1,TSLA
2024-11-01T08:00:09.784946250Z,2024-11-01T08:00:09.784779245Z,10,2,16244,A,A,0,250.800000000,100,130,167005,309445,250.000000000,250.800000000,1,100,1,1,249.970000000,251.090000000,50,50,1,1,249.930000000,252.400000000,10,1000,1,1,249.800000000,253.650000000,199,400,1,1,249.770000000,255.000000000,50,85,1,2,249.600000000,260.000000000,1000,48,1,1,249.500000000,262.660000000,1000,56,1,1,248.600000000,264.940000000,1000,7,1,1,247.150000000,265.000000000,400,1,1,1,247.000000000,267.800000000,12,30,1,1,TSLA
2024-11-01T08:00:09.785109969Z,2024-11-01T08:00:09.784944294Z,10,2,16244,C,A,0,250.800000000,100,130,165675,309446,250.000000000,251.090000000,1,50,1,1,249.970000000,252.400000000,50,1000,1,1,249.930000000,253.650000000,10,400,1,1,249.800000000,255.000000000,199,85,1,2,249.770000000,260.000000000,50,48,1,1,249.600000000,262.660000000,1000,56,1,1,249.500000000,264.940000000,1000,7,1,1,248.600000000,265.000000000,1000,1,1,1,247.150000000,267.800000000,400,30,1,1,247.000000000,268.670000000,12,100,1,1,TSLA
2024-11-01T08:00:09.785121862Z,2024-11-01T08:00:09.784955737Z,10,2,16244,A,A,0,251.010000000,100,130,166125,309447,250.000000000,251.010000000,1,100,1,1,249.970000000,251.090000000,50,50,1,1,249.930000000,252.400000000,10,1000,1,1,249.800000000,253.650000000,199,400,1,1,249.770000000,255.000000000,50,85,1,2,249.600000000,260.000000000,1000,48,1,1,249.500000000,262.660000000,1000,56,1,1,248.600000000,264.940000000,1000,7,1,1,247.150000000,265.000000000,400,1,1,1,247.000000000,267.800000000,12,30,1,1,TSLA
2024-11-01T08:00:09.786503869Z,2024-11-01T08:00:09.786337768Z,10,2,16244,C,A,0,251.010000000,100,130,166101,309452,250.000000000,251.090000000,1,50,1,1,249.970000000,252.400000000,50,1000,1,1,249.930000000,253.650000000,10,400,1,1,249.800000000,255.000000000,199,85,1,2,249.770000000,260.000000000,50,48,1,1,249.600000000,262.660000000,1000,56,1,1,249.500000000,264.940000000,1000,7,1,1,248.600000000,265.000000000,1000,1,1,1,247.150000000,267.800000000,400,30,1,1,247.000000000,268.670000000,12,100,1,1,TSLA
2024-11-01T08:00:09.786515173Z,2024-11-01T08:00:09.786349334Z,10,2,16244,A,A,0,251.030000000,100,130,165839,309453,250.000000000,251.030000000,1,100,1,1,249.970000000,251.090000000,50,50,1,1,249.930000000,252.400000000,10,1000,1,1,249.800000000,253.650000000,199,400,1,1,249.770000000,255.000000000,50,85,1,2,249.600000000,260.000000000,1000,48,1,1,249.500000000,262.660000000,1000,56,1,1,248.600000000,264.940000000,1000,7,1,1,247.150000000,265.000000000,400,1,1,1,247.000000000,267.800000000,12,30,1,1,TSLA
2024-11-01T08:00:09.786563838Z,2024-11-01T08:00:09.786398263Z,10,2,16244,C,A,0,251.030000000,100,130,165575,309455,250.000000000,251.090000000,1,50,1,1,249.970000000,252.400000000,50,1000,1,1,249.930000000,253.650000000,10,400,1,1,249.800000000,255.000000000,199,85,1,2,249.770000000,260.000000000,50,48,1,1,249.600000000,262.660000000,1000,56,1,1,249.500000000,264.940000000,1000,7,1,1,248.600000000,265.000000000,1000,1,1,1,247.150000000,267.800000000,400,30,1,1,247.000000000,268.670000000,12,100,1,1,TSLA
2024-11-01T08:00:09.786625105Z,2024-11-01T08:00:09.786459035Z,10,2,16244,A,A,0,251.050000000,100,130,166070,309456,250.000000000,251.050000000,1,100,1,1,249.970000000,251.090000000,50,50,1,1,249.930000000,252.400000000,10,1000,1,1,249.800000000,253.650000000,199,400,1,1,249.770000000,255.000000000,50,85,1,2,249.600000000,260.000000000,1000,48,1,1,249.500000000,262.660000000,1000,56,1,1,248.600000000,264.940000000,1000,7,1,1,247.150000000,265.000000000,400,1,1,1,247.000000000,267.800000000,12,30,1,1,TSLA
2024-11-01T08:00:09.786809862Z,2024-11-01T08:00:09.786643807Z,10,2,16244,C,A,0,251.050000000,100,130,166055,309457,250.000000000,251.090000000,1,50,1,1,249.970000000,252.400000000,50,1000,1,1,249.930000000,253.650000000,10,400,1,1,249.800000000,255.000000000,199,85,1,2,249.770000000,260.000000000,50,48,1,1,249.600000000,262.660000000,1000,56,1,1,249.500000000,264.940000000,1000,7,1,1,248.600000000,265.000000000,1000,1,1,1,247.150000000,267.800000000,400,30,1,1,247.000000000,268.670000000,12,100,1,1,TSLA
2024-11-01T08:00:09.786821100Z,2024-11-01T08:00:09.786654970Z,10,2,16244,A,A,0,251.070000000,100,130,166130,309458,250.000000000,251.070000000,1,100,1,1,249.970000000,251.090000000,50,50,1,1,249.930000000,252.400000000,10,1000,1,1,249.800000000,253.650000000,199,400,1,1,249.770000000,255.000000000,50,85,1,2,249.600000000,260.000000000,1000,48,1,1,249.500000000,262.660000000,1000,56,1,1,248.600000000,264.940000000,1000,7,1,1,247.150000000,265.000000000,400,1,1,1,247.000000000,267.800000000,12,30,1,1,TSLA
2024-11-01T08:00:09.788788085Z,2024-11-01T08:00:09.788621861Z,10,2,16244,C,B,1,249.970000000,50,130,166224,309459,250.000000000,251.070000000,1,100,1,1,249.930000000,251.090000000,10,50,1,1,249.800000000,252.400000000,199,1000,1,1,249.770000000,253.650000000,50,400,1,1,249.600000000,255.000000000,1000,85,1,2,249.500000000,260.000000000,1000,48,1,1,248.600000000,262.660000000,1000,56,1,1,247.150000000,264.940000000,400,7,1,1,247.000000000,265.000000000,12,1,1,1,246.000000000,267.800000000,4,30,1,1,TSLA
2024-11-01T08:00:09.789806388Z,2024-11-01T08:00:09.789640391Z,10,2,16244,A,A,0,251.070000000,100,130,165997,309463,250.000000000,251.070000000,1,200,1,2,249.930000000,251.090000000,10,50,1,1,249.800000000,252.400000000,199,1000,1,1,249.770000000,253.650000000,50,400,1,1,249.600000000,255.000000000,1000,85,1,2,249.500000000,260.000000000,1000,48,1,1,248.600000000,262.660000000,1000,56,1,1,247.150000000,264.940000000,400,7,1,1,247.000000000,265.000000000,12,1,1,1,246.000000000,267.800000000,4,30,1,1,TSLA
2024-11-01T08:00:09.801041263Z,2024-11-01T08:00:09.800874905Z,10,2,16244,A,B,0,250.000000000,1,130,166358,309488,250.000000000,251.070000000,2,200,2,2,249.930000000,251.090000000,10,50,1,1,249.800000000,252.400000000,199,1000,1,1,249.770000000,253.650000000,50,400,1,1,249.600000000,255.000000000,1000,85,1,2,249.500000000,260.000000000,1000,48,1,1,248.600000000,262.660000000,1000,56,1,1,247.150000000,264.940000000,400,7,1,1,247.000000000,265.000000000,12,1,1,1,246.000000000,267.800000000,4,30,1,1,TSLA
2024-11-01T08:00:09.844640477Z,2024-11-01T08:00:09.844474368Z,10,2,16244,C,A,1,251.090000000,50,130,166109,309590,250.000000000,251.070000000,2,200,2,2,249.930000000,252.400000000,10,1000,1,1,249.800000000,253.650000000,199,400,1,1,249.770000000,255.000000000,50,85,1,2,249.600000000,260.000000000,1000,48,1,1,249.500000000,262.660000000,1000,56,1,1,248.600000000,264.940000000,1000,7,1,1,247.150000000,265.000000000,400,1,1,1,247.000000000,267.800000000,12,30,1,1,246.000000000,268.670000000,4,100,1,1,TSLA
2024-11-01T08:00:09.844701754Z,2024-11-01T08:00:09.844532194Z,10,2,16244,A,B,1,249.970000000,50,130,169560,309591,250.000000000,251.070000000,2,200,2,2,249.970000000,252.400000000,50,1000,1,1,249.930000000,253.650000000,10,400,1,1,249.800000000,255.000000000,199,85,1,2,249.770000000,260.000000000,50,48,1,1,249.600000000,262.660000000,1000,56,1,1,249.500000000,264.940000000,1000,7,1,1,248.600000000,265.000000000,1000,1,1,1,247.150000000,267.800000000,400,30,1,1,247.000000000,268.670000000,12,100,1,1,TSLA
2024-11-01T08:00:09.844728634Z,2024-11-01T08:00:09.844562361Z,10,2,16244,A,A,1,251.150000000,50,130,166273,309592,250.000000000,251.070000000,2,200,2,2,249.970000000,251.150000000,50,50,1,1,249.930000000,252.400000000,10,1000,1,1,249.800000000,253.650000000,199,400,1,1,249.770000000,255.000000000,50,85,1,2,249.600000000,260.000000000,1000,48,1,1,249.500000000,262.660000000,1000,56,1,1,248.600000000,264.940000000,1000,7,1,1,247.150000000,265.000000000,400,1,1,1,247.000000000,267.800000000,12,30,1,1,TSLA
2024-11-01T08:00:09.848533907Z,2024-11-01T08:00:09.848366265Z,10,2,16244,A,A,1,251.150000000,50,130,167642,309595,250.000000000,251.070000000,2,200,2,2,249.970000000,251.150000000,50,100,1,2,249.930000000,252.400000000,10,1000,1,1,249.800000000,253.650000000,199,400,1,1,249.770000000,255.000000000,50,85,1,2,249.600000000,260.000000000,1000,48,1,1,249.500000000,262.660000000,1000,56,1,1,248.600000000,264.940000000,1000,7,1,1,247.150000000,265.000000000,400,1,1,1,247.000000000,267.800000000,12,30,1,1,TSLA
2024-11-01T08:00:09.848579974Z,2024-11-01T08:00:09.848414050Z,10,2,16244,C,B,1,249.970000000,50,130,165924,309596,250.000000000,251.070000000,2,200,2,2,249.930000000,251.150000000,10,100,1,2,249.800000000,252.400000000,199,1000,1,1,249.770000000,253.650000000,50,400,1,1,249.600000000,255.000000000,1000,85,1,2,249.500000000,260.000000000,1000,48,1,1,248.600000000,262.660000000,1000,56,1,1,247.150000000,264.940000000,400,7,1,1,247.000000000,265.000000000,12,1,1,1,246.000000000,267.800000000,4,30,1,1,TSLA
2024-11-01T08:00:09.855243663Z,2024-11-01T08:00:09.855077638Z,10,2,16244,C,A,0,251.070000000,100,130,166025,309599,250.000000000,251.070000000,2,100,2,1,249.930000000,251.150000000,10,100,1,2,249.800000000,252.400000000,199,1000,1,1,249.770000000,253.650000000,50,400,1,1,249.600000000,255.000000000,1000,85,1,2,249.500000000,260.000000000,1000,48,1,1,248.600000000,262.660000000,1000,56,1,1,247.150000000,264.940000000,400,7,1,1,247.000000000,265.000000000,12,1,1,1,246.000000000,267.800000000,4,30,1,1,TSLA
2024-11-01T08:00:09.855256729Z,2024-11-01T08:00:09.855090665Z,10,2,16244,A,A,0,250.940000000,100,130,166064,309600,250.000000000,250.940000000,2,100,2,1,249.930000000,251.150000000,10,100,1,2,249.800000000,252.400000000,199,1000,1,1,249.770000000,253.650000000,50,400,1,1,249.600000000,255.000000000,1000,85,1,2,249.500000000,260.000000000,1000,48,1,1,248.600000000,262.660000000,1000,56,1,1,247.150000000,264.940000000,400,7,1,1,247.000000000,265.000000000,12,1,1,1,246.000000000,267.800000000,4,30,1,1,TSLA
2024-11-01T08:00:09.891408749Z,2024-11-01T08:00:09.891242517Z,10,2,16244,A,B,2,249.920000000,50,130,166232,309785,250.000000000,250.940000000,2,100,2,1,249.930000000,251.150000000,10,100,1,2,249.920000000,252.400000000,50,1000,1,1,249.800000000,253.650000000,199,400,1,1,249.770000000,255.000000000,50,85,1,2,249.600000000,260.000000000,1000,48,1,1,249.500000000,262.660000000,1000,56,1,1,248.600000000,264.940000000,1000,7,1,1,247.150000000,265.000000000,400,1,1,1,247.000000000,267.800000000,12,30,1,1,TSLA
2024-11-01T08:00:09.900875098Z,2024-11-01T08:00:09.900709507Z,10,2,16244,C,A,1,251.150000000,50,130,165591,309911,250.000000000,250.940000000,2,100,2,1,249.930000000,251.150000000,10,50,1,1,249.920000000,252.400000000,50,1000,1,1,249.800000000,253.650000000,199,400,1,1,249.770000000,255.000000000,50,85,1,2,249.600000000,260.000000000,1000,48,1,1,249.500000000,262.660000000,1000,56,1,1,248.600000000,264.940000000,1000,7,1,1,247.150000000,265.000000000,400,1,1,1,247.000000000,267.800000000,12,30,1,1,TSLA
2024-11-01T08:00:09.900889623Z,2024-11-01T08:00:09.900723380Z,10,2,16244,A,A,1,251.090000000,50,130,166243,309912,250.000000000,250.940000000,2,100,2,1,249.930000000,251.090000000,10,50,1,1,249.920000000,252.400000000,50,1000,1,1,249.800000000,253.650000000,199,400,1,1,249.770000000,255.000000000,50,85,1,2,249.600000000,260.000000000,1000,48,1,1,249.500000000,262.660000000,1000,56,1,1,248.600000000,264.940000000,1000,7,1,1,247.150000000,265.000000000,400,1,1,1,247.000000000,267.800000000,12,30,1,1,TSLA
2024-11-01T08:00:09.932269707Z,2024-11-01T08:00:09.932103494Z,10,2,16244,A,B,8,248.500000000,40,130,166213,310073,250.000000000,250.940000000,2,100,2,1,249.930000000,251.090000000,10,50,1,1,249.920000000,252.400000000,50,1000,1,1,249.800000000,253.650000000,199,400,1,1,249.770000000,255.000000000,50,85,1,2,249.600000000,260.000000000,1000,48,1,1,249.500000000,262.660000000,1000,56,1,1,248.600000000,264.940000000,1000,7,1,1,248.500000000,265.000000000,40,1,1,1,247.150000000,267.800000000,400,30,1,1,TSLA
2024-11-01T08:00:10.038422082Z,2024-11-01T08:00:10.038255545Z,10,2,38,A,B,7,204.500000000,2,130,166537,310212,221.300000000,224.400000000,1000,1000,1,1,220.000000000,225.000000000,2,1,1,1,219.690000000,225.360000000,442,1,1,1,219.000000000,225.490000000,1,442,1,1,217.000000000,225.900000000,1525,32,1,2,213.000000000,229.330000000,5,9,1,2,210.000000000,233.670000000,1,5,1,1,204.500000000,234.000000000,2,20,1,1,200.000000000,235.000000000,30,2,1,1,190.000000000,238.760000000,1,150,1,1,AAPL
2024-11-01T08:00:10.097591952Z,2024-11-01T08:00:10.097425474Z,10,2,16244,A,A,1,251.090000000,50,130,166478,310304,250.000000000,250.940000000,2,100,2,1,249.930000000,251.090000000,10,100,1,2,249.920000000,252.400000000,50,1000,1,1,249.800000000,253.650000000,199,400,1,1,249.770000000,255.000000000,50,85,1,2,249.600000000,260.000000000,1000,48,1,1,249.500000000,262.660000000,1000,56,1,1,248.600000000,264.940000000,1000,7,1,1,248.500000000,265.000000000,40,1,1,1,247.150000000,267.800000000,400,30,1,1,TSLA
2024-11-01T08:00:10.097635281Z,2024-11-01T08:00:10.097469401Z,10,2,16244,C,B,2,249.920000000,50,130,165880,310305,250.000000000,250.940000000,2,100,2,1,249.930000000,251.090000000,10,100,1,2,249.800000000,252.400000000,199,1000,1,1,249.770000000,253.650000000,50,400,1,1,249.600000000,255.000000000,1000,85,1,2,249.500000000,260.000000000,1000,48,1,1,248.600000000,262.660000000,1000,56,1,1,248.500000000,264.940000000,40,7,1,1,247.150000000,265.000000000,400,1,1,1,247.000000000,267.800000000,12,30,1,1,TSLA
2024-11-01T08:00:10.097648012Z,2024-11-01T08:00:10.097481745Z,10,2,16244,A,B,2,249.890000000,50,130,166267,310306,250.000000000,250.940000000,2,100,2,1,249.930000000,251.090000000,10,100,1,2,249.890000000,252.400000000,50,1000,1,1,249.800000000,253.650000000,199,400,1,1,249.770000000,255.000000000,50,85,1,2,249.600000000,260.000000000,1000,48,1,1,249.500000000,262.660000000,1000,56,1,1,248.600000000,264.940000000,1000,7,1,1,248.500000000,265.000000000,40,1,1,1,247.150000000,267.800000000,400,30,1,1,TSLA
2024-11-01T08:00:10.148750553Z,2024-11-01T08:00:10.148584206Z,10,2,16244,C,A,1,251.090000000,50,130,166347,310376,250.000000000,250.940000000,2,100,2,1,249.930000000,251.090000000,10,50,1,1,249.890000000,252.400000000,50,1000,1,1,249.800000000,253.650000000,199,400,1,1,249.770000000,255.000000000,50,85,1,2,249.600000000,260.000000000,1000,48,1,1,249.500000000,262.660000000,1000,56,1,1,248.600000000,264.940000000,1000,7,1,1,248.500000000,265.000000000,40,1,1,1,247.150000000,267.800000000,400,30,1,1,TSLA
2024-11-01T08:00:10.148764513Z,2024-11-01T08:00:10.148598171Z,10,2,16244,A,A,1,250.990000000,50,130,166342,310377,250.000000000,250.940000000,2,100,2,1,249.930000000,250.990000000,10,50,1,1,249.890000000,252.400000000,50,1000,1,1,249.800000000,253.650000000,199,400,1,1,249.770000000,255.000000000,50,85,1,2,249.600000000,260.000000000,1000,48,1,1,249.500000000,262.660000000,1000,56,1,1,248.600000000,264.940000000,1000,7,1,1,248.500000000,265.000000000,40,1,1,1,247.150000000,267.800000000,400,30,1,1,TSLA
2024-11-01T08:00:10.168606294Z,2024-11-01T08:00:10.168439956Z,10,2,16244,A,B,2,249.910000000,50,130,166338,310404,250.000000000,250.940000000,2,100,2,1,249.930000000,250.990000000,10,50,1,1,249.910000000,252.400000000,50,1000,1,1,249.800000000,253.650000000,199,400,1,1,249.770000000,255.000000000,50,85,1,2,249.600000000,260.000000000,1000,48,1,1,249.500000000,262.660000000,1000,56,1,1,248.600000000,264.940000000,1000,7,1,1,248.500000000,265.000000000,40,1,1,1,247.150000000,267.800000000,400,30,1,1,TSLA
2024-11-01T08:00:10.171564993Z,2024-11-01T08:00:10.171397591Z,10,2,9155,A,B,2,218.080000000,100,130,167402,310417,221.850000000,224.940000000,3,450,1,1,219.160000000,226.800000000,450,100,1,1,218.080000000,,100,0,1,0,,,0,0,0,0,,,0,0,0,0,,,0,0,0,0,,,0,0,0,0,,,0,0,0,0,,,0,0,0,0,,,0,0,0,0,JPM
2024-11-01T08:00:10.178995283Z,2024-11-01T08:00:10.178829435Z,10,2,16244,C,B,7,248.600000000,1000,130,165848,310428,250.000000000,250.940000000,2,100,2,1,249.930000000,250.990000000,10,50,1,1,249.910000000,252.400000000,50,1000,1,1,249.800000000,253.650000000,199,400,1,1,249.770000000,255.000000000,50,85,1,2,249.600000000,260.000000000,1000,48,1,1,249.500000000,262.660000000,1000,56,1,1,248.500000000,264.940000000,40,7,1,1,247.150000000,265.000000000,400,1,1,1,247.000000000,267.800000000,12,30,1,1,TSLA
2024-11-01T08:00:10.189419686Z,2024-11-01T08:00:10.189253300Z,10,2,16244,A,B,5,249.700000000,1000,130,166386,310444,250.000000000,250.940000000,2,100,2,1,249.930000000,250.990000000,10,50,1,1,249.910000000,252.400000000,50,1000,1,1,249.800000000,253.650000000,199,400,1,1,249.770000000,255.000000000,50,85,1,2,249.700000000,260.000000000,1000,48,1,1,249.600000000,262.660000000,1000,56,1,1,249.500000000,264.940000000,1000,7,1,1,248.500000000,265.000000000,40,1,1,1,247.150000000,267.800000000,400,30,1,1,TSLA
2024-11-01T08:00:10.189446830Z,2024-11-01T08:00:10.189280846Z,10,2,16244,C,B,7,249.500000000,1000,130,165984,310445,250.000000000,250.940000000,2,100,2,1,249.930000000,250.990000000,10,50,1,1,249.910000000,252.400000000,50,1000,1,1,249.800000000,253.650000000,199,400,1,1,249.770000000,255.000000000,50,85,1,2,249.700000000,260.000000000,1000,48,1,1,249.600000000,262.660000000,1000,56,1,1,248.500000000,264.940000000,40,7,1,1,247.150000000,265.000000000,400,1,1,1,247.000000000,267.800000000,12,30,1,1,TSLA
2024-11-01T08:00:10.200968842Z,2024-11-01T08:00:10.200802660Z,10,2,16244,A,B,8,248.200000000,1000,130,166182,310455,250.000000000,250.940000000,2,100,2,1,249.930000000,250.990000000,10,50,1,1,249.910000000,252.400000000,50,1000,1,1,249.800000000,253.650000000,199,400,1,1,249.770000000,255.000000000,50,85,1,2,249.700000000,260.000000000,1000,48,1,1,249.600000000,262.660000000,1000,56,1,1,248.500000000,264.940000000,40,7,1,1,248.200000000,265.000000000,1000,1,1,1,247.150000000,267.800000000,400,30,1,1,TSLA
2024-11-01T08:00:10.250667584Z,2024-11-01T08:00:10.250500971Z,10,2,11667,A,B,0,134.680000000,100,130,166613,310528,134.680000000,134.990000000,100,10,1,1,134.500000000,135.000000000,520,38,2,3,134.410000000,135.100000000,61,10,2,1,134.380000000,135.230000000,18,360,1,1,134.210000000,135.300000000,20,1000,1,1,134.200000000,135.400000000,3,10,1,1,133.160000000,135.420000000,1,1,1,1,132.760000000,135.820000000,100,1,1,1,132.700000000,135.990000000,4,20,1,1,132.660000000,136.100000000,1,1000,1,1,NVDA
2024-11-01T08:00:10.264778366Z,2024-11-01T08:00:10.264611611Z,10,2,16244,C,B,2,249.910000000,50,130,166755,310554,250.000000000,250.940000000,2,100,2,1,249.930000000,250.990000000,10,50,1,1,249.800000000,252.400000000,199,1000,1,1,249.770000000,253.650000000,50,400,1,1,249.700000000,255.000000000,1000,85,1,2,249.600000000,260.000000000,1000,48,1,1,248.500000000,262.660000000,40,56,1,1,248.200000000,264.940000000,1000,7,1,1,247.150000000,265.000000000,400,1,1,1,247.000000000,267.800000000,12,30,1,1,TSLA
2024-11-01T08:00:10.366826490Z,2024-11-01T08:00:10.366660191Z,10,2,38,A,B,5,215.000000000,5,130,166299,310747,221.300000000,224.400000000,1000,1000,1,1,220.000000000,225.000000000,2,1,1,1,219.690000000,225.360000000,442,1,1,1,219.000000000,225.490000000,1,442,1,1,217.000000000,225.900000000,1525,32,1,2,215.000000000,229.330000000,5,9,1,2,213.000000000,233.670000000,5,5,1,1,210.000000000,234.000000000,1,20,1,1,204.500000000,235.000000000,2,2,1,1,200.000000000,238.760000000,30,150,1,1,AAPL
2024-11-01T08:00:10.445872888Z,2024-11-01T08:00:10.445705898Z,10,2,16244,A,B,0,250.150000000,50,130,166990,310826,250.150000000,250.940000000,50,100,1,1,250.000000000,250.990000000,2,50,2,1,249.930000000,252.400000000,10,1000,1,1,249.800000000,253.650000000,199,400,1,1,249.770000000,255.000000000,50,85,1,2,249.700000000,260.000000000,1000,48,1,1,249.600000000,262.660000000,1000,56,1,1,248.500000000,264.940000000,40,7,1,1,248.200000000,265.000000000,1000,1,1,1,247.150000000,267.800000000,400,30,1,1,TSLA
2024-11-01T08:00:10.540662144Z,2024-11-01T08:00:10.540496378Z,10,2,10888,A,A,3,440.000000000,35,130,165766,311211,410.000000000,414.000000000,1,33,1,1,409.750000000,415.070000000,3,246,1,1,409.080000000,420.000000000,2,3,1,1,408.970000000,440.000000000,12,35,1,1,408.960000000,445.000000000,5,25,1,1,407.600000000,445.680000000,16,3,1,1,407.000000000,448.000000000,17,15,3,2,406.350000000,450.000000000,82,10,2,1,406.000000000,468.000000000,7,65,1,1,405.000000000,472.000000000,15,6,2,1,MSFT
2024-11-01T08:00:10.622856667Z,2024-11-01T08:00:10.622690498Z,10,2,16244,A,A,8,265.000000000,1,130,166169,311375,250.150000000,250.940000000,50,100,1,1,250.000000000,250.990000000,2,50,2,1,249.930000000,252.400000000,10,1000,1,1,249.800000000,253.650000000,199,400,1,1,249.770000000,255.000000000,50,85,1,2,249.700000000,260.000000000,1000,48,1,1,249.600000000,262.660000000,1000,56,1,1,248.500000000,264.940000000,40,7,1,1,248.200000000,265.000000000,1000,2,1,2,247.150000000,267.800000000,400,30,1,1,TSLA
2024-11-01T08:00:10.625500963Z,2024-11-01T08:00:10.625335069Z,10,2,16244,A,A,1,250.980000000,50,130,165894,311383,250.150000000,250.940000000,50,100,1,1,250.000000000,250.980000000,2,50,2,1,249.930000000,252.400000000,10,1000,1,1,249.800000000,253.650000000,199,400,1,1,249.770000000,255.000000000,50,85,1,2,249.700000000,260.000000000,1000,48,1,1,249.600000000,262.660000000,1000,56,1,1,248.500000000,264.940000000,40,7,1,1,248.200000000,265.000000000,1000,2,1,2,247.150000000,267.800000000,400,30,1,1,TSLA
2024-11-01T08:00:10.801822731Z,2024-11-01T08:00:10.801656638Z,10,2,10888,A,B,3,409.000000000,2,130,166093,311853,410.000000000,414.000000000,1,33,1,1,409.750000000,415.070000000,3,246,1,1,409.080000000,420.000000000,2,3,1,1,409.000000000,440.000000000,2,35,1,1,408.970000000,445.000000000,12,25,1,1,408.960000000,445.680000000,5,3,1,1,407.600000000,448.000000000,16,15,1,2,407.000000000,450.000000000,17,10,3,1,406.350000000,468.000000000,82,65,2,1,406.000000000,472.000000000,7,6,1,1,MSFT
2024-11-01T08:00:10.852043842Z,2024-11-01T08:00:10.851877543Z,10,2,16244,A,A,8,265.000000000,100,130,166299,311997,250.150000000,250.940000000,50,100,1,1,250.000000000,250.980000000,2,50,2,1,249.930000000,252.400000000,10,1000,1,1,249.800000000,253.650000000,199,400,1,1,249.770000000,255.000000000,50,85,1,2,249.700000000,260.000000000,1000,48,1,1,249.600000000,262.660000000,1000,56,1,1,248.500000000,264.940000000,40,7,1,1,248.200000000,265.000000000,1000,102,1,3,247.150000000,267.800000000,400,30,1,1,TSLA
2024-11-01T08:00:10.963661271Z,2024-11-01T08:00:10.963495230Z,10,2,16244,C,A,1,250.980000000,50,130,166041,312130,250.150000000,250.940000000,50,100,1,1,250.000000000,252.400000000,2,1000,2,1,249.930000000,253.650000000,10,400,1,1,249.800000000,255.000000000,199,85,1,2,249.770000000,260.000000000,50,48,1,1,249.700000000,262.660000000,1000,56,1,1,249.600000000,264.940000000,1000,7,1,1,248.500000000,265.000000000,40,102,1,3,248.200000000,267.800000000,1000,30,1,1,247.150000000,268.670000000,400,100,1,1,TSLA
2024-11-01T08:00:10.982302215Z,2024-11-01T08:00:10.982135958Z,10,2,10888,A,A,8,467.560000000,5,130,166257,312178,410.000000000,414.000000000,1,33,1,1,409.750000000,415.070000000,3,246,1,1,409.080000000,420.000000000,2,3,1,1,409.000000000,440.000000000,2,35,1,1,408.970000000,445.000000000,12,25,1,1,408.960000000,445.680000000,5,3,1,1,407.600000000,448.000000000,16,15,1,2,407.000000000,450.000000000,17,10,3,1,406.350000000,467.560000000,82,5,2,1,406.000000000,468.000000000,7,65,1,1,MSFT
2024-11-01T08:00:11.008861505Z,2024-11-01T08:00:11.008695339Z,10,2,11667,A,B,6,134.000000000,1,130,166166,312250,134.680000000,134.990000000,100,10,1,1,134.500000000,135.000000000,520,38,2,3,134.410000000,135.100000000,61,10,2,1,134.380000000,135.230000000,18,360,1,1,134.210000000,135.300000000,20,1000,1,1,134.200000000,135.400000000,3,10,1,1,134.000000000,135.420000000,1,1,1,1,133.160000000,135.820000000,1,1,1,1,132.760000000,135.990000000,100,20,1,1,132.700000000,136.100000000,4,1000,1,1,NVDA
2024-11-01T08:00:11.035334462Z,2024-11-01T08:00:11.035168252Z,10,2,16244,A,A,1,250.990000000,50,130,166210,312363,250.150000000,250.940000000,50,100,1,1,250.000000000,250.990000000,2,50,2,1,249.930000000,252.400000000,10,1000,1,1,249.800000000,253.650000000,199,400,1,1,249.770000000,255.000000000,50,85,1,2,249.700000000,260.000000000,1000,48,1,1,249.600000000,262.660000000,1000,56,1,1,248.500000000,264.940000000,40,7,1,1,248.200000000,265.000000000,1000,102,1,3,247.150000000,267.800000000,400,30,1,1,TSLA
2024-11-01T08:00:11.128548275Z,2024-11-01T08:00:11.128382259Z,10,2,16244,C,B,0,250.150000000,50,130,166016,312644,250.000000000,250.940000000,2,100,2,1,249.930000000,250.990000000,10,50,1,1,249.800000000,252.400000000,199,1000,1,1,249.770000000,253.650000000,50,400,1,1,249.700000000,255.000000000,1000,85,1,2,249.600000000,260.000000000,1000,48,1,1,248.500000000,262.660000000,40,56,1,1,248.200000000,264.940000000,1000,7,1,1,247.150000000,265.000000000,400,102,1,3,247.000000000,267.800000000,12,30,1,1,TSLA
2024-11-01T08:00:11.128560599Z,2024-11-01T08:00:11.128394620Z,10,2,16244,A,B,0,250.110000000,50,130,165979,312645,250.110000000,250.940000000,50,100,1,1,250.000000000,250.990000000,2,50,2,1,249.930000000,252.400000000,10,1000,1,1,249.800000000,253.650000000,199,400,1,1,249.770000000,255.000000000,50,85,1,2,249.700000000,260.000000000,1000,48,1,1,249.600000000,262.660000000,1000,56,1,1,248.500000000,264.940000000,40,7,1,1,248.200000000,265.000000000,1000,102,1,3,247.150000000,267.800000000,400,30,1,1,TSLA
2024-11-01T08:00:11.199620873Z,2024-11-01T08:00:11.199454684Z,10,2,10888,A,A,0,414.000000000,435,130,166189,312861,410.000000000,414.000000000,1,468,1,2,409.750000000,415.070000000,3,246,1,1,409.080000000,420.000000000,2,3,1,1,409.000000000,440.000000000,2,35,1,1,408.970000000,445.000000000,12,25,1,1,408.960000000,445.680000000,5,3,1,1,407.600000000,448.000000000,16,15,1,2,407.000000000,450.000000000,17,10,3,1,406.350000000,467.560000000,82,5,2,1,406.000000000,468.000000000,7,65,1,1,MSFT
2024-11-01T08:00:11.202384331Z,2024-11-01T08:00:11.202218198Z,10,2,38,A,A,8,234.750000000,50,130,166133,312865,221.300000000,224.400000000,1000,1000,1,1,220.000000000,225.000000000,2,1,1,1,219.690000000,225.360000000,442,1,1,1,219.000000000,225.490000000,1,442,1,1,217.000000000,225.900000000,1525,32,1,2,215.000000000,229.330000000,5,9,1,2,213.000000000,233.670000000,5,5,1,1,210.000000000,234.000000000,1,20,1,1,204.500000000,234.750000000,2,50,1,1,200.000000000,235.000000000,30,2,1,1,AAPL
2024-11-01T08:00:11.207334983Z,2024-11-01T08:00:11.207168883Z,10,2,38,A,B,0,221.400000000,1000,130,166100,312871,221.400000000,224.400000000,1000,1000,1,1,221.300000000,225.000000000,1000,1,1,1,220.000000000,225.360000000,2,1,1,1,219.690000000,225.490000000,442,442,1,1,219.000000000,225.900000000,1,32,1,2,217.000000000,229.330000000,1525,9,1,2,215.000000000,233.670000000,5,5,1,1,213.000000000,234.000000000,5,20,1,1,210.000000000,234.750000000,1,50,1,1,204.500000000,235.000000000,2,2,1,1,AAPL
2024-11-01T08:00:11.207391361Z,2024-11-01T08:00:11.207225273Z,10,2,38,C,B,1,221.300000000,1000,130,166088,312872,221.400000000,224.400000000,1000,1000,1,1,220.000000000,225.000000000,2,1,1,1,219.690000000,225.360000000,442,1,1,1,219.000000000,225.490000000,1,442,1,1,217.000000000,225.900000000,1525,32,1,2,215.000000000,229.330000000,5,9,1,2,213.000000000,233.670000000,5,5,1,1,210.000000000,234.000000000,1,20,1,1,204.500000000,234.750000000,2,50,1,1,200.000000000,235.000000000,30,2,1,1,AAPL
2024-11-01T08:00:11.278220909Z,2024-11-01T08:00:11.278054242Z,10,2,38,A,B,7,212.340000000,5,130,166667,313152,221.400000000,224.400000000,1000,1000,1,1,220.000000000,225.000000000,2,1,1,1,219.690000000,225.360000000,442,1,1,1,219.000000000,225.490000000,1,442,1,1,217.000000000,225.900000000,1525,32,1,2,215.000000000,229.330000000,5,9,1,2,213.000000000,233.670000000,5,5,1,1,212.340000000,234.000000000,5,20,1,1,210.000000000,234.750000000,1,50,1,1,204.500000000,235.000000000,2,2,1,1,AAPL
2024-11-01T08:00:11.346660469Z,2024-11-01T08:00:11.346493771Z,10,2,38,A,B,0,221.700000000,10,130,166698,313649,221.700000000,224.400000000,10,1000,1,1,221.400000000,225.000000000,1000,1,1,1,220.000000000,225.360000000,2,1,1,1,219.690000000,225.490000000,442,442,1,1,219.000000000,225.900000000,1,32,1,2,217.000000000,229.330000000,1525,9,1,2,215.000000000,233.670000000,5,5,1,1,213.000000000,234.000000000,5,20,1,1,212.340000000,234.750000000,5,50,1,1,210.000000000,235.000000000,1,2,1,1,AAPL
2024-11-01T08:00:11.410487817Z,2024-11-01T08:00:11.410321560Z,10,2,16244,A,A,2,252.300000000,1000,130,166257,313780,250.110000000,250.940000000,50,100,1,1,250.000000000,250.990000000,2,50,2,1,249.930000000,252.300000000,10,1000,1,1,249.800000000,252.400000000,199,1000,1,1,249.770000000,253.650000000,50,400,1,1,249.700000000,255.000000000,1000,85,1,2,249.600000000,260.000000000,1000,48,1,1,248.500000000,262.660000000,40,56,1,1,248.200000000,264.940000000,1000,7,1,1,247.150000000,265.000000000,400,102,1,3,TSLA
2024-11-01T08:00:11.410540052Z,2024-11-01T08:00:11.410374270Z,10,2,16244,C,A,3,252.400000000,1000,130,165782,313781,250.110000000,250.940000000,50,100,1,1,250.000000000,250.990000000,2,50,2,1,249.930000000,252.300000000,10,1000,1,1,249.800000000,253.650000000,199,400,1,1,249.770000000,255.000000000,50,85,1,2,249.700000000,260.000000000,1000,48,1,1,249.600000000,262.660000000,1000,56,1,1,248.500000000,264.940000000,40,7,1,1,248.200000000,265.000000000,1000,102,1,3,247.150000000,267.800000000,400,30,1,1,TSLA
2024-11-01T08:00:11.515403085Z,2024-11-01T08:00:11.515236364Z,10,2,10888,A,A,2,415.350000000,59,130,166721,313949,410.000000000,414.000000000,1,468,1,2,409.750000000,415.070000000,3,246,1,1,409.080000000,415.350000000,2,59,1,1,409.000000000,420.000000000,2,3,1,1,408.970000000,440.000000000,12,35,1,1,408.960000000,445.000000000,5,25,1,1,407.600000000,445.680000000,16,3,1,1,407.000000000,448.000000000,17,15,3,2,406.350000000,450.000000000,82,10,2,1,406.000000000,467.560000000,7,5,1,1,MSFT
2024-11-01T08:00:11.521203105Z,2024-11-01T08:00:11.521036945Z,10,2,10888,A,A,2,415.350000000,25,130,166160,313978,410.000000000,414.000000000,1,468,1,2,409.750000000,415.070000000,3,246,1,1,409.080000000,415.350000000,2,84,1,2,409.000000000,420.000000000,2,3,1,1,408.970000000,440.000000000,12,35,1,1,408.960000000,445.000000000,5,25,1,1,407.600000000,445.680000000,16,3,1,1,407.000000000,448.000000000,17,15,3,2,406.350000000,450.000000000,82,10,2,1,406.000000000,467.560000000,7,5,1,1,MSFT
2024-11-01T08:00:11.521809062Z,2024-11-01T08:00:11.521642932Z,10,2,10888,A,B,9,406.080000000,5,130,166130,313979,410.000000000,414.000000000,1,468,1,2,409.750000000,415.070000000,3,246,1,1,409.080000000,415.350000000,2,84,1,2,409.000000000,420.000000000,2,3,1,1,408.970000000,440.000000000,12,35,1,1,408.960000000,445.000000000,5,25,1,1,407.600000000,445.680000000,16,3,1,1,407.000000000,448.000000000,17,15,3,2,406.350000000,450.000000000,82,10,2,1,406.080000000,467.560000000,5,5,1,1,MSFT
2024-11-01T08:00:11.588640971Z,2024-11-01T08:00:11.588474530Z,10,2,16244,A,A,5,260.000000000,100,130,166441,314051,250.110000000,250.940000000,50,100,1,1,250.000000000,250.990000000,2,50,2,1,249.930000000,252.300000000,10,1000,1,1,249.800000000,253.650000000,199,400,1,1,249.770000000,255.000000000,50,85,1,2,249.700000000,260.000000000,1000,148,1,2,249.600000000,262.660000000,1000,56,1,1,248.500000000,264.940000000,40,7,1,1,248.200000000,265.000000000,1000,102,1,3,247.150000000,267.800000000,400,30,1,1,TSLA
2024-11-01T08:00:11.625867129Z,2024-11-01T08:00:11.625700885Z,10,2,780,A,B,0,308.380000000,25,130,166244,314118,308.380000000,330.140000000,25,25,1,1,,,0,0,0,0,,,0,0,0,0,,,0,0,0,0,,,0,0,0,0,,,0,0,0,0,,,0,0,0,0,,,0,0,0,0,,,0,0,0,0,,,0,0,0,0,AMGN
2024-11-01T08:00:11.716180528Z,2024-11-01T08:00:11.716014319Z,10,2,16244,A,A,5,260.000000000,20,130,166209,314250,250.110000000,250.940000000,50,100,1,1,250.000000000,250.990000000,2,50,2,1,249.930000000,252.300000000,10,1000,1,1,249.800000000,253.650000000,199,400,1,1,249.770000000,255.000000000,50,85,1,2,249.700000000,260.000000000,1000,168,1,3,249.600000000,262.660000000,1000,56,1,1,248.500000000,264.940000000,40,7,1,1,248.200000000,265.000000000,1000,102,1,3,247.150000000,267.800000000,400,30,1,1,TSLA
2024-11-01T08:00:11.744818545Z,2024-11-01T08:00:11.744652546Z,10,2,16244,C,B,0,250.110000000,50,130,165999,314271,250.000000000,250.940000000,2,100,2,1,249.930000000,250.990000000,10,50,1,1,249.800000000,252.300000000,199,1000,1,1,249.770000000,253.650000000,50,400,1,1,249.700000000,255.000000000,1000,85,1,2,249.600000000,260.000000000,1000,168,1,3,248.500000000,262.660000000,40,56,1,1,248.200000000,264.940000000,1000,7,1,1,247.150000000,265.000000000,400,102,1,3,247.000000000,267.800000000,12,30,1,1,TSLA
2024-11-01T08:00:11.744831009Z,2024-11-01T08:00:11.744664963Z,10,2,16244,A,B,0,250.060000000,50,130,166046,314272,250.060000000,250.940000000,50,100,1,1,250.000000000,250.990000000,2,50,2,1,249.930000000,252.300000000,10,1000,1,1,249.800000000,253.650000000,199,400,1,1,249.770000000,255.000000000,50,85,1,2,249.700000000,260.000000000,1000,168,1,3,249.600000000,262.660000000,1000,56,1,1,248.500000000,264.940000000,40,7,1,1,248.200000000,265.000000000,1000,102,1,3,247.150000000,267.800000000,400,30,1,1,TSLA
2024-11-01T08:00:11.744846096Z,2024-11-01T08:00:11.744679696Z,10,2,16244,C,B,0,250.060000000,50,130,166400,314273,250.000000000,250.940000000,2,100,2,1,249.930000000,250.990000000,10,50,1,1,249.800000000,252.300000000,199,1000,1,1,249.770000000,253.650000000,50,400,1,1,249.700000000,255.000000000,1000,85,1,2,249.600000000,260.000000000,1000,168,1,3,248.500000000,262.660000000,40,56,1,1,248.200000000,264.940000000,1000,7,1,1,247.150000000,265.000000000,400,102,1,3,247.000000000,267.800000000,12,30,1,1,TSLA
2024-11-01T08:00:11.798934057Z,2024-11-01T08:00:11.798767560Z,10,2,16244,A,B,0,250.020000000,50,130,166497,314386,250.020000000,250.940000000,50,100,1,1,250.000000000,250.990000000,2,50,2,1,249.930000000,252.300000000,10,1000,1,1,249.800000000,253.650000000,199,400,1,1,249.770000000,255.000000000,50,85,1,2,249.700000000,260.000000000,1000,168,1,3,249.600000000,262.660000000,1000,56,1,1,248.500000000,264.940000000,40,7,1,1,248.200000000,265.000000000,1000,102,1,3,247.150000000,267.800000000,400,30,1,1,TSLA
2024-11-01T08:00:11.814157748Z,2024-11-01T08:00:11.813991242Z,10,2,11667,A,B,8,132.760000000,4,130,166506,314398,134.680000000,134.990000000,100,10,1,1,134.500000000,135.000000000,520,38,2,3,134.410000000,135.100000000,61,10,2,1,134.380000000,135.230000000,18,360,1,1,134.210000000,135.300000000,20,1000,1,1,134.200000000,135.400000000,3,10,1,1,134.000000000,135.420000000,1,1,1,1,133.160000000,135.820000000,1,1,1,1,132.760000000,135.990000000,104,20,2,1,132.700000000,136.100000000,4,1000,1,1,NVDA
2024-11-01T08:00:11.838828055Z,2024-11-01T08:00:11.838662245Z,10,2,16244,C,A,1,250.990000000,50,130,165810,314431,250.020000000,250.940000000,50,100,1,1,250.000000000,252.300000000,2,1000,2,1,249.930000000,253.650000000,10,400,1,1,249.800000000,255.000000000,199,85,1,2,249.770000000,260.000000000,50,168,1,3,249.700000000,262.660000000,1000,56,1,1,249.600000000,264.940000000,1000,7,1,1,248.500000000,265.000000000,40,102,1,3,248.200000000,267.800000000,1000,30,1,1,247.150000000,268.670000000,400,100,1,1,TSLA
2024-11-01T08:00:11.839112275Z,2024-11-01T08:00:11.838946435Z,10,2,16244,C,A,1,252.300000000,1000,130,165840,314437,250.020000000,250.940000000,50,100,1,1,250.000000000,253.650000000,2,400,2,1,249.930000000,255.000000000,10,85,1,2,249.800000000,260.000000000,199,168,1,3,249.770000000,262.660000000,50,56,1,1,249.700000000,264.940000000,1000,7,1,1,249.600000000,265.000000000,1000,102,1,3,248.500000000,267.800000000,40,30,1,1,248.200000000,268.670000000,1000,100,1,1,247.150000000,269.580000000,400,100,1,1,TSLA
2024-11-01T08:00:11.839138765Z,2024-11-01T08:00:11.838973149Z,10,2,16244,C,B,0,250.020000000,50,130,165616,314438,250.000000000,250.940000000,2,100,2,1,249.930000000,253.650000000,10,400,1,1,249.800000000,255.000000000,199,85,1,2,249.770000000,260.000000000,50,168,1,3,249.700000000,262.660000000,1000,56,1,1,249.600000000,264.940000000,1000,7,1,1,248.500000000,265.000000000,40,102,1,3,248.200000000,267.800000000,1000,30,1,1,247.150000000,268.670000000,400,100,1,1,247.000000000,269.580000000,12,100,1,1,TSLA
2024-11-01T08:00:11.839607412Z,2024-11-01T08:00:11.839441795Z,10,2,16244,C,A,0,250.940000000,100,130,165617,314441,250.000000000,253.650000000,2,400,2,1,249.930000000,255.000000000,10,85,1,2,249.800000000,260.000000000,199,168,1,3,249.770000000,262.660000000,50,56,1,1,249.700000000,264.940000000,1000,7,1,1,249.600000000,265.000000000,1000,102,1,3,248.500000000,267.800000000,40,30,1,1,248.200000000,268.670000000,1000,100,1,1,247.150000000,269.580000000,400,100,1,1,247.000000000,270.000000000,12,118,1,3,TSLA
2024-11-01T08:00:11.839620531Z,2024-11-01T08:00:11.839454020Z,10,2,16244,A,A,0,250.980000000,100,130,166511,314442,250.000000000,250.980000000,2,100,2,1,249.930000000,253.650000000,10,400,1,1,249.800000000,255.000000000,199,85,1,2,249.770000000,260.000000000,50,168,1,3,249.700000000,262.660000000,1000,56,1,1,249.600000000,264.940000000,1000,7,1,1,248.500000000,265.000000000,40,102,1,3,248.200000000,267.800000000,1000,30,1,1,247.150000000,268.670000000,400,100,1,1,247.000000000,269.580000000,12,100,1,1,TSLA
2024-11-01T08:00:11.839848675Z,2024-11-01T08:00:11.839683089Z,10,2,16244,C,A,0,250.980000000,100,130,165586,314443,250.000000000,253.650000000,2,400,2,1,249.930000000,255.000000000,10,85,1,2,249.800000000,260.000000000,199,168,1,3,249.770000000,262.660000000,50,56,1,1,249.700000000,264.940000000,1000,7,1,1,249.600000000,265.000000000,1000,102,1,3,248.500000000,267.800000000,40,30,1,1,248.200000000,268.670000000,1000,100,1,1,247.150000000,269.580000000,400,100,1,1,247.000000000,270.000000000,12,118,1,3,TSLA
2024-11-01T08:00:11.839861372Z,2024-11-01T08:00:11.839695448Z,10,2,16244,A,A,0,251.010000000,100,130,165924,314444,250.000000000,251.010000000,2,100,2,1,249.930000000,253.650000000,10,400,1,1,249.800000000,255.000000000,199,85,1,2,249.770000000,260.000000000,50,168,1,3,249.700000000,262.660000000,1000,56,1,1,249.600000000,264.940000000,1000,7,1,1,248.500000000,265.000000000,40,102,1,3,248.200000000,267.800000000,1000,30,1,1,247.150000000,268.670000000,400,100,1,1,247.000000000,269.580000000,12,100,1,1,TSLA
2024-11-01T08:00:11.840870983Z,2024-11-01T08:00:11.840705256Z,10,2,16244,C,A,0,251.010000000,100,130,165727,314447,250.000000000,253.650000000,2,400,2,1,249.930000000,255.000000000,10,85,1,2,249.800000000,260.000000000,199,168,1,3,249.770000000,262.660000000,50,56,1,1,249.700000000,264.940000000,1000,7,1,1,249.600000000,265.000000000,1000,102,1,3,248.500000000,267.800000000,40,30,1,1,248.200000000,268.670000000,1000,100,1,1,247.150000000,269.580000000,400,100,1,1,247.000000000,270.000000000,12,118,1,3,TSLA
2024-11-01T08:00:11.840884133Z,2024-11-01T08:00:11.840718163Z,10,2,16244,A,A,0,251.040000000,100,130,165970,314448,250.000000000,251.040000000,2,100,2,1,249.930000000,253.650000000,10,400,1,1,249.800000000,255.000000000,199,85,1,2,249.770000000,260.000000000,50,168,1,3,249.700000000,262.660000000,1000,56,1,1,249.600000000,264.940000000,1000,7,1,1,248.500000000,265.000000000,40,102,1,3,248.200000000,267.800000000,1000,30,1,1,247.150000000,268.670000000,400,100,1,1,247.000000000,269.580000000,12,100,1,1,TSLA
2024-11-01T08:00:11.841111394Z,2024-11-01T08:00:11.840944632Z,10,2,16244,C,A,0,251.040000000,100,130,166762,314451,250.000000000,253.650000000,2,400,2,1,249.930000000,255.000000000,10,85,1,2,249.800000000,260.000000000,199,168,1,3,249.770000000,262.660000000,50,56,1,1,249.700000000,264.940000000,1000,7,1,1,249.600000000,265.000000000,1000,102,1,3,248.500000000,267.800000000,40,30,1,1,248.200000000,268.670000000,1000,100,1,1,247.150000000,269.580000000,400,100,1,1,247.000000000,270.000000000,12,118,1,3,TSLA
2024-11-01T08:00:11.841122521Z,2024-11-01T08:00:11.840956689Z,10,2,16244,A,A,0,251.070000000,100,130,165832,314452,250.000000000,251.070000000,2,100,2,1,249.930000000,253.650000000,10,400,1,1,249.800000000,255.000000000,199,85,1,2,249.770000000,260.000000000,50,168,1,3,249.700000000,262.660000000,1000,56,1,1,249.600000000,264.940000000,1000,7,1,1,248.500000000,265.000000000,40,102,1,3,248.200000000,267.800000000,1000,30,1,1,247.150000000,268.670000000,400,100,1,1,247.000000000,269.580000000,12,100,1,1,TSLA
2024-11-01T08:00:11.841196323Z,2024-11-01T08:00:11.841030767Z,10,2,16244,C,A,0,251.070000000,100,130,165556,314455,250.000000000,253.650000000,2,400,2,1,249.930000000,255.000000000,10,85,1,2,249.800000000,260.000000000,199,168,1,3,249.770000000,262.660000000,50,56,1,1,249.700000000,264.940000000,1000,7,1,1,249.600000000,265.000000000,1000,102,1,3,248.500000000,267.800000000,40,30,1,1,248.200000000,268.670000000,1000,100,1,1,247.150000000,269.580000000,400,100,1,1,247.000000000,270.000000000,12,118,1,3,TSLA
2024-11-01T08:00:11.841209194Z,2024-11-01T08:00:11.841043022Z,10,2,16244,A,A,0,251.100000000,100,130,166172,314456,250.000000000,251.100000000,2,100,2,1,249.930000000,253.650000000,10,400,1,1,249.800000000,255.000000000,199,85,1,2,249.770000000,260.000000000,50,168,1,3,249.700000000,262.660000000,1000,56,1,1,249.600000000,264.940000000,1000,7,1,1,248.500000000,265.000000000,40,102,1,3,248.200000000,267.800000000,1000,30,1,1,247.150000000,268.670000000,400,100,1,1,247.000000000,269.580000000,12,100,1,1,TSLA
2024-11-01T08:00:11.841459071Z,2024-11-01T08:00:11.841293294Z,10,2,16244,C,A,0,251.100000000,100,130,165777,314457,250.000000000,253.650000000,2,400,2,1,249.930000000,255.000000000,10,85,1,2,249.800000000,260.000000000,199,168,1,3,249.770000000,262.660000000,50,56,1,1,249.700000000,264.940000000,1000,7,1,1,249.600000000,265.000000000,1000,102,1,3,248.500000000,267.800000000,40,30,1,1,248.200000000,268.670000000,1000,100,1,1,247.150000000,269.580000000,400,100,1,1,247.000000000,270.000000000,12,118,1,3,TSLA
2024-11-01T08:00:11.841471325Z,2024-11-01T08:00:11.841304887Z,10,2,16244,A,A,0,251.120000000,100,130,166438,314458,250.000000000,251.120000000,2,100,2,1,249.930000000,253.650000000,10,400,1,1,249.800000000,255.000000000,199,85,1,2,249.770000000,260.000000000,50,168,1,3,249.700000000,262.660000000,1000,56,1,1,249.600000000,264.940000000,1000,7,1,1,248.500000000,265.000000000,40,102,1,3,248.200000000,267.800000000,1000,30,1,1,247.150000000,268.670000000,400,100,1,1,247.000000000,269.580000000,12,100,1,1,TSLA
2024-11-01T08:00:11.849201522Z,2024-11-01T08:00:11.849035558Z,10,2,16244,A,B,6,248.800000000,1000,130,165964,314473,250.000000000,251.120000000,2,100,2,1,249.930000000,253.650000000,10,400,1,1,249.800000000,255.000000000,199,85,1,2,249.770000000,260.000000000,50,168,1,3,249.700000000,262.660000000,1000,56,1,1,249.600000000,264.940000000,1000,7,1,1,248.800000000,265.000000000,1000,102,1,3,248.500000000,267.800000000,40,30,1,1,248.200000000,268.670000000,1000,100,1,1,247.150000000,269.580000000,400,100,1,1,TSLA
2024-11-01T08:00:11.849228369Z,2024-11-01T08:00:11.849062607Z,10,2,16244,C,B,8,248.200000000,1000,130,165762,314474,250.000000000,251.120000000,2,100,2,1,249.930000000,253.650000000,10,400,1,1,249.800000000,255.000000000,199,85,1,2,249.770000000,260.000000000,50,168,1,3,249.700000000,262.660000000,1000,56,1,1,249.600000000,264.940000000,1000,7,1,1,248.800000000,265.000000000,1000,102,1,3,248.500000000,267.800000000,40,30,1,1,247.150000000,268.670000000,400,100,1,1,247.000000000,269.580000000,12,100,1,1,TSLA
2024-11-01T08:00:11.849293502Z,2024-11-01T08:00:11.849127303Z,10,2,16244,A,A,1,252.400000000,1000,130,166199,314475,250.000000000,251.120000000,2,100,2,1,249.930000000,252.400000000,10,1000,1,1,249.800000000,253.650000000,199,400,1,1,249.770000000,255.000000000,50,85,1,2,249.700000000,260.000000000,1000,168,1,3,249.600000000,262.660000000,1000,56,1,1,248.800000000,264.940000000,1000,7,1,1,248.500000000,265.000000000,40,102,1,3,247.150000000,267.800000000,400,30,1,1,247.000000000,268.670000000,12,100,1,1,TSLA
2024-11-01T08:00:11.876397328Z,2024-11-01T08:00:11.876231653Z,10,2,16244,C,B,6,248.800000000,1000,130,165675,314499,250.000000000,251.120000000,2,100,2,1,249.930000000,252.400000000,10,1000,1,1,249.800000000,253.650000000,199,400,1,1,249.770000000,255.000000000,50,85,1,2,249.700000000,260.000000000,1000,168,1,3,249.600000000,262.660000000,1000,56,1,1,248.500000000,264.940000000,40,7,1,1,247.150000000,265.000000000,400,102,1,3,247.000000000,267.800000000,12,30,1,1,246.000000000,268.670000000,4,100,1,1,TSLA
2024-11-01T08:00:11.876545666Z,2024-11-01T08:00:11.876379447Z,10,2,16244,C,B,4,249.600000000,1000,130,166219,314501,250.000000000,251.120000000,2,100,2,1,249.930000000,252.400000000,10,1000,1,1,249.800000000,253.650000000,199,400,1,1,249.770000000,255.000000000,50,85,1,2,248.500000000,260.000000000,40,168,1,3,247.150000000,262.660000000,400,56,1,1,247.000000000,264.940000000,12,7,1,1,246.000000000,265.000000000,4,102,1,3,245.000000000,267.800000000,115,30,3,1,243.200000000,268.670000000,15,100,1,1,TSLA
2024-11-01T08:00:11.887224459Z,2024-11-01T08:00:11.887058146Z,10,2,16244,A,B,4,249.700000000,1000,130,166313,314532,250.000000000,251.120000000,2,100,2,1,249.930000000,252.400000000,10,1000,1,1,249.800000000,253.650000000,199,400,1,1,249.770000000,255.000000000,50,85,1,2,249.700000000,260.000000000,1000,168,1,3,248.500000000,262.660000000,40,56,1,1,247.150000000,264.940000000,400,7,1,1,247.000000000,265.000000000,12,102,1,3,246.000000000,267.800000000,4,30,1,1,245.000000000,268.670000000,115,100,3,1,TSLA
2024-11-01T08:00:11.900500040Z,2024-11-01T08:00:11.900334458Z,10,2,16244,C,B,4,249.700000000,1000,130,165582,314541,250.000000000,251.120000000,2,100,2,1,249.930000000,252.400000000,10,1000,1,1,249.800000000,253.650000000,199,400,1,1,249.770000000,255.000000000,50,85,1,2,248.500000000,260.000000000,40,168,1,3,247.150000000,262.660000000,400,56,1,1,247.000000000,264.940000000,12,7,1,1,246.000000000,265.000000000,4,102,1,3,245.000000000,267.800000000,115,30,3,1,243.200000000,268.670000000,15,100,1,1,TSLA
2024-11-01T08:00:11.903869386Z,2024-11-01T08:00:11.903702368Z,10,2,11667,A,B,7,133.800000000,5,130,167018,314545,134.680000000,134.990000000,100,10,1,1,134.500000000,135.000000000,520,38,2,3,134.410000000,135.100000000,61,10,2,1,134.380000000,135.230000000,18,360,1,1,134.210000000,135.300000000,20,1000,1,1,134.200000000,135.400000000,3,10,1,1,134.000000000,135.420000000,1,1,1,1,133.800000000,135.820000000,5,1,1,1,133.160000000,135.990000000,1,20,1,1,132.760000000,136.100000000,104,1000,2,1,NVDA
2024-11-01T08:00:11.909754193Z,2024-11-01T08:00:11.909587907Z,10,2,16244,A,A,0,251.100000000,100,130,166286,314557,250.000000000,251.100000000,2,100,2,1,249.930000000,252.400000000,10,1000,1,1,249.800000000,253.650000000,199,400,1,1,249.770000000,255.000000000,50,85,1,2,248.500000000,260.000000000,40,168,1,3,247.150000000,262.660000000,400,56,1,1,247.000000000,264.940000000,12,7,1,1,246.000000000,265.000000000,4,102,1,3,245.000000000,267.800000000,115,30,3,1,243.200000000,268.670000000,15,100,1,1,TSLA
2024-11-01T08:00:11.911317254Z,2024-11-01T08:00:11.911151222Z,10,2,16244,A,B,4,249.400000000,1000,130,166032,314559,250.000000000,251.100000000,2,100,2,1,249.930000000,252.400000000,10,1000,1,1,249.800000000,253.650000000,199,400,1,1,249.770000000,255.000000000,50,85,1,2,249.400000000,260.000000000,1000,168,1,3,248.500000000,262.660000000,40,56,1,1,247.150000000,264.940000000,400,7,1,1,247.000000000,265.000000000,12,102,1,3,246.000000000,267.800000000,4,30,1,1,245.000000000,268.670000000,115,100,3,1,TSLA
2024-11-01T08:00:11.932580018Z,2024-11-01T08:00:11.932413732Z,10,2,10888,A,B,2,409.430000000,5,130,166286,314566,410.000000000,414.000000000,1,468,1,2,409.750000000,415.070000000,3,246,1,1,409.430000000,415.350000000,5,84,1,2,409.080000000,420.000000000,2,3,1,1,409.000000000,440.000000000,2,35,1,1,408.970000000,445.000000000,12,25,1,1,408.960000000,445.680000000,5,3,1,1,407.600000000,448.000000000,16,15,1,2,407.000000000,450.000000000,17,10,3,1,406.350000000,467.560000000,82,5,2,1,MSFT
2024-11-01T08:00:11.932656290Z,2024-11-01T08:00:11.932490158Z,10,2,10888,A,B,2,409.670000000,100,130,166132,314567,410.000000000,414.000000000,1,468,1,2,409.750000000,415.070000000,3,246,1,1,409.670000000,415.350000000,100,84,1,2,409.430000000,420.000000000,5,3,1,1,409.080000000,440.000000000,2,35,1,1,409.000000000,445.000000000,2,25,1,1,408.970000000,445.680000000,12,3,1,1,408.960000000,448.000000000,5,15,1,2,407.600000000,450.000000000,16,10,1,1,407.000000000,467.560000000,17,5,3,1,MSFT
2024-11-01T08:00:11.940234616Z,2024-11-01T08:00:11.940068402Z,10,2,16244,A,A,0,251.100000000,50,130,166214,314579,250.000000000,251.100000000,2,150,2,2,249.930000000,252.400000000,10,1000,1,1,249.800000000,253.650000000,199,400,1,1,249.770000000,255.000000000,50,85,1,2,249.400000000,260.000000000,1000,168,1,3,248.500000000,262.660000000,40,56,1,1,247.150000000,264.940000000,400,7,1,1,247.000000000,265.000000000,12,102,1,3,246.000000000,267.800000000,4,30,1,1,245.000000000,268.670000000,115,100,3,1,TSLA
2024-11-01T08:00:11.942622212Z,2024-11-01T08:00:11.942456002Z,10,2,10888,A,A,8,450.000000000,2,130,166210,314581,410.000000000,414.000000000,1,468,1,2,409.750000000,415.070000000,3,246,1,1,409.670000000,415.350000000,100,84,1,2,409.430000000,420.000000000,5,3,1,1,409.080000000,440.000000000,2,35,1,1,409.000000000,445.000000000,2,25,1,1,408.970000000,445.680000000,12,3,1,1,408.960000000,448.000000000,5,15,1,2,407.600000000,450.000000000,16,12,1,2,407.000000000,467.560000000,17,5,3,1,MSFT
2024-11-01T08:00:11.968084332Z,2024-11-01T08:00:11.967918487Z,10,2,6905,C,B,0,84.040000000,100,130,165845,314596,,91.880000000,0,100,0,1,,,0,0,0,0,,,0,0,0,0,,,0,0,0,0,,,0,0,0,0,,,0,0,0,0,,,0,0,0,0,,,0,0,0,0,,,0,0,0,0,,,0,0,0,0,GILD
2024-11-01T08:00:11.980261074Z,2024-11-01T08:00:11.980094588Z,10,2,16244,A,B,0,250.020000000,50,130,166486,314604,250.020000000,251.100000000,50,150,1,2,250.000000000,252.400000000,2,1000,2,1,249.930000000,253.650000000,10,400,1,1,249.800000000,255.000000000,199,85,1,2,249.770000000,260.000000000,50,168,1,3,249.400000000,262.660000000,1000,56,1,1,248.500000000,264.940000000,40,7,1,1,247.150000000,265.000000000,400,102,1,3,247.000000000,267.800000000,12,30,1,1,246.000000000,268.670000000,4,100,1,1,TSLA
2024-11-01T08:00:12.010298851Z,2024-11-01T08:00:12.010132491Z,10,2,16244,A,B,0,250.110000000,50,130,166360,314644,250.110000000,251.100000000,50,150,1,2,250.000000000,252.400000000,2,1000,2,1,249.930000000,253.650000000,10,400,1,1,249.800000000,255.000000000,199,85,1,2,249.770000000,260.000000000,50,168,1,3,249.400000000,262.660000000,1000,56,1,1,248.500000000,264.940000000,40,7,1,1,247.150000000,265.000000000,400,102,1,3,247.000000000,267.800000000,12,30,1,1,246.000000000,268.670000000,4,100,1,1,TSLA
2024-11-01T08:00:12.023033525Z,2024-11-01T08:00:12.022866931Z,10,2,6905,A,B,0,84.040000000,100,130,166594,314659,84.040000000,91.880000000,100,100,1,1,,,0,0,0,0,,,0,0,0,0,,,0,0,0,0,,,0,0,0,0,,,0,0,0,0,,,0,0,0,0,,,0,0,0,0,,,0,0,0,0,,,0,0,0,0,GILD
2024-11-01T08:00:12.051837828Z,2024-11-01T08:00:12.051671871Z,10,2,16244,C,A,0,251.100000000,50,130,165957,314734,250.110000000,251.100000000,50,100,1,1,250.000000000,252.400000000,2,1000,2,1,249.930000000,253.650000000,10,400,1,1,249.800000000,255.000000000,199,85,1,2,249.770000000,260.000000000,50,168,1,3,249.400000000,262.660000000,1000,56,1,1,248.500000000,264.940000000,40,7,1,1,247.150000000,265.000000000,400,102,1,3,247.000000000,267.800000000,12,30,1,1,246.000000000,268.670000000,4,100,1,1,TSLA
2024-11-01T08:00:12.052652034Z,2024-11-01T08:00:12.052486477Z,10,2,16244,C,A,0,251.100000000,100,130,165557,314740,250.110000000,252.400000000,50,1000,1,1,250.000000000,253.650000000,2,400,2,1,249.930000000,255.000000000,10,85,1,2,249.800000000,260.000000000,199,168,1,3,249.770000000,262.660000000,50,56,1,1,249.400000000,264.940000000,1000,7,1,1,248.500000000,265.000000000,40,102,1,3,247.150000000,267.800000000,400,30,1,1,247.000000000,268.670000000,12,100,1,1,246.000000000,269.580000000,4,100,1,1,TSLA
2024-11-01T08:00:12.052664746Z,2024-11-01T08:00:12.052498638Z,10,2,16244,A,A,0,251.120000000,100,130,166108,314741,250.110000000,251.120000000,50,100,1,1,250.000000000,252.400000000,2,1000,2,1,249.930000000,253.650000000,10,400,1,1,249.800000000,255.000000000,199,85,1,2,249.770000000,260.000000000,50,168,1,3,249.400000000,262.660000000,1000,56,1,1,248.500000000,264.940000000,40,7,1,1,247.150000000,265.000000000,400,102,1,3,247.000000000,267.800000000,12,30,1,1,246.000000000,268.670000000,4,100,1,1,TSLA
2024-11-01T08:00:12.052943030Z,2024-11-01T08:00:12.052777371Z,10,2,16244,C,A,0,251.120000000,100,130,165659,314742,250.110000000,252.400000000,50,1000,1,1,250.000000000,253.650000000,2,400,2,1,249.930000000,255.000000000,10,85,1,2,249.800000000,260.000000000,199,168,1,3,249.770000000,262.660000000,50,56,1,1,249.400000000,264.940000000,1000,7,1,1,248.500000000,265.000000000,40,102,1,3,247.150000000,267.800000000,400,30,1,1,247.000000000,268.670000000,12,100,1,1,246.000000000,269.580000000,4,100,1,1,TSLA
2024-11-01T08:00:12.052955594Z,2024-11-01T08:00:12.052789609Z,10,2,16244,A,A,0,251.150000000,100,130,165985,314743,250.110000000,251.150000000,50,100,1,1,250.000000000,252.400000000,2,1000,2,1,249.930000000,253.650000000,10,400,1,1,249.800000000,255.000000000,199,85,1,2,249.770000000,260.000000000,50,168,1,3,249.400000000,262.660000000,1000,56,1,1,248.500000000,264.940000000,40,7,1,1,247.150000000,265.000000000,400,102,1,3,247.000000000,267.800000000,12,30,1,1,246.000000000,268.670000000,4,100,1,1,TSLA
2024-11-01T08:00:12.062944714Z,2024-11-01T08:00:12.062778567Z,10,2,10888,A,A,9,455.000000000,5,130,166147,314751,410.000000000,414.000000000,1,468,1,2,409.750000000,415.070000000,3,246,1,1,409.670000000,415.350000000,100,84,1,2,409.430000000,420.000000000,5,3,1,1,409.080000000,440.000000000,2,35,1,1,409.000000000,445.000000000,2,25,1,1,408.970000000,445.680000000,12,3,1,1,408.960000000,448.000000000,5,15,1,2,407.600000000,450.000000000,16,12,1,2,407.000000000,455.000000000,17,5,3,1,MSFT
2024-11-01T08:00:12.072038689Z,2024-11-01T08:00:12.071872261Z,10,2,16244,A,B,0,250.150000000,50,130,166428,314755,250.150000000,251.150000000,50,100,1,1,250.000000000,252.400000000,2,1000,2,1,249.930000000,253.650000000,10,400,1,1,249.800000000,255.000000000,199,85,1,2,249.770000000,260.000000000,50,168,1,3,249.400000000,262.660000000,1000,56,1,1,248.500000000,264.940000000,40,7,1,1,247.150000000,265.000000000,400,102,1,3,247.000000000,267.800000000,12,30,1,1,246.000000000,268.670000000,4,100,1,1,TSLA
2024-11-01T08:00:12.072262589Z,2024-11-01T08:00:12.072096208Z,10,2,16244,A,B,3,249.880000000,4,130,166381,314756,250.150000000,251.150000000,50,100,1,1,250.000000000,252.400000000,2,1000,2,1,249.930000000,253.650000000,10,400,1,1,249.880000000,255.000000000,4,85,1,2,249.800000000,260.000000000,199,168,1,3,249.770000000,262.660000000,50,56,1,1,249.400000000,264.940000000,1000,7,1,1,248.500000000,265.000000000,40,102,1,3,247.150000000,267.800000000,400,30,1,1,247.000000000,268.670000000,12,100,1,1,TSLA
2024-11-01T08:00:12.083344521Z,2024-11-01T08:00:12.083178480Z,10,2,16244,A,B,0,250.150000000,50,130,166041,314776,250.150000000,251.150000000,100,100,2,1,250.000000000,252.400000000,2,1000,2,1,249.930000000,253.650000000,10,400,1,1,249.880000000,255.000000000,4,85,1,2,249.800000000,260.000000000,199,168,1,3,249.770000000,262.660000000,50,56,1,1,249.400000000,264.940000000,1000,7,1,1,248.500000000,265.000000000,40,102,1,3,247.150000000,267.800000000,400,30,1,1,247.000000000,268.670000000,12,100,1,1,TSLA
2024-11-01T08:00:12.124543568Z,2024-11-01T08:00:12.124377080Z,10,2,10888,A,B,9,407.000000000,2,130,166488,314875,410.000000000,414.000000000,1,468,1,2,409.750000000,415.070000000,3,246,1,1,409.670000000,415.350000000,100,84,1,2,409.430000000,420.000000000,5,3,1,1,409.080000000,440.000000000,2,35,1,1,409.000000000,445.000000000,2,25,1,1,408.970000000,445.680000000,12,3,1,1,408.960000000,448.000000000,5,15,1,2,407.600000000,450.000000000,16,12,1,2,407.000000000,455.000000000,19,5,4,1,MSFT
2024-11-01T08:00:12.137337594Z,2024-11-01T08:00:12.137171993Z,10,2,16244,C,B,0,250.150000000,50,130,165601,314909,250.150000000,251.150000000,50,100,1,1,250.000000000,252.400000000,2,1000,2,1,249.930000000,253.650000000,10,400,1,1,249.880000000,255.000000000,4,85,1,2,249.800000000,260.000000000,199,168,1,3,249.770000000,262.660000000,50,56,1,1,249.400000000,264.940000000,1000,7,1,1,248.500000000,265.000000000,40,102,1,3,247.150000000,267.800000000,400,30,1,1,247.000000000,268.670000000,12,100,1,1,TSLA
2024-11-01T08:00:12.137351725Z,2024-11-01T08:00:12.137185661Z,10,2,16244,A,B,0,250.170000000,100,130,166064,314910,250.170000000,251.150000000,100,100,1,1,250.000000000,252.400000000,2,1000,2,1,249.930000000,253.650000000,10,400,1,1,249.880000000,255.000000000,4,85,1,2,249.800000000,260.000000000,199,168,1,3,249.770000000,262.660000000,50,56,1,1,249.400000000,264.940000000,1000,7,1,1,248.500000000,265.000000000,40,102,1,3,247.150000000,267.800000000,400,30,1,1,247.000000000,268.670000000,12,100,1,1,TSLA
2024-11-01T08:00:12.151819356Z,2024-11-01T08:00:12.151652685Z,10,2,10888,A,B,8,408.000000000,7,130,166671,315012,410.000000000,414.000000000,1,468,1,2,409.750000000,415.070000000,3,246,1,1,409.670000000,415.350000000,100,84,1,2,409.430000000,420.000000000,5,3,1,1,409.080000000,440.000000000,2,35,1,1,409.000000000,445.000000000,2,25,1,1,408.970000000,445.680000000,12,3,1,1,408.960000000,448.000000000,5,15,1,2,408.000000000,450.000000000,7,12,1,2,407.600000000,455.000000000,16,5,1,1,MSFT
2024-11-01T08:00:12.168886635Z,2024-11-01T08:00:12.168720539Z,10,2,12463,A,B,0,163.350000000,100,130,166096,315079,163.350000000,171.810000000,100,100,1,1,,180.000000000,0,20,0,1,,,0,0,0,0,,,0,0,0,0,,,0,0,0,0,,,0,0,0,0,,,0,0,0,0,,,0,0,0,0,,,0,0,0,0,,,0,0,0,0,PEP
2024-11-01T08:00:12.179037891Z,2024-11-01T08:00:12.178871744Z,10,2,11667,A,B,9,132.800000000,89,130,166147,315115,134.680000000,134.990000000,100,10,1,1,134.500000000,135.000000000,520,38,2,3,134.410000000,135.100000000,61,10,2,1,134.380000000,135.230000000,18,360,1,1,134.210000000,135.300000000,20,1000,1,1,134.200000000,135.400000000,3,10,1,1,134.000000000,135.420000000,1,1,1,1,133.800000000,135.820000000,5,1,1,1,133.160000000,135.990000000,1,20,1,1,132.800000000,136.100000000,89,1000,1,1,NVDA
2024-11-01T08:00:12.248002240Z,2024-11-01T08:00:12.247834610Z,10,2,12463,A,B,0,163.440000000,100,130,167630,315222,163.440000000,171.810000000,100,100,1,1,,180.000000000,0,20,0,1,,,0,0,0,0,,,0,0,0,0,,,0,0,0,0,,,0,0,0,0,,,0,0,0,0,,,0,0,0,0,,,0,0,0,0,,,0,0,0,0,PEP
2024-11-01T08:00:12.259106789Z,2024-11-01T08:00:12.258940574Z,10,2,16244,A,A,1,251.500000000,50,130,166215,315240,250.170000000,251.150000000,100,100,1,1,250.000000000,251.500000000,2,50,2,1,249.930000000,252.400000000,10,1000,1,1,249.880000000,253.650000000,4,400,1,1,249.800000000,255.000000000,199,85,1,2,249.770000000,260.000000000,50,168,1,3,249.400000000,262.660000000,1000,56,1,1,248.500000000,264.940000000,40,7,1,1,247.150000000,265.000000000,400,102,1,3,247.000000000,267.800000000,12,30,1,1,TSLA
2024-11-01T08:00:12.278103756Z,2024-11-01T08:00:12.277937537Z,10,2,16244,A,A,1,251.500000000,50,130,166219,315276,250.170000000,251.150000000,100,100,1,1,250.000000000,251.500000000,2,100,2,2,249.930000000,252.400000000,10,1000,1,1,249.880000000,253.650000000,4,400,1,1,249.800000000,255.000000000,199,85,1,2,249.770000000,260.000000000,50,168,1,3,249.400000000,262.660000000,1000,56,1,1,248.500000000,264.940000000,40,7,1,1,247.150000000,265.000000000,400,102,1,3,247.000000000,267.800000000,12,30,1,1,TSLA
2024-11-01T08:00:12.311466890Z,2024-11-01T08:00:12.311300895Z,10,2,16244,C,A,1,251.500000000,50,130,165995,315376,250.170000000,251.150000000,100,100,1,1,250.000000000,251.500000000,2,50,2,1,249.930000000,252.400000000,10,1000,1,1,249.880000000,253.650000000,4,400,1,1,249.800000000,255.000000000,199,85,1,2,249.770000000,260.000000000,50,168,1,3,249.400000000,262.660000000,1000,56,1,1,248.500000000,264.940000000,40,7,1,1,247.150000000,265.000000000,400,102,1,3,247.000000000,267.800000000,12,30,1,1,TSLA
2024-11-01T08:00:12.311481300Z,2024-11-01T08:00:12.311314874Z,10,2,16244,A,A,1,251.490000000,100,130,166426,315377,250.170000000,251.150000000,100,100,1,1,250.000000000,251.490000000,2,100,2,1,249.930000000,252.400000000,10,1000,1,1,249.880000000,253.650000000,4,400,1,1,249.800000000,255.000000000,199,85,1,2,249.770000000,260.000000000,50,168,1,3,249.400000000,262.660000000,1000,56,1,1,248.500000000,264.940000000,40,7,1,1,247.150000000,265.000000000,400,102,1,3,247.000000000,267.800000000,12,30,1,1,TSLA
2024-11-01T08:00:12.330113236Z,2024-11-01T08:00:12.329946593Z,10,2,16244,A,A,0,251.150000000,50,130,166643,315397,250.170000000,251.150000000,100,150,1,2,250.000000000,252.400000000,2,1000,2,1,249.930000000,253.650000000,10,400,1,1,249.880000000,255.000000000,4,85,1,2,249.800000000,260.000000000,199,168,1,3,249.770000000,262.660000000,50,56,1,1,249.400000000,264.940000000,1000,7,1,1,248.500000000,265.000000000,40,102,1,3,247.150000000,267.800000000,400,30,1,1,247.000000000,268.670000000,12,100,1,1,TSLA
2024-11-01T08:00:12.368542254Z,2024-11-01T08:00:12.368375429Z,10,2,11667,A,A,8,135.910000000,100,130,166825,315427,134.680000000,134.990000000,100,10,1,1,134.500000000,135.000000000,520,38,2,3,134.410000000,135.100000000,61,10,2,1,134.380000000,135.230000000,18,360,1,1,134.210000000,135.300000000,20,1000,1,1,134.200000000,135.400000000,3,10,1,1,134.000000000,135.420000000,1,1,1,1,133.800000000,135.820000000,5,1,1,1,133.160000000,135.910000000,1,100,1,1,132.800000000,135.990000000,89,20,1,1,NVDA
2024-11-01T08:00:12.435561320Z,2024-11-01T08:00:12.435395133Z,10,2,10888,A,B,5,409.000000000,1,130,166187,315488,410.000000000,414.000000000,1,468,1,2,409.750000000,415.070000000,3,246,1,1,409.670000000,415.350000000,100,84,1,2,409.430000000,420.000000000,5,3,1,1,409.080000000,440.000000000,2,35,1,1,409.000000000,445.000000000,3,25,2,1,408.970000000,445.680000000,12,3,1,1,408.960000000,448.000000000,5,15,1,2,408.000000000,450.000000000,7,12,1,2,407.600000000,455.000000000,16,5,1,1,MSFT
2024-11-01T08:00:12.442102550Z,2024-11-01T08:00:12.441936488Z,10,2,16727,A,A,0,300.000000000,1,130,166062,315491,,300.000000000,0,1,0,1,,305.000000000,0,1,0,1,,,0,0,0,0,,,0,0,0,0,,,0,0,0,0,,,0,0,0,0,,,0,0,0,0,,,0,0,0,0,,,0,0,0,0,,,0,0,0,0,V
2024-11-01T08:00:12.468992768Z,2024-11-01T08:00:12.468826138Z,10,2,12463,A,B,0,163.890000000,100,130,166630,315560,163.890000000,171.810000000,100,100,1,1,,180.000000000,0,20,0,1,,,0,0,0,0,,,0,0,0,0,,,0,0,0,0,,,0,0,0,0,,,0,0,0,0,,,0,0,0,0,,,0,0,0,0,,,0,0,0,0,PEP
2024-11-01T08:00:12.521061332Z,2024-11-01T08:00:12.520894841Z,10,2,16244,A,A,0,251.150000000,50,130,166491,315732,250.170000000,251.150000000,100,200,1,3,250.000000000,252.400000000,2,1000,2,1,249.930000000,253.650000000,10,400,1,1,249.880000000,255.000000000,4,85,1,2,249.800000000,260.000000000,199,168,1,3,249.770000000,262.660000000,50,56,1,1,249.400000000,264.940000000,1000,7,1,1,248.500000000,265.000000000,40,102,1,3,247.150000000,267.800000000,400,30,1,1,247.000000000,268.670000000,12,100,1,1,TSLA
2024-11-01T08:00:12.547354063Z,2024-11-01T08:00:12.547187209Z,10,2,12463,A,B,0,163.980000000,100,130,166854,315777,163.980000000,171.810000000,100,100,1,1,,180.000000000,0,20,0,1,,,0,0,0,0,,,0,0,0,0,,,0,0,0,0,,,0,0,0,0,,,0,0,0,0,,,0,0,0,0,,,0,0,0,0,,,0,0,0,0,PEP
2024-11-01T08:00:12.582573885Z,2024-11-01T08:00:12.582407140Z,10,2,10888,A,B,4,409.250000000,2,130,166745,315826,410.000000000,414.000000000,1,468,1,2,409.750000000,415.070000000,3,246,1,1,409.670000000,415.350000000,100,84,1,2,409.430000000,420.000000000,5,3,1,1,409.250000000,440.000000000,2,35,1,1,409.080000000,445.000000000,2,25,1,1,409.000000000,445.680000000,3,3,2,1,408.970000000,448.000000000,12,15,1,2,408.960000000,450.000000000,5,12,1,2,408.000000000,455.000000000,7,5,1,1,MSFT
2024-11-01T08:00:12.582863368Z,2024-11-01T08:00:12.582697080Z,10,2,10888,A,B,2,409.740000000,500,130,166288,315830,410.000000000,414.000000000,1,468,1,2,409.750000000,415.070000000,3,246,1,1,409.740000000,415.350000000,500,84,1,2,409.670000000,420.000000000,100,3,1,1,409.430000000,440.000000000,5,35,1,1,409.250000000,445.000000000,2,25,1,1,409.080000000,445.680000000,2,3,1,1,409.000000000,448.000000000,3,15,2,2,408.970000000,450.000000000,12,12,1,2,408.960000000,455.000000000,5,5,1,1,MSFT
2024-11-01T08:00:12.689662015Z,2024-11-01T08:00:12.689495698Z,10,2,16244,A,A,0,250.770000000,6,130,166317,315982,250.170000000,250.770000000,100,6,1,1,250.000000000,251.150000000,2,200,2,3,249.930000000,252.400000000,10,1000,1,1,249.880000000,253.650000000,4,400,1,1,249.800000000,255.000000000,199,85,1,2,249.770000000,260.000000000,50,168,1,3,249.400000000,262.660000000,1000,56,1,1,248.500000000,264.940000000,40,7,1,1,247.150000000,265.000000000,400,102,1,3,247.000000000,267.800000000,12,30,1,1,TSLA
2024-11-01T08:00:12.722939114Z,2024-11-01T08:00:12.722773182Z,10,2,16244,C,A,1,251.150000000,50,130,165932,316000,250.170000000,250.770000000,100,6,1,1,250.000000000,251.150000000,2,150,2,2,249.930000000,252.400000000,10,1000,1,1,249.880000000,253.650000000,4,400,1,1,249.800000000,255.000000000,199,85,1,2,249.770000000,260.000000000,50,168,1,3,249.400000000,262.660000000,1000,56,1,1,248.500000000,264.940000000,40,7,1,1,247.150000000,265.000000000,400,102,1,3,247.000000000,267.800000000,12,30,1,1,TSLA
2024-11-01T08:00:12.722953136Z,2024-11-01T08:00:12.722786957Z,10,2,16244,A,A,1,251.140000000,50,130,166179,316001,250.170000000,250.770000000,100,6,1,1,250.000000000,251.140000000,2,50,2,1,249.930000000,251.150000000,10,100,1,1,249.880000000,252.400000000,4,1000,1,1,249.800000000,253.650000000,199,400,1,1,249.770000000,255.000000000,50,85,1,2,249.400000000,260.000000000,1000,168,1,3,248.500000000,262.660000000,40,56,1,1,247.150000000,264.940000000,400,7,1,1,247.000000000,265.000000000,12,102,1,3,TSLA
2024-11-01T08:00:12.723026482Z,2024-11-01T08:00:12.722860394Z,10,2,16244,C,B,0,250.170000000,50,130,166088,316002,250.170000000,250.770000000,50,6,1,1,250.000000000,251.140000000,2,50,2,1,249.930000000,251.150000000,10,100,1,1,249.880000000,252.400000000,4,1000,1,1,249.800000000,253.650000000,199,400,1,1,249.770000000,255.000000000,50,85,1,2,249.400000000,260.000000000,1000,168,1,3,248.500000000,262.660000000,40,56,1,1,247.150000000,264.940000000,400,7,1,1,247.000000000,265.000000000,12,102,1,3,TSLA
2024-11-01T08:00:12.757295078Z,2024-11-01T08:00:12.757129388Z,10,2,11667,C,B,0,134.680000000,100,130,165690,316076,134.500000000,134.990000000,520,10,2,1,134.410000000,135.000000000,61,38,2,3,134.380000000,135.100000000,18,10,1,1,134.210000000,135.230000000,20,360,1,1,134.200000000,135.300000000,3,1000,1,1,134.000000000,135.400000000,1,10,1,1,133.800000000,135.420000000,5,1,1,1,133.160000000,135.820000000,1,1,1,1,132.800000000,135.910000000,89,100,1,1,132.760000000,135.990000000,104,20,2,1,NVDA
2024-11-01T08:00:12.757309141Z,2024-11-01T08:00:12.757143145Z,10,2,11667,A,B,1,134.410000000,100,130,165996,316077,134.500000000,134.990000000,520,10,2,1,134.410000000,135.000000000,161,38,3,3,134.380000000,135.100000000,18,10,1,1,134.210000000,135.230000000,20,360,1,1,134.200000000,135.300000000,3,1000,1,1,134.000000000,135.400000000,1,10,1,1,133.800000000,135.420000000,5,1,1,1,133.160000000,135.820000000,1,1,1,1,132.800000000,135.910000000,89,100,1,1,132.760000000,135.990000000,104,20,2,1,NVDA
2024-11-01T08:00:12.776818250Z,2024-11-01T08:00:12.776652057Z,10,2,11667,A,A,8,135.900000000,1000,130,166193,316130,134.500000000,134.990000000,520,10,2,1,134.410000000,135.000000000,161,38,3,3,134.380000000,135.100000000,18,10,1,1,134.210000000,135.230000000,20,360,1,1,134.200000000,135.300000000,3,1000,1,1,134.000000000,135.400000000,1,10,1,1,133.800000000,135.420000000,5,1,1,1,133.160000000,135.820000000,1,1,1,1,132.800000000,135.900000000,89,1000,1,1,132.760000000,135.910000000,104,100,2,1,NVDA
2024-11-01T08:00:12.779810661Z,2024-11-01T08:00:12.779644967Z,10,2,11667,C,A,8,135.900000000,1000,130,165694,316151,134.500000000,134.990000000,520,10,2,1,134.410000000,135.000000000,161,38,3,3,134.380000000,135.100000000,18,10,1,1,134.210000000,135.230000000,20,360,1,1,134.200000000,135.300000000,3,1000,1,1,134.000000000,135.400000000,1,10,1,1,133.800000000,135.420000000,5,1,1,1,133.160000000,135.820000000,1,1,1,1,132.800000000,135.910000000,89,100,1,1,132.760000000,135.990000000,104,20,2,1,NVDA
2024-11-01T08:00:12.798582176Z,2024-11-01T08:00:12.798415686Z,10,2,16727,A,B,0,268.000000000,25,130,166490,316182,268.000000000,300.000000000,25,1,1,1,,305.000000000,0,1,0,1,,,0,0,0,0,,,0,0,0,0,,,0,0,0,0,,,0,0,0,0,,,0,0,0,0,,,0,0,0,0,,,0,0,0,0,,,0,0,0,0,V
2024-11-01T08:00:12.857072659Z,2024-11-01T08:00:12.856906453Z,10,2,11667,A,B,1,134.440000000,100,130,166206,316275,134.500000000,134.990000000,520,10,2,1,134.440000000,135.000000000,100,38,1,3,134.410000000,135.100000000,61,10,2,1,134.380000000,135.230000000,18,360,1,1,134.210000000,135.300000000,20,1000,1,1,134.200000000,135.400000000,3,10,1,1,134.000000000,135.420000000,1,1,1,1,133.800000000,135.820000000,5,1,1,1,133.160000000,135.910000000,1,100,1,1,132.800000000,135.990000000,89,20,1,1,NVDA
2024-11-01T08:00:12.923864319Z,2024-11-01T08:00:12.923698300Z,10,2,16244,A,A,4,253.350000000,23,130,166019,316503,250.170000000,250.770000000,50,6,1,1,250.000000000,251.140000000,2,50,2,1,249.930000000,251.150000000,10,100,1,1,249.880000000,252.400000000,4,1000,1,1,249.800000000,253.350000000,199,23,1,1,249.770000000,253.650000000,50,400,1,1,249.400000000,255.000000000,1000,85,1,2,248.500000000,260.000000000,40,168,1,3,247.150000000,262.660000000,400,56,1,1,247.000000000,264.940000000,12,7,1,1,TSLA
2024-11-01T08:00:12.928285652Z,2024-11-01T08:00:12.928119453Z,10,2,16244,A,A,7,258.000000000,200,130,166199,316520,250.170000000,250.770000000,50,6,1,1,250.000000000,251.140000000,2,50,2,1,249.930000000,251.150000000,10,100,1,1,249.880000000,252.400000000,4,1000,1,1,249.800000000,253.350000000,199,23,1,1,249.770000000,253.650000000,50,400,1,1,249.400000000,255.000000000,1000,85,1,2,248.500000000,258.000000000,40,200,1,1,247.150000000,260.000000000,400,168,1,3,247.000000000,262.660000000,12,56,1,1,TSLA
2024-11-01T08:00:12.951096555Z,2024-11-01T08:00:12.950930146Z,10,2,12463,A,A,0,169.560000000,100,130,166409,316609,163.980000000,169.560000000,100,100,1,1,,180.000000000,0,20,0,1,,,0,0,0,0,,,0,0,0,0,,,0,0,0,0,,,0,0,0,0,,,0,0,0,0,,,0,0,0,0,,,0,0,0,0,,,0,0,0,0,PEP
2024-11-01T08:00:13.013111583Z,2024-11-01T08:00:13.012945480Z,10,2,16244,A,A,1,251.140000000,50,130,166103,316811,250.170000000,250.770000000,50,6,1,1,250.000000000,251.140000000,2,100,2,2,249.930000000,251.150000000,10,100,1,1,249.880000000,252.400000000,4,1000,1,1,249.800000000,253.350000000,199,23,1,1,249.770000000,253.650000000,50,400,1,1,249.400000000,255.000000000,1000,85,1,2,248.500000000,258.000000000,40,200,1,1,247.150000000,260.000000000,400,168,1,3,247.000000000,262.660000000,12,56,1,1,TSLA
2024-11-01T08:00:13.021903931Z,2024-11-01T08:00:13.021737683Z,10,2,38,A,B,2,220.000000000,6,130,166248,316839,221.700000000,224.400000000,10,1000,1,1,221.400000000,225.000000000,1000,1,1,1,220.000000000,225.360000000,8,1,2,1,219.690000000,225.490000000,442,442,1,1,219.000000000,225.900000000,1,32,1,2,217.000000000,229.330000000,1525,9,1,2,215.000000000,233.670000000,5,5,1,1,213.000000000,234.000000000,5,20,1,1,212.340000000,234.750000000,5,50,1,1,210.000000000,235.000000000,1,2,1,1,AAPL
2024-11-01T08:00:13.029462293Z,2024-11-01T08:00:13.029295550Z,10,2,12463,A,A,0,169.470000000,100,130,166743,316862,163.980000000,169.470000000,100,100,1,1,,180.000000000,0,20,0,1,,,0,0,0,0,,,0,0,0,0,,,0,0,0,0,,,0,0,0,0,,,0,0,0,0,,,0,0,0,0,,,0,0,0,0,,,0,0,0,0,PEP
2024-11-01T08:00:13.067295659Z,2024-11-01T08:00:13.067129626Z,10,2,16244,C,A,1,251.140000000,50,130,166033,317010,250.170000000,250.770000000,50,6,1,1,250.000000000,251.140000000,2,50,2,1,249.930000000,251.150000000,10,100,1,1,249.880000000,252.400000000,4,1000,1,1,249.800000000,253.350000000,199,23,1,1,249.770000000,253.650000000,50,400,1,1,249.400000000,255.000000000,1000,85,1,2,248.500000000,258.000000000,40,200,1,1,247.150000000,260.000000000,400,168,1,3,247.000000000,262.660000000,12,56,1,1,TSLA
2024-11-01T08:00:13.067309448Z,2024-11-01T08:00:13.067143347Z,10,2,16244,A,A,1,251.130000000,50,130,166101,317011,250.170000000,250.770000000,50,6,1,1,250.000000000,251.130000000,2,50,2,1,249.930000000,251.150000000,10,100,1,1,249.880000000,252.400000000,4,1000,1,1,249.800000000,253.350000000,199,23,1,1,249.770000000,253.650000000,50,400,1,1,249.400000000,255.000000000,1000,85,1,2,248.500000000,258.000000000,40,200,1,1,247.150000000,260.000000000,400,168,1,3,247.000000000,262.660000000,12,56,1,1,TSLA
2024-11-01T08:00:13.083941712Z,2024-11-01T08:00:13.083775066Z,10,2,38,A,B,2,221.200000000,10,130,166646,317081,221.700000000,224.400000000,10,1000,1,1,221.400000000,225.000000000,1000,1,1,1,221.200000000,225.360000000,10,1,1,1,220.000000000,225.490000000,8,442,2,1,219.690000000,225.900000000,442,32,1,2,219.000000000,229.330000000,1,9,1,2,217.000000000,233.670000000,1525,5,1,1,215.000000000,234.000000000,5,20,1,1,213.000000000,234.750000000,5,50,1,1,212.340000000,235.000000000,5,2,1,1,AAPL
2024-11-01T08:00:13.088143916Z,2024-11-01T08:00:13.087977698Z,10,2,38,A,A,5,227.000000000,35,130,166218,317095,221.700000000,224.400000000,10,1000,1,1,221.400000000,225.000000000,1000,1,1,1,221.200000000,225.360000000,10,1,1,1,220.000000000,225.490000000,8,442,2,1,219.690000000,225.900000000,442,32,1,2,219.000000000,227.000000000,1,35,1,1,217.000000000,229.330000000,1525,9,1,2,215.000000000,233.670000000,5,5,1,1,213.000000000,234.000000000,5,20,1,1,212.340000000,234.750000000,5,50,1,1,AAPL
2024-11-01T08:00:13.132843278Z,2024-11-01T08:00:13.132677034Z,10,2,16244,A,B,7,249.000000000,100,130,166244,317239,250.170000000,250.770000000,50,6,1,1,250.000000000,251.130000000,2,50,2,1,249.930000000,251.150000000,10,100,1,1,249.880000000,252.400000000,4,1000,1,1,249.800000000,253.350000000,199,23,1,1,249.770000000,253.650000000,50,400,1,1,249.400000000,255.000000000,1000,85,1,2,249.000000000,258.000000000,100,200,1,1,248.500000000,260.000000000,40,168,1,3,247.150000000,262.660000000,400,56,1,1,TSLA
2024-11-01T08:00:13.134571071Z,2024-11-01T08:00:13.134404595Z,10,2,16244,A,A,8,260.000000000,1,130,166476,317253,250.170000000,250.770000000,50,6,1,1,250.000000000,251.130000000,2,50,2,1,249.930000000,251.150000000,10,100,1,1,249.880000000,252.400000000,4,1000,1,1,249.800000000,253.350000000,199,23,1,1,249.770000000,253.650000000,50,400,1,1,249.400000000,255.000000000,1000,85,1,2,249.000000000,258.000000000,100,200,1,1,248.500000000,260.000000000,40,169,1,4,247.150000000,262.660000000,400,56,1,1,TSLA
2024-11-01T08:00:13.137893281Z,2024-11-01T08:00:13.137727086Z,10,2,16244,C,B,0,250.170000000,50,130,166195,317269,250.000000000,250.770000000,2,6,2,1,249.930000000,251.130000000,10,50,1,1,249.880000000,251.150000000,4,100,1,1,249.800000000,252.400000000,199,1000,1,1,249.770000000,253.350000000,50,23,1,1,249.400000000,253.650000000,1000,400,1,1,249.000000000,255.000000000,100,85,1,2,248.500000000,258.000000000,40,200,1,1,247.150000000,260.000000000,400,169,1,4,247.000000000,262.660000000,12,56,1,1,TSLA
2024-11-01T08:00:13.137906177Z,2024-11-01T08:00:13.137739685Z,10,2,16244,A,B,0,250.150000000,50,130,166492,317270,250.150000000,250.770000000,50,6,1,1,250.000000000,251.130000000,2,50,2,1,249.930000000,251.150000000,10,100,1,1,249.880000000,252.400000000,4,1000,1,1,249.800000000,253.350000000,199,23,1,1,249.770000000,253.650000000,50,400,1,1,249.400000000,255.000000000,1000,85,1,2,249.000000000,258.000000000,100,200,1,1,248.500000000,260.000000000,40,169,1,4,247.150000000,262.660000000,400,56,1,1,TSLA
2024-11-01T08:00:13.234563518Z,2024-11-01T08:00:13.234395636Z,10,2,16244,A,A,9,262.560000000,50,130,167882,317926,250.150000000,250.770000000,50,6,1,1,250.000000000,251.130000000,2,50,2,1,249.930000000,251.150000000,10,100,1,1,249.880000000,252.400000000,4,1000,1,1,249.800000000,253.350000000,199,23,1,1,249.770000000,253.650000000,50,400,1,1,249.400000000,255.000000000,1000,85,1,2,249.000000000,258.000000000,100,200,1,1,248.500000000,260.000000000,40,169,1,4,247.150000000,262.560000000,400,50,1,1,TSLA
2024-11-01T08:00:13.247459338Z,2024-11-01T08:00:13.247293005Z,10,2,16244,A,B,8,248.500000000,5,130,166333,317958,250.150000000,250.770000000,50,6,1,1,250.000000000,251.130000000,2,50,2,1,249.930000000,251.150000000,10,100,1,1,249.880000000,252.400000000,4,1000,1,1,249.800000000,253.350000000,199,23,1,1,249.770000000,253.650000000,50,400,1,1,249.400000000,255.000000000,1000,85,1,2,249.000000000,258.000000000,100,200,1,1,248.500000000,260.000000000,45,169,2,4,247.150000000,262.560000000,400,50,1,1,TSLA
2024-11-01T08:00:13.302095598Z,2024-11-01T08:00:13.301929105Z,10,2,10888,A,A,3,419.860000000,10,130,166493,318048,410.000000000,414.000000000,1,468,1,2,409.750000000,415.070000000,3,246,1,1,409.740000000,415.350000000,500,84,1,2,409.670000000,419.860000000,100,10,1,1,409.430000000,420.000000000,5,3,1,1,409.250000000,440.000000000,2,35,1,1,409.080000000,445.000000000,2,25,1,1,409.000000000,445.680000000,3,3,2,1,408.970000000,448.000000000,12,15,1,2,408.960000000,450.000000000,5,12,1,2,MSFT
2024-11-01T08:00:13.310387215Z,2024-11-01T08:00:13.310221021Z,10,2,16244,A,A,3,251.500000000,10,130,166194,318064,250.150000000,250.770000000,50,6,1,1,250.000000000,251.130000000,2,50,2,1,249.930000000,251.150000000,10,100,1,1,249.880000000,251.500000000,4,10,1,1,249.800000000,252.400000000,199,1000,1,1,249.770000000,253.350000000,50,23,1,1,249.400000000,253.650000000,1000,400,1,1,249.000000000,255.000000000,100,85,1,2,248.500000000,258.000000000,45,200,2,1,247.150000000,260.000000000,400,169,1,4,TSLA
2024-11-01T08:00:13.310747707Z,2024-11-01T08:00:13.310581079Z,10,2,16244,A,B,8,248.500000000,66,130,166628,318065,250.150000000,250.770000000,50,6,1,1,250.000000000,251.130000000,2,50,2,1,249.930000000,251.150000000,10,100,1,1,249.880000000,251.500000000,4,10,1,1,249.800000000,252.400000000,199,1000,1,1,249.770000000,253.350000000,50,23,1,1,249.400000000,253.650000000,1000,400,1,1,249.000000000,255.000000000,100,85,1,2,248.500000000,258.000000000,111,200,3,1,247.150000000,260.000000000,400,169,1,4,TSLA
2024-11-01T08:00:13.339369155Z,2024-11-01T08:00:13.339203039Z,10,2,16244,A,B,6,249.500000000,1000,130,166116,318138,250.150000000,250.770000000,50,6,1,1,250.000000000,251.130000000,2,50,2,1,249.930000000,251.150000000,10,100,1,1,249.880000000,251.500000000,4,10,1,1,249.800000000,252.400000000,199,1000,1,1,249.770000000,253.350000000,50,23,1,1,249.500000000,253.650000000,1000,400,1,1,249.400000000,255.000000000,1000,85,1,2,249.000000000,258.000000000,100,200,1,1,248.500000000,260.000000000,111,169,3,4,TSLA
2024-11-01T08:00:13.339409856Z,2024-11-01T08:00:13.339243947Z,10,2,16244,C,B,7,249.400000000,1000,130,165909,318139,250.150000000,250.770000000,50,6,1,1,250.000000000,251.130000000,2,50,2,1,249.930000000,251.150000000,10,100,1,1,249.880000000,251.500000000,4,10,1,1,249.800000000,252.400000000,199,1000,1,1,249.770000000,253.350000000,50,23,1,1,249.500000000,253.650000000,1000,400,1,1,249.000000000,255.000000000,100,85,1,2,248.500000000,258.000000000,111,200,3,1,247.150000000,260.000000000,400,169,1,4,TSLA
2024-11-01T08:00:13.413851896Z,2024-11-01T08:00:13.413685637Z,10,2,11667,A,B,0,134.930000000,400,130,166259,318348,134.930000000,134.990000000,400,10,1,1,134.500000000,135.000000000,520,38,2,3,134.440000000,135.100000000,100,10,1,1,134.410000000,135.230000000,61,360,2,1,134.380000000,135.300000000,18,1000,1,1,134.210000000,135.400000000,20,10,1,1,134.200000000,135.420000000,3,1,1,1,134.000000000,135.820000000,1,1,1,1,133.800000000,135.910000000,5,100,1,1,133.160000000,135.990000000,1,20,1,1,NVDA
2024-11-01T08:00:13.413997525Z,2024-11-01T08:00:13.413831456Z,10,2,11667,A,A,4,135.300000000,9,130,166069,318351,134.930000000,134.990000000,400,10,1,1,134.500000000,135.000000000,520,38,2,3,134.440000000,135.100000000,100,10,1,1,134.410000000,135.230000000,61,360,2,1,134.380000000,135.300000000,18,1009,1,2,134.210000000,135.400000000,20,10,1,1,134.200000000,135.420000000,3,1,1,1,134.000000000,135.820000000,1,1,1,1,133.800000000,135.910000000,5,100,1,1,133.160000000,135.990000000,1,20,1,1,NVDA
2024-11-01T08:00:13.414120505Z,2024-11-01T08:00:13.413952864Z,10,2,11667,T,A,0,134.930000000,18,130,167641,318352,134.930000000,134.990000000,400,10,1,1,134.500000000,135.000000000,520,38,2,3,134.440000000,135.100000000,100,10,1,1,134.410000000,135.230000000,61,360,2,1,134.380000000,135.300000000,18,1009,1,2,134.210000000,135.400000000,20,10,1,1,134.200000000,135.420000000,3,1,1,1,134.000000000,135.820000000,1,1,1,1,133.800000000,135.910000000,5,100,1,1,133.160000000,135.990000000,1,20,1,1,NVDA
2024-11-01T08:00:13.414120505Z,2024-11-01T08:00:13.413952864Z,10,2,11667,C,B,0,134.930000000,18,130,167641,318352,134.930000000,134.990000000,382,10,1,1,134.500000000,135.000000000,520,38,2,3,134.440000000,135.100000000,100,10,1,1,134.410000000,135.230000000,61,360,2,1,134.380000000,135.300000000,18,1009,1,2,134.210000000,135.400000000,20,10,1,1,134.200000000,135.420000000,3,1,1,1,134.000000000,135.820000000,1,1,1,1,133.800000000,135.910000000,5,100,1,1,133.160000000,135.990000000,1,20,1,1,NVDA
2024-11-01T08:00:13.414270832Z,2024-11-01T08:00:13.414104004Z,10,2,11667,T,A,0,134.930000000,9,130,166828,318354,134.930000000,134.990000000,382,10,1,1,134.500000000,135.000000000,520,38,2,3,134.440000000,135.100000000,100,10,1,1,134.410000000,135.230000000,61,360,2,1,134.380000000,135.300000000,18,1009,1,2,134.210000000,135.400000000,20,10,1,1,134.200000000,135.420000000,3,1,1,1,134.000000000,135.820000000,1,1,1,1,133.800000000,135.910000000,5,100,1,1,133.160000000,135.990000000,1,20,1,1,NVDA
2024-11-01T08:00:13.414270832Z,2024-11-01T08:00:13.414104004Z,10,2,11667,C,B,0,134.930000000,9,130,166828,318354,134.930000000,134.990000000,373,10,1,1,134.500000000,135.000000000,520,38,2,3,134.440000000,135.100000000,100,10,1,1,134.410000000,135.230000000,61,360,2,1,134.380000000,135.300000000,18,1009,1,2,134.210000000,135.400000000,20,10,1,1,134.200000000,135.420000000,3,1,1,1,134.000000000,135.820000000,1,1,1,1,133.800000000,135.910000000,5,100,1,1,133.160000000,135.990000000,1,20,1,1,NVDA
2024-11-01T08:00:13.414337768Z,2024-11-01T08:00:13.414170732Z,10,2,11667,T,A,0,134.930000000,3,130,167036,318355,134.930000000,134.990000000,373,10,1,1,134.500000000,135.000000000,520,38,2,3,134.440000000,135.100000000,100,10,1,1,134.410000000,135.230000000,61,360,2,1,134.380000000,135.300000000,18,1009,1,2,134.210000000,135.400000000,20,10,1,1,134.200000000,135.420000000,3,1,1,1,134.000000000,135.820000000,1,1,1,1,133.800000000,135.910000000,5,100,1,1,133.160000000,135.990000000,1,20,1,1,NVDA
2024-11-01T08:00:13.414337768Z,2024-11-01T08:00:13.414170732Z,10,2,11667,C,B,0,134.930000000,3,130,167036,318355,134.930000000,134.990000000,370,10,1,1,134.500000000,135.000000000,520,38,2,3,134.440000000,135.100000000,100,10,1,1,134.410000000,135.230000000,61,360,2,1,134.380000000,135.300000000,18,1009,1,2,134.210000000,135.400000000,20,10,1,1,134.200000000,135.420000000,3,1,1,1,134.000000000,135.820000000,1,1,1,1,133.800000000,135.910000000,5,100,1,1,133.160000000,135.990000000,1,20,1,1,NVDA
2024-11-01T08:00:13.414369017Z,2024-11-01T08:00:13.414202196Z,10,2,11667,T,A,0,134.930000000,29,130,166821,318356,134.930000000,134.990000000,370,10,1,1,134.500000000,135.000000000,520,38,2,3,134.440000000,135.100000000,100,10,1,1,134.410000000,135.230000000,61,360,2,1,134.380000000,135.300000000,18,1009,1,2,134.210000000,135.400000000,20,10,1,1,134.200000000,135.420000000,3,1,1,1,134.000000000,135.820000000,1,1,1,1,133.800000000,135.910000000,5,100,1,1,133.160000000,135.990000000,1,20,1,1,NVDA
2024-11-01T08:00:13.414369017Z,2024-11-01T08:00:13.414202196Z,10,2,11667,C,B,0,134.930000000,29,130,166821,318356,134.930000000,134.990000000,341,10,1,1,134.500000000,135.000000000,520,38,2,3,134.440000000,135.100000000,100,10,1,1,134.410000000,135.230000000,61,360,2,1,134.380000000,135.300000000,18,1009,1,2,134.210000000,135.400000000,20,10,1,1,134.200000000,135.420000000,3,1,1,1,134.000000000,135.820000000,1,1,1,1,133.800000000,135.910000000,5,100,1,1,133.160000000,135.990000000,1,20,1,1,NVDA
2024-11-01T08:00:13.414485326Z,2024-11-01T08:00:13.414318861Z,10,2,11667,T,A,0,134.930000000,1,130,166465,318357,134.930000000,134.990000000,341,10,1,1,134.500000000,135.000000000,520,38,2,3,134.440000000,135.100000000,100,10,1,1,134.410000000,135.230000000,61,360,2,1,134.380000000,135.300000000,18,1009,1,2,134.210000000,135.400000000,20,10,1,1,134.200000000,135.420000000,3,1,1,1,134.000000000,135.820000000,1,1,1,1,133.800000000,135.910000000,5,100,1,1,133.160000000,135.990000000,1,20,1,1,NVDA
2024-11-01T08:00:13.414485326Z,2024-11-01T08:00:13.414318861Z,10,2,11667,C,B,0,134.930000000,1,130,166465,318357,134.930000000,134.990000000,340,10,1,1,134.500000000,135.000000000,520,38,2,3,134.440000000,135.100000000,100,10,1,1,134.410000000,135.230000000,61,360,2,1,134.380000000,135.300000000,18,1009,1,2,134.210000000,135.400000000,20,10,1,1,134.200000000,135.420000000,3,1,1,1,134.000000000,135.820000000,1,1,1,1,133.800000000,135.910000000,5,100,1,1,133.160000000,135.990000000,1,20,1,1,NVDA
2024-11-01T08:00:13.414546146Z,2024-11-01T08:00:13.414370627Z,10,2,11667,T,A,0,134.930000000,3,130,175519,318358,134.930000000,134.990000000,340,10,1,1,134.500000000,135.000000000,520,38,2,3,134.440000000,135.100000000,100,10,1,1,134.410000000,135.230000000,61,360,2,1,134.380000000,135.300000000,18,1009,1,2,134.210000000,135.400000000,20,10,1,1,134.200000000,135.420000000,3,1,1,1,134.000000000,135.820000000,1,1,1,1,133.800000000,135.910000000,5,100,1,1,133.160000000,135.990000000,1,20,1,1,NVDA
2024-11-01T08:00:13.414546146Z,2024-11-01T08:00:13.414370627Z,10,2,11667,C,B,0,134.930000000,3,130,175519,318358,134.930000000,134.990000000,337,10,1,1,134.500000000,135.000000000,520,38,2,3,134.440000000,135.100000000,100,10,1,1,134.410000000,135.230000000,61,360,2,1,134.380000000,135.300000000,18,1009,1,2,134.210000000,135.400000000,20,10,1,1,134.200000000,135.420000000,3,1,1,1,134.000000000,135.820000000,1,1,1,1,133.800000000,135.910000000,5,100,1,1,133.160000000,135.990000000,1,20,1,1,NVDA
2024-11-01T08:00:13.414583816Z,2024-11-01T08:00:13.414417344Z,10,2,11667,T,A,0,134.930000000,5,130,166472,318359,134.930000000,134.990000000,337,10,1,1,134.500000000,135.000000000,520,38,2,3,134.440000000,135.100000000,100,10,1,1,134.410000000,135.230000000,61,360,2,1,134.380000000,135.300000000,18,1009,1,2,134.210000000,135.400000000,20,10,1,1,134.200000000,135.420000000,3,1,1,1,134.000000000,135.820000000,1,1,1,1,133.800000000,135.910000000,5,100,1,1,133.160000000,135.990000000,1,20,1,1,NVDA
2024-11-01T08:00:13.414583816Z,2024-11-01T08:00:13.414417344Z,10,2,11667,C,B,0,134.930000000,5,130,166472,318359,134.930000000,134.990000000,332,10,1,1,134.500000000,135.000000000,520,38,2,3,134.440000000,135.100000000,100,10,1,1,134.410000000,135.230000000,61,360,2,1,134.380000000,135.300000000,18,1009,1,2,134.210000000,135.400000000,20,10,1,1,134.200000000,135.420000000,3,1,1,1,134.000000000,135.820000000,1,1,1,1,133.800000000,135.910000000,5,100,1,1,133.160000000,135.990000000,1,20,1,1,NVDA
2024-11-01T08:00:13.414688138Z,2024-11-01T08:00:13.414520069Z,10,2,11667,T,A,0,134.930000000,1,128,168069,318360,134.930000000,134.990000000,332,10,1,1,134.500000000,135.000000000,520,38,2,3,134.440000000,135.100000000,100,10,1,1,134.410000000,135.230000000,61,360,2,1,134.380000000,135.300000000,18,1009,1,2,134.210000000,135.400000000,20,10,1,1,134.200000000,135.420000000,3,1,1,1,134.000000000,135.820000000,1,1,1,1,133.800000000,135.910000000,5,100,1,1,133.160000000,135.990000000,1,20,1,1,NVDA
2024-11-01T08:00:13.414688138Z,2024-11-01T08:00:13.414520069Z,10,2,11667,C,B,0,134.930000000,1,128,168069,318360,134.930000000,134.990000000,331,10,1,1,134.500000000,135.000000000,520,38,2,3,134.440000000,135.100000000,100,10,1,1,134.410000000,135.230000000,61,360,2,1,134.380000000,135.300000000,18,1009,1,2,134.210000000,135.400000000,20,10,1,1,134.200000000,135.420000000,3,1,1,1,134.000000000,135.820000000,1,1,1,1,133.800000000,135.910000000,5,100,1,1,133.160000000,135.990000000,1,20,1,1,NVDA
2024-11-01T08:00:13.414798341Z,2024-11-01T08:00:13.414631570Z,10,2,11667,T,A,0,134.930000000,1,130,166771,318362,134.930000000,134.990000000,331,10,1,1,134.500000000,135.000000000,520,38,2,3,134.440000000,135.100000000,100,10,1,1,134.410000000,135.230000000,61,360,2,1,134.380000000,135.300000000,18,1009,1,2,134.210000000,135.400000000,20,10,1,1,134.200000000,135.420000000,3,1,1,1,134.000000000,135.820000000,1,1,1,1,133.800000000,135.910000000,5,100,1,1,133.160000000,135.990000000,1,20,1,1,NVDA
2024-11-01T08:00:13.414798341Z,2024-11-01T08:00:13.414631570Z,10,2,11667,C,B,0,134.930000000,1,130,166771,318362,134.930000000,134.990000000,330,10,1,1,134.500000000,135.000000000,520,38,2,3,134.440000000,135.100000000,100,10,1,1,134.410000000,135.230000000,61,360,2,1,134.380000000,135.300000000,18,1009,1,2,134.210000000,135.400000000,20,10,1,1,134.200000000,135.420000000,3,1,1,1,134.000000000,135.820000000,1,1,1,1,133.800000000,135.910000000,5,100,1,1,133.160000000,135.990000000,1,20,1,1,NVDA
2024-11-01T08:00:13.415031779Z,2024-11-01T08:00:13.414865847Z,10,2,11667,A,B,1,134.660000000,54,130,165932,318364,134.930000000,134.990000000,330,10,1,1,134.660000000,135.000000000,54,38,1,3,134.500000000,135.100000000,520,10,2,1,134.440000000,135.230000000,100,360,1,1,134.410000000,135.300000000,61,1009,2,2,134.380000000,135.400000000,18,10,1,1,134.210000000,135.420000000,20,1,1,1,134.200000000,135.820000000,3,1,1,1,134.000000000,135.910000000,1,100,1,1,133.800000000,135.990000000,5,20,1,1,NVDA
2024-11-01T08:00:13.415352573Z,2024-11-01T08:00:13.415185963Z,10,2,11667,T,A,0,134.930000000,14,130,166610,318365,134.930000000,134.990000000,330,10,1,1,134.660000000,135.000000000,54,38,1,3,134.500000000,135.100000000,520,10,2,1,134.440000000,135.230000000,100,360,1,1,134.410000000,135.300000000,61,1009,2,2,134.380000000,135.400000000,18,10,1,1,134.210000000,135.420000000,20,1,1,1,134.200000000,135.820000000,3,1,1,1,134.000000000,135.910000000,1,100,1,1,133.800000000,135.990000000,5,20,1,1,NVDA
2024-11-01T08:00:13.415352573Z,2024-11-01T08:00:13.415185963Z,10,2,11667,C,B,0,134.930000000,14,130,166610,318365,134.930000000,134.990000000,316,10,1,1,134.660000000,135.000000000,54,38,1,3,134.500000000,135.100000000,520,10,2,1,134.440000000,135.230000000,100,360,1,1,134.410000000,135.300000000,61,1009,2,2,134.380000000,135.400000000,18,10,1,1,134.210000000,135.420000000,20,1,1,1,134.200000000,135.820000000,3,1,1,1,134.000000000,135.910000000,1,100,1,1,133.800000000,135.990000000,5,20,1,1,NVDA
2024-11-01T08:00:13.420067566Z,2024-11-01T08:00:13.419900772Z,10,2,11667,T,A,0,134.930000000,1,130,166794,318375,134.930000000,134.990000000,316,10,1,1,134.660000000,135.000000000,54,38,1,3,134.500000000,135.100000000,520,10,2,1,134.440000000,135.230000000,100,360,1,1,134.410000000,135.300000000,61,1009,2,2,134.380000000,135.400000000,18,10,1,1,134.210000000,135.420000000,20,1,1,1,134.200000000,135.820000000,3,1,1,1,134.000000000,135.910000000,1,100,1,1,133.800000000,135.990000000,5,20,1,1,NVDA
2024-11-01T08:00:13.420067566Z,2024-11-01T08:00:13.419900772Z,10,2,11667,C,B,0,134.930000000,1,130,166794,318375,134.930000000,134.990000000,315,10,1,1,134.660000000,135.000000000,54,38,1,3,134.500000000,135.100000000,520,10,2,1,134.440000000,135.230000000,100,360,1,1,134.410000000,135.300000000,61,1009,2,2,134.380000000,135.400000000,18,10,1,1,134.210000000,135.420000000,20,1,1,1,134.200000000,135.820000000,3,1,1,1,134.000000000,135.910000000,1,100,1,1,133.800000000,135.990000000,5,20,1,1,NVDA
2024-11-01T08:00:13.426205548Z,2024-11-01T08:00:13.426039238Z,10,2,10888,A,A,9,450.000000000,36,130,166310,318399,410.000000000,414.000000000,1,468,1,2,409.750000000,415.070000000,3,246,1,1,409.740000000,415.350000000,500,84,1,2,409.670000000,419.860000000,100,10,1,1,409.430000000,420.000000000,5,3,1,1,409.250000000,440.000000000,2,35,1,1,409.080000000,445.000000000,2,25,1,1,409.000000000,445.680000000,3,3,2,1,408.970000000,448.000000000,12,15,1,2,408.960000000,450.000000000,5,48,1,3,MSFT
2024-11-01T08:00:13.436280559Z,2024-11-01T08:00:13.436114452Z,10,2,11667,A,B,3,134.440000000,100,130,166107,318414,134.930000000,134.990000000,315,10,1,1,134.660000000,135.000000000,54,38,1,3,134.500000000,135.100000000,520,10,2,1,134.440000000,135.230000000,200,360,2,1,134.410000000,135.300000000,61,1009,2,2,134.380000000,135.400000000,18,10,1,1,134.210000000,135.420000000,20,1,1,1,134.200000000,135.820000000,3,1,1,1,134.000000000,135.910000000,1,100,1,1,133.800000000,135.990000000,5,20,1,1,NVDA
2024-11-01T08:00:13.438080735Z,2024-11-01T08:00:13.437915091Z,10,2,11667,C,B,1,134.660000000,54,130,165644,318419,134.930000000,134.990000000,315,10,1,1,134.500000000,135.000000000,520,38,2,3,134.440000000,135.100000000,200,10,2,1,134.410000000,135.230000000,61,360,2,1,134.380000000,135.300000000,18,1009,1,2,134.210000000,135.400000000,20,10,1,1,134.200000000,135.420000000,3,1,1,1,134.000000000,135.820000000,1,1,1,1,133.800000000,135.910000000,5,100,1,1,133.160000000,135.990000000,1,20,1,1,NVDA
2024-11-01T08:00:13.442108136Z,2024-11-01T08:00:13.441942088Z,10,2,16244,A,A,7,254.990000000,5,130,166048,318427,250.150000000,250.770000000,50,6,1,1,250.000000000,251.130000000,2,50,2,1,249.930000000,251.150000000,10,100,1,1,249.880000000,251.500000000,4,10,1,1,249.800000000,252.400000000,199,1000,1,1,249.770000000,253.350000000,50,23,1,1,249.500000000,253.650000000,1000,400,1,1,249.000000000,254.990000000,100,5,1,1,248.500000000,255.000000000,111,85,3,2,247.150000000,258.000000000,400,200,1,1,TSLA
2024-11-01T08:00:13.452403627Z,2024-11-01T08:00:13.452236643Z,10,2,16244,T,N,0,250.760000000,6,130,166984,318449,250.150000000,250.770000000,50,6,1,1,250.000000000,251.130000000,2,50,2,1,249.930000000,251.150000000,10,100,1,1,249.880000000,251.500000000,4,10,1,1,249.800000000,252.400000000,199,1000,1,1,249.770000000,253.350000000,50,23,1,1,249.500000000,253.650000000,1000,400,1,1,249.000000000,254.990000000,100,5,1,1,248.500000000,255.000000000,111,85,3,2,247.150000000,258.000000000,400,200,1,1,TSLA
2024-11-01T08:00:13.452455678Z,2024-11-01T08:00:13.452289609Z,10,2,16244,A,B,0,250.450000000,1,130,166069,318450,250.450000000,250.770000000,1,6,1,1,250.150000000,251.130000000,50,50,1,1,250.000000000,251.150000000,2,100,2,1,249.930000000,251.500000000,10,10,1,1,249.880000000,252.400000000,4,1000,1,1,249.800000000,253.350000000,199,23,1,1,249.770000000,253.650000000,50,400,1,1,249.500000000,254.990000000,1000,5,1,1,249.000000000,255.000000000,100,85,1,2,248.500000000,258.000000000,111,200,3,1,TSLA
2024-11-01T08:00:13.452480070Z,2024-11-01T08:00:13.452313759Z,10,2,16244,A,B,1,250.270000000,1,130,166311,318451,250.450000000,250.770000000,1,6,1,1,250.270000000,251.130000000,1,50,1,1,250.150000000,251.150000000,50,100,1,1,250.000000000,251.500000000,2,10,2,1,249.930000000,252.400000000,10,1000,1,1,249.880000000,253.350000000,4,23,1,1,249.800000000,253.650000000,199,400,1,1,249.770000000,254.990000000,50,5,1,1,249.500000000,255.000000000,1000,85,1,2,249.000000000,258.000000000,100,200,1,1,TSLA
2024-11-01T08:00:13.452978654Z,2024-11-01T08:00:13.452811833Z,10,2,16244,T,B,0,250.770000000,6,130,166821,318455,250.450000000,250.770000000,1,6,1,1,250.270000000,251.130000000,1,50,1,1,250.150000000,251.150000000,50,100,1,1,250.000000000,251.500000000,2,10,2,1,249.930000000,252.400000000,10,1000,1,1,249.880000000,253.350000000,4,23,1,1,249.800000000,253.650000000,199,400,1,1,249.770000000,254.990000000,50,5,1,1,249.500000000,255.000000000,1000,85,1,2,249.000000000,258.000000000,100,200,1,1,TSLA
2024-11-01T08:00:13.452978654Z,2024-11-01T08:00:13.452811833Z,10,2,16244,C,A,0,250.770000000,6,130,166821,318455,250.450000000,251.130000000,1,50,1,1,250.270000000,251.150000000,1,100,1,1,250.150000000,251.500000000,50,10,1,1,250.000000000,252.400000000,2,1000,2,1,249.930000000,253.350000000,10,23,1,1,249.880000000,253.650000000,4,400,1,1,249.800000000,254.990000000,199,5,1,1,249.770000000,255.000000000,50,85,1,2,249.500000000,258.000000000,1000,200,1,1,249.000000000,260.000000000,100,169,1,4,TSLA
2024-11-01T08:00:13.453000958Z,2024-11-01T08:00:13.452833319Z,10,2,16244,A,B,0,250.520000000,100,130,167639,318456,250.520000000,251.130000000,100,50,1,1,250.450000000,251.150000000,1,100,1,1,250.270000000,251.500000000,1,10,1,1,250.150000000,252.400000000,50,1000,1,1,250.000000000,253.350000000,2,23,2,1,249.930000000,253.650000000,10,400,1,1,249.880000000,254.990000000,4,5,1,1,249.800000000,255.000000000,199,85,1,2,249.770000000,258.000000000,50,200,1,1,249.500000000,260.000000000,1000,169,1,4,TSLA
2024-11-01T08:00:13.453012249Z,2024-11-01T08:00:13.452846044Z,10,2,16244,A,B,0,250.610000000,26,130,166205,318458,250.610000000,251.130000000,26,50,1,1,250.520000000,251.150000000,100,100,1,1,250.450000000,251.500000000,1,10,1,1,250.270000000,252.400000000,1,1000,1,1,250.150000000,253.350000000,50,23,1,1,250.000000000,253.650000000,2,400,2,1,249.930000000,254.990000000,10,5,1,1,249.880000000,255.000000000,4,85,1,2,249.800000000,258.000000000,199,200,1,1,249.770000000,260.000000000,50,169,1,4,TSLA
2024-11-01T08:00:13.453014645Z,2024-11-01T08:00:13.452849113Z,10,2,16244,C,B,1,250.520000000,100,130,165532,318459,250.610000000,251.130000000,26,50,1,1,250.450000000,251.150000000,1,100,1,1,250.270000000,251.500000000,1,10,1,1,250.150000000,252.400000000,50,1000,1,1,250.000000000,253.350000000,2,23,2,1,249.930000000,253.650000000,10,400,1,1,249.880000000,254.990000000,4,5,1,1,249.800000000,255.000000000,199,85,1,2,249.770000000,258.000000000,50,200,1,1,249.500000000,260.000000000,1000,169,1,4,TSLA
2024-11-01T08:00:13.453042680Z,2024-11-01T08:00:13.452876693Z,10,2,16244,A,B,1,250.510000000,26,130,165987,318460,250.610000000,251.130000000,26,50,1,1,250.510000000,251.150000000,26,100,1,1,250.450000000,251.500000000,1,10,1,1,250.270000000,252.400000000,1,1000,1,1,250.150000000,253.350000000,50,23,1,1,250.000000000,253.650000000,2,400,2,1,249.930000000,254.990000000,10,5,1,1,249.880000000,255.000000000,4,85,1,2,249.800000000,258.000000000,199,200,1,1,249.770000000,260.000000000,50,169,1,4,TSLA
2024-11-01T08:00:13.453082155Z,2024-11-01T08:00:13.452915842Z,10,2,16244,A,B,1,250.510000000,67,130,166313,318461,250.610000000,251.130000000,26,50,1,1,250.510000000,251.150000000,93,100,2,1,250.450000000,251.500000000,1,10,1,1,250.270000000,252.400000000,1,1000,1,1,250.150000000,253.350000000,50,23,1,1,250.000000000,253.650000000,2,400,2,1,249.930000000,254.990000000,10,5,1,1,249.880000000,255.000000000,4,85,1,2,249.800000000,258.000000000,199,200,1,1,249.770000000,260.000000000,50,169,1,4,TSLA
2024-11-01T08:00:13.453093819Z,2024-11-01T08:00:13.452928000Z,10,2,16244,C,B,0,250.610000000,26,130,165819,318462,250.510000000,251.130000000,93,50,2,1,250.450000000,251.150000000,1,100,1,1,250.270000000,251.500000000,1,10,1,1,250.150000000,252.400000000,50,1000,1,1,250.000000000,253.350000000,2,23,2,1,249.930000000,253.650000000,10,400,1,1,249.880000000,254.990000000,4,5,1,1,249.800000000,255.000000000,199,85,1,2,249.770000000,258.000000000,50,200,1,1,249.500000000,260.000000000,1000,169,1,4,TSLA
2024-11-01T08:00:13.453106450Z,2024-11-01T08:00:13.452940931Z,10,2,16244,C,B,0,250.510000000,26,130,165519,318463,250.510000000,251.130000000,67,50,1,1,250.450000000,251.150000000,1,100,1,1,250.270000000,251.500000000,1,10,1,1,250.150000000,252.400000000,50,1000,1,1,250.000000000,253.350000000,2,23,2,1,249.930000000,253.650000000,10,400,1,1,249.880000000,254.990000000,4,5,1,1,249.800000000,255.000000000,199,85,1,2,249.770000000,258.000000000,50,200,1,1,249.500000000,260.000000000,1000,169,1,4,TSLA
2024-11-01T08:00:13.453121984Z,2024-11-01T08:00:13.452951117Z,10,2,16244,C,B,0,250.510000000,67,130,170867,318464,250.450000000,251.130000000,1,50,1,1,250.270000000,251.150000000,1,100,1,1,250.150000000,251.500000000,50,10,1,1,250.000000000,252.400000000,2,1000,2,1,249.930000000,253.350000000,10,23,1,1,249.880000000,253.650000000,4,400,1,1,249.800000000,254.990000000,199,5,1,1,249.770000000,255.000000000,50,85,1,2,249.500000000,258.000000000,1000,200,1,1,249.000000000,260.000000000,100,169,1,4,TSLA
2024-11-01T08:00:13.453847021Z,2024-11-01T08:00:13.453681294Z,10,2,16244,C,B,0,250.450000000,1,130,165727,318468,250.270000000,251.130000000,1,50,1,1,250.150000000,251.150000000,50,100,1,1,250.000000000,251.500000000,2,10,2,1,249.930000000,252.400000000,10,1000,1,1,249.880000000,253.350000000,4,23,1,1,249.800000000,253.650000000,199,400,1,1,249.770000000,254.990000000,50,5,1,1,249.500000000,255.000000000,1000,85,1,2,249.000000000,258.000000000,100,200,1,1,248.500000000,260.000000000,111,169,3,4,TSLA
2024-11-01T08:00:13.464929853Z,2024-11-01T08:00:13.464763555Z,10,2,16244,A,B,5,249.850000000,4,130,166298,318477,250.270000000,251.130000000,1,50,1,1,250.150000000,251.150000000,50,100,1,1,250.000000000,251.500000000,2,10,2,1,249.930000000,252.400000000,10,1000,1,1,249.880000000,253.350000000,4,23,1,1,249.850000000,253.650000000,4,400,1,1,249.800000000,254.990000000,199,5,1,1,249.770000000,255.000000000,50,85,1,2,249.500000000,258.000000000,1000,200,1,1,249.000000000,260.000000000,100,169,1,4,TSLA
2024-11-01T08:00:13.482904385Z,2024-11-01T08:00:13.482738113Z,10,2,9155,A,B,1,220.000000000,3,130,166272,318513,221.850000000,224.940000000,3,450,1,1,220.000000000,226.800000000,3,100,1,1,219.160000000,,450,0,1,0,218.080000000,,100,0,1,0,,,0,0,0,0,,,0,0,0,0,,,0,0,0,0,,,0,0,0,0,,,0,0,0,0,,,0,0,0,0,JPM
2024-11-01T08:00:13.497208830Z,2024-11-01T08:00:13.497042990Z,10,2,11667,C,B,2,134.440000000,100,130,165840,318545,134.930000000,134.990000000,315,10,1,1,134.500000000,135.000000000,520,38,2,3,134.440000000,135.100000000,100,10,1,1,134.410000000,135.230000000,61,360,2,1,134.380000000,135.300000000,18,1009,1,2,134.210000000,135.400000000,20,10,1,1,134.200000000,135.420000000,3,1,1,1,134.000000000,135.820000000,1,1,1,1,133.800000000,135.910000000,5,100,1,1,133.160000000,135.990000000,1,20,1,1,NVDA
2024-11-01T08:00:13.497223541Z,2024-11-01T08:00:13.497057443Z,10,2,11667,A,B,2,134.450000000,200,130,166098,318546,134.930000000,134.990000000,315,10,1,1,134.500000000,135.000000000,520,38,2,3,134.450000000,135.100000000,200,10,1,1,134.410000000,135.230000000,61,360,2,1,134.380000000,135.300000000,18,1009,1,2,134.210000000,135.400000000,20,10,1,1,134.200000000,135.420000000,3,1,1,1,134.000000000,135.820000000,1,1,1,1,133.800000000,135.910000000,5,100,1,1,133.160000000,135.990000000,1,20,1,1,NVDA
2024-11-01T08:00:13.517343137Z,2024-11-01T08:00:13.517176848Z,10,2,11667,A,B,1,134.830000000,100,130,166289,318654,134.930000000,134.990000000,315,10,1,1,134.830000000,135.000000000,100,38,1,3,134.500000000,135.100000000,520,10,2,1,134.410000000,135.230000000,61,360,2,1,134.380000000,135.300000000,18,1009,1,2,134.210000000,135.400000000,20,10,1,1,134.200000000,135.420000000,3,1,1,1,134.000000000,135.820000000,1,1,1,1,133.800000000,135.910000000,5,100,1,1,133.160000000,135.990000000,1,20,1,1,NVDA
2024-11-01T08:00:13.853492934Z,2024-11-01T08:00:13.853326813Z,10,2,10888,A,B,0,410.000000000,30,130,166121,319208,410.000000000,414.000000000,31,468,2,2,409.750000000,415.070000000,3,246,1,1,409.740000000,415.350000000,500,84,1,2,409.670000000,419.860000000,100,10,1,1,409.430000000,420.000000000,5,3,1,1,409.250000000,440.000000000,2,35,1,1,409.080000000,445.000000000,2,25,1,1,409.000000000,445.680000000,3,3,2,1,408.970000000,448.000000000,12,15,1,2,408.960000000,450.000000000,5,48,1,3,MSFT
2024-11-01T08:00:13.877129516Z,2024-11-01T08:00:13.876961906Z,10,2,11667,T,A,0,134.930000000,5,130,167610,319269,134.930000000,134.990000000,315,10,1,1,134.830000000,135.000000000,100,38,1,3,134.500000000,135.100000000,520,10,2,1,134.410000000,135.230000000,61,360,2,1,134.380000000,135.300000000,18,1009,1,2,134.210000000,135.400000000,20,10,1,1,134.200000000,135.420000000,3,1,1,1,134.000000000,135.820000000,1,1,1,1,133.800000000,135.910000000,5,100,1,1,133.160000000,135.990000000,1,20,1,1,NVDA
2024-11-01T08:00:13.877129516Z,2024-11-01T08:00:13.876961906Z,10,2,11667,C,B,0,134.930000000,5,130,167610,319269,134.930000000,134.990000000,310,10,1,1,134.830000000,135.000000000,100,38,1,3,134.500000000,135.100000000,520,10,2,1,134.410000000,135.230000000,61,360,2,1,134.380000000,135.300000000,18,1009,1,2,134.210000000,135.400000000,20,10,1,1,134.200000000,135.420000000,3,1,1,1,134.000000000,135.820000000,1,1,1,1,133.800000000,135.910000000,5,100,1,1,133.160000000,135.990000000,1,20,1,1,NVDA
2024-11-01T08:00:13.960272379Z,2024-11-01T08:00:13.960106672Z,10,2,16244,C,B,0,250.270000000,1,130,165707,319530,250.150000000,251.130000000,50,50,1,1,250.000000000,251.150000000,2,100,2,1,249.930000000,251.500000000,10,10,1,1,249.880000000,252.400000000,4,1000,1,1,249.850000000,253.350000000,4,23,1,1,249.800000000,253.650000000,199,400,1,1,249.770000000,254.990000000,50,5,1,1,249.500000000,255.000000000,1000,85,1,2,249.000000000,258.000000000,100,200,1,1,248.500000000,260.000000000,111,169,3,4,TSLA
2024-11-01T08:00:14.022169941Z,2024-11-01T08:00:14.022003134Z,10,2,11667,T,A,0,134.930000000,58,130,166807,319675,134.930000000,134.990000000,310,10,1,1,134.830000000,135.000000000,100,38,1,3,134.500000000,135.100000000,520,10,2,1,134.410000000,135.230000000,61,360,2,1,134.380000000,135.300000000,18,1009,1,2,134.210000000,135.400000000,20,10,1,1,134.200000000,135.420000000,3,1,1,1,134.000000000,135.820000000,1,1,1,1,133.800000000,135.910000000,5,100,1,1,133.160000000,135.990000000,1,20,1,1,NVDA
2024-11-01T08:00:14.022169941Z,2024-11-01T08:00:14.022003134Z,10,2,11667,C,B,0,134.930000000,58,130,166807,319675,134.930000000,134.990000000,252,10,1,1,134.830000000,135.000000000,100,38,1,3,134.500000000,135.100000000,520,10,2,1,134.410000000,135.230000000,61,360,2,1,134.380000000,135.300000000,18,1009,1,2,134.210000000,135.400000000,20,10,1,1,134.200000000,135.420000000,3,1,1,1,134.000000000,135.820000000,1,1,1,1,133.800000000,135.910000000,5,100,1,1,133.160000000,135.990000000,1,20,1,1,NVDA
2024-11-01T08:00:14.022415716Z,2024-11-01T08:00:14.022249021Z,10,2,11667,T,A,0,134.930000000,6,130,166695,319676,134.930000000,134.990000000,252,10,1,1,134.830000000,135.000000000,100,38,1,3,134.500000000,135.100000000,520,10,2,1,134.410000000,135.230000000,61,360,2,1,134.380000000,135.300000000,18,1009,1,2,134.210000000,135.400000000,20,10,1,1,134.200000000,135.420000000,3,1,1,1,134.000000000,135.820000000,1,1,1,1,133.800000000,135.910000000,5,100,1,1,133.160000000,135.990000000,1,20,1,1,NVDA
2024-11-01T08:00:14.022415716Z,2024-11-01T08:00:14.022249021Z,10,2,11667,C,B,0,134.930000000,6,130,166695,319676,134.930000000,134.990000000,246,10,1,1,134.830000000,135.000000000,100,38,1,3,134.500000000,135.100000000,520,10,2,1,134.410000000,135.230000000,61,360,2,1,134.380000000,135.300000000,18,1009,1,2,134.210000000,135.400000000,20,10,1,1,134.200000000,135.420000000,3,1,1,1,134.000000000,135.820000000,1,1,1,1,133.800000000,135.910000000,5,100,1,1,133.160000000,135.990000000,1,20,1,1,NVDA
2024-11-01T08:00:14.022625994Z,2024-11-01T08:00:14.022459549Z,10,2,11667,T,A,0,134.930000000,4,130,166445,319677,134.930000000,134.990000000,246,10,1,1,134.830000000,135.000000000,100,38,1,3,134.500000000,135.100000000,520,10,2,1,134.410000000,135.230000000,61,360,2,1,134.380000000,135.300000000,18,1009,1,2,134.210000000,135.400000000,20,10,1,1,134.200000000,135.420000000,3,1,1,1,134.000000000,135.820000000,1,1,1,1,133.800000000,135.910000000,5,100,1,1,133.160000000,135.990000000,1,20,1,1,NVDA
2024-11-01T08:00:14.022625994Z,2024-11-01T08:00:14.022459549Z,10,2,11667,C,B,0,134.930000000,4,130,166445,319677,134.930000000,134.990000000,242,10,1,1,134.830000000,135.000000000,100,38,1,3,134.500000000,135.100000000,520,10,2,1,134.410000000,135.230000000,61,360,2,1,134.380000000,135.300000000,18,1009,1,2,134.210000000,135.400000000,20,10,1,1,134.200000000,135.420000000,3,1,1,1,134.000000000,135.820000000,1,1,1,1,133.800000000,135.910000000,5,100,1,1,133.160000000,135.990000000,1,20,1,1,NVDA
2024-11-01T08:00:14.022631628Z,2024-11-01T08:00:14.022465132Z,10,2,11667,T,A,0,134.930000000,1,130,166496,319678,134.930000000,134.990000000,242,10,1,1,134.830000000,135.000000000,100,38,1,3,134.500000000,135.100000000,520,10,2,1,134.410000000,135.230000000,61,360,2,1,134.380000000,135.300000000,18,1009,1,2,134.210000000,135.400000000,20,10,1,1,134.200000000,135.420000000,3,1,1,1,134.000000000,135.820000000,1,1,1,1,133.800000000,135.910000000,5,100,1,1,133.160000000,135.990000000,1,20,1,1,NVDA
2024-11-01T08:00:14.022631628Z,2024-11-01T08:00:14.022465132Z,10,2,11667,C,B,0,134.930000000,1,130,166496,319678,134.930000000,134.990000000,241,10,1,1,134.830000000,135.000000000,100,38,1,3,134.500000000,135.100000000,520,10,2,1,134.410000000,135.230000000,61,360,2,1,134.380000000,135.300000000,18,1009,1,2,134.210000000,135.400000000,20,10,1,1,134.200000000,135.420000000,3,1,1,1,134.000000000,135.820000000,1,1,1,1,133.800000000,135.910000000,5,100,1,1,133.160000000,135.990000000,1,20,1,1,NVDA
2024-11-01T08:00:14.022832250Z,2024-11-01T08:00:14.022665702Z,10,2,11667,T,A,0,134.930000000,1,130,166548,319680,134.930000000,134.990000000,241,10,1,1,134.830000000,135.000000000,100,38,1,3,134.500000000,135.100000000,520,10,2,1,134.410000000,135.230000000,61,360,2,1,134.380000000,135.300000000,18,1009,1,2,134.210000000,135.400000000,20,10,1,1,134.200000000,135.420000000,3,1,1,1,134.000000000,135.820000000,1,1,1,1,133.800000000,135.910000000,5,100,1,1,133.160000000,135.990000000,1,20,1,1,NVDA
2024-11-01T08:00:14.022832250Z,2024-11-01T08:00:14.022665702Z,10,2,11667,C,B,0,134.930000000,1,130,166548,319680,134.930000000,134.990000000,240,10,1,1,134.830000000,135.000000000,100,38,1,3,134.500000000,135.100000000,520,10,2,1,134.410000000,135.230000000,61,360,2,1,134.380000000,135.300000000,18,1009,1,2,134.210000000,135.400000000,20,10,1,1,134.200000000,135.420000000,3,1,1,1,134.000000000,135.820000000,1,1,1,1,133.800000000,135.910000000,5,100,1,1,133.160000000,135.990000000,1,20,1,1,NVDA
2024-11-01T08:00:14.023048308Z,2024-11-01T08:00:14.022881174Z,10,2,11667,T,A,0,134.930000000,1,130,167134,319685,134.930000000,134.990000000,240,10,1,1,134.830000000,135.000000000,100,38,1,3,134.500000000,135.100000000,520,10,2,1,134.410000000,135.230000000,61,360,2,1,134.380000000,135.300000000,18,1009,1,2,134.210000000,135.400000000,20,10,1,1,134.200000000,135.420000000,3,1,1,1,134.000000000,135.820000000,1,1,1,1,133.800000000,135.910000000,5,100,1,1,133.160000000,135.990000000,1,20,1,1,NVDA
2024-11-01T08:00:14.023048308Z,2024-11-01T08:00:14.022881174Z,10,2,11667,C,B,0,134.930000000,1,130,167134,319685,134.930000000,134.990000000,239,10,1,1,134.830000000,135.000000000,100,38,1,3,134.500000000,135.100000000,520,10,2,1,134.410000000,135.230000000,61,360,2,1,134.380000000,135.300000000,18,1009,1,2,134.210000000,135.400000000,20,10,1,1,134.200000000,135.420000000,3,1,1,1,134.000000000,135.820000000,1,1,1,1,133.800000000,135.910000000,5,100,1,1,133.160000000,135.990000000,1,20,1,1,NVDA
2024-11-01T08:00:14.059816709Z,2024-11-01T08:00:14.059650349Z,10,2,16244,A,A,0,250.880000000,23,130,166360,319767,250.150000000,250.880000000,50,23,1,1,250.000000000,251.130000000,2,50,2,1,249.930000000,251.150000000,10,100,1,1,249.880000000,251.500000000,4,10,1,1,249.850000000,252.400000000,4,1000,1,1,249.800000000,253.350000000,199,23,1,1,249.770000000,253.650000000,50,400,1,1,249.500000000,254.990000000,1000,5,1,1,249.000000000,255.000000000,100,85,1,2,248.500000000,258.000000000,111,200,3,1,TSLA
2024-11-01T08:00:14.061115915Z,2024-11-01T08:00:14.060949344Z,10,2,16244,A,A,8,255.000000000,20,130,166571,319780,250.150000000,250.880000000,50,23,1,1,250.000000000,251.130000000,2,50,2,1,249.930000000,251.150000000,10,100,1,1,249.880000000,251.500000000,4,10,1,1,249.850000000,252.400000000,4,1000,1,1,249.800000000,253.350000000,199,23,1,1,249.770000000,253.650000000,50,400,1,1,249.500000000,254.990000000,1000,5,1,1,249.000000000,255.000000000,100,105,1,3,248.500000000,258.000000000,111,200,3,1,TSLA
2024-11-01T08:00:14.100987514Z,2024-11-01T08:00:14.100821560Z,10,2,17709,C,B,2,115.280000000,856,130,165954,319861,116.000000000,118.320000000,100,856,1,1,115.290000000,118.600000000,100,100,1,1,,125.000000000,0,30,0,1,,,0,0,0,0,,,0,0,0,0,,,0,0,0,0,,,0,0,0,0,,,0,0,0,0,,,0,0,0,0,,,0,0,0,0,XOM
2024-11-01T08:00:14.101502438Z,2024-11-01T08:00:14.101336367Z,10,2,17709,C,A,0,118.320000000,856,130,166071,319865,116.000000000,118.600000000,100,100,1,1,115.290000000,125.000000000,100,30,1,1,,,0,0,0,0,,,0,0,0,0,,,0,0,0,0,,,0,0,0,0,,,0,0,0,0,,,0,0,0,0,,,0,0,0,0,,,0,0,0,0,XOM
2024-11-01T08:00:14.103942544Z,2024-11-01T08:00:14.103774190Z,10,2,16244,T,N,0,250.870000000,12,0,168354,319875,250.150000000,250.880000000,50,23,1,1,250.000000000,251.130000000,2,50,2,1,249.930000000,251.150000000,10,100,1,1,249.880000000,251.500000000,4,10,1,1,249.850000000,252.400000000,4,1000,1,1,249.800000000,253.350000000,199,23,1,1,249.770000000,253.650000000,50,400,1,1,249.500000000,254.990000000,1000,5,1,1,249.000000000,255.000000000,100,105,1,3,248.500000000,258.000000000,111,200,3,1,TSLA
2024-11-01T08:00:14.103942544Z,2024-11-01T08:00:14.103774190Z,10,2,16244,T,B,0,250.880000000,9,130,168354,319876,250.150000000,250.880000000,50,23,1,1,250.000000000,251.130000000,2,50,2,1,249.930000000,251.150000000,10,100,1,1,249.880000000,251.500000000,4,10,1,1,249.850000000,252.400000000,4,1000,1,1,249.800000000,253.350000000,199,23,1,1,249.770000000,253.650000000,50,400,1,1,249.500000000,254.990000000,1000,5,1,1,249.000000000,255.000000000,100,105,1,3,248.500000000,258.000000000,111,200,3,1,TSLA
2024-11-01T08:00:14.103942544Z,2024-11-01T08:00:14.103774190Z,10,2,16244,C,A,0,250.880000000,9,130,168354,319876,250.150000000,250.880000000,50,14,1,1,250.000000000,251.130000000,2,50,2,1,249.930000000,251.150000000,10,100,1,1,249.880000000,251.500000000,4,10,1,1,249.850000000,252.400000000,4,1000,1,1,249.800000000,253.350000000,199,23,1,1,249.770000000,253.650000000,50,400,1,1,249.500000000,254.990000000,1000,5,1,1,249.000000000,255.000000000,100,105,1,3,248.500000000,258.000000000,111,200,3,1,TSLA
2024-11-01T08:00:14.103983462Z,2024-11-01T08:00:14.103817271Z,10,2,16244,A,B,0,250.510000000,1,130,166191,319878,250.510000000,250.880000000,1,14,1,1,250.150000000,251.130000000,50,50,1,1,250.000000000,251.150000000,2,100,2,1,249.930000000,251.500000000,10,10,1,1,249.880000000,252.400000000,4,1000,1,1,249.850000000,253.350000000,4,23,1,1,249.800000000,253.650000000,199,400,1,1,249.770000000,254.990000000,50,5,1,1,249.500000000,255.000000000,1000,105,1,3,249.000000000,258.000000000,100,200,1,1,TSLA
2024-11-01T08:00:14.104001263Z,2024-11-01T08:00:14.103834859Z,10,2,16244,A,B,1,250.290000000,1,130,166404,319879,250.510000000,250.880000000,1,14,1,1,250.290000000,251.130000000,1,50,1,1,250.150000000,251.150000000,50,100,1,1,250.000000000,251.500000000,2,10,2,1,249.930000000,252.400000000,10,1000,1,1,249.880000000,253.350000000,4,23,1,1,249.850000000,253.650000000,4,400,1,1,249.800000000,254.990000000,199,5,1,1,249.770000000,255.000000000,50,105,1,3,249.500000000,258.000000000,1000,200,1,1,TSLA
2024-11-01T08:00:14.110389232Z,2024-11-01T08:00:14.110223085Z,10,2,16244,C,B,0,250.510000000,1,130,166147,319882,250.290000000,250.880000000,1,14,1,1,250.150000000,251.130000000,50,50,1,1,250.000000000,251.150000000,2,100,2,1,249.930000000,251.500000000,10,10,1,1,249.880000000,252.400000000,4,1000,1,1,249.850000000,253.350000000,4,23,1,1,249.800000000,253.650000000,199,400,1,1,249.770000000,254.990000000,50,5,1,1,249.500000000,255.000000000,1000,105,1,3,249.000000000,258.000000000,100,200,1,1,TSLA
2024-11-01T08:00:14.166791492Z,2024-11-01T08:00:14.166625216Z,10,2,17709,A,A,2,9900.000000000,11,130,166276,320064,116.000000000,118.600000000,100,100,1,1,115.290000000,125.000000000,100,30,1,1,,9900.000000000,0,11,0,1,,,0,0,0,0,,,0,0,0,0,,,0,0,0,0,,,0,0,0,0,,,0,0,0,0,,,0,0,0,0,,,0,0,0,0,XOM
2024-11-01T08:00:14.193592237Z,2024-11-01T08:00:14.193426478Z,10,2,38,C,B,1,221.400000000,1000,130,165759,320200,221.700000000,224.400000000,10,1000,1,1,221.200000000,225.000000000,10,1,1,1,220.000000000,225.360000000,8,1,2,1,219.690000000,225.490000000,442,442,1,1,219.000000000,225.900000000,1,32,1,2,217.000000000,227.000000000,1525,35,1,1,215.000000000,229.330000000,5,9,1,2,213.000000000,233.670000000,5,5,1,1,212.340000000,234.000000000,5,20,1,1,210.000000000,234.750000000,6,50,2,1,AAPL
2024-11-01T08:00:14.204321367Z,2024-11-01T08:00:14.204155394Z,10,2,38,A,B,1,221.300000000,1000,130,165973,320299,221.700000000,224.400000000,10,1000,1,1,221.300000000,225.000000000,1000,1,1,1,221.200000000,225.360000000,10,1,1,1,220.000000000,225.490000000,8,442,2,1,219.690000000,225.900000000,442,32,1,2,219.000000000,227.000000000,1,35,1,1,217.000000000,229.330000000,1525,9,1,2,215.000000000,233.670000000,5,5,1,1,213.000000000,234.000000000,5,20,1,1,212.340000000,234.750000000,5,50,1,1,AAPL
2024-11-01T08:00:14.239148320Z,2024-11-01T08:00:14.238982209Z,10,2,16727,A,B,0,273.000000000,2,130,166111,320677,273.000000000,300.000000000,2,1,1,1,268.000000000,305.000000000,25,1,1,1,,,0,0,0,0,,,0,0,0,0,,,0,0,0,0,,,0,0,0,0,,,0,0,0,0,,,0,0,0,0,,,0,0,0,0,,,0,0,0,0,V
2024-11-01T08:00:14.263062898Z,2024-11-01T08:00:14.262896339Z,10,2,16727,A,A,0,295.000000000,5,130,166559,320728,273.000000000,295.000000000,2,5,1,1,268.000000000,300.000000000,25,1,1,1,,305.000000000,0,1,0,1,,,0,0,0,0,,,0,0,0,0,,,0,0,0,0,,,0,0,0,0,,,0,0,0,0,,,0,0,0,0,,,0,0,0,0,V
2024-11-01T08:00:14.268163964Z,2024-11-01T08:00:14.267997708Z,10,2,10888,A,A,6,445.000000000,2,130,166256,320759,410.000000000,414.000000000,31,468,2,2,409.750000000,415.070000000,3,246,1,1,409.740000000,415.350000000,500,84,1,2,409.670000000,419.860000000,100,10,1,1,409.430000000,420.000000000,5,3,1,1,409.250000000,440.000000000,2,35,1,1,409.080000000,445.000000000,2,27,1,2,409.000000000,445.680000000,3,3,2,1,408.970000000,448.000000000,12,15,1,2,408.960000000,450.000000000,5,48,1,3,MSFT
2024-11-01T08:00:14.337263072Z,2024-11-01T08:00:14.337096409Z,10,2,16727,A,B,0,275.000000000,2,130,166663,320986,275.000000000,295.000000000,2,5,1,1,273.000000000,300.000000000,2,1,1,1,268.000000000,305.000000000,25,1,1,1,,,0,0,0,0,,,0,0,0,0,,,0,0,0,0,,,0,0,0,0,,,0,0,0,0,,,0,0,0,0,,,0,0,0,0,V
2024-11-01T08:00:14.368303065Z,2024-11-01T08:00:14.368136838Z,10,2,16727,A,A,1,298.000000000,7,130,166227,321054,275.000000000,295.000000000,2,5,1,1,273.000000000,298.000000000,2,7,1,1,268.000000000,300.000000000,25,1,1,1,,305.000000000,0,1,0,1,,,0,0,0,0,,,0,0,0,0,,,0,0,0,0,,,0,0,0,0,,,0,0,0,0,,,0,0,0,0,V
2024-11-01T08:00:14.372789135Z,2024-11-01T08:00:14.372622693Z,10,2,16244,A,B,0,250.590000000,2,130,166442,321093,250.590000000,250.880000000,2,14,1,1,250.290000000,251.130000000,1,50,1,1,250.150000000,251.150000000,50,100,1,1,250.000000000,251.500000000,2,10,2,1,249.930000000,252.400000000,10,1000,1,1,249.880000000,253.350000000,4,23,1,1,249.850000000,253.650000000,4,400,1,1,249.800000000,254.990000000,199,5,1,1,249.770000000,255.000000000,50,105,1,3,249.500000000,258.000000000,1000,200,1,1,TSLA
2024-11-01T08:00:14.372951976Z,2024-11-01T08:00:14.372785914Z,10,2,16244,A,B,0,250.590000000,1,130,166062,321096,250.590000000,250.880000000,3,14,2,1,250.290000000,251.130000000,1,50,1,1,250.150000000,251.150000000,50,100,1,1,250.000000000,251.500000000,2,10,2,1,249.930000000,252.400000000,10,1000,1,1,249.880000000,253.350000000,4,23,1,1,249.850000000,253.650000000,4,400,1,1,249.800000000,254.990000000,199,5,1,1,249.770000000,255.000000000,50,105,1,3,249.500000000,258.000000000,1000,200,1,1,TSLA
2024-11-01T08:00:14.373237946Z,2024-11-01T08:00:14.373071835Z,10,2,16244,A,A,3,251.450000000,157,130,166111,321101,250.590000000,250.880000000,3,14,2,1,250.290000000,251.130000000,1,50,1,1,250.150000000,251.150000000,50,100,1,1,250.000000000,251.450000000,2,157,2,1,249.930000000,251.500000000,10,10,1,1,249.880000000,252.400000000,4,1000,1,1,249.850000000,253.350000000,4,23,1,1,249.800000000,253.650000000,199,400,1,1,249.770000000,254.990000000,50,5,1,1,249.500000000,255.000000000,1000,105,1,3,TSLA
2024-11-01T08:00:14.373786027Z,2024-11-01T08:00:14.373619762Z,10,2,16244,A,A,9,255.000000000,50,130,166265,321109,250.590000000,250.880000000,3,14,2,1,250.290000000,251.130000000,1,50,1,1,250.150000000,251.150000000,50,100,1,1,250.000000000,251.450000000,2,157,2,1,249.930000000,251.500000000,10,10,1,1,249.880000000,252.400000000,4,1000,1,1,249.850000000,253.350000000,4,23,1,1,249.800000000,253.650000000,199,400,1,1,249.770000000,254.990000000,50,5,1,1,249.500000000,255.000000000,1000,155,1,4,TSLA
2024-11-01T08:00:14.389979179Z,2024-11-01T08:00:14.389813052Z,10,2,38,A,B,0,221.700000000,14,130,166127,321190,221.700000000,224.400000000,24,1000,2,1,221.300000000,225.000000000,1000,1,1,1,221.200000000,225.360000000,10,1,1,1,220.000000000,225.490000000,8,442,2,1,219.690000000,225.900000000,442,32,1,2,219.000000000,227.000000000,1,35,1,1,217.000000000,229.330000000,1525,9,1,2,215.000000000,233.670000000,5,5,1,1,213.000000000,234.000000000,5,20,1,1,212.340000000,234.750000000,5,50,1,1,AAPL
2024-11-01T08:00:14.399904537Z,2024-11-01T08:00:14.399738320Z,10,2,12463,A,A,1,175.000000000,4,130,166217,321199,163.980000000,169.470000000,100,100,1,1,,175.000000000,0,4,0,1,,180.000000000,0,20,0,1,,,0,0,0,0,,,0,0,0,0,,,0,0,0,0,,,0,0,0,0,,,0,0,0,0,,,0,0,0,0,,,0,0,0,0,PEP
2024-11-01T08:00:14.421150070Z,2024-11-01T08:00:14.420983738Z,10,2,16244,A,A,9,255.000000000,5,130,166332,321243,250.590000000,250.880000000,3,14,2,1,250.290000000,251.130000000,1,50,1,1,250.150000000,251.150000000,50,100,1,1,250.000000000,251.450000000,2,157,2,1,249.930000000,251.500000000,10,10,1,1,249.880000000,252.400000000,4,1000,1,1,249.850000000,253.350000000,4,23,1,1,249.800000000,253.650000000,199,400,1,1,249.770000000,254.990000000,50,5,1,1,249.500000000,255.000000000,1000,160,1,5,TSLA
2024-11-01T08:00:14.422030836Z,2024-11-01T08:00:14.421864617Z,10,2,16244,A,A,3,251.450000000,217,130,166219,321257,250.590000000,250.880000000,3,14,2,1,250.290000000,251.130000000,1,50,1,1,250.150000000,251.150000000,50,100,1,1,250.000000000,251.450000000,2,374,2,2,249.930000000,251.500000000,10,10,1,1,249.880000000,252.400000000,4,1000,1,1,249.850000000,253.350000000,4,23,1,1,249.800000000,253.650000000,199,400,1,1,249.770000000,254.990000000,50,5,1,1,249.500000000,255.000000000,1000,160,1,5,TSLA
2024-11-01T08:00:14.452294541Z,2024-11-01T08:00:14.452128117Z,10,2,10888,A,A,9,449.970000000,30,130,166424,321286,410.000000000,414.000000000,31,468,2,2,409.750000000,415.070000000,3,246,1,1,409.740000000,415.350000000,500,84,1,2,409.670000000,419.860000000,100,10,1,1,409.430000000,420.000000000,5,3,1,1,409.250000000,440.000000000,2,35,1,1,409.080000000,445.000000000,2,27,1,2,409.000000000,445.680000000,3,3,2,1,408.970000000,448.000000000,12,15,1,2,408.960000000,449.970000000,5,30,1,1,MSFT
2024-11-01T08:00:14.474154694Z,2024-11-01T08:00:14.473988644Z,10,2,16244,A,B,0,250.590000000,4,130,166050,321323,250.590000000,250.880000000,7,14,3,1,250.290000000,251.130000000,1,50,1,1,250.150000000,251.150000000,50,100,1,1,250.000000000,251.450000000,2,374,2,2,249.930000000,251.500000000,10,10,1,1,249.880000000,252.400000000,4,1000,1,1,249.850000000,253.350000000,4,23,1,1,249.800000000,253.650000000,199,400,1,1,249.770000000,254.990000000,50,5,1,1,249.500000000,255.000000000,1000,160,1,5,TSLA
2024-11-01T08:00:14.475259273Z,2024-11-01T08:00:14.475093049Z,10,2,16244,A,A,8,253.880000000,8,130,166224,321336,250.590000000,250.880000000,7,14,3,1,250.290000000,251.130000000,1,50,1,1,250.150000000,251.150000000,50,100,1,1,250.000000000,251.450000000,2,374,2,2,249.930000000,251.500000000,10,10,1,1,249.880000000,252.400000000,4,1000,1,1,249.850000000,253.350000000,4,23,1,1,249.800000000,253.650000000,199,400,1,1,249.770000000,253.880000000,50,8,1,1,249.500000000,254.990000000,1000,5,1,1,TSLA
2024-11-01T08:00:14.480435975Z,2024-11-01T08:00:14.480269714Z,10,2,10888,A,A,0,413.000000000,20,130,166261,321390,410.000000000,413.000000000,31,20,2,1,409.750000000,414.000000000,3,468,1,2,409.740000000,415.070000000,500,246,1,1,409.670000000,415.350000000,100,84,1,2,409.430000000,419.860000000,5,10,1,1,409.250000000,420.000000000,2,3,1,1,409.080000000,440.000000000,2,35,1,1,409.000000000,445.000000000,3,27,2,2,408.970000000,445.680000000,12,3,1,1,408.960000000,448.000000000,5,15,1,2,MSFT
2024-11-01T08:00:14.480656467Z,2024-11-01T08:00:14.480490127Z,10,2,10888,A,A,3,415.290000000,34,130,166340,321394,410.000000000,413.000000000,31,20,2,1,409.750000000,414.000000000,3,468,1,2,409.740000000,415.070000000,500,246,1,1,409.670000000,415.290000000,100,34,1,1,409.430000000,415.350000000,5,84,1,2,409.250000000,419.860000000,2,10,1,1,409.080000000,420.000000000,2,3,1,1,409.000000000,440.000000000,3,35,2,1,408.970000000,445.000000000,12,27,1,2,408.960000000,445.680000000,5,3,1,1,MSFT
2024-11-01T08:00:14.496381540Z,2024-11-01T08:00:14.496215309Z,10,2,38,A,B,7,215.000000000,5,130,166231,321443,221.700000000,224.400000000,24,1000,2,1,221.300000000,225.000000000,1000,1,1,1,221.200000000,225.360000000,10,1,1,1,220.000000000,225.490000000,8,442,2,1,219.690000000,225.900000000,442,32,1,2,219.000000000,227.000000000,1,35,1,1,217.000000000,229.330000000,1525,9,1,2,215.000000000,233.670000000,10,5,2,1,213.000000000,234.000000000,5,20,1,1,212.340000000,234.750000000,5,50,1,1,AAPL
2024-11-01T08:00:14.500711884Z,2024-11-01T08:00:14.500545397Z,10,2,38,A,A,0,223.000000000,90,130,166487,321451,221.700000000,223.000000000,24,90,2,1,221.300000000,224.400000000,1000,1000,1,1,221.200000000,225.000000000,10,1,1,1,220.000000000,225.360000000,8,1,2,1,219.690000000,225.490000000,442,442,1,1,219.000000000,225.900000000,1,32,1,2,217.000000000,227.000000000,1525,35,1,1,215.000000000,229.330000000,10,9,2,2,213.000000000,233.670000000,5,5,1,1,212.340000000,234.000000000,5,20,1,1,AAPL
2024-11-01T08:00:14.557536036Z,2024-11-01T08:00:14.557369854Z,10,2,10888,A,A,7,440.000000000,630,130,166182,321552,410.000000000,413.000000000,31,20,2,1,409.750000000,414.000000000,3,468,1,2,409.740000000,415.070000000,500,246,1,1,409.670000000,415.290000000,100,34,1,1,409.430000000,415.350000000,5,84,1,2,409.250000000,419.860000000,2,10,1,1,409.080000000,420.000000000,2,3,1,1,409.000000000,440.000000000,3,665,2,2,408.970000000,445.000000000,12,27,1,2,408.960000000,445.680000000,5,3,1,1,MSFT
2024-11-01T08:00:14.558418220Z,2024-11-01T08:00:14.558251663Z,10,2,10888,A,A,7,435.000000000,1,130,166557,321564,410.000000000,413.000000000,31,20,2,1,409.750000000,414.000000000,3,468,1,2,409.740000000,415.070000000,500,246,1,1,409.670000000,415.290000000,100,34,1,1,409.430000000,415.350000000,5,84,1,2,409.250000000,419.860000000,2,10,1,1,409.080000000,420.000000000,2,3,1,1,409.000000000,435.000000000,3,1,2,1,408.970000000,440.000000000,12,665,1,2,408.960000000,445.000000000,5,27,1,2,MSFT
2024-11-01T08:00:14.558905587Z,2024-11-01T08:00:14.558739383Z,10,2,10888,A,A,7,430.000000000,5,130,166204,321568,410.000000000,413.000000000,31,20,2,1,409.750000000,414.000000000,3,468,1,2,409.740000000,415.070000000,500,246,1,1,409.670000000,415.290000000,100,34,1,1,409.430000000,415.350000000,5,84,1,2,409.250000000,419.860000000,2,10,1,1,409.080000000,420.000000000,2,3,1,1,409.000000000,430.000000000,3,5,2,1,408.970000000,435.000000000,12,1,1,1,408.960000000,440.000000000,5,665,1,2,MSFT
2024-11-01T08:00:14.559050499Z,2024-11-01T08:00:14.558884326Z,10,2,10888,A,A,7,425.000000000,50,130,166173,321570,410.000000000,413.000000000,31,20,2,1,409.750000000,414.000000000,3,468,1,2,409.740000000,415.070000000,500,246,1,1,409.670000000,415.290000000,100,34,1,1,409.430000000,415.350000000,5,84,1,2,409.250000000,419.860000000,2,10,1,1,409.080000000,420.000000000,2,3,1,1,409.000000000,425.000000000,3,50,2,1,408.970000000,430.000000000,12,5,1,1,408.960000000,435.000000000,5,1,1,1,MSFT
2024-11-01T08:00:14.559367322Z,2024-11-01T08:00:14.559201061Z,10,2,10888,A,A,9,435.000000000,1,130,166261,321574,410.000000000,413.000000000,31,20,2,1,409.750000000,414.000000000,3,468,1,2,409.740000000,415.070000000,500,246,1,1,409.670000000,415.290000000,100,34,1,1,409.430000000,415.350000000,5,84,1,2,409.250000000,419.860000000,2,10,1,1,409.080000000,420.000000000,2,3,1,1,409.000000000,425.000000000,3,50,2,1,408.970000000,430.000000000,12,5,1,1,408.960000000,435.000000000,5,2,1,2,MSFT
2024-11-01T08:00:14.561172921Z,2024-11-01T08:00:14.561006642Z,10,2,16244,A,B,2,250.150000000,50,130,166279,321582,250.590000000,250.880000000,7,14,3,1,250.290000000,251.130000000,1,50,1,1,250.150000000,251.150000000,100,100,2,1,250.000000000,251.450000000,2,374,2,2,249.930000000,251.500000000,10,10,1,1,249.880000000,252.400000000,4,1000,1,1,249.850000000,253.350000000,4,23,1,1,249.800000000,253.650000000,199,400,1,1,249.770000000,253.880000000,50,8,1,1,249.500000000,254.990000000,1000,5,1,1,TSLA
2024-11-01T08:00:14.602015068Z,2024-11-01T08:00:14.601848870Z,10,2,38,A,B,4,219.960000000,4,130,166198,321678,221.700000000,223.000000000,24,90,2,1,221.300000000,224.400000000,1000,1000,1,1,221.200000000,225.000000000,10,1,1,1,220.000000000,225.360000000,8,1,2,1,219.960000000,225.490000000,4,442,1,1,219.690000000,225.900000000,442,32,1,2,219.000000000,227.000000000,1,35,1,1,217.000000000,229.330000000,1525,9,1,2,215.000000000,233.670000000,10,5,2,1,213.000000000,234.000000000,5,20,1,1,AAPL
2024-11-01T08:00:14.609094522Z,2024-11-01T08:00:14.608928632Z,10,2,16244,C,B,1,250.290000000,1,130,165890,321698,250.590000000,250.880000000,7,14,3,1,250.150000000,251.130000000,100,50,2,1,250.000000000,251.150000000,2,100,2,1,249.930000000,251.450000000,10,374,1,2,249.880000000,251.500000000,4,10,1,1,249.850000000,252.400000000,4,1000,1,1,249.800000000,253.350000000,199,23,1,1,249.770000000,253.650000000,50,400,1,1,249.500000000,253.880000000,1000,8,1,1,249.010000000,254.990000000,3,5,1,1,TSLA
2024-11-01T08:00:14.663031535Z,2024-11-01T08:00:14.662865164Z,10,2,10888,A,B,6,409.220000000,22,130,166371,321878,410.000000000,413.000000000,31,20,2,1,409.750000000,414.000000000,3,468,1,2,409.740000000,415.070000000,500,246,1,1,409.670000000,415.290000000,100,34,1,1,409.430000000,415.350000000,5,84,1,2,409.250000000,419.860000000,2,10,1,1,409.220000000,420.000000000,22,3,1,1,409.080000000,425.000000000,2,50,1,1,409.000000000,430.000000000,3,5,2,1,408.970000000,435.000000000,12,2,1,2,MSFT
2024-11-01T08:00:14.683704535Z,2024-11-01T08:00:14.683538439Z,10,2,17709,A,B,2,101.000000000,10,130,166096,322011,116.000000000,118.600000000,100,100,1,1,115.290000000,125.000000000,100,30,1,1,101.000000000,9900.000000000,10,11,1,1,,,0,0,0,0,,,0,0,0,0,,,0,0,0,0,,,0,0,0,0,,,0,0,0,0,,,0,0,0,0,,,0,0,0,0,XOM
2024-11-01T08:00:14.700697929Z,2024-11-01T08:00:14.700522417Z,10,2,38,A,A,2,224.520000000,100,130,175512,322078,221.700000000,223.000000000,24,90,2,1,221.300000000,224.400000000,1000,1000,1,1,221.200000000,224.520000000,10,100,1,1,220.000000000,225.000000000,8,1,2,1,219.960000000,225.360000000,4,1,1,1,219.690000000,225.490000000,442,442,1,1,219.000000000,225.900000000,1,32,1,2,217.000000000,227.000000000,1525,35,1,1,215.000000000,229.330000000,10,9,2,2,213.000000000,233.670000000,5,5,1,1,AAPL
2024-11-01T08:00:14.700751383Z,2024-11-01T08:00:14.700585164Z,10,2,38,A,B,9,214.380000000,27,130,166219,322079,221.700000000,223.000000000,24,90,2,1,221.300000000,224.400000000,1000,1000,1,1,221.200000000,224.520000000,10,100,1,1,220.000000000,225.000000000,8,1,2,1,219.960000000,225.360000000,4,1,1,1,219.690000000,225.490000000,442,442,1,1,219.000000000,225.900000000,1,32,1,2,217.000000000,227.000000000,1525,35,1,1,215.000000000,229.330000000,10,9,2,2,214.380000000,233.670000000,27,5,1,1,AAPL
2024-11-01T08:00:14.737892197Z,2024-11-01T08:00:14.737725942Z,10,2,16244,A,A,0,250.790000000,200,130,166255,322141,250.590000000,250.790000000,7,200,3,1,250.150000000,250.880000000,100,14,2,1,250.000000000,251.130000000,2,50,2,1,249.930000000,251.150000000,10,100,1,1,249.880000000,251.450000000,4,374,1,2,249.850000000,251.500000000,4,10,1,1,249.800000000,252.400000000,199,1000,1,1,249.770000000,253.350000000,50,23,1,1,249.500000000,253.650000000,1000,400,1,1,249.010000000,253.880000000,3,8,1,1,TSLA
2024-11-01T08:00:14.746954322Z,2024-11-01T08:00:14.746786698Z,10,2,11667,T,A,0,134.930000000,5,130,167624,322150,134.930000000,134.990000000,239,10,1,1,134.830000000,135.000000000,100,38,1,3,134.500000000,135.100000000,520,10,2,1,134.410000000,135.230000000,61,360,2,1,134.380000000,135.300000000,18,1009,1,2,134.210000000,135.400000000,20,10,1,1,134.200000000,135.420000000,3,1,1,1,134.000000000,135.820000000,1,1,1,1,133.800000000,135.910000000,5,100,1,1,133.160000000,135.990000000,1,20,1,1,NVDA
2024-11-01T08:00:14.746954322Z,2024-11-01T08:00:14.746786698Z,10,2,11667,C,B,0,134.930000000,5,130,167624,322150,134.930000000,134.990000000,234,10,1,1,134.830000000,135.000000000,100,38,1,3,134.500000000,135.100000000,520,10,2,1,134.410000000,135.230000000,61,360,2,1,134.380000000,135.300000000,18,1009,1,2,134.210000000,135.400000000,20,10,1,1,134.200000000,135.420000000,3,1,1,1,134.000000000,135.820000000,1,1,1,1,133.800000000,135.910000000,5,100,1,1,133.160000000,135.990000000,1,20,1,1,NVDA
2024-11-01T08:00:14.749487202Z,2024-11-01T08:00:14.749320310Z,10,2,16244,A,A,4,251.400000000,1000,130,166892,322153,250.590000000,250.790000000,7,200,3,1,250.150000000,250.880000000,100,14,2,1,250.000000000,251.130000000,2,50,2,1,249.930000000,251.150000000,10,100,1,1,249.880000000,251.400000000,4,1000,1,1,249.850000000,251.450000000,4,374,1,2,249.800000000,251.500000000,199,10,1,1,249.770000000,252.400000000,50,1000,1,1,249.500000000,253.350000000,1000,23,1,1,249.010000000,253.650000000,3,400,1,1,TSLA
2024-11-01T08:00:14.749537643Z,2024-11-01T08:00:14.749371488Z,10,2,16244,C,A,7,252.400000000,1000,130,166155,322154,250.590000000,250.790000000,7,200,3,1,250.150000000,250.880000000,100,14,2,1,250.000000000,251.130000000,2,50,2,1,249.930000000,251.150000000,10,100,1,1,249.880000000,251.400000000,4,1000,1,1,249.850000000,251.450000000,4,374,1,2,249.800000000,251.500000000,199,10,1,1,249.770000000,253.350000000,50,23,1,1,249.500000000,253.650000000,1000,400,1,1,249.010000000,253.880000000,3,8,1,1,TSLA
2024-11-01T08:00:14.768424321Z,2024-11-01T08:00:14.768258475Z,10,2,16244,C,A,4,251.400000000,1000,130,165846,322175,250.590000000,250.790000000,7,200,3,1,250.150000000,250.880000000,100,14,2,1,250.000000000,251.130000000,2,50,2,1,249.930000000,251.150000000,10,100,1,1,249.880000000,251.450000000,4,374,1,2,249.850000000,251.500000000,4,10,1,1,249.800000000,253.350000000,199,23,1,1,249.770000000,253.650000000,50,400,1,1,249.500000000,253.880000000,1000,8,1,1,249.010000000,254.990000000,3,5,1,1,TSLA
2024-11-01T08:00:14.779854583Z,2024-11-01T08:00:14.779688487Z,10,2,16244,A,A,6,252.100000000,1000,130,166096,322200,250.590000000,250.790000000,7,200,3,1,250.150000000,250.880000000,100,14,2,1,250.000000000,251.130000000,2,50,2,1,249.930000000,251.150000000,10,100,1,1,249.880000000,251.450000000,4,374,1,2,249.850000000,251.500000000,4,10,1,1,249.800000000,252.100000000,199,1000,1,1,249.770000000,253.350000000,50,23,1,1,249.500000000,253.650000000,1000,400,1,1,249.010000000,253.880000000,3,8,1,1,TSLA
2024-11-01T08:00:14.780606166Z,2024-11-01T08:00:14.780439656Z,10,2,16244,A,A,3,251.150000000,100,130,166510,322202,250.590000000,250.790000000,7,200,3,1,250.150000000,250.880000000,100,14,2,1,250.000000000,251.130000000,2,50,2,1,249.930000000,251.150000000,10,200,1,2,249.880000000,251.450000000,4,374,1,2,249.850000000,251.500000000,4,10,1,1,249.800000000,252.100000000,199,1000,1,1,249.770000000,253.350000000,50,23,1,1,249.500000000,253.650000000,1000,400,1,1,249.010000000,253.880000000,3,8,1,1,TSLA
2024-11-01T08:00:14.797344069Z,2024-11-01T08:00:14.797177638Z,10,2,9155,A,B,4,200.000000000,2,130,166431,322229,221.850000000,224.940000000,3,450,1,1,220.000000000,226.800000000,3,100,1,1,219.160000000,,450,0,1,0,218.080000000,,100,0,1,0,200.000000000,,2,0,1,0,,,0,0,0,0,,,0,0,0,0,,,0,0,0,0,,,0,0,0,0,,,0,0,0,0,JPM
2024-11-01T08:00:14.800331271Z,2024-11-01T08:00:14.800165481Z,10,2,16244,C,A,6,252.100000000,1000,130,165790,322237,250.590000000,250.790000000,7,200,3,1,250.150000000,250.880000000,100,14,2,1,250.000000000,251.130000000,2,50,2,1,249.930000000,251.150000000,10,200,1,2,249.880000000,251.450000000,4,374,1,2,249.850000000,251.500000000,4,10,1,1,249.800000000,253.350000000,199,23,1,1,249.770000000,253.650000000,50,400,1,1,249.500000000,253.880000000,1000,8,1,1,249.010000000,254.990000000,3,5,1,1,TSLA
2024-11-01T08:00:14.811830976Z,2024-11-01T08:00:14.811664676Z,10,2,16244,A,A,6,252.300000000,1000,130,166300,322246,250.590000000,250.790000000,7,200,3,1,250.150000000,250.880000000,100,14,2,1,250.000000000,251.130000000,2,50,2,1,249.930000000,251.150000000,10,200,1,2,249.880000000,251.450000000,4,374,1,2,249.850000000,251.500000000,4,10,1,1,249.800000000,252.300000000,199,1000,1,1,249.770000000,253.350000000,50,23,1,1,249.500000000,253.650000000,1000,400,1,1,249.010000000,253.880000000,3,8,1,1,TSLA
2024-11-01T08:00:14.845725995Z,2024-11-01T08:00:14.845560224Z,10,2,16244,C,A,3,251.150000000,100,130,165771,322335,250.590000000,250.790000000,7,200,3,1,250.150000000,250.880000000,100,14,2,1,250.000000000,251.130000000,2,50,2,1,249.930000000,251.150000000,10,100,1,1,249.880000000,251.450000000,4,374,1,2,249.850000000,251.500000000,4,10,1,1,249.800000000,252.300000000,199,1000,1,1,249.770000000,253.350000000,50,23,1,1,249.500000000,253.650000000,1000,400,1,1,249.010000000,253.880000000,3,8,1,1,TSLA
2024-11-01T08:00:14.845743247Z,2024-11-01T08:00:14.845576901Z,10,2,16244,A,A,2,250.940000000,100,130,166346,322336,250.590000000,250.790000000,7,200,3,1,250.150000000,250.880000000,100,14,2,1,250.000000000,250.940000000,2,100,2,1,249.930000000,251.130000000,10,50,1,1,249.880000000,251.450000000,4,374,1,2,249.850000000,251.500000000,4,10,1,1,249.800000000,252.300000000,199,1000,1,1,249.770000000,253.350000000,50,23,1,1,249.500000000,253.650000000,1000,400,1,1,249.010000000,253.880000000,3,8,1,1,TSLA
2024-11-01T08:00:14.982454469Z,2024-11-01T08:00:14.982288003Z,10,2,16244,A,A,3,251.130000000,50,130,166466,322620,250.590000000,250.790000000,7,200,3,1,250.150000000,250.880000000,100,14,2,1,250.000000000,250.940000000,2,100,2,1,249.930000000,251.130000000,10,100,1,2,249.880000000,251.450000000,4,374,1,2,249.850000000,251.500000000,4,10,1,1,249.800000000,252.300000000,199,1000,1,1,249.770000000,253.350000000,50,23,1,1,249.500000000,253.650000000,1000,400,1,1,249.010000000,253.880000000,3,8,1,1,TSLA
2024-11-01T08:00:14.982571709Z,2024-11-01T08:00:14.982405684Z,10,2,16244,C,B,1,250.150000000,50,130,166025,322621,250.590000000,250.790000000,7,200,3,1,250.150000000,250.880000000,50,14,1,1,250.000000000,250.940000000,2,100,2,1,249.930000000,251.130000000,10,100,1,2,249.880000000,251.450000000,4,374,1,2,249.850000000,251.500000000,4,10,1,1,249.800000000,252.300000000,199,1000,1,1,249.770000000,253.350000000,50,23,1,1,249.500000000,253.650000000,1000,400,1,1,249.010000000,253.880000000,3,8,1,1,TSLA
2024-11-01T08:00:15.037297016Z,2024-11-01T08:00:15.037131293Z,10,2,16244,C,A,3,251.130000000,50,130,165723,322673,250.590000000,250.790000000,7,200,3,1,250.150000000,250.880000000,50,14,1,1,250.000000000,250.940000000,2,100,2,1,249.930000000,251.130000000,10,50,1,1,249.880000000,251.450000000,4,374,1,2,249.850000000,251.500000000,4,10,1,1,249.800000000,252.300000000,199,1000,1,1,249.770000000,253.350000000,50,23,1,1,249.500000000,253.650000000,1000,400,1,1,249.010000000,253.880000000,3,8,1,1,TSLA
2024-11-01T08:00:15.037311818Z,2024-11-01T08:00:15.037145518Z,10,2,16244,A,A,3,251.080000000,100,130,166300,322674,250.590000000,250.790000000,7,200,3,1,250.150000000,250.880000000,50,14,1,1,250.000000000,250.940000000,2,100,2,1,249.930000000,251.080000000,10,100,1,1,249.880000000,251.450000000,4,374,1,2,249.850000000,251.500000000,4,10,1,1,249.800000000,252.300000000,199,1000,1,1,249.770000000,253.350000000,50,23,1,1,249.500000000,253.650000000,1000,400,1,1,249.010000000,253.880000000,3,8,1,1,TSLA
2024-11-01T08:00:15.050462920Z,2024-11-01T08:00:15.050297076Z,10,2,16244,C,A,3,251.080000000,100,130,165844,322689,250.590000000,250.790000000,7,200,3,1,250.150000000,250.880000000,50,14,1,1,250.000000000,250.940000000,2,100,2,1,249.930000000,251.450000000,10,374,1,2,249.880000000,251.500000000,4,10,1,1,249.850000000,252.300000000,4,1000,1,1,249.800000000,253.350000000,199,23,1,1,249.770000000,253.650000000,50,400,1,1,249.500000000,253.880000000,1000,8,1,1,249.010000000,254.990000000,3,5,1,1,TSLA
2024-11-01T08:00:15.050476834Z,2024-11-01T08:00:15.050310498Z,10,2,16244,A,A,3,251.100000000,100,130,166336,322690,250.590000000,250.790000000,7,200,3,1,250.150000000,250.880000000,50,14,1,1,250.000000000,250.940000000,2,100,2,1,249.930000000,251.100000000,10,100,1,1,249.880000000,251.450000000,4,374,1,2,249.850000000,251.500000000,4,10,1,1,249.800000000,252.300000000,199,1000,1,1,249.770000000,253.350000000,50,23,1,1,249.500000000,253.650000000,1000,400,1,1,249.010000000,253.880000000,3,8,1,1,TSLA
2024-11-01T08:00:15.076061217Z,2024-11-01T08:00:15.075894968Z,10,2,38,A,A,9,231.750000000,7,130,166249,322720,221.700000000,223.000000000,24,90,2,1,221.300000000,224.400000000,1000,1000,1,1,221.200000000,224.520000000,10,100,1,1,220.000000000,225.000000000,8,1,2,1,219.960000000,225.360000000,4,1,1,1,219.690000000,225.490000000,442,442,1,1,219.000000000,225.900000000,1,32,1,2,217.000000000,227.000000000,1525,35,1,1,215.000000000,229.330000000,10,9,2,2,214.380000000,231.750000000,27,7,1,1,AAPL
2024-11-01T08:00:15.103636017Z,2024-11-01T08:00:15.103468390Z,10,2,16244,A,A,3,251.090000000,100,130,167627,322741,250.590000000,250.790000000,7,200,3,1,250.150000000,250.880000000,50,14,1,1,250.000000000,250.940000000,2,100,2,1,249.930000000,251.090000000,10,100,1,1,249.880000000,251.450000000,4,374,1,2,249.850000000,251.500000000,4,10,1,1,249.800000000,252.300000000,199,1000,1,1,249.770000000,253.350000000,50,23,1,1,249.500000000,253.650000000,1000,400,1,1,249.010000000,253.880000000,3,8,1,1,TSLA
2024-11-01T08:00:15.148864309Z,2024-11-01T08:00:15.148697998Z,10,2,11667,A,B,1,134.870000000,228,130,166311,323049,134.930000000,134.990000000,234,10,1,1,134.870000000,135.000000000,228,38,1,3,134.830000000,135.100000000,100,10,1,1,134.500000000,135.230000000,520,360,2,1,134.410000000,135.300000000,61,1009,2,2,134.380000000,135.400000000,18,10,1,1,134.210000000,135.420000000,20,1,1,1,134.200000000,135.820000000,3,1,1,1,134.000000000,135.910000000,1,100,1,1,133.800000000,135.990000000,5,20,1,1,NVDA
2024-11-01T08:00:15.149079905Z,2024-11-01T08:00:15.148913092Z,10,2,11667,T,A,0,134.930000000,100,130,166813,323050,134.930000000,134.990000000,234,10,1,1,134.870000000,135.000000000,228,38,1,3,134.830000000,135.100000000,100,10,1,1,134.500000000,135.230000000,520,360,2,1,134.410000000,135.300000000,61,1009,2,2,134.380000000,135.400000000,18,10,1,1,134.210000000,135.420000000,20,1,1,1,134.200000000,135.820000000,3,1,1,1,134.000000000,135.910000000,1,100,1,1,133.800000000,135.990000000,5,20,1,1,NVDA
2024-11-01T08:00:15.149079905Z,2024-11-01T08:00:15.148913092Z,10,2,11667,C,B,0,134.930000000,100,130,166813,323050,134.930000000,134.990000000,134,10,1,1,134.870000000,135.000000000,228,38,1,3,134.830000000,135.100000000,100,10,1,1,134.500000000,135.230000000,520,360,2,1,134.410000000,135.300000000,61,1009,2,2,134.380000000,135.400000000,18,10,1,1,134.210000000,135.420000000,20,1,1,1,134.200000000,135.820000000,3,1,1,1,134.000000000,135.910000000,1,100,1,1,133.800000000,135.990000000,5,20,1,1,NVDA
2024-11-01T08:00:15.149297735Z,2024-11-01T08:00:15.149131189Z,10,2,11667,T,A,0,134.930000000,13,130,166546,323052,134.930000000,134.990000000,134,10,1,1,134.870000000,135.000000000,228,38,1,3,134.830000000,135.100000000,100,10,1,1,134.500000000,135.230000000,520,360,2,1,134.410000000,135.300000000,61,1009,2,2,134.380000000,135.400000000,18,10,1,1,134.210000000,135.420000000,20,1,1,1,134.200000000,135.820000000,3,1,1,1,134.000000000,135.910000000,1,100,1,1,133.800000000,135.990000000,5,20,1,1,NVDA
2024-11-01T08:00:15.149297735Z,2024-11-01T08:00:15.149131189Z,10,2,11667,C,B,0,134.930000000,13,130,166546,323052,134.930000000,134.990000000,121,10,1,1,134.870000000,135.000000000,228,38,1,3,134.830000000,135.100000000,100,10,1,1,134.500000000,135.230000000,520,360,2,1,134.410000000,135.300000000,61,1009,2,2,134.380000000,135.400000000,18,10,1,1,134.210000000,135.420000000,20,1,1,1,134.200000000,135.820000000,3,1,1,1,134.000000000,135.910000000,1,100,1,1,133.800000000,135.990000000,5,20,1,1,NVDA
2024-11-01T08:00:15.149398661Z,2024-11-01T08:00:15.149232547Z,10,2,11667,C,B,2,134.830000000,100,130,166114,323055,134.930000000,134.990000000,121,10,1,1,134.870000000,135.000000000,228,38,1,3,134.500000000,135.100000000,520,10,2,1,134.410000000,135.230000000,61,360,2,1,134.380000000,135.300000000,18,1009,1,2,134.210000000,135.400000000,20,10,1,1,134.200000000,135.420000000,3,1,1,1,134.000000000,135.820000000,1,1,1,1,133.800000000,135.910000000,5,100,1,1,133.160000000,135.990000000,1,20,1,1,NVDA
2024-11-01T08:00:15.149500293Z,2024-11-01T08:00:15.149333262Z,10,2,11667,T,A,0,134.930000000,13,130,167031,323056,134.930000000,134.990000000,121,10,1,1,134.870000000,135.000000000,228,38,1,3,134.500000000,135.100000000,520,10,2,1,134.410000000,135.230000000,61,360,2,1,134.380000000,135.300000000,18,1009,1,2,134.210000000,135.400000000,20,10,1,1,134.200000000,135.420000000,3,1,1,1,134.000000000,135.820000000,1,1,1,1,133.800000000,135.910000000,5,100,1,1,133.160000000,135.990000000,1,20,1,1,NVDA
2024-11-01T08:00:15.149500293Z,2024-11-01T08:00:15.149333262Z,10,2,11667,C,B,0,134.930000000,13,130,167031,323056,134.930000000,134.990000000,108,10,1,1,134.870000000,135.000000000,228,38,1,3,134.500000000,135.100000000,520,10,2,1,134.410000000,135.230000000,61,360,2,1,134.380000000,135.300000000,18,1009,1,2,134.210000000,135.400000000,20,10,1,1,134.200000000,135.420000000,3,1,1,1,134.000000000,135.820000000,1,1,1,1,133.800000000,135.910000000,5,100,1,1,133.160000000,135.990000000,1,20,1,1,NVDA
2024-11-01T08:00:15.149532663Z,2024-11-01T08:00:15.149365932Z,10,2,11667,T,A,0,134.930000000,2,130,166731,323057,134.930000000,134.990000000,108,10,1,1,134.870000000,135.000000000,228,38,1,3,134.500000000,135.100000000,520,10,2,1,134.410000000,135.230000000,61,360,2,1,134.380000000,135.300000000,18,1009,1,2,134.210000000,135.400000000,20,10,1,1,134.200000000,135.420000000,3,1,1,1,134.000000000,135.820000000,1,1,1,1,133.800000000,135.910000000,5,100,1,1,133.160000000,135.990000000,1,20,1,1,NVDA
2024-11-01T08:00:15.149532663Z,2024-11-01T08:00:15.149365932Z,10,2,11667,C,B,0,134.930000000,2,130,166731,323057,134.930000000,134.990000000,106,10,1,1,134.870000000,135.000000000,228,38,1,3,134.500000000,135.100000000,520,10,2,1,134.410000000,135.230000000,61,360,2,1,134.380000000,135.300000000,18,1009,1,2,134.210000000,135.400000000,20,10,1,1,134.200000000,135.420000000,3,1,1,1,134.000000000,135.820000000,1,1,1,1,133.800000000,135.910000000,5,100,1,1,133.160000000,135.990000000,1,20,1,1,NVDA
2024-11-01T08:00:15.149715120Z,2024-11-01T08:00:15.149548296Z,10,2,11667,T,A,0,134.930000000,2,130,166824,323059,134.930000000,134.990000000,106,10,1,1,134.870000000,135.000000000,228,38,1,3,134.500000000,135.100000000,520,10,2,1,134.410000000,135.230000000,61,360,2,1,134.380000000,135.300000000,18,1009,1,2,134.210000000,135.400000000,20,10,1,1,134.200000000,135.420000000,3,1,1,1,134.000000000,135.820000000,1,1,1,1,133.800000000,135.910000000,5,100,1,1,133.160000000,135.990000000,1,20,1,1,NVDA
2024-11-01T08:00:15.149715120Z,2024-11-01T08:00:15.149548296Z,10,2,11667,C,B,0,134.930000000,2,130,166824,323059,134.930000000,134.990000000,104,10,1,1,134.870000000,135.000000000,228,38,1,3,134.500000000,135.100000000,520,10,2,1,134.410000000,135.230000000,61,360,2,1,134.380000000,135.300000000,18,1009,1,2,134.210000000,135.400000000,20,10,1,1,134.200000000,135.420000000,3,1,1,1,134.000000000,135.820000000,1,1,1,1,133.800000000,135.910000000,5,100,1,1,133.160000000,135.990000000,1,20,1,1,NVDA
2024-11-01T08:00:15.149745215Z,2024-11-01T08:00:15.149578504Z,10,2,11667,T,A,0,134.930000000,2,130,166711,323060,134.930000000,134.990000000,104,10,1,1,134.870000000,135.000000000,228,38,1,3,134.500000000,135.100000000,520,10,2,1,134.410000000,135.230000000,61,360,2,1,134.380000000,135.300000000,18,1009,1,2,134.210000000,135.400000000,20,10,1,1,134.200000000,135.420000000,3,1,1,1,134.000000000,135.820000000,1,1,1,1,133.800000000,135.910000000,5,100,1,1,133.160000000,135.990000000,1,20,1,1,NVDA
2024-11-01T08:00:15.149745215Z,2024-11-01T08:00:15.149578504Z,10,2,11667,C,B,0,134.930000000,2,130,166711,323060,134.930000000,134.990000000,102,10,1,1,134.870000000,135.000000000,228,38,1,3,134.500000000,135.100000000,520,10,2,1,134.410000000,135.230000000,61,360,2,1,134.380000000,135.300000000,18,1009,1,2,134.210000000,135.400000000,20,10,1,1,134.200000000,135.420000000,3,1,1,1,134.000000000,135.820000000,1,1,1,1,133.800000000,135.910000000,5,100,1,1,133.160000000,135.990000000,1,20,1,1,NVDA
2024-11-01T08:00:15.149824160Z,2024-11-01T08:00:15.149658187Z,10,2,11667,A,B,2,134.850000000,300,130,165973,323062,134.930000000,134.990000000,102,10,1,1,134.870000000,135.000000000,228,38,1,3,134.850000000,135.100000000,300,10,1,1,134.500000000,135.230000000,520,360,2,1,134.410000000,135.300000000,61,1009,2,2,134.380000000,135.400000000,18,10,1,1,134.210000000,135.420000000,20,1,1,1,134.200000000,135.820000000,3,1,1,1,134.000000000,135.910000000,1,100,1,1,133.800000000,135.990000000,5,20,1,1,NVDA
2024-11-01T08:00:15.149931415Z,2024-11-01T08:00:15.149764485Z,10,2,11667,T,A,0,134.930000000,1,130,166930,323063,134.930000000,134.990000000,102,10,1,1,134.870000000,135.000000000,228,38,1,3,134.850000000,135.100000000,300,10,1,1,134.500000000,135.230000000,520,360,2,1,134.410000000,135.300000000,61,1009,2,2,134.380000000,135.400000000,18,10,1,1,134.210000000,135.420000000,20,1,1,1,134.200000000,135.820000000,3,1,1,1,134.000000000,135.910000000,1,100,1,1,133.800000000,135.990000000,5,20,1,1,NVDA
2024-11-01T08:00:15.149931415Z,2024-11-01T08:00:15.149764485Z,10,2,11667,C,B,0,134.930000000,1,130,166930,323063,134.930000000,134.990000000,101,10,1,1,134.870000000,135.000000000,228,38,1,3,134.850000000,135.100000000,300,10,1,1,134.500000000,135.230000000,520,360,2,1,134.410000000,135.300000000,61,1009,2,2,134.380000000,135.400000000,18,10,1,1,134.210000000,135.420000000,20,1,1,1,134.200000000,135.820000000,3,1,1,1,134.000000000,135.910000000,1,100,1,1,133.800000000,135.990000000,5,20,1,1,NVDA
2024-11-01T08:00:15.150664916Z,2024-11-01T08:00:15.150498714Z,10,2,11667,A,B,3,134.800000000,400,130,166202,323068,134.930000000,134.990000000,101,10,1,1,134.870000000,135.000000000,228,38,1,3,134.850000000,135.100000000,300,10,1,1,134.800000000,135.230000000,400,360,1,1,134.500000000,135.300000000,520,1009,2,2,134.410000000,135.400000000,61,10,2,1,134.380000000,135.420000000,18,1,1,1,134.210000000,135.820000000,20,1,1,1,134.200000000,135.910000000,3,100,1,1,134.000000000,135.990000000,1,20,1,1,NVDA
2024-11-01T08:00:15.150713250Z,2024-11-01T08:00:15.150547307Z,10,2,11667,A,B,5,134.440000000,100,130,165943,323069,134.930000000,134.990000000,101,10,1,1,134.870000000,135.000000000,228,38,1,3,134.850000000,135.100000000,300,10,1,1,134.800000000,135.230000000,400,360,1,1,134.500000000,135.300000000,520,1009,2,2,134.440000000,135.400000000,100,10,1,1,134.410000000,135.420000000,61,1,2,1,134.380000000,135.820000000,18,1,1,1,134.210000000,135.910000000,20,100,1,1,134.200000000,135.990000000,3,20,1,1,NVDA
2024-11-01T08:00:15.150784729Z,2024-11-01T08:00:15.150618633Z,10,2,11667,A,B,4,134.750000000,500,130,166096,323071,134.930000000,134.990000000,101,10,1,1,134.870000000,135.000000000,228,38,1,3,134.850000000,135.100000000,300,10,1,1,134.800000000,135.230000000,400,360,1,1,134.750000000,135.300000000,500,1009,1,2,134.500000000,135.400000000,520,10,2,1,134.440000000,135.420000000,100,1,1,1,134.410000000,135.820000000,61,1,2,1,134.380000000,135.910000000,18,100,1,1,134.210000000,135.990000000,20,20,1,1,NVDA
2024-11-01T08:00:15.186942780Z,2024-11-01T08:00:15.186776341Z,10,2,11667,A,B,6,134.440000000,100,130,166439,323142,134.930000000,134.990000000,101,10,1,1,134.870000000,135.000000000,228,38,1,3,134.850000000,135.100000000,300,10,1,1,134.800000000,135.230000000,400,360,1,1,134.750000000,135.300000000,500,1009,1,2,134.500000000,135.400000000,520,10,2,1,134.440000000,135.420000000,200,1,2,1,134.410000000,135.820000000,61,1,2,1,134.380000000,135.910000000,18,100,1,1,134.210000000,135.990000000,20,20,1,1,NVDA
2024-11-01T08:00:15.218124048Z,2024-11-01T08:00:15.217957301Z,10,2,16244,A,A,4,251.200000000,1000,130,166747,323179,250.590000000,250.790000000,7,200,3,1,250.150000000,250.880000000,50,14,1,1,250.000000000,250.940000000,2,100,2,1,249.930000000,251.090000000,10,100,1,1,249.880000000,251.200000000,4,1000,1,1,249.850000000,251.450000000,4,374,1,2,249.800000000,251.500000000,199,10,1,1,249.770000000,252.300000000,50,1000,1,1,249.500000000,253.350000000,1000,23,1,1,249.010000000,253.650000000,3,400,1,1,TSLA
2024-11-01T08:00:15.218181241Z,2024-11-01T08:00:15.218015156Z,10,2,16244,C,A,7,252.300000000,1000,130,166085,323180,250.590000000,250.790000000,7,200,3,1,250.150000000,250.880000000,50,14,1,1,250.000000000,250.940000000,2,100,2,1,249.930000000,251.090000000,10,100,1,1,249.880000000,251.200000000,4,1000,1,1,249.850000000,251.450000000,4,374,1,2,249.800000000,251.500000000,199,10,1,1,249.770000000,253.350000000,50,23,1,1,249.500000000,253.650000000,1000,400,1,1,249.010000000,253.880000000,3,8,1,1,TSLA
2024-11-01T08:00:15.245536436Z,2024-11-01T08:00:15.245368080Z,10,2,11667,A,A,5,135.390000000,1000,130,168356,323207,134.930000000,134.990000000,101,10,1,1,134.870000000,135.000000000,228,38,1,3,134.850000000,135.100000000,300,10,1,1,134.800000000,135.230000000,400,360,1,1,134.750000000,135.300000000,500,1009,1,2,134.500000000,135.390000000,520,1000,2,1,134.440000000,135.400000000,200,10,2,1,134.410000000,135.420000000,61,1,2,1,134.380000000,135.820000000,18,1,1,1,134.210000000,135.910000000,20,100,1,1,NVDA
2024-11-01T08:00:15.254026323Z,2024-11-01T08:00:15.253860518Z,10,2,11667,C,B,6,134.440000000,100,130,165805,323247,134.930000000,134.990000000,101,10,1,1,134.870000000,135.000000000,228,38,1,3,134.850000000,135.100000000,300,10,1,1,134.800000000,135.230000000,400,360,1,1,134.750000000,135.300000000,500,1009,1,2,134.500000000,135.390000000,520,1000,2,1,134.440000000,135.400000000,100,10,1,1,134.410000000,135.420000000,61,1,2,1,134.380000000,135.820000000,18,1,1,1,134.210000000,135.910000000,20,100,1,1,NVDA
2024-11-01T08:00:15.254040810Z,2024-11-01T08:00:15.253874508Z,10,2,11667,A,B,6,134.450000000,200,130,166302,323248,134.930000000,134.990000000,101,10,1,1,134.870000000,135.000000000,228,38,1,3,134.850000000,135.100000000,300,10,1,1,134.800000000,135.230000000,400,360,1,1,134.750000000,135.300000000,500,1009,1,2,134.500000000,135.390000000,520,1000,2,1,134.450000000,135.400000000,200,10,1,1,134.410000000,135.420000000,61,1,2,1,134.380000000,135.820000000,18,1,1,1,134.210000000,135.910000000,20,100,1,1,NVDA
2024-11-01T08:00:15.254667448Z,2024-11-01T08:00:15.254500146Z,10,2,11667,T,A,0,134.930000000,3,130,167302,323251,134.930000000,134.990000000,101,10,1,1,134.870000000,135.000000000,228,38,1,3,134.850000000,135.100000000,300,10,1,1,134.800000000,135.230000000,400,360,1,1,134.750000000,135.300000000,500,1009,1,2,134.500000000,135.390000000,520,1000,2,1,134.450000000,135.400000000,200,10,1,1,134.410000000,135.420000000,61,1,2,1,134.380000000,135.820000000,18,1,1,1,134.210000000,135.910000000,20,100,1,1,NVDA
2024-11-01T08:00:15.254667448Z,2024-11-01T08:00:15.254500146Z,10,2,11667,C,B,0,134.930000000,3,130,167302,323251,134.930000000,134.990000000,98,10,1,1,134.870000000,135.000000000,228,38,1,3,134.850000000,135.100000000,300,10,1,1,134.800000000,135.230000000,400,360,1,1,134.750000000,135.300000000,500,1009,1,2,134.500000000,135.390000000,520,1000,2,1,134.450000000,135.400000000,200,10,1,1,134.410000000,135.420000000,61,1,2,1,134.380000000,135.820000000,18,1,1,1,134.210000000,135.910000000,20,100,1,1,NVDA
2024-11-01T08:00:15.255386124Z,2024-11-01T08:00:15.255128797Z,10,2,11667,T,A,0,134.930000000,98,0,257327,323256,134.930000000,134.990000000,98,10,1,1,134.870000000,135.000000000,228,38,1,3,134.850000000,135.100000000,300,10,1,1,134.800000000,135.230000000,400,360,1,1,134.750000000,135.300000000,500,1009,1,2,134.500000000,135.390000000,520,1000,2,1,134.450000000,135.400000000,200,10,1,1,134.410000000,135.420000000,61,1,2,1,134.380000000,135.820000000,18,1,1,1,134.210000000,135.910000000,20,100,1,1,NVDA
2024-11-01T08:00:15.255386124Z,2024-11-01T08:00:15.255128797Z,10,2,11667,T,A,0,134.870000000,228,0,257327,323257,134.870000000,134.990000000,228,10,1,1,134.850000000,135.000000000,300,38,1,3,134.800000000,135.100000000,400,10,1,1,134.750000000,135.230000000,500,360,1,1,134.500000000,135.300000000,520,1009,2,2,134.450000000,135.390000000,200,1000,1,1,134.410000000,135.400000000,61,10,2,1,134.380000000,135.420000000,18,1,1,1,134.210000000,135.820000000,20,1,1,1,134.200000000,135.910000000,3,100,1,1,NVDA
2024-11-01T08:00:15.255386124Z,2024-11-01T08:00:15.255128797Z,10,2,11667,T,A,0,134.850000000,300,0,257327,323258,134.850000000,134.990000000,300,10,1,1,134.800000000,135.000000000,400,38,1,3,134.750000000,135.100000000,500,10,1,1,134.500000000,135.230000000,520,360,2,1,134.450000000,135.300000000,200,1009,1,2,134.410000000,135.390000000,61,1000,2,1,134.380000000,135.400000000,18,10,1,1,134.210000000,135.420000000,20,1,1,1,134.200000000,135.820000000,3,1,1,1,134.000000000,135.910000000,41,100,2,1,NVDA
2024-11-01T08:00:15.255386124Z,2024-11-01T08:00:15.255128797Z,10,2,11667,T,A,0,134.800000000,87,128,257327,323259,134.800000000,134.990000000,400,10,1,1,134.750000000,135.000000000,500,38,1,3,134.500000000,135.100000000,520,10,2,1,134.450000000,135.230000000,200,360,1,1,134.410000000,135.300000000,61,1009,2,2,134.380000000,135.390000000,18,1000,1,1,134.210000000,135.400000000,20,10,1,1,134.200000000,135.420000000,3,1,1,1,134.000000000,135.820000000,41,1,2,1,133.800000000,135.910000000,5,100,1,1,NVDA
2024-11-01T08:00:15.255386124Z,2024-11-01T08:00:15.255128797Z,10,2,11667,C,B,0,134.800000000,87,128,257327,323259,134.800000000,134.990000000,313,10,1,1,134.750000000,135.000000000,500,38,1,3,134.500000000,135.100000000,520,10,2,1,134.450000000,135.230000000,200,360,1,1,134.410000000,135.300000000,61,1009,2,2,134.380000000,135.390000000,18,1000,1,1,134.210000000,135.400000000,20,10,1,1,134.200000000,135.420000000,3,1,1,1,134.000000000,135.820000000,41,1,2,1,133.800000000,135.910000000,5,100,1,1,NVDA
2024-11-01T08:00:15.255430061Z,2024-11-01T08:00:15.255259387Z,10,2,11667,A,A,0,134.920000000,100,130,170674,323265,134.800000000,134.920000000,313,100,1,1,134.750000000,134.960000000,500,200,1,2,134.500000000,134.970000000,520,400,2,2,134.450000000,134.990000000,200,10,1,1,134.410000000,135.000000000,61,38,2,3,134.380000000,135.100000000,18,10,1,1,134.210000000,135.230000000,20,360,1,1,134.200000000,135.300000000,3,1009,1,2,134.000000000,135.390000000,41,1000,2,1,133.800000000,135.400000000,5,10,1,1,NVDA
2024-11-01T08:00:15.255450131Z,2024-11-01T08:00:15.255279593Z,10,2,11667,A,A,1,134.970000000,100,130,170538,323273,134.800000000,134.920000000,313,100,1,1,134.750000000,134.960000000,500,700,1,5,134.500000000,134.970000000,520,600,2,4,134.450000000,134.990000000,200,10,1,1,134.410000000,135.000000000,61,38,2,3,134.380000000,135.100000000,18,10,1,1,134.210000000,135.230000000,20,360,1,1,134.200000000,135.300000000,3,1009,1,2,134.000000000,135.390000000,41,1000,2,1,133.800000000,135.400000000,5,10,1,1,NVDA
2024-11-01T08:00:15.255458102Z,2024-11-01T08:00:15.255291935Z,10,2,11667,A,A,1,134.960000000,100,130,166167,323274,134.800000000,134.920000000,313,100,1,1,134.750000000,134.960000000,500,800,1,6,134.500000000,134.970000000,520,600,2,4,134.450000000,134.990000000,200,10,1,1,134.410000000,135.000000000,61,38,2,3,134.380000000,135.100000000,18,10,1,1,134.210000000,135.230000000,20,360,1,1,134.200000000,135.300000000,3,1009,1,2,134.000000000,135.390000000,41,1000,2,1,133.800000000,135.400000000,5,10,1,1,NVDA
2024-11-01T08:00:15.255459635Z,2024-11-01T08:00:15.255292904Z,10,2,11667,A,A,1,134.930000000,100,130,166731,323275,134.800000000,134.920000000,313,100,1,1,134.750000000,134.930000000,500,100,1,1,134.500000000,134.960000000,520,800,2,6,134.450000000,134.970000000,200,600,1,4,134.410000000,134.990000000,61,10,2,1,134.380000000,135.000000000,18,38,1,3,134.210000000,135.100000000,20,10,1,1,134.200000000,135.230000000,3,360,1,1,134.000000000,135.300000000,41,1009,2,2,133.800000000,135.390000000,5,1000,1,1,NVDA
2024-11-01T08:00:15.255462139Z,2024-11-01T08:00:15.255294057Z,10,2,11667,A,A,2,134.960000000,300,128,168082,323276,134.800000000,134.920000000,313,100,1,1,134.750000000,134.930000000,500,100,1,1,134.500000000,134.960000000,520,1100,2,7,134.450000000,134.970000000,200,600,1,4,134.410000000,134.990000000,61,10,2,1,134.380000000,135.000000000,18,38,1,3,134.210000000,135.100000000,20,10,1,1,134.200000000,135.230000000,3,360,1,1,134.000000000,135.300000000,41,1009,2,2,133.800000000,135.390000000,5,1000,1,1,NVDA
2024-11-01T08:00:15.255464752Z,2024-11-01T08:00:15.255298748Z,10,2,11667,A,A,3,134.970000000,100,130,166004,323279,134.800000000,134.920000000,313,100,1,1,134.750000000,134.930000000,500,100,1,1,134.500000000,134.960000000,520,1100,2,7,134.450000000,134.970000000,200,700,1,5,134.410000000,134.990000000,61,10,2,1,134.380000000,135.000000000,18,38,1,3,134.210000000,135.100000000,20,10,1,1,134.200000000,135.230000000,3,360,1,1,134.000000000,135.300000000,41,1009,2,2,133.800000000,135.390000000,5,1000,1,1,NVDA
2024-11-01T08:00:15.255470787Z,2024-11-01T08:00:15.255305043Z,10,2,11667,C,A,2,134.970000000,300,130,165744,323281,134.800000000,134.920000000,313,100,1,1,134.750000000,134.930000000,500,100,1,1,134.500000000,134.960000000,520,1200,2,8,134.450000000,134.970000000,200,400,1,4,134.410000000,134.990000000,61,10,2,1,134.380000000,135.000000000,18,38,1,3,134.210000000,135.100000000,20,10,1,1,134.200000000,135.230000000,3,360,1,1,134.000000000,135.300000000,41,1009,2,2,133.800000000,135.390000000,5,1000,1,1,NVDA
2024-11-01T08:00:15.255481383Z,2024-11-01T08:00:15.255315130Z,10,2,11667,A,A,0,134.910000000,100,130,166253,323282,134.800000000,134.910000000,313,100,1,1,134.750000000,134.920000000,500,100,1,1,134.500000000,134.930000000,520,100,2,1,134.450000000,134.960000000,200,1200,1,8,134.410000000,134.970000000,61,400,2,4,134.380000000,134.990000000,18,10,1,1,134.210000000,135.000000000,20,38,1,3,134.200000000,135.100000000,3,10,1,1,134.000000000,135.230000000,41,360,2,1,133.800000000,135.300000000,5,1009,1,2,NVDA
2024-11-01T08:00:15.255491607Z,2024-11-01T08:00:15.255325802Z,10,2,11667,A,A,3,134.960000000,100,130,165805,323283,134.800000000,134.910000000,313,100,1,1,134.750000000,134.920000000,500,100,1,1,134.500000000,134.930000000,520,100,2,1,134.450000000,134.960000000,200,1300,1,9,134.410000000,134.970000000,61,400,2,4,134.380000000,134.990000000,18,10,1,1,134.210000000,135.000000000,20,38,1,3,134.200000000,135.100000000,3,10,1,1,134.000000000,135.230000000,41,360,2,1,133.800000000,135.300000000,5,1009,1,2,NVDA
2024-11-01T08:00:15.255499144Z,2024-11-01T08:00:15.255333472Z,10,2,11667,C,A,3,134.960000000,100,130,165672,323284,134.800000000,134.910000000,313,100,1,1,134.750000000,134.920000000,500,100,1,1,134.500000000,134.930000000,520,100,2,1,134.450000000,134.960000000,200,1200,1,8,134.410000000,134.970000000,61,400,2,4,134.380000000,134.990000000,18,10,1,1,134.210000000,135.000000000,20,38,1,3,134.200000000,135.100000000,3,10,1,1,134.000000000,135.230000000,41,360,2,1,133.800000000,135.300000000,5,1009,1,2,NVDA
2024-11-01T08:00:15.255504280Z,2024-11-01T08:00:15.255338067Z,10,2,11667,C,A,3,134.960000000,100,130,166213,323285,134.800000000,134.910000000,313,100,1,1,134.750000000,134.920000000,500,100,1,1,134.500000000,134.930000000,520,100,2,1,134.450000000,134.960000000,200,1100,1,7,134.410000000,134.970000000,61,400,2,4,134.380000000,134.990000000,18,10,1,1,134.210000000,135.000000000,20,38,1,3,134.200000000,135.100000000,3,10,1,1,134.000000000,135.230000000,41,360,2,1,133.800000000,135.300000000,5,1009,1,2,NVDA
2024-11-01T08:00:15.255512754Z,2024-11-01T08:00:15.255347181Z,10,2,11667,C,A,4,134.970000000,100,130,165573,323286,134.800000000,134.910000000,313,100,1,1,134.750000000,134.920000000,500,100,1,1,134.500000000,134.930000000,520,100,2,1,134.450000000,134.960000000,200,1100,1,7,134.410000000,134.970000000,61,300,2,3,134.380000000,134.990000000,18,10,1,1,134.210000000,135.000000000,20,38,1,3,134.200000000,135.100000000,3,10,1,1,134.000000000,135.230000000,41,360,2,1,133.800000000,135.300000000,5,1009,1,2,NVDA
2024-11-01T08:00:15.255522066Z,2024-11-01T08:00:15.255356611Z,10,2,11667,C,A,2,134.930000000,100,130,165455,323287,134.800000000,134.910000000,313,100,1,1,134.750000000,134.920000000,500,100,1,1,134.500000000,134.960000000,520,1100,2,7,134.450000000,134.970000000,200,300,1,3,134.410000000,134.990000000,61,10,2,1,134.380000000,135.000000000,18,38,1,3,134.210000000,135.100000000,20,10,1,1,134.200000000,135.230000000,3,360,1,1,134.000000000,135.300000000,41,1009,2,2,133.800000000,135.390000000,5,1000,1,1,NVDA
2024-11-01T08:00:15.255530943Z,2024-11-01T08:00:15.255365230Z,10,2,11667,C,A,2,134.960000000,100,130,165713,323288,134.800000000,134.910000000,313,100,1,1,134.750000000,134.920000000,500,100,1,1,134.500000000,134.960000000,520,1000,2,6,134.450000000,134.970000000,200,300,1,3,134.410000000,134.990000000,61,10,2,1,134.380000000,135.000000000,18,38,1,3,134.210000000,135.100000000,20,10,1,1,134.200000000,135.230000000,3,360,1,1,134.000000000,135.300000000,41,1009,2,2,133.800000000,135.390000000,5,1000,1,1,NVDA
2024-11-01T08:00:15.255540286Z,2024-11-01T08:00:15.255374812Z,10,2,11667,C,A,0,134.910000000,100,130,165474,323289,134.800000000,134.920000000,313,100,1,1,134.750000000,134.960000000,500,1000,1,6,134.500000000,134.970000000,520,300,2,3,134.450000000,134.990000000,200,10,1,1,134.410000000,135.000000000,61,38,2,3,134.380000000,135.100000000,18,10,1,1,134.210000000,135.230000000,20,360,1,1,134.200000000,135.300000000,3,1009,1,2,134.000000000,135.390000000,41,1000,2,1,133.800000000,135.400000000,5,10,1,1,NVDA
2024-11-01T08:00:15.255549678Z,2024-11-01T08:00:15.255384024Z,10,2,11667,C,A,1,134.960000000,100,130,165654,323290,134.800000000,134.920000000,313,100,1,1,134.750000000,134.960000000,500,900,1,5,134.500000000,134.970000000,520,300,2,3,134.450000000,134.990000000,200,10,1,1,134.410000000,135.000000000,61,38,2,3,134.380000000,135.100000000,18,10,1,1,134.210000000,135.230000000,20,360,1,1,134.200000000,135.300000000,3,1009,1,2,134.000000000,135.390000000,41,1000,2,1,133.800000000,135.400000000,5,10,1,1,NVDA
2024-11-01T08:00:15.255762216Z,2024-11-01T08:00:15.255594428Z,10,2,11667,T,A,0,134.800000000,98,0,167788,323291,134.800000000,134.920000000,313,100,1,1,134.750000000,134.960000000,500,900,1,5,134.500000000,134.970000000,520,300,2,3,134.450000000,134.990000000,200,10,1,1,134.410000000,135.000000000,61,38,2,3,134.380000000,135.100000000,18,10,1,1,134.210000000,135.230000000,20,360,1,1,134.200000000,135.300000000,3,1009,1,2,134.000000000,135.390000000,41,1000,2,1,133.800000000,135.400000000,5,10,1,1,NVDA
2024-11-01T08:00:15.255762216Z,2024-11-01T08:00:15.255595961Z,10,2,11667,C,B,0,134.960000000,300,130,166255,323293,134.800000000,134.920000000,215,100,1,1,134.750000000,134.960000000,500,500,1,3,134.500000000,134.970000000,520,300,2,3,134.450000000,134.990000000,200,10,1,1,134.410000000,135.000000000,61,38,2,3,134.380000000,135.100000000,18,10,1,1,134.210000000,135.230000000,20,360,1,1,134.200000000,135.300000000,3,1009,1,2,134.000000000,135.390000000,41,1000,2,1,133.800000000,135.400000000,5,10,1,1,NVDA
2024-11-01T08:00:15.255773901Z,2024-11-01T08:00:15.255607807Z,10,2,11667,C,A,1,134.960000000,300,130,166094,323294,134.800000000,134.920000000,215,100,1,1,134.750000000,134.960000000,500,200,1,2,134.500000000,134.970000000,520,300,2,3,134.450000000,134.990000000,200,10,1,1,134.410000000,135.000000000,61,38,2,3,134.380000000,135.100000000,18,10,1,1,134.210000000,135.230000000,20,360,1,1,134.200000000,135.300000000,3,1009,1,2,134.000000000,135.390000000,41,1000,2,1,133.800000000,135.400000000,5,10,1,1,NVDA
2024-11-01T08:00:15.255966505Z,2024-11-01T08:00:15.255797958Z,10,2,11667,T,A,0,134.800000000,13,130,168547,323295,134.800000000,134.920000000,215,100,1,1,134.750000000,134.960000000,500,200,1,2,134.500000000,134.970000000,520,300,2,3,134.450000000,134.990000000,200,10,1,1,134.410000000,135.000000000,61,38,2,3,134.380000000,135.100000000,18,10,1,1,134.210000000,135.230000000,20,360,1,1,134.200000000,135.300000000,3,1009,1,2,134.000000000,135.390000000,41,1000,2,1,133.800000000,135.400000000,5,10,1,1,NVDA
2024-11-01T08:00:15.255966505Z,2024-11-01T08:00:15.255797958Z,10,2,11667,C,B,0,134.800000000,13,130,168547,323295,134.800000000,134.920000000,202,100,1,1,134.750000000,134.960000000,500,200,1,2,134.500000000,134.970000000,520,300,2,3,134.450000000,134.990000000,200,10,1,1,134.410000000,135.000000000,61,38,2,3,134.380000000,135.100000000,18,10,1,1,134.210000000,135.230000000,20,360,1,1,134.200000000,135.300000000,3,1009,1,2,134.000000000,135.390000000,41,1000,2,1,133.800000000,135.400000000,5,10,1,1,NVDA
2024-11-01T08:00:15.255974482Z,2024-11-01T08:00:15.255805997Z,10,2,11667,T,N,0,134.830000000,1,130,168485,323296,134.800000000,134.920000000,202,100,1,1,134.750000000,134.960000000,500,200,1,2,134.500000000,134.970000000,520,300,2,3,134.450000000,134.990000000,200,10,1,1,134.410000000,135.000000000,61,38,2,3,134.380000000,135.100000000,18,10,1,1,134.210000000,135.230000000,20,360,1,1,134.200000000,135.300000000,3,1009,1,2,134.000000000,135.390000000,41,1000,2,1,133.800000000,135.400000000,5,10,1,1,NVDA
2024-11-01T08:00:15.255979186Z,2024-11-01T08:00:15.255812756Z,10,2,11667,T,N,0,134.830000000,86,130,166430,323297,134.800000000,134.920000000,202,100,1,1,134.750000000,134.960000000,500,200,1,2,134.500000000,134.970000000,520,300,2,3,134.450000000,134.990000000,200,10,1,1,134.410000000,135.000000000,61,38,2,3,134.380000000,135.100000000,18,10,1,1,134.210000000,135.230000000,20,360,1,1,134.200000000,135.300000000,3,1009,1,2,134.000000000,135.390000000,41,1000,2,1,133.800000000,135.400000000,5,10,1,1,NVDA
2024-11-01T08:00:15.256009647Z,2024-11-01T08:00:15.255841178Z,10,2,11667,T,N,0,134.830000000,1,128,168469,323298,134.800000000,134.920000000,202,100,1,1,134.750000000,134.960000000,500,200,1,2,134.500000000,134.970000000,520,300,2,3,134.450000000,134.990000000,200,10,1,1,134.410000000,135.000000000,61,38,2,3,134.380000000,135.100000000,18,10,1,1,134.210000000,135.230000000,20,360,1,1,134.200000000,135.300000000,3,1009,1,2,134.000000000,135.390000000,41,1000,2,1,133.800000000,135.400000000,5,10,1,1,NVDA
2024-11-01T08:00:15.256180127Z,2024-11-01T08:00:15.256013380Z,10,2,11667,T,N,0,134.830000000,14,130,166747,323301,134.800000000,134.920000000,202,100,1,1,134.750000000,134.960000000,500,200,1,2,134.500000000,134.970000000,520,300,2,3,134.450000000,134.990000000,200,10,1,1,134.410000000,135.000000000,61,38,2,3,134.380000000,135.100000000,18,10,1,1,134.210000000,135.230000000,20,360,1,1,134.200000000,135.300000000,3,1009,1,2,134.000000000,135.390000000,41,1000,2,1,133.800000000,135.400000000,5,10,1,1,NVDA
2024-11-01T08:00:15.256185452Z,2024-11-01T08:00:15.256018882Z,10,2,11667,T,N,0,134.830000000,2,130,166570,323302,134.800000000,134.920000000,202,100,1,1,134.750000000,134.960000000,500,200,1,2,134.500000000,134.970000000,520,300,2,3,134.450000000,134.990000000,200,10,1,1,134.410000000,135.000000000,61,38,2,3,134.380000000,135.100000000,18,10,1,1,134.210000000,135.230000000,20,360,1,1,134.200000000,135.300000000,3,1009,1,2,134.000000000,135.390000000,41,1000,2,1,133.800000000,135.400000000,5,10,1,1,NVDA
2024-11-01T08:00:15.256339170Z,2024-11-01T08:00:15.256173614Z,10,2,11667,C,B,3,134.450000000,200,130,165556,323305,134.800000000,134.920000000,202,100,1,1,134.750000000,134.960000000,500,200,1,2,134.500000000,134.970000000,520,300,2,3,134.410000000,134.990000000,61,10,2,1,134.380000000,135.000000000,18,38,1,3,134.210000000,135.100000000,20,10,1,1,134.200000000,135.230000000,3,360,1,1,134.000000000,135.300000000,41,1009,2,2,133.800000000,135.390000000,5,1000,1,1,133.160000000,135.400000000,1,10,1,1,NVDA
2024-11-01T08:00:15.256348308Z,2024-11-01T08:00:15.256181654Z,10,2,11667,T,N,0,134.830000000,15,130,166654,323306,134.800000000,134.920000000,202,100,1,1,134.750000000,134.960000000,500,200,1,2,134.500000000,134.970000000,520,300,2,3,134.410000000,134.990000000,61,10,2,1,134.380000000,135.000000000,18,38,1,3,134.210000000,135.100000000,20,10,1,1,134.200000000,135.230000000,3,360,1,1,134.000000000,135.300000000,41,1009,2,2,133.800000000,135.390000000,5,1000,1,1,133.160000000,135.400000000,1,10,1,1,NVDA
2024-11-01T08:00:15.260406453Z,2024-11-01T08:00:15.260240430Z,10,2,11667,C,A,2,134.970000000,100,130,166023,323308,134.800000000,134.920000000,202,100,1,1,134.750000000,134.960000000,500,200,1,2,134.500000000,134.970000000,520,200,2,2,134.410000000,134.990000000,61,10,2,1,134.380000000,135.000000000,18,38,1,3,134.210000000,135.100000000,20,10,1,1,134.200000000,135.230000000,3,360,1,1,134.000000000,135.300000000,41,1009,2,2,133.800000000,135.390000000,5,1000,1,1,133.160000000,135.400000000,1,10,1,1,NVDA
2024-11-01T08:00:15.260417605Z,2024-11-01T08:00:15.260251763Z,10,2,11667,C,A,1,134.960000000,100,130,165842,323309,134.800000000,134.920000000,202,100,1,1,134.750000000,134.960000000,500,100,1,1,134.500000000,134.970000000,520,200,2,2,134.410000000,134.990000000,61,10,2,1,134.380000000,135.000000000,18,38,1,3,134.210000000,135.100000000,20,10,1,1,134.200000000,135.230000000,3,360,1,1,134.000000000,135.300000000,41,1009,2,2,133.800000000,135.390000000,5,1000,1,1,133.160000000,135.400000000,1,10,1,1,NVDA
2024-11-01T08:00:15.260427075Z,2024-11-01T08:00:15.260261435Z,10,2,11667,C,A,1,134.960000000,100,130,165640,323310,134.800000000,134.920000000,202,100,1,1,134.750000000,134.970000000,500,200,1,2,134.500000000,134.990000000,520,10,2,1,134.410000000,135.000000000,61,38,2,3,134.380000000,135.100000000,18,10,1,1,134.210000000,135.230000000,20,360,1,1,134.200000000,135.300000000,3,1009,1,2,134.000000000,135.390000000,41,1000,2,1,133.800000000,135.400000000,5,10,1,1,133.160000000,135.420000000,1,1,1,1,NVDA
2024-11-01T08:00:15.266617431Z,2024-11-01T08:00:15.266451468Z,10,2,11667,A,B,3,134.410000000,100,130,165963,323314,134.800000000,134.920000000,202,100,1,1,134.750000000,134.970000000,500,200,1,2,134.500000000,134.990000000,520,10,2,1,134.410000000,135.000000000,161,38,3,3,134.380000000,135.100000000,18,10,1,1,134.210000000,135.230000000,20,360,1,1,134.200000000,135.300000000,3,1009,1,2,134.000000000,135.390000000,41,1000,2,1,133.800000000,135.400000000,5,10,1,1,133.160000000,135.420000000,1,1,1,1,NVDA
2024-11-01T08:00:15.291878261Z,2024-11-01T08:00:15.291712273Z,10,2,11667,A,B,3,134.410000000,100,130,165988,323324,134.800000000,134.920000000,202,100,1,1,134.750000000,134.970000000,500,200,1,2,134.500000000,134.990000000,520,10,2,1,134.410000000,135.000000000,261,38,4,3,134.380000000,135.100000000,18,10,1,1,134.210000000,135.230000000,20,360,1,1,134.200000000,135.300000000,3,1009,1,2,134.000000000,135.390000000,41,1000,2,1,133.800000000,135.400000000,5,10,1,1,133.160000000,135.420000000,1,1,1,1,NVDA
2024-11-01T08:00:15.357818043Z,2024-11-01T08:00:15.357652137Z,10,2,11667,C,B,3,134.410000000,100,130,165906,323415,134.800000000,134.920000000,202,100,1,1,134.750000000,134.970000000,500,200,1,2,134.500000000,134.990000000,520,10,2,1,134.410000000,135.000000000,161,38,3,3,134.380000000,135.100000000,18,10,1,1,134.210000000,135.230000000,20,360,1,1,134.200000000,135.300000000,3,1009,1,2,134.000000000,135.390000000,41,1000,2,1,133.800000000,135.400000000,5,10,1,1,133.160000000,135.420000000,1,1,1,1,NVDA
2024-11-01T08:00:15.357832167Z,2024-11-01T08:00:15.357665994Z,10,2,11667,A,B,3,134.490000000,100,130,166173,323416,134.800000000,134.920000000,202,100,1,1,134.750000000,134.970000000,500,200,1,2,134.500000000,134.990000000,520,10,2,1,134.490000000,135.000000000,100,38,1,3,134.410000000,135.100000000,61,10,2,1,134.380000000,135.230000000,18,360,1,1,134.210000000,135.300000000,20,1009,1,2,134.200000000,135.390000000,3,1000,1,1,134.000000000,135.400000000,41,10,2,1,133.800000000,135.420000000,5,1,1,1,NVDA
2024-11-01T08:00:15.357848113Z,2024-11-01T08:00:15.357682367Z,10,2,11667,C,A,1,134.970000000,100,130,165746,323417,134.800000000,134.920000000,202,100,1,1,134.750000000,134.970000000,500,100,1,1,134.500000000,134.990000000,520,10,2,1,134.490000000,135.000000000,100,38,1,3,134.410000000,135.100000000,61,10,2,1,134.380000000,135.230000000,18,360,1,1,134.210000000,135.300000000,20,1009,1,2,134.200000000,135.390000000,3,1000,1,1,134.000000000,135.400000000,41,10,2,1,133.800000000,135.420000000,5,1,1,1,NVDA
2024-11-01T08:00:15.458754081Z,2024-11-01T08:00:15.458586882Z,10,2,11667,T,A,0,134.800000000,18,130,167199,323558,134.800000000,134.920000000,202,100,1,1,134.750000000,134.970000000,500,100,1,1,134.500000000,134.990000000,520,10,2,1,134.490000000,135.000000000,100,38,1,3,134.410000000,135.100000000,61,10,2,1,134.380000000,135.230000000,18,360,1,1,134.210000000,135.300000000,20,1009,1,2,134.200000000,135.390000000,3,1000,1,1,134.000000000,135.400000000,41,10,2,1,133.800000000,135.420000000,5,1,1,1,NVDA
2024-11-01T08:00:15.458754081Z,2024-11-01T08:00:15.458586882Z,10,2,11667,C,B,0,134.800000000,18,130,167199,323558,134.800000000,134.920000000,184,100,1,1,134.750000000,134.970000000,500,100,1,1,134.500000000,134.990000000,520,10,2,1,134.490000000,135.000000000,100,38,1,3,134.410000000,135.100000000,61,10,2,1,134.380000000,135.230000000,18,360,1,1,134.210000000,135.300000000,20,1009,1,2,134.200000000,135.390000000,3,1000,1,1,134.000000000,135.400000000,41,10,2,1,133.800000000,135.420000000,5,1,1,1,NVDA
2024-11-01T08:00:15.514082576Z,2024-11-01T08:00:15.513916761Z,10,2,11667,C,A,0,134.920000000,100,130,165815,323640,134.800000000,134.970000000,184,100,1,1,134.750000000,134.990000000,500,10,1,1,134.500000000,135.000000000,520,38,2,3,134.490000000,135.100000000,100,10,1,1,134.410000000,135.230000000,61,360,2,1,134.380000000,135.300000000,18,1009,1,2,134.210000000,135.390000000,20,1000,1,1,134.200000000,135.400000000,3,10,1,1,134.000000000,135.420000000,41,1,2,1,133.800000000,135.820000000,5,1,1,1,NVDA
2024-11-01T08:00:15.553322624Z,2024-11-01T08:00:15.553155003Z,10,2,11667,A,B,3,134.490000000,100,128,167621,323673,134.800000000,134.970000000,184,100,1,1,134.750000000,134.990000000,500,10,1,1,134.500000000,135.000000000,520,38,2,3,134.490000000,135.100000000,200,10,2,1,134.410000000,135.230000000,61,360,2,1,134.380000000,135.300000000,18,1009,1,2,134.210000000,135.390000000,20,1000,1,1,134.200000000,135.400000000,3,10,1,1,134.000000000,135.420000000,41,1,2,1,133.800000000,135.820000000,5,1,1,1,NVDA
2024-11-01T08:00:15.619083498Z,2024-11-01T08:00:15.618917802Z,10,2,11667,C,B,3,134.490000000,100,130,165696,323777,134.800000000,134.970000000,184,100,1,1,134.750000000,134.990000000,500,10,1,1,134.500000000,135.000000000,520,38,2,3,134.490000000,135.100000000,100,10,1,1,134.410000000,135.230000000,61,360,2,1,134.380000000,135.300000000,18,1009,1,2,134.210000000,135.390000000,20,1000,1,1,134.200000000,135.400000000,3,10,1,1,134.000000000,135.420000000,41,1,2,1,133.800000000,135.820000000,5,1,1,1,NVDA
2024-11-01T08:00:15.619098380Z,2024-11-01T08:00:15.618932222Z,10,2,11667,A,B,2,134.530000000,100,130,166158,323778,134.800000000,134.970000000,184,100,1,1,134.750000000,134.990000000,500,10,1,1,134.530000000,135.000000000,100,38,1,3,134.500000000,135.100000000,520,10,2,1,134.410000000,135.230000000,61,360,2,1,134.380000000,135.300000000,18,1009,1,2,134.210000000,135.390000000,20,1000,1,1,134.200000000,135.400000000,3,10,1,1,134.000000000,135.420000000,41,1,2,1,133.800000000,135.820000000,5,1,1,1,NVDA
2024-11-01T08:00:15.620266829Z,2024-11-01T08:00:15.620096684Z,10,2,16244,T,A,0,250.590000000,2,0,170145,323779,250.590000000,250.790000000,7,200,3,1,250.150000000,250.880000000,50,14,1,1,250.000000000,250.940000000,2,100,2,1,249.930000000,251.090000000,10,100,1,1,249.880000000,251.200000000,4,1000,1,1,249.850000000,251.450000000,4,374,1,2,249.800000000,251.500000000,199,10,1,1,249.770000000,253.350000000,50,23,1,1,249.500000000,253.650000000,1000,400,1,1,249.010000000,253.880000000,3,8,1,1,TSLA
2024-11-01T08:00:15.620266829Z,2024-11-01T08:00:15.620096684Z,10,2,16244,T,A,0,250.590000000,1,0,170145,323780,250.590000000,250.790000000,5,200,2,1,250.150000000,250.880000000,50,14,1,1,250.000000000,250.940000000,2,100,2,1,249.930000000,251.090000000,10,100,1,1,249.880000000,251.200000000,4,1000,1,1,249.850000000,251.450000000,4,374,1,2,249.800000000,251.500000000,199,10,1,1,249.770000000,253.350000000,50,23,1,1,249.500000000,253.650000000,1000,400,1,1,249.010000000,253.880000000,3,8,1,1,TSLA
2024-11-01T08:00:15.620266829Z,2024-11-01T08:00:15.620096684Z,10,2,16244,T,A,0,250.590000000,4,130,170145,323781,250.590000000,250.790000000,4,200,1,1,250.150000000,250.880000000,50,14,1,1,250.000000000,250.940000000,2,100,2,1,249.930000000,251.090000000,10,100,1,1,249.880000000,251.200000000,4,1000,1,1,249.850000000,251.450000000,4,374,1,2,249.800000000,251.500000000,199,10,1,1,249.770000000,253.350000000,50,23,1,1,249.500000000,253.650000000,1000,400,1,1,249.010000000,253.880000000,3,8,1,1,TSLA
2024-11-01T08:00:15.620266829Z,2024-11-01T08:00:15.620096684Z,10,2,16244,C,B,0,250.590000000,4,130,170145,323781,250.150000000,250.790000000,50,200,1,1,250.000000000,250.880000000,2,14,2,1,249.930000000,250.940000000,10,100,1,1,249.880000000,251.090000000,4,100,1,1,249.850000000,251.200000000,4,1000,1,1,249.800000000,251.450000000,199,374,1,2,249.770000000,251.500000000,50,10,1,1,249.500000000,253.350000000,1000,23,1,1,249.010000000,253.650000000,3,400,1,1,249.000000000,253.880000000,100,8,1,1,TSLA
2024-11-01T08:00:15.620287094Z,2024-11-01T08:00:15.620120276Z,10,2,16244,A,A,0,250.750000000,100,130,166818,323782,250.150000000,250.750000000,50,100,1,1,250.000000000,250.790000000,2,200,2,1,249.930000000,250.880000000,10,14,1,1,249.880000000,250.940000000,4,100,1,1,249.850000000,251.090000000,4,100,1,1,249.800000000,251.200000000,199,1000,1,1,249.770000000,251.450000000,50,374,1,2,249.500000000,251.500000000,1000,10,1,1,249.010000000,253.350000000,3,23,1,1,249.000000000,253.650000000,100,400,1,1,TSLA
2024-11-01T08:00:15.620300756Z,2024-11-01T08:00:15.620135185Z,10,2,16244,C,A,0,250.750000000,100,130,165571,323783,250.150000000,250.790000000,50,200,1,1,250.000000000,250.880000000,2,14,2,1,249.930000000,250.940000000,10,100,1,1,249.880000000,251.090000000,4,100,1,1,249.850000000,251.200000000,4,1000,1,1,249.800000000,251.450000000,199,374,1,2,249.770000000,251.500000000,50,10,1,1,249.500000000,253.350000000,1000,23,1,1,249.010000000,253.650000000,3,400,1,1,249.000000000,253.880000000,100,8,1,1,TSLA
2024-11-01T08:00:15.620321114Z,2024-11-01T08:00:15.620155302Z,10,2,16244,A,A,0,250.690000000,26,130,165812,323784,250.150000000,250.690000000,50,26,1,1,250.000000000,250.790000000,2,200,2,1,249.930000000,250.880000000,10,14,1,1,249.880000000,250.940000000,4,100,1,1,249.850000000,251.090000000,4,100,1,1,249.800000000,251.200000000,199,1000,1,1,249.770000000,251.450000000,50,374,1,2,249.500000000,251.500000000,1000,10,1,1,249.010000000,253.350000000,3,23,1,1,249.000000000,253.650000000,100,400,1,1,TSLA
2024-11-01T08:00:15.620338152Z,2024-11-01T08:00:15.620172185Z,10,2,16244,A,A,1,250.750000000,26,130,165967,323785,250.150000000,250.690000000,50,26,1,1,250.000000000,250.750000000,2,26,2,1,249.930000000,250.790000000,10,200,1,1,249.880000000,250.880000000,4,14,1,1,249.850000000,250.940000000,4,100,1,1,249.800000000,251.090000000,199,100,1,1,249.770000000,251.200000000,50,1000,1,1,249.500000000,251.450000000,1000,374,1,2,249.010000000,251.500000000,3,10,1,1,249.000000000,253.350000000,100,23,1,1,TSLA
