{"ts_recv":"2024-11-01T08:00:01.887177526Z","hd":{"ts_event":"2024-11-01T08:00:01.887011820Z","rtype":10,"publisher_id":2,"instrument_id":16244},"action":"C","side":"B","depth":0,"price":"250.330000000","size":50,"flags":130,"ts_in_delta":165706,"sequence":291358,"levels":[{"bid_px":"249.500000000","ask_px":"251.140000000","bid_sz":1000,"ask_sz":100,"bid_ct":1,"ask_ct":1},{"bid_px":"247.150000000","ask_px":"252.400000000","bid_sz":400,"ask_sz":1000,"bid_ct":1,"ask_ct":1},{"bid_px":"235.000000000","ask_px":"253.650000000","bid_sz":100,"ask_sz":400,"bid_ct":1,"ask_ct":1},{"bid_px":null,"ask_px":"960.000000000","bid_sz":0,"ask_sz":25,"bid_ct":0,"ask_ct":1},{"bid_px":null,"ask_px":null,"bid_sz":0,"ask_sz":0,"bid_ct":0,"ask_ct":0},{"bid_px":null,"ask_px":null,"bid_sz":0,"ask_sz":0,"bid_ct":0,"ask_ct":0},{"bid_px":null,"ask_px":null,"bid_sz":0,"ask_sz":0,"bid_ct":0,"ask_ct":0},{"bid_px":null,"ask_px":null,"bid_sz":0,"ask_sz":0,"bid_ct":0,"ask_ct":0},{"bid_px":null,"ask_px":null,"bid_sz":0,"ask_sz":0,"bid_ct":0,"ask_ct":0},{"bid_px":null,"ask_px":null,"bid_sz":0,"ask_sz":0,"bid_ct":0,"ask_ct":0}],"symbol":"TSLA"}
{"ts_recv":"2024-11-01T08:00:01.938948169Z","hd":{"ts_event":"2024-11-01T08:00:01.938781736Z","rtype":10,"publisher_id":2,"instrument_id":16244},"action":"A","side":"B","depth":0,"price":"249.600000000","size":1000,"flags":130,"ts_in_delta":166433,"sequence":291441,"levels":[{"bid_px":"249.600000000","ask_px":"251.140000000","bid_sz":1000,"ask_sz":100,"bid_ct":1,"ask_ct":1},{"bid_px":"249.500000000","ask_px":"252.400000000","bid_sz":1000,"ask_sz":1000,"bid_ct":1,"ask_ct":1},{"bid_px":"247.150000000","ask_px":"253.650000000","bid_sz":400,"ask_sz":400,"bid_ct":1,"ask_ct":1},{"bid_px":"235.000000000","ask_px":"960.000000000","bid_sz":100,"ask_sz":25,"bid_ct":1,"ask_ct":1},{"bid_px":null,"ask_px":null,"bid_sz":0,"ask_sz":0,"bid_ct":0,"ask_ct":0},{"bid_px":null,"ask_px":null,"bid_sz":0,"ask_sz":0,"bid_ct":0,"ask_ct":0},{"bid_px":null,"ask_px":null,"bid_sz":0,"ask_sz":0,"bid_ct":0,"ask_ct":0},{"bid_px":null,"ask_px":null,"bid_sz":0,"ask_sz":0,"bid_ct":0,"ask_ct":0},{"bid_px":null,"ask_px":null,"bid_sz":0,"ask_sz":0,"bid_ct":0,"ask_ct":0},{"bid_px":null,"ask_px":null,"bid_sz":0,"ask_sz":0,"bid_ct":0,"ask_ct":0}],"symbol":"TSLA"}
{"ts_recv":"2024-11-01T08:00:01.939568626Z","hd":{"ts_event":"2024-11-01T08:00:01.939402273Z","rtype":10,"publisher_id":2,"instrument_id":16244},"action":"C","side":"B","depth":1,"price":"249.500000000","size":1000,"flags":130,"ts_in_delta":166353,"sequence":291442,"levels":[{"bid_px":"249.600000000","ask_px":"251.140000000","bid_sz":1000,"ask_sz":100,"bid_ct":1,"ask_ct":1},{"bid_px":"247.150000000","ask_px":"252.400000000","bid_sz":400,"ask_sz":1000,"bid_ct":1,"ask_ct":1},{"bid_px":"235.000000000","ask_px":"253.650000000","bid_sz":100,"ask_sz":400,"bid_ct":1,"ask_ct":1},{"bid_px":null,"ask_px":"960.000000000","bid_sz":0,"ask_sz":25,"bid_ct":0,"ask_ct":1},{"bid_px":null,"ask_px":null,"bid_sz":0,"ask_sz":0,"bid_ct":0,"ask_ct":0},{"bid_px":null,"ask_px":null,"bid_sz":0,"ask_sz":0,"bid_ct":0,"ask_ct":0},{"bid_px":null,"ask_px":null,"bid_sz":0,"ask_sz":0,"bid_ct":0,"ask_ct":0},{"bid_px":null,"ask_px":null,"bid_sz":0,"ask_sz":0,"bid_ct":0,"ask_ct":0},{"bid_px":null,"ask_px":null,"bid_sz":0,"ask_sz":0,"bid_ct":0,"ask_ct":0},{"bid_px":null,"ask_px":null,"bid_sz":0,"ask_sz":0,"bid_ct":0,"ask_ct":0}],"symbol":"TSLA"}
{"ts_recv":"2024-11-01T08:00:01.946482277Z","hd":{"ts_event":"2024-11-01T08:00:01.946315842Z","rtype":10,"publisher_id":2,"instrument_id":16244},"action":"A","side":"B","depth":0,"price":"250.200000000","size":50,"flags":130,"ts_in_delta":166435,"sequence":291446,"levels":[{"bid_px":"250.200000000","ask_px":"251.140000000","bid_sz":50,"ask_sz":100,"bid_ct":1,"ask_ct":1},{"bid_px":"249.600000000","ask_px":"252.400000000","bid_sz":1000,"ask_sz":1000,"bid_ct":1,"ask_ct":1},{"bid_px":"247.150000000","ask_px":"253.650000000","bid_sz":400,"ask_sz":400,"bid_ct":1,"ask_ct":1},{"bid_px":"235.000000000","ask_px":"960.000000000","bid_sz":100,"ask_sz":25,"bid_ct":1,"ask_ct":1},{"bid_px":null,"ask_px":null,"bid_sz":0,"ask_sz":0,"bid_ct":0,"ask_ct":0},{"bid_px":null,"ask_px":null,"bid_sz":0,"ask_sz":0,"bid_ct":0,"ask_ct":0},{"bid_px":null,"ask_px":null,"bid_sz":0,"ask_sz":0,"bid_ct":0,"ask_ct":0},{"bid_px":null,"ask_px":null,"bid_sz":0,"ask_sz":0,"bid_ct":0,"ask_ct":0},{"bid_px":null,"ask_px":null,"bid_sz":0,"ask_sz":0,"bid_ct":0,"ask_ct":0},{"bid_px":null,"ask_px":null,"bid_sz":0,"ask_sz":0,"bid_ct":0,"ask_ct":0}],"symbol":"TSLA"}
{"ts_recv":"2024-11-01T08:00:01.946561239Z","hd":{"ts_event":"2024-11-01T08:00:01.946395496Z","rtype":10,"publisher_id":2,"instrument_id":16244},"action":"C","side":"B","depth":0,"price":"250.200000000","size":50,"flags":130,"ts_in_delta":165743,"sequence":291447,"levels":[{"bid_px":"249.600000000","ask_px":"251.140000000","bid_sz":1000,"ask_sz":100,"bid_ct":1,"ask_ct":1},{"bid_px":"247.150000000","ask_px":"252.400000000","bid_sz":400,"ask_sz":1000,"bid_ct":1,"ask_ct":1},{"bid_px":"235.000000000","ask_px":"253.650000000","bid_sz":100,"ask_sz":400,"bid_ct":1,"ask_ct":1},{"bid_px":null,"ask_px":"960.000000000","bid_sz":0,"ask_sz":25,"bid_ct":0,"ask_ct":1},{"bid_px":null,"ask_px":null,"bid_sz":0,"ask_sz":0,"bid_ct":0,"ask_ct":0},{"bid_px":null,"ask_px":null,"bid_sz":0,"ask_sz":0,"bid_ct":0,"ask_ct":0},{"bid_px":null,"ask_px":null,"bid_sz":0,"ask_sz":0,"bid_ct":0,"ask_ct":0},{"bid_px":null,"ask_px":null,"bid_sz":0,"ask_sz":0,"bid_ct":0,"ask_ct":0},{"bid_px":null,"ask_px":null,"bid_sz":0,"ask_sz":0,"bid_ct":0,"ask_ct":0},{"bid_px":null,"ask_px":null,"bid_sz":0,"ask_sz":0,"bid_ct":0,"ask_ct":0}],"symbol":"TSLA"}
{"ts_recv":"2024-11-01T08:00:01.946573797Z","hd":{"ts_event":"2024-11-01T08:00:01.946407831Z","rtype":10,"publisher_id":2,"instrument_id":16244},"action":"A","side":"B","depth":0,"price":"250.170000000","size":50,"flags":130,"ts_in_delta":165966,"sequence":291448,"levels":[{"bid_px":"250.170000000","ask_px":"251.140000000","bid_sz":50,"ask_sz":100,"bid_ct":1,"ask_ct":1},{"bid_px":"249.600000000","ask_px":"252.400000000","bid_sz":1000,"ask_sz":1000,"bid_ct":1,"ask_ct":1},{"bid_px":"247.150000000","ask_px":"253.650000000","bid_sz":400,"ask_sz":400,"bid_ct":1,"ask_ct":1},{"bid_px":"235.000000000","ask_px":"960.000000000","bid_sz":100,"ask_sz":25,"bid_ct":1,"ask_ct":1},{"bid_px":null,"ask_px":null,"bid_sz":0,"ask_sz":0,"bid_ct":0,"ask_ct":0},{"bid_px":null,"ask_px":null,"bid_sz":0,"ask_sz":0,"bid_ct":0,"ask_ct":0},{"bid_px":null,"ask_px":null,"bid_sz":0,"ask_sz":0,"bid_ct":0,"ask_ct":0},{"bid_px":null,"ask_px":null,"bid_sz":0,"ask_sz":0,"bid_ct":0,"ask_ct":0},{"bid_px":null,"ask_px":null,"bid_sz":0,"ask_sz":0,"bid_ct":0,"ask_ct":0},{"bid_px":null,"ask_px":null,"bid_sz":0,"ask_sz":0,"bid_ct":0,"ask_ct":0}],"symbol":"TSLA"}
{"ts_recv":"2024-11-01T08:00:01.946600876Z","hd":{"ts_event":"2024-11-01T08:00:01.946435553Z","rtype":10,"publisher_id":2,"instrument_id":16244},"action":"C","side":"B","depth":0,"price":"250.170000000","size":50,"flags":130,"ts_in_delta":165323,"sequence":291449,"levels":[{"bid_px":"249.600000000","ask_px":"251.140000000","bid_sz":1000,"ask_sz":100,"bid_ct":1,"ask_ct":1},{"bid_px":"247.150000000","ask_px":"252.400000000","bid_sz":400,"ask_sz":1000,"bid_ct":1,"ask_ct":1},{"bid_px":"235.000000000","ask_px":"253.650000000","bid_sz":100,"ask_sz":400,"bid_ct":1,"ask_ct":1},{"bid_px":null,"ask_px":"960.000000000","bid_sz":0,"ask_sz":25,"bid_ct":0,"ask_ct":1},{"bid_px":null,"ask_px":null,"bid_sz":0,"ask_sz":0,"bid_ct":0,"ask_ct":0},{"bid_px":null,"ask_px":null,"bid_sz":0,"ask_sz":0,"bid_ct":0,"ask_ct":0},{"bid_px":null,"ask_px":null,"bid_sz":0,"ask_sz":0,"bid_ct":0,"ask_ct":0},{"bid_px":null,"ask_px":null,"bid_sz":0,"ask_sz":0,"bid_ct":0,"ask_ct":0},{"bid_px":null,"ask_px":null,"bid_sz":0,"ask_sz":0,"bid_ct":0,"ask_ct":0},{"bid_px":null,"ask_px":null,"bid_sz":0,"ask_sz":0,"bid_ct":0,"ask_ct":0}],"symbol":"TSLA"}
{"ts_recv":"2024-11-01T08:00:01.947101210Z","hd":{"ts_event":"2024-11-01T08:00:01.946935533Z","rtype":10,"publisher_id":2,"instrument_id":16244},"action":"C","side":"B","depth":0,"price":"249.600000000","size":1000,"flags":130,"ts_in_delta":165677,"sequence":291450,"levels":[{"bid_px":"247.150000000","ask_px":"251.140000000","bid_sz":400,"ask_sz":100,"bid_ct":1,"ask_ct":1},{"bid_px":"235.000000000","ask_px":"252.400000000","bid_sz":100,"ask_sz":1000,"bid_ct":1,"ask_ct":1},{"bid_px":null,"ask_px":"253.650000000","bid_sz":0,"ask_sz":400,"bid_ct":0,"ask_ct":1},{"bid_px":null,"ask_px":"960.000000000","bid_sz":0,"ask_sz":25,"bid_ct":0,"ask_ct":1},{"bid_px":null,"ask_px":null,"bid_sz":0,"ask_sz":0,"bid_ct":0,"ask_ct":0},{"bid_px":null,"ask_px":null,"bid_sz":0,"ask_sz":0,"bid_ct":0,"ask_ct":0},{"bid_px":null,"ask_px":null,"bid_sz":0,"ask_sz":0,"bid_ct":0,"ask_ct":0},{"bid_px":null,"ask_px":null,"bid_sz":0,"ask_sz":0,"bid_ct":0,"ask_ct":0},{"bid_px":null,"ask_px":null,"bid_sz":0,"ask_sz":0,"bid_ct":0,"ask_ct":0},{"bid_px":null,"ask_px":null,"bid_sz":0,"ask_sz":0,"bid_ct":0,"ask_ct":0}],"symbol":"TSLA"}
{"ts_recv":"2024-11-01T08:00:01.958539201Z","hd":{"ts_event":"2024-11-01T08:00:01.958372688Z","rtype":10,"publisher_id":2,"instrument_id":16244},"action":"A","side":"B","depth":0,"price":"249.400000000","size":1000,"flags":130,"ts_in_delta":166513,"sequence":291461,"levels":[{"bid_px":"249.400000000","ask_px":"251.140000000","bid_sz":1000,"ask_sz":100,"bid_ct":1,"ask_ct":1},{"bid_px":"247.150000000","ask_px":"252.400000000","bid_sz":400,"ask_sz":1000,"bid_ct":1,"ask_ct":1},{"bid_px":"235.000000000","ask_px":"253.650000000","bid_sz":100,"ask_sz":400,"bid_ct":1,"ask_ct":1},{"bid_px":null,"ask_px":"960.000000000","bid_sz":0,"ask_sz":25,"bid_ct":0,"ask_ct":1},{"bid_px":null,"ask_px":null,"bid_sz":0,"ask_sz":0,"bid_ct":0,"ask_ct":0},{"bid_px":null,"ask_px":null,"bid_sz":0,"ask_sz":0,"bid_ct":0,"ask_ct":0},{"bid_px":null,"ask_px":null,"bid_sz":0,"ask_sz":0,"bid_ct":0,"ask_ct":0},{"bid_px":null,"ask_px":null,"bid_sz":0,"ask_sz":0,"bid_ct":0,"ask_ct":0},{"bid_px":null,"ask_px":null,"bid_sz":0,"ask_sz":0,"bid_ct":0,"ask_ct":0},{"bid_px":null,"ask_px":null,"bid_sz":0,"ask_sz":0,"bid_ct":0,"ask_ct":0}],"symbol":"TSLA"}
{"ts_recv":"2024-11-01T08:00:01.987700128Z","hd":{"ts_event":"2024-11-01T08:00:01.987534676Z","rtype":10,"publisher_id":2,"instrument_id":16244},"action":"C","side":"B","depth":0,"price":"249.400000000","size":1000,"flags":130,"ts_in_delta":165452,"sequence":291501,"levels":[{"bid_px":"247.150000000","ask_px":"251.140000000","bid_sz":400,"ask_sz":100,"bid_ct":1,"ask_ct":1},{"bid_px":"235.000000000","ask_px":"252.400000000","bid_sz":100,"ask_sz":1000,"bid_ct":1,"ask_ct":1},{"bid_px":null,"ask_px":"253.650000000","bid_sz":0,"ask_sz":400,"bid_ct":0,"ask_ct":1},{"bid_px":null,"ask_px":"960.000000000","bid_sz":0,"ask_sz":25,"bid_ct":0,"ask_ct":1},{"bid_px":null,"ask_px":null,"bid_sz":0,"ask_sz":0,"bid_ct":0,"ask_ct":0},{"bid_px":null,"ask_px":null,"bid_sz":0,"ask_sz":0,"bid_ct":0,"ask_ct":0},{"bid_px":null,"ask_px":null,"bid_sz":0,"ask_sz":0,"bid_ct":0,"ask_ct":0},{"bid_px":null,"ask_px":null,"bid_sz":0,"ask_sz":0,"bid_ct":0,"ask_ct":0},{"bid_px":null,"ask_px":null,"bid_sz":0,"ask_sz":0,"bid_ct":0,"ask_ct":0},{"bid_px":null,"ask_px":null,"bid_sz":0,"ask_sz":0,"bid_ct":0,"ask_ct":0}],"symbol":"TSLA"}
{"ts_recv":"2024-11-01T08:00:01.997110302Z","hd":{"ts_event":"2024-11-01T08:00:01.996944436Z","rtype":10,"publisher_id":2,"instrument_id":16244},"action":"A","side":"A","depth":1,"price":"251.400000000","size":1000,"flags":130,"ts_in_delta":165866,"sequence":291530,"levels":[{"bid_px":"247.150000000","ask_px":"251.140000000","bid_sz":400,"ask_sz":100,"bid_ct":1,"ask_ct":1},{"bid_px":"235.000000000","ask_px":"251.400000000","bid_sz":100,"ask_sz":1000,"bid_ct":1,"ask_ct":1},{"bid_px":null,"ask_px":"252.400000000","bid_sz":0,"ask_sz":1000,"bid_ct":0,"ask_ct":1},{"bid_px":null,"ask_px":"253.650000000","bid_sz":0,"ask_sz":400,"bid_ct":0,"ask_ct":1},{"bid_px":null,"ask_px":"960.000000000","bid_sz":0,"ask_sz":25,"bid_ct":0,"ask_ct":1},{"bid_px":null,"ask_px":null,"bid_sz":0,"ask_sz":0,"bid_ct":0,"ask_ct":0},{"bid_px":null,"ask_px":null,"bid_sz":0,"ask_sz":0,"bid_ct":0,"ask_ct":0},{"bid_px":null,"ask_px":null,"bid_sz":0,"ask_sz":0,"bid_ct":0,"ask_ct":0},{"bid_px":null,"ask_px":null,"bid_sz":0,"ask_sz":0,"bid_ct":0,"ask_ct":0},{"bid_px":null,"ask_px":null,"bid_sz":0,"ask_sz":0,"bid_ct":0,"ask_ct":0}],"symbol":"TSLA"}
{"ts_recv":"2024-11-01T08:00:01.997612898Z","hd":{"ts_event":"2024-11-01T08:00:01.997446238Z","rtype":10,"publisher_id":2,"instrument_id":16244},"action":"C","side":"A","depth":1,"price":"251.400000000","size":1000,"flags":130,"ts_in_delta":166660,"sequence":291535,"levels":[{"bid_px":"247.150000000","ask_px":"251.140000000","bid_sz":400,"ask_sz":100,"bid_ct":1,"ask_ct":1},{"bid_px":"235.000000000","ask_px":"252.400000000","bid_sz":100,"ask_sz":1000,"bid_ct":1,"ask_ct":1},{"bid_px":null,"ask_px":"253.650000000","bid_sz":0,"ask_sz":400,"bid_ct":0,"ask_ct":1},{"bid_px":null,"ask_px":"960.000000000","bid_sz":0,"ask_sz":25,"bid_ct":0,"ask_ct":1},{"bid_px":null,"ask_px":null,"bid_sz":0,"ask_sz":0,"bid_ct":0,"ask_ct":0},{"bid_px":null,"ask_px":null,"bid_sz":0,"ask_sz":0,"bid_ct":0,"ask_ct":0},{"bid_px":null,"ask_px":null,"bid_sz":0,"ask_sz":0,"bid_ct":0,"ask_ct":0},{"bid_px":null,"ask_px":null,"bid_sz":0,"ask_sz":0,"bid_ct":0,"ask_ct":0},{"bid_px":null,"ask_px":null,"bid_sz":0,"ask_sz":0,"bid_ct":0,"ask_ct":0},{"bid_px":null,"ask_px":null,"bid_sz":0,"ask_sz":0,"bid_ct":0,"ask_ct":0}],"symbol":"TSLA"}
{"ts_recv":"2024-11-01T08:00:02.016857213Z","hd":{"ts_event":"2024-11-01T08:00:02.016691039Z","rtype":10,"publisher_id":2,"instrument_id":11667},"action":"A","side":"B","depth":1,"price":"134.730000000","size":61,"flags":130,"ts_in_delta":166174,"sequence":291570,"levels":[{"bid_px":"134.770000000","ask_px":"135.300000000","bid_sz":100,"ask_sz":1000,"bid_ct":1,"ask_ct":1},{"bid_px":"134.730000000","ask_px":"136.100000000","bid_sz":61,"ask_sz":1000,"bid_ct":1,"ask_ct":1},{"bid_px":"134.410000000","ask_px":"137.680000000","bid_sz":1,"ask_sz":500,"bid_ct":1,"ask_ct":1},{"bid_px":"134.210000000","ask_px":"138.870000000","bid_sz":20,"ask_sz":1000,"bid_ct":1,"ask_ct":2},{"bid_px":"133.200000000","ask_px":"140.740000000","bid_sz":1000,"ask_sz":100,"bid_ct":1,"ask_ct":1},{"bid_px":"132.000000000","ask_px":"140.880000000","bid_sz":71,"ask_sz":1000,"bid_ct":2,"ask_ct":2},{"bid_px":"129.050000000","ask_px":"143.690000000","bid_sz":500,"ask_sz":500,"bid_ct":1,"ask_ct":1},{"bid_px":"128.470000000","ask_px":"146.510000000","bid_sz":500,"ask_sz":5,"bid_ct":1,"ask_ct":1},{"bid_px":"127.680000000","ask_px":"148.000000000","bid_sz":30,"ask_sz":5,"bid_ct":1,"ask_ct":1},{"bid_px":"127.000000000","ask_px":null,"bid_sz":20,"ask_sz":0,"bid_ct":1,"ask_ct":0}],"symbol":"NVDA"}
{"ts_recv":"2024-11-01T08:00:02.025313199Z","hd":{"ts_event":"2024-11-01T08:00:02.025146947Z","rtype":10,"publisher_id":2,"instrument_id":16244},"action":"A","side":"B","depth":0,"price":"249.800000000","size":1000,"flags":130,"ts_in_delta":166252,"sequence":291575,"levels":[{"bid_px":"249.800000000","ask_px":"251.140000000","bid_sz":1000,"ask_sz":100,"bid_ct":1,"ask_ct":1},{"bid_px":"247.150000000","ask_px":"252.400000000","bid_sz":400,"ask_sz":1000,"bid_ct":1,"ask_ct":1},{"bid_px":"235.000000000","ask_px":"253.650000000","bid_sz":100,"ask_sz":400,"bid_ct":1,"ask_ct":1},{"bid_px":null,"ask_px":"960.000000000","bid_sz":0,"ask_sz":25,"bid_ct":0,"ask_ct":1},{"bid_px":null,"ask_px":null,"bid_sz":0,"ask_sz":0,"bid_ct":0,"ask_ct":0},{"bid_px":null,"ask_px":null,"bid_sz":0,"ask_sz":0,"bid_ct":0,"ask_ct":0},{"bid_px":null,"ask_px":null,"bid_sz":0,"ask_sz":0,"bid_ct":0,"ask_ct":0},{"bid_px":null,"ask_px":null,"bid_sz":0,"ask_sz":0,"bid_ct":0,"ask_ct":0},{"bid_px":null,"ask_px":null,"bid_sz":0,"ask_sz":0,"bid_ct":0,"ask_ct":0},{"bid_px":null,"ask_px":null,"bid_sz":0,"ask_sz":0,"bid_ct":0,"ask_ct":0}],"symbol":"TSLA"}
{"ts_recv":"2024-11-01T08:00:02.026542310Z","hd":{"ts_event":"2024-11-01T08:00:02.026376594Z","rtype":10,"publisher_id":2,"instrument_id":16244},"action":"C","side":"B","depth":0,"price":"249.800000000","size":1000,"flags":130,"ts_in_delta":165716,"sequence":291578,"levels":[{"bid_px":"247.150000000","ask_px":"251.140000000","bid_sz":400,"ask_sz":100,"bid_ct":1,"ask_ct":1},{"bid_px":"235.000000000","ask_px":"252.400000000","bid_sz":100,"ask_sz":1000,"bid_ct":1,"ask_ct":1},{"bid_px":null,"ask_px":"253.650000000","bid_sz":0,"ask_sz":400,"bid_ct":0,"ask_ct":1},{"bid_px":null,"ask_px":"960.000000000","bid_sz":0,"ask_sz":25,"bid_ct":0,"ask_ct":1},{"bid_px":null,"ask_px":null,"bid_sz":0,"ask_sz":0,"bid_ct":0,"ask_ct":0},{"bid_px":null,"ask_px":null,"bid_sz":0,"ask_sz":0,"bid_ct":0,"ask_ct":0},{"bid_px":null,"ask_px":null,"bid_sz":0,"ask_sz":0,"bid_ct":0,"ask_ct":0},{"bid_px":null,"ask_px":null,"bid_sz":0,"ask_sz":0,"bid_ct":0,"ask_ct":0},{"bid_px":null,"ask_px":null,"bid_sz":0,"ask_sz":0,"bid_ct":0,"ask_ct":0},{"bid_px":null,"ask_px":null,"bid_sz":0,"ask_sz":0,"bid_ct":0,"ask_ct":0}],"symbol":"TSLA"}
{"ts_recv":"2024-11-01T08:00:02.037412574Z","hd":{"ts_event":"2024-11-01T08:00:02.037246234Z","rtype":10,"publisher_id":2,"instrument_id":16244},"action":"A","side":"B","depth":0,"price":"249.800000000","size":1000,"flags":130,"ts_in_delta":166340,"sequence":291588,"levels":[{"bid_px":"249.800000000","ask_px":"251.140000000","bid_sz":1000,"ask_sz":100,"bid_ct":1,"ask_ct":1},{"bid_px":"247.150000000","ask_px":"252.400000000","bid_sz":400,"ask_sz":1000,"bid_ct":1,"ask_ct":1},{"bid_px":"235.000000000","ask_px":"253.650000000","bid_sz":100,"ask_sz":400,"bid_ct":1,"ask_ct":1},{"bid_px":null,"ask_px":"960.000000000","bid_sz":0,"ask_sz":25,"bid_ct":0,"ask_ct":1},{"bid_px":null,"ask_px":null,"bid_sz":0,"ask_sz":0,"bid_ct":0,"ask_ct":0},{"bid_px":null,"ask_px":null,"bid_sz":0,"ask_sz":0,"bid_ct":0,"ask_ct":0},{"bid_px":null,"ask_px":null,"bid_sz":0,"ask_sz":0,"bid_ct":0,"ask_ct":0},{"bid_px":null,"ask_px":null,"bid_sz":0,"ask_sz":0,"bid_ct":0,"ask_ct":0},{"bid_px":null,"ask_px":null,"bid_sz":0,"ask_sz":0,"bid_ct":0,"ask_ct":0},{"bid_px":null,"ask_px":null,"bid_sz":0,"ask_sz":0,"bid_ct":0,"ask_ct":0}],"symbol":"TSLA"}
{"ts_recv":"2024-11-01T08:00:02.040002923Z","hd":{"ts_event":"2024-11-01T08:00:02.039837284Z","rtype":10,"publisher_id":2,"instrument_id":11667},"action":"C","side":"B","depth":1,"price":"134.730000000","size":61,"flags":130,"ts_in_delta":165639,"sequence":291600,"levels":[{"bid_px":"134.770000000","ask_px":"135.300000000","bid_sz":100,"ask_sz":1000,"bid_ct":1,"ask_ct":1},{"bid_px":"134.410000000","ask_px":"136.100000000","bid_sz":1,"ask_sz":1000,"bid_ct":1,"ask_ct":1},{"bid_px":"134.210000000","ask_px":"137.680000000","bid_sz":20,"ask_sz":500,"bid_ct":1,"ask_ct":1},{"bid_px":"133.200000000","ask_px":"138.870000000","bid_sz":1000,"ask_sz":1000,"bid_ct":1,"ask_ct":2},{"bid_px":"132.000000000","ask_px":"140.740000000","bid_sz":71,"ask_sz":100,"bid_ct":2,"ask_ct":1},{"bid_px":"129.050000000","ask_px":"140.880000000","bid_sz":500,"ask_sz":1000,"bid_ct":1,"ask_ct":2},{"bid_px":"128.470000000","ask_px":"143.690000000","bid_sz":500,"ask_sz":500,"bid_ct":1,"ask_ct":1},{"bid_px":"127.680000000","ask_px":"146.510000000","bid_sz":30,"ask_sz":5,"bid_ct":1,"ask_ct":1},{"bid_px":"127.000000000","ask_px":"148.000000000","bid_sz":20,"ask_sz":5,"bid_ct":1,"ask_ct":1},{"bid_px":null,"ask_px":null,"bid_sz":0,"ask_sz":0,"bid_ct":0,"ask_ct":0}],"symbol":"NVDA"}
{"ts_recv":"2024-11-01T08:00:02.059422962Z","hd":{"ts_event":"2024-11-01T08:00:02.059257397Z","rtype":10,"publisher_id":2,"instrument_id":16244},"action":"C","side":"B","depth":0,"price":"249.800000000","size":1000,"flags":130,"ts_in_delta":165565,"sequence":291627,"levels":[{"bid_px":"247.150000000","ask_px":"251.140000000","bid_sz":400,"ask_sz":100,"bid_ct":1,"ask_ct":1},{"bid_px":"235.000000000","ask_px":"252.400000000","bid_sz":100,"ask_sz":1000,"bid_ct":1,"ask_ct":1},{"bid_px":null,"ask_px":"253.650000000","bid_sz":0,"ask_sz":400,"bid_ct":0,"ask_ct":1},{"bid_px":null,"ask_px":"960.000000000","bid_sz":0,"ask_sz":25,"bid_ct":0,"ask_ct":1},{"bid_px":null,"ask_px":null,"bid_sz":0,"ask_sz":0,"bid_ct":0,"ask_ct":0},{"bid_px":null,"ask_px":null,"bid_sz":0,"ask_sz":0,"bid_ct":0,"ask_ct":0},{"bid_px":null,"ask_px":null,"bid_sz":0,"ask_sz":0,"bid_ct":0,"ask_ct":0},{"bid_px":null,"ask_px":null,"bid_sz":0,"ask_sz":0,"bid_ct":0,"ask_ct":0},{"bid_px":null,"ask_px":null,"bid_sz":0,"ask_sz":0,"bid_ct":0,"ask_ct":0},{"bid_px":null,"ask_px":null,"bid_sz":0,"ask_sz":0,"bid_ct":0,"ask_ct":0}],"symbol":"TSLA"}
{"ts_recv":"2024-11-01T08:00:02.070468260Z","hd":{"ts_event":"2024-11-01T08:00:02.070301937Z","rtype":10,"publisher_id":2,"instrument_id":16244},"action":"A","side":"B","depth":0,"price":"249.700000000","size":1000,"flags":130,"ts_in_delta":166323,"sequence":291635,"levels":[{"bid_px":"249.700000000","ask_px":"251.140000000","bid_sz":1000,"ask_sz":100,"bid_ct":1,"ask_ct":1},{"bid_px":"247.150000000","ask_px":"252.400000000","bid_sz":400,"ask_sz":1000,"bid_ct":1,"ask_ct":1},{"bid_px":"235.000000000","ask_px":"253.650000000","bid_sz":100,"ask_sz":400,"bid_ct":1,"ask_ct":1},{"bid_px":null,"ask_px":"960.000000000","bid_sz":0,"ask_sz":25,"bid_ct":0,"ask_ct":1},{"bid_px":null,"ask_px":null,"bid_sz":0,"ask_sz":0,"bid_ct":0,"ask_ct":0},{"bid_px":null,"ask_px":null,"bid_sz":0,"ask_sz":0,"bid_ct":0,"ask_ct":0},{"bid_px":null,"ask_px":null,"bid_sz":0,"ask_sz":0,"bid_ct":0,"ask_ct":0},{"bid_px":null,"ask_px":null,"bid_sz":0,"ask_sz":0,"bid_ct":0,"ask_ct":0},{"bid_px":null,"ask_px":null,"bid_sz":0,"ask_sz":0,"bid_ct":0,"ask_ct":0},{"bid_px":null,"ask_px":null,"bid_sz":0,"ask_sz":0,"bid_ct":0,"ask_ct":0}],"symbol":"TSLA"}
{"ts_recv":"2024-11-01T08:00:02.074574181Z","hd":{"ts_event":"2024-11-01T08:00:02.074408476Z","rtype":10,"publisher_id":2,"instrument_id":16244},"action":"C","side":"B","depth":0,"price":"249.700000000","size":1000,"flags":130,"ts_in_delta":165705,"sequence":291641,"levels":[{"bid_px":"247.150000000","ask_px":"251.140000000","bid_sz":400,"ask_sz":100,"bid_ct":1,"ask_ct":1},{"bid_px":"235.000000000","ask_px":"252.400000000","bid_sz":100,"ask_sz":1000,"bid_ct":1,"ask_ct":1},{"bid_px":null,"ask_px":"253.650000000","bid_sz":0,"ask_sz":400,"bid_ct":0,"ask_ct":1},{"bid_px":null,"ask_px":"960.000000000","bid_sz":0,"ask_sz":25,"bid_ct":0,"ask_ct":1},{"bid_px":null,"ask_px":null,"bid_sz":0,"ask_sz":0,"bid_ct":0,"ask_ct":0},{"bid_px":null,"ask_px":null,"bid_sz":0,"ask_sz":0,"bid_ct":0,"ask_ct":0},{"bid_px":null,"ask_px":null,"bid_sz":0,"ask_sz":0,"bid_ct":0,"ask_ct":0},{"bid_px":null,"ask_px":null,"bid_sz":0,"ask_sz":0,"bid_ct":0,"ask_ct":0},{"bid_px":null,"ask_px":null,"bid_sz":0,"ask_sz":0,"bid_ct":0,"ask_ct":0},{"bid_px":null,"ask_px":null,"bid_sz":0,"ask_sz":0,"bid_ct":0,"ask_ct":0}],"symbol":"TSLA"}
{"ts_recv":"2024-11-01T08:00:02.111309439Z","hd":{"ts_event":"2024-11-01T08:00:02.111143168Z","rtype":10,"publisher_id":2,"instrument_id":16244},"action":"A","side":"B","depth":0,"price":"249.600000000","size":1000,"flags":130,"ts_in_delta":166271,"sequence":291698,"levels":[{"bid_px":"249.600000000","ask_px":"251.140000000","bid_sz":1000,"ask_sz":100,"bid_ct":1,"ask_ct":1},{"bid_px":"247.150000000","ask_px":"252.400000000","bid_sz":400,"ask_sz":1000,"bid_ct":1,"ask_ct":1},{"bid_px":"235.000000000","ask_px":"253.650000000","bid_sz":100,"ask_sz":400,"bid_ct":1,"ask_ct":1},{"bid_px":null,"ask_px":"960.000000000","bid_sz":0,"ask_sz":25,"bid_ct":0,"ask_ct":1},{"bid_px":null,"ask_px":null,"bid_sz":0,"ask_sz":0,"bid_ct":0,"ask_ct":0},{"bid_px":null,"ask_px":null,"bid_sz":0,"ask_sz":0,"bid_ct":0,"ask_ct":0},{"bid_px":null,"ask_px":null,"bid_sz":0,"ask_sz":0,"bid_ct":0,"ask_ct":0},{"bid_px":null,"ask_px":null,"bid_sz":0,"ask_sz":0,"bid_ct":0,"ask_ct":0},{"bid_px":null,"ask_px":null,"bid_sz":0,"ask_sz":0,"bid_ct":0,"ask_ct":0},{"bid_px":null,"ask_px":null,"bid_sz":0,"ask_sz":0,"bid_ct":0,"ask_ct":0}],"symbol":"TSLA"}
{"ts_recv":"2024-11-01T08:00:02.139266720Z","hd":{"ts_event":"2024-11-01T08:00:02.139100235Z","rtype":10,"publisher_id":2,"instrument_id":16244},"action":"A","side":"B","depth":0,"price":"249.900000000","size":1000,"flags":130,"ts_in_delta":166485,"sequence":291729,"levels":[{"bid_px":"249.900000000","ask_px":"251.140000000","bid_sz":1000,"ask_sz":100,"bid_ct":1,"ask_ct":1},{"bid_px":"249.600000000","ask_px":"252.400000000","bid_sz":1000,"ask_sz":1000,"bid_ct":1,"ask_ct":1},{"bid_px":"247.150000000","ask_px":"253.650000000","bid_sz":400,"ask_sz":400,"bid_ct":1,"ask_ct":1},{"bid_px":"235.000000000","ask_px":"960.000000000","bid_sz":100,"ask_sz":25,"bid_ct":1,"ask_ct":1},{"bid_px":null,"ask_px":null,"bid_sz":0,"ask_sz":0,"bid_ct":0,"ask_ct":0},{"bid_px":null,"ask_px":null,"bid_sz":0,"ask_sz":0,"bid_ct":0,"ask_ct":0},{"bid_px":null,"ask_px":null,"bid_sz":0,"ask_sz":0,"bid_ct":0,"ask_ct":0},{"bid_px":null,"ask_px":null,"bid_sz":0,"ask_sz":0,"bid_ct":0,"ask_ct":0},{"bid_px":null,"ask_px":null,"bid_sz":0,"ask_sz":0,"bid_ct":0,"ask_ct":0},{"bid_px":null,"ask_px":null,"bid_sz":0,"ask_sz":0,"bid_ct":0,"ask_ct":0}],"symbol":"TSLA"}
{"ts_recv":"2024-11-01T08:00:02.139322548Z","hd":{"ts_event":"2024-11-01T08:00:02.139155746Z","rtype":10,"publisher_id":2,"instrument_id":16244},"action":"C","side":"B","depth":1,"price":"249.600000000","size":1000,"flags":130,"ts_in_delta":166802,"sequence":291730,"levels":[{"bid_px":"249.900000000","ask_px":"251.140000000","bid_sz":1000,"ask_sz":100,"bid_ct":1,"ask_ct":1},{"bid_px":"247.150000000","ask_px":"252.400000000","bid_sz":400,"ask_sz":1000,"bid_ct":1,"ask_ct":1},{"bid_px":"235.000000000","ask_px":"253.650000000","bid_sz":100,"ask_sz":400,"bid_ct":1,"ask_ct":1},{"bid_px":null,"ask_px":"960.000000000","bid_sz":0,"ask_sz":25,"bid_ct":0,"ask_ct":1},{"bid_px":null,"ask_px":null,"bid_sz":0,"ask_sz":0,"bid_ct":0,"ask_ct":0},{"bid_px":null,"ask_px":null,"bid_sz":0,"ask_sz":0,"bid_ct":0,"ask_ct":0},{"bid_px":null,"ask_px":null,"bid_sz":0,"ask_sz":0,"bid_ct":0,"ask_ct":0},{"bid_px":null,"ask_px":null,"bid_sz":0,"ask_sz":0,"bid_ct":0,"ask_ct":0},{"bid_px":null,"ask_px":null,"bid_sz":0,"ask_sz":0,"bid_ct":0,"ask_ct":0},{"bid_px":null,"ask_px":null,"bid_sz":0,"ask_sz":0,"bid_ct":0,"ask_ct":0}],"symbol":"TSLA"}
{"ts_recv":"2024-11-01T08:00:02.143874005Z","hd":{"ts_event":"2024-11-01T08:00:02.143707801Z","rtype":10,"publisher_id":2,"instrument_id":16244},"action":"A","side":"B","depth":3,"price":"203.000000000","size":2,"flags":130,"ts_in_delta":166204,"sequence":291748,"levels":[{"bid_px":"249.900000000","ask_px":"251.140000000","bid_sz":1000,"ask_sz":100,"bid_ct":1,"ask_ct":1},{"bid_px":"247.150000000","ask_px":"252.400000000","bid_sz":400,"ask_sz":1000,"bid_ct":1,"ask_ct":1},{"bid_px":"235.000000000","ask_px":"253.650000000","bid_sz":100,"ask_sz":400,"bid_ct":1,"ask_ct":1},{"bid_px":"203.000000000","ask_px":"960.000000000","bid_sz":2,"ask_sz":25,"bid_ct":1,"ask_ct":1},{"bid_px":null,"ask_px":null,"bid_sz":0,"ask_sz":0,"bid_ct":0,"ask_ct":0},{"bid_px":null,"ask_px":null,"bid_sz":0,"ask_sz":0,"bid_ct":0,"ask_ct":0},{"bid_px":null,"ask_px":null,"bid_sz":0,"ask_sz":0,"bid_ct":0,"ask_ct":0},{"bid_px":null,"ask_px":null,"bid_sz":0,"ask_sz":0,"bid_ct":0,"ask_ct":0},{"bid_px":null,"ask_px":null,"bid_sz":0,"ask_sz":0,"bid_ct":0,"ask_ct":0},{"bid_px":null,"ask_px":null,"bid_sz":0,"ask_sz":0,"bid_ct":0,"ask_ct":0}],"symbol":"TSLA"}
{"ts_recv":"2024-11-01T08:00:02.150347466Z","hd":{"ts_event":"2024-11-01T08:00:02.150181297Z","rtype":10,"publisher_id":2,"instrument_id":16244},"action":"A","side":"B","depth":1,"price":"248.500000000","size":1000,"flags":130,"ts_in_delta":166169,"sequence":291750,"levels":[{"bid_px":"249.900000000","ask_px":"251.140000000","bid_sz":1000,"ask_sz":100,"bid_ct":1,"ask_ct":1},{"bid_px":"248.500000000","ask_px":"252.400000000","bid_sz":1000,"ask_sz":1000,"bid_ct":1,"ask_ct":1},{"bid_px":"247.150000000","ask_px":"253.650000000","bid_sz":400,"ask_sz":400,"bid_ct":1,"ask_ct":1},{"bid_px":"235.000000000","ask_px":"960.000000000","bid_sz":100,"ask_sz":25,"bid_ct":1,"ask_ct":1},{"bid_px":"203.000000000","ask_px":null,"bid_sz":2,"ask_sz":0,"bid_ct":1,"ask_ct":0},{"bid_px":null,"ask_px":null,"bid_sz":0,"ask_sz":0,"bid_ct":0,"ask_ct":0},{"bid_px":null,"ask_px":null,"bid_sz":0,"ask_sz":0,"bid_ct":0,"ask_ct":0},{"bid_px":null,"ask_px":null,"bid_sz":0,"ask_sz":0,"bid_ct":0,"ask_ct":0},{"bid_px":null,"ask_px":null,"bid_sz":0,"ask_sz":0,"bid_ct":0,"ask_ct":0},{"bid_px":null,"ask_px":null,"bid_sz":0,"ask_sz":0,"bid_ct":0,"ask_ct":0}],"symbol":"TSLA"}
{"ts_recv":"2024-11-01T08:00:02.160208746Z","hd":{"ts_event":"2024-11-01T08:00:02.160042857Z","rtype":10,"publisher_id":2,"instrument_id":16244},"action":"C","side":"B","depth":1,"price":"248.500000000","size":1000,"flags":130,"ts_in_delta":165889,"sequence":291766,"levels":[{"bid_px":"249.900000000","ask_px":"251.140000000","bid_sz":1000,"ask_sz":100,"bid_ct":1,"ask_ct":1},{"bid_px":"247.150000000","ask_px":"252.400000000","bid_sz":400,"ask_sz":1000,"bid_ct":1,"ask_ct":1},{"bid_px":"235.000000000","ask_px":"253.650000000","bid_sz":100,"ask_sz":400,"bid_ct":1,"ask_ct":1},{"bid_px":"203.000000000","ask_px":"960.000000000","bid_sz":2,"ask_sz":25,"bid_ct":1,"ask_ct":1},{"bid_px":null,"ask_px":null,"bid_sz":0,"ask_sz":0,"bid_ct":0,"ask_ct":0},{"bid_px":null,"ask_px":null,"bid_sz":0,"ask_sz":0,"bid_ct":0,"ask_ct":0},{"bid_px":null,"ask_px":null,"bid_sz":0,"ask_sz":0,"bid_ct":0,"ask_ct":0},{"bid_px":null,"ask_px":null,"bid_sz":0,"ask_sz":0,"bid_ct":0,"ask_ct":0},{"bid_px":null,"ask_px":null,"bid_sz":0,"ask_sz":0,"bid_ct":0,"ask_ct":0},{"bid_px":null,"ask_px":null,"bid_sz":0,"ask_sz":0,"bid_ct":0,"ask_ct":0}],"symbol":"TSLA"}
{"ts_recv":"2024-11-01T08:00:02.160509269Z","hd":{"ts_event":"2024-11-01T08:00:02.160343613Z","rtype":10,"publisher_id":2,"instrument_id":16244},"action":"C","side":"B","depth":0,"price":"249.900000000","size":1000,"flags":130,"ts_in_delta":165656,"sequence":291767,"levels":[{"bid_px":"247.150000000","ask_px":"251.140000000","bid_sz":400,"ask_sz":100,"bid_ct":1,"ask_ct":1},{"bid_px":"235.000000000","ask_px":"252.400000000","bid_sz":100,"ask_sz":1000,"bid_ct":1,"ask_ct":1},{"bid_px":"203.000000000","ask_px":"253.650000000","bid_sz":2,"ask_sz":400,"bid_ct":1,"ask_ct":1},{"bid_px":null,"ask_px":"960.000000000","bid_sz":0,"ask_sz":25,"bid_ct":0,"ask_ct":1},{"bid_px":null,"ask_px":null,"bid_sz":0,"ask_sz":0,"bid_ct":0,"ask_ct":0},{"bid_px":null,"ask_px":null,"bid_sz":0,"ask_sz":0,"bid_ct":0,"ask_ct":0},{"bid_px":null,"ask_px":null,"bid_sz":0,"ask_sz":0,"bid_ct":0,"ask_ct":0},{"bid_px":null,"ask_px":null,"bid_sz":0,"ask_sz":0,"bid_ct":0,"ask_ct":0},{"bid_px":null,"ask_px":null,"bid_sz":0,"ask_sz":0,"bid_ct":0,"ask_ct":0},{"bid_px":null,"ask_px":null,"bid_sz":0,"ask_sz":0,"bid_ct":0,"ask_ct":0}],"symbol":"TSLA"}
{"ts_recv":"2024-11-01T08:00:02.171672991Z","hd":{"ts_event":"2024-11-01T08:00:02.171506732Z","rtype":10,"publisher_id":2,"instrument_id":16244},"action":"A","side":"B","depth":0,"price":"249.800000000","size":1000,"flags":130,"ts_in_delta":166259,"sequence":291778,"levels":[{"bid_px":"249.800000000","ask_px":"251.140000000","bid_sz":1000,"ask_sz":100,"bid_ct":1,"ask_ct":1},{"bid_px":"247.150000000","ask_px":"252.400000000","bid_sz":400,"ask_sz":1000,"bid_ct":1,"ask_ct":1},{"bid_px":"235.000000000","ask_px":"253.650000000","bid_sz":100,"ask_sz":400,"bid_ct":1,"ask_ct":1},{"bid_px":"203.000000000","ask_px":"960.000000000","bid_sz":2,"ask_sz":25,"bid_ct":1,"ask_ct":1},{"bid_px":null,"ask_px":null,"bid_sz":0,"ask_sz":0,"bid_ct":0,"ask_ct":0},{"bid_px":null,"ask_px":null,"bid_sz":0,"ask_sz":0,"bid_ct":0,"ask_ct":0},{"bid_px":null,"ask_px":null,"bid_sz":0,"ask_sz":0,"bid_ct":0,"ask_ct":0},{"bid_px":null,"ask_px":null,"bid_sz":0,"ask_sz":0,"bid_ct":0,"ask_ct":0},{"bid_px":null,"ask_px":null,"bid_sz":0,"ask_sz":0,"bid_ct":0,"ask_ct":0},{"bid_px":null,"ask_px":null,"bid_sz":0,"ask_sz":0,"bid_ct":0,"ask_ct":0}],"symbol":"TSLA"}
{"ts_recv":"2024-11-01T08:00:02.189343537Z","hd":{"ts_event":"2024-11-01T08:00:02.189177936Z","rtype":10,"publisher_id":2,"instrument_id":16244},"action":"C","side":"B","depth":0,"price":"249.800000000","size":1000,"flags":130,"ts_in_delta":165601,"sequence":291802,"levels":[{"bid_px":"247.150000000","ask_px":"251.140000000","bid_sz":400,"ask_sz":100,"bid_ct":1,"ask_ct":1},{"bid_px":"235.000000000","ask_px":"252.400000000","bid_sz":100,"ask_sz":1000,"bid_ct":1,"ask_ct":1},{"bid_px":"203.000000000","ask_px":"253.650000000","bid_sz":2,"ask_sz":400,"bid_ct":1,"ask_ct":1},{"bid_px":null,"ask_px":"960.000000000","bid_sz":0,"ask_sz":25,"bid_ct":0,"ask_ct":1},{"bid_px":null,"ask_px":null,"bid_sz":0,"ask_sz":0,"bid_ct":0,"ask_ct":0},{"bid_px":null,"ask_px":null,"bid_sz":0,"ask_sz":0,"bid_ct":0,"ask_ct":0},{"bid_px":null,"ask_px":null,"bid_sz":0,"ask_sz":0,"bid_ct":0,"ask_ct":0},{"bid_px":null,"ask_px":null,"bid_sz":0,"ask_sz":0,"bid_ct":0,"ask_ct":0},{"bid_px":null,"ask_px":null,"bid_sz":0,"ask_sz":0,"bid_ct":0,"ask_ct":0},{"bid_px":null,"ask_px":null,"bid_sz":0,"ask_sz":0,"bid_ct":0,"ask_ct":0}],"symbol":"TSLA"}
{"ts_recv":"2024-11-01T08:00:02.200278583Z","hd":{"ts_event":"2024-11-01T08:00:02.200112430Z","rtype":10,"publisher_id":2,"instrument_id":16244},"action":"A","side":"B","depth":0,"price":"249.700000000","size":1000,"flags":130,"ts_in_delta":166153,"sequence":291816,"levels":[{"bid_px":"249.700000000","ask_px":"251.140000000","bid_sz":1000,"ask_sz":100,"bid_ct":1,"ask_ct":1},{"bid_px":"247.150000000","ask_px":"252.400000000","bid_sz":400,"ask_sz":1000,"bid_ct":1,"ask_ct":1},{"bid_px":"235.000000000","ask_px":"253.650000000","bid_sz":100,"ask_sz":400,"bid_ct":1,"ask_ct":1},{"bid_px":"203.000000000","ask_px":"960.000000000","bid_sz":2,"ask_sz":25,"bid_ct":1,"ask_ct":1},{"bid_px":null,"ask_px":null,"bid_sz":0,"ask_sz":0,"bid_ct":0,"ask_ct":0},{"bid_px":null,"ask_px":null,"bid_sz":0,"ask_sz":0,"bid_ct":0,"ask_ct":0},{"bid_px":null,"ask_px":null,"bid_sz":0,"ask_sz":0,"bid_ct":0,"ask_ct":0},{"bid_px":null,"ask_px":null,"bid_sz":0,"ask_sz":0,"bid_ct":0,"ask_ct":0},{"bid_px":null,"ask_px":null,"bid_sz":0,"ask_sz":0,"bid_ct":0,"ask_ct":0},{"bid_px":null,"ask_px":null,"bid_sz":0,"ask_sz":0,"bid_ct":0,"ask_ct":0}],"symbol":"TSLA"}
{"ts_recv":"2024-11-01T08:00:02.306823519Z","hd":{"ts_event":"2024-11-01T08:00:02.306655672Z","rtype":10,"publisher_id":2,"instrument_id":16244},"action":"A","side":"B","depth":0,"price":"249.930000000","size":50,"flags":130,"ts_in_delta":167847,"sequence":291894,"levels":[{"bid_px":"249.930000000","ask_px":"251.140000000","bid_sz":50,"ask_sz":100,"bid_ct":1,"ask_ct":1},{"bid_px":"249.700000000","ask_px":"252.400000000","bid_sz":1000,"ask_sz":1000,"bid_ct":1,"ask_ct":1},{"bid_px":"247.150000000","ask_px":"253.650000000","bid_sz":400,"ask_sz":400,"bid_ct":1,"ask_ct":1},{"bid_px":"235.000000000","ask_px":"960.000000000","bid_sz":100,"ask_sz":25,"bid_ct":1,"ask_ct":1},{"bid_px":"203.000000000","ask_px":null,"bid_sz":2,"ask_sz":0,"bid_ct":1,"ask_ct":0},{"bid_px":null,"ask_px":null,"bid_sz":0,"ask_sz":0,"bid_ct":0,"ask_ct":0},{"bid_px":null,"ask_px":null,"bid_sz":0,"ask_sz":0,"bid_ct":0,"ask_ct":0},{"bid_px":null,"ask_px":null,"bid_sz":0,"ask_sz":0,"bid_ct":0,"ask_ct":0},{"bid_px":null,"ask_px":null,"bid_sz":0,"ask_sz":0,"bid_ct":0,"ask_ct":0},{"bid_px":null,"ask_px":null,"bid_sz":0,"ask_sz":0,"bid_ct":0,"ask_ct":0}],"symbol":"TSLA"}
{"ts_recv":"2024-11-01T08:00:02.326848147Z","hd":{"ts_event":"2024-11-01T08:00:02.326682484Z","rtype":10,"publisher_id":2,"instrument_id":16244},"action":"C","side":"B","depth":0,"price":"249.930000000","size":50,"flags":130,"ts_in_delta":165663,"sequence":291910,"levels":[{"bid_px":"249.700000000","ask_px":"251.140000000","bid_sz":1000,"ask_sz":100,"bid_ct":1,"ask_ct":1},{"bid_px":"247.150000000","ask_px":"252.400000000","bid_sz":400,"ask_sz":1000,"bid_ct":1,"ask_ct":1},{"bid_px":"235.000000000","ask_px":"253.650000000","bid_sz":100,"ask_sz":400,"bid_ct":1,"ask_ct":1},{"bid_px":"203.000000000","ask_px":"960.000000000","bid_sz":2,"ask_sz":25,"bid_ct":1,"ask_ct":1},{"bid_px":null,"ask_px":null,"bid_sz":0,"ask_sz":0,"bid_ct":0,"ask_ct":0},{"bid_px":null,"ask_px":null,"bid_sz":0,"ask_sz":0,"bid_ct":0,"ask_ct":0},{"bid_px":null,"ask_px":null,"bid_sz":0,"ask_sz":0,"bid_ct":0,"ask_ct":0},{"bid_px":null,"ask_px":null,"bid_sz":0,"ask_sz":0,"bid_ct":0,"ask_ct":0},{"bid_px":null,"ask_px":null,"bid_sz":0,"ask_sz":0,"bid_ct":0,"ask_ct":0},{"bid_px":null,"ask_px":null,"bid_sz":0,"ask_sz":0,"bid_ct":0,"ask_ct":0}],"symbol":"TSLA"}
{"ts_recv":"2024-11-01T08:00:02.429223051Z","hd":{"ts_event":"2024-11-01T08:00:02.429057207Z","rtype":10,"publisher_id":2,"instrument_id":16244},"action":"A","side":"B","depth":0,"price":"250.030000000","size":50,"flags":130,"ts_in_delta":165844,"sequence":292086,"levels":[{"bid_px":"250.030000000","ask_px":"251.140000000","bid_sz":50,"ask_sz":100,"bid_ct":1,"ask_ct":1},{"bid_px":"249.700000000","ask_px":"252.400000000","bid_sz":1000,"ask_sz":1000,"bid_ct":1,"ask_ct":1},{"bid_px":"247.150000000","ask_px":"253.650000000","bid_sz":400,"ask_sz":400,"bid_ct":1,"ask_ct":1},{"bid_px":"235.000000000","ask_px":"960.000000000","bid_sz":100,"ask_sz":25,"bid_ct":1,"ask_ct":1},{"bid_px":"203.000000000","ask_px":null,"bid_sz":2,"ask_sz":0,"bid_ct":1,"ask_ct":0},{"bid_px":null,"ask_px":null,"bid_sz":0,"ask_sz":0,"bid_ct":0,"ask_ct":0},{"bid_px":null,"ask_px":null,"bid_sz":0,"ask_sz":0,"bid_ct":0,"ask_ct":0},{"bid_px":null,"ask_px":null,"bid_sz":0,"ask_sz":0,"bid_ct":0,"ask_ct":0},{"bid_px":null,"ask_px":null,"bid_sz":0,"ask_sz":0,"bid_ct":0,"ask_ct":0},{"bid_px":null,"ask_px":null,"bid_sz":0,"ask_sz":0,"bid_ct":0,"ask_ct":0}],"symbol":"TSLA"}
{"ts_recv":"2024-11-01T08:00:02.432420114Z","hd":{"ts_event":"2024-11-01T08:00:02.432254479Z","rtype":10,"publisher_id":2,"instrument_id":16244},"action":"C","side":"B","depth":0,"price":"250.030000000","size":50,"flags":130,"ts_in_delta":165635,"sequence":292107,"levels":[{"bid_px":"249.700000000","ask_px":"251.140000000","bid_sz":1000,"ask_sz":100,"bid_ct":1,"ask_ct":1},{"bid_px":"247.150000000","ask_px":"252.400000000","bid_sz":400,"ask_sz":1000,"bid_ct":1,"ask_ct":1},{"bid_px":"235.000000000","ask_px":"253.650000000","bid_sz":100,"ask_sz":400,"bid_ct":1,"ask_ct":1},{"bid_px":"203.000000000","ask_px":"960.000000000","bid_sz":2,"ask_sz":25,"bid_ct":1,"ask_ct":1},{"bid_px":null,"ask_px":null,"bid_sz":0,"ask_sz":0,"bid_ct":0,"ask_ct":0},{"bid_px":null,"ask_px":null,"bid_sz":0,"ask_sz":0,"bid_ct":0,"ask_ct":0},{"bid_px":null,"ask_px":null,"bid_sz":0,"ask_sz":0,"bid_ct":0,"ask_ct":0},{"bid_px":null,"ask_px":null,"bid_sz":0,"ask_sz":0,"bid_ct":0,"ask_ct":0},{"bid_px":null,"ask_px":null,"bid_sz":0,"ask_sz":0,"bid_ct":0,"ask_ct":0},{"bid_px":null,"ask_px":null,"bid_sz":0,"ask_sz":0,"bid_ct":0,"ask_ct":0}],"symbol":"TSLA"}
{"ts_recv":"2024-11-01T08:00:02.432433721Z","hd":{"ts_event":"2024-11-01T08:00:02.432267658Z","rtype":10,"publisher_id":2,"instrument_id":16244},"action":"A","side":"B","depth":0,"price":"250.020000000","size":50,"flags":130,"ts_in_delta":166063,"sequence":292108,"levels":[{"bid_px":"250.020000000","ask_px":"251.140000000","bid_sz":50,"ask_sz":100,"bid_ct":1,"ask_ct":1},{"bid_px":"249.700000000","ask_px":"252.400000000","bid_sz":1000,"ask_sz":1000,"bid_ct":1,"ask_ct":1},{"bid_px":"247.150000000","ask_px":"253.650000000","bid_sz":400,"ask_sz":400,"bid_ct":1,"ask_ct":1},{"bid_px":"235.000000000","ask_px":"960.000000000","bid_sz":100,"ask_sz":25,"bid_ct":1,"ask_ct":1},{"bid_px":"203.000000000","ask_px":null,"bid_sz":2,"ask_sz":0,"bid_ct":1,"ask_ct":0},{"bid_px":null,"ask_px":null,"bid_sz":0,"ask_sz":0,"bid_ct":0,"ask_ct":0},{"bid_px":null,"ask_px":null,"bid_sz":0,"ask_sz":0,"bid_ct":0,"ask_ct":0},{"bid_px":null,"ask_px":null,"bid_sz":0,"ask_sz":0,"bid_ct":0,"ask_ct":0},{"bid_px":null,"ask_px":null,"bid_sz":0,"ask_sz":0,"bid_ct":0,"ask_ct":0},{"bid_px":null,"ask_px":null,"bid_sz":0,"ask_sz":0,"bid_ct":0,"ask_ct":0}],"symbol":"TSLA"}
{"ts_recv":"2024-11-01T08:00:02.432505603Z","hd":{"ts_event":"2024-11-01T08:00:02.432340214Z","rtype":10,"publisher_id":2,"instrument_id":16244},"action":"C","side":"B","depth":0,"price":"250.020000000","size":50,"flags":130,"ts_in_delta":165389,"sequence":292110,"levels":[{"bid_px":"249.700000000","ask_px":"251.140000000","bid_sz":1000,"ask_sz":100,"bid_ct":1,"ask_ct":1},{"bid_px":"247.150000000","ask_px":"252.400000000","bid_sz":400,"ask_sz":1000,"bid_ct":1,"ask_ct":1},{"bid_px":"235.000000000","ask_px":"253.650000000","bid_sz":100,"ask_sz":400,"bid_ct":1,"ask_ct":1},{"bid_px":"203.000000000","ask_px":"960.000000000","bid_sz":2,"ask_sz":25,"bid_ct":1,"ask_ct":1},{"bid_px":null,"ask_px":null,"bid_sz":0,"ask_sz":0,"bid_ct":0,"ask_ct":0},{"bid_px":null,"ask_px":null,"bid_sz":0,"ask_sz":0,"bid_ct":0,"ask_ct":0},{"bid_px":null,"ask_px":null,"bid_sz":0,"ask_sz":0,"bid_ct":0,"ask_ct":0},{"bid_px":null,"ask_px":null,"bid_sz":0,"ask_sz":0,"bid_ct":0,"ask_ct":0},{"bid_px":null,"ask_px":null,"bid_sz":0,"ask_sz":0,"bid_ct":0,"ask_ct":0},{"bid_px":null,"ask_px":null,"bid_sz":0,"ask_sz":0,"bid_ct":0,"ask_ct":0}],"symbol":"TSLA"}
{"ts_recv":"2024-11-01T08:00:02.432528850Z","hd":{"ts_event":"2024-11-01T08:00:02.432362700Z","rtype":10,"publisher_id":2,"instrument_id":16244},"action":"A","side":"B","depth":0,"price":"249.880000000","size":50,"flags":130,"ts_in_delta":166150,"sequence":292111,"levels":[{"bid_px":"249.880000000","ask_px":"251.140000000","bid_sz":50,"ask_sz":100,"bid_ct":1,"ask_ct":1},{"bid_px":"249.700000000","ask_px":"252.400000000","bid_sz":1000,"ask_sz":1000,"bid_ct":1,"ask_ct":1},{"bid_px":"247.150000000","ask_px":"253.650000000","bid_sz":400,"ask_sz":400,"bid_ct":1,"ask_ct":1},{"bid_px":"235.000000000","ask_px":"960.000000000","bid_sz":100,"ask_sz":25,"bid_ct":1,"ask_ct":1},{"bid_px":"203.000000000","ask_px":null,"bid_sz":2,"ask_sz":0,"bid_ct":1,"ask_ct":0},{"bid_px":null,"ask_px":null,"bid_sz":0,"ask_sz":0,"bid_ct":0,"ask_ct":0},{"bid_px":null,"ask_px":null,"bid_sz":0,"ask_sz":0,"bid_ct":0,"ask_ct":0},{"bid_px":null,"ask_px":null,"bid_sz":0,"ask_sz":0,"bid_ct":0,"ask_ct":0},{"bid_px":null,"ask_px":null,"bid_sz":0,"ask_sz":0,"bid_ct":0,"ask_ct":0},{"bid_px":null,"ask_px":null,"bid_sz":0,"ask_sz":0,"bid_ct":0,"ask_ct":0}],"symbol":"TSLA"}
{"ts_recv":"2024-11-01T08:00:02.432570044Z","hd":{"ts_event":"2024-11-01T08:00:02.432404499Z","rtype":10,"publisher_id":2,"instrument_id":16244},"action":"C","side":"B","depth":0,"price":"249.880000000","size":50,"flags":130,"ts_in_delta":165545,"sequence":292112,"levels":[{"bid_px":"249.700000000","ask_px":"251.140000000","bid_sz":1000,"ask_sz":100,"bid_ct":1,"ask_ct":1},{"bid_px":"247.150000000","ask_px":"252.400000000","bid_sz":400,"ask_sz":1000,"bid_ct":1,"ask_ct":1},{"bid_px":"235.000000000","ask_px":"253.650000000","bid_sz":100,"ask_sz":400,"bid_ct":1,"ask_ct":1},{"bid_px":"203.000000000","ask_px":"960.000000000","bid_sz":2,"ask_sz":25,"bid_ct":1,"ask_ct":1},{"bid_px":null,"ask_px":null,"bid_sz":0,"ask_sz":0,"bid_ct":0,"ask_ct":0},{"bid_px":null,"ask_px":null,"bid_sz":0,"ask_sz":0,"bid_ct":0,"ask_ct":0},{"bid_px":null,"ask_px":null,"bid_sz":0,"ask_sz":0,"bid_ct":0,"ask_ct":0},{"bid_px":null,"ask_px":null,"bid_sz":0,"ask_sz":0,"bid_ct":0,"ask_ct":0},{"bid_px":null,"ask_px":null,"bid_sz":0,"ask_sz":0,"bid_ct":0,"ask_ct":0},{"bid_px":null,"ask_px":null,"bid_sz":0,"ask_sz":0,"bid_ct":0,"ask_ct":0}],"symbol":"TSLA"}
{"ts_recv":"2024-11-01T08:00:02.432582033Z","hd":{"ts_event":"2024-11-01T08:00:02.432416301Z","rtype":10,"publisher_id":2,"instrument_id":16244},"action":"A","side":"B","depth":1,"price":"249.680000000","size":50,"flags":130,"ts_in_delta":165732,"sequence":292113,"levels":[{"bid_px":"249.700000000","ask_px":"251.140000000","bid_sz":1000,"ask_sz":100,"bid_ct":1,"ask_ct":1},{"bid_px":"249.680000000","ask_px":"252.400000000","bid_sz":50,"ask_sz":1000,"bid_ct":1,"ask_ct":1},{"bid_px":"247.150000000","ask_px":"253.650000000","bid_sz":400,"ask_sz":400,"bid_ct":1,"ask_ct":1},{"bid_px":"235.000000000","ask_px":"960.000000000","bid_sz":100,"ask_sz":25,"bid_ct":1,"ask_ct":1},{"bid_px":"203.000000000","ask_px":null,"bid_sz":2,"ask_sz":0,"bid_ct":1,"ask_ct":0},{"bid_px":null,"ask_px":null,"bid_sz":0,"ask_sz":0,"bid_ct":0,"ask_ct":0},{"bid_px":null,"ask_px":null,"bid_sz":0,"ask_sz":0,"bid_ct":0,"ask_ct":0},{"bid_px":null,"ask_px":null,"bid_sz":0,"ask_sz":0,"bid_ct":0,"ask_ct":0},{"bid_px":null,"ask_px":null,"bid_sz":0,"ask_sz":0,"bid_ct":0,"ask_ct":0},{"bid_px":null,"ask_px":null,"bid_sz":0,"ask_sz":0,"bid_ct":0,"ask_ct":0}],"symbol":"TSLA"}
{"ts_recv":"2024-11-01T08:00:02.432613196Z","hd":{"ts_event":"2024-11-01T08:00:02.432447734Z","rtype":10,"publisher_id":2,"instrument_id":16244},"action":"C","side":"B","depth":1,"price":"249.680000000","size":50,"flags":130,"ts_in_delta":165462,"sequence":292114,"levels":[{"bid_px":"249.700000000","ask_px":"251.140000000","bid_sz":1000,"ask_sz":100,"bid_ct":1,"ask_ct":1},{"bid_px":"247.150000000","ask_px":"252.400000000","bid_sz":400,"ask_sz":1000,"bid_ct":1,"ask_ct":1},{"bid_px":"235.000000000","ask_px":"253.650000000","bid_sz":100,"ask_sz":400,"bid_ct":1,"ask_ct":1},{"bid_px":"203.000000000","ask_px":"960.000000000","bid_sz":2,"ask_sz":25,"bid_ct":1,"ask_ct":1},{"bid_px":null,"ask_px":null,"bid_sz":0,"ask_sz":0,"bid_ct":0,"ask_ct":0},{"bid_px":null,"ask_px":null,"bid_sz":0,"ask_sz":0,"bid_ct":0,"ask_ct":0},{"bid_px":null,"ask_px":null,"bid_sz":0,"ask_sz":0,"bid_ct":0,"ask_ct":0},{"bid_px":null,"ask_px":null,"bid_sz":0,"ask_sz":0,"bid_ct":0,"ask_ct":0},{"bid_px":null,"ask_px":null,"bid_sz":0,"ask_sz":0,"bid_ct":0,"ask_ct":0},{"bid_px":null,"ask_px":null,"bid_sz":0,"ask_sz":0,"bid_ct":0,"ask_ct":0}],"symbol":"TSLA"}
{"ts_recv":"2024-11-01T08:00:02.508790806Z","hd":{"ts_event":"2024-11-01T08:00:02.508624558Z","rtype":10,"publisher_id":2,"instrument_id":16244},"action":"C","side":"B","depth":0,"price":"249.700000000","size":1000,"flags":130,"ts_in_delta":166248,"sequence":292194,"levels":[{"bid_px":"247.150000000","ask_px":"251.140000000","bid_sz":400,"ask_sz":100,"bid_ct":1,"ask_ct":1},{"bid_px":"235.000000000","ask_px":"252.400000000","bid_sz":100,"ask_sz":1000,"bid_ct":1,"ask_ct":1},{"bid_px":"203.000000000","ask_px":"253.650000000","bid_sz":2,"ask_sz":400,"bid_ct":1,"ask_ct":1},{"bid_px":null,"ask_px":"960.000000000","bid_sz":0,"ask_sz":25,"bid_ct":0,"ask_ct":1},{"bid_px":null,"ask_px":null,"bid_sz":0,"ask_sz":0,"bid_ct":0,"ask_ct":0},{"bid_px":null,"ask_px":null,"bid_sz":0,"ask_sz":0,"bid_ct":0,"ask_ct":0},{"bid_px":null,"ask_px":null,"bid_sz":0,"ask_sz":0,"bid_ct":0,"ask_ct":0},{"bid_px":null,"ask_px":null,"bid_sz":0,"ask_sz":0,"bid_ct":0,"ask_ct":0},{"bid_px":null,"ask_px":null,"bid_sz":0,"ask_sz":0,"bid_ct":0,"ask_ct":0},{"bid_px":null,"ask_px":null,"bid_sz":0,"ask_sz":0,"bid_ct":0,"ask_ct":0}],"symbol":"TSLA"}
{"ts_recv":"2024-11-01T08:00:02.519427424Z","hd":{"ts_event":"2024-11-01T08:00:02.519261287Z","rtype":10,"publisher_id":2,"instrument_id":16244},"action":"A","side":"B","depth":0,"price":"249.500000000","size":1000,"flags":130,"ts_in_delta":166137,"sequence":292210,"levels":[{"bid_px":"249.500000000","ask_px":"251.140000000","bid_sz":1000,"ask_sz":100,"bid_ct":1,"ask_ct":1},{"bid_px":"247.150000000","ask_px":"252.400000000","bid_sz":400,"ask_sz":1000,"bid_ct":1,"ask_ct":1},{"bid_px":"235.000000000","ask_px":"253.650000000","bid_sz":100,"ask_sz":400,"bid_ct":1,"ask_ct":1},{"bid_px":"203.000000000","ask_px":"960.000000000","bid_sz":2,"ask_sz":25,"bid_ct":1,"ask_ct":1},{"bid_px":null,"ask_px":null,"bid_sz":0,"ask_sz":0,"bid_ct":0,"ask_ct":0},{"bid_px":null,"ask_px":null,"bid_sz":0,"ask_sz":0,"bid_ct":0,"ask_ct":0},{"bid_px":null,"ask_px":null,"bid_sz":0,"ask_sz":0,"bid_ct":0,"ask_ct":0},{"bid_px":null,"ask_px":null,"bid_sz":0,"ask_sz":0,"bid_ct":0,"ask_ct":0},{"bid_px":null,"ask_px":null,"bid_sz":0,"ask_sz":0,"bid_ct":0,"ask_ct":0},{"bid_px":null,"ask_px":null,"bid_sz":0,"ask_sz":0,"bid_ct":0,"ask_ct":0}],"symbol":"TSLA"}
{"ts_recv":"2024-11-01T08:00:02.542468800Z","hd":{"ts_event":"2024-11-01T08:00:02.542301121Z","rtype":10,"publisher_id":2,"instrument_id":16244},"action":"A","side":"B","depth":0,"price":"249.700000000","size":1000,"flags":130,"ts_in_delta":167679,"sequence":292261,"levels":[{"bid_px":"249.700000000","ask_px":"251.140000000","bid_sz":1000,"ask_sz":100,"bid_ct":1,"ask_ct":1},{"bid_px":"249.500000000","ask_px":"252.400000000","bid_sz":1000,"ask_sz":1000,"bid_ct":1,"ask_ct":1},{"bid_px":"247.150000000","ask_px":"253.650000000","bid_sz":400,"ask_sz":400,"bid_ct":1,"ask_ct":1},{"bid_px":"235.000000000","ask_px":"960.000000000","bid_sz":100,"ask_sz":25,"bid_ct":1,"ask_ct":1},{"bid_px":"203.000000000","ask_px":null,"bid_sz":2,"ask_sz":0,"bid_ct":1,"ask_ct":0},{"bid_px":null,"ask_px":null,"bid_sz":0,"ask_sz":0,"bid_ct":0,"ask_ct":0},{"bid_px":null,"ask_px":null,"bid_sz":0,"ask_sz":0,"bid_ct":0,"ask_ct":0},{"bid_px":null,"ask_px":null,"bid_sz":0,"ask_sz":0,"bid_ct":0,"ask_ct":0},{"bid_px":null,"ask_px":null,"bid_sz":0,"ask_sz":0,"bid_ct":0,"ask_ct":0},{"bid_px":null,"ask_px":null,"bid_sz":0,"ask_sz":0,"bid_ct":0,"ask_ct":0}],"symbol":"TSLA"}
{"ts_recv":"2024-11-01T08:00:02.542514357Z","hd":{"ts_event":"2024-11-01T08:00:02.542348590Z","rtype":10,"publisher_id":2,"instrument_id":16244},"action":"C","side":"B","depth":1,"price":"249.500000000","size":1000,"flags":130,"ts_in_delta":165767,"sequence":292262,"levels":[{"bid_px":"249.700000000","ask_px":"251.140000000","bid_sz":1000,"ask_sz":100,"bid_ct":1,"ask_ct":1},{"bid_px":"247.150000000","ask_px":"252.400000000","bid_sz":400,"ask_sz":1000,"bid_ct":1,"ask_ct":1},{"bid_px":"235.000000000","ask_px":"253.650000000","bid_sz":100,"ask_sz":400,"bid_ct":1,"ask_ct":1},{"bid_px":"203.000000000","ask_px":"960.000000000","bid_sz":2,"ask_sz":25,"bid_ct":1,"ask_ct":1},{"bid_px":null,"ask_px":null,"bid_sz":0,"ask_sz":0,"bid_ct":0,"ask_ct":0},{"bid_px":null,"ask_px":null,"bid_sz":0,"ask_sz":0,"bid_ct":0,"ask_ct":0},{"bid_px":null,"ask_px":null,"bid_sz":0,"ask_sz":0,"bid_ct":0,"ask_ct":0},{"bid_px":null,"ask_px":null,"bid_sz":0,"ask_sz":0,"bid_ct":0,"ask_ct":0},{"bid_px":null,"ask_px":null,"bid_sz":0,"ask_sz":0,"bid_ct":0,"ask_ct":0},{"bid_px":null,"ask_px":null,"bid_sz":0,"ask_sz":0,"bid_ct":0,"ask_ct":0}],"symbol":"TSLA"}
{"ts_recv":"2024-11-01T08:00:02.546283531Z","hd":{"ts_event":"2024-11-01T08:00:02.546117257Z","rtype":10,"publisher_id":2,"instrument_id":16244},"action":"A","side":"A","depth":1,"price":"252.100000000","size":1000,"flags":130,"ts_in_delta":166274,"sequence":292268,"levels":[{"bid_px":"249.700000000","ask_px":"251.140000000","bid_sz":1000,"ask_sz":100,"bid_ct":1,"ask_ct":1},{"bid_px":"247.150000000","ask_px":"252.100000000","bid_sz":400,"ask_sz":1000,"bid_ct":1,"ask_ct":1},{"bid_px":"235.000000000","ask_px":"252.400000000","bid_sz":100,"ask_sz":1000,"bid_ct":1,"ask_ct":1},{"bid_px":"203.000000000","ask_px":"253.650000000","bid_sz":2,"ask_sz":400,"bid_ct":1,"ask_ct":1},{"bid_px":null,"ask_px":"960.000000000","bid_sz":0,"ask_sz":25,"bid_ct":0,"ask_ct":1},{"bid_px":null,"ask_px":null,"bid_sz":0,"ask_sz":0,"bid_ct":0,"ask_ct":0},{"bid_px":null,"ask_px":null,"bid_sz":0,"ask_sz":0,"bid_ct":0,"ask_ct":0},{"bid_px":null,"ask_px":null,"bid_sz":0,"ask_sz":0,"bid_ct":0,"ask_ct":0},{"bid_px":null,"ask_px":null,"bid_sz":0,"ask_sz":0,"bid_ct":0,"ask_ct":0},{"bid_px":null,"ask_px":null,"bid_sz":0,"ask_sz":0,"bid_ct":0,"ask_ct":0}],"symbol":"TSLA"}
{"ts_recv":"2024-11-01T08:00:02.546320207Z","hd":{"ts_event":"2024-11-01T08:00:02.546154333Z","rtype":10,"publisher_id":2,"instrument_id":16244},"action":"C","side":"A","depth":2,"price":"252.400000000","size":1000,"flags":130,"ts_in_delta":165874,"sequence":292269,"levels":[{"bid_px":"249.700000000","ask_px":"251.140000000","bid_sz":1000,"ask_sz":100,"bid_ct":1,"ask_ct":1},{"bid_px":"247.150000000","ask_px":"252.100000000","bid_sz":400,"ask_sz":1000,"bid_ct":1,"ask_ct":1},{"bid_px":"235.000000000","ask_px":"253.650000000","bid_sz":100,"ask_sz":400,"bid_ct":1,"ask_ct":1},{"bid_px":"203.000000000","ask_px":"960.000000000","bid_sz":2,"ask_sz":25,"bid_ct":1,"ask_ct":1},{"bid_px":null,"ask_px":null,"bid_sz":0,"ask_sz":0,"bid_ct":0,"ask_ct":0},{"bid_px":null,"ask_px":null,"bid_sz":0,"ask_sz":0,"bid_ct":0,"ask_ct":0},{"bid_px":null,"ask_px":null,"bid_sz":0,"ask_sz":0,"bid_ct":0,"ask_ct":0},{"bid_px":null,"ask_px":null,"bid_sz":0,"ask_sz":0,"bid_ct":0,"ask_ct":0},{"bid_px":null,"ask_px":null,"bid_sz":0,"ask_sz":0,"bid_ct":0,"ask_ct":0},{"bid_px":null,"ask_px":null,"bid_sz":0,"ask_sz":0,"bid_ct":0,"ask_ct":0}],"symbol":"TSLA"}
{"ts_recv":"2024-11-01T08:00:02.546605793Z","hd":{"ts_event":"2024-11-01T08:00:02.546439522Z","rtype":10,"publisher_id":2,"instrument_id":16244},"action":"A","side":"A","depth":0,"price":"251.140000000","size":100,"flags":130,"ts_in_delta":166271,"sequence":292273,"levels":[{"bid_px":"249.700000000","ask_px":"251.140000000","bid_sz":1000,"ask_sz":200,"bid_ct":1,"ask_ct":2},{"bid_px":"247.150000000","ask_px":"252.100000000","bid_sz":400,"ask_sz":1000,"bid_ct":1,"ask_ct":1},{"bid_px":"235.000000000","ask_px":"253.650000000","bid_sz":100,"ask_sz":400,"bid_ct":1,"ask_ct":1},{"bid_px":"203.000000000","ask_px":"960.000000000","bid_sz":2,"ask_sz":25,"bid_ct":1,"ask_ct":1},{"bid_px":null,"ask_px":null,"bid_sz":0,"ask_sz":0,"bid_ct":0,"ask_ct":0},{"bid_px":null,"ask_px":null,"bid_sz":0,"ask_sz":0,"bid_ct":0,"ask_ct":0},{"bid_px":null,"ask_px":null,"bid_sz":0,"ask_sz":0,"bid_ct":0,"ask_ct":0},{"bid_px":null,"ask_px":null,"bid_sz":0,"ask_sz":0,"bid_ct":0,"ask_ct":0},{"bid_px":null,"ask_px":null,"bid_sz":0,"ask_sz":0,"bid_ct":0,"ask_ct":0},{"bid_px":null,"ask_px":null,"bid_sz":0,"ask_sz":0,"bid_ct":0,"ask_ct":0}],"symbol":"TSLA"}
{"ts_recv":"2024-11-01T08:00:02.553143352Z","hd":{"ts_event":"2024-11-01T08:00:02.552977007Z","rtype":10,"publisher_id":2,"instrument_id":16244},"action":"A","side":"B","depth":1,"price":"249.300000000","size":1000,"flags":130,"ts_in_delta":166345,"sequence":292282,"levels":[{"bid_px":"249.700000000","ask_px":"251.140000000","bid_sz":1000,"ask_sz":200,"bid_ct":1,"ask_ct":2},{"bid_px":"249.300000000","ask_px":"252.100000000","bid_sz":1000,"ask_sz":1000,"bid_ct":1,"ask_ct":1},{"bid_px":"247.150000000","ask_px":"253.650000000","bid_sz":400,"ask_sz":400,"bid_ct":1,"ask_ct":1},{"bid_px":"235.000000000","ask_px":"960.000000000","bid_sz":100,"ask_sz":25,"bid_ct":1,"ask_ct":1},{"bid_px":"203.000000000","ask_px":null,"bid_sz":2,"ask_sz":0,"bid_ct":1,"ask_ct":0},{"bid_px":null,"ask_px":null,"bid_sz":0,"ask_sz":0,"bid_ct":0,"ask_ct":0},{"bid_px":null,"ask_px":null,"bid_sz":0,"ask_sz":0,"bid_ct":0,"ask_ct":0},{"bid_px":null,"ask_px":null,"bid_sz":0,"ask_sz":0,"bid_ct":0,"ask_ct":0},{"bid_px":null,"ask_px":null,"bid_sz":0,"ask_sz":0,"bid_ct":0,"ask_ct":0},{"bid_px":null,"ask_px":null,"bid_sz":0,"ask_sz":0,"bid_ct":0,"ask_ct":0}],"symbol":"TSLA"}
{"ts_recv":"2024-11-01T08:00:02.571609303Z","hd":{"ts_event":"2024-11-01T08:00:02.571443429Z","rtype":10,"publisher_id":2,"instrument_id":16244},"action":"C","side":"A","depth":1,"price":"252.100000000","size":1000,"flags":130,"ts_in_delta":165874,"sequence":292311,"levels":[{"bid_px":"249.700000000","ask_px":"251.140000000","bid_sz":1000,"ask_sz":200,"bid_ct":1,"ask_ct":2},{"bid_px":"249.300000000","ask_px":"253.650000000","bid_sz":1000,"ask_sz":400,"bid_ct":1,"ask_ct":1},{"bid_px":"247.150000000","ask_px":"960.000000000","bid_sz":400,"ask_sz":25,"bid_ct":1,"ask_ct":1},{"bid_px":"235.000000000","ask_px":null,"bid_sz":100,"ask_sz":0,"bid_ct":1,"ask_ct":0},{"bid_px":"203.000000000","ask_px":null,"bid_sz":2,"ask_sz":0,"bid_ct":1,"ask_ct":0},{"bid_px":null,"ask_px":null,"bid_sz":0,"ask_sz":0,"bid_ct":0,"ask_ct":0},{"bid_px":null,"ask_px":null,"bid_sz":0,"ask_sz":0,"bid_ct":0,"ask_ct":0},{"bid_px":null,"ask_px":null,"bid_sz":0,"ask_sz":0,"bid_ct":0,"ask_ct":0},{"bid_px":null,"ask_px":null,"bid_sz":0,"ask_sz":0,"bid_ct":0,"ask_ct":0},{"bid_px":null,"ask_px":null,"bid_sz":0,"ask_sz":0,"bid_ct":0,"ask_ct":0}],"symbol":"TSLA"}
{"ts_recv":"2024-11-01T08:00:02.578965142Z","hd":{"ts_event":"2024-11-01T08:00:02.578798865Z","rtype":10,"publisher_id":2,"instrument_id":16244},"action":"A","side":"B","depth":1,"price":"249.520000000","size":50,"flags":130,"ts_in_delta":166277,"sequence":292318,"levels":[{"bid_px":"249.700000000","ask_px":"251.140000000","bid_sz":1000,"ask_sz":200,"bid_ct":1,"ask_ct":2},{"bid_px":"249.520000000","ask_px":"253.650000000","bid_sz":50,"ask_sz":400,"bid_ct":1,"ask_ct":1},{"bid_px":"249.300000000","ask_px":"960.000000000","bid_sz":1000,"ask_sz":25,"bid_ct":1,"ask_ct":1},{"bid_px":"247.150000000","ask_px":null,"bid_sz":400,"ask_sz":0,"bid_ct":1,"ask_ct":0},{"bid_px":"235.000000000","ask_px":null,"bid_sz":100,"ask_sz":0,"bid_ct":1,"ask_ct":0},{"bid_px":"203.000000000","ask_px":null,"bid_sz":2,"ask_sz":0,"bid_ct":1,"ask_ct":0},{"bid_px":null,"ask_px":null,"bid_sz":0,"ask_sz":0,"bid_ct":0,"ask_ct":0},{"bid_px":null,"ask_px":null,"bid_sz":0,"ask_sz":0,"bid_ct":0,"ask_ct":0},{"bid_px":null,"ask_px":null,"bid_sz":0,"ask_sz":0,"bid_ct":0,"ask_ct":0},{"bid_px":null,"ask_px":null,"bid_sz":0,"ask_sz":0,"bid_ct":0,"ask_ct":0}],"symbol":"TSLA"}
{"ts_recv":"2024-11-01T08:00:02.582249857Z","hd":{"ts_event":"2024-11-01T08:00:02.582083710Z","rtype":10,"publisher_id":2,"instrument_id":16244},"action":"A","side":"A","depth":1,"price":"252.300000000","size":1000,"flags":130,"ts_in_delta":166147,"sequence":292323,"levels":[{"bid_px":"249.700000000","ask_px":"251.140000000","bid_sz":1000,"ask_sz":200,"bid_ct":1,"ask_ct":2},{"bid_px":"249.520000000","ask_px":"252.300000000","bid_sz":50,"ask_sz":1000,"bid_ct":1,"ask_ct":1},{"bid_px":"249.300000000","ask_px":"253.650000000","bid_sz":1000,"ask_sz":400,"bid_ct":1,"ask_ct":1},{"bid_px":"247.150000000","ask_px":"960.000000000","bid_sz":400,"ask_sz":25,"bid_ct":1,"ask_ct":1},{"bid_px":"235.000000000","ask_px":null,"bid_sz":100,"ask_sz":0,"bid_ct":1,"ask_ct":0},{"bid_px":"203.000000000","ask_px":null,"bid_sz":2,"ask_sz":0,"bid_ct":1,"ask_ct":0},{"bid_px":null,"ask_px":null,"bid_sz":0,"ask_sz":0,"bid_ct":0,"ask_ct":0},{"bid_px":null,"ask_px":null,"bid_sz":0,"ask_sz":0,"bid_ct":0,"ask_ct":0},{"bid_px":null,"ask_px":null,"bid_sz":0,"ask_sz":0,"bid_ct":0,"ask_ct":0},{"bid_px":null,"ask_px":null,"bid_sz":0,"ask_sz":0,"bid_ct":0,"ask_ct":0}],"symbol":"TSLA"}
{"ts_recv":"2024-11-01T08:00:02.603637970Z","hd":{"ts_event":"2024-11-01T08:00:02.603472261Z","rtype":10,"publisher_id":2,"instrument_id":16244},"action":"C","side":"B","depth":1,"price":"249.520000000","size":50,"flags":130,"ts_in_delta":165709,"sequence":292342,"levels":[{"bid_px":"249.700000000","ask_px":"251.140000000","bid_sz":1000,"ask_sz":200,"bid_ct":1,"ask_ct":2},{"bid_px":"249.300000000","ask_px":"252.300000000","bid_sz":1000,"ask_sz":1000,"bid_ct":1,"ask_ct":1},{"bid_px":"247.150000000","ask_px":"253.650000000","bid_sz":400,"ask_sz":400,"bid_ct":1,"ask_ct":1},{"bid_px":"235.000000000","ask_px":"960.000000000","bid_sz":100,"ask_sz":25,"bid_ct":1,"ask_ct":1},{"bid_px":"203.000000000","ask_px":null,"bid_sz":2,"ask_sz":0,"bid_ct":1,"ask_ct":0},{"bid_px":null,"ask_px":null,"bid_sz":0,"ask_sz":0,"bid_ct":0,"ask_ct":0},{"bid_px":null,"ask_px":null,"bid_sz":0,"ask_sz":0,"bid_ct":0,"ask_ct":0},{"bid_px":null,"ask_px":null,"bid_sz":0,"ask_sz":0,"bid_ct":0,"ask_ct":0},{"bid_px":null,"ask_px":null,"bid_sz":0,"ask_sz":0,"bid_ct":0,"ask_ct":0},{"bid_px":null,"ask_px":null,"bid_sz":0,"ask_sz":0,"bid_ct":0,"ask_ct":0}],"symbol":"TSLA"}
{"ts_recv":"2024-11-01T08:00:02.607204031Z","hd":{"ts_event":"2024-11-01T08:00:02.607037998Z","rtype":10,"publisher_id":2,"instrument_id":16244},"action":"C","side":"A","depth":0,"price":"251.140000000","size":100,"flags":130,"ts_in_delta":166033,"sequence":292348,"levels":[{"bid_px":"249.700000000","ask_px":"251.140000000","bid_sz":1000,"ask_sz":100,"bid_ct":1,"ask_ct":1},{"bid_px":"249.300000000","ask_px":"252.300000000","bid_sz":1000,"ask_sz":1000,"bid_ct":1,"ask_ct":1},{"bid_px":"247.150000000","ask_px":"253.650000000","bid_sz":400,"ask_sz":400,"bid_ct":1,"ask_ct":1},{"bid_px":"235.000000000","ask_px":"960.000000000","bid_sz":100,"ask_sz":25,"bid_ct":1,"ask_ct":1},{"bid_px":"203.000000000","ask_px":null,"bid_sz":2,"ask_sz":0,"bid_ct":1,"ask_ct":0},{"bid_px":null,"ask_px":null,"bid_sz":0,"ask_sz":0,"bid_ct":0,"ask_ct":0},{"bid_px":null,"ask_px":null,"bid_sz":0,"ask_sz":0,"bid_ct":0,"ask_ct":0},{"bid_px":null,"ask_px":null,"bid_sz":0,"ask_sz":0,"bid_ct":0,"ask_ct":0},{"bid_px":null,"ask_px":null,"bid_sz":0,"ask_sz":0,"bid_ct":0,"ask_ct":0},{"bid_px":null,"ask_px":null,"bid_sz":0,"ask_sz":0,"bid_ct":0,"ask_ct":0}],"symbol":"TSLA"}
{"ts_recv":"2024-11-01T08:00:02.607227477Z","hd":{"ts_event":"2024-11-01T08:00:02.607060809Z","rtype":10,"publisher_id":2,"instrument_id":16244},"action":"A","side":"A","depth":0,"price":"250.940000000","size":100,"flags":130,"ts_in_delta":166668,"sequence":292349,"levels":[{"bid_px":"249.700000000","ask_px":"250.940000000","bid_sz":1000,"ask_sz":100,"bid_ct":1,"ask_ct":1},{"bid_px":"249.300000000","ask_px":"252.300000000","bid_sz":1000,"ask_sz":1000,"bid_ct":1,"ask_ct":1},{"bid_px":"247.150000000","ask_px":"253.650000000","bid_sz":400,"ask_sz":400,"bid_ct":1,"ask_ct":1},{"bid_px":"235.000000000","ask_px":"960.000000000","bid_sz":100,"ask_sz":25,"bid_ct":1,"ask_ct":1},{"bid_px":"203.000000000","ask_px":null,"bid_sz":2,"ask_sz":0,"bid_ct":1,"ask_ct":0},{"bid_px":null,"ask_px":null,"bid_sz":0,"ask_sz":0,"bid_ct":0,"ask_ct":0},{"bid_px":null,"ask_px":null,"bid_sz":0,"ask_sz":0,"bid_ct":0,"ask_ct":0},{"bid_px":null,"ask_px":null,"bid_sz":0,"ask_sz":0,"bid_ct":0,"ask_ct":0},{"bid_px":null,"ask_px":null,"bid_sz":0,"ask_sz":0,"bid_ct":0,"ask_ct":0},{"bid_px":null,"ask_px":null,"bid_sz":0,"ask_sz":0,"bid_ct":0,"ask_ct":0}],"symbol":"TSLA"}
{"ts_recv":"2024-11-01T08:00:02.640478961Z","hd":{"ts_event":"2024-11-01T08:00:02.640312645Z","rtype":10,"publisher_id":2,"instrument_id":10888},"action":"A","side":"A","depth":1,"price":"420.000000000","size":3,"flags":130,"ts_in_delta":166316,"sequence":292410,"levels":[{"bid_px":"404.410000000","ask_px":"415.070000000","bid_sz":246,"ask_sz":246,"bid_ct":1,"ask_ct":1},{"bid_px":null,"ask_px":"420.000000000","bid_sz":0,"ask_sz":3,"bid_ct":0,"ask_ct":1},{"bid_px":null,"ask_px":"468.000000000","bid_sz":0,"ask_sz":65,"bid_ct":0,"ask_ct":1},{"bid_px":null,"ask_px":null,"bid_sz":0,"ask_sz":0,"bid_ct":0,"ask_ct":0},{"bid_px":null,"ask_px":null,"bid_sz":0,"ask_sz":0,"bid_ct":0,"ask_ct":0},{"bid_px":null,"ask_px":null,"bid_sz":0,"ask_sz":0,"bid_ct":0,"ask_ct":0},{"bid_px":null,"ask_px":null,"bid_sz":0,"ask_sz":0,"bid_ct":0,"ask_ct":0},{"bid_px":null,"ask_px":null,"bid_sz":0,"ask_sz":0,"bid_ct":0,"ask_ct":0},{"bid_px":null,"ask_px":null,"bid_sz":0,"ask_sz":0,"bid_ct":0,"ask_ct":0},{"bid_px":null,"ask_px":null,"bid_sz":0,"ask_sz":0,"bid_ct":0,"ask_ct":0}],"symbol":"MSFT"}
{"ts_recv":"2024-11-01T08:00:02.648988454Z","hd":{"ts_event":"2024-11-01T08:00:02.648822101Z","rtype":10,"publisher_id":2,"instrument_id":16244},"action":"A","side":"B","depth":1,"price":"249.600000000","size":1000,"flags":130,"ts_in_delta":166353,"sequence":292419,"levels":[{"bid_px":"249.700000000","ask_px":"250.940000000","bid_sz":1000,"ask_sz":100,"bid_ct":1,"ask_ct":1},{"bid_px":"249.600000000","ask_px":"252.300000000","bid_sz":1000,"ask_sz":1000,"bid_ct":1,"ask_ct":1},{"bid_px":"249.300000000","ask_px":"253.650000000","bid_sz":1000,"ask_sz":400,"bid_ct":1,"ask_ct":1},{"bid_px":"247.150000000","ask_px":"960.000000000","bid_sz":400,"ask_sz":25,"bid_ct":1,"ask_ct":1},{"bid_px":"235.000000000","ask_px":null,"bid_sz":100,"ask_sz":0,"bid_ct":1,"ask_ct":0},{"bid_px":"203.000000000","ask_px":null,"bid_sz":2,"ask_sz":0,"bid_ct":1,"ask_ct":0},{"bid_px":null,"ask_px":null,"bid_sz":0,"ask_sz":0,"bid_ct":0,"ask_ct":0},{"bid_px":null,"ask_px":null,"bid_sz":0,"ask_sz":0,"bid_ct":0,"ask_ct":0},{"bid_px":null,"ask_px":null,"bid_sz":0,"ask_sz":0,"bid_ct":0,"ask_ct":0},{"bid_px":null,"ask_px":null,"bid_sz":0,"ask_sz":0,"bid_ct":0,"ask_ct":0}],"symbol":"TSLA"}
{"ts_recv":"2024-11-01T08:00:02.649909893Z","hd":{"ts_event":"2024-11-01T08:00:02.649743714Z","rtype":10,"publisher_id":2,"instrument_id":16244},"action":"A","side":"A","depth":0,"price":"250.940000000","size":100,"flags":130,"ts_in_delta":166179,"sequence":292421,"levels":[{"bid_px":"249.700000000","ask_px":"250.940000000","bid_sz":1000,"ask_sz":200,"bid_ct":1,"ask_ct":2},{"bid_px":"249.600000000","ask_px":"252.300000000","bid_sz":1000,"ask_sz":1000,"bid_ct":1,"ask_ct":1},{"bid_px":"249.300000000","ask_px":"253.650000000","bid_sz":1000,"ask_sz":400,"bid_ct":1,"ask_ct":1},{"bid_px":"247.150000000","ask_px":"960.000000000","bid_sz":400,"ask_sz":25,"bid_ct":1,"ask_ct":1},{"bid_px":"235.000000000","ask_px":null,"bid_sz":100,"ask_sz":0,"bid_ct":1,"ask_ct":0},{"bid_px":"203.000000000","ask_px":null,"bid_sz":2,"ask_sz":0,"bid_ct":1,"ask_ct":0},{"bid_px":null,"ask_px":null,"bid_sz":0,"ask_sz":0,"bid_ct":0,"ask_ct":0},{"bid_px":null,"ask_px":null,"bid_sz":0,"ask_sz":0,"bid_ct":0,"ask_ct":0},{"bid_px":null,"ask_px":null,"bid_sz":0,"ask_sz":0,"bid_ct":0,"ask_ct":0},{"bid_px":null,"ask_px":null,"bid_sz":0,"ask_sz":0,"bid_ct":0,"ask_ct":0}],"symbol":"TSLA"}
{"ts_recv":"2024-11-01T08:00:02.659428370Z","hd":{"ts_event":"2024-11-01T08:00:02.659262625Z","rtype":10,"publisher_id":2,"instrument_id":16244},"action":"C","side":"B","depth":2,"price":"249.300000000","size":1000,"flags":130,"ts_in_delta":165745,"sequence":292453,"levels":[{"bid_px":"249.700000000","ask_px":"250.940000000","bid_sz":1000,"ask_sz":200,"bid_ct":1,"ask_ct":2},{"bid_px":"249.600000000","ask_px":"252.300000000","bid_sz":1000,"ask_sz":1000,"bid_ct":1,"ask_ct":1},{"bid_px":"247.150000000","ask_px":"253.650000000","bid_sz":400,"ask_sz":400,"bid_ct":1,"ask_ct":1},{"bid_px":"235.000000000","ask_px":"960.000000000","bid_sz":100,"ask_sz":25,"bid_ct":1,"ask_ct":1},{"bid_px":"203.000000000","ask_px":null,"bid_sz":2,"ask_sz":0,"bid_ct":1,"ask_ct":0},{"bid_px":null,"ask_px":null,"bid_sz":0,"ask_sz":0,"bid_ct":0,"ask_ct":0},{"bid_px":null,"ask_px":null,"bid_sz":0,"ask_sz":0,"bid_ct":0,"ask_ct":0},{"bid_px":null,"ask_px":null,"bid_sz":0,"ask_sz":0,"bid_ct":0,"ask_ct":0},{"bid_px":null,"ask_px":null,"bid_sz":0,"ask_sz":0,"bid_ct":0,"ask_ct":0},{"bid_px":null,"ask_px":null,"bid_sz":0,"ask_sz":0,"bid_ct":0,"ask_ct":0}],"symbol":"TSLA"}
{"ts_recv":"2024-11-01T08:00:02.659429599Z","hd":{"ts_event":"2024-11-01T08:00:02.659263539Z","rtype":10,"publisher_id":2,"instrument_id":16244},"action":"A","side":"B","depth":2,"price":"249.500000000","size":1000,"flags":130,"ts_in_delta":166060,"sequence":292454,"levels":[{"bid_px":"249.700000000","ask_px":"250.940000000","bid_sz":1000,"ask_sz":200,"bid_ct":1,"ask_ct":2},{"bid_px":"249.600000000","ask_px":"252.300000000","bid_sz":1000,"ask_sz":1000,"bid_ct":1,"ask_ct":1},{"bid_px":"249.500000000","ask_px":"253.650000000","bid_sz":1000,"ask_sz":400,"bid_ct":1,"ask_ct":1},{"bid_px":"247.150000000","ask_px":"960.000000000","bid_sz":400,"ask_sz":25,"bid_ct":1,"ask_ct":1},{"bid_px":"235.000000000","ask_px":null,"bid_sz":100,"ask_sz":0,"bid_ct":1,"ask_ct":0},{"bid_px":"203.000000000","ask_px":null,"bid_sz":2,"ask_sz":0,"bid_ct":1,"ask_ct":0},{"bid_px":null,"ask_px":null,"bid_sz":0,"ask_sz":0,"bid_ct":0,"ask_ct":0},{"bid_px":null,"ask_px":null,"bid_sz":0,"ask_sz":0,"bid_ct":0,"ask_ct":0},{"bid_px":null,"ask_px":null,"bid_sz":0,"ask_sz":0,"bid_ct":0,"ask_ct":0},{"bid_px":null,"ask_px":null,"bid_sz":0,"ask_sz":0,"bid_ct":0,"ask_ct":0}],"symbol":"TSLA"}
{"ts_recv":"2024-11-01T08:00:02.690780625Z","hd":{"ts_event":"2024-11-01T08:00:02.690614817Z","rtype":10,"publisher_id":2,"instrument_id":16244},"action":"C","side":"B","depth":2,"price":"249.500000000","size":1000,"flags":130,"ts_in_delta":165808,"sequence":292490,"levels":[{"bid_px":"249.700000000","ask_px":"250.940000000","bid_sz":1000,"ask_sz":200,"bid_ct":1,"ask_ct":2},{"bid_px":"249.600000000","ask_px":"252.300000000","bid_sz":1000,"ask_sz":1000,"bid_ct":1,"ask_ct":1},{"bid_px":"247.150000000","ask_px":"253.650000000","bid_sz":400,"ask_sz":400,"bid_ct":1,"ask_ct":1},{"bid_px":"235.000000000","ask_px":"960.000000000","bid_sz":100,"ask_sz":25,"bid_ct":1,"ask_ct":1},{"bid_px":"203.000000000","ask_px":null,"bid_sz":2,"ask_sz":0,"bid_ct":1,"ask_ct":0},{"bid_px":null,"ask_px":null,"bid_sz":0,"ask_sz":0,"bid_ct":0,"ask_ct":0},{"bid_px":null,"ask_px":null,"bid_sz":0,"ask_sz":0,"bid_ct":0,"ask_ct":0},{"bid_px":null,"ask_px":null,"bid_sz":0,"ask_sz":0,"bid_ct":0,"ask_ct":0},{"bid_px":null,"ask_px":null,"bid_sz":0,"ask_sz":0,"bid_ct":0,"ask_ct":0},{"bid_px":null,"ask_px":null,"bid_sz":0,"ask_sz":0,"bid_ct":0,"ask_ct":0}],"symbol":"TSLA"}
{"ts_recv":"2024-11-01T08:00:02.701304590Z","hd":{"ts_event":"2024-11-01T08:00:02.701138373Z","rtype":10,"publisher_id":2,"instrument_id":16244},"action":"A","side":"B","depth":0,"price":"249.800000000","size":1000,"flags":130,"ts_in_delta":166217,"sequence":292499,"levels":[{"bid_px":"249.800000000","ask_px":"250.940000000","bid_sz":1000,"ask_sz":200,"bid_ct":1,"ask_ct":2},{"bid_px":"249.700000000","ask_px":"252.300000000","bid_sz":1000,"ask_sz":1000,"bid_ct":1,"ask_ct":1},{"bid_px":"249.600000000","ask_px":"253.650000000","bid_sz":1000,"ask_sz":400,"bid_ct":1,"ask_ct":1},{"bid_px":"247.150000000","ask_px":"960.000000000","bid_sz":400,"ask_sz":25,"bid_ct":1,"ask_ct":1},{"bid_px":"235.000000000","ask_px":null,"bid_sz":100,"ask_sz":0,"bid_ct":1,"ask_ct":0},{"bid_px":"203.000000000","ask_px":null,"bid_sz":2,"ask_sz":0,"bid_ct":1,"ask_ct":0},{"bid_px":null,"ask_px":null,"bid_sz":0,"ask_sz":0,"bid_ct":0,"ask_ct":0},{"bid_px":null,"ask_px":null,"bid_sz":0,"ask_sz":0,"bid_ct":0,"ask_ct":0},{"bid_px":null,"ask_px":null,"bid_sz":0,"ask_sz":0,"bid_ct":0,"ask_ct":0},{"bid_px":null,"ask_px":null,"bid_sz":0,"ask_sz":0,"bid_ct":0,"ask_ct":0}],"symbol":"TSLA"}
{"ts_recv":"2024-11-01T08:00:02.701353470Z","hd":{"ts_event":"2024-11-01T08:00:02.701187733Z","rtype":10,"publisher_id":2,"instrument_id":16244},"action":"C","side":"B","depth":1,"price":"249.700000000","size":1000,"flags":130,"ts_in_delta":165737,"sequence":292500,"levels":[{"bid_px":"249.800000000","ask_px":"250.940000000","bid_sz":1000,"ask_sz":200,"bid_ct":1,"ask_ct":2},{"bid_px":"249.600000000","ask_px":"252.300000000","bid_sz":1000,"ask_sz":1000,"bid_ct":1,"ask_ct":1},{"bid_px":"247.150000000","ask_px":"253.650000000","bid_sz":400,"ask_sz":400,"bid_ct":1,"ask_ct":1},{"bid_px":"235.000000000","ask_px":"960.000000000","bid_sz":100,"ask_sz":25,"bid_ct":1,"ask_ct":1},{"bid_px":"203.000000000","ask_px":null,"bid_sz":2,"ask_sz":0,"bid_ct":1,"ask_ct":0},{"bid_px":null,"ask_px":null,"bid_sz":0,"ask_sz":0,"bid_ct":0,"ask_ct":0},{"bid_px":null,"ask_px":null,"bid_sz":0,"ask_sz":0,"bid_ct":0,"ask_ct":0},{"bid_px":null,"ask_px":null,"bid_sz":0,"ask_sz":0,"bid_ct":0,"ask_ct":0},{"bid_px":null,"ask_px":null,"bid_sz":0,"ask_sz":0,"bid_ct":0,"ask_ct":0},{"bid_px":null,"ask_px":null,"bid_sz":0,"ask_sz":0,"bid_ct":0,"ask_ct":0}],"symbol":"TSLA"}
{"ts_recv":"2024-11-01T08:00:02.710429594Z","hd":{"ts_event":"2024-11-01T08:00:02.710263894Z","rtype":10,"publisher_id":2,"instrument_id":16244},"action":"C","side":"A","depth":0,"price":"250.940000000","size":100,"flags":130,"ts_in_delta":165700,"sequence":292504,"levels":[{"bid_px":"249.800000000","ask_px":"250.940000000","bid_sz":1000,"ask_sz":100,"bid_ct":1,"ask_ct":1},{"bid_px":"249.600000000","ask_px":"252.300000000","bid_sz":1000,"ask_sz":1000,"bid_ct":1,"ask_ct":1},{"bid_px":"247.150000000","ask_px":"253.650000000","bid_sz":400,"ask_sz":400,"bid_ct":1,"ask_ct":1},{"bid_px":"235.000000000","ask_px":"960.000000000","bid_sz":100,"ask_sz":25,"bid_ct":1,"ask_ct":1},{"bid_px":"203.000000000","ask_px":null,"bid_sz":2,"ask_sz":0,"bid_ct":1,"ask_ct":0},{"bid_px":null,"ask_px":null,"bid_sz":0,"ask_sz":0,"bid_ct":0,"ask_ct":0},{"bid_px":null,"ask_px":null,"bid_sz":0,"ask_sz":0,"bid_ct":0,"ask_ct":0},{"bid_px":null,"ask_px":null,"bid_sz":0,"ask_sz":0,"bid_ct":0,"ask_ct":0},{"bid_px":null,"ask_px":null,"bid_sz":0,"ask_sz":0,"bid_ct":0,"ask_ct":0},{"bid_px":null,"ask_px":null,"bid_sz":0,"ask_sz":0,"bid_ct":0,"ask_ct":0}],"symbol":"TSLA"}
{"ts_recv":"2024-11-01T08:00:02.710450991Z","hd":{"ts_event":"2024-11-01T08:00:02.710284708Z","rtype":10,"publisher_id":2,"instrument_id":16244},"action":"A","side":"A","depth":0,"price":"250.830000000","size":100,"flags":130,"ts_in_delta":166283,"sequence":292505,"levels":[{"bid_px":"249.800000000","ask_px":"250.830000000","bid_sz":1000,"ask_sz":100,"bid_ct":1,"ask_ct":1},{"bid_px":"249.600000000","ask_px":"252.300000000","bid_sz":1000,"ask_sz":1000,"bid_ct":1,"ask_ct":1},{"bid_px":"247.150000000","ask_px":"253.650000000","bid_sz":400,"ask_sz":400,"bid_ct":1,"ask_ct":1},{"bid_px":"235.000000000","ask_px":"960.000000000","bid_sz":100,"ask_sz":25,"bid_ct":1,"ask_ct":1},{"bid_px":"203.000000000","ask_px":null,"bid_sz":2,"ask_sz":0,"bid_ct":1,"ask_ct":0},{"bid_px":null,"ask_px":null,"bid_sz":0,"ask_sz":0,"bid_ct":0,"ask_ct":0},{"bid_px":null,"ask_px":null,"bid_sz":0,"ask_sz":0,"bid_ct":0,"ask_ct":0},{"bid_px":null,"ask_px":null,"bid_sz":0,"ask_sz":0,"bid_ct":0,"ask_ct":0},{"bid_px":null,"ask_px":null,"bid_sz":0,"ask_sz":0,"bid_ct":0,"ask_ct":0},{"bid_px":null,"ask_px":null,"bid_sz":0,"ask_sz":0,"bid_ct":0,"ask_ct":0}],"symbol":"TSLA"}
{"ts_recv":"2024-11-01T08:00:02.710481000Z","hd":{"ts_event":"2024-11-01T08:00:02.710313713Z","rtype":10,"publisher_id":2,"instrument_id":16244},"action":"A","side":"B","depth":1,"price":"249.600000000","size":50,"flags":130,"ts_in_delta":167287,"sequence":292506,"levels":[{"bid_px":"249.800000000","ask_px":"250.830000000","bid_sz":1000,"ask_sz":100,"bid_ct":1,"ask_ct":1},{"bid_px":"249.600000000","ask_px":"252.300000000","bid_sz":1050,"ask_sz":1000,"bid_ct":2,"ask_ct":1},{"bid_px":"247.150000000","ask_px":"253.650000000","bid_sz":400,"ask_sz":400,"bid_ct":1,"ask_ct":1},{"bid_px":"235.000000000","ask_px":"960.000000000","bid_sz":100,"ask_sz":25,"bid_ct":1,"ask_ct":1},{"bid_px":"203.000000000","ask_px":null,"bid_sz":2,"ask_sz":0,"bid_ct":1,"ask_ct":0},{"bid_px":null,"ask_px":null,"bid_sz":0,"ask_sz":0,"bid_ct":0,"ask_ct":0},{"bid_px":null,"ask_px":null,"bid_sz":0,"ask_sz":0,"bid_ct":0,"ask_ct":0},{"bid_px":null,"ask_px":null,"bid_sz":0,"ask_sz":0,"bid_ct":0,"ask_ct":0},{"bid_px":null,"ask_px":null,"bid_sz":0,"ask_sz":0,"bid_ct":0,"ask_ct":0},{"bid_px":null,"ask_px":null,"bid_sz":0,"ask_sz":0,"bid_ct":0,"ask_ct":0}],"symbol":"TSLA"}
{"ts_recv":"2024-11-01T08:00:02.721528719Z","hd":{"ts_event":"2024-11-01T08:00:02.721362015Z","rtype":10,"publisher_id":2,"instrument_id":16244},"action":"A","side":"B","depth":2,"price":"248.700000000","size":1000,"flags":130,"ts_in_delta":166704,"sequence":292528,"levels":[{"bid_px":"249.800000000","ask_px":"250.830000000","bid_sz":1000,"ask_sz":100,"bid_ct":1,"ask_ct":1},{"bid_px":"249.600000000","ask_px":"252.300000000","bid_sz":1050,"ask_sz":1000,"bid_ct":2,"ask_ct":1},{"bid_px":"248.700000000","ask_px":"253.650000000","bid_sz":1000,"ask_sz":400,"bid_ct":1,"ask_ct":1},{"bid_px":"247.150000000","ask_px":"960.000000000","bid_sz":400,"ask_sz":25,"bid_ct":1,"ask_ct":1},{"bid_px":"235.000000000","ask_px":null,"bid_sz":100,"ask_sz":0,"bid_ct":1,"ask_ct":0},{"bid_px":"203.000000000","ask_px":null,"bid_sz":2,"ask_sz":0,"bid_ct":1,"ask_ct":0},{"bid_px":null,"ask_px":null,"bid_sz":0,"ask_sz":0,"bid_ct":0,"ask_ct":0},{"bid_px":null,"ask_px":null,"bid_sz":0,"ask_sz":0,"bid_ct":0,"ask_ct":0},{"bid_px":null,"ask_px":null,"bid_sz":0,"ask_sz":0,"bid_ct":0,"ask_ct":0},{"bid_px":null,"ask_px":null,"bid_sz":0,"ask_sz":0,"bid_ct":0,"ask_ct":0}],"symbol":"TSLA"}
{"ts_recv":"2024-11-01T08:00:02.721574031Z","hd":{"ts_event":"2024-11-01T08:00:02.721408022Z","rtype":10,"publisher_id":2,"instrument_id":16244},"action":"A","side":"B","depth":1,"price":"249.600000000","size":50,"flags":130,"ts_in_delta":166009,"sequence":292529,"levels":[{"bid_px":"249.800000000","ask_px":"250.830000000","bid_sz":1000,"ask_sz":100,"bid_ct":1,"ask_ct":1},{"bid_px":"249.600000000","ask_px":"252.300000000","bid_sz":1100,"ask_sz":1000,"bid_ct":3,"ask_ct":1},{"bid_px":"248.700000000","ask_px":"253.650000000","bid_sz":1000,"ask_sz":400,"bid_ct":1,"ask_ct":1},{"bid_px":"247.150000000","ask_px":"960.000000000","bid_sz":400,"ask_sz":25,"bid_ct":1,"ask_ct":1},{"bid_px":"235.000000000","ask_px":null,"bid_sz":100,"ask_sz":0,"bid_ct":1,"ask_ct":0},{"bid_px":"203.000000000","ask_px":null,"bid_sz":2,"ask_sz":0,"bid_ct":1,"ask_ct":0},{"bid_px":null,"ask_px":null,"bid_sz":0,"ask_sz":0,"bid_ct":0,"ask_ct":0},{"bid_px":null,"ask_px":null,"bid_sz":0,"ask_sz":0,"bid_ct":0,"ask_ct":0},{"bid_px":null,"ask_px":null,"bid_sz":0,"ask_sz":0,"bid_ct":0,"ask_ct":0},{"bid_px":null,"ask_px":null,"bid_sz":0,"ask_sz":0,"bid_ct":0,"ask_ct":0}],"symbol":"TSLA"}
{"ts_recv":"2024-11-01T08:00:02.721791756Z","hd":{"ts_event":"2024-11-01T08:00:02.721626204Z","rtype":10,"publisher_id":2,"instrument_id":16244},"action":"C","side":"B","depth":2,"price":"248.700000000","size":1000,"flags":130,"ts_in_delta":165552,"sequence":292531,"levels":[{"bid_px":"249.800000000","ask_px":"250.830000000","bid_sz":1000,"ask_sz":100,"bid_ct":1,"ask_ct":1},{"bid_px":"249.600000000","ask_px":"252.300000000","bid_sz":1100,"ask_sz":1000,"bid_ct":3,"ask_ct":1},{"bid_px":"247.150000000","ask_px":"253.650000000","bid_sz":400,"ask_sz":400,"bid_ct":1,"ask_ct":1},{"bid_px":"235.000000000","ask_px":"960.000000000","bid_sz":100,"ask_sz":25,"bid_ct":1,"ask_ct":1},{"bid_px":"203.000000000","ask_px":null,"bid_sz":2,"ask_sz":0,"bid_ct":1,"ask_ct":0},{"bid_px":null,"ask_px":null,"bid_sz":0,"ask_sz":0,"bid_ct":0,"ask_ct":0},{"bid_px":null,"ask_px":null,"bid_sz":0,"ask_sz":0,"bid_ct":0,"ask_ct":0},{"bid_px":null,"ask_px":null,"bid_sz":0,"ask_sz":0,"bid_ct":0,"ask_ct":0},{"bid_px":null,"ask_px":null,"bid_sz":0,"ask_sz":0,"bid_ct":0,"ask_ct":0},{"bid_px":null,"ask_px":null,"bid_sz":0,"ask_sz":0,"bid_ct":0,"ask_ct":0}],"symbol":"TSLA"}
{"ts_recv":"2024-11-01T08:00:02.732345694Z","hd":{"ts_event":"2024-11-01T08:00:02.732179390Z","rtype":10,"publisher_id":2,"instrument_id":16244},"action":"A","side":"B","depth":2,"price":"248.500000000","size":1000,"flags":130,"ts_in_delta":166304,"sequence":292547,"levels":[{"bid_px":"249.800000000","ask_px":"250.830000000","bid_sz":1000,"ask_sz":100,"bid_ct":1,"ask_ct":1},{"bid_px":"249.600000000","ask_px":"252.300000000","bid_sz":1100,"ask_sz":1000,"bid_ct":3,"ask_ct":1},{"bid_px":"248.500000000","ask_px":"253.650000000","bid_sz":1000,"ask_sz":400,"bid_ct":1,"ask_ct":1},{"bid_px":"247.150000000","ask_px":"960.000000000","bid_sz":400,"ask_sz":25,"bid_ct":1,"ask_ct":1},{"bid_px":"235.000000000","ask_px":null,"bid_sz":100,"ask_sz":0,"bid_ct":1,"ask_ct":0},{"bid_px":"203.000000000","ask_px":null,"bid_sz":2,"ask_sz":0,"bid_ct":1,"ask_ct":0},{"bid_px":null,"ask_px":null,"bid_sz":0,"ask_sz":0,"bid_ct":0,"ask_ct":0},{"bid_px":null,"ask_px":null,"bid_sz":0,"ask_sz":0,"bid_ct":0,"ask_ct":0},{"bid_px":null,"ask_px":null,"bid_sz":0,"ask_sz":0,"bid_ct":0,"ask_ct":0},{"bid_px":null,"ask_px":null,"bid_sz":0,"ask_sz":0,"bid_ct":0,"ask_ct":0}],"symbol":"TSLA"}
{"ts_recv":"2024-11-01T08:00:02.769927085Z","hd":{"ts_event":"2024-11-01T08:00:02.769760727Z","rtype":10,"publisher_id":2,"instrument_id":16244},"action":"C","side":"B","depth":1,"price":"249.600000000","size":50,"flags":130,"ts_in_delta":166358,"sequence":292585,"levels":[{"bid_px":"249.800000000","ask_px":"250.830000000","bid_sz":1000,"ask_sz":100,"bid_ct":1,"ask_ct":1},{"bid_px":"249.600000000","ask_px":"252.300000000","bid_sz":1050,"ask_sz":1000,"bid_ct":2,"ask_ct":1},{"bid_px":"248.500000000","ask_px":"253.650000000","bid_sz":1000,"ask_sz":400,"bid_ct":1,"ask_ct":1},{"bid_px":"247.150000000","ask_px":"960.000000000","bid_sz":400,"ask_sz":25,"bid_ct":1,"ask_ct":1},{"bid_px":"235.000000000","ask_px":null,"bid_sz":100,"ask_sz":0,"bid_ct":1,"ask_ct":0},{"bid_px":"203.000000000","ask_px":null,"bid_sz":2,"ask_sz":0,"bid_ct":1,"ask_ct":0},{"bid_px":null,"ask_px":null,"bid_sz":0,"ask_sz":0,"bid_ct":0,"ask_ct":0},{"bid_px":null,"ask_px":null,"bid_sz":0,"ask_sz":0,"bid_ct":0,"ask_ct":0},{"bid_px":null,"ask_px":null,"bid_sz":0,"ask_sz":0,"bid_ct":0,"ask_ct":0},{"bid_px":null,"ask_px":null,"bid_sz":0,"ask_sz":0,"bid_ct":0,"ask_ct":0}],"symbol":"TSLA"}
{"ts_recv":"2024-11-01T08:00:02.769946788Z","hd":{"ts_event":"2024-11-01T08:00:02.769780516Z","rtype":10,"publisher_id":2,"instrument_id":16244},"action":"A","side":"B","depth":1,"price":"249.610000000","size":100,"flags":130,"ts_in_delta":166272,"sequence":292586,"levels":[{"bid_px":"249.800000000","ask_px":"250.830000000","bid_sz":1000,"ask_sz":100,"bid_ct":1,"ask_ct":1},{"bid_px":"249.610000000","ask_px":"252.300000000","bid_sz":100,"ask_sz":1000,"bid_ct":1,"ask_ct":1},{"bid_px":"249.600000000","ask_px":"253.650000000","bid_sz":1000,"ask_sz":400,"bid_ct":1,"ask_ct":1},{"bid_px":"248.500000000","ask_px":"960.000000000","bid_sz":1000,"ask_sz":25,"bid_ct":1,"ask_ct":1},{"bid_px":"247.150000000","ask_px":null,"bid_sz":400,"ask_sz":0,"bid_ct":1,"ask_ct":0},{"bid_px":"235.000000000","ask_px":null,"bid_sz":100,"ask_sz":0,"bid_ct":1,"ask_ct":0},{"bid_px":"203.000000000","ask_px":null,"bid_sz":2,"ask_sz":0,"bid_ct":1,"ask_ct":0},{"bid_px":null,"ask_px":null,"bid_sz":0,"ask_sz":0,"bid_ct":0,"ask_ct":0},{"bid_px":null,"ask_px":null,"bid_sz":0,"ask_sz":0,"bid_ct":0,"ask_ct":0},{"bid_px":null,"ask_px":null,"bid_sz":0,"ask_sz":0,"bid_ct":0,"ask_ct":0}],"symbol":"TSLA"}
{"ts_recv":"2024-11-01T08:00:02.781101894Z","hd":{"ts_event":"2024-11-01T08:00:02.780935559Z","rtype":10,"publisher_id":2,"instrument_id":16244},"action":"A","side":"B","depth":0,"price":"249.870000000","size":50,"flags":130,"ts_in_delta":166335,"sequence":292595,"levels":[{"bid_px":"249.870000000","ask_px":"250.830000000","bid_sz":50,"ask_sz":100,"bid_ct":1,"ask_ct":1},{"bid_px":"249.800000000","ask_px":"252.300000000","bid_sz":1000,"ask_sz":1000,"bid_ct":1,"ask_ct":1},{"bid_px":"249.600000000","ask_px":"253.650000000","bid_sz":1000,"ask_sz":400,"bid_ct":1,"ask_ct":1},{"bid_px":"248.500000000","ask_px":"960.000000000","bid_sz":1000,"ask_sz":25,"bid_ct":1,"ask_ct":1},{"bid_px":"247.150000000","ask_px":null,"bid_sz":400,"ask_sz":0,"bid_ct":1,"ask_ct":0},{"bid_px":"235.000000000","ask_px":null,"bid_sz":100,"ask_sz":0,"bid_ct":1,"ask_ct":0},{"bid_px":"203.000000000","ask_px":null,"bid_sz":2,"ask_sz":0,"bid_ct":1,"ask_ct":0},{"bid_px":null,"ask_px":null,"bid_sz":0,"ask_sz":0,"bid_ct":0,"ask_ct":0},{"bid_px":null,"ask_px":null,"bid_sz":0,"ask_sz":0,"bid_ct":0,"ask_ct":0},{"bid_px":null,"ask_px":null,"bid_sz":0,"ask_sz":0,"bid_ct":0,"ask_ct":0}],"symbol":"TSLA"}
{"ts_recv":"2024-11-01T08:00:02.813321525Z","hd":{"ts_event":"2024-11-01T08:00:02.813155243Z","rtype":10,"publisher_id":2,"instrument_id":16244},"action":"A","side":"B","depth":7,"price":"170.000000000","size":3,"flags":130,"ts_in_delta":166282,"sequence":292603,"levels":[{"bid_px":"249.870000000","ask_px":"250.830000000","bid_sz":50,"ask_sz":100,"bid_ct":1,"ask_ct":1},{"bid_px":"249.800000000","ask_px":"252.300000000","bid_sz":1000,"ask_sz":1000,"bid_ct":1,"ask_ct":1},{"bid_px":"249.600000000","ask_px":"253.650000000","bid_sz":1000,"ask_sz":400,"bid_ct":1,"ask_ct":1},{"bid_px":"248.500000000","ask_px":"960.000000000","bid_sz":1000,"ask_sz":25,"bid_ct":1,"ask_ct":1},{"bid_px":"247.150000000","ask_px":null,"bid_sz":400,"ask_sz":0,"bid_ct":1,"ask_ct":0},{"bid_px":"235.000000000","ask_px":null,"bid_sz":100,"ask_sz":0,"bid_ct":1,"ask_ct":0},{"bid_px":"203.000000000","ask_px":null,"bid_sz":2,"ask_sz":0,"bid_ct":1,"ask_ct":0},{"bid_px":"170.000000000","ask_px":null,"bid_sz":3,"ask_sz":0,"bid_ct":1,"ask_ct":0},{"bid_px":null,"ask_px":null,"bid_sz":0,"ask_sz":0,"bid_ct":0,"ask_ct":0},{"bid_px":null,"ask_px":null,"bid_sz":0,"ask_sz":0,"bid_ct":0,"ask_ct":0}],"symbol":"TSLA"}
{"ts_recv":"2024-11-01T08:00:02.819310866Z","hd":{"ts_event":"2024-11-01T08:00:02.819145368Z","rtype":10,"publisher_id":2,"instrument_id":16244},"action":"C","side":"B","depth":0,"price":"249.870000000","size":50,"flags":130,"ts_in_delta":165498,"sequence":292610,"levels":[{"bid_px":"249.800000000","ask_px":"250.830000000","bid_sz":1000,"ask_sz":100,"bid_ct":1,"ask_ct":1},{"bid_px":"249.600000000","ask_px":"252.300000000","bid_sz":1000,"ask_sz":1000,"bid_ct":1,"ask_ct":1},{"bid_px":"248.500000000","ask_px":"253.650000000","bid_sz":1000,"ask_sz":400,"bid_ct":1,"ask_ct":1},{"bid_px":"247.150000000","ask_px":"960.000000000","bid_sz":400,"ask_sz":25,"bid_ct":1,"ask_ct":1},{"bid_px":"235.000000000","ask_px":null,"bid_sz":100,"ask_sz":0,"bid_ct":1,"ask_ct":0},{"bid_px":"203.000000000","ask_px":null,"bid_sz":2,"ask_sz":0,"bid_ct":1,"ask_ct":0},{"bid_px":"170.000000000","ask_px":null,"bid_sz":3,"ask_sz":0,"bid_ct":1,"ask_ct":0},{"bid_px":null,"ask_px":null,"bid_sz":0,"ask_sz":0,"bid_ct":0,"ask_ct":0},{"bid_px":null,"ask_px":null,"bid_sz":0,"ask_sz":0,"bid_ct":0,"ask_ct":0},{"bid_px":null,"ask_px":null,"bid_sz":0,"ask_sz":0,"bid_ct":0,"ask_ct":0}],"symbol":"TSLA"}
{"ts_recv":"2024-11-01T08:00:02.819580129Z","hd":{"ts_event":"2024-11-01T08:00:02.819414326Z","rtype":10,"publisher_id":2,"instrument_id":16244},"action":"C","side":"B","depth":2,"price":"248.500000000","size":1000,"flags":130,"ts_in_delta":165803,"sequence":292611,"levels":[{"bid_px":"249.800000000","ask_px":"250.830000000","bid_sz":1000,"ask_sz":100,"bid_ct":1,"ask_ct":1},{"bid_px":"249.600000000","ask_px":"252.300000000","bid_sz":1000,"ask_sz":1000,"bid_ct":1,"ask_ct":1},{"bid_px":"247.150000000","ask_px":"253.650000000","bid_sz":400,"ask_sz":400,"bid_ct":1,"ask_ct":1},{"bid_px":"235.000000000","ask_px":"960.000000000","bid_sz":100,"ask_sz":25,"bid_ct":1,"ask_ct":1},{"bid_px":"203.000000000","ask_px":null,"bid_sz":2,"ask_sz":0,"bid_ct":1,"ask_ct":0},{"bid_px":"170.000000000","ask_px":null,"bid_sz":3,"ask_sz":0,"bid_ct":1,"ask_ct":0},{"bid_px":null,"ask_px":null,"bid_sz":0,"ask_sz":0,"bid_ct":0,"ask_ct":0},{"bid_px":null,"ask_px":null,"bid_sz":0,"ask_sz":0,"bid_ct":0,"ask_ct":0},{"bid_px":null,"ask_px":null,"bid_sz":0,"ask_sz":0,"bid_ct":0,"ask_ct":0},{"bid_px":null,"ask_px":null,"bid_sz":0,"ask_sz":0,"bid_ct":0,"ask_ct":0}],"symbol":"TSLA"}
{"ts_recv":"2024-11-01T08:00:02.819973569Z","hd":{"ts_event":"2024-11-01T08:00:02.819806929Z","rtype":10,"publisher_id":2,"instrument_id":16244},"action":"A","side":"A","depth":0,"price":"250.430000000","size":13,"flags":130,"ts_in_delta":166640,"sequence":292612,"levels":[{"bid_px":"249.800000000","ask_px":"250.430000000","bid_sz":1000,"ask_sz":13,"bid_ct":1,"ask_ct":1},{"bid_px":"249.600000000","ask_px":"250.830000000","bid_sz":1000,"ask_sz":100,"bid_ct":1,"ask_ct":1},{"bid_px":"247.150000000","ask_px":"252.300000000","bid_sz":400,"ask_sz":1000,"bid_ct":1,"ask_ct":1},{"bid_px":"235.000000000","ask_px":"253.650000000","bid_sz":100,"ask_sz":400,"bid_ct":1,"ask_ct":1},{"bid_px":"203.000000000","ask_px":"960.000000000","bid_sz":2,"ask_sz":25,"bid_ct":1,"ask_ct":1},{"bid_px":"170.000000000","ask_px":null,"bid_sz":3,"ask_sz":0,"bid_ct":1,"ask_ct":0},{"bid_px":null,"ask_px":null,"bid_sz":0,"ask_sz":0,"bid_ct":0,"ask_ct":0},{"bid_px":null,"ask_px":null,"bid_sz":0,"ask_sz":0,"bid_ct":0,"ask_ct":0},{"bid_px":null,"ask_px":null,"bid_sz":0,"ask_sz":0,"bid_ct":0,"ask_ct":0},{"bid_px":null,"ask_px":null,"bid_sz":0,"ask_sz":0,"bid_ct":0,"ask_ct":0}],"symbol":"TSLA"}
{"ts_recv":"2024-11-01T08:00:02.819984926Z","hd":{"ts_event":"2024-11-01T08:00:02.819819196Z","rtype":10,"publisher_id":2,"instrument_id":16244},"action":"C","side":"A","depth":0,"price":"250.430000000","size":13,"flags":130,"ts_in_delta":165730,"sequence":292613,"levels":[{"bid_px":"249.800000000","ask_px":"250.830000000","bid_sz":1000,"ask_sz":100,"bid_ct":1,"ask_ct":1},{"bid_px":"249.600000000","ask_px":"252.300000000","bid_sz":1000,"ask_sz":1000,"bid_ct":1,"ask_ct":1},{"bid_px":"247.150000000","ask_px":"253.650000000","bid_sz":400,"ask_sz":400,"bid_ct":1,"ask_ct":1},{"bid_px":"235.000000000","ask_px":"960.000000000","bid_sz":100,"ask_sz":25,"bid_ct":1,"ask_ct":1},{"bid_px":"203.000000000","ask_px":null,"bid_sz":2,"ask_sz":0,"bid_ct":1,"ask_ct":0},{"bid_px":"170.000000000","ask_px":null,"bid_sz":3,"ask_sz":0,"bid_ct":1,"ask_ct":0},{"bid_px":null,"ask_px":null,"bid_sz":0,"ask_sz":0,"bid_ct":0,"ask_ct":0},{"bid_px":null,"ask_px":null,"bid_sz":0,"ask_sz":0,"bid_ct":0,"ask_ct":0},{"bid_px":null,"ask_px":null,"bid_sz":0,"ask_sz":0,"bid_ct":0,"ask_ct":0},{"bid_px":null,"ask_px":null,"bid_sz":0,"ask_sz":0,"bid_ct":0,"ask_ct":0}],"symbol":"TSLA"}
{"ts_recv":"2024-11-01T08:00:02.821250331Z","hd":{"ts_event":"2024-11-01T08:00:02.821084428Z","rtype":10,"publisher_id":2,"instrument_id":16244},"action":"C","side":"B","depth":0,"price":"249.800000000","size":1000,"flags":130,"ts_in_delta":165903,"sequence":292616,"levels":[{"bid_px":"249.600000000","ask_px":"250.830000000","bid_sz":1000,"ask_sz":100,"bid_ct":1,"ask_ct":1},{"bid_px":"247.150000000","ask_px":"252.300000000","bid_sz":400,"ask_sz":1000,"bid_ct":1,"ask_ct":1},{"bid_px":"235.000000000","ask_px":"253.650000000","bid_sz":100,"ask_sz":400,"bid_ct":1,"ask_ct":1},{"bid_px":"203.000000000","ask_px":"960.000000000","bid_sz":2,"ask_sz":25,"bid_ct":1,"ask_ct":1},{"bid_px":"170.000000000","ask_px":null,"bid_sz":3,"ask_sz":0,"bid_ct":1,"ask_ct":0},{"bid_px":null,"ask_px":null,"bid_sz":0,"ask_sz":0,"bid_ct":0,"ask_ct":0},{"bid_px":null,"ask_px":null,"bid_sz":0,"ask_sz":0,"bid_ct":0,"ask_ct":0},{"bid_px":null,"ask_px":null,"bid_sz":0,"ask_sz":0,"bid_ct":0,"ask_ct":0},{"bid_px":null,"ask_px":null,"bid_sz":0,"ask_sz":0,"bid_ct":0,"ask_ct":0},{"bid_px":null,"ask_px":null,"bid_sz":0,"ask_sz":0,"bid_ct":0,"ask_ct":0}],"symbol":"TSLA"}
{"ts_recv":"2024-11-01T08:00:02.830665898Z","hd":{"ts_event":"2024-11-01T08:00:02.830499730Z","rtype":10,"publisher_id":2,"instrument_id":16244},"action":"A","side":"A","depth":0,"price":"250.830000000","size":100,"flags":130,"ts_in_delta":166168,"sequence":292626,"levels":[{"bid_px":"249.600000000","ask_px":"250.830000000","bid_sz":1000,"ask_sz":200,"bid_ct":1,"ask_ct":2},{"bid_px":"247.150000000","ask_px":"252.300000000","bid_sz":400,"ask_sz":1000,"bid_ct":1,"ask_ct":1},{"bid_px":"235.000000000","ask_px":"253.650000000","bid_sz":100,"ask_sz":400,"bid_ct":1,"ask_ct":1},{"bid_px":"203.000000000","ask_px":"960.000000000","bid_sz":2,"ask_sz":25,"bid_ct":1,"ask_ct":1},{"bid_px":"170.000000000","ask_px":null,"bid_sz":3,"ask_sz":0,"bid_ct":1,"ask_ct":0},{"bid_px":null,"ask_px":null,"bid_sz":0,"ask_sz":0,"bid_ct":0,"ask_ct":0},{"bid_px":null,"ask_px":null,"bid_sz":0,"ask_sz":0,"bid_ct":0,"ask_ct":0},{"bid_px":null,"ask_px":null,"bid_sz":0,"ask_sz":0,"bid_ct":0,"ask_ct":0},{"bid_px":null,"ask_px":null,"bid_sz":0,"ask_sz":0,"bid_ct":0,"ask_ct":0},{"bid_px":null,"ask_px":null,"bid_sz":0,"ask_sz":0,"bid_ct":0,"ask_ct":0}],"symbol":"TSLA"}
{"ts_recv":"2024-11-01T08:00:02.844290141Z","hd":{"ts_event":"2024-11-01T08:00:02.844123787Z","rtype":10,"publisher_id":2,"instrument_id":16244},"action":"A","side":"A","depth":1,"price":"252.200000000","size":1000,"flags":130,"ts_in_delta":166354,"sequence":292637,"levels":[{"bid_px":"249.600000000","ask_px":"250.830000000","bid_sz":1000,"ask_sz":200,"bid_ct":1,"ask_ct":2},{"bid_px":"247.150000000","ask_px":"252.200000000","bid_sz":400,"ask_sz":1000,"bid_ct":1,"ask_ct":1},{"bid_px":"235.000000000","ask_px":"252.300000000","bid_sz":100,"ask_sz":1000,"bid_ct":1,"ask_ct":1},{"bid_px":"203.000000000","ask_px":"253.650000000","bid_sz":2,"ask_sz":400,"bid_ct":1,"ask_ct":1},{"bid_px":"170.000000000","ask_px":"960.000000000","bid_sz":3,"ask_sz":25,"bid_ct":1,"ask_ct":1},{"bid_px":null,"ask_px":null,"bid_sz":0,"ask_sz":0,"bid_ct":0,"ask_ct":0},{"bid_px":null,"ask_px":null,"bid_sz":0,"ask_sz":0,"bid_ct":0,"ask_ct":0},{"bid_px":null,"ask_px":null,"bid_sz":0,"ask_sz":0,"bid_ct":0,"ask_ct":0},{"bid_px":null,"ask_px":null,"bid_sz":0,"ask_sz":0,"bid_ct":0,"ask_ct":0},{"bid_px":null,"ask_px":null,"bid_sz":0,"ask_sz":0,"bid_ct":0,"ask_ct":0}],"symbol":"TSLA"}
{"ts_recv":"2024-11-01T08:00:02.844344811Z","hd":{"ts_event":"2024-11-01T08:00:02.844178721Z","rtype":10,"publisher_id":2,"instrument_id":16244},"action":"C","side":"A","depth":2,"price":"252.300000000","size":1000,"flags":130,"ts_in_delta":166090,"sequence":292638,"levels":[{"bid_px":"249.600000000","ask_px":"250.830000000","bid_sz":1000,"ask_sz":200,"bid_ct":1,"ask_ct":2},{"bid_px":"247.150000000","ask_px":"252.200000000","bid_sz":400,"ask_sz":1000,"bid_ct":1,"ask_ct":1},{"bid_px":"235.000000000","ask_px":"253.650000000","bid_sz":100,"ask_sz":400,"bid_ct":1,"ask_ct":1},{"bid_px":"203.000000000","ask_px":"960.000000000","bid_sz":2,"ask_sz":25,"bid_ct":1,"ask_ct":1},{"bid_px":"170.000000000","ask_px":null,"bid_sz":3,"ask_sz":0,"bid_ct":1,"ask_ct":0},{"bid_px":null,"ask_px":null,"bid_sz":0,"ask_sz":0,"bid_ct":0,"ask_ct":0},{"bid_px":null,"ask_px":null,"bid_sz":0,"ask_sz":0,"bid_ct":0,"ask_ct":0},{"bid_px":null,"ask_px":null,"bid_sz":0,"ask_sz":0,"bid_ct":0,"ask_ct":0},{"bid_px":null,"ask_px":null,"bid_sz":0,"ask_sz":0,"bid_ct":0,"ask_ct":0},{"bid_px":null,"ask_px":null,"bid_sz":0,"ask_sz":0,"bid_ct":0,"ask_ct":0}],"symbol":"TSLA"}
{"ts_recv":"2024-11-01T08:00:02.858272469Z","hd":{"ts_event":"2024-11-01T08:00:02.858106249Z","rtype":10,"publisher_id":2,"instrument_id":16244},"action":"A","side":"B","depth":1,"price":"249.100000000","size":1000,"flags":130,"ts_in_delta":166220,"sequence":292648,"levels":[{"bid_px":"249.600000000","ask_px":"250.830000000","bid_sz":1000,"ask_sz":200,"bid_ct":1,"ask_ct":2},{"bid_px":"249.100000000","ask_px":"252.200000000","bid_sz":1000,"ask_sz":1000,"bid_ct":1,"ask_ct":1},{"bid_px":"247.150000000","ask_px":"253.650000000","bid_sz":400,"ask_sz":400,"bid_ct":1,"ask_ct":1},{"bid_px":"235.000000000","ask_px":"960.000000000","bid_sz":100,"ask_sz":25,"bid_ct":1,"ask_ct":1},{"bid_px":"203.000000000","ask_px":null,"bid_sz":2,"ask_sz":0,"bid_ct":1,"ask_ct":0},{"bid_px":"170.000000000","ask_px":null,"bid_sz":3,"ask_sz":0,"bid_ct":1,"ask_ct":0},{"bid_px":null,"ask_px":null,"bid_sz":0,"ask_sz":0,"bid_ct":0,"ask_ct":0},{"bid_px":null,"ask_px":null,"bid_sz":0,"ask_sz":0,"bid_ct":0,"ask_ct":0},{"bid_px":null,"ask_px":null,"bid_sz":0,"ask_sz":0,"bid_ct":0,"ask_ct":0},{"bid_px":null,"ask_px":null,"bid_sz":0,"ask_sz":0,"bid_ct":0,"ask_ct":0}],"symbol":"TSLA"}
{"ts_recv":"2024-11-01T08:00:02.895223166Z","hd":{"ts_event":"2024-11-01T08:00:02.895056773Z","rtype":10,"publisher_id":2,"instrument_id":17709},"action":"A","side":"B","depth":0,"price":"116.000000000","size":100,"flags":130,"ts_in_delta":166393,"sequence":292817,"levels":[{"bid_px":"116.000000000","ask_px":"118.320000000","bid_sz":100,"ask_sz":856,"bid_ct":1,"ask_ct":1},{"bid_px":"115.320000000","ask_px":"118.600000000","bid_sz":100,"ask_sz":100,"bid_ct":1,"ask_ct":1},{"bid_px":"115.280000000","ask_px":null,"bid_sz":856,"ask_sz":0,"bid_ct":1,"ask_ct":0},{"bid_px":null,"ask_px":null,"bid_sz":0,"ask_sz":0,"bid_ct":0,"ask_ct":0},{"bid_px":null,"ask_px":null,"bid_sz":0,"ask_sz":0,"bid_ct":0,"ask_ct":0},{"bid_px":null,"ask_px":null,"bid_sz":0,"ask_sz":0,"bid_ct":0,"ask_ct":0},{"bid_px":null,"ask_px":null,"bid_sz":0,"ask_sz":0,"bid_ct":0,"ask_ct":0},{"bid_px":null,"ask_px":null,"bid_sz":0,"ask_sz":0,"bid_ct":0,"ask_ct":0},{"bid_px":null,"ask_px":null,"bid_sz":0,"ask_sz":0,"bid_ct":0,"ask_ct":0},{"bid_px":null,"ask_px":null,"bid_sz":0,"ask_sz":0,"bid_ct":0,"ask_ct":0}],"symbol":"XOM"}
{"ts_recv":"2024-11-01T08:00:02.895656804Z","hd":{"ts_event":"2024-11-01T08:00:02.895491059Z","rtype":10,"publisher_id":2,"instrument_id":16244},"action":"C","side":"A","depth":0,"price":"250.830000000","size":100,"flags":130,"ts_in_delta":165745,"sequence":292819,"levels":[{"bid_px":"249.600000000","ask_px":"250.830000000","bid_sz":1000,"ask_sz":100,"bid_ct":1,"ask_ct":1},{"bid_px":"249.100000000","ask_px":"252.200000000","bid_sz":1000,"ask_sz":1000,"bid_ct":1,"ask_ct":1},{"bid_px":"247.150000000","ask_px":"253.650000000","bid_sz":400,"ask_sz":400,"bid_ct":1,"ask_ct":1},{"bid_px":"235.000000000","ask_px":"960.000000000","bid_sz":100,"ask_sz":25,"bid_ct":1,"ask_ct":1},{"bid_px":"203.000000000","ask_px":null,"bid_sz":2,"ask_sz":0,"bid_ct":1,"ask_ct":0},{"bid_px":"170.000000000","ask_px":null,"bid_sz":3,"ask_sz":0,"bid_ct":1,"ask_ct":0},{"bid_px":null,"ask_px":null,"bid_sz":0,"ask_sz":0,"bid_ct":0,"ask_ct":0},{"bid_px":null,"ask_px":null,"bid_sz":0,"ask_sz":0,"bid_ct":0,"ask_ct":0},{"bid_px":null,"ask_px":null,"bid_sz":0,"ask_sz":0,"bid_ct":0,"ask_ct":0},{"bid_px":null,"ask_px":null,"bid_sz":0,"ask_sz":0,"bid_ct":0,"ask_ct":0}],"symbol":"TSLA"}
{"ts_recv":"2024-11-01T08:00:02.895686744Z","hd":{"ts_event":"2024-11-01T08:00:02.895520294Z","rtype":10,"publisher_id":2,"instrument_id":16244},"action":"A","side":"A","depth":0,"price":"250.730000000","size":100,"flags":130,"ts_in_delta":166450,"sequence":292820,"levels":[{"bid_px":"249.600000000","ask_px":"250.730000000","bid_sz":1000,"ask_sz":100,"bid_ct":1,"ask_ct":1},{"bid_px":"249.100000000","ask_px":"252.200000000","bid_sz":1000,"ask_sz":1000,"bid_ct":1,"ask_ct":1},{"bid_px":"247.150000000","ask_px":"253.650000000","bid_sz":400,"ask_sz":400,"bid_ct":1,"ask_ct":1},{"bid_px":"235.000000000","ask_px":"960.000000000","bid_sz":100,"ask_sz":25,"bid_ct":1,"ask_ct":1},{"bid_px":"203.000000000","ask_px":null,"bid_sz":2,"ask_sz":0,"bid_ct":1,"ask_ct":0},{"bid_px":"170.000000000","ask_px":null,"bid_sz":3,"ask_sz":0,"bid_ct":1,"ask_ct":0},{"bid_px":null,"ask_px":null,"bid_sz":0,"ask_sz":0,"bid_ct":0,"ask_ct":0},{"bid_px":null,"ask_px":null,"bid_sz":0,"ask_sz":0,"bid_ct":0,"ask_ct":0},{"bid_px":null,"ask_px":null,"bid_sz":0,"ask_sz":0,"bid_ct":0,"ask_ct":0},{"bid_px":null,"ask_px":null,"bid_sz":0,"ask_sz":0,"bid_ct":0,"ask_ct":0}],"symbol":"TSLA"}
{"ts_recv":"2024-11-01T08:00:02.923206986Z","hd":{"ts_event":"2024-11-01T08:00:02.923040840Z","rtype":10,"publisher_id":2,"instrument_id":16244},"action":"A","side":"B","depth":0,"price":"249.870000000","size":50,"flags":130,"ts_in_delta":166146,"sequence":292854,"levels":[{"bid_px":"249.870000000","ask_px":"250.730000000","bid_sz":50,"ask_sz":100,"bid_ct":1,"ask_ct":1},{"bid_px":"249.600000000","ask_px":"252.200000000","bid_sz":1000,"ask_sz":1000,"bid_ct":1,"ask_ct":1},{"bid_px":"249.100000000","ask_px":"253.650000000","bid_sz":1000,"ask_sz":400,"bid_ct":1,"ask_ct":1},{"bid_px":"247.150000000","ask_px":"960.000000000","bid_sz":400,"ask_sz":25,"bid_ct":1,"ask_ct":1},{"bid_px":"235.000000000","ask_px":null,"bid_sz":100,"ask_sz":0,"bid_ct":1,"ask_ct":0},{"bid_px":"203.000000000","ask_px":null,"bid_sz":2,"ask_sz":0,"bid_ct":1,"ask_ct":0},{"bid_px":"170.000000000","ask_px":null,"bid_sz":3,"ask_sz":0,"bid_ct":1,"ask_ct":0},{"bid_px":null,"ask_px":null,"bid_sz":0,"ask_sz":0,"bid_ct":0,"ask_ct":0},{"bid_px":null,"ask_px":null,"bid_sz":0,"ask_sz":0,"bid_ct":0,"ask_ct":0},{"bid_px":null,"ask_px":null,"bid_sz":0,"ask_sz":0,"bid_ct":0,"ask_ct":0}],"symbol":"TSLA"}
{"ts_recv":"2024-11-01T08:00:02.941910475Z","hd":{"ts_event":"2024-11-01T08:00:02.941743559Z","rtype":10,"publisher_id":2,"instrument_id":16244},"action":"A","side":"B","depth":0,"price":"249.900000000","size":50,"flags":130,"ts_in_delta":166916,"sequence":292875,"levels":[{"bid_px":"249.900000000","ask_px":"250.730000000","bid_sz":50,"ask_sz":100,"bid_ct":1,"ask_ct":1},{"bid_px":"249.600000000","ask_px":"252.200000000","bid_sz":1000,"ask_sz":1000,"bid_ct":1,"ask_ct":1},{"bid_px":"249.100000000","ask_px":"253.650000000","bid_sz":1000,"ask_sz":400,"bid_ct":1,"ask_ct":1},{"bid_px":"247.150000000","ask_px":"960.000000000","bid_sz":400,"ask_sz":25,"bid_ct":1,"ask_ct":1},{"bid_px":"235.000000000","ask_px":null,"bid_sz":100,"ask_sz":0,"bid_ct":1,"ask_ct":0},{"bid_px":"203.000000000","ask_px":null,"bid_sz":2,"ask_sz":0,"bid_ct":1,"ask_ct":0},{"bid_px":"170.000000000","ask_px":null,"bid_sz":3,"ask_sz":0,"bid_ct":1,"ask_ct":0},{"bid_px":null,"ask_px":null,"bid_sz":0,"ask_sz":0,"bid_ct":0,"ask_ct":0},{"bid_px":null,"ask_px":null,"bid_sz":0,"ask_sz":0,"bid_ct":0,"ask_ct":0},{"bid_px":null,"ask_px":null,"bid_sz":0,"ask_sz":0,"bid_ct":0,"ask_ct":0}],"symbol":"TSLA"}
{"ts_recv":"2024-11-01T08:00:02.952347233Z","hd":{"ts_event":"2024-11-01T08:00:02.952181020Z","rtype":10,"publisher_id":2,"instrument_id":16244},"action":"A","side":"B","depth":2,"price":"249.500000000","size":1000,"flags":130,"ts_in_delta":166213,"sequence":292889,"levels":[{"bid_px":"249.900000000","ask_px":"250.730000000","bid_sz":50,"ask_sz":100,"bid_ct":1,"ask_ct":1},{"bid_px":"249.600000000","ask_px":"252.200000000","bid_sz":1000,"ask_sz":1000,"bid_ct":1,"ask_ct":1},{"bid_px":"249.500000000","ask_px":"253.650000000","bid_sz":1000,"ask_sz":400,"bid_ct":1,"ask_ct":1},{"bid_px":"249.100000000","ask_px":"960.000000000","bid_sz":1000,"ask_sz":25,"bid_ct":1,"ask_ct":1},{"bid_px":"247.150000000","ask_px":null,"bid_sz":400,"ask_sz":0,"bid_ct":1,"ask_ct":0},{"bid_px":"235.000000000","ask_px":null,"bid_sz":100,"ask_sz":0,"bid_ct":1,"ask_ct":0},{"bid_px":"203.000000000","ask_px":null,"bid_sz":2,"ask_sz":0,"bid_ct":1,"ask_ct":0},{"bid_px":"170.000000000","ask_px":null,"bid_sz":3,"ask_sz":0,"bid_ct":1,"ask_ct":0},{"bid_px":null,"ask_px":null,"bid_sz":0,"ask_sz":0,"bid_ct":0,"ask_ct":0},{"bid_px":null,"ask_px":null,"bid_sz":0,"ask_sz":0,"bid_ct":0,"ask_ct":0}],"symbol":"TSLA"}
{"ts_recv":"2024-11-01T08:00:02.952388850Z","hd":{"ts_event":"2024-11-01T08:00:02.952222880Z","rtype":10,"publisher_id":2,"instrument_id":16244},"action":"C","side":"B","depth":3,"price":"249.100000000","size":1000,"flags":130,"ts_in_delta":165970,"sequence":292890,"levels":[{"bid_px":"249.900000000","ask_px":"250.730000000","bid_sz":50,"ask_sz":100,"bid_ct":1,"ask_ct":1},{"bid_px":"249.600000000","ask_px":"252.200000000","bid_sz":1000,"ask_sz":1000,"bid_ct":1,"ask_ct":1},{"bid_px":"249.500000000","ask_px":"253.650000000","bid_sz":1000,"ask_sz":400,"bid_ct":1,"ask_ct":1},{"bid_px":"247.150000000","ask_px":"960.000000000","bid_sz":400,"ask_sz":25,"bid_ct":1,"ask_ct":1},{"bid_px":"235.000000000","ask_px":null,"bid_sz":100,"ask_sz":0,"bid_ct":1,"ask_ct":0},{"bid_px":"203.000000000","ask_px":null,"bid_sz":2,"ask_sz":0,"bid_ct":1,"ask_ct":0},{"bid_px":"170.000000000","ask_px":null,"bid_sz":3,"ask_sz":0,"bid_ct":1,"ask_ct":0},{"bid_px":null,"ask_px":null,"bid_sz":0,"ask_sz":0,"bid_ct":0,"ask_ct":0},{"bid_px":null,"ask_px":null,"bid_sz":0,"ask_sz":0,"bid_ct":0,"ask_ct":0},{"bid_px":null,"ask_px":null,"bid_sz":0,"ask_sz":0,"bid_ct":0,"ask_ct":0}],"symbol":"TSLA"}
{"ts_recv":"2024-11-01T08:00:02.963417496Z","hd":{"ts_event":"2024-11-01T08:00:02.963251228Z","rtype":10,"publisher_id":2,"instrument_id":16244},"action":"A","side":"B","depth":3,"price":"248.700000000","size":1000,"flags":130,"ts_in_delta":166268,"sequence":292897,"levels":[{"bid_px":"249.900000000","ask_px":"250.730000000","bid_sz":50,"ask_sz":100,"bid_ct":1,"ask_ct":1},{"bid_px":"249.600000000","ask_px":"252.200000000","bid_sz":1000,"ask_sz":1000,"bid_ct":1,"ask_ct":1},{"bid_px":"249.500000000","ask_px":"253.650000000","bid_sz":1000,"ask_sz":400,"bid_ct":1,"ask_ct":1},{"bid_px":"248.700000000","ask_px":"960.000000000","bid_sz":1000,"ask_sz":25,"bid_ct":1,"ask_ct":1},{"bid_px":"247.150000000","ask_px":null,"bid_sz":400,"ask_sz":0,"bid_ct":1,"ask_ct":0},{"bid_px":"235.000000000","ask_px":null,"bid_sz":100,"ask_sz":0,"bid_ct":1,"ask_ct":0},{"bid_px":"203.000000000","ask_px":null,"bid_sz":2,"ask_sz":0,"bid_ct":1,"ask_ct":0},{"bid_px":"170.000000000","ask_px":null,"bid_sz":3,"ask_sz":0,"bid_ct":1,"ask_ct":0},{"bid_px":null,"ask_px":null,"bid_sz":0,"ask_sz":0,"bid_ct":0,"ask_ct":0},{"bid_px":null,"ask_px":null,"bid_sz":0,"ask_sz":0,"bid_ct":0,"ask_ct":0}],"symbol":"TSLA"}
{"ts_recv":"2024-11-01T08:00:02.972222719Z","hd":{"ts_event":"2024-11-01T08:00:02.972055985Z","rtype":10,"publisher_id":2,"instrument_id":12463},"action":"A","side":"N","depth":0,"price":"163.080000000","size":100,"flags":130,"ts_in_delta":166734,"sequence":292905,"levels":[{"bid_px":"163.080000000","ask_px":null,"bid_sz":100,"ask_sz":0,"bid_ct":1,"ask_ct":0},{"bid_px":null,"ask_px":null,"bid_sz":0,"ask_sz":0,"bid_ct":0,"ask_ct":0},{"bid_px":null,"ask_px":null,"bid_sz":0,"ask_sz":0,"bid_ct":0,"ask_ct":0},{"bid_px":null,"ask_px":null,"bid_sz":0,"ask_sz":0,"bid_ct":0,"ask_ct":0},{"bid_px":null,"ask_px":null,"bid_sz":0,"ask_sz":0,"bid_ct":0,"ask_ct":0},{"bid_px":null,"ask_px":null,"bid_sz":0,"ask_sz":0,"bid_ct":0,"ask_ct":0},{"bid_px":null,"ask_px":null,"bid_sz":0,"ask_sz":0,"bid_ct":0,"ask_ct":0},{"bid_px":null,"ask_px":null,"bid_sz":0,"ask_sz":0,"bid_ct":0,"ask_ct":0},{"bid_px":null,"ask_px":null,"bid_sz":0,"ask_sz":0,"bid_ct":0,"ask_ct":0},{"bid_px":null,"ask_px":null,"bid_sz":0,"ask_sz":0,"bid_ct":0,"ask_ct":0}],"symbol":"PEP"}
{"ts_recv":"2024-11-01T08:00:03.011423815Z","hd":{"ts_event":"2024-11-01T08:00:03.011257518Z","rtype":10,"publisher_id":2,"instrument_id":11667},"action":"A","side":"B","depth":6,"price":"129.000000000","size":10,"flags":130,"ts_in_delta":166297,"sequence":293036,"levels":[{"bid_px":"134.770000000","ask_px":"135.300000000","bid_sz":100,"ask_sz":1000,"bid_ct":1,"ask_ct":1},{"bid_px":"134.410000000","ask_px":"136.100000000","bid_sz":1,"ask_sz":1000,"bid_ct":1,"ask_ct":1},{"bid_px":"134.210000000","ask_px":"137.680000000","bid_sz":20,"ask_sz":500,"bid_ct":1,"ask_ct":1},{"bid_px":"133.200000000","ask_px":"138.870000000","bid_sz":1000,"ask_sz":1000,"bid_ct":1,"ask_ct":2},{"bid_px":"132.000000000","ask_px":"140.740000000","bid_sz":71,"ask_sz":100,"bid_ct":2,"ask_ct":1},{"bid_px":"129.050000000","ask_px":"140.880000000","bid_sz":500,"ask_sz":1000,"bid_ct":1,"ask_ct":2},{"bid_px":"129.000000000","ask_px":"143.690000000","bid_sz":10,"ask_sz":500,"bid_ct":1,"ask_ct":1},{"bid_px":"128.470000000","ask_px":"146.510000000","bid_sz":500,"ask_sz":5,"bid_ct":1,"ask_ct":1},{"bid_px":"127.680000000","ask_px":"148.000000000","bid_sz":30,"ask_sz":5,"bid_ct":1,"ask_ct":1},{"bid_px":"127.000000000","ask_px":null,"bid_sz":20,"ask_sz":0,"bid_ct":1,"ask_ct":0}],"symbol":"NVDA"}
{"ts_recv":"2024-11-01T08:00:03.032059829Z","hd":{"ts_event":"2024-11-01T08:00:03.031893056Z","rtype":10,"publisher_id":2,"instrument_id":16244},"action":"A","side":"B","depth":0,"price":"249.930000000","size":50,"flags":130,"ts_in_delta":166773,"sequence":293097,"levels":[{"bid_px":"249.930000000","ask_px":"250.730000000","bid_sz":50,"ask_sz":100,"bid_ct":1,"ask_ct":1},{"bid_px":"249.600000000","ask_px":"252.200000000","bid_sz":1000,"ask_sz":1000,"bid_ct":1,"ask_ct":1},{"bid_px":"249.500000000","ask_px":"253.650000000","bid_sz":1000,"ask_sz":400,"bid_ct":1,"ask_ct":1},{"bid_px":"248.700000000","ask_px":"960.000000000","bid_sz":1000,"ask_sz":25,"bid_ct":1,"ask_ct":1},{"bid_px":"247.150000000","ask_px":null,"bid_sz":400,"ask_sz":0,"bid_ct":1,"ask_ct":0},{"bid_px":"235.000000000","ask_px":null,"bid_sz":100,"ask_sz":0,"bid_ct":1,"ask_ct":0},{"bid_px":"203.000000000","ask_px":null,"bid_sz":2,"ask_sz":0,"bid_ct":1,"ask_ct":0},{"bid_px":"170.000000000","ask_px":null,"bid_sz":3,"ask_sz":0,"bid_ct":1,"ask_ct":0},{"bid_px":null,"ask_px":null,"bid_sz":0,"ask_sz":0,"bid_ct":0,"ask_ct":0},{"bid_px":null,"ask_px":null,"bid_sz":0,"ask_sz":0,"bid_ct":0,"ask_ct":0}],"symbol":"TSLA"}
{"ts_recv":"2024-11-01T08:00:03.032778841Z","hd":{"ts_event":"2024-11-01T08:00:03.032613046Z","rtype":10,"publisher_id":2,"instrument_id":16244},"action":"C","side":"B","depth":0,"price":"249.930000000","size":50,"flags":130,"ts_in_delta":165795,"sequence":293101,"levels":[{"bid_px":"249.600000000","ask_px":"250.730000000","bid_sz":1000,"ask_sz":100,"bid_ct":1,"ask_ct":1},{"bid_px":"249.500000000","ask_px":"252.200000000","bid_sz":1000,"ask_sz":1000,"bid_ct":1,"ask_ct":1},{"bid_px":"248.700000000","ask_px":"253.650000000","bid_sz":1000,"ask_sz":400,"bid_ct":1,"ask_ct":1},{"bid_px":"247.150000000","ask_px":"960.000000000","bid_sz":400,"ask_sz":25,"bid_ct":1,"ask_ct":1},{"bid_px":"235.000000000","ask_px":null,"bid_sz":100,"ask_sz":0,"bid_ct":1,"ask_ct":0},{"bid_px":"203.000000000","ask_px":null,"bid_sz":2,"ask_sz":0,"bid_ct":1,"ask_ct":0},{"bid_px":"170.000000000","ask_px":null,"bid_sz":3,"ask_sz":0,"bid_ct":1,"ask_ct":0},{"bid_px":null,"ask_px":null,"bid_sz":0,"ask_sz":0,"bid_ct":0,"ask_ct":0},{"bid_px":null,"ask_px":null,"bid_sz":0,"ask_sz":0,"bid_ct":0,"ask_ct":0},{"bid_px":null,"ask_px":null,"bid_sz":0,"ask_sz":0,"bid_ct":0,"ask_ct":0}],"symbol":"TSLA"}
{"ts_recv":"2024-11-01T08:00:03.032790852Z","hd":{"ts_event":"2024-11-01T08:00:03.032624801Z","rtype":10,"publisher_id":2,"instrument_id":16244},"action":"A","side":"B","depth":0,"price":"249.900000000","size":50,"flags":130,"ts_in_delta":166051,"sequence":293102,"levels":[{"bid_px":"249.900000000","ask_px":"250.730000000","bid_sz":50,"ask_sz":100,"bid_ct":1,"ask_ct":1},{"bid_px":"249.600000000","ask_px":"252.200000000","bid_sz":1000,"ask_sz":1000,"bid_ct":1,"ask_ct":1},{"bid_px":"249.500000000","ask_px":"253.650000000","bid_sz":1000,"ask_sz":400,"bid_ct":1,"ask_ct":1},{"bid_px":"248.700000000","ask_px":"960.000000000","bid_sz":1000,"ask_sz":25,"bid_ct":1,"ask_ct":1},{"bid_px":"247.150000000","ask_px":null,"bid_sz":400,"ask_sz":0,"bid_ct":1,"ask_ct":0},{"bid_px":"235.000000000","ask_px":null,"bid_sz":100,"ask_sz":0,"bid_ct":1,"ask_ct":0},{"bid_px":"203.000000000","ask_px":null,"bid_sz":2,"ask_sz":0,"bid_ct":1,"ask_ct":0},{"bid_px":"170.000000000","ask_px":null,"bid_sz":3,"ask_sz":0,"bid_ct":1,"ask_ct":0},{"bid_px":null,"ask_px":null,"bid_sz":0,"ask_sz":0,"bid_ct":0,"ask_ct":0},{"bid_px":null,"ask_px":null,"bid_sz":0,"ask_sz":0,"bid_ct":0,"ask_ct":0}],"symbol":"TSLA"}
{"ts_recv":"2024-11-01T08:00:03.078595680Z","hd":{"ts_event":"2024-11-01T08:00:03.078428790Z","rtype":10,"publisher_id":2,"instrument_id":16244},"action":"C","side":"B","depth":0,"price":"249.900000000","size":50,"flags":130,"ts_in_delta":166890,"sequence":293176,"levels":[{"bid_px":"249.600000000","ask_px":"250.730000000","bid_sz":1000,"ask_sz":100,"bid_ct":1,"ask_ct":1},{"bid_px":"249.500000000","ask_px":"252.200000000","bid_sz":1000,"ask_sz":1000,"bid_ct":1,"ask_ct":1},{"bid_px":"248.700000000","ask_px":"253.650000000","bid_sz":1000,"ask_sz":400,"bid_ct":1,"ask_ct":1},{"bid_px":"247.150000000","ask_px":"960.000000000","bid_sz":400,"ask_sz":25,"bid_ct":1,"ask_ct":1},{"bid_px":"235.000000000","ask_px":null,"bid_sz":100,"ask_sz":0,"bid_ct":1,"ask_ct":0},{"bid_px":"203.000000000","ask_px":null,"bid_sz":2,"ask_sz":0,"bid_ct":1,"ask_ct":0},{"bid_px":"170.000000000","ask_px":null,"bid_sz":3,"ask_sz":0,"bid_ct":1,"ask_ct":0},{"bid_px":null,"ask_px":null,"bid_sz":0,"ask_sz":0,"bid_ct":0,"ask_ct":0},{"bid_px":null,"ask_px":null,"bid_sz":0,"ask_sz":0,"bid_ct":0,"ask_ct":0},{"bid_px":null,"ask_px":null,"bid_sz":0,"ask_sz":0,"bid_ct":0,"ask_ct":0}],"symbol":"TSLA"}
{"ts_recv":"2024-11-01T08:00:03.078608523Z","hd":{"ts_event":"2024-11-01T08:00:03.078442368Z","rtype":10,"publisher_id":2,"instrument_id":16244},"action":"A","side":"B","depth":0,"price":"249.870000000","size":50,"flags":130,"ts_in_delta":166155,"sequence":293177,"levels":[{"bid_px":"249.870000000","ask_px":"250.730000000","bid_sz":50,"ask_sz":100,"bid_ct":1,"ask_ct":1},{"bid_px":"249.600000000","ask_px":"252.200000000","bid_sz":1000,"ask_sz":1000,"bid_ct":1,"ask_ct":1},{"bid_px":"249.500000000","ask_px":"253.650000000","bid_sz":1000,"ask_sz":400,"bid_ct":1,"ask_ct":1},{"bid_px":"248.700000000","ask_px":"960.000000000","bid_sz":1000,"ask_sz":25,"bid_ct":1,"ask_ct":1},{"bid_px":"247.150000000","ask_px":null,"bid_sz":400,"ask_sz":0,"bid_ct":1,"ask_ct":0},{"bid_px":"235.000000000","ask_px":null,"bid_sz":100,"ask_sz":0,"bid_ct":1,"ask_ct":0},{"bid_px":"203.000000000","ask_px":null,"bid_sz":2,"ask_sz":0,"bid_ct":1,"ask_ct":0},{"bid_px":"170.000000000","ask_px":null,"bid_sz":3,"ask_sz":0,"bid_ct":1,"ask_ct":0},{"bid_px":null,"ask_px":null,"bid_sz":0,"ask_sz":0,"bid_ct":0,"ask_ct":0},{"bid_px":null,"ask_px":null,"bid_sz":0,"ask_sz":0,"bid_ct":0,"ask_ct":0}],"symbol":"TSLA"}
{"ts_recv":"2024-11-01T08:00:03.078689152Z","hd":{"ts_event":"2024-11-01T08:00:03.078523259Z","rtype":10,"publisher_id":2,"instrument_id":16244},"action":"C","side":"B","depth":0,"price":"249.870000000","size":50,"flags":130,"ts_in_delta":165893,"sequence":293178,"levels":[{"bid_px":"249.600000000","ask_px":"250.730000000","bid_sz":1000,"ask_sz":100,"bid_ct":1,"ask_ct":1},{"bid_px":"249.500000000","ask_px":"252.200000000","bid_sz":1000,"ask_sz":1000,"bid_ct":1,"ask_ct":1},{"bid_px":"248.700000000","ask_px":"253.650000000","bid_sz":1000,"ask_sz":400,"bid_ct":1,"ask_ct":1},{"bid_px":"247.150000000","ask_px":"960.000000000","bid_sz":400,"ask_sz":25,"bid_ct":1,"ask_ct":1},{"bid_px":"235.000000000","ask_px":null,"bid_sz":100,"ask_sz":0,"bid_ct":1,"ask_ct":0},{"bid_px":"203.000000000","ask_px":null,"bid_sz":2,"ask_sz":0,"bid_ct":1,"ask_ct":0},{"bid_px":"170.000000000","ask_px":null,"bid_sz":3,"ask_sz":0,"bid_ct":1,"ask_ct":0},{"bid_px":null,"ask_px":null,"bid_sz":0,"ask_sz":0,"bid_ct":0,"ask_ct":0},{"bid_px":null,"ask_px":null,"bid_sz":0,"ask_sz":0,"bid_ct":0,"ask_ct":0},{"bid_px":null,"ask_px":null,"bid_sz":0,"ask_sz":0,"bid_ct":0,"ask_ct":0}],"symbol":"TSLA"}
{"ts_recv":"2024-11-01T08:00:03.078712855Z","hd":{"ts_event":"2024-11-01T08:00:03.078546687Z","rtype":10,"publisher_id":2,"instrument_id":16244},"action":"A","side":"B","depth":0,"price":"249.850000000","size":50,"flags":130,"ts_in_delta":166168,"sequence":293179,"levels":[{"bid_px":"249.850000000","ask_px":"250.730000000","bid_sz":50,"ask_sz":100,"bid_ct":1,"ask_ct":1},{"bid_px":"249.600000000","ask_px":"252.200000000","bid_sz":1000,"ask_sz":1000,"bid_ct":1,"ask_ct":1},{"bid_px":"249.500000000","ask_px":"253.650000000","bid_sz":1000,"ask_sz":400,"bid_ct":1,"ask_ct":1},{"bid_px":"248.700000000","ask_px":"960.000000000","bid_sz":1000,"ask_sz":25,"bid_ct":1,"ask_ct":1},{"bid_px":"247.150000000","ask_px":null,"bid_sz":400,"ask_sz":0,"bid_ct":1,"ask_ct":0},{"bid_px":"235.000000000","ask_px":null,"bid_sz":100,"ask_sz":0,"bid_ct":1,"ask_ct":0},{"bid_px":"203.000000000","ask_px":null,"bid_sz":2,"ask_sz":0,"bid_ct":1,"ask_ct":0},{"bid_px":"170.000000000","ask_px":null,"bid_sz":3,"ask_sz":0,"bid_ct":1,"ask_ct":0},{"bid_px":null,"ask_px":null,"bid_sz":0,"ask_sz":0,"bid_ct":0,"ask_ct":0},{"bid_px":null,"ask_px":null,"bid_sz":0,"ask_sz":0,"bid_ct":0,"ask_ct":0}],"symbol":"TSLA"}
{"ts_recv":"2024-11-01T08:00:03.146238622Z","hd":{"ts_event":"2024-11-01T08:00:03.146072343Z","rtype":10,"publisher_id":2,"instrument_id":16244},"action":"A","side":"A","depth":1,"price":"250.960000000","size":50,"flags":130,"ts_in_delta":166279,"sequence":293289,"levels":[{"bid_px":"249.850000000","ask_px":"250.730000000","bid_sz":50,"ask_sz":100,"bid_ct":1,"ask_ct":1},{"bid_px":"249.600000000","ask_px":"250.960000000","bid_sz":1000,"ask_sz":50,"bid_ct":1,"ask_ct":1},{"bid_px":"249.500000000","ask_px":"252.200000000","bid_sz":1000,"ask_sz":1000,"bid_ct":1,"ask_ct":1},{"bid_px":"248.700000000","ask_px":"253.650000000","bid_sz":1000,"ask_sz":400,"bid_ct":1,"ask_ct":1},{"bid_px":"247.150000000","ask_px":"960.000000000","bid_sz":400,"ask_sz":25,"bid_ct":1,"ask_ct":1},{"bid_px":"235.000000000","ask_px":null,"bid_sz":100,"ask_sz":0,"bid_ct":1,"ask_ct":0},{"bid_px":"203.000000000","ask_px":null,"bid_sz":2,"ask_sz":0,"bid_ct":1,"ask_ct":0},{"bid_px":"170.000000000","ask_px":null,"bid_sz":3,"ask_sz":0,"bid_ct":1,"ask_ct":0},{"bid_px":null,"ask_px":null,"bid_sz":0,"ask_sz":0,"bid_ct":0,"ask_ct":0},{"bid_px":null,"ask_px":null,"bid_sz":0,"ask_sz":0,"bid_ct":0,"ask_ct":0}],"symbol":"TSLA"}
{"ts_recv":"2024-11-01T08:00:03.194370387Z","hd":{"ts_event":"2024-11-01T08:00:03.194203980Z","rtype":10,"publisher_id":2,"instrument_id":16244},"action":"A","side":"B","depth":2,"price":"249.500000000","size":1000,"flags":130,"ts_in_delta":166407,"sequence":293354,"levels":[{"bid_px":"249.850000000","ask_px":"250.730000000","bid_sz":50,"ask_sz":100,"bid_ct":1,"ask_ct":1},{"bid_px":"249.600000000","ask_px":"250.960000000","bid_sz":1000,"ask_sz":50,"bid_ct":1,"ask_ct":1},{"bid_px":"249.500000000","ask_px":"252.200000000","bid_sz":2000,"ask_sz":1000,"bid_ct":2,"ask_ct":1},{"bid_px":"248.700000000","ask_px":"253.650000000","bid_sz":1000,"ask_sz":400,"bid_ct":1,"ask_ct":1},{"bid_px":"247.150000000","ask_px":"960.000000000","bid_sz":400,"ask_sz":25,"bid_ct":1,"ask_ct":1},{"bid_px":"235.000000000","ask_px":null,"bid_sz":100,"ask_sz":0,"bid_ct":1,"ask_ct":0},{"bid_px":"203.000000000","ask_px":null,"bid_sz":2,"ask_sz":0,"bid_ct":1,"ask_ct":0},{"bid_px":"170.000000000","ask_px":null,"bid_sz":3,"ask_sz":0,"bid_ct":1,"ask_ct":0},{"bid_px":null,"ask_px":null,"bid_sz":0,"ask_sz":0,"bid_ct":0,"ask_ct":0},{"bid_px":null,"ask_px":null,"bid_sz":0,"ask_sz":0,"bid_ct":0,"ask_ct":0}],"symbol":"TSLA"}
{"ts_recv":"2024-11-01T08:00:03.194570308Z","hd":{"ts_event":"2024-11-01T08:00:03.194404399Z","rtype":10,"publisher_id":2,"instrument_id":16244},"action":"C","side":"B","depth":3,"price":"248.700000000","size":1000,"flags":130,"ts_in_delta":165909,"sequence":293355,"levels":[{"bid_px":"249.850000000","ask_px":"250.730000000","bid_sz":50,"ask_sz":100,"bid_ct":1,"ask_ct":1},{"bid_px":"249.600000000","ask_px":"250.960000000","bid_sz":1000,"ask_sz":50,"bid_ct":1,"ask_ct":1},{"bid_px":"249.500000000","ask_px":"252.200000000","bid_sz":2000,"ask_sz":1000,"bid_ct":2,"ask_ct":1},{"bid_px":"247.150000000","ask_px":"253.650000000","bid_sz":400,"ask_sz":400,"bid_ct":1,"ask_ct":1},{"bid_px":"235.000000000","ask_px":"960.000000000","bid_sz":100,"ask_sz":25,"bid_ct":1,"ask_ct":1},{"bid_px":"203.000000000","ask_px":null,"bid_sz":2,"ask_sz":0,"bid_ct":1,"ask_ct":0},{"bid_px":"170.000000000","ask_px":null,"bid_sz":3,"ask_sz":0,"bid_ct":1,"ask_ct":0},{"bid_px":null,"ask_px":null,"bid_sz":0,"ask_sz":0,"bid_ct":0,"ask_ct":0},{"bid_px":null,"ask_px":null,"bid_sz":0,"ask_sz":0,"bid_ct":0,"ask_ct":0},{"bid_px":null,"ask_px":null,"bid_sz":0,"ask_sz":0,"bid_ct":0,"ask_ct":0}],"symbol":"TSLA"}
{"ts_recv":"2024-11-01T08:00:03.205151206Z","hd":{"ts_event":"2024-11-01T08:00:03.204984748Z","rtype":10,"publisher_id":2,"instrument_id":16244},"action":"A","side":"B","depth":3,"price":"248.200000000","size":1000,"flags":130,"ts_in_delta":166458,"sequence":293360,"levels":[{"bid_px":"249.850000000","ask_px":"250.730000000","bid_sz":50,"ask_sz":100,"bid_ct":1,"ask_ct":1},{"bid_px":"249.600000000","ask_px":"250.960000000","bid_sz":1000,"ask_sz":50,"bid_ct":1,"ask_ct":1},{"bid_px":"249.500000000","ask_px":"252.200000000","bid_sz":2000,"ask_sz":1000,"bid_ct":2,"ask_ct":1},{"bid_px":"248.200000000","ask_px":"253.650000000","bid_sz":1000,"ask_sz":400,"bid_ct":1,"ask_ct":1},{"bid_px":"247.150000000","ask_px":"960.000000000","bid_sz":400,"ask_sz":25,"bid_ct":1,"ask_ct":1},{"bid_px":"235.000000000","ask_px":null,"bid_sz":100,"ask_sz":0,"bid_ct":1,"ask_ct":0},{"bid_px":"203.000000000","ask_px":null,"bid_sz":2,"ask_sz":0,"bid_ct":1,"ask_ct":0},{"bid_px":"170.000000000","ask_px":null,"bid_sz":3,"ask_sz":0,"bid_ct":1,"ask_ct":0},{"bid_px":null,"ask_px":null,"bid_sz":0,"ask_sz":0,"bid_ct":0,"ask_ct":0},{"bid_px":null,"ask_px":null,"bid_sz":0,"ask_sz":0,"bid_ct":0,"ask_ct":0}],"symbol":"TSLA"}
{"ts_recv":"2024-11-01T08:00:03.214331004Z","hd":{"ts_event":"2024-11-01T08:00:03.214163798Z","rtype":10,"publisher_id":2,"instrument_id":16244},"action":"A","side":"B","depth":0,"price":"249.870000000","size":50,"flags":130,"ts_in_delta":167206,"sequence":293369,"levels":[{"bid_px":"249.870000000","ask_px":"250.730000000","bid_sz":50,"ask_sz":100,"bid_ct":1,"ask_ct":1},{"bid_px":"249.600000000","ask_px":"250.960000000","bid_sz":1000,"ask_sz":50,"bid_ct":1,"ask_ct":1},{"bid_px":"249.500000000","ask_px":"252.200000000","bid_sz":2000,"ask_sz":1000,"bid_ct":2,"ask_ct":1},{"bid_px":"248.200000000","ask_px":"253.650000000","bid_sz":1000,"ask_sz":400,"bid_ct":1,"ask_ct":1},{"bid_px":"247.150000000","ask_px":"960.000000000","bid_sz":400,"ask_sz":25,"bid_ct":1,"ask_ct":1},{"bid_px":"235.000000000","ask_px":null,"bid_sz":100,"ask_sz":0,"bid_ct":1,"ask_ct":0},{"bid_px":"203.000000000","ask_px":null,"bid_sz":2,"ask_sz":0,"bid_ct":1,"ask_ct":0},{"bid_px":"170.000000000","ask_px":null,"bid_sz":3,"ask_sz":0,"bid_ct":1,"ask_ct":0},{"bid_px":null,"ask_px":null,"bid_sz":0,"ask_sz":0,"bid_ct":0,"ask_ct":0},{"bid_px":null,"ask_px":null,"bid_sz":0,"ask_sz":0,"bid_ct":0,"ask_ct":0}],"symbol":"TSLA"}
{"ts_recv":"2024-11-01T08:00:03.215083394Z","hd":{"ts_event":"2024-11-01T08:00:03.214917607Z","rtype":10,"publisher_id":2,"instrument_id":16244},"action":"C","side":"B","depth":2,"price":"249.500000000","size":1000,"flags":130,"ts_in_delta":165787,"sequence":293371,"levels":[{"bid_px":"249.870000000","ask_px":"250.730000000","bid_sz":50,"ask_sz":100,"bid_ct":1,"ask_ct":1},{"bid_px":"249.600000000","ask_px":"250.960000000","bid_sz":1000,"ask_sz":50,"bid_ct":1,"ask_ct":1},{"bid_px":"249.500000000","ask_px":"252.200000000","bid_sz":1000,"ask_sz":1000,"bid_ct":1,"ask_ct":1},{"bid_px":"248.200000000","ask_px":"253.650000000","bid_sz":1000,"ask_sz":400,"bid_ct":1,"ask_ct":1},{"bid_px":"247.150000000","ask_px":"960.000000000","bid_sz":400,"ask_sz":25,"bid_ct":1,"ask_ct":1},{"bid_px":"235.000000000","ask_px":null,"bid_sz":100,"ask_sz":0,"bid_ct":1,"ask_ct":0},{"bid_px":"203.000000000","ask_px":null,"bid_sz":2,"ask_sz":0,"bid_ct":1,"ask_ct":0},{"bid_px":"170.000000000","ask_px":null,"bid_sz":3,"ask_sz":0,"bid_ct":1,"ask_ct":0},{"bid_px":null,"ask_px":null,"bid_sz":0,"ask_sz":0,"bid_ct":0,"ask_ct":0},{"bid_px":null,"ask_px":null,"bid_sz":0,"ask_sz":0,"bid_ct":0,"ask_ct":0}],"symbol":"TSLA"}
{"ts_recv":"2024-11-01T08:00:03.225393824Z","hd":{"ts_event":"2024-11-01T08:00:03.225227516Z","rtype":10,"publisher_id":2,"instrument_id":16244},"action":"A","side":"B","depth":3,"price":"248.700000000","size":1000,"flags":130,"ts_in_delta":166308,"sequence":293382,"levels":[{"bid_px":"249.870000000","ask_px":"250.730000000","bid_sz":50,"ask_sz":100,"bid_ct":1,"ask_ct":1},{"bid_px":"249.600000000","ask_px":"250.960000000","bid_sz":1000,"ask_sz":50,"bid_ct":1,"ask_ct":1},{"bid_px":"249.500000000","ask_px":"252.200000000","bid_sz":1000,"ask_sz":1000,"bid_ct":1,"ask_ct":1},{"bid_px":"248.700000000","ask_px":"253.650000000","bid_sz":1000,"ask_sz":400,"bid_ct":1,"ask_ct":1},{"bid_px":"248.200000000","ask_px":"960.000000000","bid_sz":1000,"ask_sz":25,"bid_ct":1,"ask_ct":1},{"bid_px":"247.150000000","ask_px":null,"bid_sz":400,"ask_sz":0,"bid_ct":1,"ask_ct":0},{"bid_px":"235.000000000","ask_px":null,"bid_sz":100,"ask_sz":0,"bid_ct":1,"ask_ct":0},{"bid_px":"203.000000000","ask_px":null,"bid_sz":2,"ask_sz":0,"bid_ct":1,"ask_ct":0},{"bid_px":"170.000000000","ask_px":null,"bid_sz":3,"ask_sz":0,"bid_ct":1,"ask_ct":0},{"bid_px":null,"ask_px":null,"bid_sz":0,"ask_sz":0,"bid_ct":0,"ask_ct":0}],"symbol":"TSLA"}
{"ts_recv":"2024-11-01T08:00:03.225512312Z","hd":{"ts_event":"2024-11-01T08:00:03.225345068Z","rtype":10,"publisher_id":2,"instrument_id":16244},"action":"C","side":"B","depth":4,"price":"248.200000000","size":1000,"flags":130,"ts_in_delta":167244,"sequence":293383,"levels":[{"bid_px":"249.870000000","ask_px":"250.730000000","bid_sz":50,"ask_sz":100,"bid_ct":1,"ask_ct":1},{"bid_px":"249.600000000","ask_px":"250.960000000","bid_sz":1000,"ask_sz":50,"bid_ct":1,"ask_ct":1},{"bid_px":"249.500000000","ask_px":"252.200000000","bid_sz":1000,"ask_sz":1000,"bid_ct":1,"ask_ct":1},{"bid_px":"248.700000000","ask_px":"253.650000000","bid_sz":1000,"ask_sz":400,"bid_ct":1,"ask_ct":1},{"bid_px":"247.150000000","ask_px":"960.000000000","bid_sz":400,"ask_sz":25,"bid_ct":1,"ask_ct":1},{"bid_px":"235.000000000","ask_px":null,"bid_sz":100,"ask_sz":0,"bid_ct":1,"ask_ct":0},{"bid_px":"203.000000000","ask_px":null,"bid_sz":2,"ask_sz":0,"bid_ct":1,"ask_ct":0},{"bid_px":"170.000000000","ask_px":null,"bid_sz":3,"ask_sz":0,"bid_ct":1,"ask_ct":0},{"bid_px":null,"ask_px":null,"bid_sz":0,"ask_sz":0,"bid_ct":0,"ask_ct":0},{"bid_px":null,"ask_px":null,"bid_sz":0,"ask_sz":0,"bid_ct":0,"ask_ct":0}],"symbol":"TSLA"}
{"ts_recv":"2024-11-01T08:00:03.266462909Z","hd":{"ts_event":"2024-11-01T08:00:03.266296551Z","rtype":10,"publisher_id":2,"instrument_id":38},"action":"A","side":"B","depth":1,"price":"220.000000000","size":2,"flags":130,"ts_in_delta":166358,"sequence":293430,"levels":[{"bid_px":"221.200000000","ask_px":"224.400000000","bid_sz":1000,"ask_sz":1000,"bid_ct":1,"ask_ct":1},{"bid_px":"220.000000000","ask_px":"225.490000000","bid_sz":2,"ask_sz":442,"bid_ct":1,"ask_ct":1},{"bid_px":"219.690000000","ask_px":"234.000000000","bid_sz":442,"ask_sz":20,"bid_ct":1,"ask_ct":1},{"bid_px":"217.000000000","ask_px":null,"bid_sz":1525,"ask_sz":0,"bid_ct":1,"ask_ct":0},{"bid_px":null,"ask_px":null,"bid_sz":0,"ask_sz":0,"bid_ct":0,"ask_ct":0},{"bid_px":null,"ask_px":null,"bid_sz":0,"ask_sz":0,"bid_ct":0,"ask_ct":0},{"bid_px":null,"ask_px":null,"bid_sz":0,"ask_sz":0,"bid_ct":0,"ask_ct":0},{"bid_px":null,"ask_px":null,"bid_sz":0,"ask_sz":0,"bid_ct":0,"ask_ct":0},{"bid_px":null,"ask_px":null,"bid_sz":0,"ask_sz":0,"bid_ct":0,"ask_ct":0},{"bid_px":null,"ask_px":null,"bid_sz":0,"ask_sz":0,"bid_ct":0,"ask_ct":0}],"symbol":"AAPL"}
{"ts_recv":"2024-11-01T08:00:03.281800226Z","hd":{"ts_event":"2024-11-01T08:00:03.281633854Z","rtype":10,"publisher_id":2,"instrument_id":780},"action":"A","side":"N","depth":0,"price":"330.140000000","size":25,"flags":130,"ts_in_delta":166372,"sequence":293454,"levels":[{"bid_px":null,"ask_px":"330.140000000","bid_sz":0,"ask_sz":25,"bid_ct":0,"ask_ct":1},{"bid_px":null,"ask_px":null,"bid_sz":0,"ask_sz":0,"bid_ct":0,"ask_ct":0},{"bid_px":null,"ask_px":null,"bid_sz":0,"ask_sz":0,"bid_ct":0,"ask_ct":0},{"bid_px":null,"ask_px":null,"bid_sz":0,"ask_sz":0,"bid_ct":0,"ask_ct":0},{"bid_px":null,"ask_px":null,"bid_sz":0,"ask_sz":0,"bid_ct":0,"ask_ct":0},{"bid_px":null,"ask_px":null,"bid_sz":0,"ask_sz":0,"bid_ct":0,"ask_ct":0},{"bid_px":null,"ask_px":null,"bid_sz":0,"ask_sz":0,"bid_ct":0,"ask_ct":0},{"bid_px":null,"ask_px":null,"bid_sz":0,"ask_sz":0,"bid_ct":0,"ask_ct":0},{"bid_px":null,"ask_px":null,"bid_sz":0,"ask_sz":0,"bid_ct":0,"ask_ct":0},{"bid_px":null,"ask_px":null,"bid_sz":0,"ask_sz":0,"bid_ct":0,"ask_ct":0}],"symbol":"AMGN"}
{"ts_recv":"2024-11-01T08:00:03.290794949Z","hd":{"ts_event":"2024-11-01T08:00:03.290628629Z","rtype":10,"publisher_id":2,"instrument_id":16244},"action":"C","side":"A","depth":2,"price":"252.200000000","size":1000,"flags":130,"ts_in_delta":166320,"sequence":293466,"levels":[{"bid_px":"249.870000000","ask_px":"250.730000000","bid_sz":50,"ask_sz":100,"bid_ct":1,"ask_ct":1},{"bid_px":"249.600000000","ask_px":"250.960000000","bid_sz":1000,"ask_sz":50,"bid_ct":1,"ask_ct":1},{"bid_px":"249.500000000","ask_px":"253.650000000","bid_sz":1000,"ask_sz":400,"bid_ct":1,"ask_ct":1},{"bid_px":"248.700000000","ask_px":"960.000000000","bid_sz":1000,"ask_sz":25,"bid_ct":1,"ask_ct":1},{"bid_px":"247.150000000","ask_px":null,"bid_sz":400,"ask_sz":0,"bid_ct":1,"ask_ct":0},{"bid_px":"235.000000000","ask_px":null,"bid_sz":100,"ask_sz":0,"bid_ct":1,"ask_ct":0},{"bid_px":"203.000000000","ask_px":null,"bid_sz":2,"ask_sz":0,"bid_ct":1,"ask_ct":0},{"bid_px":"170.000000000","ask_px":null,"bid_sz":3,"ask_sz":0,"bid_ct":1,"ask_ct":0},{"bid_px":null,"ask_px":null,"bid_sz":0,"ask_sz":0,"bid_ct":0,"ask_ct":0},{"bid_px":null,"ask_px":null,"bid_sz":0,"ask_sz":0,"bid_ct":0,"ask_ct":0}],"symbol":"TSLA"}
{"ts_recv":"2024-11-01T08:00:03.301371617Z","hd":{"ts_event":"2024-11-01T08:00:03.301205171Z","rtype":10,"publisher_id":2,"instrument_id":16244},"action":"A","side":"A","depth":2,"price":"252.300000000","size":1000,"flags":130,"ts_in_delta":166446,"sequence":293477,"levels":[{"bid_px":"249.870000000","ask_px":"250.730000000","bid_sz":50,"ask_sz":100,"bid_ct":1,"ask_ct":1},{"bid_px":"249.600000000","ask_px":"250.960000000","bid_sz":1000,"ask_sz":50,"bid_ct":1,"ask_ct":1},{"bid_px":"249.500000000","ask_px":"252.300000000","bid_sz":1000,"ask_sz":1000,"bid_ct":1,"ask_ct":1},{"bid_px":"248.700000000","ask_px":"253.650000000","bid_sz":1000,"ask_sz":400,"bid_ct":1,"ask_ct":1},{"bid_px":"247.150000000","ask_px":"960.000000000","bid_sz":400,"ask_sz":25,"bid_ct":1,"ask_ct":1},{"bid_px":"235.000000000","ask_px":null,"bid_sz":100,"ask_sz":0,"bid_ct":1,"ask_ct":0},{"bid_px":"203.000000000","ask_px":null,"bid_sz":2,"ask_sz":0,"bid_ct":1,"ask_ct":0},{"bid_px":"170.000000000","ask_px":null,"bid_sz":3,"ask_sz":0,"bid_ct":1,"ask_ct":0},{"bid_px":null,"ask_px":null,"bid_sz":0,"ask_sz":0,"bid_ct":0,"ask_ct":0},{"bid_px":null,"ask_px":null,"bid_sz":0,"ask_sz":0,"bid_ct":0,"ask_ct":0}],"symbol":"TSLA"}
{"ts_recv":"2024-11-01T08:00:03.405898932Z","hd":{"ts_event":"2024-11-01T08:00:03.405732567Z","rtype":10,"publisher_id":2,"instrument_id":11667},"action":"A","side":"B","depth":0,"price":"134.810000000","size":61,"flags":130,"ts_in_delta":166365,"sequence":293620,"levels":[{"bid_px":"134.810000000","ask_px":"135.300000000","bid_sz":61,"ask_sz":1000,"bid_ct":1,"ask_ct":1},{"bid_px":"134.770000000","ask_px":"136.100000000","bid_sz":100,"ask_sz":1000,"bid_ct":1,"ask_ct":1},{"bid_px":"134.410000000","ask_px":"137.680000000","bid_sz":1,"ask_sz":500,"bid_ct":1,"ask_ct":1},{"bid_px":"134.210000000","ask_px":"138.870000000","bid_sz":20,"ask_sz":1000,"bid_ct":1,"ask_ct":2},{"bid_px":"133.200000000","ask_px":"140.740000000","bid_sz":1000,"ask_sz":100,"bid_ct":1,"ask_ct":1},{"bid_px":"132.000000000","ask_px":"140.880000000","bid_sz":71,"ask_sz":1000,"bid_ct":2,"ask_ct":2},{"bid_px":"129.050000000","ask_px":"143.690000000","bid_sz":500,"ask_sz":500,"bid_ct":1,"ask_ct":1},{"bid_px":"129.000000000","ask_px":"146.510000000","bid_sz":10,"ask_sz":5,"bid_ct":1,"ask_ct":1},{"bid_px":"128.470000000","ask_px":"148.000000000","bid_sz":500,"ask_sz":5,"bid_ct":1,"ask_ct":1},{"bid_px":"127.680000000","ask_px":null,"bid_sz":30,"ask_sz":0,"bid_ct":1,"ask_ct":0}],"symbol":"NVDA"}
{"ts_recv":"2024-11-01T08:00:03.429244732Z","hd":{"ts_event":"2024-11-01T08:00:03.429078827Z","rtype":10,"publisher_id":2,"instrument_id":11667},"action":"C","side":"B","depth":0,"price":"134.810000000","size":61,"flags":130,"ts_in_delta":165905,"sequence":293686,"levels":[{"bid_px":"134.770000000","ask_px":"135.300000000","bid_sz":100,"ask_sz":1000,"bid_ct":1,"ask_ct":1},{"bid_px":"134.410000000","ask_px":"136.100000000","bid_sz":1,"ask_sz":1000,"bid_ct":1,"ask_ct":1},{"bid_px":"134.210000000","ask_px":"137.680000000","bid_sz":20,"ask_sz":500,"bid_ct":1,"ask_ct":1},{"bid_px":"133.200000000","ask_px":"138.870000000","bid_sz":1000,"ask_sz":1000,"bid_ct":1,"ask_ct":2},{"bid_px":"132.000000000","ask_px":"140.740000000","bid_sz":71,"ask_sz":100,"bid_ct":2,"ask_ct":1},{"bid_px":"129.050000000","ask_px":"140.880000000","bid_sz":500,"ask_sz":1000,"bid_ct":1,"ask_ct":2},{"bid_px":"129.000000000","ask_px":"143.690000000","bid_sz":10,"ask_sz":500,"bid_ct":1,"ask_ct":1},{"bid_px":"128.470000000","ask_px":"146.510000000","bid_sz":500,"ask_sz":5,"bid_ct":1,"ask_ct":1},{"bid_px":"127.680000000","ask_px":"148.000000000","bid_sz":30,"ask_sz":5,"bid_ct":1,"ask_ct":1},{"bid_px":"127.000000000","ask_px":null,"bid_sz":20,"ask_sz":0,"bid_ct":1,"ask_ct":0}],"symbol":"NVDA"}
{"ts_recv":"2024-11-01T08:00:03.604595157Z","hd":{"ts_event":"2024-11-01T08:00:03.604428840Z","rtype":10,"publisher_id":2,"instrument_id":9155},"action":"A","side":"B","depth":1,"price":"217.610000000","size":100,"flags":130,"ts_in_delta":166317,"sequence":293899,"levels":[{"bid_px":"219.160000000","ask_px":"224.940000000","bid_sz":450,"ask_sz":450,"bid_ct":1,"ask_ct":1},{"bid_px":"217.610000000","ask_px":null,"bid_sz":100,"ask_sz":0,"bid_ct":1,"ask_ct":0},{"bid_px":null,"ask_px":null,"bid_sz":0,"ask_sz":0,"bid_ct":0,"ask_ct":0},{"bid_px":null,"ask_px":null,"bid_sz":0,"ask_sz":0,"bid_ct":0,"ask_ct":0},{"bid_px":null,"ask_px":null,"bid_sz":0,"ask_sz":0,"bid_ct":0,"ask_ct":0},{"bid_px":null,"ask_px":null,"bid_sz":0,"ask_sz":0,"bid_ct":0,"ask_ct":0},{"bid_px":null,"ask_px":null,"bid_sz":0,"ask_sz":0,"bid_ct":0,"ask_ct":0},{"bid_px":null,"ask_px":null,"bid_sz":0,"ask_sz":0,"bid_ct":0,"ask_ct":0},{"bid_px":null,"ask_px":null,"bid_sz":0,"ask_sz":0,"bid_ct":0,"ask_ct":0},{"bid_px":null,"ask_px":null,"bid_sz":0,"ask_sz":0,"bid_ct":0,"ask_ct":0}],"symbol":"JPM"}
{"ts_recv":"2024-11-01T08:00:03.604610327Z","hd":{"ts_event":"2024-11-01T08:00:03.604443910Z","rtype":10,"publisher_id":2,"instrument_id":9155},"action":"A","side":"A","depth":1,"price":"226.800000000","size":100,"flags":130,"ts_in_delta":166417,"sequence":293900,"levels":[{"bid_px":"219.160000000","ask_px":"224.940000000","bid_sz":450,"ask_sz":450,"bid_ct":1,"ask_ct":1},{"bid_px":"217.610000000","ask_px":"226.800000000","bid_sz":100,"ask_sz":100,"bid_ct":1,"ask_ct":1},{"bid_px":null,"ask_px":null,"bid_sz":0,"ask_sz":0,"bid_ct":0,"ask_ct":0},{"bid_px":null,"ask_px":null,"bid_sz":0,"ask_sz":0,"bid_ct":0,"ask_ct":0},{"bid_px":null,"ask_px":null,"bid_sz":0,"ask_sz":0,"bid_ct":0,"ask_ct":0},{"bid_px":null,"ask_px":null,"bid_sz":0,"ask_sz":0,"bid_ct":0,"ask_ct":0},{"bid_px":null,"ask_px":null,"bid_sz":0,"ask_sz":0,"bid_ct":0,"ask_ct":0},{"bid_px":null,"ask_px":null,"bid_sz":0,"ask_sz":0,"bid_ct":0,"ask_ct":0},{"bid_px":null,"ask_px":null,"bid_sz":0,"ask_sz":0,"bid_ct":0,"ask_ct":0},{"bid_px":null,"ask_px":null,"bid_sz":0,"ask_sz":0,"bid_ct":0,"ask_ct":0}],"symbol":"JPM"}
{"ts_recv":"2024-11-01T08:00:03.733783141Z","hd":{"ts_event":"2024-11-01T08:00:03.733616642Z","rtype":10,"publisher_id":2,"instrument_id":17709},"action":"A","side":"A","depth":2,"price":"125.000000000","size":30,"flags":130,"ts_in_delta":166499,"sequence":294251,"levels":[{"bid_px":"116.000000000","ask_px":"118.320000000","bid_sz":100,"ask_sz":856,"bid_ct":1,"ask_ct":1},{"bid_px":"115.320000000","ask_px":"118.600000000","bid_sz":100,"ask_sz":100,"bid_ct":1,"ask_ct":1},{"bid_px":"115.280000000","ask_px":"125.000000000","bid_sz":856,"ask_sz":30,"bid_ct":1,"ask_ct":1},{"bid_px":null,"ask_px":null,"bid_sz":0,"ask_sz":0,"bid_ct":0,"ask_ct":0},{"bid_px":null,"ask_px":null,"bid_sz":0,"ask_sz":0,"bid_ct":0,"ask_ct":0},{"bid_px":null,"ask_px":null,"bid_sz":0,"ask_sz":0,"bid_ct":0,"ask_ct":0},{"bid_px":null,"ask_px":null,"bid_sz":0,"ask_sz":0,"bid_ct":0,"ask_ct":0},{"bid_px":null,"ask_px":null,"bid_sz":0,"ask_sz":0,"bid_ct":0,"ask_ct":0},{"bid_px":null,"ask_px":null,"bid_sz":0,"ask_sz":0,"bid_ct":0,"ask_ct":0},{"bid_px":null,"ask_px":null,"bid_sz":0,"ask_sz":0,"bid_ct":0,"ask_ct":0}],"symbol":"XOM"}
{"ts_recv":"2024-11-01T08:00:03.859483445Z","hd":{"ts_event":"2024-11-01T08:00:03.859317306Z","rtype":10,"publisher_id":2,"instrument_id":11667},"action":"C","side":"B","depth":3,"price":"133.200000000","size":1000,"flags":130,"ts_in_delta":166139,"sequence":294581,"levels":[{"bid_px":"134.770000000","ask_px":"135.300000000","bid_sz":100,"ask_sz":1000,"bid_ct":1,"ask_ct":1},{"bid_px":"134.410000000","ask_px":"136.100000000","bid_sz":1,"ask_sz":1000,"bid_ct":1,"ask_ct":1},{"bid_px":"134.210000000","ask_px":"137.680000000","bid_sz":20,"ask_sz":500,"bid_ct":1,"ask_ct":1},{"bid_px":"132.000000000","ask_px":"138.870000000","bid_sz":71,"ask_sz":1000,"bid_ct":2,"ask_ct":2},{"bid_px":"129.050000000","ask_px":"140.740000000","bid_sz":500,"ask_sz":100,"bid_ct":1,"ask_ct":1},{"bid_px":"129.000000000","ask_px":"140.880000000","bid_sz":10,"ask_sz":1000,"bid_ct":1,"ask_ct":2},{"bid_px":"128.470000000","ask_px":"143.690000000","bid_sz":500,"ask_sz":500,"bid_ct":1,"ask_ct":1},{"bid_px":"127.680000000","ask_px":"146.510000000","bid_sz":30,"ask_sz":5,"bid_ct":1,"ask_ct":1},{"bid_px":"127.000000000","ask_px":"148.000000000","bid_sz":20,"ask_sz":5,"bid_ct":1,"ask_ct":1},{"bid_px":"91.000000000","ask_px":null,"bid_sz":50,"ask_sz":0,"bid_ct":1,"ask_ct":0}],"symbol":"NVDA"}
{"ts_recv":"2024-11-01T08:00:03.864687567Z","hd":{"ts_event":"2024-11-01T08:00:03.864521543Z","rtype":10,"publisher_id":2,"instrument_id":16244},"action":"A","side":"B","depth":6,"price":"214.000000000","size":5,"flags":130,"ts_in_delta":166024,"sequence":294590,"levels":[{"bid_px":"249.870000000","ask_px":"250.730000000","bid_sz":50,"ask_sz":100,"bid_ct":1,"ask_ct":1},{"bid_px":"249.600000000","ask_px":"250.960000000","bid_sz":1000,"ask_sz":50,"bid_ct":1,"ask_ct":1},{"bid_px":"249.500000000","ask_px":"252.300000000","bid_sz":1000,"ask_sz":1000,"bid_ct":1,"ask_ct":1},{"bid_px":"248.700000000","ask_px":"253.650000000","bid_sz":1000,"ask_sz":400,"bid_ct":1,"ask_ct":1},{"bid_px":"247.150000000","ask_px":"960.000000000","bid_sz":400,"ask_sz":25,"bid_ct":1,"ask_ct":1},{"bid_px":"235.000000000","ask_px":null,"bid_sz":100,"ask_sz":0,"bid_ct":1,"ask_ct":0},{"bid_px":"214.000000000","ask_px":null,"bid_sz":5,"ask_sz":0,"bid_ct":1,"ask_ct":0},{"bid_px":"203.000000000","ask_px":null,"bid_sz":2,"ask_sz":0,"bid_ct":1,"ask_ct":0},{"bid_px":"170.000000000","ask_px":null,"bid_sz":3,"ask_sz":0,"bid_ct":1,"ask_ct":0},{"bid_px":null,"ask_px":null,"bid_sz":0,"ask_sz":0,"bid_ct":0,"ask_ct":0}],"symbol":"TSLA"}
{"ts_recv":"2024-11-01T08:00:03.870457550Z","hd":{"ts_event":"2024-11-01T08:00:03.870291285Z","rtype":10,"publisher_id":2,"instrument_id":11667},"action":"A","side":"B","depth":3,"price":"133.100000000","size":1000,"flags":130,"ts_in_delta":166265,"sequence":294607,"levels":[{"bid_px":"134.770000000","ask_px":"135.300000000","bid_sz":100,"ask_sz":1000,"bid_ct":1,"ask_ct":1},{"bid_px":"134.410000000","ask_px":"136.100000000","bid_sz":1,"ask_sz":1000,"bid_ct":1,"ask_ct":1},{"bid_px":"134.210000000","ask_px":"137.680000000","bid_sz":20,"ask_sz":500,"bid_ct":1,"ask_ct":1},{"bid_px":"133.100000000","ask_px":"138.870000000","bid_sz":1000,"ask_sz":1000,"bid_ct":1,"ask_ct":2},{"bid_px":"132.000000000","ask_px":"140.740000000","bid_sz":71,"ask_sz":100,"bid_ct":2,"ask_ct":1},{"bid_px":"129.050000000","ask_px":"140.880000000","bid_sz":500,"ask_sz":1000,"bid_ct":1,"ask_ct":2},{"bid_px":"129.000000000","ask_px":"143.690000000","bid_sz":10,"ask_sz":500,"bid_ct":1,"ask_ct":1},{"bid_px":"128.470000000","ask_px":"146.510000000","bid_sz":500,"ask_sz":5,"bid_ct":1,"ask_ct":1},{"bid_px":"127.680000000","ask_px":"148.000000000","bid_sz":30,"ask_sz":5,"bid_ct":1,"ask_ct":1},{"bid_px":"127.000000000","ask_px":null,"bid_sz":20,"ask_sz":0,"bid_ct":1,"ask_ct":0}],"symbol":"NVDA"}
{"ts_recv":"2024-11-01T08:00:03.904687498Z","hd":{"ts_event":"2024-11-01T08:00:03.904521638Z","rtype":10,"publisher_id":2,"instrument_id":10888},"action":"A","side":"B","depth":1,"price":"398.000000000","size":5,"flags":130,"ts_in_delta":165860,"sequence":294699,"levels":[{"bid_px":"404.410000000","ask_px":"415.070000000","bid_sz":246,"ask_sz":246,"bid_ct":1,"ask_ct":1},{"bid_px":"398.000000000","ask_px":"420.000000000","bid_sz":5,"ask_sz":3,"bid_ct":1,"ask_ct":1},{"bid_px":null,"ask_px":"468.000000000","bid_sz":0,"ask_sz":65,"bid_ct":0,"ask_ct":1},{"bid_px":null,"ask_px":null,"bid_sz":0,"ask_sz":0,"bid_ct":0,"ask_ct":0},{"bid_px":null,"ask_px":null,"bid_sz":0,"ask_sz":0,"bid_ct":0,"ask_ct":0},{"bid_px":null,"ask_px":null,"bid_sz":0,"ask_sz":0,"bid_ct":0,"ask_ct":0},{"bid_px":null,"ask_px":null,"bid_sz":0,"ask_sz":0,"bid_ct":0,"ask_ct":0},{"bid_px":null,"ask_px":null,"bid_sz":0,"ask_sz":0,"bid_ct":0,"ask_ct":0},{"bid_px":null,"ask_px":null,"bid_sz":0,"ask_sz":0,"bid_ct":0,"ask_ct":0},{"bid_px":null,"ask_px":null,"bid_sz":0,"ask_sz":0,"bid_ct":0,"ask_ct":0}],"symbol":"MSFT"}
{"ts_recv":"2024-11-01T08:00:03.979793361Z","hd":{"ts_event":"2024-11-01T08:00:03.979627113Z","rtype":10,"publisher_id":2,"instrument_id":11667},"action":"A","side":"B","depth":9,"price":"127.500000000","size":5,"flags":130,"ts_in_delta":166248,"sequence":294879,"levels":[{"bid_px":"134.770000000","ask_px":"135.300000000","bid_sz":100,"ask_sz":1000,"bid_ct":1,"ask_ct":1},{"bid_px":"134.410000000","ask_px":"136.100000000","bid_sz":1,"ask_sz":1000,"bid_ct":1,"ask_ct":1},{"bid_px":"134.210000000","ask_px":"137.680000000","bid_sz":20,"ask_sz":500,"bid_ct":1,"ask_ct":1},{"bid_px":"133.100000000","ask_px":"138.870000000","bid_sz":1000,"ask_sz":1000,"bid_ct":1,"ask_ct":2},{"bid_px":"132.000000000","ask_px":"140.740000000","bid_sz":71,"ask_sz":100,"bid_ct":2,"ask_ct":1},{"bid_px":"129.050000000","ask_px":"140.880000000","bid_sz":500,"ask_sz":1000,"bid_ct":1,"ask_ct":2},{"bid_px":"129.000000000","ask_px":"143.690000000","bid_sz":10,"ask_sz":500,"bid_ct":1,"ask_ct":1},{"bid_px":"128.470000000","ask_px":"146.510000000","bid_sz":500,"ask_sz":5,"bid_ct":1,"ask_ct":1},{"bid_px":"127.680000000","ask_px":"148.000000000","bid_sz":30,"ask_sz":5,"bid_ct":1,"ask_ct":1},{"bid_px":"127.500000000","ask_px":null,"bid_sz":5,"ask_sz":0,"bid_ct":1,"ask_ct":0}],"symbol":"NVDA"}
{"ts_recv":"2024-11-01T08:00:03.990343678Z","hd":{"ts_event":"2024-11-01T08:00:03.990176949Z","rtype":10,"publisher_id":2,"instrument_id":16244},"action":"A","side":"A","depth":4,"price":"275.000000000","size":4,"flags":130,"ts_in_delta":166729,"sequence":294920,"levels":[{"bid_px":"249.870000000","ask_px":"250.730000000","bid_sz":50,"ask_sz":100,"bid_ct":1,"ask_ct":1},{"bid_px":"249.600000000","ask_px":"250.960000000","bid_sz":1000,"ask_sz":50,"bid_ct":1,"ask_ct":1},{"bid_px":"249.500000000","ask_px":"252.300000000","bid_sz":1000,"ask_sz":1000,"bid_ct":1,"ask_ct":1},{"bid_px":"248.700000000","ask_px":"253.650000000","bid_sz":1000,"ask_sz":400,"bid_ct":1,"ask_ct":1},{"bid_px":"247.150000000","ask_px":"275.000000000","bid_sz":400,"ask_sz":4,"bid_ct":1,"ask_ct":1},{"bid_px":"235.000000000","ask_px":"960.000000000","bid_sz":100,"ask_sz":25,"bid_ct":1,"ask_ct":1},{"bid_px":"214.000000000","ask_px":null,"bid_sz":5,"ask_sz":0,"bid_ct":1,"ask_ct":0},{"bid_px":"203.000000000","ask_px":null,"bid_sz":2,"ask_sz":0,"bid_ct":1,"ask_ct":0},{"bid_px":"170.000000000","ask_px":null,"bid_sz":3,"ask_sz":0,"bid_ct":1,"ask_ct":0},{"bid_px":null,"ask_px":null,"bid_sz":0,"ask_sz":0,"bid_ct":0,"ask_ct":0}],"symbol":"TSLA"}
{"ts_recv":"2024-11-01T08:00:04.001618747Z","hd":{"ts_event":"2024-11-01T08:00:04.001452430Z","rtype":10,"publisher_id":2,"instrument_id":6905},"action":"A","side":"N","depth":0,"price":"91.880000000","size":100,"flags":130,"ts_in_delta":166317,"sequence":294945,"levels":[{"bid_px":null,"ask_px":"91.880000000","bid_sz":0,"ask_sz":100,"bid_ct":0,"ask_ct":1},{"bid_px":null,"ask_px":null,"bid_sz":0,"ask_sz":0,"bid_ct":0,"ask_ct":0},{"bid_px":null,"ask_px":null,"bid_sz":0,"ask_sz":0,"bid_ct":0,"ask_ct":0},{"bid_px":null,"ask_px":null,"bid_sz":0,"ask_sz":0,"bid_ct":0,"ask_ct":0},{"bid_px":null,"ask_px":null,"bid_sz":0,"ask_sz":0,"bid_ct":0,"ask_ct":0},{"bid_px":null,"ask_px":null,"bid_sz":0,"ask_sz":0,"bid_ct":0,"ask_ct":0},{"bid_px":null,"ask_px":null,"bid_sz":0,"ask_sz":0,"bid_ct":0,"ask_ct":0},{"bid_px":null,"ask_px":null,"bid_sz":0,"ask_sz":0,"bid_ct":0,"ask_ct":0},{"bid_px":null,"ask_px":null,"bid_sz":0,"ask_sz":0,"bid_ct":0,"ask_ct":0},{"bid_px":null,"ask_px":null,"bid_sz":0,"ask_sz":0,"bid_ct":0,"ask_ct":0}],"symbol":"GILD"}
{"ts_recv":"2024-11-01T08:00:04.119754546Z","hd":{"ts_event":"2024-11-01T08:00:04.119588707Z","rtype":10,"publisher_id":2,"instrument_id":16244},"action":"A","side":"A","depth":0,"price":"250.730000000","size":100,"flags":130,"ts_in_delta":165839,"sequence":295080,"levels":[{"bid_px":"249.870000000","ask_px":"250.730000000","bid_sz":50,"ask_sz":200,"bid_ct":1,"ask_ct":2},{"bid_px":"249.600000000","ask_px":"250.960000000","bid_sz":1000,"ask_sz":50,"bid_ct":1,"ask_ct":1},{"bid_px":"249.500000000","ask_px":"252.300000000","bid_sz":1000,"ask_sz":1000,"bid_ct":1,"ask_ct":1},{"bid_px":"248.700000000","ask_px":"253.650000000","bid_sz":1000,"ask_sz":400,"bid_ct":1,"ask_ct":1},{"bid_px":"247.150000000","ask_px":"275.000000000","bid_sz":400,"ask_sz":4,"bid_ct":1,"ask_ct":1},{"bid_px":"235.000000000","ask_px":"960.000000000","bid_sz":100,"ask_sz":25,"bid_ct":1,"ask_ct":1},{"bid_px":"214.000000000","ask_px":null,"bid_sz":5,"ask_sz":0,"bid_ct":1,"ask_ct":0},{"bid_px":"203.000000000","ask_px":null,"bid_sz":2,"ask_sz":0,"bid_ct":1,"ask_ct":0},{"bid_px":"170.000000000","ask_px":null,"bid_sz":3,"ask_sz":0,"bid_ct":1,"ask_ct":0},{"bid_px":null,"ask_px":null,"bid_sz":0,"ask_sz":0,"bid_ct":0,"ask_ct":0}],"symbol":"TSLA"}
{"ts_recv":"2024-11-01T08:00:04.119835321Z","hd":{"ts_event":"2024-11-01T08:00:04.119669642Z","rtype":10,"publisher_id":2,"instrument_id":16244},"action":"C","side":"B","depth":0,"price":"249.870000000","size":50,"flags":130,"ts_in_delta":165679,"sequence":295081,"levels":[{"bid_px":"249.600000000","ask_px":"250.730000000","bid_sz":1000,"ask_sz":200,"bid_ct":1,"ask_ct":2},{"bid_px":"249.500000000","ask_px":"250.960000000","bid_sz":1000,"ask_sz":50,"bid_ct":1,"ask_ct":1},{"bid_px":"248.700000000","ask_px":"252.300000000","bid_sz":1000,"ask_sz":1000,"bid_ct":1,"ask_ct":1},{"bid_px":"247.150000000","ask_px":"253.650000000","bid_sz":400,"ask_sz":400,"bid_ct":1,"ask_ct":1},{"bid_px":"235.000000000","ask_px":"275.000000000","bid_sz":100,"ask_sz":4,"bid_ct":1,"ask_ct":1},{"bid_px":"214.000000000","ask_px":"960.000000000","bid_sz":5,"ask_sz":25,"bid_ct":1,"ask_ct":1},{"bid_px":"203.000000000","ask_px":null,"bid_sz":2,"ask_sz":0,"bid_ct":1,"ask_ct":0},{"bid_px":"170.000000000","ask_px":null,"bid_sz":3,"ask_sz":0,"bid_ct":1,"ask_ct":0},{"bid_px":null,"ask_px":null,"bid_sz":0,"ask_sz":0,"bid_ct":0,"ask_ct":0},{"bid_px":null,"ask_px":null,"bid_sz":0,"ask_sz":0,"bid_ct":0,"ask_ct":0}],"symbol":"TSLA"}
{"ts_recv":"2024-11-01T08:00:04.119911891Z","hd":{"ts_event":"2024-11-01T08:00:04.119746189Z","rtype":10,"publisher_id":2,"instrument_id":16244},"action":"C","side":"B","depth":2,"price":"248.700000000","size":1000,"flags":130,"ts_in_delta":165702,"sequence":295082,"levels":[{"bid_px":"249.600000000","ask_px":"250.730000000","bid_sz":1000,"ask_sz":200,"bid_ct":1,"ask_ct":2},{"bid_px":"249.500000000","ask_px":"250.960000000","bid_sz":1000,"ask_sz":50,"bid_ct":1,"ask_ct":1},{"bid_px":"247.150000000","ask_px":"252.300000000","bid_sz":400,"ask_sz":1000,"bid_ct":1,"ask_ct":1},{"bid_px":"235.000000000","ask_px":"253.650000000","bid_sz":100,"ask_sz":400,"bid_ct":1,"ask_ct":1},{"bid_px":"214.000000000","ask_px":"275.000000000","bid_sz":5,"ask_sz":4,"bid_ct":1,"ask_ct":1},{"bid_px":"203.000000000","ask_px":"960.000000000","bid_sz":2,"ask_sz":25,"bid_ct":1,"ask_ct":1},{"bid_px":"170.000000000","ask_px":null,"bid_sz":3,"ask_sz":0,"bid_ct":1,"ask_ct":0},{"bid_px":null,"ask_px":null,"bid_sz":0,"ask_sz":0,"bid_ct":0,"ask_ct":0},{"bid_px":null,"ask_px":null,"bid_sz":0,"ask_sz":0,"bid_ct":0,"ask_ct":0},{"bid_px":null,"ask_px":null,"bid_sz":0,"ask_sz":0,"bid_ct":0,"ask_ct":0}],"symbol":"TSLA"}
{"ts_recv":"2024-11-01T08:00:04.120156195Z","hd":{"ts_event":"2024-11-01T08:00:04.119989815Z","rtype":10,"publisher_id":2,"instrument_id":16244},"action":"C","side":"B","depth":1,"price":"249.500000000","size":1000,"flags":130,"ts_in_delta":166380,"sequence":295083,"levels":[{"bid_px":"249.600000000","ask_px":"250.730000000","bid_sz":1000,"ask_sz":200,"bid_ct":1,"ask_ct":2},{"bid_px":"247.150000000","ask_px":"250.960000000","bid_sz":400,"ask_sz":50,"bid_ct":1,"ask_ct":1},{"bid_px":"235.000000000","ask_px":"252.300000000","bid_sz":100,"ask_sz":1000,"bid_ct":1,"ask_ct":1},{"bid_px":"214.000000000","ask_px":"253.650000000","bid_sz":5,"ask_sz":400,"bid_ct":1,"ask_ct":1},{"bid_px":"203.000000000","ask_px":"275.000000000","bid_sz":2,"ask_sz":4,"bid_ct":1,"ask_ct":1},{"bid_px":"170.000000000","ask_px":"960.000000000","bid_sz":3,"ask_sz":25,"bid_ct":1,"ask_ct":1},{"bid_px":null,"ask_px":null,"bid_sz":0,"ask_sz":0,"bid_ct":0,"ask_ct":0},{"bid_px":null,"ask_px":null,"bid_sz":0,"ask_sz":0,"bid_ct":0,"ask_ct":0},{"bid_px":null,"ask_px":null,"bid_sz":0,"ask_sz":0,"bid_ct":0,"ask_ct":0},{"bid_px":null,"ask_px":null,"bid_sz":0,"ask_sz":0,"bid_ct":0,"ask_ct":0}],"symbol":"TSLA"}
{"ts_recv":"2024-11-01T08:00:04.134985360Z","hd":{"ts_event":"2024-11-01T08:00:04.134815895Z","rtype":10,"publisher_id":2,"instrument_id":16244},"action":"A","side":"A","depth":2,"price":"251.300000000","size":1000,"flags":130,"ts_in_delta":169465,"sequence":295095,"levels":[{"bid_px":"249.600000000","ask_px":"250.730000000","bid_sz":1000,"ask_sz":200,"bid_ct":1,"ask_ct":2},{"bid_px":"247.150000000","ask_px":"250.960000000","bid_sz":400,"ask_sz":50,"bid_ct":1,"ask_ct":1},{"bid_px":"235.000000000","ask_px":"251.300000000","bid_sz":100,"ask_sz":1000,"bid_ct":1,"ask_ct":1},{"bid_px":"214.000000000","ask_px":"252.300000000","bid_sz":5,"ask_sz":1000,"bid_ct":1,"ask_ct":1},{"bid_px":"203.000000000","ask_px":"253.650000000","bid_sz":2,"ask_sz":400,"bid_ct":1,"ask_ct":1},{"bid_px":"170.000000000","ask_px":"275.000000000","bid_sz":3,"ask_sz":4,"bid_ct":1,"ask_ct":1},{"bid_px":null,"ask_px":"960.000000000","bid_sz":0,"ask_sz":25,"bid_ct":0,"ask_ct":1},{"bid_px":null,"ask_px":null,"bid_sz":0,"ask_sz":0,"bid_ct":0,"ask_ct":0},{"bid_px":null,"ask_px":null,"bid_sz":0,"ask_sz":0,"bid_ct":0,"ask_ct":0},{"bid_px":null,"ask_px":null,"bid_sz":0,"ask_sz":0,"bid_ct":0,"ask_ct":0}],"symbol":"TSLA"}
{"ts_recv":"2024-11-01T08:00:04.135044430Z","hd":{"ts_event":"2024-11-01T08:00:04.134878033Z","rtype":10,"publisher_id":2,"instrument_id":16244},"action":"C","side":"A","depth":3,"price":"252.300000000","size":1000,"flags":130,"ts_in_delta":166397,"sequence":295096,"levels":[{"bid_px":"249.600000000","ask_px":"250.730000000","bid_sz":1000,"ask_sz":200,"bid_ct":1,"ask_ct":2},{"bid_px":"247.150000000","ask_px":"250.960000000","bid_sz":400,"ask_sz":50,"bid_ct":1,"ask_ct":1},{"bid_px":"235.000000000","ask_px":"251.300000000","bid_sz":100,"ask_sz":1000,"bid_ct":1,"ask_ct":1},{"bid_px":"214.000000000","ask_px":"253.650000000","bid_sz":5,"ask_sz":400,"bid_ct":1,"ask_ct":1},{"bid_px":"203.000000000","ask_px":"275.000000000","bid_sz":2,"ask_sz":4,"bid_ct":1,"ask_ct":1},{"bid_px":"170.000000000","ask_px":"960.000000000","bid_sz":3,"ask_sz":25,"bid_ct":1,"ask_ct":1},{"bid_px":null,"ask_px":null,"bid_sz":0,"ask_sz":0,"bid_ct":0,"ask_ct":0},{"bid_px":null,"ask_px":null,"bid_sz":0,"ask_sz":0,"bid_ct":0,"ask_ct":0},{"bid_px":null,"ask_px":null,"bid_sz":0,"ask_sz":0,"bid_ct":0,"ask_ct":0},{"bid_px":null,"ask_px":null,"bid_sz":0,"ask_sz":0,"bid_ct":0,"ask_ct":0}],"symbol":"TSLA"}
{"ts_recv":"2024-11-01T08:00:04.153954286Z","hd":{"ts_event":"2024-11-01T08:00:04.153788131Z","rtype":10,"publisher_id":2,"instrument_id":16244},"action":"C","side":"A","depth":2,"price":"251.300000000","size":1000,"flags":130,"ts_in_delta":166155,"sequence":295110,"levels":[{"bid_px":"249.600000000","ask_px":"250.730000000","bid_sz":1000,"ask_sz":200,"bid_ct":1,"ask_ct":2},{"bid_px":"247.150000000","ask_px":"250.960000000","bid_sz":400,"ask_sz":50,"bid_ct":1,"ask_ct":1},{"bid_px":"235.000000000","ask_px":"253.650000000","bid_sz":100,"ask_sz":400,"bid_ct":1,"ask_ct":1},{"bid_px":"214.000000000","ask_px":"275.000000000","bid_sz":5,"ask_sz":4,"bid_ct":1,"ask_ct":1},{"bid_px":"203.000000000","ask_px":"960.000000000","bid_sz":2,"ask_sz":25,"bid_ct":1,"ask_ct":1},{"bid_px":"170.000000000","ask_px":null,"bid_sz":3,"ask_sz":0,"bid_ct":1,"ask_ct":0},{"bid_px":null,"ask_px":null,"bid_sz":0,"ask_sz":0,"bid_ct":0,"ask_ct":0},{"bid_px":null,"ask_px":null,"bid_sz":0,"ask_sz":0,"bid_ct":0,"ask_ct":0},{"bid_px":null,"ask_px":null,"bid_sz":0,"ask_sz":0,"bid_ct":0,"ask_ct":0},{"bid_px":null,"ask_px":null,"bid_sz":0,"ask_sz":0,"bid_ct":0,"ask_ct":0}],"symbol":"TSLA"}
{"ts_recv":"2024-11-01T08:00:04.162073569Z","hd":{"ts_event":"2024-11-01T08:00:04.161907144Z","rtype":10,"publisher_id":2,"instrument_id":16244},"action":"A","side":"B","depth":1,"price":"249.300000000","size":1000,"flags":130,"ts_in_delta":166425,"sequence":295120,"levels":[{"bid_px":"249.600000000","ask_px":"250.730000000","bid_sz":1000,"ask_sz":200,"bid_ct":1,"ask_ct":2},{"bid_px":"249.300000000","ask_px":"250.960000000","bid_sz":1000,"ask_sz":50,"bid_ct":1,"ask_ct":1},{"bid_px":"247.150000000","ask_px":"253.650000000","bid_sz":400,"ask_sz":400,"bid_ct":1,"ask_ct":1},{"bid_px":"235.000000000","ask_px":"275.000000000","bid_sz":100,"ask_sz":4,"bid_ct":1,"ask_ct":1},{"bid_px":"214.000000000","ask_px":"960.000000000","bid_sz":5,"ask_sz":25,"bid_ct":1,"ask_ct":1},{"bid_px":"203.000000000","ask_px":null,"bid_sz":2,"ask_sz":0,"bid_ct":1,"ask_ct":0},{"bid_px":"170.000000000","ask_px":null,"bid_sz":3,"ask_sz":0,"bid_ct":1,"ask_ct":0},{"bid_px":null,"ask_px":null,"bid_sz":0,"ask_sz":0,"bid_ct":0,"ask_ct":0},{"bid_px":null,"ask_px":null,"bid_sz":0,"ask_sz":0,"bid_ct":0,"ask_ct":0},{"bid_px":null,"ask_px":null,"bid_sz":0,"ask_sz":0,"bid_ct":0,"ask_ct":0}],"symbol":"TSLA"}
{"ts_recv":"2024-11-01T08:00:04.164271209Z","hd":{"ts_event":"2024-11-01T08:00:04.164104182Z","rtype":10,"publisher_id":2,"instrument_id":16244},"action":"A","side":"A","depth":2,"price":"251.700000000","size":1000,"flags":130,"ts_in_delta":167027,"sequence":295121,"levels":[{"bid_px":"249.600000000","ask_px":"250.730000000","bid_sz":1000,"ask_sz":200,"bid_ct":1,"ask_ct":2},{"bid_px":"249.300000000","ask_px":"250.960000000","bid_sz":1000,"ask_sz":50,"bid_ct":1,"ask_ct":1},{"bid_px":"247.150000000","ask_px":"251.700000000","bid_sz":400,"ask_sz":1000,"bid_ct":1,"ask_ct":1},{"bid_px":"235.000000000","ask_px":"253.650000000","bid_sz":100,"ask_sz":400,"bid_ct":1,"ask_ct":1},{"bid_px":"214.000000000","ask_px":"275.000000000","bid_sz":5,"ask_sz":4,"bid_ct":1,"ask_ct":1},{"bid_px":"203.000000000","ask_px":"960.000000000","bid_sz":2,"ask_sz":25,"bid_ct":1,"ask_ct":1},{"bid_px":"170.000000000","ask_px":null,"bid_sz":3,"ask_sz":0,"bid_ct":1,"ask_ct":0},{"bid_px":null,"ask_px":null,"bid_sz":0,"ask_sz":0,"bid_ct":0,"ask_ct":0},{"bid_px":null,"ask_px":null,"bid_sz":0,"ask_sz":0,"bid_ct":0,"ask_ct":0},{"bid_px":null,"ask_px":null,"bid_sz":0,"ask_sz":0,"bid_ct":0,"ask_ct":0}],"symbol":"TSLA"}
{"ts_recv":"2024-11-01T08:00:04.172136969Z","hd":{"ts_event":"2024-11-01T08:00:04.171971303Z","rtype":10,"publisher_id":2,"instrument_id":16244},"action":"C","side":"A","depth":2,"price":"251.700000000","size":1000,"flags":130,"ts_in_delta":165666,"sequence":295134,"levels":[{"bid_px":"249.600000000","ask_px":"250.730000000","bid_sz":1000,"ask_sz":200,"bid_ct":1,"ask_ct":2},{"bid_px":"249.300000000","ask_px":"250.960000000","bid_sz":1000,"ask_sz":50,"bid_ct":1,"ask_ct":1},{"bid_px":"247.150000000","ask_px":"253.650000000","bid_sz":400,"ask_sz":400,"bid_ct":1,"ask_ct":1},{"bid_px":"235.000000000","ask_px":"275.000000000","bid_sz":100,"ask_sz":4,"bid_ct":1,"ask_ct":1},{"bid_px":"214.000000000","ask_px":"960.000000000","bid_sz":5,"ask_sz":25,"bid_ct":1,"ask_ct":1},{"bid_px":"203.000000000","ask_px":null,"bid_sz":2,"ask_sz":0,"bid_ct":1,"ask_ct":0},{"bid_px":"170.000000000","ask_px":null,"bid_sz":3,"ask_sz":0,"bid_ct":1,"ask_ct":0},{"bid_px":null,"ask_px":null,"bid_sz":0,"ask_sz":0,"bid_ct":0,"ask_ct":0},{"bid_px":null,"ask_px":null,"bid_sz":0,"ask_sz":0,"bid_ct":0,"ask_ct":0},{"bid_px":null,"ask_px":null,"bid_sz":0,"ask_sz":0,"bid_ct":0,"ask_ct":0}],"symbol":"TSLA"}
{"ts_recv":"2024-11-01T08:00:04.185656271Z","hd":{"ts_event":"2024-11-01T08:00:04.185489815Z","rtype":10,"publisher_id":2,"instrument_id":16244},"action":"A","side":"A","depth":2,"price":"251.300000000","size":1000,"flags":130,"ts_in_delta":166456,"sequence":295160,"levels":[{"bid_px":"249.600000000","ask_px":"250.730000000","bid_sz":1000,"ask_sz":200,"bid_ct":1,"ask_ct":2},{"bid_px":"249.300000000","ask_px":"250.960000000","bid_sz":1000,"ask_sz":50,"bid_ct":1,"ask_ct":1},{"bid_px":"247.150000000","ask_px":"251.300000000","bid_sz":400,"ask_sz":1000,"bid_ct":1,"ask_ct":1},{"bid_px":"235.000000000","ask_px":"253.650000000","bid_sz":100,"ask_sz":400,"bid_ct":1,"ask_ct":1},{"bid_px":"214.000000000","ask_px":"275.000000000","bid_sz":5,"ask_sz":4,"bid_ct":1,"ask_ct":1},{"bid_px":"203.000000000","ask_px":"960.000000000","bid_sz":2,"ask_sz":25,"bid_ct":1,"ask_ct":1},{"bid_px":"170.000000000","ask_px":null,"bid_sz":3,"ask_sz":0,"bid_ct":1,"ask_ct":0},{"bid_px":null,"ask_px":null,"bid_sz":0,"ask_sz":0,"bid_ct":0,"ask_ct":0},{"bid_px":null,"ask_px":null,"bid_sz":0,"ask_sz":0,"bid_ct":0,"ask_ct":0},{"bid_px":null,"ask_px":null,"bid_sz":0,"ask_sz":0,"bid_ct":0,"ask_ct":0}],"symbol":"TSLA"}
{"ts_recv":"2024-11-01T08:00:04.185708515Z","hd":{"ts_event":"2024-11-01T08:00:04.185542577Z","rtype":10,"publisher_id":2,"instrument_id":16244},"action":"C","side":"A","depth":0,"price":"250.730000000","size":100,"flags":130,"ts_in_delta":165938,"sequence":295161,"levels":[{"bid_px":"249.600000000","ask_px":"250.730000000","bid_sz":1000,"ask_sz":100,"bid_ct":1,"ask_ct":1},{"bid_px":"249.300000000","ask_px":"250.960000000","bid_sz":1000,"ask_sz":50,"bid_ct":1,"ask_ct":1},{"bid_px":"247.150000000","ask_px":"251.300000000","bid_sz":400,"ask_sz":1000,"bid_ct":1,"ask_ct":1},{"bid_px":"235.000000000","ask_px":"253.650000000","bid_sz":100,"ask_sz":400,"bid_ct":1,"ask_ct":1},{"bid_px":"214.000000000","ask_px":"275.000000000","bid_sz":5,"ask_sz":4,"bid_ct":1,"ask_ct":1},{"bid_px":"203.000000000","ask_px":"960.000000000","bid_sz":2,"ask_sz":25,"bid_ct":1,"ask_ct":1},{"bid_px":"170.000000000","ask_px":null,"bid_sz":3,"ask_sz":0,"bid_ct":1,"ask_ct":0},{"bid_px":null,"ask_px":null,"bid_sz":0,"ask_sz":0,"bid_ct":0,"ask_ct":0},{"bid_px":null,"ask_px":null,"bid_sz":0,"ask_sz":0,"bid_ct":0,"ask_ct":0},{"bid_px":null,"ask_px":null,"bid_sz":0,"ask_sz":0,"bid_ct":0,"ask_ct":0}],"symbol":"TSLA"}
{"ts_recv":"2024-11-01T08:00:04.185728699Z","hd":{"ts_event":"2024-11-01T08:00:04.185562559Z","rtype":10,"publisher_id":2,"instrument_id":16244},"action":"A","side":"A","depth":0,"price":"250.680000000","size":100,"flags":130,"ts_in_delta":166140,"sequence":295162,"levels":[{"bid_px":"249.600000000","ask_px":"250.680000000","bid_sz":1000,"ask_sz":100,"bid_ct":1,"ask_ct":1},{"bid_px":"249.300000000","ask_px":"250.960000000","bid_sz":1000,"ask_sz":50,"bid_ct":1,"ask_ct":1},{"bid_px":"247.150000000","ask_px":"251.300000000","bid_sz":400,"ask_sz":1000,"bid_ct":1,"ask_ct":1},{"bid_px":"235.000000000","ask_px":"253.650000000","bid_sz":100,"ask_sz":400,"bid_ct":1,"ask_ct":1},{"bid_px":"214.000000000","ask_px":"275.000000000","bid_sz":5,"ask_sz":4,"bid_ct":1,"ask_ct":1},{"bid_px":"203.000000000","ask_px":"960.000000000","bid_sz":2,"ask_sz":25,"bid_ct":1,"ask_ct":1},{"bid_px":"170.000000000","ask_px":null,"bid_sz":3,"ask_sz":0,"bid_ct":1,"ask_ct":0},{"bid_px":null,"ask_px":null,"bid_sz":0,"ask_sz":0,"bid_ct":0,"ask_ct":0},{"bid_px":null,"ask_px":null,"bid_sz":0,"ask_sz":0,"bid_ct":0,"ask_ct":0},{"bid_px":null,"ask_px":null,"bid_sz":0,"ask_sz":0,"bid_ct":0,"ask_ct":0}],"symbol":"TSLA"}
{"ts_recv":"2024-11-01T08:00:04.197584272Z","hd":{"ts_event":"2024-11-01T08:00:04.197416893Z","rtype":10,"publisher_id":2,"instrument_id":38},"action":"A","side":"B","depth":4,"price":"190.000000000","size":1,"flags":130,"ts_in_delta":167379,"sequence":295174,"levels":[{"bid_px":"221.200000000","ask_px":"224.400000000","bid_sz":1000,"ask_sz":1000,"bid_ct":1,"ask_ct":1},{"bid_px":"220.000000000","ask_px":"225.490000000","bid_sz":2,"ask_sz":442,"bid_ct":1,"ask_ct":1},{"bid_px":"219.690000000","ask_px":"234.000000000","bid_sz":442,"ask_sz":20,"bid_ct":1,"ask_ct":1},{"bid_px":"217.000000000","ask_px":null,"bid_sz":1525,"ask_sz":0,"bid_ct":1,"ask_ct":0},{"bid_px":"190.000000000","ask_px":null,"bid_sz":1,"ask_sz":0,"bid_ct":1,"ask_ct":0},{"bid_px":null,"ask_px":null,"bid_sz":0,"ask_sz":0,"bid_ct":0,"ask_ct":0},{"bid_px":null,"ask_px":null,"bid_sz":0,"ask_sz":0,"bid_ct":0,"ask_ct":0},{"bid_px":null,"ask_px":null,"bid_sz":0,"ask_sz":0,"bid_ct":0,"ask_ct":0},{"bid_px":null,"ask_px":null,"bid_sz":0,"ask_sz":0,"bid_ct":0,"ask_ct":0},{"bid_px":null,"ask_px":null,"bid_sz":0,"ask_sz":0,"bid_ct":0,"ask_ct":0}],"symbol":"AAPL"}
{"ts_recv":"2024-11-01T08:00:04.206245462Z","hd":{"ts_event":"2024-11-01T08:00:04.206079566Z","rtype":10,"publisher_id":2,"instrument_id":11667},"action":"C","side":"B","depth":0,"price":"134.770000000","size":100,"flags":130,"ts_in_delta":165896,"sequence":295179,"levels":[{"bid_px":"134.410000000","ask_px":"135.300000000","bid_sz":1,"ask_sz":1000,"bid_ct":1,"ask_ct":1},{"bid_px":"134.210000000","ask_px":"136.100000000","bid_sz":20,"ask_sz":1000,"bid_ct":1,"ask_ct":1},{"bid_px":"133.100000000","ask_px":"137.680000000","bid_sz":1000,"ask_sz":500,"bid_ct":1,"ask_ct":1},{"bid_px":"132.000000000","ask_px":"138.870000000","bid_sz":71,"ask_sz":1000,"bid_ct":2,"ask_ct":2},{"bid_px":"129.050000000","ask_px":"140.740000000","bid_sz":500,"ask_sz":100,"bid_ct":1,"ask_ct":1},{"bid_px":"129.000000000","ask_px":"140.880000000","bid_sz":10,"ask_sz":1000,"bid_ct":1,"ask_ct":2},{"bid_px":"128.470000000","ask_px":"143.690000000","bid_sz":500,"ask_sz":500,"bid_ct":1,"ask_ct":1},{"bid_px":"127.680000000","ask_px":"146.510000000","bid_sz":30,"ask_sz":5,"bid_ct":1,"ask_ct":1},{"bid_px":"127.500000000","ask_px":"148.000000000","bid_sz":5,"ask_sz":5,"bid_ct":1,"ask_ct":1},{"bid_px":"127.000000000","ask_px":null,"bid_sz":20,"ask_sz":0,"bid_ct":1,"ask_ct":0}],"symbol":"NVDA"}
{"ts_recv":"2024-11-01T08:00:04.206723102Z","hd":{"ts_event":"2024-11-01T08:00:04.206556827Z","rtype":10,"publisher_id":2,"instrument_id":11667},"action":"A","side":"B","depth":0,"price":"134.560000000","size":100,"flags":130,"ts_in_delta":166275,"sequence":295180,"levels":[{"bid_px":"134.560000000","ask_px":"135.300000000","bid_sz":100,"ask_sz":1000,"bid_ct":1,"ask_ct":1},{"bid_px":"134.410000000","ask_px":"136.100000000","bid_sz":1,"ask_sz":1000,"bid_ct":1,"ask_ct":1},{"bid_px":"134.210000000","ask_px":"137.680000000","bid_sz":20,"ask_sz":500,"bid_ct":1,"ask_ct":1},{"bid_px":"133.100000000","ask_px":"138.870000000","bid_sz":1000,"ask_sz":1000,"bid_ct":1,"ask_ct":2},{"bid_px":"132.000000000","ask_px":"140.740000000","bid_sz":71,"ask_sz":100,"bid_ct":2,"ask_ct":1},{"bid_px":"129.050000000","ask_px":"140.880000000","bid_sz":500,"ask_sz":1000,"bid_ct":1,"ask_ct":2},{"bid_px":"129.000000000","ask_px":"143.690000000","bid_sz":10,"ask_sz":500,"bid_ct":1,"ask_ct":1},{"bid_px":"128.470000000","ask_px":"146.510000000","bid_sz":500,"ask_sz":5,"bid_ct":1,"ask_ct":1},{"bid_px":"127.680000000","ask_px":"148.000000000","bid_sz":30,"ask_sz":5,"bid_ct":1,"ask_ct":1},{"bid_px":"127.500000000","ask_px":null,"bid_sz":5,"ask_sz":0,"bid_ct":1,"ask_ct":0}],"symbol":"NVDA"}
{"ts_recv":"2024-11-01T08:00:04.209954772Z","hd":{"ts_event":"2024-11-01T08:00:04.209789063Z","rtype":10,"publisher_id":2,"instrument_id":16244},"action":"C","side":"A","depth":2,"price":"251.300000000","size":1000,"flags":130,"ts_in_delta":165709,"sequence":295186,"levels":[{"bid_px":"249.600000000","ask_px":"250.680000000","bid_sz":1000,"ask_sz":100,"bid_ct":1,"ask_ct":1},{"bid_px":"249.300000000","ask_px":"250.960000000","bid_sz":1000,"ask_sz":50,"bid_ct":1,"ask_ct":1},{"bid_px":"247.150000000","ask_px":"253.650000000","bid_sz":400,"ask_sz":400,"bid_ct":1,"ask_ct":1},{"bid_px":"235.000000000","ask_px":"275.000000000","bid_sz":100,"ask_sz":4,"bid_ct":1,"ask_ct":1},{"bid_px":"214.000000000","ask_px":"960.000000000","bid_sz":5,"ask_sz":25,"bid_ct":1,"ask_ct":1},{"bid_px":"203.000000000","ask_px":null,"bid_sz":2,"ask_sz":0,"bid_ct":1,"ask_ct":0},{"bid_px":"170.000000000","ask_px":null,"bid_sz":3,"ask_sz":0,"bid_ct":1,"ask_ct":0},{"bid_px":null,"ask_px":null,"bid_sz":0,"ask_sz":0,"bid_ct":0,"ask_ct":0},{"bid_px":null,"ask_px":null,"bid_sz":0,"ask_sz":0,"bid_ct":0,"ask_ct":0},{"bid_px":null,"ask_px":null,"bid_sz":0,"ask_sz":0,"bid_ct":0,"ask_ct":0}],"symbol":"TSLA"}
{"ts_recv":"2024-11-01T08:00:04.210810479Z","hd":{"ts_event":"2024-11-01T08:00:04.210644343Z","rtype":10,"publisher_id":2,"instrument_id":16244},"action":"A","side":"B","depth":5,"price":"213.000000000","size":1,"flags":130,"ts_in_delta":166136,"sequence":295187,"levels":[{"bid_px":"249.600000000","ask_px":"250.680000000","bid_sz":1000,"ask_sz":100,"bid_ct":1,"ask_ct":1},{"bid_px":"249.300000000","ask_px":"250.960000000","bid_sz":1000,"ask_sz":50,"bid_ct":1,"ask_ct":1},{"bid_px":"247.150000000","ask_px":"253.650000000","bid_sz":400,"ask_sz":400,"bid_ct":1,"ask_ct":1},{"bid_px":"235.000000000","ask_px":"275.000000000","bid_sz":100,"ask_sz":4,"bid_ct":1,"ask_ct":1},{"bid_px":"214.000000000","ask_px":"960.000000000","bid_sz":5,"ask_sz":25,"bid_ct":1,"ask_ct":1},{"bid_px":"213.000000000","ask_px":null,"bid_sz":1,"ask_sz":0,"bid_ct":1,"ask_ct":0},{"bid_px":"203.000000000","ask_px":null,"bid_sz":2,"ask_sz":0,"bid_ct":1,"ask_ct":0},{"bid_px":"170.000000000","ask_px":null,"bid_sz":3,"ask_sz":0,"bid_ct":1,"ask_ct":0},{"bid_px":null,"ask_px":null,"bid_sz":0,"ask_sz":0,"bid_ct":0,"ask_ct":0},{"bid_px":null,"ask_px":null,"bid_sz":0,"ask_sz":0,"bid_ct":0,"ask_ct":0}],"symbol":"TSLA"}
{"ts_recv":"2024-11-01T08:00:04.220490319Z","hd":{"ts_event":"2024-11-01T08:00:04.220324092Z","rtype":10,"publisher_id":2,"instrument_id":16244},"action":"A","side":"A","depth":2,"price":"251.700000000","size":1000,"flags":130,"ts_in_delta":166227,"sequence":295214,"levels":[{"bid_px":"249.600000000","ask_px":"250.680000000","bid_sz":1000,"ask_sz":100,"bid_ct":1,"ask_ct":1},{"bid_px":"249.300000000","ask_px":"250.960000000","bid_sz":1000,"ask_sz":50,"bid_ct":1,"ask_ct":1},{"bid_px":"247.150000000","ask_px":"251.700000000","bid_sz":400,"ask_sz":1000,"bid_ct":1,"ask_ct":1},{"bid_px":"235.000000000","ask_px":"253.650000000","bid_sz":100,"ask_sz":400,"bid_ct":1,"ask_ct":1},{"bid_px":"214.000000000","ask_px":"275.000000000","bid_sz":5,"ask_sz":4,"bid_ct":1,"ask_ct":1},{"bid_px":"213.000000000","ask_px":"960.000000000","bid_sz":1,"ask_sz":25,"bid_ct":1,"ask_ct":1},{"bid_px":"203.000000000","ask_px":null,"bid_sz":2,"ask_sz":0,"bid_ct":1,"ask_ct":0},{"bid_px":"170.000000000","ask_px":null,"bid_sz":3,"ask_sz":0,"bid_ct":1,"ask_ct":0},{"bid_px":null,"ask_px":null,"bid_sz":0,"ask_sz":0,"bid_ct":0,"ask_ct":0},{"bid_px":null,"ask_px":null,"bid_sz":0,"ask_sz":0,"bid_ct":0,"ask_ct":0}],"symbol":"TSLA"}
{"ts_recv":"2024-11-01T08:00:04.233938968Z","hd":{"ts_event":"2024-11-01T08:00:04.233772682Z","rtype":10,"publisher_id":2,"instrument_id":38},"action":"A","side":"B","depth":5,"price":"180.000000000","size":1,"flags":130,"ts_in_delta":166286,"sequence":295267,"levels":[{"bid_px":"221.200000000","ask_px":"224.400000000","bid_sz":1000,"ask_sz":1000,"bid_ct":1,"ask_ct":1},{"bid_px":"220.000000000","ask_px":"225.490000000","bid_sz":2,"ask_sz":442,"bid_ct":1,"ask_ct":1},{"bid_px":"219.690000000","ask_px":"234.000000000","bid_sz":442,"ask_sz":20,"bid_ct":1,"ask_ct":1},{"bid_px":"217.000000000","ask_px":null,"bid_sz":1525,"ask_sz":0,"bid_ct":1,"ask_ct":0},{"bid_px":"190.000000000","ask_px":null,"bid_sz":1,"ask_sz":0,"bid_ct":1,"ask_ct":0},{"bid_px":"180.000000000","ask_px":null,"bid_sz":1,"ask_sz":0,"bid_ct":1,"ask_ct":0},{"bid_px":null,"ask_px":null,"bid_sz":0,"ask_sz":0,"bid_ct":0,"ask_ct":0},{"bid_px":null,"ask_px":null,"bid_sz":0,"ask_sz":0,"bid_ct":0,"ask_ct":0},{"bid_px":null,"ask_px":null,"bid_sz":0,"ask_sz":0,"bid_ct":0,"ask_ct":0},{"bid_px":null,"ask_px":null,"bid_sz":0,"ask_sz":0,"bid_ct":0,"ask_ct":0}],"symbol":"AAPL"}
{"ts_recv":"2024-11-01T08:00:04.238566791Z","hd":{"ts_event":"2024-11-01T08:00:04.238400706Z","rtype":10,"publisher_id":2,"instrument_id":16244},"action":"A","side":"B","depth":0,"price":"249.870000000","size":50,"flags":130,"ts_in_delta":166085,"sequence":295290,"levels":[{"bid_px":"249.870000000","ask_px":"250.680000000","bid_sz":50,"ask_sz":100,"bid_ct":1,"ask_ct":1},{"bid_px":"249.600000000","ask_px":"250.960000000","bid_sz":1000,"ask_sz":50,"bid_ct":1,"ask_ct":1},{"bid_px":"249.300000000","ask_px":"251.700000000","bid_sz":1000,"ask_sz":1000,"bid_ct":1,"ask_ct":1},{"bid_px":"247.150000000","ask_px":"253.650000000","bid_sz":400,"ask_sz":400,"bid_ct":1,"ask_ct":1},{"bid_px":"235.000000000","ask_px":"275.000000000","bid_sz":100,"ask_sz":4,"bid_ct":1,"ask_ct":1},{"bid_px":"214.000000000","ask_px":"960.000000000","bid_sz":5,"ask_sz":25,"bid_ct":1,"ask_ct":1},{"bid_px":"213.000000000","ask_px":null,"bid_sz":1,"ask_sz":0,"bid_ct":1,"ask_ct":0},{"bid_px":"203.000000000","ask_px":null,"bid_sz":2,"ask_sz":0,"bid_ct":1,"ask_ct":0},{"bid_px":"170.000000000","ask_px":null,"bid_sz":3,"ask_sz":0,"bid_ct":1,"ask_ct":0},{"bid_px":null,"ask_px":null,"bid_sz":0,"ask_sz":0,"bid_ct":0,"ask_ct":0}],"symbol":"TSLA"}
{"ts_recv":"2024-11-01T08:00:04.238923737Z","hd":{"ts_event":"2024-11-01T08:00:04.238758087Z","rtype":10,"publisher_id":2,"instrument_id":16244},"action":"C","side":"A","depth":2,"price":"251.700000000","size":1000,"flags":130,"ts_in_delta":165650,"sequence":295293,"levels":[{"bid_px":"249.870000000","ask_px":"250.680000000","bid_sz":50,"ask_sz":100,"bid_ct":1,"ask_ct":1},{"bid_px":"249.600000000","ask_px":"250.960000000","bid_sz":1000,"ask_sz":50,"bid_ct":1,"ask_ct":1},{"bid_px":"249.300000000","ask_px":"253.650000000","bid_sz":1000,"ask_sz":400,"bid_ct":1,"ask_ct":1},{"bid_px":"247.150000000","ask_px":"275.000000000","bid_sz":400,"ask_sz":4,"bid_ct":1,"ask_ct":1},{"bid_px":"235.000000000","ask_px":"960.000000000","bid_sz":100,"ask_sz":25,"bid_ct":1,"ask_ct":1},{"bid_px":"214.000000000","ask_px":null,"bid_sz":5,"ask_sz":0,"bid_ct":1,"ask_ct":0},{"bid_px":"213.000000000","ask_px":null,"bid_sz":1,"ask_sz":0,"bid_ct":1,"ask_ct":0},{"bid_px":"203.000000000","ask_px":null,"bid_sz":2,"ask_sz":0,"bid_ct":1,"ask_ct":0},{"bid_px":"170.000000000","ask_px":null,"bid_sz":3,"ask_sz":0,"bid_ct":1,"ask_ct":0},{"bid_px":null,"ask_px":null,"bid_sz":0,"ask_sz":0,"bid_ct":0,"ask_ct":0}],"symbol":"TSLA"}
{"ts_recv":"2024-11-01T08:00:04.249251005Z","hd":{"ts_event":"2024-11-01T08:00:04.249084553Z","rtype":10,"publisher_id":2,"instrument_id":16244},"action":"A","side":"A","depth":2,"price":"251.900000000","size":1000,"flags":130,"ts_in_delta":166452,"sequence":295330,"levels":[{"bid_px":"249.870000000","ask_px":"250.680000000","bid_sz":50,"ask_sz":100,"bid_ct":1,"ask_ct":1},{"bid_px":"249.600000000","ask_px":"250.960000000","bid_sz":1000,"ask_sz":50,"bid_ct":1,"ask_ct":1},{"bid_px":"249.300000000","ask_px":"251.900000000","bid_sz":1000,"ask_sz":1000,"bid_ct":1,"ask_ct":1},{"bid_px":"247.150000000","ask_px":"253.650000000","bid_sz":400,"ask_sz":400,"bid_ct":1,"ask_ct":1},{"bid_px":"235.000000000","ask_px":"275.000000000","bid_sz":100,"ask_sz":4,"bid_ct":1,"ask_ct":1},{"bid_px":"214.000000000","ask_px":"960.000000000","bid_sz":5,"ask_sz":25,"bid_ct":1,"ask_ct":1},{"bid_px":"213.000000000","ask_px":null,"bid_sz":1,"ask_sz":0,"bid_ct":1,"ask_ct":0},{"bid_px":"203.000000000","ask_px":null,"bid_sz":2,"ask_sz":0,"bid_ct":1,"ask_ct":0},{"bid_px":"170.000000000","ask_px":null,"bid_sz":3,"ask_sz":0,"bid_ct":1,"ask_ct":0},{"bid_px":null,"ask_px":null,"bid_sz":0,"ask_sz":0,"bid_ct":0,"ask_ct":0}],"symbol":"TSLA"}
{"ts_recv":"2024-11-01T08:00:04.280306392Z","hd":{"ts_event":"2024-11-01T08:00:04.280140242Z","rtype":10,"publisher_id":2,"instrument_id":11667},"action":"A","side":"A","depth":6,"price":"143.000000000","size":1,"flags":130,"ts_in_delta":166150,"sequence":295376,"levels":[{"bid_px":"134.560000000","ask_px":"135.300000000","bid_sz":100,"ask_sz":1000,"bid_ct":1,"ask_ct":1},{"bid_px":"134.410000000","ask_px":"136.100000000","bid_sz":1,"ask_sz":1000,"bid_ct":1,"ask_ct":1},{"bid_px":"134.210000000","ask_px":"137.680000000","bid_sz":20,"ask_sz":500,"bid_ct":1,"ask_ct":1},{"bid_px":"133.100000000","ask_px":"138.870000000","bid_sz":1000,"ask_sz":1000,"bid_ct":1,"ask_ct":2},{"bid_px":"132.000000000","ask_px":"140.740000000","bid_sz":71,"ask_sz":100,"bid_ct":2,"ask_ct":1},{"bid_px":"129.050000000","ask_px":"140.880000000","bid_sz":500,"ask_sz":1000,"bid_ct":1,"ask_ct":2},{"bid_px":"129.000000000","ask_px":"143.000000000","bid_sz":10,"ask_sz":1,"bid_ct":1,"ask_ct":1},{"bid_px":"128.470000000","ask_px":"143.690000000","bid_sz":500,"ask_sz":500,"bid_ct":1,"ask_ct":1},{"bid_px":"127.680000000","ask_px":"146.510000000","bid_sz":30,"ask_sz":5,"bid_ct":1,"ask_ct":1},{"bid_px":"127.500000000","ask_px":"148.000000000","bid_sz":5,"ask_sz":5,"bid_ct":1,"ask_ct":1}],"symbol":"NVDA"}
{"ts_recv":"2024-11-01T08:00:04.291897046Z","hd":{"ts_event":"2024-11-01T08:00:04.291730773Z","rtype":10,"publisher_id":2,"instrument_id":9155},"action":"A","side":"B","depth":0,"price":"221.850000000","size":3,"flags":130,"ts_in_delta":166273,"sequence":295399,"levels":[{"bid_px":"221.850000000","ask_px":"224.940000000","bid_sz":3,"ask_sz":450,"bid_ct":1,"ask_ct":1},{"bid_px":"219.160000000","ask_px":"226.800000000","bid_sz":450,"ask_sz":100,"bid_ct":1,"ask_ct":1},{"bid_px":"217.610000000","ask_px":null,"bid_sz":100,"ask_sz":0,"bid_ct":1,"ask_ct":0},{"bid_px":null,"ask_px":null,"bid_sz":0,"ask_sz":0,"bid_ct":0,"ask_ct":0},{"bid_px":null,"ask_px":null,"bid_sz":0,"ask_sz":0,"bid_ct":0,"ask_ct":0},{"bid_px":null,"ask_px":null,"bid_sz":0,"ask_sz":0,"bid_ct":0,"ask_ct":0},{"bid_px":null,"ask_px":null,"bid_sz":0,"ask_sz":0,"bid_ct":0,"ask_ct":0},{"bid_px":null,"ask_px":null,"bid_sz":0,"ask_sz":0,"bid_ct":0,"ask_ct":0},{"bid_px":null,"ask_px":null,"bid_sz":0,"ask_sz":0,"bid_ct":0,"ask_ct":0},{"bid_px":null,"ask_px":null,"bid_sz":0,"ask_sz":0,"bid_ct":0,"ask_ct":0}],"symbol":"JPM"}
{"ts_recv":"2024-11-01T08:00:04.303537228Z","hd":{"ts_event":"2024-11-01T08:00:04.303371082Z","rtype":10,"publisher_id":2,"instrument_id":38},"action":"A","side":"A","depth":3,"price":"240.000000000","size":150,"flags":130,"ts_in_delta":166146,"sequence":295408,"levels":[{"bid_px":"221.200000000","ask_px":"224.400000000","bid_sz":1000,"ask_sz":1000,"bid_ct":1,"ask_ct":1},{"bid_px":"220.000000000","ask_px":"225.490000000","bid_sz":2,"ask_sz":442,"bid_ct":1,"ask_ct":1},{"bid_px":"219.690000000","ask_px":"234.000000000","bid_sz":442,"ask_sz":20,"bid_ct":1,"ask_ct":1},{"bid_px":"217.000000000","ask_px":"240.000000000","bid_sz":1525,"ask_sz":150,"bid_ct":1,"ask_ct":1},{"bid_px":"190.000000000","ask_px":null,"bid_sz":1,"ask_sz":0,"bid_ct":1,"ask_ct":0},{"bid_px":"180.000000000","ask_px":null,"bid_sz":1,"ask_sz":0,"bid_ct":1,"ask_ct":0},{"bid_px":null,"ask_px":null,"bid_sz":0,"ask_sz":0,"bid_ct":0,"ask_ct":0},{"bid_px":null,"ask_px":null,"bid_sz":0,"ask_sz":0,"bid_ct":0,"ask_ct":0},{"bid_px":null,"ask_px":null,"bid_sz":0,"ask_sz":0,"bid_ct":0,"ask_ct":0},{"bid_px":null,"ask_px":null,"bid_sz":0,"ask_sz":0,"bid_ct":0,"ask_ct":0}],"symbol":"AAPL"}
{"ts_recv":"2024-11-01T08:00:04.366083888Z","hd":{"ts_event":"2024-11-01T08:00:04.365918109Z","rtype":10,"publisher_id":2,"instrument_id":16244},"action":"C","side":"B","depth":0,"price":"249.870000000","size":50,"flags":130,"ts_in_delta":165779,"sequence":295485,"levels":[{"bid_px":"249.600000000","ask_px":"250.680000000","bid_sz":1000,"ask_sz":100,"bid_ct":1,"ask_ct":1},{"bid_px":"249.300000000","ask_px":"250.960000000","bid_sz":1000,"ask_sz":50,"bid_ct":1,"ask_ct":1},{"bid_px":"247.150000000","ask_px":"251.900000000","bid_sz":400,"ask_sz":1000,"bid_ct":1,"ask_ct":1},{"bid_px":"235.000000000","ask_px":"253.650000000","bid_sz":100,"ask_sz":400,"bid_ct":1,"ask_ct":1},{"bid_px":"214.000000000","ask_px":"275.000000000","bid_sz":5,"ask_sz":4,"bid_ct":1,"ask_ct":1},{"bid_px":"213.000000000","ask_px":"960.000000000","bid_sz":1,"ask_sz":25,"bid_ct":1,"ask_ct":1},{"bid_px":"203.000000000","ask_px":null,"bid_sz":2,"ask_sz":0,"bid_ct":1,"ask_ct":0},{"bid_px":"170.000000000","ask_px":null,"bid_sz":3,"ask_sz":0,"bid_ct":1,"ask_ct":0},{"bid_px":null,"ask_px":null,"bid_sz":0,"ask_sz":0,"bid_ct":0,"ask_ct":0},{"bid_px":null,"ask_px":null,"bid_sz":0,"ask_sz":0,"bid_ct":0,"ask_ct":0}],"symbol":"TSLA"}
{"ts_recv":"2024-11-01T08:00:04.366098645Z","hd":{"ts_event":"2024-11-01T08:00:04.365931595Z","rtype":10,"publisher_id":2,"instrument_id":16244},"action":"A","side":"B","depth":0,"price":"249.850000000","size":50,"flags":128,"ts_in_delta":167050,"sequence":295487,"levels":[{"bid_px":"249.850000000","ask_px":"250.680000000","bid_sz":50,"ask_sz":100,"bid_ct":1,"ask_ct":1},{"bid_px":"249.600000000","ask_px":"250.960000000","bid_sz":1000,"ask_sz":50,"bid_ct":1,"ask_ct":1},{"bid_px":"249.300000000","ask_px":"251.900000000","bid_sz":1000,"ask_sz":1000,"bid_ct":1,"ask_ct":1},{"bid_px":"247.150000000","ask_px":"253.650000000","bid_sz":400,"ask_sz":400,"bid_ct":1,"ask_ct":1},{"bid_px":"235.000000000","ask_px":"275.000000000","bid_sz":100,"ask_sz":4,"bid_ct":1,"ask_ct":1},{"bid_px":"214.000000000","ask_px":"960.000000000","bid_sz":5,"ask_sz":25,"bid_ct":1,"ask_ct":1},{"bid_px":"213.000000000","ask_px":null,"bid_sz":1,"ask_sz":0,"bid_ct":1,"ask_ct":0},{"bid_px":"203.000000000","ask_px":null,"bid_sz":2,"ask_sz":0,"bid_ct":1,"ask_ct":0},{"bid_px":"170.000000000","ask_px":null,"bid_sz":3,"ask_sz":0,"bid_ct":1,"ask_ct":0},{"bid_px":null,"ask_px":null,"bid_sz":0,"ask_sz":0,"bid_ct":0,"ask_ct":0}],"symbol":"TSLA"}
{"ts_recv":"2024-11-01T08:00:04.367087628Z","hd":{"ts_event":"2024-11-01T08:00:04.366921961Z","rtype":10,"publisher_id":2,"instrument_id":16244},"action":"C","side":"B","depth":0,"price":"249.850000000","size":50,"flags":130,"ts_in_delta":165667,"sequence":295494,"levels":[{"bid_px":"249.600000000","ask_px":"250.680000000","bid_sz":1000,"ask_sz":100,"bid_ct":1,"ask_ct":1},{"bid_px":"249.300000000","ask_px":"250.960000000","bid_sz":1000,"ask_sz":50,"bid_ct":1,"ask_ct":1},{"bid_px":"247.150000000","ask_px":"251.900000000","bid_sz":400,"ask_sz":1000,"bid_ct":1,"ask_ct":1},{"bid_px":"235.000000000","ask_px":"253.650000000","bid_sz":100,"ask_sz":400,"bid_ct":1,"ask_ct":1},{"bid_px":"214.000000000","ask_px":"275.000000000","bid_sz":5,"ask_sz":4,"bid_ct":1,"ask_ct":1},{"bid_px":"213.000000000","ask_px":"960.000000000","bid_sz":1,"ask_sz":25,"bid_ct":1,"ask_ct":1},{"bid_px":"203.000000000","ask_px":null,"bid_sz":2,"ask_sz":0,"bid_ct":1,"ask_ct":0},{"bid_px":"170.000000000","ask_px":null,"bid_sz":3,"ask_sz":0,"bid_ct":1,"ask_ct":0},{"bid_px":null,"ask_px":null,"bid_sz":0,"ask_sz":0,"bid_ct":0,"ask_ct":0},{"bid_px":null,"ask_px":null,"bid_sz":0,"ask_sz":0,"bid_ct":0,"ask_ct":0}],"symbol":"TSLA"}
{"ts_recv":"2024-11-01T08:00:04.367100716Z","hd":{"ts_event":"2024-11-01T08:00:04.366934766Z","rtype":10,"publisher_id":2,"instrument_id":16244},"action":"A","side":"B","depth":0,"price":"249.820000000","size":100,"flags":130,"ts_in_delta":165950,"sequence":295495,"levels":[{"bid_px":"249.820000000","ask_px":"250.680000000","bid_sz":100,"ask_sz":100,"bid_ct":1,"ask_ct":1},{"bid_px":"249.600000000","ask_px":"250.960000000","bid_sz":1000,"ask_sz":50,"bid_ct":1,"ask_ct":1},{"bid_px":"249.300000000","ask_px":"251.900000000","bid_sz":1000,"ask_sz":1000,"bid_ct":1,"ask_ct":1},{"bid_px":"247.150000000","ask_px":"253.650000000","bid_sz":400,"ask_sz":400,"bid_ct":1,"ask_ct":1},{"bid_px":"235.000000000","ask_px":"275.000000000","bid_sz":100,"ask_sz":4,"bid_ct":1,"ask_ct":1},{"bid_px":"214.000000000","ask_px":"960.000000000","bid_sz":5,"ask_sz":25,"bid_ct":1,"ask_ct":1},{"bid_px":"213.000000000","ask_px":null,"bid_sz":1,"ask_sz":0,"bid_ct":1,"ask_ct":0},{"bid_px":"203.000000000","ask_px":null,"bid_sz":2,"ask_sz":0,"bid_ct":1,"ask_ct":0},{"bid_px":"170.000000000","ask_px":null,"bid_sz":3,"ask_sz":0,"bid_ct":1,"ask_ct":0},{"bid_px":null,"ask_px":null,"bid_sz":0,"ask_sz":0,"bid_ct":0,"ask_ct":0}],"symbol":"TSLA"}
{"ts_recv":"2024-11-01T08:00:04.390459448Z","hd":{"ts_event":"2024-11-01T08:00:04.390293393Z","rtype":10,"publisher_id":2,"instrument_id":16244},"action":"A","side":"A","depth":4,"price":"265.000000000","size":1,"flags":130,"ts_in_delta":166055,"sequence":295522,"levels":[{"bid_px":"249.820000000","ask_px":"250.680000000","bid_sz":100,"ask_sz":100,"bid_ct":1,"ask_ct":1},{"bid_px":"249.600000000","ask_px":"250.960000000","bid_sz":1000,"ask_sz":50,"bid_ct":1,"ask_ct":1},{"bid_px":"249.300000000","ask_px":"251.900000000","bid_sz":1000,"ask_sz":1000,"bid_ct":1,"ask_ct":1},{"bid_px":"247.150000000","ask_px":"253.650000000","bid_sz":400,"ask_sz":400,"bid_ct":1,"ask_ct":1},{"bid_px":"235.000000000","ask_px":"265.000000000","bid_sz":100,"ask_sz":1,"bid_ct":1,"ask_ct":1},{"bid_px":"214.000000000","ask_px":"275.000000000","bid_sz":5,"ask_sz":4,"bid_ct":1,"ask_ct":1},{"bid_px":"213.000000000","ask_px":"960.000000000","bid_sz":1,"ask_sz":25,"bid_ct":1,"ask_ct":1},{"bid_px":"203.000000000","ask_px":null,"bid_sz":2,"ask_sz":0,"bid_ct":1,"ask_ct":0},{"bid_px":"170.000000000","ask_px":null,"bid_sz":3,"ask_sz":0,"bid_ct":1,"ask_ct":0},{"bid_px":null,"ask_px":null,"bid_sz":0,"ask_sz":0,"bid_ct":0,"ask_ct":0}],"symbol":"TSLA"}
{"ts_recv":"2024-11-01T08:00:04.404980797Z","hd":{"ts_event":"2024-11-01T08:00:04.404814202Z","rtype":10,"publisher_id":2,"instrument_id":16244},"action":"A","side":"B","depth":5,"price":"220.000000000","size":1,"flags":130,"ts_in_delta":166595,"sequence":295529,"levels":[{"bid_px":"249.820000000","ask_px":"250.680000000","bid_sz":100,"ask_sz":100,"bid_ct":1,"ask_ct":1},{"bid_px":"249.600000000","ask_px":"250.960000000","bid_sz":1000,"ask_sz":50,"bid_ct":1,"ask_ct":1},{"bid_px":"249.300000000","ask_px":"251.900000000","bid_sz":1000,"ask_sz":1000,"bid_ct":1,"ask_ct":1},{"bid_px":"247.150000000","ask_px":"253.650000000","bid_sz":400,"ask_sz":400,"bid_ct":1,"ask_ct":1},{"bid_px":"235.000000000","ask_px":"265.000000000","bid_sz":100,"ask_sz":1,"bid_ct":1,"ask_ct":1},{"bid_px":"220.000000000","ask_px":"275.000000000","bid_sz":1,"ask_sz":4,"bid_ct":1,"ask_ct":1},{"bid_px":"214.000000000","ask_px":"960.000000000","bid_sz":5,"ask_sz":25,"bid_ct":1,"ask_ct":1},{"bid_px":"213.000000000","ask_px":null,"bid_sz":1,"ask_sz":0,"bid_ct":1,"ask_ct":0},{"bid_px":"203.000000000","ask_px":null,"bid_sz":2,"ask_sz":0,"bid_ct":1,"ask_ct":0},{"bid_px":"170.000000000","ask_px":null,"bid_sz":3,"ask_sz":0,"bid_ct":1,"ask_ct":0}],"symbol":"TSLA"}
{"ts_recv":"2024-11-01T08:00:04.443604460Z","hd":{"ts_event":"2024-11-01T08:00:04.443438209Z","rtype":10,"publisher_id":2,"instrument_id":16244},"action":"A","side":"A","depth":1,"price":"250.960000000","size":50,"flags":130,"ts_in_delta":166251,"sequence":295569,"levels":[{"bid_px":"249.820000000","ask_px":"250.680000000","bid_sz":100,"ask_sz":100,"bid_ct":1,"ask_ct":1},{"bid_px":"249.600000000","ask_px":"250.960000000","bid_sz":1000,"ask_sz":100,"bid_ct":1,"ask_ct":2},{"bid_px":"249.300000000","ask_px":"251.900000000","bid_sz":1000,"ask_sz":1000,"bid_ct":1,"ask_ct":1},{"bid_px":"247.150000000","ask_px":"253.650000000","bid_sz":400,"ask_sz":400,"bid_ct":1,"ask_ct":1},{"bid_px":"235.000000000","ask_px":"265.000000000","bid_sz":100,"ask_sz":1,"bid_ct":1,"ask_ct":1},{"bid_px":"220.000000000","ask_px":"275.000000000","bid_sz":1,"ask_sz":4,"bid_ct":1,"ask_ct":1},{"bid_px":"214.000000000","ask_px":"960.000000000","bid_sz":5,"ask_sz":25,"bid_ct":1,"ask_ct":1},{"bid_px":"213.000000000","ask_px":null,"bid_sz":1,"ask_sz":0,"bid_ct":1,"ask_ct":0},{"bid_px":"203.000000000","ask_px":null,"bid_sz":2,"ask_sz":0,"bid_ct":1,"ask_ct":0},{"bid_px":"170.000000000","ask_px":null,"bid_sz":3,"ask_sz":0,"bid_ct":1,"ask_ct":0}],"symbol":"TSLA"}
{"ts_recv":"2024-11-01T08:00:04.470413664Z","hd":{"ts_event":"2024-11-01T08:00:04.470247417Z","rtype":10,"publisher_id":2,"instrument_id":16244},"action":"A","side":"A","depth":4,"price":"260.000000000","size":48,"flags":130,"ts_in_delta":166247,"sequence":295623,"levels":[{"bid_px":"249.820000000","ask_px":"250.680000000","bid_sz":100,"ask_sz":100,"bid_ct":1,"ask_ct":1},{"bid_px":"249.600000000","ask_px":"250.960000000","bid_sz":1000,"ask_sz":100,"bid_ct":1,"ask_ct":2},{"bid_px":"249.300000000","ask_px":"251.900000000","bid_sz":1000,"ask_sz":1000,"bid_ct":1,"ask_ct":1},{"bid_px":"247.150000000","ask_px":"253.650000000","bid_sz":400,"ask_sz":400,"bid_ct":1,"ask_ct":1},{"bid_px":"235.000000000","ask_px":"260.000000000","bid_sz":100,"ask_sz":48,"bid_ct":1,"ask_ct":1},{"bid_px":"220.000000000","ask_px":"265.000000000","bid_sz":1,"ask_sz":1,"bid_ct":1,"ask_ct":1},{"bid_px":"214.000000000","ask_px":"275.000000000","bid_sz":5,"ask_sz":4,"bid_ct":1,"ask_ct":1},{"bid_px":"213.000000000","ask_px":"960.000000000","bid_sz":1,"ask_sz":25,"bid_ct":1,"ask_ct":1},{"bid_px":"203.000000000","ask_px":null,"bid_sz":2,"ask_sz":0,"bid_ct":1,"ask_ct":0},{"bid_px":"170.000000000","ask_px":null,"bid_sz":3,"ask_sz":0,"bid_ct":1,"ask_ct":0}],"symbol":"TSLA"}
{"ts_recv":"2024-11-01T08:00:04.497617147Z","hd":{"ts_event":"2024-11-01T08:00:04.497451271Z","rtype":10,"publisher_id":2,"instrument_id":16244},"action":"C","side":"A","depth":1,"price":"250.960000000","size":50,"flags":130,"ts_in_delta":165876,"sequence":295704,"levels":[{"bid_px":"249.820000000","ask_px":"250.680000000","bid_sz":100,"ask_sz":100,"bid_ct":1,"ask_ct":1},{"bid_px":"249.600000000","ask_px":"250.960000000","bid_sz":1000,"ask_sz":50,"bid_ct":1,"ask_ct":1},{"bid_px":"249.300000000","ask_px":"251.900000000","bid_sz":1000,"ask_sz":1000,"bid_ct":1,"ask_ct":1},{"bid_px":"247.150000000","ask_px":"253.650000000","bid_sz":400,"ask_sz":400,"bid_ct":1,"ask_ct":1},{"bid_px":"235.000000000","ask_px":"260.000000000","bid_sz":100,"ask_sz":48,"bid_ct":1,"ask_ct":1},{"bid_px":"220.000000000","ask_px":"265.000000000","bid_sz":1,"ask_sz":1,"bid_ct":1,"ask_ct":1},{"bid_px":"214.000000000","ask_px":"275.000000000","bid_sz":5,"ask_sz":4,"bid_ct":1,"ask_ct":1},{"bid_px":"213.000000000","ask_px":"960.000000000","bid_sz":1,"ask_sz":25,"bid_ct":1,"ask_ct":1},{"bid_px":"203.000000000","ask_px":null,"bid_sz":2,"ask_sz":0,"bid_ct":1,"ask_ct":0},{"bid_px":"170.000000000","ask_px":null,"bid_sz":3,"ask_sz":0,"bid_ct":1,"ask_ct":0}],"symbol":"TSLA"}
{"ts_recv":"2024-11-01T08:00:04.497637192Z","hd":{"ts_event":"2024-11-01T08:00:04.497470818Z","rtype":10,"publisher_id":2,"instrument_id":16244},"action":"A","side":"A","depth":1,"price":"250.750000000","size":50,"flags":130,"ts_in_delta":166374,"sequence":295705,"levels":[{"bid_px":"249.820000000","ask_px":"250.680000000","bid_sz":100,"ask_sz":100,"bid_ct":1,"ask_ct":1},{"bid_px":"249.600000000","ask_px":"250.750000000","bid_sz":1000,"ask_sz":50,"bid_ct":1,"ask_ct":1},{"bid_px":"249.300000000","ask_px":"251.900000000","bid_sz":1000,"ask_sz":1000,"bid_ct":1,"ask_ct":1},{"bid_px":"247.150000000","ask_px":"253.650000000","bid_sz":400,"ask_sz":400,"bid_ct":1,"ask_ct":1},{"bid_px":"235.000000000","ask_px":"260.000000000","bid_sz":100,"ask_sz":48,"bid_ct":1,"ask_ct":1},{"bid_px":"220.000000000","ask_px":"265.000000000","bid_sz":1,"ask_sz":1,"bid_ct":1,"ask_ct":1},{"bid_px":"214.000000000","ask_px":"275.000000000","bid_sz":5,"ask_sz":4,"bid_ct":1,"ask_ct":1},{"bid_px":"213.000000000","ask_px":"960.000000000","bid_sz":1,"ask_sz":25,"bid_ct":1,"ask_ct":1},{"bid_px":"203.000000000","ask_px":null,"bid_sz":2,"ask_sz":0,"bid_ct":1,"ask_ct":0},{"bid_px":"170.000000000","ask_px":null,"bid_sz":3,"ask_sz":0,"bid_ct":1,"ask_ct":0}],"symbol":"TSLA"}
{"ts_recv":"2024-11-01T08:00:04.501706334Z","hd":{"ts_event":"2024-11-01T08:00:04.501540214Z","rtype":10,"publisher_id":2,"instrument_id":16244},"action":"C","side":"B","depth":0,"price":"249.820000000","size":50,"flags":130,"ts_in_delta":166120,"sequence":295725,"levels":[{"bid_px":"249.820000000","ask_px":"250.680000000","bid_sz":50,"ask_sz":100,"bid_ct":1,"ask_ct":1},{"bid_px":"249.600000000","ask_px":"250.750000000","bid_sz":1000,"ask_sz":50,"bid_ct":1,"ask_ct":1},{"bid_px":"249.300000000","ask_px":"251.900000000","bid_sz":1000,"ask_sz":1000,"bid_ct":1,"ask_ct":1},{"bid_px":"247.150000000","ask_px":"253.650000000","bid_sz":400,"ask_sz":400,"bid_ct":1,"ask_ct":1},{"bid_px":"235.000000000","ask_px":"260.000000000","bid_sz":100,"ask_sz":48,"bid_ct":1,"ask_ct":1},{"bid_px":"220.000000000","ask_px":"265.000000000","bid_sz":1,"ask_sz":1,"bid_ct":1,"ask_ct":1},{"bid_px":"214.000000000","ask_px":"275.000000000","bid_sz":5,"ask_sz":4,"bid_ct":1,"ask_ct":1},{"bid_px":"213.000000000","ask_px":"960.000000000","bid_sz":1,"ask_sz":25,"bid_ct":1,"ask_ct":1},{"bid_px":"203.000000000","ask_px":null,"bid_sz":2,"ask_sz":0,"bid_ct":1,"ask_ct":0},{"bid_px":"170.000000000","ask_px":null,"bid_sz":3,"ask_sz":0,"bid_ct":1,"ask_ct":0}],"symbol":"TSLA"}
{"ts_recv":"2024-11-01T08:00:04.514934233Z","hd":{"ts_event":"2024-11-01T08:00:04.514768318Z","rtype":10,"publisher_id":2,"instrument_id":16244},"action":"A","side":"B","depth":8,"price":"211.000000000","size":2,"flags":130,"ts_in_delta":165915,"sequence":295781,"levels":[{"bid_px":"249.820000000","ask_px":"250.680000000","bid_sz":50,"ask_sz":100,"bid_ct":1,"ask_ct":1},{"bid_px":"249.600000000","ask_px":"250.750000000","bid_sz":1000,"ask_sz":50,"bid_ct":1,"ask_ct":1},{"bid_px":"249.300000000","ask_px":"251.900000000","bid_sz":1000,"ask_sz":1000,"bid_ct":1,"ask_ct":1},{"bid_px":"247.150000000","ask_px":"253.650000000","bid_sz":400,"ask_sz":400,"bid_ct":1,"ask_ct":1},{"bid_px":"235.000000000","ask_px":"260.000000000","bid_sz":100,"ask_sz":48,"bid_ct":1,"ask_ct":1},{"bid_px":"220.000000000","ask_px":"265.000000000","bid_sz":1,"ask_sz":1,"bid_ct":1,"ask_ct":1},{"bid_px":"214.000000000","ask_px":"275.000000000","bid_sz":5,"ask_sz":4,"bid_ct":1,"ask_ct":1},{"bid_px":"213.000000000","ask_px":"960.000000000","bid_sz":1,"ask_sz":25,"bid_ct":1,"ask_ct":1},{"bid_px":"211.000000000","ask_px":null,"bid_sz":2,"ask_sz":0,"bid_ct":1,"ask_ct":0},{"bid_px":"203.000000000","ask_px":null,"bid_sz":2,"ask_sz":0,"bid_ct":1,"ask_ct":0}],"symbol":"TSLA"}
{"ts_recv":"2024-11-01T08:00:04.523349487Z","hd":{"ts_event":"2024-11-01T08:00:04.523183346Z","rtype":10,"publisher_id":2,"instrument_id":11667},"action":"C","side":"A","depth":1,"price":"136.100000000","size":1000,"flags":130,"ts_in_delta":166141,"sequence":295798,"levels":[{"bid_px":"134.560000000","ask_px":"135.300000000","bid_sz":100,"ask_sz":1000,"bid_ct":1,"ask_ct":1},{"bid_px":"134.410000000","ask_px":"137.680000000","bid_sz":1,"ask_sz":500,"bid_ct":1,"ask_ct":1},{"bid_px":"134.210000000","ask_px":"138.870000000","bid_sz":20,"ask_sz":1000,"bid_ct":1,"ask_ct":2},{"bid_px":"133.100000000","ask_px":"140.740000000","bid_sz":1000,"ask_sz":100,"bid_ct":1,"ask_ct":1},{"bid_px":"132.000000000","ask_px":"140.880000000","bid_sz":71,"ask_sz":1000,"bid_ct":2,"ask_ct":2},{"bid_px":"129.050000000","ask_px":"143.000000000","bid_sz":500,"ask_sz":1,"bid_ct":1,"ask_ct":1},{"bid_px":"129.000000000","ask_px":"143.690000000","bid_sz":10,"ask_sz":500,"bid_ct":1,"ask_ct":1},{"bid_px":"128.470000000","ask_px":"146.510000000","bid_sz":500,"ask_sz":5,"bid_ct":1,"ask_ct":1},{"bid_px":"127.680000000","ask_px":"148.000000000","bid_sz":30,"ask_sz":5,"bid_ct":1,"ask_ct":1},{"bid_px":"127.500000000","ask_px":null,"bid_sz":5,"ask_sz":0,"bid_ct":1,"ask_ct":0}],"symbol":"NVDA"}
{"ts_recv":"2024-11-01T08:00:04.534120949Z","hd":{"ts_event":"2024-11-01T08:00:04.533954375Z","rtype":10,"publisher_id":2,"instrument_id":11667},"action":"A","side":"A","depth":1,"price":"136.200000000","size":1000,"flags":130,"ts_in_delta":166574,"sequence":295865,"levels":[{"bid_px":"134.560000000","ask_px":"135.300000000","bid_sz":100,"ask_sz":1000,"bid_ct":1,"ask_ct":1},{"bid_px":"134.410000000","ask_px":"136.200000000","bid_sz":1,"ask_sz":1000,"bid_ct":1,"ask_ct":1},{"bid_px":"134.210000000","ask_px":"137.680000000","bid_sz":20,"ask_sz":500,"bid_ct":1,"ask_ct":1},{"bid_px":"133.100000000","ask_px":"138.870000000","bid_sz":1000,"ask_sz":1000,"bid_ct":1,"ask_ct":2},{"bid_px":"132.000000000","ask_px":"140.740000000","bid_sz":71,"ask_sz":100,"bid_ct":2,"ask_ct":1},{"bid_px":"129.050000000","ask_px":"140.880000000","bid_sz":500,"ask_sz":1000,"bid_ct":1,"ask_ct":2},{"bid_px":"129.000000000","ask_px":"143.000000000","bid_sz":10,"ask_sz":1,"bid_ct":1,"ask_ct":1},{"bid_px":"128.470000000","ask_px":"143.690000000","bid_sz":500,"ask_sz":500,"bid_ct":1,"ask_ct":1},{"bid_px":"127.680000000","ask_px":"146.510000000","bid_sz":30,"ask_sz":5,"bid_ct":1,"ask_ct":1},{"bid_px":"127.500000000","ask_px":"148.000000000","bid_sz":5,"ask_sz":5,"bid_ct":1,"ask_ct":1}],"symbol":"NVDA"}
{"ts_recv":"2024-11-01T08:00:04.596259823Z","hd":{"ts_event":"2024-11-01T08:00:04.596093879Z","rtype":10,"publisher_id":2,"instrument_id":11667},"action":"A","side":"A","depth":9,"price":"148.000000000","size":100,"flags":130,"ts_in_delta":165944,"sequence":296072,"levels":[{"bid_px":"134.560000000","ask_px":"135.300000000","bid_sz":100,"ask_sz":1000,"bid_ct":1,"ask_ct":1},{"bid_px":"134.410000000","ask_px":"136.200000000","bid_sz":1,"ask_sz":1000,"bid_ct":1,"ask_ct":1},{"bid_px":"134.210000000","ask_px":"137.680000000","bid_sz":20,"ask_sz":500,"bid_ct":1,"ask_ct":1},{"bid_px":"133.100000000","ask_px":"138.870000000","bid_sz":1000,"ask_sz":1000,"bid_ct":1,"ask_ct":2},{"bid_px":"132.000000000","ask_px":"140.740000000","bid_sz":71,"ask_sz":100,"bid_ct":2,"ask_ct":1},{"bid_px":"129.050000000","ask_px":"140.880000000","bid_sz":500,"ask_sz":1000,"bid_ct":1,"ask_ct":2},{"bid_px":"129.000000000","ask_px":"143.000000000","bid_sz":10,"ask_sz":1,"bid_ct":1,"ask_ct":1},{"bid_px":"128.470000000","ask_px":"143.690000000","bid_sz":500,"ask_sz":500,"bid_ct":1,"ask_ct":1},{"bid_px":"127.680000000","ask_px":"146.510000000","bid_sz":30,"ask_sz":5,"bid_ct":1,"ask_ct":1},{"bid_px":"127.500000000","ask_px":"148.000000000","bid_sz":5,"ask_sz":105,"bid_ct":1,"ask_ct":2}],"symbol":"NVDA"}
{"ts_recv":"2024-11-01T08:00:04.724128638Z","hd":{"ts_event":"2024-11-01T08:00:04.723962496Z","rtype":10,"publisher_id":2,"instrument_id":16244},"action":"A","side":"B","depth":7,"price":"213.650000000","size":3,"flags":130,"ts_in_delta":166142,"sequence":296410,"levels":[{"bid_px":"249.820000000","ask_px":"250.680000000","bid_sz":50,"ask_sz":100,"bid_ct":1,"ask_ct":1},{"bid_px":"249.600000000","ask_px":"250.750000000","bid_sz":1000,"ask_sz":50,"bid_ct":1,"ask_ct":1},{"bid_px":"249.300000000","ask_px":"251.900000000","bid_sz":1000,"ask_sz":1000,"bid_ct":1,"ask_ct":1},{"bid_px":"247.150000000","ask_px":"253.650000000","bid_sz":400,"ask_sz":400,"bid_ct":1,"ask_ct":1},{"bid_px":"235.000000000","ask_px":"260.000000000","bid_sz":100,"ask_sz":48,"bid_ct":1,"ask_ct":1},{"bid_px":"220.000000000","ask_px":"265.000000000","bid_sz":1,"ask_sz":1,"bid_ct":1,"ask_ct":1},{"bid_px":"214.000000000","ask_px":"275.000000000","bid_sz":5,"ask_sz":4,"bid_ct":1,"ask_ct":1},{"bid_px":"213.650000000","ask_px":"960.000000000","bid_sz":3,"ask_sz":25,"bid_ct":1,"ask_ct":1},{"bid_px":"213.000000000","ask_px":null,"bid_sz":1,"ask_sz":0,"bid_ct":1,"ask_ct":0},{"bid_px":"211.000000000","ask_px":null,"bid_sz":2,"ask_sz":0,"bid_ct":1,"ask_ct":0}],"symbol":"TSLA"}
{"ts_recv":"2024-11-01T08:00:04.836981943Z","hd":{"ts_event":"2024-11-01T08:00:04.836815700Z","rtype":10,"publisher_id":2,"instrument_id":16244},"action":"A","side":"A","depth":5,"price":"264.940000000","size":7,"flags":130,"ts_in_delta":166243,"sequence":296857,"levels":[{"bid_px":"249.820000000","ask_px":"250.680000000","bid_sz":50,"ask_sz":100,"bid_ct":1,"ask_ct":1},{"bid_px":"249.600000000","ask_px":"250.750000000","bid_sz":1000,"ask_sz":50,"bid_ct":1,"ask_ct":1},{"bid_px":"249.300000000","ask_px":"251.900000000","bid_sz":1000,"ask_sz":1000,"bid_ct":1,"ask_ct":1},{"bid_px":"247.150000000","ask_px":"253.650000000","bid_sz":400,"ask_sz":400,"bid_ct":1,"ask_ct":1},{"bid_px":"235.000000000","ask_px":"260.000000000","bid_sz":100,"ask_sz":48,"bid_ct":1,"ask_ct":1},{"bid_px":"220.000000000","ask_px":"264.940000000","bid_sz":1,"ask_sz":7,"bid_ct":1,"ask_ct":1},{"bid_px":"214.000000000","ask_px":"265.000000000","bid_sz":5,"ask_sz":1,"bid_ct":1,"ask_ct":1},{"bid_px":"213.650000000","ask_px":"275.000000000","bid_sz":3,"ask_sz":4,"bid_ct":1,"ask_ct":1},{"bid_px":"213.000000000","ask_px":"960.000000000","bid_sz":1,"ask_sz":25,"bid_ct":1,"ask_ct":1},{"bid_px":"211.000000000","ask_px":null,"bid_sz":2,"ask_sz":0,"bid_ct":1,"ask_ct":0}],"symbol":"TSLA"}
{"ts_recv":"2024-11-01T08:00:04.896524829Z","hd":{"ts_event":"2024-11-01T08:00:04.896358681Z","rtype":10,"publisher_id":2,"instrument_id":10888},"action":"A","side":"B","depth":0,"price":"410.000000000","size":1,"flags":130,"ts_in_delta":166148,"sequence":297030,"levels":[{"bid_px":"410.000000000","ask_px":"415.070000000","bid_sz":1,"ask_sz":246,"bid_ct":1,"ask_ct":1},{"bid_px":"404.410000000","ask_px":"420.000000000","bid_sz":246,"ask_sz":3,"bid_ct":1,"ask_ct":1},{"bid_px":"398.000000000","ask_px":"468.000000000","bid_sz":5,"ask_sz":65,"bid_ct":1,"ask_ct":1},{"bid_px":null,"ask_px":null,"bid_sz":0,"ask_sz":0,"bid_ct":0,"ask_ct":0},{"bid_px":null,"ask_px":null,"bid_sz":0,"ask_sz":0,"bid_ct":0,"ask_ct":0},{"bid_px":null,"ask_px":null,"bid_sz":0,"ask_sz":0,"bid_ct":0,"ask_ct":0},{"bid_px":null,"ask_px":null,"bid_sz":0,"ask_sz":0,"bid_ct":0,"ask_ct":0},{"bid_px":null,"ask_px":null,"bid_sz":0,"ask_sz":0,"bid_ct":0,"ask_ct":0},{"bid_px":null,"ask_px":null,"bid_sz":0,"ask_sz":0,"bid_ct":0,"ask_ct":0},{"bid_px":null,"ask_px":null,"bid_sz":0,"ask_sz":0,"bid_ct":0,"ask_ct":0}],"symbol":"MSFT"}
{"ts_recv":"2024-11-01T08:00:05.080861532Z","hd":{"ts_event":"2024-11-01T08:00:05.080695459Z","rtype":10,"publisher_id":2,"instrument_id":11667},"action":"A","side":"B","depth":5,"price":"130.000000000","size":5,"flags":130,"ts_in_delta":166073,"sequence":297402,"levels":[{"bid_px":"134.560000000","ask_px":"135.300000000","bid_sz":100,"ask_sz":1000,"bid_ct":1,"ask_ct":1},{"bid_px":"134.410000000","ask_px":"136.200000000","bid_sz":1,"ask_sz":1000,"bid_ct":1,"ask_ct":1},{"bid_px":"134.210000000","ask_px":"137.680000000","bid_sz":20,"ask_sz":500,"bid_ct":1,"ask_ct":1},{"bid_px":"133.100000000","ask_px":"138.870000000","bid_sz":1000,"ask_sz":1000,"bid_ct":1,"ask_ct":2},{"bid_px":"132.000000000","ask_px":"140.740000000","bid_sz":71,"ask_sz":100,"bid_ct":2,"ask_ct":1},{"bid_px":"130.000000000","ask_px":"140.880000000","bid_sz":5,"ask_sz":1000,"bid_ct":1,"ask_ct":2},{"bid_px":"129.050000000","ask_px":"143.000000000","bid_sz":500,"ask_sz":1,"bid_ct":1,"ask_ct":1},{"bid_px":"129.000000000","ask_px":"143.690000000","bid_sz":10,"ask_sz":500,"bid_ct":1,"ask_ct":1},{"bid_px":"128.470000000","ask_px":"146.510000000","bid_sz":500,"ask_sz":5,"bid_ct":1,"ask_ct":1},{"bid_px":"127.680000000","ask_px":"148.000000000","bid_sz":30,"ask_sz":105,"bid_ct":1,"ask_ct":2}],"symbol":"NVDA"}
{"ts_recv":"2024-11-01T08:00:05.125416215Z","hd":{"ts_event":"2024-11-01T08:00:05.125250462Z","rtype":10,"publisher_id":2,"instrument_id":12463},"action":"C","side":"B","depth":0,"price":"163.080000000","size":100,"flags":130,"ts_in_delta":165753,"sequence":297478,"levels":[{"bid_px":null,"ask_px":null,"bid_sz":0,"ask_sz":0,"bid_ct":0,"ask_ct":0},{"bid_px":null,"ask_px":null,"bid_sz":0,"ask_sz":0,"bid_ct":0,"ask_ct":0},{"bid_px":null,"ask_px":null,"bid_sz":0,"ask_sz":0,"bid_ct":0,"ask_ct":0},{"bid_px":null,"ask_px":null,"bid_sz":0,"ask_sz":0,"bid_ct":0,"ask_ct":0},{"bid_px":null,"ask_px":null,"bid_sz":0,"ask_sz":0,"bid_ct":0,"ask_ct":0},{"bid_px":null,"ask_px":null,"bid_sz":0,"ask_sz":0,"bid_ct":0,"ask_ct":0},{"bid_px":null,"ask_px":null,"bid_sz":0,"ask_sz":0,"bid_ct":0,"ask_ct":0},{"bid_px":null,"ask_px":null,"bid_sz":0,"ask_sz":0,"bid_ct":0,"ask_ct":0},{"bid_px":null,"ask_px":null,"bid_sz":0,"ask_sz":0,"bid_ct":0,"ask_ct":0},{"bid_px":null,"ask_px":null,"bid_sz":0,"ask_sz":0,"bid_ct":0,"ask_ct":0}],"symbol":"PEP"}
{"ts_recv":"2024-11-01T08:00:05.150130228Z","hd":{"ts_event":"2024-11-01T08:00:05.149964125Z","rtype":10,"publisher_id":2,"instrument_id":10888},"action":"A","side":"B","depth":1,"price":"408.960000000","size":5,"flags":130,"ts_in_delta":166103,"sequence":297501,"levels":[{"bid_px":"410.000000000","ask_px":"415.070000000","bid_sz":1,"ask_sz":246,"bid_ct":1,"ask_ct":1},{"bid_px":"408.960000000","ask_px":"420.000000000","bid_sz":5,"ask_sz":3,"bid_ct":1,"ask_ct":1},{"bid_px":"404.410000000","ask_px":"468.000000000","bid_sz":246,"ask_sz":65,"bid_ct":1,"ask_ct":1},{"bid_px":"398.000000000","ask_px":null,"bid_sz":5,"ask_sz":0,"bid_ct":1,"ask_ct":0},{"bid_px":null,"ask_px":null,"bid_sz":0,"ask_sz":0,"bid_ct":0,"ask_ct":0},{"bid_px":null,"ask_px":null,"bid_sz":0,"ask_sz":0,"bid_ct":0,"ask_ct":0},{"bid_px":null,"ask_px":null,"bid_sz":0,"ask_sz":0,"bid_ct":0,"ask_ct":0},{"bid_px":null,"ask_px":null,"bid_sz":0,"ask_sz":0,"bid_ct":0,"ask_ct":0},{"bid_px":null,"ask_px":null,"bid_sz":0,"ask_sz":0,"bid_ct":0,"ask_ct":0},{"bid_px":null,"ask_px":null,"bid_sz":0,"ask_sz":0,"bid_ct":0,"ask_ct":0}],"symbol":"MSFT"}
