ts_recv,ts_event,rtype,publisher_id,instrument_id,action,side,depth,price,size,flags,ts_in_delta,sequence,bid_px_00,ask_px_00,bid_sz_00,ask_sz_00,bid_ct_00,ask_ct_00,bid_px_01,ask_px_01,bid_sz_01,ask_sz_01,bid_ct_01,ask_ct_01,bid_px_02,ask_px_02,bid_sz_02,ask_sz_02,bid_ct_02,ask_ct_02,bid_px_03,ask_px_03,bid_sz_03,ask_sz_03,bid_ct_03,ask_ct_03,bid_px_04,ask_px_04,bid_sz_04,ask_sz_04,bid_ct_04,ask_ct_04,bid_px_05,ask_px_05,bid_sz_05,ask_sz_05,bid_ct_05,ask_ct_05,bid_px_06,ask_px_06,bid_sz_06,ask_sz_06,bid_ct_06,ask_ct_06,bid_px_07,ask_px_07,bid_sz_07,ask_sz_07,bid_ct_07,ask_ct_07,bid_px_08,ask_px_08,bid_sz_08,ask_sz_08,bid_ct_08,ask_ct_08,bid_px_09,ask_px_09,bid_sz_09,ask_sz_09,bid_ct_09,ask_ct_09,symbol
2024-11-01T08:00:00.013053287Z,2024-11-01T08:00:00.012886460Z,10,2,16244,A,N,0,235.000000000,20000,130,166827,284484,235.000000000,,20000,0,1,0,,,0,0,0,0,,,0,0,0,0,,,0,0,0,0,,,0,0,0,0,,,0,0,0,0,,,0,0,0,0,,,0,0,0,0,,,0,0,0,0,,,0,0,0,0,TSLA
2024-11-01T08:00:00.014680653Z,2024-11-01T08:00:00.014514561Z,10,2,11667,A,N,0,129.050000000,500,130,166092,284547,129.050000000,,500,0,1,0,,,0,0,0,0,,,0,0,0,0,,,0,0,0,0,,,0,0,0,0,,,0,0,0,0,,,0,0,0,0,,,0,0,0,0,,,0,0,0,0,,,0,0,0,0,NVDA
2024-11-01T08:00:00.015308076Z,2024-11-01T08:00:00.015141714Z,10,2,11667,A,A,0,143.690000000,500,130,166362,284560,129.050000000,143.690000000,500,500,1,1,,,0,0,0,0,,,0,0,0,0,,,0,0,0,0,,,0,0,0,0,,,0,0,0,0,,,0,0,0,0,,,0,0,0,0,,,0,0,0,0,,,0,0,0,0,NVDA
2024-11-01T08:00:00.031749638Z,2024-11-01T08:00:00.031567530Z,10,2,11667,A,B,1,128.470000000,500,130,182108,284618,129.050000000,143.690000000,500,500,1,1,128.470000000,,500,0,1,0,,,0,0,0,0,,,0,0,0,0,,,0,0,0,0,,,0,0,0,0,,,0,0,0,0,,,0,0,0,0,,,0,0,0,0,,,0,0,0,0,NVDA
2024-11-01T08:00:00.031763477Z,2024-11-01T08:00:00.031584979Z,10,2,10888,A,N,0,415.070000000,246,130,178498,284620,,415.070000000,0,246,0,1,,,0,0,0,0,,,0,0,0,0,,,0,0,0,0,,,0,0,0,0,,,0,0,0,0,,,0,0,0,0,,,0,0,0,0,,,0,0,0,0,,,0,0,0,0,MSFT
2024-11-01T08:00:00.031886181Z,2024-11-01T08:00:00.031701605Z,10,2,16244,A,A,0,960.000000000,25,130,184576,284655,235.000000000,960.000000000,20000,25,1,1,,,0,0,0,0,,,0,0,0,0,,,0,0,0,0,,,0,0,0,0,,,0,0,0,0,,,0,0,0,0,,,0,0,0,0,,,0,0,0,0,,,0,0,0,0,TSLA
2024-11-01T08:00:00.032200260Z,2024-11-01T08:00:00.032016036Z,10,2,38,A,N,0,217.000000000,1525,130,184224,284703,217.000000000,,1525,0,1,0,,,0,0,0,0,,,0,0,0,0,,,0,0,0,0,,,0,0,0,0,,,0,0,0,0,,,0,0,0,0,,,0,0,0,0,,,0,0,0,0,,,0,0,0,0,AAPL
2024-11-01T08:00:00.039818091Z,2024-11-01T08:00:00.039594104Z,10,2,10888,A,B,0,404.410000000,246,130,223987,284818,404.410000000,415.070000000,246,246,1,1,,,0,0,0,0,,,0,0,0,0,,,0,0,0,0,,,0,0,0,0,,,0,0,0,0,,,0,0,0,0,,,0,0,0,0,,,0,0,0,0,,,0,0,0,0,MSFT
2024-11-01T08:00:00.039965141Z,2024-11-01T08:00:00.039798792Z,10,2,11667,A,A,0,138.870000000,500,130,166349,284824,129.050000000,138.870000000,500,500,1,1,128.470000000,143.690000000,500,500,1,1,,,0,0,0,0,,,0,0,0,0,,,0,0,0,0,,,0,0,0,0,,,0,0,0,0,,,0,0,0,0,,,0,0,0,0,,,0,0,0,0,NVDA
2024-11-01T08:00:00.039976165Z,2024-11-01T08:00:00.039810019Z,10,2,11667,A,A,1,140.880000000,500,130,166146,284825,129.050000000,138.870000000,500,500,1,1,128.470000000,140.880000000,500,500,1,1,,143.690000000,0,500,0,1,,,0,0,0,0,,,0,0,0,0,,,0,0,0,0,,,0,0,0,0,,,0,0,0,0,,,0,0,0,0,,,0,0,0,0,NVDA
2024-11-01T08:00:00.039986579Z,2024-11-01T08:00:00.039820200Z,10,2,11667,A,A,0,138.870000000,500,130,166379,284826,129.050000000,138.870000000,500,1000,1,2,128.470000000,140.880000000,500,500,1,1,,143.690000000,0,500,0,1,,,0,0,0,0,,,0,0,0,0,,,0,0,0,0,,,0,0,0,0,,,0,0,0,0,,,0,0,0,0,,,0,0,0,0,NVDA
2024-11-01T08:00:00.040086697Z,2024-11-01T08:00:00.039920398Z,10,2,11667,A,A,0,137.680000000,500,130,166299,284836,129.050000000,137.680000000,500,500,1,1,128.470000000,138.870000000,500,1000,1,2,,140.880000000,0,500,0,1,,143.690000000,0,500,0,1,,,0,0,0,0,,,0,0,0,0,,,0,0,0,0,,,0,0,0,0,,,0,0,0,0,,,0,0,0,0,NVDA
2024-11-01T08:00:00.040266355Z,2024-11-01T08:00:00.040100286Z,10,2,11667,A,A,2,140.880000000,500,130,166069,284851,129.050000000,137.680000000,500,500,1,1,128.470000000,138.870000000,500,1000,1,2,,140.880000000,0,1000,0,2,,143.690000000,0,500,0,1,,,0,0,0,0,,,0,0,0,0,,,0,0,0,0,,,0,0,0,0,,,0,0,0,0,,,0,0,0,0,NVDA
2024-11-01T08:00:00.045329777Z,2024-11-01T08:00:00.045163077Z,10,2,17709,A,N,0,118.250000000,33,130,166700,285160,,118.250000000,0,33,0,1,,,0,0,0,0,,,0,0,0,0,,,0,0,0,0,,,0,0,0,0,,,0,0,0,0,,,0,0,0,0,,,0,0,0,0,,,0,0,0,0,,,0,0,0,0,XOM
2024-11-01T08:00:00.136377397Z,2024-11-01T08:00:00.136210914Z,10,2,16244,A,A,0,251.050000000,100,130,166483,286141,235.000000000,251.050000000,20000,100,1,1,,960.000000000,0,25,0,1,,,0,0,0,0,,,0,0,0,0,,,0,0,0,0,,,0,0,0,0,,,0,0,0,0,,,0,0,0,0,,,0,0,0,0,,,0,0,0,0,TSLA
2024-11-01T08:00:00.164660660Z,2024-11-01T08:00:00.164494591Z,10,2,11667,A,B,2,127.000000000,20,130,166069,286324,129.050000000,137.680000000,500,500,1,1,128.470000000,138.870000000,500,1000,1,2,127.000000000,140.880000000,20,1000,1,2,,143.690000000,0,500,0,1,,,0,0,0,0,,,0,0,0,0,,,0,0,0,0,,,0,0,0,0,,,0,0,0,0,,,0,0,0,0,NVDA
2024-11-01T08:00:00.164779604Z,2024-11-01T08:00:00.164612923Z,10,2,11667,A,A,4,146.510000000,5,130,166681,286329,129.050000000,137.680000000,500,500,1,1,128.470000000,138.870000000,500,1000,1,2,127.000000000,140.880000000,20,1000,1,2,,143.690000000,0,500,0,1,,146.510000000,0,5,0,1,,,0,0,0,0,,,0,0,0,0,,,0,0,0,0,,,0,0,0,0,,,0,0,0,0,NVDA
2024-11-01T08:00:00.176651949Z,2024-11-01T08:00:00.176486081Z,10,2,16244,C,B,0,235.000000000,20000,130,165868,286384,,251.050000000,0,100,0,1,,960.000000000,0,25,0,1,,,0,0,0,0,,,0,0,0,0,,,0,0,0,0,,,0,0,0,0,,,0,0,0,0,,,0,0,0,0,,,0,0,0,0,,,0,0,0,0,TSLA
2024-11-01T08:00:00.176756781Z,2024-11-01T08:00:00.176590432Z,10,2,16244,A,B,0,235.000000000,100,130,166349,286385,235.000000000,251.050000000,100,100,1,1,,960.000000000,0,25,0,1,,,0,0,0,0,,,0,0,0,0,,,0,0,0,0,,,0,0,0,0,,,0,0,0,0,,,0,0,0,0,,,0,0,0,0,,,0,0,0,0,TSLA
2024-11-01T08:00:00.179242588Z,2024-11-01T08:00:00.179076504Z,10,2,11667,A,B,0,134.780000000,100,130,166084,286417,134.780000000,137.680000000,100,500,1,1,129.050000000,138.870000000,500,1000,1,2,128.470000000,140.880000000,500,1000,1,2,127.000000000,143.690000000,20,500,1,1,,146.510000000,0,5,0,1,,,0,0,0,0,,,0,0,0,0,,,0,0,0,0,,,0,0,0,0,,,0,0,0,0,NVDA
2024-11-01T08:00:00.189970576Z,2024-11-01T08:00:00.189802730Z,10,2,16244,A,A,0,249.520000000,27,130,167846,286452,235.000000000,249.520000000,100,27,1,1,,251.050000000,0,100,0,1,,960.000000000,0,25,0,1,,,0,0,0,0,,,0,0,0,0,,,0,0,0,0,,,0,0,0,0,,,0,0,0,0,,,0,0,0,0,,,0,0,0,0,TSLA
2024-11-01T08:00:00.191482094Z,2024-11-01T08:00:00.191316476Z,10,2,16244,C,A,0,249.520000000,27,130,165618,286454,235.000000000,251.050000000,100,100,1,1,,960.000000000,0,25,0,1,,,0,0,0,0,,,0,0,0,0,,,0,0,0,0,,,0,0,0,0,,,0,0,0,0,,,0,0,0,0,,,0,0,0,0,,,0,0,0,0,TSLA
2024-11-01T08:00:00.191557126Z,2024-11-01T08:00:00.191390836Z,10,2,16244,A,B,0,250.590000000,100,130,166290,286455,250.590000000,251.050000000,100,100,1,1,235.000000000,960.000000000,100,25,1,1,,,0,0,0,0,,,0,0,0,0,,,0,0,0,0,,,0,0,0,0,,,0,0,0,0,,,0,0,0,0,,,0,0,0,0,,,0,0,0,0,TSLA
2024-11-01T08:00:00.191885779Z,2024-11-01T08:00:00.191719300Z,10,2,16244,A,B,1,249.240000000,27,130,166479,286457,250.590000000,251.050000000,100,100,1,1,249.240000000,960.000000000,27,25,1,1,235.000000000,,100,0,1,0,,,0,0,0,0,,,0,0,0,0,,,0,0,0,0,,,0,0,0,0,,,0,0,0,0,,,0,0,0,0,,,0,0,0,0,TSLA
2024-11-01T08:00:00.191900223Z,2024-11-01T08:00:00.191734501Z,10,2,16244,C,B,1,249.240000000,27,130,165722,286458,250.590000000,251.050000000,100,100,1,1,235.000000000,960.000000000,100,25,1,1,,,0,0,0,0,,,0,0,0,0,,,0,0,0,0,,,0,0,0,0,,,0,0,0,0,,,0,0,0,0,,,0,0,0,0,,,0,0,0,0,TSLA
2024-11-01T08:00:00.191986130Z,2024-11-01T08:00:00.191819920Z,10,2,16244,A,B,1,249.890000000,27,130,166210,286459,250.590000000,251.050000000,100,100,1,1,249.890000000,960.000000000,27,25,1,1,235.000000000,,100,0,1,0,,,0,0,0,0,,,0,0,0,0,,,0,0,0,0,,,0,0,0,0,,,0,0,0,0,,,0,0,0,0,,,0,0,0,0,TSLA
2024-11-01T08:00:00.193671303Z,2024-11-01T08:00:00.193504306Z,10,2,11667,A,A,2,140.740000000,100,130,166997,286474,134.780000000,137.680000000,100,500,1,1,129.050000000,138.870000000,500,1000,1,2,128.470000000,140.740000000,500,100,1,1,127.000000000,140.880000000,20,1000,1,2,,143.690000000,0,500,0,1,,146.510000000,0,5,0,1,,,0,0,0,0,,,0,0,0,0,,,0,0,0,0,,,0,0,0,0,NVDA
2024-11-01T08:00:00.196977431Z,2024-11-01T08:00:00.196811568Z,10,2,16244,C,A,0,251.050000000,100,130,165863,286485,250.590000000,960.000000000,100,25,1,1,249.890000000,,27,0,1,0,235.000000000,,100,0,1,0,,,0,0,0,0,,,0,0,0,0,,,0,0,0,0,,,0,0,0,0,,,0,0,0,0,,,0,0,0,0,,,0,0,0,0,TSLA
2024-11-01T08:00:00.196992070Z,2024-11-01T08:00:00.196825881Z,10,2,16244,A,A,0,251.100000000,100,130,166189,286486,250.590000000,251.100000000,100,100,1,1,249.890000000,960.000000000,27,25,1,1,235.000000000,,100,0,1,0,,,0,0,0,0,,,0,0,0,0,,,0,0,0,0,,,0,0,0,0,,,0,0,0,0,,,0,0,0,0,,,0,0,0,0,TSLA
2024-11-01T08:00:00.197233272Z,2024-11-01T08:00:00.197067720Z,10,2,16244,C,A,0,251.100000000,100,130,165552,286487,250.590000000,960.000000000,100,25,1,1,249.890000000,,27,0,1,0,235.000000000,,100,0,1,0,,,0,0,0,0,,,0,0,0,0,,,0,0,0,0,,,0,0,0,0,,,0,0,0,0,,,0,0,0,0,,,0,0,0,0,TSLA
2024-11-01T08:00:00.197246429Z,2024-11-01T08:00:00.197080392Z,10,2,16244,A,A,0,251.540000000,100,130,166037,286488,250.590000000,251.540000000,100,100,1,1,249.890000000,960.000000000,27,25,1,1,235.000000000,,100,0,1,0,,,0,0,0,0,,,0,0,0,0,,,0,0,0,0,,,0,0,0,0,,,0,0,0,0,,,0,0,0,0,,,0,0,0,0,TSLA
2024-11-01T08:00:00.231884577Z,2024-11-01T08:00:00.231718811Z,10,2,11667,C,B,0,134.780000000,100,130,165766,286651,129.050000000,137.680000000,500,500,1,1,128.470000000,138.870000000,500,1000,1,2,127.000000000,140.740000000,20,100,1,1,,140.880000000,0,1000,0,2,,143.690000000,0,500,0,1,,146.510000000,0,5,0,1,,,0,0,0,0,,,0,0,0,0,,,0,0,0,0,,,0,0,0,0,NVDA
2024-11-01T08:00:00.232703765Z,2024-11-01T08:00:00.232536537Z,10,2,11667,A,B,0,134.580000000,100,130,167228,286652,134.580000000,137.680000000,100,500,1,1,129.050000000,138.870000000,500,1000,1,2,128.470000000,140.740000000,500,100,1,1,127.000000000,140.880000000,20,1000,1,2,,143.690000000,0,500,0,1,,146.510000000,0,5,0,1,,,0,0,0,0,,,0,0,0,0,,,0,0,0,0,,,0,0,0,0,NVDA
2024-11-01T08:00:00.241387465Z,2024-11-01T08:00:00.241220838Z,10,2,16244,A,A,0,251.540000000,100,130,166627,286694,250.590000000,251.540000000,100,200,1,2,249.890000000,960.000000000,27,25,1,1,235.000000000,,100,0,1,0,,,0,0,0,0,,,0,0,0,0,,,0,0,0,0,,,0,0,0,0,,,0,0,0,0,,,0,0,0,0,,,0,0,0,0,TSLA
2024-11-01T08:00:00.281366214Z,2024-11-01T08:00:00.281200406Z,10,2,17709,C,A,0,118.250000000,33,130,165808,286902,,,0,0,0,0,,,0,0,0,0,,,0,0,0,0,,,0,0,0,0,,,0,0,0,0,,,0,0,0,0,,,0,0,0,0,,,0,0,0,0,,,0,0,0,0,,,0,0,0,0,XOM
2024-11-01T08:00:00.301168858Z,2024-11-01T08:00:00.301003128Z,10,2,16244,C,A,0,251.540000000,100,130,165730,287040,250.590000000,251.540000000,100,100,1,1,249.890000000,960.000000000,27,25,1,1,235.000000000,,100,0,1,0,,,0,0,0,0,,,0,0,0,0,,,0,0,0,0,,,0,0,0,0,,,0,0,0,0,,,0,0,0,0,,,0,0,0,0,TSLA
2024-11-01T08:00:00.301192443Z,2024-11-01T08:00:00.301026245Z,10,2,16244,A,A,0,251.530000000,200,130,166198,287041,250.590000000,251.530000000,100,200,1,1,249.890000000,960.000000000,27,25,1,1,235.000000000,,100,0,1,0,,,0,0,0,0,,,0,0,0,0,,,0,0,0,0,,,0,0,0,0,,,0,0,0,0,,,0,0,0,0,,,0,0,0,0,TSLA
2024-11-01T08:00:00.316129151Z,2024-11-01T08:00:00.315961115Z,10,2,16244,T,N,0,250.610000000,60,0,168036,287214,250.590000000,251.530000000,100,200,1,1,249.890000000,960.000000000,27,25,1,1,235.000000000,,100,0,1,0,,,0,0,0,0,,,0,0,0,0,,,0,0,0,0,,,0,0,0,0,,,0,0,0,0,,,0,0,0,0,,,0,0,0,0,TSLA
2024-11-01T08:00:00.316129151Z,2024-11-01T08:00:00.315961115Z,10,2,16244,T,A,0,250.590000000,40,130,168036,287215,250.590000000,251.530000000,100,200,1,1,249.890000000,960.000000000,27,25,1,1,235.000000000,,100,0,1,0,,,0,0,0,0,,,0,0,0,0,,,0,0,0,0,,,0,0,0,0,,,0,0,0,0,,,0,0,0,0,,,0,0,0,0,TSLA
2024-11-01T08:00:00.316129151Z,2024-11-01T08:00:00.315961115Z,10,2,16244,C,B,0,250.590000000,40,130,168036,287215,250.590000000,251.530000000,60,200,1,1,249.890000000,960.000000000,27,25,1,1,235.000000000,,100,0,1,0,,,0,0,0,0,,,0,0,0,0,,,0,0,0,0,,,0,0,0,0,,,0,0,0,0,,,0,0,0,0,,,0,0,0,0,TSLA
2024-11-01T08:00:00.316199950Z,2024-11-01T08:00:00.316033983Z,10,2,16244,A,A,0,251.070000000,5,130,165967,287216,250.590000000,251.070000000,60,5,1,1,249.890000000,251.530000000,27,200,1,1,235.000000000,960.000000000,100,25,1,1,,,0,0,0,0,,,0,0,0,0,,,0,0,0,0,,,0,0,0,0,,,0,0,0,0,,,0,0,0,0,,,0,0,0,0,TSLA
2024-11-01T08:00:00.316243164Z,2024-11-01T08:00:00.316076612Z,10,2,16244,A,A,1,251.350000000,1,130,166552,287217,250.590000000,251.070000000,60,5,1,1,249.890000000,251.350000000,27,1,1,1,235.000000000,251.530000000,100,200,1,1,,960.000000000,0,25,0,1,,,0,0,0,0,,,0,0,0,0,,,0,0,0,0,,,0,0,0,0,,,0,0,0,0,,,0,0,0,0,TSLA
2024-11-01T08:00:00.318804188Z,2024-11-01T08:00:00.318637776Z,10,2,16244,C,A,0,251.070000000,5,130,166412,287233,250.590000000,251.350000000,60,1,1,1,249.890000000,251.530000000,27,200,1,1,235.000000000,960.000000000,100,25,1,1,,,0,0,0,0,,,0,0,0,0,,,0,0,0,0,,,0,0,0,0,,,0,0,0,0,,,0,0,0,0,,,0,0,0,0,TSLA
2024-11-01T08:00:00.323474524Z,2024-11-01T08:00:00.323308484Z,10,2,38,A,A,0,234.000000000,20,130,166040,287272,217.000000000,234.000000000,1525,20,1,1,,,0,0,0,0,,,0,0,0,0,,,0,0,0,0,,,0,0,0,0,,,0,0,0,0,,,0,0,0,0,,,0,0,0,0,,,0,0,0,0,,,0,0,0,0,AAPL
2024-11-01T08:00:00.342977977Z,2024-11-01T08:00:00.342811821Z,10,2,38,A,A,0,224.400000000,1000,130,166156,287323,217.000000000,224.400000000,1525,1000,1,1,,234.000000000,0,20,0,1,,,0,0,0,0,,,0,0,0,0,,,0,0,0,0,,,0,0,0,0,,,0,0,0,0,,,0,0,0,0,,,0,0,0,0,,,0,0,0,0,AAPL
2024-11-01T08:00:00.342981520Z,2024-11-01T08:00:00.342815351Z,10,2,38,A,B,0,221.200000000,1000,130,166169,287324,221.200000000,224.400000000,1000,1000,1,1,217.000000000,234.000000000,1525,20,1,1,,,0,0,0,0,,,0,0,0,0,,,0,0,0,0,,,0,0,0,0,,,0,0,0,0,,,0,0,0,0,,,0,0,0,0,,,0,0,0,0,AAPL
2024-11-01T08:00:00.366635346Z,2024-11-01T08:00:00.366469191Z,10,2,11667,A,B,0,134.580000000,100,130,166155,287375,134.580000000,137.680000000,200,500,2,1,129.050000000,138.870000000,500,1000,1,2,128.470000000,140.740000000,500,100,1,1,127.000000000,140.880000000,20,1000,1,2,,143.690000000,0,500,0,1,,146.510000000,0,5,0,1,,,0,0,0,0,,,0,0,0,0,,,0,0,0,0,,,0,0,0,0,NVDA
2024-11-01T08:00:00.369440196Z,2024-11-01T08:00:00.369273960Z,10,2,16244,A,A,1,251.520000000,200,130,166236,287383,250.590000000,251.350000000,60,1,1,1,249.890000000,251.520000000,27,200,1,1,235.000000000,960.000000000,100,25,1,1,,,0,0,0,0,,,0,0,0,0,,,0,0,0,0,,,0,0,0,0,,,0,0,0,0,,,0,0,0,0,,,0,0,0,0,TSLA
2024-11-01T08:00:00.387442715Z,2024-11-01T08:00:00.387276086Z,10,2,16244,A,A,0,251.120000000,100,130,166629,287422,250.590000000,251.120000000,60,100,1,1,249.890000000,251.350000000,27,1,1,1,235.000000000,960.000000000,100,25,1,1,,,0,0,0,0,,,0,0,0,0,,,0,0,0,0,,,0,0,0,0,,,0,0,0,0,,,0,0,0,0,,,0,0,0,0,TSLA
2024-11-01T08:00:00.396884523Z,2024-11-01T08:00:00.396718671Z,10,2,11667,C,B,0,134.580000000,100,130,165852,287445,134.580000000,137.680000000,100,500,1,1,129.050000000,138.870000000,500,1000,1,2,128.470000000,140.740000000,500,100,1,1,127.000000000,140.880000000,20,1000,1,2,,143.690000000,0,500,0,1,,146.510000000,0,5,0,1,,,0,0,0,0,,,0,0,0,0,,,0,0,0,0,,,0,0,0,0,NVDA
2024-11-01T08:00:00.396907044Z,2024-11-01T08:00:00.396740236Z,10,2,11667,A,B,0,134.590000000,200,130,166808,287446,134.590000000,137.680000000,200,500,1,1,129.050000000,138.870000000,500,1000,1,2,128.470000000,140.740000000,500,100,1,1,127.000000000,140.880000000,20,1000,1,2,,143.690000000,0,500,0,1,,146.510000000,0,5,0,1,,,0,0,0,0,,,0,0,0,0,,,0,0,0,0,,,0,0,0,0,NVDA
2024-11-01T08:00:00.431384581Z,2024-11-01T08:00:00.431218708Z,10,2,11667,C,B,0,134.590000000,200,130,165873,287578,129.050000000,137.680000000,500,500,1,1,128.470000000,138.870000000,500,1000,1,2,127.000000000,140.740000000,20,100,1,1,,140.880000000,0,1000,0,2,,143.690000000,0,500,0,1,,146.510000000,0,5,0,1,,,0,0,0,0,,,0,0,0,0,,,0,0,0,0,,,0,0,0,0,NVDA
2024-11-01T08:00:00.431637059Z,2024-11-01T08:00:00.431470344Z,10,2,11667,A,B,0,134.730000000,63,130,166715,287584,134.730000000,137.680000000,63,500,1,1,129.050000000,138.870000000,500,1000,1,2,128.470000000,140.740000000,500,100,1,1,127.000000000,140.880000000,20,1000,1,2,,143.690000000,0,500,0,1,,146.510000000,0,5,0,1,,,0,0,0,0,,,0,0,0,0,,,0,0,0,0,,,0,0,0,0,NVDA
2024-11-01T08:00:00.431648673Z,2024-11-01T08:00:00.431483076Z,10,2,11667,C,B,0,134.730000000,63,130,165597,287585,129.050000000,137.680000000,500,500,1,1,128.470000000,138.870000000,500,1000,1,2,127.000000000,140.740000000,20,100,1,1,,140.880000000,0,1000,0,2,,143.690000000,0,500,0,1,,146.510000000,0,5,0,1,,,0,0,0,0,,,0,0,0,0,,,0,0,0,0,,,0,0,0,0,NVDA
2024-11-01T08:00:00.431682833Z,2024-11-01T08:00:00.431516877Z,10,2,11667,A,B,0,134.630000000,100,130,165956,287586,134.630000000,137.680000000,100,500,1,1,129.050000000,138.870000000,500,1000,1,2,128.470000000,140.740000000,500,100,1,1,127.000000000,140.880000000,20,1000,1,2,,143.690000000,0,500,0,1,,146.510000000,0,5,0,1,,,0,0,0,0,,,0,0,0,0,,,0,0,0,0,,,0,0,0,0,NVDA
2024-11-01T08:00:00.432197000Z,2024-11-01T08:00:00.432030721Z,10,2,16244,C,A,0,251.120000000,100,128,166279,287589,250.590000000,251.350000000,60,1,1,1,249.890000000,960.000000000,27,25,1,1,235.000000000,,100,0,1,0,,,0,0,0,0,,,0,0,0,0,,,0,0,0,0,,,0,0,0,0,,,0,0,0,0,,,0,0,0,0,,,0,0,0,0,TSLA
2024-11-01T08:00:00.432210472Z,2024-11-01T08:00:00.432044433Z,10,2,16244,A,A,0,251.140000000,100,130,166039,287591,250.590000000,251.140000000,60,100,1,1,249.890000000,251.350000000,27,1,1,1,235.000000000,960.000000000,100,25,1,1,,,0,0,0,0,,,0,0,0,0,,,0,0,0,0,,,0,0,0,0,,,0,0,0,0,,,0,0,0,0,,,0,0,0,0,TSLA
2024-11-01T08:00:00.442560532Z,2024-11-01T08:00:00.442394402Z,10,2,16244,C,B,1,249.890000000,27,130,166130,287605,250.590000000,251.140000000,60,100,1,1,235.000000000,251.350000000,100,1,1,1,,960.000000000,0,25,0,1,,,0,0,0,0,,,0,0,0,0,,,0,0,0,0,,,0,0,0,0,,,0,0,0,0,,,0,0,0,0,,,0,0,0,0,TSLA
2024-11-01T08:00:00.445664686Z,2024-11-01T08:00:00.445498437Z,10,2,16244,A,B,0,250.590000000,60,130,166249,287612,250.590000000,251.140000000,120,100,2,1,235.000000000,251.350000000,100,1,1,1,,960.000000000,0,25,0,1,,,0,0,0,0,,,0,0,0,0,,,0,0,0,0,,,0,0,0,0,,,0,0,0,0,,,0,0,0,0,,,0,0,0,0,TSLA
2024-11-01T08:00:00.445690307Z,2024-11-01T08:00:00.445524743Z,10,2,16244,C,B,0,250.590000000,60,130,165564,287613,250.590000000,251.140000000,60,100,1,1,235.000000000,251.350000000,100,1,1,1,,960.000000000,0,25,0,1,,,0,0,0,0,,,0,0,0,0,,,0,0,0,0,,,0,0,0,0,,,0,0,0,0,,,0,0,0,0,,,0,0,0,0,TSLA
2024-11-01T08:00:00.474545078Z,2024-11-01T08:00:00.474378454Z,10,2,16244,T,A,0,250.590000000,1,130,166624,287659,250.590000000,251.140000000,60,100,1,1,235.000000000,251.350000000,100,1,1,1,,960.000000000,0,25,0,1,,,0,0,0,0,,,0,0,0,0,,,0,0,0,0,,,0,0,0,0,,,0,0,0,0,,,0,0,0,0,,,0,0,0,0,TSLA
2024-11-01T08:00:00.474545078Z,2024-11-01T08:00:00.474378454Z,10,2,16244,C,B,0,250.590000000,1,130,166624,287659,250.590000000,251.140000000,59,100,1,1,235.000000000,251.350000000,100,1,1,1,,960.000000000,0,25,0,1,,,0,0,0,0,,,0,0,0,0,,,0,0,0,0,,,0,0,0,0,,,0,0,0,0,,,0,0,0,0,,,0,0,0,0,TSLA
2024-11-01T08:00:00.482523142Z,2024-11-01T08:00:00.482356557Z,10,2,16244,T,A,0,250.590000000,2,130,166585,287680,250.590000000,251.140000000,59,100,1,1,235.000000000,251.350000000,100,1,1,1,,960.000000000,0,25,0,1,,,0,0,0,0,,,0,0,0,0,,,0,0,0,0,,,0,0,0,0,,,0,0,0,0,,,0,0,0,0,,,0,0,0,0,TSLA
2024-11-01T08:00:00.482523142Z,2024-11-01T08:00:00.482356557Z,10,2,16244,C,B,0,250.590000000,2,130,166585,287680,250.590000000,251.140000000,57,100,1,1,235.000000000,251.350000000,100,1,1,1,,960.000000000,0,25,0,1,,,0,0,0,0,,,0,0,0,0,,,0,0,0,0,,,0,0,0,0,,,0,0,0,0,,,0,0,0,0,,,0,0,0,0,TSLA
2024-11-01T08:00:00.486672774Z,2024-11-01T08:00:00.486506095Z,10,2,16244,A,B,0,250.590000000,57,130,166679,287685,250.590000000,251.140000000,114,100,2,1,235.000000000,251.350000000,100,1,1,1,,960.000000000,0,25,0,1,,,0,0,0,0,,,0,0,0,0,,,0,0,0,0,,,0,0,0,0,,,0,0,0,0,,,0,0,0,0,,,0,0,0,0,TSLA
2024-11-01T08:00:00.486706449Z,2024-11-01T08:00:00.486540735Z,10,2,16244,C,B,0,250.590000000,57,130,165714,287686,250.590000000,251.140000000,57,100,1,1,235.000000000,251.350000000,100,1,1,1,,960.000000000,0,25,0,1,,,0,0,0,0,,,0,0,0,0,,,0,0,0,0,,,0,0,0,0,,,0,0,0,0,,,0,0,0,0,,,0,0,0,0,TSLA
2024-11-01T08:00:00.501417442Z,2024-11-01T08:00:00.501249656Z,10,2,16244,T,A,0,250.590000000,8,130,167786,287707,250.590000000,251.140000000,57,100,1,1,235.000000000,251.350000000,100,1,1,1,,960.000000000,0,25,0,1,,,0,0,0,0,,,0,0,0,0,,,0,0,0,0,,,0,0,0,0,,,0,0,0,0,,,0,0,0,0,,,0,0,0,0,TSLA
2024-11-01T08:00:00.501417442Z,2024-11-01T08:00:00.501249656Z,10,2,16244,C,B,0,250.590000000,8,130,167786,287707,250.590000000,251.140000000,49,100,1,1,235.000000000,251.350000000,100,1,1,1,,960.000000000,0,25,0,1,,,0,0,0,0,,,0,0,0,0,,,0,0,0,0,,,0,0,0,0,,,0,0,0,0,,,0,0,0,0,,,0,0,0,0,TSLA
2024-11-01T08:00:00.518478532Z,2024-11-01T08:00:00.518311853Z,10,2,11667,A,A,0,133.200000000,1000,130,166679,287787,134.630000000,135.300000000,100,1000,1,1,133.200000000,137.680000000,1000,500,1,1,129.050000000,138.870000000,500,1000,1,2,128.470000000,140.740000000,500,100,1,1,127.000000000,140.880000000,20,1000,1,2,,143.690000000,0,500,0,1,,146.510000000,0,5,0,1,,,0,0,0,0,,,0,0,0,0,,,0,0,0,0,NVDA
2024-11-01T08:00:00.529483864Z,2024-11-01T08:00:00.529317790Z,10,2,11667,A,A,1,136.100000000,1000,130,166074,287840,134.630000000,135.300000000,100,1000,1,1,133.200000000,136.100000000,1000,1000,1,1,129.050000000,137.680000000,500,500,1,1,128.470000000,138.870000000,500,1000,1,2,127.000000000,140.740000000,20,100,1,1,,140.880000000,0,1000,0,2,,143.690000000,0,500,0,1,,146.510000000,0,5,0,1,,,0,0,0,0,,,0,0,0,0,NVDA
2024-11-01T08:00:00.535855868Z,2024-11-01T08:00:00.535688993Z,10,2,16244,T,A,0,250.590000000,5,130,166875,287853,250.590000000,251.140000000,49,100,1,1,235.000000000,251.350000000,100,1,1,1,,960.000000000,0,25,0,1,,,0,0,0,0,,,0,0,0,0,,,0,0,0,0,,,0,0,0,0,,,0,0,0,0,,,0,0,0,0,,,0,0,0,0,TSLA
2024-11-01T08:00:00.535855868Z,2024-11-01T08:00:00.535688993Z,10,2,16244,C,B,0,250.590000000,5,130,166875,287853,250.590000000,251.140000000,44,100,1,1,235.000000000,251.350000000,100,1,1,1,,960.000000000,0,25,0,1,,,0,0,0,0,,,0,0,0,0,,,0,0,0,0,,,0,0,0,0,,,0,0,0,0,,,0,0,0,0,,,0,0,0,0,TSLA
2024-11-01T08:00:00.549680583Z,2024-11-01T08:00:00.549514422Z,10,2,16244,A,B,0,250.640000000,44,130,166161,287892,250.640000000,251.140000000,44,100,1,1,250.590000000,251.350000000,44,1,1,1,235.000000000,960.000000000,100,25,1,1,,,0,0,0,0,,,0,0,0,0,,,0,0,0,0,,,0,0,0,0,,,0,0,0,0,,,0,0,0,0,,,0,0,0,0,TSLA
2024-11-01T08:00:00.549718559Z,2024-11-01T08:00:00.549552699Z,10,2,16244,C,B,1,250.590000000,44,130,165860,287893,250.640000000,251.140000000,44,100,1,1,235.000000000,251.350000000,100,1,1,1,,960.000000000,0,25,0,1,,,0,0,0,0,,,0,0,0,0,,,0,0,0,0,,,0,0,0,0,,,0,0,0,0,,,0,0,0,0,,,0,0,0,0,TSLA
2024-11-01T08:00:00.549765488Z,2024-11-01T08:00:00.549599269Z,10,2,16244,A,B,0,250.650000000,44,130,166219,287894,250.650000000,251.140000000,44,100,1,1,250.640000000,251.350000000,44,1,1,1,235.000000000,960.000000000,100,25,1,1,,,0,0,0,0,,,0,0,0,0,,,0,0,0,0,,,0,0,0,0,,,0,0,0,0,,,0,0,0,0,,,0,0,0,0,TSLA
2024-11-01T08:00:00.549787962Z,2024-11-01T08:00:00.549622245Z,10,2,16244,C,B,1,250.640000000,44,130,165717,287895,250.650000000,251.140000000,44,100,1,1,235.000000000,251.350000000,100,1,1,1,,960.000000000,0,25,0,1,,,0,0,0,0,,,0,0,0,0,,,0,0,0,0,,,0,0,0,0,,,0,0,0,0,,,0,0,0,0,,,0,0,0,0,TSLA
2024-11-01T08:00:00.602698323Z,2024-11-01T08:00:00.602531836Z,10,2,16244,A,B,1,249.700000000,1000,130,166487,288041,250.650000000,251.140000000,44,100,1,1,249.700000000,251.350000000,1000,1,1,1,235.000000000,252.400000000,100,1000,1,1,,960.000000000,0,25,0,1,,,0,0,0,0,,,0,0,0,0,,,0,0,0,0,,,0,0,0,0,,,0,0,0,0,,,0,0,0,0,TSLA
2024-11-01T08:00:00.625868436Z,2024-11-01T08:00:00.625702136Z,10,2,11667,A,B,2,132.000000000,70,130,166300,288146,134.630000000,135.300000000,100,1000,1,1,133.200000000,136.100000000,1000,1000,1,1,132.000000000,137.680000000,70,500,1,1,129.050000000,138.870000000,500,1000,1,2,128.470000000,140.740000000,500,100,1,1,127.000000000,140.880000000,20,1000,1,2,,143.690000000,0,500,0,1,,146.510000000,0,5,0,1,,,0,0,0,0,,,0,0,0,0,NVDA
2024-11-01T08:00:00.646448551Z,2024-11-01T08:00:00.646282292Z,10,2,16244,A,A,1,251.300000000,50,130,166259,288185,250.650000000,251.140000000,44,100,1,1,249.700000000,251.300000000,1000,50,1,1,235.000000000,251.350000000,100,1,1,1,,252.400000000,0,1000,0,1,,960.000000000,0,25,0,1,,,0,0,0,0,,,0,0,0,0,,,0,0,0,0,,,0,0,0,0,,,0,0,0,0,TSLA
2024-11-01T08:00:00.667701491Z,2024-11-01T08:00:00.667534920Z,10,2,9155,A,N,0,219.160000000,450,130,166571,288249,219.160000000,,450,0,1,0,,,0,0,0,0,,,0,0,0,0,,,0,0,0,0,,,0,0,0,0,,,0,0,0,0,,,0,0,0,0,,,0,0,0,0,,,0,0,0,0,,,0,0,0,0,JPM
2024-11-01T08:00:00.667811256Z,2024-11-01T08:00:00.667645044Z,10,2,9155,A,A,0,224.940000000,450,130,166212,288250,219.160000000,224.940000000,450,450,1,1,,,0,0,0,0,,,0,0,0,0,,,0,0,0,0,,,0,0,0,0,,,0,0,0,0,,,0,0,0,0,,,0,0,0,0,,,0,0,0,0,,,0,0,0,0,JPM
2024-11-01T08:00:00.685257122Z,2024-11-01T08:00:00.685090840Z,10,2,16244,A,B,2,247.150000000,400,130,166282,288302,250.650000000,251.140000000,44,100,1,1,249.700000000,251.300000000,1000,50,1,1,247.150000000,251.350000000,400,1,1,1,235.000000000,252.400000000,100,1000,1,1,,960.000000000,0,25,0,1,,,0,0,0,0,,,0,0,0,0,,,0,0,0,0,,,0,0,0,0,,,0,0,0,0,TSLA
2024-11-01T08:00:00.685358404Z,2024-11-01T08:00:00.685191982Z,10,2,16244,A,A,4,253.650000000,400,130,166422,288303,250.650000000,251.140000000,44,100,1,1,249.700000000,251.300000000,1000,50,1,1,247.150000000,251.350000000,400,1,1,1,235.000000000,252.400000000,100,1000,1,1,,253.650000000,0,400,0,1,,960.000000000,0,25,0,1,,,0,0,0,0,,,0,0,0,0,,,0,0,0,0,,,0,0,0,0,TSLA
2024-11-01T08:00:00.728053346Z,2024-11-01T08:00:00.727887097Z,10,2,16244,A,A,1,251.300000000,50,130,166249,288414,250.650000000,251.140000000,44,100,1,1,249.700000000,251.300000000,1000,100,1,2,247.150000000,251.350000000,400,1,1,1,235.000000000,252.400000000,100,1000,1,1,,253.650000000,0,400,0,1,,960.000000000,0,25,0,1,,,0,0,0,0,,,0,0,0,0,,,0,0,0,0,,,0,0,0,0,TSLA
2024-11-01T08:00:00.737585014Z,2024-11-01T08:00:00.737419091Z,10,2,16244,A,B,1,250.370000000,50,130,165923,288424,250.650000000,251.140000000,44,100,1,1,250.370000000,251.300000000,50,100,1,2,249.700000000,251.350000000,1000,1,1,1,247.150000000,252.400000000,400,1000,1,1,235.000000000,253.650000000,100,400,1,1,,960.000000000,0,25,0,1,,,0,0,0,0,,,0,0,0,0,,,0,0,0,0,,,0,0,0,0,TSLA
2024-11-01T08:00:00.737615718Z,2024-11-01T08:00:00.737450175Z,10,2,16244,C,A,1,251.300000000,50,130,165543,288425,250.650000000,251.140000000,44,100,1,1,250.370000000,251.300000000,50,50,1,1,249.700000000,251.350000000,1000,1,1,1,247.150000000,252.400000000,400,1000,1,1,235.000000000,253.650000000,100,400,1,1,,960.000000000,0,25,0,1,,,0,0,0,0,,,0,0,0,0,,,0,0,0,0,,,0,0,0,0,TSLA
2024-11-01T08:00:00.737637686Z,2024-11-01T08:00:00.737471510Z,10,2,16244,A,A,1,251.290000000,50,130,166176,288426,250.650000000,251.140000000,44,100,1,1,250.370000000,251.290000000,50,50,1,1,249.700000000,251.350000000,1000,1,1,1,247.150000000,252.400000000,400,1000,1,1,235.000000000,253.650000000,100,400,1,1,,960.000000000,0,25,0,1,,,0,0,0,0,,,0,0,0,0,,,0,0,0,0,,,0,0,0,0,TSLA
2024-11-01T08:00:00.739666524Z,2024-11-01T08:00:00.739500213Z,10,2,10888,A,A,1,468.000000000,65,130,166311,288427,404.410000000,415.070000000,246,246,1,1,,468.000000000,0,65,0,1,,,0,0,0,0,,,0,0,0,0,,,0,0,0,0,,,0,0,0,0,,,0,0,0,0,,,0,0,0,0,,,0,0,0,0,,,0,0,0,0,MSFT
2024-11-01T08:00:00.783046930Z,2024-11-01T08:00:00.782879583Z,10,2,16244,A,A,1,251.250000000,50,130,167347,288564,250.650000000,251.140000000,44,100,1,1,250.370000000,251.250000000,50,50,1,1,249.700000000,251.350000000,1000,1,1,1,247.150000000,252.400000000,400,1000,1,1,235.000000000,253.650000000,100,400,1,1,,960.000000000,0,25,0,1,,,0,0,0,0,,,0,0,0,0,,,0,0,0,0,,,0,0,0,0,TSLA
2024-11-01T08:00:00.790858828Z,2024-11-01T08:00:00.790692621Z,10,2,17709,A,B,0,115.280000000,856,130,166207,288581,115.280000000,,856,0,1,0,,,0,0,0,0,,,0,0,0,0,,,0,0,0,0,,,0,0,0,0,,,0,0,0,0,,,0,0,0,0,,,0,0,0,0,,,0,0,0,0,,,0,0,0,0,XOM
2024-11-01T08:00:00.791025097Z,2024-11-01T08:00:00.790858762Z,10,2,17709,A,A,0,118.320000000,856,130,166335,288582,115.280000000,118.320000000,856,856,1,1,,,0,0,0,0,,,0,0,0,0,,,0,0,0,0,,,0,0,0,0,,,0,0,0,0,,,0,0,0,0,,,0,0,0,0,,,0,0,0,0,,,0,0,0,0,XOM
2024-11-01T08:00:00.816324059Z,2024-11-01T08:00:00.816157932Z,10,2,16244,C,A,2,251.350000000,1,130,166127,288650,250.650000000,251.140000000,44,100,1,1,250.370000000,251.250000000,50,50,1,1,249.700000000,252.400000000,1000,1000,1,1,247.150000000,253.650000000,400,400,1,1,235.000000000,960.000000000,100,25,1,1,,,0,0,0,0,,,0,0,0,0,,,0,0,0,0,,,0,0,0,0,,,0,0,0,0,TSLA
2024-11-01T08:00:00.870798645Z,2024-11-01T08:00:00.870632992Z,10,2,16244,C,B,1,250.370000000,50,130,165653,288765,250.650000000,251.140000000,44,100,1,1,249.700000000,251.250000000,1000,50,1,1,247.150000000,252.400000000,400,1000,1,1,235.000000000,253.650000000,100,400,1,1,,960.000000000,0,25,0,1,,,0,0,0,0,,,0,0,0,0,,,0,0,0,0,,,0,0,0,0,,,0,0,0,0,TSLA
2024-11-01T08:00:00.870810579Z,2024-11-01T08:00:00.870644760Z,10,2,16244,A,B,1,250.320000000,50,130,165819,288766,250.650000000,251.140000000,44,100,1,1,250.320000000,251.250000000,50,50,1,1,249.700000000,252.400000000,1000,1000,1,1,247.150000000,253.650000000,400,400,1,1,235.000000000,960.000000000,100,25,1,1,,,0,0,0,0,,,0,0,0,0,,,0,0,0,0,,,0,0,0,0,,,0,0,0,0,TSLA
2024-11-01T08:00:00.874060839Z,2024-11-01T08:00:00.873894771Z,10,2,38,A,A,1,225.490000000,442,130,166068,288771,221.200000000,224.400000000,1000,1000,1,1,217.000000000,225.490000000,1525,442,1,1,,234.000000000,0,20,0,1,,,0,0,0,0,,,0,0,0,0,,,0,0,0,0,,,0,0,0,0,,,0,0,0,0,,,0,0,0,0,,,0,0,0,0,AAPL
2024-11-01T08:00:00.874748502Z,2024-11-01T08:00:00.874582349Z,10,2,38,A,B,1,219.690000000,442,130,166153,288782,221.200000000,224.400000000,1000,1000,1,1,219.690000000,225.490000000,442,442,1,1,217.000000000,234.000000000,1525,20,1,1,,,0,0,0,0,,,0,0,0,0,,,0,0,0,0,,,0,0,0,0,,,0,0,0,0,,,0,0,0,0,,,0,0,0,0,AAPL
2024-11-01T08:00:00.923892379Z,2024-11-01T08:00:00.923726506Z,10,2,16244,C,B,1,250.320000000,50,130,165873,289004,250.650000000,251.140000000,44,100,1,1,249.700000000,251.250000000,1000,50,1,1,247.150000000,252.400000000,400,1000,1,1,235.000000000,253.650000000,100,400,1,1,,960.000000000,0,25,0,1,,,0,0,0,0,,,0,0,0,0,,,0,0,0,0,,,0,0,0,0,,,0,0,0,0,TSLA
2024-11-01T08:00:00.924058952Z,2024-11-01T08:00:00.923891312Z,10,2,16244,T,A,0,250.650000000,44,130,167640,289007,250.650000000,251.140000000,44,100,1,1,249.700000000,251.250000000,1000,50,1,1,247.150000000,252.400000000,400,1000,1,1,235.000000000,253.650000000,100,400,1,1,,960.000000000,0,25,0,1,,,0,0,0,0,,,0,0,0,0,,,0,0,0,0,,,0,0,0,0,,,0,0,0,0,TSLA
2024-11-01T08:00:00.924058952Z,2024-11-01T08:00:00.923891312Z,10,2,16244,C,B,0,250.650000000,44,130,167640,289007,249.700000000,251.140000000,1000,100,1,1,247.150000000,251.250000000,400,50,1,1,235.000000000,252.400000000,100,1000,1,1,,253.650000000,0,400,0,1,,960.000000000,0,25,0,1,,,0,0,0,0,,,0,0,0,0,,,0,0,0,0,,,0,0,0,0,,,0,0,0,0,TSLA
2024-11-01T08:00:00.924082550Z,2024-11-01T08:00:00.923916634Z,10,2,16244,A,A,0,251.040000000,100,130,165916,289008,249.700000000,251.040000000,1000,100,1,1,247.150000000,251.140000000,400,100,1,1,235.000000000,251.250000000,100,50,1,1,,252.400000000,0,1000,0,1,,253.650000000,0,400,0,1,,960.000000000,0,25,0,1,,,0,0,0,0,,,0,0,0,0,,,0,0,0,0,,,0,0,0,0,TSLA
2024-11-01T08:00:00.924083719Z,2024-11-01T08:00:00.923917728Z,10,2,16244,A,A,0,250.860000000,100,130,165991,289009,249.700000000,250.860000000,1000,100,1,1,247.150000000,251.040000000,400,100,1,1,235.000000000,251.140000000,100,100,1,1,,251.250000000,0,50,0,1,,252.400000000,0,1000,0,1,,253.650000000,0,400,0,1,,960.000000000,0,25,0,1,,,0,0,0,0,,,0,0,0,0,,,0,0,0,0,TSLA
2024-11-01T08:00:00.924085460Z,2024-11-01T08:00:00.923918768Z,10,2,16244,A,A,1,251.040000000,100,130,166692,289010,249.700000000,250.860000000,1000,100,1,1,247.150000000,251.040000000,400,200,1,2,235.000000000,251.140000000,100,100,1,1,,251.250000000,0,50,0,1,,252.400000000,0,1000,0,1,,253.650000000,0,400,0,1,,960.000000000,0,25,0,1,,,0,0,0,0,,,0,0,0,0,,,0,0,0,0,TSLA
2024-11-01T08:00:00.924097499Z,2024-11-01T08:00:00.923931446Z,10,2,16244,A,A,1,251.040000000,100,130,166053,289011,249.700000000,250.860000000,1000,100,1,1,247.150000000,251.040000000,400,300,1,3,235.000000000,251.140000000,100,100,1,1,,251.250000000,0,50,0,1,,252.400000000,0,1000,0,1,,253.650000000,0,400,0,1,,960.000000000,0,25,0,1,,,0,0,0,0,,,0,0,0,0,,,0,0,0,0,TSLA
2024-11-01T08:00:00.924108518Z,2024-11-01T08:00:00.923942922Z,10,2,16244,C,A,0,250.860000000,100,130,165596,289012,249.700000000,251.040000000,1000,300,1,3,247.150000000,251.140000000,400,100,1,1,235.000000000,251.250000000,100,50,1,1,,252.400000000,0,1000,0,1,,253.650000000,0,400,0,1,,960.000000000,0,25,0,1,,,0,0,0,0,,,0,0,0,0,,,0,0,0,0,,,0,0,0,0,TSLA
2024-11-01T08:00:00.924122177Z,2024-11-01T08:00:00.923956325Z,10,2,16244,C,A,0,251.040000000,100,130,165852,289014,249.700000000,250.900000000,1000,27,1,1,247.150000000,251.040000000,400,200,1,2,235.000000000,251.140000000,100,100,1,1,,251.250000000,0,50,0,1,,252.400000000,0,1000,0,1,,253.650000000,0,400,0,1,,960.000000000,0,25,0,1,,,0,0,0,0,,,0,0,0,0,,,0,0,0,0,TSLA
2024-11-01T08:00:00.924162055Z,2024-11-01T08:00:00.923996173Z,10,2,16244,A,A,2,251.050000000,27,130,165882,289015,249.700000000,250.900000000,1000,27,1,1,247.150000000,251.040000000,400,200,1,2,235.000000000,251.050000000,100,27,1,1,,251.140000000,0,100,0,1,,251.250000000,0,50,0,1,,252.400000000,0,1000,0,1,,253.650000000,0,400,0,1,,960.000000000,0,25,0,1,,,0,0,0,0,,,0,0,0,0,TSLA
2024-11-01T08:00:00.924222494Z,2024-11-01T08:00:00.924056793Z,10,2,16244,A,A,2,251.050000000,69,130,165701,289016,249.700000000,250.900000000,1000,27,1,1,247.150000000,251.040000000,400,200,1,2,235.000000000,251.050000000,100,96,1,2,,251.140000000,0,100,0,1,,251.250000000,0,50,0,1,,252.400000000,0,1000,0,1,,253.650000000,0,400,0,1,,960.000000000,0,25,0,1,,,0,0,0,0,,,0,0,0,0,TSLA
2024-11-01T08:00:00.924238256Z,2024-11-01T08:00:00.924072526Z,10,2,16244,C,A,0,250.900000000,27,130,165730,289017,249.700000000,251.040000000,1000,200,1,2,247.150000000,251.050000000,400,96,1,2,235.000000000,251.140000000,100,100,1,1,,251.250000000,0,50,0,1,,252.400000000,0,1000,0,1,,253.650000000,0,400,0,1,,960.000000000,0,25,0,1,,,0,0,0,0,,,0,0,0,0,,,0,0,0,0,TSLA
2024-11-01T08:00:00.924250448Z,2024-11-01T08:00:00.924084776Z,10,2,16244,C,A,1,251.050000000,27,130,165672,289018,249.700000000,251.040000000,1000,200,1,2,247.150000000,251.050000000,400,69,1,1,235.000000000,251.140000000,100,100,1,1,,251.250000000,0,50,0,1,,252.400000000,0,1000,0,1,,253.650000000,0,400,0,1,,960.000000000,0,25,0,1,,,0,0,0,0,,,0,0,0,0,,,0,0,0,0,TSLA
2024-11-01T08:00:00.924261497Z,2024-11-01T08:00:00.924095782Z,10,2,16244,C,A,1,251.050000000,69,130,165715,289019,249.700000000,251.040000000,1000,200,1,2,247.150000000,251.140000000,400,100,1,1,235.000000000,251.250000000,100,50,1,1,,252.400000000,0,1000,0,1,,253.650000000,0,400,0,1,,960.000000000,0,25,0,1,,,0,0,0,0,,,0,0,0,0,,,0,0,0,0,,,0,0,0,0,TSLA
2024-11-01T08:00:00.924336479Z,2024-11-01T08:00:00.924170863Z,10,2,16244,C,A,0,251.040000000,100,130,165616,289020,249.700000000,251.040000000,1000,100,1,1,247.150000000,251.140000000,400,100,1,1,235.000000000,251.250000000,100,50,1,1,,252.400000000,0,1000,0,1,,253.650000000,0,400,0,1,,960.000000000,0,25,0,1,,,0,0,0,0,,,0,0,0,0,,,0,0,0,0,,,0,0,0,0,TSLA
2024-11-01T08:00:00.926519472Z,2024-11-01T08:00:00.926353755Z,10,2,16244,C,B,0,249.700000000,1000,130,165717,289028,247.150000000,251.040000000,400,100,1,1,235.000000000,251.140000000,100,100,1,1,,251.250000000,0,50,0,1,,252.400000000,0,1000,0,1,,253.650000000,0,400,0,1,,960.000000000,0,25,0,1,,,0,0,0,0,,,0,0,0,0,,,0,0,0,0,,,0,0,0,0,TSLA
2024-11-01T08:00:00.929078256Z,2024-11-01T08:00:00.928912137Z,10,2,16244,C,A,0,251.040000000,100,130,166119,289038,247.150000000,251.140000000,400,100,1,1,235.000000000,251.250000000,100,50,1,1,,252.400000000,0,1000,0,1,,253.650000000,0,400,0,1,,960.000000000,0,25,0,1,,,0,0,0,0,,,0,0,0,0,,,0,0,0,0,,,0,0,0,0,,,0,0,0,0,TSLA
2024-11-01T08:00:00.935447415Z,2024-11-01T08:00:00.935281138Z,10,2,11667,A,B,0,134.630000000,100,130,166277,289061,134.630000000,135.300000000,200,1000,2,1,133.200000000,136.100000000,1000,1000,1,1,132.000000000,137.680000000,70,500,1,1,129.050000000,138.870000000,500,1000,1,2,128.470000000,140.740000000,500,100,1,1,127.000000000,140.880000000,20,1000,1,2,,143.690000000,0,500,0,1,,146.510000000,0,5,0,1,,,0,0,0,0,,,0,0,0,0,NVDA
2024-11-01T08:00:00.960394963Z,2024-11-01T08:00:00.960228634Z,10,2,16244,A,B,0,249.600000000,1000,130,166329,289123,249.600000000,251.140000000,1000,100,1,1,247.150000000,251.250000000,400,50,1,1,235.000000000,252.400000000,100,1000,1,1,,253.650000000,0,400,0,1,,960.000000000,0,25,0,1,,,0,0,0,0,,,0,0,0,0,,,0,0,0,0,,,0,0,0,0,,,0,0,0,0,TSLA
2024-11-01T08:00:00.983216400Z,2024-11-01T08:00:00.983050792Z,10,2,16244,C,A,1,251.250000000,50,130,165608,289185,249.600000000,251.140000000,1000,100,1,1,247.150000000,252.400000000,400,1000,1,1,235.000000000,253.650000000,100,400,1,1,,960.000000000,0,25,0,1,,,0,0,0,0,,,0,0,0,0,,,0,0,0,0,,,0,0,0,0,,,0,0,0,0,,,0,0,0,0,TSLA
2024-11-01T08:00:00.983229752Z,2024-11-01T08:00:00.983063706Z,10,2,16244,A,A,1,251.280000000,50,130,166046,289186,249.600000000,251.140000000,1000,100,1,1,247.150000000,251.280000000,400,50,1,1,235.000000000,252.400000000,100,1000,1,1,,253.650000000,0,400,0,1,,960.000000000,0,25,0,1,,,0,0,0,0,,,0,0,0,0,,,0,0,0,0,,,0,0,0,0,,,0,0,0,0,TSLA
2024-11-01T08:00:00.983312891Z,2024-11-01T08:00:00.983147307Z,10,2,16244,C,A,1,251.280000000,50,130,165584,289187,249.600000000,251.140000000,1000,100,1,1,247.150000000,252.400000000,400,1000,1,1,235.000000000,253.650000000,100,400,1,1,,960.000000000,0,25,0,1,,,0,0,0,0,,,0,0,0,0,,,0,0,0,0,,,0,0,0,0,,,0,0,0,0,,,0,0,0,0,TSLA
2024-11-01T08:00:00.983325098Z,2024-11-01T08:00:00.983159237Z,10,2,16244,A,A,1,251.300000000,50,130,165861,289188,249.600000000,251.140000000,1000,100,1,1,247.150000000,251.300000000,400,50,1,1,235.000000000,252.400000000,100,1000,1,1,,253.650000000,0,400,0,1,,960.000000000,0,25,0,1,,,0,0,0,0,,,0,0,0,0,,,0,0,0,0,,,0,0,0,0,,,0,0,0,0,TSLA
2024-11-01T08:00:00.983364607Z,2024-11-01T08:00:00.983198689Z,10,2,16244,C,A,1,251.300000000,50,130,165918,289189,249.600000000,251.140000000,1000,100,1,1,247.150000000,252.400000000,400,1000,1,1,235.000000000,253.650000000,100,400,1,1,,960.000000000,0,25,0,1,,,0,0,0,0,,,0,0,0,0,,,0,0,0,0,,,0,0,0,0,,,0,0,0,0,,,0,0,0,0,TSLA
2024-11-01T08:00:00.983459000Z,2024-11-01T08:00:00.983292932Z,10,2,16244,A,A,1,251.490000000,50,130,166068,289190,249.600000000,251.140000000,1000,100,1,1,247.150000000,251.490000000,400,50,1,1,235.000000000,252.400000000,100,1000,1,1,,253.650000000,0,400,0,1,,960.000000000,0,25,0,1,,,0,0,0,0,,,0,0,0,0,,,0,0,0,0,,,0,0,0,0,,,0,0,0,0,TSLA
2024-11-01T08:00:00.997076982Z,2024-11-01T08:00:00.996911132Z,10,2,11667,C,B,0,134.630000000,100,130,165850,289211,134.630000000,135.300000000,100,1000,1,1,133.200000000,136.100000000,1000,1000,1,1,132.000000000,137.680000000,70,500,1,1,129.050000000,138.870000000,500,1000,1,2,128.470000000,140.740000000,500,100,1,1,127.000000000,140.880000000,20,1000,1,2,,143.690000000,0,500,0,1,,146.510000000,0,5,0,1,,,0,0,0,0,,,0,0,0,0,NVDA
2024-11-01T08:00:00.997097899Z,2024-11-01T08:00:00.996931723Z,10,2,11667,A,B,0,134.770000000,100,130,166176,289212,134.770000000,135.300000000,100,1000,1,1,133.200000000,136.100000000,1000,1000,1,1,132.000000000,137.680000000,70,500,1,1,129.050000000,138.870000000,500,1000,1,2,128.470000000,140.740000000,500,100,1,1,127.000000000,140.880000000,20,1000,1,2,,143.690000000,0,500,0,1,,146.510000000,0,5,0,1,,,0,0,0,0,,,0,0,0,0,NVDA
2024-11-01T08:00:01.004277713Z,2024-11-01T08:00:01.004111311Z,10,2,16244,A,B,0,249.700000000,1000,130,166402,289243,249.700000000,251.140000000,1000,100,1,1,249.600000000,251.490000000,1000,50,1,1,247.150000000,252.400000000,400,1000,1,1,235.000000000,253.650000000,100,400,1,1,,960.000000000,0,25,0,1,,,0,0,0,0,,,0,0,0,0,,,0,0,0,0,,,0,0,0,0,,,0,0,0,0,TSLA
2024-11-01T08:00:01.004489943Z,2024-11-01T08:00:01.004324198Z,10,2,16244,C,B,1,249.600000000,1000,130,165745,289245,249.700000000,251.140000000,1000,100,1,1,247.150000000,251.490000000,400,50,1,1,235.000000000,252.400000000,100,1000,1,1,,253.650000000,0,400,0,1,,960.000000000,0,25,0,1,,,0,0,0,0,,,0,0,0,0,,,0,0,0,0,,,0,0,0,0,,,0,0,0,0,TSLA
2024-11-01T08:00:01.005588232Z,2024-11-01T08:00:01.005422090Z,10,2,11667,A,B,1,134.210000000,20,130,166142,289258,134.770000000,135.300000000,100,1000,1,1,134.210000000,136.100000000,20,1000,1,1,133.200000000,137.680000000,1000,500,1,1,132.000000000,138.870000000,70,1000,1,2,129.050000000,140.740000000,500,100,1,1,128.470000000,140.880000000,500,1000,1,2,127.000000000,143.690000000,20,500,1,1,,146.510000000,0,5,0,1,,,0,0,0,0,,,0,0,0,0,NVDA
2024-11-01T08:00:01.007035676Z,2024-11-01T08:00:01.006869811Z,10,2,11667,C,B,0,134.770000000,100,130,165865,289272,134.210000000,135.300000000,20,1000,1,1,133.200000000,136.100000000,1000,1000,1,1,132.000000000,137.680000000,70,500,1,1,129.050000000,138.870000000,500,1000,1,2,128.470000000,140.740000000,500,100,1,1,127.000000000,140.880000000,20,1000,1,2,,143.690000000,0,500,0,1,,146.510000000,0,5,0,1,,,0,0,0,0,,,0,0,0,0,NVDA
2024-11-01T08:00:01.011900111Z,2024-11-01T08:00:01.011734044Z,10,2,11667,A,B,0,134.620000000,100,130,166067,289282,134.620000000,135.300000000,100,1000,1,1,134.210000000,136.100000000,20,1000,1,1,133.200000000,137.680000000,1000,500,1,1,132.000000000,138.870000000,70,1000,1,2,129.050000000,140.740000000,500,100,1,1,128.470000000,140.880000000,500,1000,1,2,127.000000000,143.690000000,20,500,1,1,,146.510000000,0,5,0,1,,,0,0,0,0,,,0,0,0,0,NVDA
2024-11-01T08:00:01.059109773Z,2024-11-01T08:00:01.058943966Z,10,2,16244,C,B,0,249.700000000,1000,130,165807,289424,247.150000000,251.140000000,400,100,1,1,235.000000000,251.490000000,100,50,1,1,,252.400000000,0,1000,0,1,,253.650000000,0,400,0,1,,960.000000000,0,25,0,1,,,0,0,0,0,,,0,0,0,0,,,0,0,0,0,,,0,0,0,0,,,0,0,0,0,TSLA
2024-11-01T08:00:01.059811325Z,2024-11-01T08:00:01.059645174Z,10,2,11667,A,B,0,134.620000000,100,130,166151,289428,134.620000000,135.300000000,200,1000,2,1,134.210000000,136.100000000,20,1000,1,1,133.200000000,137.680000000,1000,500,1,1,132.000000000,138.870000000,70,1000,1,2,129.050000000,140.740000000,500,100,1,1,128.470000000,140.880000000,500,1000,1,2,127.000000000,143.690000000,20,500,1,1,,146.510000000,0,5,0,1,,,0,0,0,0,,,0,0,0,0,NVDA
2024-11-01T08:00:01.094440542Z,2024-11-01T08:00:01.094274556Z,10,2,16244,A,B,0,249.500000000,1000,130,165986,289532,249.500000000,251.140000000,1000,100,1,1,247.150000000,251.490000000,400,50,1,1,235.000000000,252.400000000,100,1000,1,1,,253.650000000,0,400,0,1,,960.000000000,0,25,0,1,,,0,0,0,0,,,0,0,0,0,,,0,0,0,0,,,0,0,0,0,,,0,0,0,0,TSLA
2024-11-01T08:00:01.110332272Z,2024-11-01T08:00:01.110166175Z,10,2,16244,A,A,1,251.490000000,50,130,166097,289565,249.500000000,251.140000000,1000,100,1,1,247.150000000,251.490000000,400,100,1,2,235.000000000,252.400000000,100,1000,1,1,,253.650000000,0,400,0,1,,960.000000000,0,25,0,1,,,0,0,0,0,,,0,0,0,0,,,0,0,0,0,,,0,0,0,0,,,0,0,0,0,TSLA
2024-11-01T08:00:01.116734144Z,2024-11-01T08:00:01.116568271Z,10,2,16244,C,A,1,251.490000000,50,130,165873,289574,249.500000000,251.140000000,1000,100,1,1,247.150000000,251.490000000,400,50,1,1,235.000000000,252.400000000,100,1000,1,1,,253.650000000,0,400,0,1,,960.000000000,0,25,0,1,,,0,0,0,0,,,0,0,0,0,,,0,0,0,0,,,0,0,0,0,,,0,0,0,0,TSLA
2024-11-01T08:00:01.116754577Z,2024-11-01T08:00:01.116588527Z,10,2,16244,A,A,1,251.480000000,100,130,166050,289575,249.500000000,251.140000000,1000,100,1,1,247.150000000,251.480000000,400,100,1,1,235.000000000,252.400000000,100,1000,1,1,,253.650000000,0,400,0,1,,960.000000000,0,25,0,1,,,0,0,0,0,,,0,0,0,0,,,0,0,0,0,,,0,0,0,0,,,0,0,0,0,TSLA
2024-11-01T08:00:01.127156707Z,2024-11-01T08:00:01.126991081Z,10,2,11667,C,B,0,134.620000000,100,130,165626,289584,134.620000000,135.300000000,100,1000,1,1,134.210000000,136.100000000,20,1000,1,1,133.200000000,137.680000000,1000,500,1,1,132.000000000,138.870000000,70,1000,1,2,129.050000000,140.740000000,500,100,1,1,128.470000000,140.880000000,500,1000,1,2,127.000000000,143.690000000,20,500,1,1,,146.510000000,0,5,0,1,,,0,0,0,0,,,0,0,0,0,NVDA
2024-11-01T08:00:01.127186870Z,2024-11-01T08:00:01.127020954Z,10,2,11667,A,B,0,134.770000000,100,130,165916,289585,134.770000000,135.300000000,100,1000,1,1,134.210000000,136.100000000,20,1000,1,1,133.200000000,137.680000000,1000,500,1,1,132.000000000,138.870000000,70,1000,1,2,129.050000000,140.740000000,500,100,1,1,128.470000000,140.880000000,500,1000,1,2,127.000000000,143.690000000,20,500,1,1,,146.510000000,0,5,0,1,,,0,0,0,0,,,0,0,0,0,NVDA
2024-11-01T08:00:01.137385846Z,2024-11-01T08:00:01.137219880Z,10,2,16244,A,B,0,249.600000000,1000,130,165966,289595,249.600000000,251.140000000,1000,100,1,1,249.500000000,251.480000000,1000,100,1,1,247.150000000,252.400000000,400,1000,1,1,235.000000000,253.650000000,100,400,1,1,,960.000000000,0,25,0,1,,,0,0,0,0,,,0,0,0,0,,,0,0,0,0,,,0,0,0,0,,,0,0,0,0,TSLA
2024-11-01T08:00:01.137488602Z,2024-11-01T08:00:01.137322871Z,10,2,16244,C,B,1,249.500000000,1000,130,165731,289596,249.600000000,251.140000000,1000,100,1,1,247.150000000,251.480000000,400,100,1,1,235.000000000,252.400000000,100,1000,1,1,,253.650000000,0,400,0,1,,960.000000000,0,25,0,1,,,0,0,0,0,,,0,0,0,0,,,0,0,0,0,,,0,0,0,0,,,0,0,0,0,TSLA
2024-11-01T08:00:01.155279986Z,2024-11-01T08:00:01.155114036Z,10,2,16244,C,A,1,251.480000000,50,130,165950,289634,249.600000000,251.140000000,1000,100,1,1,247.150000000,251.480000000,400,50,1,1,235.000000000,252.400000000,100,1000,1,1,,253.650000000,0,400,0,1,,960.000000000,0,25,0,1,,,0,0,0,0,,,0,0,0,0,,,0,0,0,0,,,0,0,0,0,,,0,0,0,0,TSLA
2024-11-01T08:00:01.164347156Z,2024-11-01T08:00:01.164180860Z,10,2,16244,A,A,1,251.440000000,50,130,166296,289643,249.600000000,251.140000000,1000,100,1,1,247.150000000,251.440000000,400,50,1,1,235.000000000,252.400000000,100,1000,1,1,,253.650000000,0,400,0,1,,960.000000000,0,25,0,1,,,0,0,0,0,,,0,0,0,0,,,0,0,0,0,,,0,0,0,0,,,0,0,0,0,TSLA
2024-11-01T08:00:01.174029238Z,2024-11-01T08:00:01.173863038Z,10,2,16244,A,B,0,250.240000000,50,130,166200,289666,250.240000000,251.140000000,50,100,1,1,249.600000000,251.440000000,1000,50,1,1,247.150000000,252.400000000,400,1000,1,1,235.000000000,253.650000000,100,400,1,1,,960.000000000,0,25,0,1,,,0,0,0,0,,,0,0,0,0,,,0,0,0,0,,,0,0,0,0,,,0,0,0,0,TSLA
2024-11-01T08:00:01.194416923Z,2024-11-01T08:00:01.194251316Z,10,2,16244,C,A,1,251.440000000,50,130,165607,289700,250.240000000,251.140000000,50,100,1,1,249.600000000,252.400000000,1000,1000,1,1,247.150000000,253.650000000,400,400,1,1,235.000000000,960.000000000,100,25,1,1,,,0,0,0,0,,,0,0,0,0,,,0,0,0,0,,,0,0,0,0,,,0,0,0,0,,,0,0,0,0,TSLA
2024-11-01T08:00:01.194428947Z,2024-11-01T08:00:01.194262835Z,10,2,16244,A,A,1,251.490000000,50,130,166112,289701,250.240000000,251.140000000,50,100,1,1,249.600000000,251.490000000,1000,50,1,1,247.150000000,252.400000000,400,1000,1,1,235.000000000,253.650000000,100,400,1,1,,960.000000000,0,25,0,1,,,0,0,0,0,,,0,0,0,0,,,0,0,0,0,,,0,0,0,0,,,0,0,0,0,TSLA
2024-11-01T08:00:01.198788725Z,2024-11-01T08:00:01.198623132Z,10,2,16244,C,B,1,249.600000000,1000,130,165593,289709,250.240000000,251.140000000,50,100,1,1,247.150000000,251.490000000,400,50,1,1,235.000000000,252.400000000,100,1000,1,1,,253.650000000,0,400,0,1,,960.000000000,0,25,0,1,,,0,0,0,0,,,0,0,0,0,,,0,0,0,0,,,0,0,0,0,,,0,0,0,0,TSLA
2024-11-01T08:00:01.210385512Z,2024-11-01T08:00:01.210218950Z,10,2,16244,A,B,1,249.100000000,1000,130,166562,289727,250.240000000,251.140000000,50,100,1,1,249.100000000,251.490000000,1000,50,1,1,247.150000000,252.400000000,400,1000,1,1,235.000000000,253.650000000,100,400,1,1,,960.000000000,0,25,0,1,,,0,0,0,0,,,0,0,0,0,,,0,0,0,0,,,0,0,0,0,,,0,0,0,0,TSLA
2024-11-01T08:00:01.220425809Z,2024-11-01T08:00:01.220258901Z,10,2,11667,A,A,8,148.000000000,5,130,166908,289729,134.770000000,135.300000000,100,1000,1,1,134.210000000,136.100000000,20,1000,1,1,133.200000000,137.680000000,1000,500,1,1,132.000000000,138.870000000,70,1000,1,2,129.050000000,140.740000000,500,100,1,1,128.470000000,140.880000000,500,1000,1,2,127.000000000,143.690000000,20,500,1,1,,146.510000000,0,5,0,1,,148.000000000,0,5,0,1,,,0,0,0,0,NVDA
2024-11-01T08:00:01.251765817Z,2024-11-01T08:00:01.251599819Z,10,2,16244,A,B,0,250.250000000,50,130,165998,289765,250.250000000,251.140000000,50,100,1,1,249.100000000,251.490000000,1000,50,1,1,247.150000000,252.400000000,400,1000,1,1,235.000000000,253.650000000,100,400,1,1,,960.000000000,0,25,0,1,,,0,0,0,0,,,0,0,0,0,,,0,0,0,0,,,0,0,0,0,,,0,0,0,0,TSLA
2024-11-01T08:00:01.251881540Z,2024-11-01T08:00:01.251715874Z,10,2,16244,C,A,1,251.490000000,50,130,165666,289767,250.250000000,251.140000000,50,100,1,1,249.100000000,252.400000000,1000,1000,1,1,247.150000000,253.650000000,400,400,1,1,235.000000000,960.000000000,100,25,1,1,,,0,0,0,0,,,0,0,0,0,,,0,0,0,0,,,0,0,0,0,,,0,0,0,0,,,0,0,0,0,TSLA
2024-11-01T08:00:01.257626533Z,2024-11-01T08:00:01.257461044Z,10,2,16244,C,B,0,250.250000000,50,130,165489,289773,249.100000000,251.140000000,1000,100,1,1,247.150000000,252.400000000,400,1000,1,1,235.000000000,253.650000000,100,400,1,1,,960.000000000,0,25,0,1,,,0,0,0,0,,,0,0,0,0,,,0,0,0,0,,,0,0,0,0,,,0,0,0,0,,,0,0,0,0,TSLA
2024-11-01T08:00:01.257640258Z,2024-11-01T08:00:01.257474236Z,10,2,16244,A,B,0,250.180000000,50,130,166022,289774,250.180000000,251.140000000,50,100,1,1,249.100000000,252.400000000,1000,1000,1,1,247.150000000,253.650000000,400,400,1,1,235.000000000,960.000000000,100,25,1,1,,,0,0,0,0,,,0,0,0,0,,,0,0,0,0,,,0,0,0,0,,,0,0,0,0,,,0,0,0,0,TSLA
2024-11-01T08:00:01.257711873Z,2024-11-01T08:00:01.257546474Z,10,2,16244,C,B,0,250.180000000,50,130,165399,289776,249.100000000,251.140000000,1000,100,1,1,247.150000000,252.400000000,400,1000,1,1,235.000000000,253.650000000,100,400,1,1,,960.000000000,0,25,0,1,,,0,0,0,0,,,0,0,0,0,,,0,0,0,0,,,0,0,0,0,,,0,0,0,0,,,0,0,0,0,TSLA
2024-11-01T08:00:01.260575799Z,2024-11-01T08:00:01.260409723Z,10,2,16244,A,B,0,249.400000000,1000,130,166076,289780,249.400000000,251.140000000,1000,100,1,1,249.100000000,252.400000000,1000,1000,1,1,247.150000000,253.650000000,400,400,1,1,235.000000000,960.000000000,100,25,1,1,,,0,0,0,0,,,0,0,0,0,,,0,0,0,0,,,0,0,0,0,,,0,0,0,0,,,0,0,0,0,TSLA
2024-11-01T08:00:01.260754015Z,2024-11-01T08:00:01.260588405Z,10,2,16244,C,B,1,249.100000000,1000,130,165610,289784,249.400000000,251.140000000,1000,100,1,1,247.150000000,252.400000000,400,1000,1,1,235.000000000,253.650000000,100,400,1,1,,960.000000000,0,25,0,1,,,0,0,0,0,,,0,0,0,0,,,0,0,0,0,,,0,0,0,0,,,0,0,0,0,,,0,0,0,0,TSLA
2024-11-01T08:00:01.299802595Z,2024-11-01T08:00:01.299636583Z,10,2,16244,A,B,0,249.500000000,1000,130,166012,289822,249.500000000,251.140000000,1000,100,1,1,249.400000000,252.400000000,1000,1000,1,1,247.150000000,253.650000000,400,400,1,1,235.000000000,960.000000000,100,25,1,1,,,0,0,0,0,,,0,0,0,0,,,0,0,0,0,,,0,0,0,0,,,0,0,0,0,,,0,0,0,0,TSLA
2024-11-01T08:00:01.299887425Z,2024-11-01T08:00:01.299721582Z,10,2,16244,C,B,1,249.400000000,1000,130,165843,289823,249.500000000,251.140000000,1000,100,1,1,247.150000000,252.400000000,400,1000,1,1,235.000000000,253.650000000,100,400,1,1,,960.000000000,0,25,0,1,,,0,0,0,0,,,0,0,0,0,,,0,0,0,0,,,0,0,0,0,,,0,0,0,0,,,0,0,0,0,TSLA
2024-11-01T08:00:01.334757259Z,2024-11-01T08:00:01.334591004Z,10,2,16244,A,B,0,249.600000000,1000,130,166255,289876,249.600000000,251.140000000,1000,100,1,1,249.500000000,252.400000000,1000,1000,1,1,247.150000000,253.650000000,400,400,1,1,235.000000000,960.000000000,100,25,1,1,,,0,0,0,0,,,0,0,0,0,,,0,0,0,0,,,0,0,0,0,,,0,0,0,0,,,0,0,0,0,TSLA
2024-11-01T08:00:01.334873314Z,2024-11-01T08:00:01.334707574Z,10,2,16244,C,B,1,249.500000000,1000,130,165740,289877,249.600000000,251.140000000,1000,100,1,1,247.150000000,252.400000000,400,1000,1,1,235.000000000,253.650000000,100,400,1,1,,960.000000000,0,25,0,1,,,0,0,0,0,,,0,0,0,0,,,0,0,0,0,,,0,0,0,0,,,0,0,0,0,,,0,0,0,0,TSLA
2024-11-01T08:00:01.421607851Z,2024-11-01T08:00:01.421441589Z,10,2,16244,A,B,0,250.310000000,50,130,166262,290276,250.310000000,251.140000000,50,100,1,1,249.600000000,252.400000000,1000,1000,1,1,247.150000000,253.650000000,400,400,1,1,235.000000000,960.000000000,100,25,1,1,,,0,0,0,0,,,0,0,0,0,,,0,0,0,0,,,0,0,0,0,,,0,0,0,0,,,0,0,0,0,TSLA
2024-11-01T08:00:01.472376727Z,2024-11-01T08:00:01.472210778Z,10,2,16244,A,B,0,250.340000000,50,130,165949,290611,250.340000000,251.140000000,50,100,1,1,249.600000000,252.400000000,1000,1000,1,1,247.150000000,253.650000000,400,400,1,1,235.000000000,960.000000000,100,25,1,1,,,0,0,0,0,,,0,0,0,0,,,0,0,0,0,,,0,0,0,0,,,0,0,0,0,,,0,0,0,0,TSLA
2024-11-01T08:00:01.472941909Z,2024-11-01T08:00:01.472776285Z,10,2,16244,C,B,1,249.600000000,1000,130,165624,290617,250.340000000,251.140000000,50,100,1,1,247.150000000,252.400000000,400,1000,1,1,235.000000000,253.650000000,100,400,1,1,,960.000000000,0,25,0,1,,,0,0,0,0,,,0,0,0,0,,,0,0,0,0,,,0,0,0,0,,,0,0,0,0,,,0,0,0,0,TSLA
2024-11-01T08:00:01.484355921Z,2024-11-01T08:00:01.484189995Z,10,2,16244,A,B,1,249.100000000,1000,130,165926,290642,250.340000000,251.140000000,50,100,1,1,249.100000000,252.400000000,1000,1000,1,1,247.150000000,253.650000000,400,400,1,1,235.000000000,960.000000000,100,25,1,1,,,0,0,0,0,,,0,0,0,0,,,0,0,0,0,,,0,0,0,0,,,0,0,0,0,,,0,0,0,0,TSLA
2024-11-01T08:00:01.532508123Z,2024-11-01T08:00:01.532342419Z,10,2,16244,C,B,0,250.340000000,50,130,165704,290695,249.100000000,251.140000000,1000,100,1,1,247.150000000,252.400000000,400,1000,1,1,235.000000000,253.650000000,100,400,1,1,,960.000000000,0,25,0,1,,,0,0,0,0,,,0,0,0,0,,,0,0,0,0,,,0,0,0,0,,,0,0,0,0,,,0,0,0,0,TSLA
2024-11-01T08:00:01.532521726Z,2024-11-01T08:00:01.532355375Z,10,2,16244,A,B,0,250.280000000,50,130,166351,290696,250.280000000,251.140000000,50,100,1,1,249.100000000,252.400000000,1000,1000,1,1,247.150000000,253.650000000,400,400,1,1,235.000000000,960.000000000,100,25,1,1,,,0,0,0,0,,,0,0,0,0,,,0,0,0,0,,,0,0,0,0,,,0,0,0,0,,,0,0,0,0,TSLA
2024-11-01T08:00:01.532601371Z,2024-11-01T08:00:01.532435839Z,10,2,16244,C,B,0,250.280000000,50,130,165532,290697,249.100000000,251.140000000,1000,100,1,1,247.150000000,252.400000000,400,1000,1,1,235.000000000,253.650000000,100,400,1,1,,960.000000000,0,25,0,1,,,0,0,0,0,,,0,0,0,0,,,0,0,0,0,,,0,0,0,0,,,0,0,0,0,,,0,0,0,0,TSLA
2024-11-01T08:00:01.532647825Z,2024-11-01T08:00:01.532481982Z,10,2,16244,A,B,0,250.230000000,50,130,165843,290698,250.230000000,251.140000000,50,100,1,1,249.100000000,252.400000000,1000,1000,1,1,247.150000000,253.650000000,400,400,1,1,235.000000000,960.000000000,100,25,1,1,,,0,0,0,0,,,0,0,0,0,,,0,0,0,0,,,0,0,0,0,,,0,0,0,0,,,0,0,0,0,TSLA
2024-11-01T08:00:01.533380248Z,2024-11-01T08:00:01.533213887Z,10,2,16244,A,B,1,249.400000000,1000,130,166361,290700,250.230000000,251.140000000,50,100,1,1,249.400000000,252.400000000,1000,1000,1,1,249.100000000,253.650000000,1000,400,1,1,247.150000000,960.000000000,400,25,1,1,235.000000000,,100,0,1,0,,,0,0,0,0,,,0,0,0,0,,,0,0,0,0,,,0,0,0,0,,,0,0,0,0,TSLA
2024-11-01T08:00:01.533475659Z,2024-11-01T08:00:01.533309394Z,10,2,16244,C,B,2,249.100000000,1000,130,166265,290702,250.230000000,251.140000000,50,100,1,1,249.400000000,252.400000000,1000,1000,1,1,247.150000000,253.650000000,400,400,1,1,235.000000000,960.000000000,100,25,1,1,,,0,0,0,0,,,0,0,0,0,,,0,0,0,0,,,0,0,0,0,,,0,0,0,0,,,0,0,0,0,TSLA
2024-11-01T08:00:01.579298891Z,2024-11-01T08:00:01.579132585Z,10,2,16244,A,B,1,249.500000000,1000,130,166306,290847,250.230000000,251.140000000,50,100,1,1,249.500000000,252.400000000,1000,1000,1,1,249.400000000,253.650000000,1000,400,1,1,247.150000000,960.000000000,400,25,1,1,235.000000000,,100,0,1,0,,,0,0,0,0,,,0,0,0,0,,,0,0,0,0,,,0,0,0,0,,,0,0,0,0,TSLA
2024-11-01T08:00:01.579386027Z,2024-11-01T08:00:01.579220012Z,10,2,16244,C,B,2,249.400000000,1000,130,166015,290848,250.230000000,251.140000000,50,100,1,1,249.500000000,252.400000000,1000,1000,1,1,247.150000000,253.650000000,400,400,1,1,235.000000000,960.000000000,100,25,1,1,,,0,0,0,0,,,0,0,0,0,,,0,0,0,0,,,0,0,0,0,,,0,0,0,0,,,0,0,0,0,TSLA
2024-11-01T08:00:01.604221479Z,2024-11-01T08:00:01.604055078Z,10,2,17709,A,B,1,115.260000000,100,130,166401,290886,115.280000000,118.320000000,856,856,1,1,115.260000000,,100,0,1,0,,,0,0,0,0,,,0,0,0,0,,,0,0,0,0,,,0,0,0,0,,,0,0,0,0,,,0,0,0,0,,,0,0,0,0,,,0,0,0,0,XOM
2024-11-01T08:00:01.657474188Z,2024-11-01T08:00:01.657307769Z,10,2,16244,A,B,0,250.310000000,50,130,166419,291006,250.310000000,251.140000000,50,100,1,1,249.500000000,252.400000000,1000,1000,1,1,247.150000000,253.650000000,400,400,1,1,235.000000000,960.000000000,100,25,1,1,,,0,0,0,0,,,0,0,0,0,,,0,0,0,0,,,0,0,0,0,,,0,0,0,0,,,0,0,0,0,TSLA
2024-11-01T08:00:01.660234697Z,2024-11-01T08:00:01.660068118Z,10,2,17709,A,B,0,115.320000000,100,130,166579,291019,115.320000000,118.320000000,100,856,1,1,115.280000000,,856,0,1,0,,,0,0,0,0,,,0,0,0,0,,,0,0,0,0,,,0,0,0,0,,,0,0,0,0,,,0,0,0,0,,,0,0,0,0,,,0,0,0,0,XOM
2024-11-01T08:00:01.660249179Z,2024-11-01T08:00:01.660082991Z,10,2,17709,A,A,1,118.600000000,100,130,166188,291020,115.320000000,118.320000000,100,856,1,1,115.280000000,118.600000000,856,100,1,1,,,0,0,0,0,,,0,0,0,0,,,0,0,0,0,,,0,0,0,0,,,0,0,0,0,,,0,0,0,0,,,0,0,0,0,,,0,0,0,0,XOM
2024-11-01T08:00:01.702424020Z,2024-11-01T08:00:01.702257693Z,10,2,11667,A,B,1,134.410000000,1,130,166327,291099,134.770000000,135.300000000,100,1000,1,1,134.410000000,136.100000000,1,1000,1,1,134.210000000,137.680000000,20,500,1,1,133.200000000,138.870000000,1000,1000,1,2,132.000000000,140.740000000,70,100,1,1,129.050000000,140.880000000,500,1000,1,2,128.470000000,143.690000000,500,500,1,1,127.000000000,146.510000000,20,5,1,1,,148.000000000,0,5,0,1,,,0,0,0,0,NVDA
2024-11-01T08:00:01.716519672Z,2024-11-01T08:00:01.716353332Z,10,2,16244,A,B,0,250.330000000,50,130,166340,291116,250.330000000,251.140000000,50,100,1,1,249.500000000,252.400000000,1000,1000,1,1,247.150000000,253.650000000,400,400,1,1,235.000000000,960.000000000,100,25,1,1,,,0,0,0,0,,,0,0,0,0,,,0,0,0,0,,,0,0,0,0,,,0,0,0,0,,,0,0,0,0,TSLA
2024-11-01T08:00:01.753221359Z,2024-11-01T08:00:01.753055198Z,10,2,11667,A,B,7,127.680000000,30,130,166161,291164,134.770000000,135.300000000,100,1000,1,1,134.410000000,136.100000000,1,1000,1,1,134.210000000,137.680000000,20,500,1,1,133.200000000,138.870000000,1000,1000,1,2,132.000000000,140.740000000,70,100,1,1,129.050000000,140.880000000,500,1000,1,2,128.470000000,143.690000000,500,500,1,1,127.680000000,146.510000000,30,5,1,1,127.000000000,148.000000000,20,5,1,1,,,0,0,0,0,NVDA
2024-11-01T08:00:01.798580328Z,2024-11-01T08:00:01.798414146Z,10,2,11667,A,B,4,132.000000000,1,130,166182,291209,134.770000000,135.300000000,100,1000,1,1,134.410000000,136.100000000,1,1000,1,1,134.210000000,137.680000000,20,500,1,1,133.200000000,138.870000000,1000,1000,1,2,132.000000000,140.740000000,71,100,2,1,129.050000000,140.880000000,500,1000,1,2,128.470000000,143.690000000,500,500,1,1,127.680000000,146.510000000,30,5,1,1,127.000000000,148.000000000,20,5,1,1,,,0,0,0,0,NVDA
2024-11-01T08:00:01.887177526Z,2024-11-01T08:00:01.887011820Z,10,2,16244,C,B,0,250.330000000,50,130,165706,291358,249.500000000,251.140000000,1000,100,1,1,247.150000000,252.400000000,400,1000,1,1,235.000000000,253.650000000,100,400,1,1,,960.000000000,0,25,0,1,,,0,0,0,0,,,0,0,0,0,,,0,0,0,0,,,0,0,0,0,,,0,0,0,0,,,0,0,0,0,TSLA
2024-11-01T08:00:01.938948169Z,2024-11-01T08:00:01.938781736Z,10,2,16244,A,B,0,249.600000000,1000,130,166433,291441,249.600000000,251.140000000,1000,100,1,1,249.500000000,252.400000000,1000,1000,1,1,247.150000000,253.650000000,400,400,1,1,235.000000000,960.000000000,100,25,1,1,,,0,0,0,0,,,0,0,0,0,,,0,0,0,0,,,0,0,0,0,,,0,0,0,0,,,0,0,0,0,TSLA
2024-11-01T08:00:01.939568626Z,2024-11-01T08:00:01.939402273Z,10,2,16244,C,B,1,249.500000000,1000,130,166353,291442,249.600000000,251.140000000,1000,100,1,1,247.150000000,252.400000000,400,1000,1,1,235.000000000,253.650000000,100,400,1,1,,960.000000000,0,25,0,1,,,0,0,0,0,,,0,0,0,0,,,0,0,0,0,,,0,0,0,0,,,0,0,0,0,,,0,0,0,0,TSLA
2024-11-01T08:00:01.946482277Z,2024-11-01T08:00:01.946315842Z,10,2,16244,A,B,0,250.200000000,50,130,166435,291446,250.200000000,251.140000000,50,100,1,1,249.600000000,252.400000000,1000,1000,1,1,247.150000000,253.650000000,400,400,1,1,235.000000000,960.000000000,100,25,1,1,,,0,0,0,0,,,0,0,0,0,,,0,0,0,0,,,0,0,0,0,,,0,0,0,0,,,0,0,0,0,TSLA
2024-11-01T08:00:01.946561239Z,2024-11-01T08:00:01.946395496Z,10,2,16244,C,B,0,250.200000000,50,130,165743,291447,249.600000000,251.140000000,1000,100,1,1,247.150000000,252.400000000,400,1000,1,1,235.000000000,253.650000000,100,400,1,1,,960.000000000,0,25,0,1,,,0,0,0,0,,,0,0,0,0,,,0,0,0,0,,,0,0,0,0,,,0,0,0,0,,,0,0,0,0,TSLA
2024-11-01T08:00:01.946573797Z,2024-11-01T08:00:01.946407831Z,10,2,16244,A,B,0,250.170000000,50,130,165966,291448,250.170000000,251.140000000,50,100,1,1,249.600000000,252.400000000,1000,1000,1,1,247.150000000,253.650000000,400,400,1,1,235.000000000,960.000000000,100,25,1,1,,,0,0,0,0,,,0,0,0,0,,,0,0,0,0,,,0,0,0,0,,,0,0,0,0,,,0,0,0,0,TSLA
2024-11-01T08:00:01.946600876Z,2024-11-01T08:00:01.946435553Z,10,2,16244,C,B,0,250.170000000,50,130,165323,291449,249.600000000,251.140000000,1000,100,1,1,247.150000000,252.400000000,400,1000,1,1,235.000000000,253.650000000,100,400,1,1,,960.000000000,0,25,0,1,,,0,0,0,0,,,0,0,0,0,,,0,0,0,0,,,0,0,0,0,,,0,0,0,0,,,0,0,0,0,TSLA
2024-11-01T08:00:01.947101210Z,2024-11-01T08:00:01.946935533Z,10,2,16244,C,B,0,249.600000000,1000,130,165677,291450,247.150000000,251.140000000,400,100,1,1,235.000000000,252.400000000,100,1000,1,1,,253.650000000,0,400,0,1,,960.000000000,0,25,0,1,,,0,0,0,0,,,0,0,0,0,,,0,0,0,0,,,0,0,0,0,,,0,0,0,0,,,0,0,0,0,TSLA
2024-11-01T08:00:01.958539201Z,2024-11-01T08:00:01.958372688Z,10,2,16244,A,B,0,249.400000000,1000,130,166513,291461,249.400000000,251.140000000,1000,100,1,1,247.150000000,252.400000000,400,1000,1,1,235.000000000,253.650000000,100,400,1,1,,960.000000000,0,25,0,1,,,0,0,0,0,,,0,0,0,0,,,0,0,0,0,,,0,0,0,0,,,0,0,0,0,,,0,0,0,0,TSLA
2024-11-01T08:00:01.987700128Z,2024-11-01T08:00:01.987534676Z,10,2,16244,C,B,0,249.400000000,1000,130,165452,291501,247.150000000,251.140000000,400,100,1,1,235.000000000,252.400000000,100,1000,1,1,,253.650000000,0,400,0,1,,960.000000000,0,25,0,1,,,0,0,0,0,,,0,0,0,0,,,0,0,0,0,,,0,0,0,0,,,0,0,0,0,,,0,0,0,0,TSLA
2024-11-01T08:00:01.997110302Z,2024-11-01T08:00:01.996944436Z,10,2,16244,A,A,1,251.400000000,1000,130,165866,291530,247.150000000,251.140000000,400,100,1,1,235.000000000,251.400000000,100,1000,1,1,,252.400000000,0,1000,0,1,,253.650000000,0,400,0,1,,960.000000000,0,25,0,1,,,0,0,0,0,,,0,0,0,0,,,0,0,0,0,,,0,0,0,0,,,0,0,0,0,TSLA
2024-11-01T08:00:01.997612898Z,2024-11-01T08:00:01.997446238Z,10,2,16244,C,A,1,251.400000000,1000,130,166660,291535,247.150000000,251.140000000,400,100,1,1,235.000000000,252.400000000,100,1000,1,1,,253.650000000,0,400,0,1,,960.000000000,0,25,0,1,,,0,0,0,0,,,0,0,0,0,,,0,0,0,0,,,0,0,0,0,,,0,0,0,0,,,0,0,0,0,TSLA
2024-11-01T08:00:02.016857213Z,2024-11-01T08:00:02.016691039Z,10,2,11667,A,B,1,134.730000000,61,130,166174,291570,134.770000000,135.300000000,100,1000,1,1,134.730000000,136.100000000,61,1000,1,1,134.410000000,137.680000000,1,500,1,1,134.210000000,138.870000000,20,1000,1,2,133.200000000,140.740000000,1000,100,1,1,132.000000000,140.880000000,71,1000,2,2,129.050000000,143.690000000,500,500,1,1,128.470000000,146.510000000,500,5,1,1,127.680000000,148.000000000,30,5,1,1,127.000000000,,20,0,1,0,NVDA
2024-11-01T08:00:02.025313199Z,2024-11-01T08:00:02.025146947Z,10,2,16244,A,B,0,249.800000000,1000,130,166252,291575,249.800000000,251.140000000,1000,100,1,1,247.150000000,252.400000000,400,1000,1,1,235.000000000,253.650000000,100,400,1,1,,960.000000000,0,25,0,1,,,0,0,0,0,,,0,0,0,0,,,0,0,0,0,,,0,0,0,0,,,0,0,0,0,,,0,0,0,0,TSLA
2024-11-01T08:00:02.026542310Z,2024-11-01T08:00:02.026376594Z,10,2,16244,C,B,0,249.800000000,1000,130,165716,291578,247.150000000,251.140000000,400,100,1,1,235.000000000,252.400000000,100,1000,1,1,,253.650000000,0,400,0,1,,960.000000000,0,25,0,1,,,0,0,0,0,,,0,0,0,0,,,0,0,0,0,,,0,0,0,0,,,0,0,0,0,,,0,0,0,0,TSLA
2024-11-01T08:00:02.037412574Z,2024-11-01T08:00:02.037246234Z,10,2,16244,A,B,0,249.800000000,1000,130,166340,291588,249.800000000,251.140000000,1000,100,1,1,247.150000000,252.400000000,400,1000,1,1,235.000000000,253.650000000,100,400,1,1,,960.000000000,0,25,0,1,,,0,0,0,0,,,0,0,0,0,,,0,0,0,0,,,0,0,0,0,,,0,0,0,0,,,0,0,0,0,TSLA
2024-11-01T08:00:02.040002923Z,2024-11-01T08:00:02.039837284Z,10,2,11667,C,B,1,134.730000000,61,130,165639,291600,134.770000000,135.300000000,100,1000,1,1,134.410000000,136.100000000,1,1000,1,1,134.210000000,137.680000000,20,500,1,1,133.200000000,138.870000000,1000,1000,1,2,132.000000000,140.740000000,71,100,2,1,129.050000000,140.880000000,500,1000,1,2,128.470000000,143.690000000,500,500,1,1,127.680000000,146.510000000,30,5,1,1,127.000000000,148.000000000,20,5,1,1,,,0,0,0,0,NVDA
2024-11-01T08:00:02.059422962Z,2024-11-01T08:00:02.059257397Z,10,2,16244,C,B,0,249.800000000,1000,130,165565,291627,247.150000000,251.140000000,400,100,1,1,235.000000000,252.400000000,100,1000,1,1,,253.650000000,0,400,0,1,,960.000000000,0,25,0,1,,,0,0,0,0,,,0,0,0,0,,,0,0,0,0,,,0,0,0,0,,,0,0,0,0,,,0,0,0,0,TSLA
2024-11-01T08:00:02.070468260Z,2024-11-01T08:00:02.070301937Z,10,2,16244,A,B,0,249.700000000,1000,130,166323,291635,249.700000000,251.140000000,1000,100,1,1,247.150000000,252.400000000,400,1000,1,1,235.000000000,253.650000000,100,400,1,1,,960.000000000,0,25,0,1,,,0,0,0,0,,,0,0,0,0,,,0,0,0,0,,,0,0,0,0,,,0,0,0,0,,,0,0,0,0,TSLA
2024-11-01T08:00:02.074574181Z,2024-11-01T08:00:02.074408476Z,10,2,16244,C,B,0,249.700000000,1000,130,165705,291641,247.150000000,251.140000000,400,100,1,1,235.000000000,252.400000000,100,1000,1,1,,253.650000000,0,400,0,1,,960.000000000,0,25,0,1,,,0,0,0,0,,,0,0,0,0,,,0,0,0,0,,,0,0,0,0,,,0,0,0,0,,,0,0,0,0,TSLA
2024-11-01T08:00:02.111309439Z,2024-11-01T08:00:02.111143168Z,10,2,16244,A,B,0,249.600000000,1000,130,166271,291698,249.600000000,251.140000000,1000,100,1,1,247.150000000,252.400000000,400,1000,1,1,235.000000000,253.650000000,100,400,1,1,,960.000000000,0,25,0,1,,,0,0,0,0,,,0,0,0,0,,,0,0,0,0,,,0,0,0,0,,,0,0,0,0,,,0,0,0,0,TSLA
2024-11-01T08:00:02.139266720Z,2024-11-01T08:00:02.139100235Z,10,2,16244,A,B,0,249.900000000,1000,130,166485,291729,249.900000000,251.140000000,1000,100,1,1,249.600000000,252.400000000,1000,1000,1,1,247.150000000,253.650000000,400,400,1,1,235.000000000,960.000000000,100,25,1,1,,,0,0,0,0,,,0,0,0,0,,,0,0,0,0,,,0,0,0,0,,,0,0,0,0,,,0,0,0,0,TSLA
2024-11-01T08:00:02.139322548Z,2024-11-01T08:00:02.139155746Z,10,2,16244,C,B,1,249.600000000,1000,130,166802,291730,249.900000000,251.140000000,1000,100,1,1,247.150000000,252.400000000,400,1000,1,1,235.000000000,253.650000000,100,400,1,1,,960.000000000,0,25,0,1,,,0,0,0,0,,,0,0,0,0,,,0,0,0,0,,,0,0,0,0,,,0,0,0,0,,,0,0,0,0,TSLA
2024-11-01T08:00:02.143874005Z,2024-11-01T08:00:02.143707801Z,10,2,16244,A,B,3,203.000000000,2,130,166204,291748,249.900000000,251.140000000,1000,100,1,1,247.150000000,252.400000000,400,1000,1,1,235.000000000,253.650000000,100,400,1,1,203.000000000,960.000000000,2,25,1,1,,,0,0,0,0,,,0,0,0,0,,,0,0,0,0,,,0,0,0,0,,,0,0,0,0,,,0,0,0,0,TSLA
2024-11-01T08:00:02.150347466Z,2024-11-01T08:00:02.150181297Z,10,2,16244,A,B,1,248.500000000,1000,130,166169,291750,249.900000000,251.140000000,1000,100,1,1,248.500000000,252.400000000,1000,1000,1,1,247.150000000,253.650000000,400,400,1,1,235.000000000,960.000000000,100,25,1,1,203.000000000,,2,0,1,0,,,0,0,0,0,,,0,0,0,0,,,0,0,0,0,,,0,0,0,0,,,0,0,0,0,TSLA
2024-11-01T08:00:02.160208746Z,2024-11-01T08:00:02.160042857Z,10,2,16244,C,B,1,248.500000000,1000,130,165889,291766,249.900000000,251.140000000,1000,100,1,1,247.150000000,252.400000000,400,1000,1,1,235.000000000,253.650000000,100,400,1,1,203.000000000,960.000000000,2,25,1,1,,,0,0,0,0,,,0,0,0,0,,,0,0,0,0,,,0,0,0,0,,,0,0,0,0,,,0,0,0,0,TSLA
2024-11-01T08:00:02.160509269Z,2024-11-01T08:00:02.160343613Z,10,2,16244,C,B,0,249.900000000,1000,130,165656,291767,247.150000000,251.140000000,400,100,1,1,235.000000000,252.400000000,100,1000,1,1,203.000000000,253.650000000,2,400,1,1,,960.000000000,0,25,0,1,,,0,0,0,0,,,0,0,0,0,,,0,0,0,0,,,0,0,0,0,,,0,0,0,0,,,0,0,0,0,TSLA
2024-11-01T08:00:02.171672991Z,2024-11-01T08:00:02.171506732Z,10,2,16244,A,B,0,249.800000000,1000,130,166259,291778,249.800000000,251.140000000,1000,100,1,1,247.150000000,252.400000000,400,1000,1,1,235.000000000,253.650000000,100,400,1,1,203.000000000,960.000000000,2,25,1,1,,,0,0,0,0,,,0,0,0,0,,,0,0,0,0,,,0,0,0,0,,,0,0,0,0,,,0,0,0,0,TSLA
2024-11-01T08:00:02.189343537Z,2024-11-01T08:00:02.189177936Z,10,2,16244,C,B,0,249.800000000,1000,130,165601,291802,247.150000000,251.140000000,400,100,1,1,235.000000000,252.400000000,100,1000,1,1,203.000000000,253.650000000,2,400,1,1,,960.000000000,0,25,0,1,,,0,0,0,0,,,0,0,0,0,,,0,0,0,0,,,0,0,0,0,,,0,0,0,0,,,0,0,0,0,TSLA
2024-11-01T08:00:02.200278583Z,2024-11-01T08:00:02.200112430Z,10,2,16244,A,B,0,249.700000000,1000,130,166153,291816,249.700000000,251.140000000,1000,100,1,1,247.150000000,252.400000000,400,1000,1,1,235.000000000,253.650000000,100,400,1,1,203.000000000,960.000000000,2,25,1,1,,,0,0,0,0,,,0,0,0,0,,,0,0,0,0,,,0,0,0,0,,,0,0,0,0,,,0,0,0,0,TSLA
2024-11-01T08:00:02.306823519Z,2024-11-01T08:00:02.306655672Z,10,2,16244,A,B,0,249.930000000,50,130,167847,291894,249.930000000,251.140000000,50,100,1,1,249.700000000,252.400000000,1000,1000,1,1,247.150000000,253.650000000,400,400,1,1,235.000000000,960.000000000,100,25,1,1,203.000000000,,2,0,1,0,,,0,0,0,0,,,0,0,0,0,,,0,0,0,0,,,0,0,0,0,,,0,0,0,0,TSLA
2024-11-01T08:00:02.326848147Z,2024-11-01T08:00:02.326682484Z,10,2,16244,C,B,0,249.930000000,50,130,165663,291910,249.700000000,251.140000000,1000,100,1,1,247.150000000,252.400000000,400,1000,1,1,235.000000000,253.650000000,100,400,1,1,203.000000000,960.000000000,2,25,1,1,,,0,0,0,0,,,0,0,0,0,,,0,0,0,0,,,0,0,0,0,,,0,0,0,0,,,0,0,0,0,TSLA
2024-11-01T08:00:02.429223051Z,2024-11-01T08:00:02.429057207Z,10,2,16244,A,B,0,250.030000000,50,130,165844,292086,250.030000000,251.140000000,50,100,1,1,249.700000000,252.400000000,1000,1000,1,1,247.150000000,253.650000000,400,400,1,1,235.000000000,960.000000000,100,25,1,1,203.000000000,,2,0,1,0,,,0,0,0,0,,,0,0,0,0,,,0,0,0,0,,,0,0,0,0,,,0,0,0,0,TSLA
2024-11-01T08:00:02.432420114Z,2024-11-01T08:00:02.432254479Z,10,2,16244,C,B,0,250.030000000,50,130,165635,292107,249.700000000,251.140000000,1000,100,1,1,247.150000000,252.400000000,400,1000,1,1,235.000000000,253.650000000,100,400,1,1,203.000000000,960.000000000,2,25,1,1,,,0,0,0,0,,,0,0,0,0,,,0,0,0,0,,,0,0,0,0,,,0,0,0,0,,,0,0,0,0,TSLA
2024-11-01T08:00:02.432433721Z,2024-11-01T08:00:02.432267658Z,10,2,16244,A,B,0,250.020000000,50,130,166063,292108,250.020000000,251.140000000,50,100,1,1,249.700000000,252.400000000,1000,1000,1,1,247.150000000,253.650000000,400,400,1,1,235.000000000,960.000000000,100,25,1,1,203.000000000,,2,0,1,0,,,0,0,0,0,,,0,0,0,0,,,0,0,0,0,,,0,0,0,0,,,0,0,0,0,TSLA
2024-11-01T08:00:02.432505603Z,2024-11-01T08:00:02.432340214Z,10,2,16244,C,B,0,250.020000000,50,130,165389,292110,249.700000000,251.140000000,1000,100,1,1,247.150000000,252.400000000,400,1000,1,1,235.000000000,253.650000000,100,400,1,1,203.000000000,960.000000000,2,25,1,1,,,0,0,0,0,,,0,0,0,0,,,0,0,0,0,,,0,0,0,0,,,0,0,0,0,,,0,0,0,0,TSLA
2024-11-01T08:00:02.432528850Z,2024-11-01T08:00:02.432362700Z,10,2,16244,A,B,0,249.880000000,50,130,166150,292111,249.880000000,251.140000000,50,100,1,1,249.700000000,252.400000000,1000,1000,1,1,247.150000000,253.650000000,400,400,1,1,235.000000000,960.000000000,100,25,1,1,203.000000000,,2,0,1,0,,,0,0,0,0,,,0,0,0,0,,,0,0,0,0,,,0,0,0,0,,,0,0,0,0,TSLA
2024-11-01T08:00:02.432570044Z,2024-11-01T08:00:02.432404499Z,10,2,16244,C,B,0,249.880000000,50,130,165545,292112,249.700000000,251.140000000,1000,100,1,1,247.150000000,252.400000000,400,1000,1,1,235.000000000,253.650000000,100,400,1,1,203.000000000,960.000000000,2,25,1,1,,,0,0,0,0,,,0,0,0,0,,,0,0,0,0,,,0,0,0,0,,,0,0,0,0,,,0,0,0,0,TSLA
2024-11-01T08:00:02.432582033Z,2024-11-01T08:00:02.432416301Z,10,2,16244,A,B,1,249.680000000,50,130,165732,292113,249.700000000,251.140000000,1000,100,1,1,249.680000000,252.400000000,50,1000,1,1,247.150000000,253.650000000,400,400,1,1,235.000000000,960.000000000,100,25,1,1,203.000000000,,2,0,1,0,,,0,0,0,0,,,0,0,0,0,,,0,0,0,0,,,0,0,0,0,,,0,0,0,0,TSLA
2024-11-01T08:00:02.432613196Z,2024-11-01T08:00:02.432447734Z,10,2,16244,C,B,1,249.680000000,50,130,165462,292114,249.700000000,251.140000000,1000,100,1,1,247.150000000,252.400000000,400,1000,1,1,235.000000000,253.650000000,100,400,1,1,203.000000000,960.000000000,2,25,1,1,,,0,0,0,0,,,0,0,0,0,,,0,0,0,0,,,0,0,0,0,,,0,0,0,0,,,0,0,0,0,TSLA
2024-11-01T08:00:02.508790806Z,2024-11-01T08:00:02.508624558Z,10,2,16244,C,B,0,249.700000000,1000,130,166248,292194,247.150000000,251.140000000,400,100,1,1,235.000000000,252.400000000,100,1000,1,1,203.000000000,253.650000000,2,400,1,1,,960.000000000,0,25,0,1,,,0,0,0,0,,,0,0,0,0,,,0,0,0,0,,,0,0,0,0,,,0,0,0,0,,,0,0,0,0,TSLA
2024-11-01T08:00:02.519427424Z,2024-11-01T08:00:02.519261287Z,10,2,16244,A,B,0,249.500000000,1000,130,166137,292210,249.500000000,251.140000000,1000,100,1,1,247.150000000,252.400000000,400,1000,1,1,235.000000000,253.650000000,100,400,1,1,203.000000000,960.000000000,2,25,1,1,,,0,0,0,0,,,0,0,0,0,,,0,0,0,0,,,0,0,0,0,,,0,0,0,0,,,0,0,0,0,TSLA
2024-11-01T08:00:02.542468800Z,2024-11-01T08:00:02.542301121Z,10,2,16244,A,B,0,249.700000000,1000,130,167679,292261,249.700000000,251.140000000,1000,100,1,1,249.500000000,252.400000000,1000,1000,1,1,247.150000000,253.650000000,400,400,1,1,235.000000000,960.000000000,100,25,1,1,203.000000000,,2,0,1,0,,,0,0,0,0,,,0,0,0,0,,,0,0,0,0,,,0,0,0,0,,,0,0,0,0,TSLA
2024-11-01T08:00:02.542514357Z,2024-11-01T08:00:02.542348590Z,10,2,16244,C,B,1,249.500000000,1000,130,165767,292262,249.700000000,251.140000000,1000,100,1,1,247.150000000,252.400000000,400,1000,1,1,235.000000000,253.650000000,100,400,1,1,203.000000000,960.000000000,2,25,1,1,,,0,0,0,0,,,0,0,0,0,,,0,0,0,0,,,0,0,0,0,,,0,0,0,0,,,0,0,0,0,TSLA
2024-11-01T08:00:02.546283531Z,2024-11-01T08:00:02.546117257Z,10,2,16244,A,A,1,252.100000000,1000,130,166274,292268,249.700000000,251.140000000,1000,100,1,1,247.150000000,252.100000000,400,1000,1,1,235.000000000,252.400000000,100,1000,1,1,203.000000000,253.650000000,2,400,1,1,,960.000000000,0,25,0,1,,,0,0,0,0,,,0,0,0,0,,,0,0,0,0,,,0,0,0,0,,,0,0,0,0,TSLA
2024-11-01T08:00:02.546320207Z,2024-11-01T08:00:02.546154333Z,10,2,16244,C,A,2,252.400000000,1000,130,165874,292269,249.700000000,251.140000000,1000,100,1,1,247.150000000,252.100000000,400,1000,1,1,235.000000000,253.650000000,100,400,1,1,203.000000000,960.000000000,2,25,1,1,,,0,0,0,0,,,0,0,0,0,,,0,0,0,0,,,0,0,0,0,,,0,0,0,0,,,0,0,0,0,TSLA
2024-11-01T08:00:02.546605793Z,2024-11-01T08:00:02.546439522Z,10,2,16244,A,A,0,251.140000000,100,130,166271,292273,249.700000000,251.140000000,1000,200,1,2,247.150000000,252.100000000,400,1000,1,1,235.000000000,253.650000000,100,400,1,1,203.000000000,960.000000000,2,25,1,1,,,0,0,0,0,,,0,0,0,0,,,0,0,0,0,,,0,0,0,0,,,0,0,0,0,,,0,0,0,0,TSLA
2024-11-01T08:00:02.553143352Z,2024-11-01T08:00:02.552977007Z,10,2,16244,A,B,1,249.300000000,1000,130,166345,292282,249.700000000,251.140000000,1000,200,1,2,249.300000000,252.100000000,1000,1000,1,1,247.150000000,253.650000000,400,400,1,1,235.000000000,960.000000000,100,25,1,1,203.000000000,,2,0,1,0,,,0,0,0,0,,,0,0,0,0,,,0,0,0,0,,,0,0,0,0,,,0,0,0,0,TSLA
2024-11-01T08:00:02.571609303Z,2024-11-01T08:00:02.571443429Z,10,2,16244,C,A,1,252.100000000,1000,130,165874,292311,249.700000000,251.140000000,1000,200,1,2,249.300000000,253.650000000,1000,400,1,1,247.150000000,960.000000000,400,25,1,1,235.000000000,,100,0,1,0,203.000000000,,2,0,1,0,,,0,0,0,0,,,0,0,0,0,,,0,0,0,0,,,0,0,0,0,,,0,0,0,0,TSLA
2024-11-01T08:00:02.578965142Z,2024-11-01T08:00:02.578798865Z,10,2,16244,A,B,1,249.520000000,50,130,166277,292318,249.700000000,251.140000000,1000,200,1,2,249.520000000,253.650000000,50,400,1,1,249.300000000,960.000000000,1000,25,1,1,247.150000000,,400,0,1,0,235.000000000,,100,0,1,0,203.000000000,,2,0,1,0,,,0,0,0,0,,,0,0,0,0,,,0,0,0,0,,,0,0,0,0,TSLA
2024-11-01T08:00:02.582249857Z,2024-11-01T08:00:02.582083710Z,10,2,16244,A,A,1,252.300000000,1000,130,166147,292323,249.700000000,251.140000000,1000,200,1,2,249.520000000,252.300000000,50,1000,1,1,249.300000000,253.650000000,1000,400,1,1,247.150000000,960.000000000,400,25,1,1,235.000000000,,100,0,1,0,203.000000000,,2,0,1,0,,,0,0,0,0,,,0,0,0,0,,,0,0,0,0,,,0,0,0,0,TSLA
2024-11-01T08:00:02.603637970Z,2024-11-01T08:00:02.603472261Z,10,2,16244,C,B,1,249.520000000,50,130,165709,292342,249.700000000,251.140000000,1000,200,1,2,249.300000000,252.300000000,1000,1000,1,1,247.150000000,253.650000000,400,400,1,1,235.000000000,960.000000000,100,25,1,1,203.000000000,,2,0,1,0,,,0,0,0,0,,,0,0,0,0,,,0,0,0,0,,,0,0,0,0,,,0,0,0,0,TSLA
2024-11-01T08:00:02.607204031Z,2024-11-01T08:00:02.607037998Z,10,2,16244,C,A,0,251.140000000,100,130,166033,292348,249.700000000,251.140000000,1000,100,1,1,249.300000000,252.300000000,1000,1000,1,1,247.150000000,253.650000000,400,400,1,1,235.000000000,960.000000000,100,25,1,1,203.000000000,,2,0,1,0,,,0,0,0,0,,,0,0,0,0,,,0,0,0,0,,,0,0,0,0,,,0,0,0,0,TSLA
2024-11-01T08:00:02.607227477Z,2024-11-01T08:00:02.607060809Z,10,2,16244,A,A,0,250.940000000,100,130,166668,292349,249.700000000,250.940000000,1000,100,1,1,249.300000000,252.300000000,1000,1000,1,1,247.150000000,253.650000000,400,400,1,1,235.000000000,960.000000000,100,25,1,1,203.000000000,,2,0,1,0,,,0,0,0,0,,,0,0,0,0,,,0,0,0,0,,,0,0,0,0,,,0,0,0,0,TSLA
2024-11-01T08:00:02.640478961Z,2024-11-01T08:00:02.640312645Z,10,2,10888,A,A,1,420.000000000,3,130,166316,292410,404.410000000,415.070000000,246,246,1,1,,420.000000000,0,3,0,1,,468.000000000,0,65,0,1,,,0,0,0,0,,,0,0,0,0,,,0,0,0,0,,,0,0,0,0,,,0,0,0,0,,,0,0,0,0,,,0,0,0,0,MSFT
2024-11-01T08:00:02.648988454Z,2024-11-01T08:00:02.648822101Z,10,2,16244,A,B,1,249.600000000,1000,130,166353,292419,249.700000000,250.940000000,1000,100,1,1,249.600000000,252.300000000,1000,1000,1,1,249.300000000,253.650000000,1000,400,1,1,247.150000000,960.000000000,400,25,1,1,235.000000000,,100,0,1,0,203.000000000,,2,0,1,0,,,0,0,0,0,,,0,0,0,0,,,0,0,0,0,,,0,0,0,0,TSLA
2024-11-01T08:00:02.649909893Z,2024-11-01T08:00:02.649743714Z,10,2,16244,A,A,0,250.940000000,100,130,166179,292421,249.700000000,250.940000000,1000,200,1,2,249.600000000,252.300000000,1000,1000,1,1,249.300000000,253.650000000,1000,400,1,1,247.150000000,960.000000000,400,25,1,1,235.000000000,,100,0,1,0,203.000000000,,2,0,1,0,,,0,0,0,0,,,0,0,0,0,,,0,0,0,0,,,0,0,0,0,TSLA
2024-11-01T08:00:02.659428370Z,2024-11-01T08:00:02.659262625Z,10,2,16244,C,B,2,249.300000000,1000,130,165745,292453,249.700000000,250.940000000,1000,200,1,2,249.600000000,252.300000000,1000,1000,1,1,247.150000000,253.650000000,400,400,1,1,235.000000000,960.000000000,100,25,1,1,203.000000000,,2,0,1,0,,,0,0,0,0,,,0,0,0,0,,,0,0,0,0,,,0,0,0,0,,,0,0,0,0,TSLA
2024-11-01T08:00:02.659429599Z,2024-11-01T08:00:02.659263539Z,10,2,16244,A,B,2,249.500000000,1000,130,166060,292454,249.700000000,250.940000000,1000,200,1,2,249.600000000,252.300000000,1000,1000,1,1,249.500000000,253.650000000,1000,400,1,1,247.150000000,960.000000000,400,25,1,1,235.000000000,,100,0,1,0,203.000000000,,2,0,1,0,,,0,0,0,0,,,0,0,0,0,,,0,0,0,0,,,0,0,0,0,TSLA
2024-11-01T08:00:02.690780625Z,2024-11-01T08:00:02.690614817Z,10,2,16244,C,B,2,249.500000000,1000,130,165808,292490,249.700000000,250.940000000,1000,200,1,2,249.600000000,252.300000000,1000,1000,1,1,247.150000000,253.650000000,400,400,1,1,235.000000000,960.000000000,100,25,1,1,203.000000000,,2,0,1,0,,,0,0,0,0,,,0,0,0,0,,,0,0,0,0,,,0,0,0,0,,,0,0,0,0,TSLA
2024-11-01T08:00:02.701304590Z,2024-11-01T08:00:02.701138373Z,10,2,16244,A,B,0,249.800000000,1000,130,166217,292499,249.800000000,250.940000000,1000,200,1,2,249.700000000,252.300000000,1000,1000,1,1,249.600000000,253.650000000,1000,400,1,1,247.150000000,960.000000000,400,25,1,1,235.000000000,,100,0,1,0,203.000000000,,2,0,1,0,,,0,0,0,0,,,0,0,0,0,,,0,0,0,0,,,0,0,0,0,TSLA
2024-11-01T08:00:02.701353470Z,2024-11-01T08:00:02.701187733Z,10,2,16244,C,B,1,249.700000000,1000,130,165737,292500,249.800000000,250.940000000,1000,200,1,2,249.600000000,252.300000000,1000,1000,1,1,247.150000000,253.650000000,400,400,1,1,235.000000000,960.000000000,100,25,1,1,203.000000000,,2,0,1,0,,,0,0,0,0,,,0,0,0,0,,,0,0,0,0,,,0,0,0,0,,,0,0,0,0,TSLA
2024-11-01T08:00:02.710429594Z,2024-11-01T08:00:02.710263894Z,10,2,16244,C,A,0,250.940000000,100,130,165700,292504,249.800000000,250.940000000,1000,100,1,1,249.600000000,252.300000000,1000,1000,1,1,247.150000000,253.650000000,400,400,1,1,235.000000000,960.000000000,100,25,1,1,203.000000000,,2,0,1,0,,,0,0,0,0,,,0,0,0,0,,,0,0,0,0,,,0,0,0,0,,,0,0,0,0,TSLA
2024-11-01T08:00:02.710450991Z,2024-11-01T08:00:02.710284708Z,10,2,16244,A,A,0,250.830000000,100,130,166283,292505,249.800000000,250.830000000,1000,100,1,1,249.600000000,252.300000000,1000,1000,1,1,247.150000000,253.650000000,400,400,1,1,235.000000000,960.000000000,100,25,1,1,203.000000000,,2,0,1,0,,,0,0,0,0,,,0,0,0,0,,,0,0,0,0,,,0,0,0,0,,,0,0,0,0,TSLA
2024-11-01T08:00:02.710481000Z,2024-11-01T08:00:02.710313713Z,10,2,16244,A,B,1,249.600000000,50,130,167287,292506,249.800000000,250.830000000,1000,100,1,1,249.600000000,252.300000000,1050,1000,2,1,247.150000000,253.650000000,400,400,1,1,235.000000000,960.000000000,100,25,1,1,203.000000000,,2,0,1,0,,,0,0,0,0,,,0,0,0,0,,,0,0,0,0,,,0,0,0,0,,,0,0,0,0,TSLA
2024-11-01T08:00:02.721528719Z,2024-11-01T08:00:02.721362015Z,10,2,16244,A,B,2,248.700000000,1000,130,166704,292528,249.800000000,250.830000000,1000,100,1,1,249.600000000,252.300000000,1050,1000,2,1,248.700000000,253.650000000,1000,400,1,1,247.150000000,960.000000000,400,25,1,1,235.000000000,,100,0,1,0,203.000000000,,2,0,1,0,,,0,0,0,0,,,0,0,0,0,,,0,0,0,0,,,0,0,0,0,TSLA
2024-11-01T08:00:02.721574031Z,2024-11-01T08:00:02.721408022Z,10,2,16244,A,B,1,249.600000000,50,130,166009,292529,249.800000000,250.830000000,1000,100,1,1,249.600000000,252.300000000,1100,1000,3,1,248.700000000,253.650000000,1000,400,1,1,247.150000000,960.000000000,400,25,1,1,235.000000000,,100,0,1,0,203.000000000,,2,0,1,0,,,0,0,0,0,,,0,0,0,0,,,0,0,0,0,,,0,0,0,0,TSLA
2024-11-01T08:00:02.721791756Z,2024-11-01T08:00:02.721626204Z,10,2,16244,C,B,2,248.700000000,1000,130,165552,292531,249.800000000,250.830000000,1000,100,1,1,249.600000000,252.300000000,1100,1000,3,1,247.150000000,253.650000000,400,400,1,1,235.000000000,960.000000000,100,25,1,1,203.000000000,,2,0,1,0,,,0,0,0,0,,,0,0,0,0,,,0,0,0,0,,,0,0,0,0,,,0,0,0,0,TSLA
2024-11-01T08:00:02.732345694Z,2024-11-01T08:00:02.732179390Z,10,2,16244,A,B,2,248.500000000,1000,130,166304,292547,249.800000000,250.830000000,1000,100,1,1,249.600000000,252.300000000,1100,1000,3,1,248.500000000,253.650000000,1000,400,1,1,247.150000000,960.000000000,400,25,1,1,235.000000000,,100,0,1,0,203.000000000,,2,0,1,0,,,0,0,0,0,,,0,0,0,0,,,0,0,0,0,,,0,0,0,0,TSLA
2024-11-01T08:00:02.769927085Z,2024-11-01T08:00:02.769760727Z,10,2,16244,C,B,1,249.600000000,50,130,166358,292585,249.800000000,250.830000000,1000,100,1,1,249.600000000,252.300000000,1050,1000,2,1,248.500000000,253.650000000,1000,400,1,1,247.150000000,960.000000000,400,25,1,1,235.000000000,,100,0,1,0,203.000000000,,2,0,1,0,,,0,0,0,0,,,0,0,0,0,,,0,0,0,0,,,0,0,0,0,TSLA
2024-11-01T08:00:02.769946788Z,2024-11-01T08:00:02.769780516Z,10,2,16244,A,B,1,249.610000000,100,130,166272,292586,249.800000000,250.830000000,1000,100,1,1,249.610000000,252.300000000,100,1000,1,1,249.600000000,253.650000000,1000,400,1,1,248.500000000,960.000000000,1000,25,1,1,247.150000000,,400,0,1,0,235.000000000,,100,0,1,0,203.000000000,,2,0,1,0,,,0,0,0,0,,,0,0,0,0,,,0,0,0,0,TSLA
2024-11-01T08:00:02.781101894Z,2024-11-01T08:00:02.780935559Z,10,2,16244,A,B,0,249.870000000,50,130,166335,292595,249.870000000,250.830000000,50,100,1,1,249.800000000,252.300000000,1000,1000,1,1,249.600000000,253.650000000,1000,400,1,1,248.500000000,960.000000000,1000,25,1,1,247.150000000,,400,0,1,0,235.000000000,,100,0,1,0,203.000000000,,2,0,1,0,,,0,0,0,0,,,0,0,0,0,,,0,0,0,0,TSLA
2024-11-01T08:00:02.813321525Z,2024-11-01T08:00:02.813155243Z,10,2,16244,A,B,7,170.000000000,3,130,166282,292603,249.870000000,250.830000000,50,100,1,1,249.800000000,252.300000000,1000,1000,1,1,249.600000000,253.650000000,1000,400,1,1,248.500000000,960.000000000,1000,25,1,1,247.150000000,,400,0,1,0,235.000000000,,100,0,1,0,203.000000000,,2,0,1,0,170.000000000,,3,0,1,0,,,0,0,0,0,,,0,0,0,0,TSLA
2024-11-01T08:00:02.819310866Z,2024-11-01T08:00:02.819145368Z,10,2,16244,C,B,0,249.870000000,50,130,165498,292610,249.800000000,250.830000000,1000,100,1,1,249.600000000,252.300000000,1000,1000,1,1,248.500000000,253.650000000,1000,400,1,1,247.150000000,960.000000000,400,25,1,1,235.000000000,,100,0,1,0,203.000000000,,2,0,1,0,170.000000000,,3,0,1,0,,,0,0,0,0,,,0,0,0,0,,,0,0,0,0,TSLA
2024-11-01T08:00:02.819580129Z,2024-11-01T08:00:02.819414326Z,10,2,16244,C,B,2,248.500000000,1000,130,165803,292611,249.800000000,250.830000000,1000,100,1,1,249.600000000,252.300000000,1000,1000,1,1,247.150000000,253.650000000,400,400,1,1,235.000000000,960.000000000,100,25,1,1,203.000000000,,2,0,1,0,170.000000000,,3,0,1,0,,,0,0,0,0,,,0,0,0,0,,,0,0,0,0,,,0,0,0,0,TSLA
2024-11-01T08:00:02.819973569Z,2024-11-01T08:00:02.819806929Z,10,2,16244,A,A,0,250.430000000,13,130,166640,292612,249.800000000,250.430000000,1000,13,1,1,249.600000000,250.830000000,1000,100,1,1,247.150000000,252.300000000,400,1000,1,1,235.000000000,253.650000000,100,400,1,1,203.000000000,960.000000000,2,25,1,1,170.000000000,,3,0,1,0,,,0,0,0,0,,,0,0,0,0,,,0,0,0,0,,,0,0,0,0,TSLA
2024-11-01T08:00:02.819984926Z,2024-11-01T08:00:02.819819196Z,10,2,16244,C,A,0,250.430000000,13,130,165730,292613,249.800000000,250.830000000,1000,100,1,1,249.600000000,252.300000000,1000,1000,1,1,247.150000000,253.650000000,400,400,1,1,235.000000000,960.000000000,100,25,1,1,203.000000000,,2,0,1,0,170.000000000,,3,0,1,0,,,0,0,0,0,,,0,0,0,0,,,0,0,0,0,,,0,0,0,0,TSLA
2024-11-01T08:00:02.821250331Z,2024-11-01T08:00:02.821084428Z,10,2,16244,C,B,0,249.800000000,1000,130,165903,292616,249.600000000,250.830000000,1000,100,1,1,247.150000000,252.300000000,400,1000,1,1,235.000000000,253.650000000,100,400,1,1,203.000000000,960.000000000,2,25,1,1,170.000000000,,3,0,1,0,,,0,0,0,0,,,0,0,0,0,,,0,0,0,0,,,0,0,0,0,,,0,0,0,0,TSLA
2024-11-01T08:00:02.830665898Z,2024-11-01T08:00:02.830499730Z,10,2,16244,A,A,0,250.830000000,100,130,166168,292626,249.600000000,250.830000000,1000,200,1,2,247.150000000,252.300000000,400,1000,1,1,235.000000000,253.650000000,100,400,1,1,203.000000000,960.000000000,2,25,1,1,170.000000000,,3,0,1,0,,,0,0,0,0,,,0,0,0,0,,,0,0,0,0,,,0,0,0,0,,,0,0,0,0,TSLA
2024-11-01T08:00:02.844290141Z,2024-11-01T08:00:02.844123787Z,10,2,16244,A,A,1,252.200000000,1000,130,166354,292637,249.600000000,250.830000000,1000,200,1,2,247.150000000,252.200000000,400,1000,1,1,235.000000000,252.300000000,100,1000,1,1,203.000000000,253.650000000,2,400,1,1,170.000000000,960.000000000,3,25,1,1,,,0,0,0,0,,,0,0,0,0,,,0,0,0,0,,,0,0,0,0,,,0,0,0,0,TSLA
2024-11-01T08:00:02.844344811Z,2024-11-01T08:00:02.844178721Z,10,2,16244,C,A,2,252.300000000,1000,130,166090,292638,249.600000000,250.830000000,1000,200,1,2,247.150000000,252.200000000,400,1000,1,1,235.000000000,253.650000000,100,400,1,1,203.000000000,960.000000000,2,25,1,1,170.000000000,,3,0,1,0,,,0,0,0,0,,,0,0,0,0,,,0,0,0,0,,,0,0,0,0,,,0,0,0,0,TSLA
2024-11-01T08:00:02.858272469Z,2024-11-01T08:00:02.858106249Z,10,2,16244,A,B,1,249.100000000,1000,130,166220,292648,249.600000000,250.830000000,1000,200,1,2,249.100000000,252.200000000,1000,1000,1,1,247.150000000,253.650000000,400,400,1,1,235.000000000,960.000000000,100,25,1,1,203.000000000,,2,0,1,0,170.000000000,,3,0,1,0,,,0,0,0,0,,,0,0,0,0,,,0,0,0,0,,,0,0,0,0,TSLA
2024-11-01T08:00:02.895223166Z,2024-11-01T08:00:02.895056773Z,10,2,17709,A,B,0,116.000000000,100,130,166393,292817,116.000000000,118.320000000,100,856,1,1,115.320000000,118.600000000,100,100,1,1,115.280000000,,856,0,1,0,,,0,0,0,0,,,0,0,0,0,,,0,0,0,0,,,0,0,0,0,,,0,0,0,0,,,0,0,0,0,,,0,0,0,0,XOM
2024-11-01T08:00:02.895656804Z,2024-11-01T08:00:02.895491059Z,10,2,16244,C,A,0,250.830000000,100,130,165745,292819,249.600000000,250.830000000,1000,100,1,1,249.100000000,252.200000000,1000,1000,1,1,247.150000000,253.650000000,400,400,1,1,235.000000000,960.000000000,100,25,1,1,203.000000000,,2,0,1,0,170.000000000,,3,0,1,0,,,0,0,0,0,,,0,0,0,0,,,0,0,0,0,,,0,0,0,0,TSLA
2024-11-01T08:00:02.895686744Z,2024-11-01T08:00:02.895520294Z,10,2,16244,A,A,0,250.730000000,100,130,166450,292820,249.600000000,250.730000000,1000,100,1,1,249.100000000,252.200000000,1000,1000,1,1,247.150000000,253.650000000,400,400,1,1,235.000000000,960.000000000,100,25,1,1,203.000000000,,2,0,1,0,170.000000000,,3,0,1,0,,,0,0,0,0,,,0,0,0,0,,,0,0,0,0,,,0,0,0,0,TSLA
2024-11-01T08:00:02.923206986Z,2024-11-01T08:00:02.923040840Z,10,2,16244,A,B,0,249.870000000,50,130,166146,292854,249.870000000,250.730000000,50,100,1,1,249.600000000,252.200000000,1000,1000,1,1,249.100000000,253.650000000,1000,400,1,1,247.150000000,960.000000000,400,25,1,1,235.000000000,,100,0,1,0,203.000000000,,2,0,1,0,170.000000000,,3,0,1,0,,,0,0,0,0,,,0,0,0,0,,,0,0,0,0,TSLA
2024-11-01T08:00:02.941910475Z,2024-11-01T08:00:02.941743559Z,10,2,16244,A,B,0,249.900000000,50,130,166916,292875,249.900000000,250.730000000,50,100,1,1,249.600000000,252.200000000,1000,1000,1,1,249.100000000,253.650000000,1000,400,1,1,247.150000000,960.000000000,400,25,1,1,235.000000000,,100,0,1,0,203.000000000,,2,0,1,0,170.000000000,,3,0,1,0,,,0,0,0,0,,,0,0,0,0,,,0,0,0,0,TSLA
2024-11-01T08:00:02.952347233Z,2024-11-01T08:00:02.952181020Z,10,2,16244,A,B,2,249.500000000,1000,130,166213,292889,249.900000000,250.730000000,50,100,1,1,249.600000000,252.200000000,1000,1000,1,1,249.500000000,253.650000000,1000,400,1,1,249.100000000,960.000000000,1000,25,1,1,247.150000000,,400,0,1,0,235.000000000,,100,0,1,0,203.000000000,,2,0,1,0,170.000000000,,3,0,1,0,,,0,0,0,0,,,0,0,0,0,TSLA
2024-11-01T08:00:02.952388850Z,2024-11-01T08:00:02.952222880Z,10,2,16244,C,B,3,249.100000000,1000,130,165970,292890,249.900000000,250.730000000,50,100,1,1,249.600000000,252.200000000,1000,1000,1,1,249.500000000,253.650000000,1000,400,1,1,247.150000000,960.000000000,400,25,1,1,235.000000000,,100,0,1,0,203.000000000,,2,0,1,0,170.000000000,,3,0,1,0,,,0,0,0,0,,,0,0,0,0,,,0,0,0,0,TSLA
2024-11-01T08:00:02.963417496Z,2024-11-01T08:00:02.963251228Z,10,2,16244,A,B,3,248.700000000,1000,130,166268,292897,249.900000000,250.730000000,50,100,1,1,249.600000000,252.200000000,1000,1000,1,1,249.500000000,253.650000000,1000,400,1,1,248.700000000,960.000000000,1000,25,1,1,247.150000000,,400,0,1,0,235.000000000,,100,0,1,0,203.000000000,,2,0,1,0,170.000000000,,3,0,1,0,,,0,0,0,0,,,0,0,0,0,TSLA
2024-11-01T08:00:02.972222719Z,2024-11-01T08:00:02.972055985Z,10,2,12463,A,N,0,163.080000000,100,130,166734,292905,163.080000000,,100,0,1,0,,,0,0,0,0,,,0,0,0,0,,,0,0,0,0,,,0,0,0,0,,,0,0,0,0,,,0,0,0,0,,,0,0,0,0,,,0,0,0,0,,,0,0,0,0,PEP
2024-11-01T08:00:03.011423815Z,2024-11-01T08:00:03.011257518Z,10,2,11667,A,B,6,129.000000000,10,130,166297,293036,134.770000000,135.300000000,100,1000,1,1,134.410000000,136.100000000,1,1000,1,1,134.210000000,137.680000000,20,500,1,1,133.200000000,138.870000000,1000,1000,1,2,132.000000000,140.740000000,71,100,2,1,129.050000000,140.880000000,500,1000,1,2,129.000000000,143.690000000,10,500,1,1,128.470000000,146.510000000,500,5,1,1,127.680000000,148.000000000,30,5,1,1,127.000000000,,20,0,1,0,NVDA
2024-11-01T08:00:03.032059829Z,2024-11-01T08:00:03.031893056Z,10,2,16244,A,B,0,249.930000000,50,130,166773,293097,249.930000000,250.730000000,50,100,1,1,249.600000000,252.200000000,1000,1000,1,1,249.500000000,253.650000000,1000,400,1,1,248.700000000,960.000000000,1000,25,1,1,247.150000000,,400,0,1,0,235.000000000,,100,0,1,0,203.000000000,,2,0,1,0,170.000000000,,3,0,1,0,,,0,0,0,0,,,0,0,0,0,TSLA
2024-11-01T08:00:03.032778841Z,2024-11-01T08:00:03.032613046Z,10,2,16244,C,B,0,249.930000000,50,130,165795,293101,249.600000000,250.730000000,1000,100,1,1,249.500000000,252.200000000,1000,1000,1,1,248.700000000,253.650000000,1000,400,1,1,247.150000000,960.000000000,400,25,1,1,235.000000000,,100,0,1,0,203.000000000,,2,0,1,0,170.000000000,,3,0,1,0,,,0,0,0,0,,,0,0,0,0,,,0,0,0,0,TSLA
2024-11-01T08:00:03.032790852Z,2024-11-01T08:00:03.032624801Z,10,2,16244,A,B,0,249.900000000,50,130,166051,293102,249.900000000,250.730000000,50,100,1,1,249.600000000,252.200000000,1000,1000,1,1,249.500000000,253.650000000,1000,400,1,1,248.700000000,960.000000000,1000,25,1,1,247.150000000,,400,0,1,0,235.000000000,,100,0,1,0,203.000000000,,2,0,1,0,170.000000000,,3,0,1,0,,,0,0,0,0,,,0,0,0,0,TSLA
2024-11-01T08:00:03.078595680Z,2024-11-01T08:00:03.078428790Z,10,2,16244,C,B,0,249.900000000,50,130,166890,293176,249.600000000,250.730000000,1000,100,1,1,249.500000000,252.200000000,1000,1000,1,1,248.700000000,253.650000000,1000,400,1,1,247.150000000,960.000000000,400,25,1,1,235.000000000,,100,0,1,0,203.000000000,,2,0,1,0,170.000000000,,3,0,1,0,,,0,0,0,0,,,0,0,0,0,,,0,0,0,0,TSLA
2024-11-01T08:00:03.078608523Z,2024-11-01T08:00:03.078442368Z,10,2,16244,A,B,0,249.870000000,50,130,166155,293177,249.870000000,250.730000000,50,100,1,1,249.600000000,252.200000000,1000,1000,1,1,249.500000000,253.650000000,1000,400,1,1,248.700000000,960.000000000,1000,25,1,1,247.150000000,,400,0,1,0,235.000000000,,100,0,1,0,203.000000000,,2,0,1,0,170.000000000,,3,0,1,0,,,0,0,0,0,,,0,0,0,0,TSLA
2024-11-01T08:00:03.078689152Z,2024-11-01T08:00:03.078523259Z,10,2,16244,C,B,0,249.870000000,50,130,165893,293178,249.600000000,250.730000000,1000,100,1,1,249.500000000,252.200000000,1000,1000,1,1,248.700000000,253.650000000,1000,400,1,1,247.150000000,960.000000000,400,25,1,1,235.000000000,,100,0,1,0,203.000000000,,2,0,1,0,170.000000000,,3,0,1,0,,,0,0,0,0,,,0,0,0,0,,,0,0,0,0,TSLA
2024-11-01T08:00:03.078712855Z,2024-11-01T08:00:03.078546687Z,10,2,16244,A,B,0,249.850000000,50,130,166168,293179,249.850000000,250.730000000,50,100,1,1,249.600000000,252.200000000,1000,1000,1,1,249.500000000,253.650000000,1000,400,1,1,248.700000000,960.000000000,1000,25,1,1,247.150000000,,400,0,1,0,235.000000000,,100,0,1,0,203.000000000,,2,0,1,0,170.000000000,,3,0,1,0,,,0,0,0,0,,,0,0,0,0,TSLA
2024-11-01T08:00:03.146238622Z,2024-11-01T08:00:03.146072343Z,10,2,16244,A,A,1,250.960000000,50,130,166279,293289,249.850000000,250.730000000,50,100,1,1,249.600000000,250.960000000,1000,50,1,1,249.500000000,252.200000000,1000,1000,1,1,248.700000000,253.650000000,1000,400,1,1,247.150000000,960.000000000,400,25,1,1,235.000000000,,100,0,1,0,203.000000000,,2,0,1,0,170.000000000,,3,0,1,0,,,0,0,0,0,,,0,0,0,0,TSLA
2024-11-01T08:00:03.194370387Z,2024-11-01T08:00:03.194203980Z,10,2,16244,A,B,2,249.500000000,1000,130,166407,293354,249.850000000,250.730000000,50,100,1,1,249.600000000,250.960000000,1000,50,1,1,249.500000000,252.200000000,2000,1000,2,1,248.700000000,253.650000000,1000,400,1,1,247.150000000,960.000000000,400,25,1,1,235.000000000,,100,0,1,0,203.000000000,,2,0,1,0,170.000000000,,3,0,1,0,,,0,0,0,0,,,0,0,0,0,TSLA
2024-11-01T08:00:03.194570308Z,2024-11-01T08:00:03.194404399Z,10,2,16244,C,B,3,248.700000000,1000,130,165909,293355,249.850000000,250.730000000,50,100,1,1,249.600000000,250.960000000,1000,50,1,1,249.500000000,252.200000000,2000,1000,2,1,247.150000000,253.650000000,400,400,1,1,235.000000000,960.000000000,100,25,1,1,203.000000000,,2,0,1,0,170.000000000,,3,0,1,0,,,0,0,0,0,,,0,0,0,0,,,0,0,0,0,TSLA
2024-11-01T08:00:03.205151206Z,2024-11-01T08:00:03.204984748Z,10,2,16244,A,B,3,248.200000000,1000,130,166458,293360,249.850000000,250.730000000,50,100,1,1,249.600000000,250.960000000,1000,50,1,1,249.500000000,252.200000000,2000,1000,2,1,248.200000000,253.650000000,1000,400,1,1,247.150000000,960.000000000,400,25,1,1,235.000000000,,100,0,1,0,203.000000000,,2,0,1,0,170.000000000,,3,0,1,0,,,0,0,0,0,,,0,0,0,0,TSLA
2024-11-01T08:00:03.214331004Z,2024-11-01T08:00:03.214163798Z,10,2,16244,A,B,0,249.870000000,50,130,167206,293369,249.870000000,250.730000000,50,100,1,1,249.600000000,250.960000000,1000,50,1,1,249.500000000,252.200000000,2000,1000,2,1,248.200000000,253.650000000,1000,400,1,1,247.150000000,960.000000000,400,25,1,1,235.000000000,,100,0,1,0,203.000000000,,2,0,1,0,170.000000000,,3,0,1,0,,,0,0,0,0,,,0,0,0,0,TSLA
2024-11-01T08:00:03.215083394Z,2024-11-01T08:00:03.214917607Z,10,2,16244,C,B,2,249.500000000,1000,130,165787,293371,249.870000000,250.730000000,50,100,1,1,249.600000000,250.960000000,1000,50,1,1,249.500000000,252.200000000,1000,1000,1,1,248.200000000,253.650000000,1000,400,1,1,247.150000000,960.000000000,400,25,1,1,235.000000000,,100,0,1,0,203.000000000,,2,0,1,0,170.000000000,,3,0,1,0,,,0,0,0,0,,,0,0,0,0,TSLA
2024-11-01T08:00:03.225393824Z,2024-11-01T08:00:03.225227516Z,10,2,16244,A,B,3,248.700000000,1000,130,166308,293382,249.870000000,250.730000000,50,100,1,1,249.600000000,250.960000000,1000,50,1,1,249.500000000,252.200000000,1000,1000,1,1,248.700000000,253.650000000,1000,400,1,1,248.200000000,960.000000000,1000,25,1,1,247.150000000,,400,0,1,0,235.000000000,,100,0,1,0,203.000000000,,2,0,1,0,170.000000000,,3,0,1,0,,,0,0,0,0,TSLA
2024-11-01T08:00:03.225512312Z,2024-11-01T08:00:03.225345068Z,10,2,16244,C,B,4,248.200000000,1000,130,167244,293383,249.870000000,250.730000000,50,100,1,1,249.600000000,250.960000000,1000,50,1,1,249.500000000,252.200000000,1000,1000,1,1,248.700000000,253.650000000,1000,400,1,1,247.150000000,960.000000000,400,25,1,1,235.000000000,,100,0,1,0,203.000000000,,2,0,1,0,170.000000000,,3,0,1,0,,,0,0,0,0,,,0,0,0,0,TSLA
2024-11-01T08:00:03.266462909Z,2024-11-01T08:00:03.266296551Z,10,2,38,A,B,1,220.000000000,2,130,166358,293430,221.200000000,224.400000000,1000,1000,1,1,220.000000000,225.490000000,2,442,1,1,219.690000000,234.000000000,442,20,1,1,217.000000000,,1525,0,1,0,,,0,0,0,0,,,0,0,0,0,,,0,0,0,0,,,0,0,0,0,,,0,0,0,0,,,0,0,0,0,AAPL
2024-11-01T08:00:03.281800226Z,2024-11-01T08:00:03.281633854Z,10,2,780,A,N,0,330.140000000,25,130,166372,293454,,330.140000000,0,25,0,1,,,0,0,0,0,,,0,0,0,0,,,0,0,0,0,,,0,0,0,0,,,0,0,0,0,,,0,0,0,0,,,0,0,0,0,,,0,0,0,0,,,0,0,0,0,AMGN
2024-11-01T08:00:03.290794949Z,2024-11-01T08:00:03.290628629Z,10,2,16244,C,A,2,252.200000000,1000,130,166320,293466,249.870000000,250.730000000,50,100,1,1,249.600000000,250.960000000,1000,50,1,1,249.500000000,253.650000000,1000,400,1,1,248.700000000,960.000000000,1000,25,1,1,247.150000000,,400,0,1,0,235.000000000,,100,0,1,0,203.000000000,,2,0,1,0,170.000000000,,3,0,1,0,,,0,0,0,0,,,0,0,0,0,TSLA
2024-11-01T08:00:03.301371617Z,2024-11-01T08:00:03.301205171Z,10,2,16244,A,A,2,252.300000000,1000,130,166446,293477,249.870000000,250.730000000,50,100,1,1,249.600000000,250.960000000,1000,50,1,1,249.500000000,252.300000000,1000,1000,1,1,248.700000000,253.650000000,1000,400,1,1,247.150000000,960.000000000,400,25,1,1,235.000000000,,100,0,1,0,203.000000000,,2,0,1,0,170.000000000,,3,0,1,0,,,0,0,0,0,,,0,0,0,0,TSLA
2024-11-01T08:00:03.405898932Z,2024-11-01T08:00:03.405732567Z,10,2,11667,A,B,0,134.810000000,61,130,166365,293620,134.810000000,135.300000000,61,1000,1,1,134.770000000,136.100000000,100,1000,1,1,134.410000000,137.680000000,1,500,1,1,134.210000000,138.870000000,20,1000,1,2,133.200000000,140.740000000,1000,100,1,1,132.000000000,140.880000000,71,1000,2,2,129.050000000,143.690000000,500,500,1,1,129.000000000,146.510000000,10,5,1,1,128.470000000,148.000000000,500,5,1,1,127.680000000,,30,0,1,0,NVDA
2024-11-01T08:00:03.429244732Z,2024-11-01T08:00:03.429078827Z,10,2,11667,C,B,0,134.810000000,61,130,165905,293686,134.770000000,135.300000000,100,1000,1,1,134.410000000,136.100000000,1,1000,1,1,134.210000000,137.680000000,20,500,1,1,133.200000000,138.870000000,1000,1000,1,2,132.000000000,140.740000000,71,100,2,1,129.050000000,140.880000000,500,1000,1,2,129.000000000,143.690000000,10,500,1,1,128.470000000,146.510000000,500,5,1,1,127.680000000,148.000000000,30,5,1,1,127.000000000,,20,0,1,0,NVDA
2024-11-01T08:00:03.604595157Z,2024-11-01T08:00:03.604428840Z,10,2,9155,A,B,1,217.610000000,100,130,166317,293899,219.160000000,224.940000000,450,450,1,1,217.610000000,,100,0,1,0,,,0,0,0,0,,,0,0,0,0,,,0,0,0,0,,,0,0,0,0,,,0,0,0,0,,,0,0,0,0,,,0,0,0,0,,,0,0,0,0,JPM
2024-11-01T08:00:03.604610327Z,2024-11-01T08:00:03.604443910Z,10,2,9155,A,A,1,226.800000000,100,130,166417,293900,219.160000000,224.940000000,450,450,1,1,217.610000000,226.800000000,100,100,1,1,,,0,0,0,0,,,0,0,0,0,,,0,0,0,0,,,0,0,0,0,,,0,0,0,0,,,0,0,0,0,,,0,0,0,0,,,0,0,0,0,JPM
2024-11-01T08:00:03.733783141Z,2024-11-01T08:00:03.733616642Z,10,2,17709,A,A,2,125.000000000,30,130,166499,294251,116.000000000,118.320000000,100,856,1,1,115.320000000,118.600000000,100,100,1,1,115.280000000,125.000000000,856,30,1,1,,,0,0,0,0,,,0,0,0,0,,,0,0,0,0,,,0,0,0,0,,,0,0,0,0,,,0,0,0,0,,,0,0,0,0,XOM
2024-11-01T08:00:03.859483445Z,2024-11-01T08:00:03.859317306Z,10,2,11667,C,B,3,133.200000000,1000,130,166139,294581,134.770000000,135.300000000,100,1000,1,1,134.410000000,136.100000000,1,1000,1,1,134.210000000,137.680000000,20,500,1,1,132.000000000,138.870000000,71,1000,2,2,129.050000000,140.740000000,500,100,1,1,129.000000000,140.880000000,10,1000,1,2,128.470000000,143.690000000,500,500,1,1,127.680000000,146.510000000,30,5,1,1,127.000000000,148.000000000,20,5,1,1,91.000000000,,50,0,1,0,NVDA
2024-11-01T08:00:03.864687567Z,2024-11-01T08:00:03.864521543Z,10,2,16244,A,B,6,214.000000000,5,130,166024,294590,249.870000000,250.730000000,50,100,1,1,249.600000000,250.960000000,1000,50,1,1,249.500000000,252.300000000,1000,1000,1,1,248.700000000,253.650000000,1000,400,1,1,247.150000000,960.000000000,400,25,1,1,235.000000000,,100,0,1,0,214.000000000,,5,0,1,0,203.000000000,,2,0,1,0,170.000000000,,3,0,1,0,,,0,0,0,0,TSLA
2024-11-01T08:00:03.870457550Z,2024-11-01T08:00:03.870291285Z,10,2,11667,A,B,3,133.100000000,1000,130,166265,294607,134.770000000,135.300000000,100,1000,1,1,134.410000000,136.100000000,1,1000,1,1,134.210000000,137.680000000,20,500,1,1,133.100000000,138.870000000,1000,1000,1,2,132.000000000,140.740000000,71,100,2,1,129.050000000,140.880000000,500,1000,1,2,129.000000000,143.690000000,10,500,1,1,128.470000000,146.510000000,500,5,1,1,127.680000000,148.000000000,30,5,1,1,127.000000000,,20,0,1,0,NVDA
2024-11-01T08:00:03.904687498Z,2024-11-01T08:00:03.904521638Z,10,2,10888,A,B,1,398.000000000,5,130,165860,294699,404.410000000,415.070000000,246,246,1,1,398.000000000,420.000000000,5,3,1,1,,468.000000000,0,65,0,1,,,0,0,0,0,,,0,0,0,0,,,0,0,0,0,,,0,0,0,0,,,0,0,0,0,,,0,0,0,0,,,0,0,0,0,MSFT
2024-11-01T08:00:03.979793361Z,2024-11-01T08:00:03.979627113Z,10,2,11667,A,B,9,127.500000000,5,130,166248,294879,134.770000000,135.300000000,100,1000,1,1,134.410000000,136.100000000,1,1000,1,1,134.210000000,137.680000000,20,500,1,1,133.100000000,138.870000000,1000,1000,1,2,132.000000000,140.740000000,71,100,2,1,129.050000000,140.880000000,500,1000,1,2,129.000000000,143.690000000,10,500,1,1,128.470000000,146.510000000,500,5,1,1,127.680000000,148.000000000,30,5,1,1,127.500000000,,5,0,1,0,NVDA
2024-11-01T08:00:03.990343678Z,2024-11-01T08:00:03.990176949Z,10,2,16244,A,A,4,275.000000000,4,130,166729,294920,249.870000000,250.730000000,50,100,1,1,249.600000000,250.960000000,1000,50,1,1,249.500000000,252.300000000,1000,1000,1,1,248.700000000,253.650000000,1000,400,1,1,247.150000000,275.000000000,400,4,1,1,235.000000000,960.000000000,100,25,1,1,214.000000000,,5,0,1,0,203.000000000,,2,0,1,0,170.000000000,,3,0,1,0,,,0,0,0,0,TSLA
2024-11-01T08:00:04.001618747Z,2024-11-01T08:00:04.001452430Z,10,2,6905,A,N,0,91.880000000,100,130,166317,294945,,91.880000000,0,100,0,1,,,0,0,0,0,,,0,0,0,0,,,0,0,0,0,,,0,0,0,0,,,0,0,0,0,,,0,0,0,0,,,0,0,0,0,,,0,0,0,0,,,0,0,0,0,GILD
2024-11-01T08:00:04.119754546Z,2024-11-01T08:00:04.119588707Z,10,2,16244,A,A,0,250.730000000,100,130,165839,295080,249.870000000,250.730000000,50,200,1,2,249.600000000,250.960000000,1000,50,1,1,249.500000000,252.300000000,1000,1000,1,1,248.700000000,253.650000000,1000,400,1,1,247.150000000,275.000000000,400,4,1,1,235.000000000,960.000000000,100,25,1,1,214.000000000,,5,0,1,0,203.000000000,,2,0,1,0,170.000000000,,3,0,1,0,,,0,0,0,0,TSLA
2024-11-01T08:00:04.119835321Z,2024-11-01T08:00:04.119669642Z,10,2,16244,C,B,0,249.870000000,50,130,165679,295081,249.600000000,250.730000000,1000,200,1,2,249.500000000,250.960000000,1000,50,1,1,248.700000000,252.300000000,1000,1000,1,1,247.150000000,253.650000000,400,400,1,1,235.000000000,275.000000000,100,4,1,1,214.000000000,960.000000000,5,25,1,1,203.000000000,,2,0,1,0,170.000000000,,3,0,1,0,,,0,0,0,0,,,0,0,0,0,TSLA
2024-11-01T08:00:04.119911891Z,2024-11-01T08:00:04.119746189Z,10,2,16244,C,B,2,248.700000000,1000,130,165702,295082,249.600000000,250.730000000,1000,200,1,2,249.500000000,250.960000000,1000,50,1,1,247.150000000,252.300000000,400,1000,1,1,235.000000000,253.650000000,100,400,1,1,214.000000000,275.000000000,5,4,1,1,203.000000000,960.000000000,2,25,1,1,170.000000000,,3,0,1,0,,,0,0,0,0,,,0,0,0,0,,,0,0,0,0,TSLA
2024-11-01T08:00:04.120156195Z,2024-11-01T08:00:04.119989815Z,10,2,16244,C,B,1,249.500000000,1000,130,166380,295083,249.600000000,250.730000000,1000,200,1,2,247.150000000,250.960000000,400,50,1,1,235.000000000,252.300000000,100,1000,1,1,214.000000000,253.650000000,5,400,1,1,203.000000000,275.000000000,2,4,1,1,170.000000000,960.000000000,3,25,1,1,,,0,0,0,0,,,0,0,0,0,,,0,0,0,0,,,0,0,0,0,TSLA
2024-11-01T08:00:04.134985360Z,2024-11-01T08:00:04.134815895Z,10,2,16244,A,A,2,251.300000000,1000,130,169465,295095,249.600000000,250.730000000,1000,200,1,2,247.150000000,250.960000000,400,50,1,1,235.000000000,251.300000000,100,1000,1,1,214.000000000,252.300000000,5,1000,1,1,203.000000000,253.650000000,2,400,1,1,170.000000000,275.000000000,3,4,1,1,,960.000000000,0,25,0,1,,,0,0,0,0,,,0,0,0,0,,,0,0,0,0,TSLA
2024-11-01T08:00:04.135044430Z,2024-11-01T08:00:04.134878033Z,10,2,16244,C,A,3,252.300000000,1000,130,166397,295096,249.600000000,250.730000000,1000,200,1,2,247.150000000,250.960000000,400,50,1,1,235.000000000,251.300000000,100,1000,1,1,214.000000000,253.650000000,5,400,1,1,203.000000000,275.000000000,2,4,1,1,170.000000000,960.000000000,3,25,1,1,,,0,0,0,0,,,0,0,0,0,,,0,0,0,0,,,0,0,0,0,TSLA
2024-11-01T08:00:04.153954286Z,2024-11-01T08:00:04.153788131Z,10,2,16244,C,A,2,251.300000000,1000,130,166155,295110,249.600000000,250.730000000,1000,200,1,2,247.150000000,250.960000000,400,50,1,1,235.000000000,253.650000000,100,400,1,1,214.000000000,275.000000000,5,4,1,1,203.000000000,960.000000000,2,25,1,1,170.000000000,,3,0,1,0,,,0,0,0,0,,,0,0,0,0,,,0,0,0,0,,,0,0,0,0,TSLA
2024-11-01T08:00:04.162073569Z,2024-11-01T08:00:04.161907144Z,10,2,16244,A,B,1,249.300000000,1000,130,166425,295120,249.600000000,250.730000000,1000,200,1,2,249.300000000,250.960000000,1000,50,1,1,247.150000000,253.650000000,400,400,1,1,235.000000000,275.000000000,100,4,1,1,214.000000000,960.000000000,5,25,1,1,203.000000000,,2,0,1,0,170.000000000,,3,0,1,0,,,0,0,0,0,,,0,0,0,0,,,0,0,0,0,TSLA
2024-11-01T08:00:04.164271209Z,2024-11-01T08:00:04.164104182Z,10,2,16244,A,A,2,251.700000000,1000,130,167027,295121,249.600000000,250.730000000,1000,200,1,2,249.300000000,250.960000000,1000,50,1,1,247.150000000,251.700000000,400,1000,1,1,235.000000000,253.650000000,100,400,1,1,214.000000000,275.000000000,5,4,1,1,203.000000000,960.000000000,2,25,1,1,170.000000000,,3,0,1,0,,,0,0,0,0,,,0,0,0,0,,,0,0,0,0,TSLA
2024-11-01T08:00:04.172136969Z,2024-11-01T08:00:04.171971303Z,10,2,16244,C,A,2,251.700000000,1000,130,165666,295134,249.600000000,250.730000000,1000,200,1,2,249.300000000,250.960000000,1000,50,1,1,247.150000000,253.650000000,400,400,1,1,235.000000000,275.000000000,100,4,1,1,214.000000000,960.000000000,5,25,1,1,203.000000000,,2,0,1,0,170.000000000,,3,0,1,0,,,0,0,0,0,,,0,0,0,0,,,0,0,0,0,TSLA
2024-11-01T08:00:04.185656271Z,2024-11-01T08:00:04.185489815Z,10,2,16244,A,A,2,251.300000000,1000,130,166456,295160,249.600000000,250.730000000,1000,200,1,2,249.300000000,250.960000000,1000,50,1,1,247.150000000,251.300000000,400,1000,1,1,235.000000000,253.650000000,100,400,1,1,214.000000000,275.000000000,5,4,1,1,203.000000000,960.000000000,2,25,1,1,170.000000000,,3,0,1,0,,,0,0,0,0,,,0,0,0,0,,,0,0,0,0,TSLA
2024-11-01T08:00:04.185708515Z,2024-11-01T08:00:04.185542577Z,10,2,16244,C,A,0,250.730000000,100,130,165938,295161,249.600000000,250.730000000,1000,100,1,1,249.300000000,250.960000000,1000,50,1,1,247.150000000,251.300000000,400,1000,1,1,235.000000000,253.650000000,100,400,1,1,214.000000000,275.000000000,5,4,1,1,203.000000000,960.000000000,2,25,1,1,170.000000000,,3,0,1,0,,,0,0,0,0,,,0,0,0,0,,,0,0,0,0,TSLA
2024-11-01T08:00:04.185728699Z,2024-11-01T08:00:04.185562559Z,10,2,16244,A,A,0,250.680000000,100,130,166140,295162,249.600000000,250.680000000,1000,100,1,1,249.300000000,250.960000000,1000,50,1,1,247.150000000,251.300000000,400,1000,1,1,235.000000000,253.650000000,100,400,1,1,214.000000000,275.000000000,5,4,1,1,203.000000000,960.000000000,2,25,1,1,170.000000000,,3,0,1,0,,,0,0,0,0,,,0,0,0,0,,,0,0,0,0,TSLA
2024-11-01T08:00:04.197584272Z,2024-11-01T08:00:04.197416893Z,10,2,38,A,B,4,190.000000000,1,130,167379,295174,221.200000000,224.400000000,1000,1000,1,1,220.000000000,225.490000000,2,442,1,1,219.690000000,234.000000000,442,20,1,1,217.000000000,,1525,0,1,0,190.000000000,,1,0,1,0,,,0,0,0,0,,,0,0,0,0,,,0,0,0,0,,,0,0,0,0,,,0,0,0,0,AAPL
2024-11-01T08:00:04.206245462Z,2024-11-01T08:00:04.206079566Z,10,2,11667,C,B,0,134.770000000,100,130,165896,295179,134.410000000,135.300000000,1,1000,1,1,134.210000000,136.100000000,20,1000,1,1,133.100000000,137.680000000,1000,500,1,1,132.000000000,138.870000000,71,1000,2,2,129.050000000,140.740000000,500,100,1,1,129.000000000,140.880000000,10,1000,1,2,128.470000000,143.690000000,500,500,1,1,127.680000000,146.510000000,30,5,1,1,127.500000000,148.000000000,5,5,1,1,127.000000000,,20,0,1,0,NVDA
2024-11-01T08:00:04.206723102Z,2024-11-01T08:00:04.206556827Z,10,2,11667,A,B,0,134.560000000,100,130,166275,295180,134.560000000,135.300000000,100,1000,1,1,134.410000000,136.100000000,1,1000,1,1,134.210000000,137.680000000,20,500,1,1,133.100000000,138.870000000,1000,1000,1,2,132.000000000,140.740000000,71,100,2,1,129.050000000,140.880000000,500,1000,1,2,129.000000000,143.690000000,10,500,1,1,128.470000000,146.510000000,500,5,1,1,127.680000000,148.000000000,30,5,1,1,127.500000000,,5,0,1,0,NVDA
2024-11-01T08:00:04.209954772Z,2024-11-01T08:00:04.209789063Z,10,2,16244,C,A,2,251.300000000,1000,130,165709,295186,249.600000000,250.680000000,1000,100,1,1,249.300000000,250.960000000,1000,50,1,1,247.150000000,253.650000000,400,400,1,1,235.000000000,275.000000000,100,4,1,1,214.000000000,960.000000000,5,25,1,1,203.000000000,,2,0,1,0,170.000000000,,3,0,1,0,,,0,0,0,0,,,0,0,0,0,,,0,0,0,0,TSLA
2024-11-01T08:00:04.210810479Z,2024-11-01T08:00:04.210644343Z,10,2,16244,A,B,5,213.000000000,1,130,166136,295187,249.600000000,250.680000000,1000,100,1,1,249.300000000,250.960000000,1000,50,1,1,247.150000000,253.650000000,400,400,1,1,235.000000000,275.000000000,100,4,1,1,214.000000000,960.000000000,5,25,1,1,213.000000000,,1,0,1,0,203.000000000,,2,0,1,0,170.000000000,,3,0,1,0,,,0,0,0,0,,,0,0,0,0,TSLA
2024-11-01T08:00:04.220490319Z,2024-11-01T08:00:04.220324092Z,10,2,16244,A,A,2,251.700000000,1000,130,166227,295214,249.600000000,250.680000000,1000,100,1,1,249.300000000,250.960000000,1000,50,1,1,247.150000000,251.700000000,400,1000,1,1,235.000000000,253.650000000,100,400,1,1,214.000000000,275.000000000,5,4,1,1,213.000000000,960.000000000,1,25,1,1,203.000000000,,2,0,1,0,170.000000000,,3,0,1,0,,,0,0,0,0,,,0,0,0,0,TSLA
2024-11-01T08:00:04.233938968Z,2024-11-01T08:00:04.233772682Z,10,2,38,A,B,5,180.000000000,1,130,166286,295267,221.200000000,224.400000000,1000,1000,1,1,220.000000000,225.490000000,2,442,1,1,219.690000000,234.000000000,442,20,1,1,217.000000000,,1525,0,1,0,190.000000000,,1,0,1,0,180.000000000,,1,0,1,0,,,0,0,0,0,,,0,0,0,0,,,0,0,0,0,,,0,0,0,0,AAPL
2024-11-01T08:00:04.238566791Z,2024-11-01T08:00:04.238400706Z,10,2,16244,A,B,0,249.870000000,50,130,166085,295290,249.870000000,250.680000000,50,100,1,1,249.600000000,250.960000000,1000,50,1,1,249.300000000,251.700000000,1000,1000,1,1,247.150000000,253.650000000,400,400,1,1,235.000000000,275.000000000,100,4,1,1,214.000000000,960.000000000,5,25,1,1,213.000000000,,1,0,1,0,203.000000000,,2,0,1,0,170.000000000,,3,0,1,0,,,0,0,0,0,TSLA
2024-11-01T08:00:04.238923737Z,2024-11-01T08:00:04.238758087Z,10,2,16244,C,A,2,251.700000000,1000,130,165650,295293,249.870000000,250.680000000,50,100,1,1,249.600000000,250.960000000,1000,50,1,1,249.300000000,253.650000000,1000,400,1,1,247.150000000,275.000000000,400,4,1,1,235.000000000,960.000000000,100,25,1,1,214.000000000,,5,0,1,0,213.000000000,,1,0,1,0,203.000000000,,2,0,1,0,170.000000000,,3,0,1,0,,,0,0,0,0,TSLA
2024-11-01T08:00:04.249251005Z,2024-11-01T08:00:04.249084553Z,10,2,16244,A,A,2,251.900000000,1000,130,166452,295330,249.870000000,250.680000000,50,100,1,1,249.600000000,250.960000000,1000,50,1,1,249.300000000,251.900000000,1000,1000,1,1,247.150000000,253.650000000,400,400,1,1,235.000000000,275.000000000,100,4,1,1,214.000000000,960.000000000,5,25,1,1,213.000000000,,1,0,1,0,203.000000000,,2,0,1,0,170.000000000,,3,0,1,0,,,0,0,0,0,TSLA
2024-11-01T08:00:04.280306392Z,2024-11-01T08:00:04.280140242Z,10,2,11667,A,A,6,143.000000000,1,130,166150,295376,134.560000000,135.300000000,100,1000,1,1,134.410000000,136.100000000,1,1000,1,1,134.210000000,137.680000000,20,500,1,1,133.100000000,138.870000000,1000,1000,1,2,132.000000000,140.740000000,71,100,2,1,129.050000000,140.880000000,500,1000,1,2,129.000000000,143.000000000,10,1,1,1,128.470000000,143.690000000,500,500,1,1,127.680000000,146.510000000,30,5,1,1,127.500000000,148.000000000,5,5,1,1,NVDA
2024-11-01T08:00:04.291897046Z,2024-11-01T08:00:04.291730773Z,10,2,9155,A,B,0,221.850000000,3,130,166273,295399,221.850000000,224.940000000,3,450,1,1,219.160000000,226.800000000,450,100,1,1,217.610000000,,100,0,1,0,,,0,0,0,0,,,0,0,0,0,,,0,0,0,0,,,0,0,0,0,,,0,0,0,0,,,0,0,0,0,,,0,0,0,0,JPM
2024-11-01T08:00:04.303537228Z,2024-11-01T08:00:04.303371082Z,10,2,38,A,A,3,240.000000000,150,130,166146,295408,221.200000000,224.400000000,1000,1000,1,1,220.000000000,225.490000000,2,442,1,1,219.690000000,234.000000000,442,20,1,1,217.000000000,240.000000000,1525,150,1,1,190.000000000,,1,0,1,0,180.000000000,,1,0,1,0,,,0,0,0,0,,,0,0,0,0,,,0,0,0,0,,,0,0,0,0,AAPL
2024-11-01T08:00:04.366083888Z,2024-11-01T08:00:04.365918109Z,10,2,16244,C,B,0,249.870000000,50,130,165779,295485,249.600000000,250.680000000,1000,100,1,1,249.300000000,250.960000000,1000,50,1,1,247.150000000,251.900000000,400,1000,1,1,235.000000000,253.650000000,100,400,1,1,214.000000000,275.000000000,5,4,1,1,213.000000000,960.000000000,1,25,1,1,203.000000000,,2,0,1,0,170.000000000,,3,0,1,0,,,0,0,0,0,,,0,0,0,0,TSLA
2024-11-01T08:00:04.366098645Z,2024-11-01T08:00:04.365931595Z,10,2,16244,A,B,0,249.850000000,50,128,167050,295487,249.850000000,250.680000000,50,100,1,1,249.600000000,250.960000000,1000,50,1,1,249.300000000,251.900000000,1000,1000,1,1,247.150000000,253.650000000,400,400,1,1,235.000000000,275.000000000,100,4,1,1,214.000000000,960.000000000,5,25,1,1,213.000000000,,1,0,1,0,203.000000000,,2,0,1,0,170.000000000,,3,0,1,0,,,0,0,0,0,TSLA
2024-11-01T08:00:04.367087628Z,2024-11-01T08:00:04.366921961Z,10,2,16244,C,B,0,249.850000000,50,130,165667,295494,249.600000000,250.680000000,1000,100,1,1,249.300000000,250.960000000,1000,50,1,1,247.150000000,251.900000000,400,1000,1,1,235.000000000,253.650000000,100,400,1,1,214.000000000,275.000000000,5,4,1,1,213.000000000,960.000000000,1,25,1,1,203.000000000,,2,0,1,0,170.000000000,,3,0,1,0,,,0,0,0,0,,,0,0,0,0,TSLA
2024-11-01T08:00:04.367100716Z,2024-11-01T08:00:04.366934766Z,10,2,16244,A,B,0,249.820000000,100,130,165950,295495,249.820000000,250.680000000,100,100,1,1,249.600000000,250.960000000,1000,50,1,1,249.300000000,251.900000000,1000,1000,1,1,247.150000000,253.650000000,400,400,1,1,235.000000000,275.000000000,100,4,1,1,214.000000000,960.000000000,5,25,1,1,213.000000000,,1,0,1,0,203.000000000,,2,0,1,0,170.000000000,,3,0,1,0,,,0,0,0,0,TSLA
2024-11-01T08:00:04.390459448Z,2024-11-01T08:00:04.390293393Z,10,2,16244,A,A,4,265.000000000,1,130,166055,295522,249.820000000,250.680000000,100,100,1,1,249.600000000,250.960000000,1000,50,1,1,249.300000000,251.900000000,1000,1000,1,1,247.150000000,253.650000000,400,400,1,1,235.000000000,265.000000000,100,1,1,1,214.000000000,275.000000000,5,4,1,1,213.000000000,960.000000000,1,25,1,1,203.000000000,,2,0,1,0,170.000000000,,3,0,1,0,,,0,0,0,0,TSLA
2024-11-01T08:00:04.404980797Z,2024-11-01T08:00:04.404814202Z,10,2,16244,A,B,5,220.000000000,1,130,166595,295529,249.820000000,250.680000000,100,100,1,1,249.600000000,250.960000000,1000,50,1,1,249.300000000,251.900000000,1000,1000,1,1,247.150000000,253.650000000,400,400,1,1,235.000000000,265.000000000,100,1,1,1,220.000000000,275.000000000,1,4,1,1,214.000000000,960.000000000,5,25,1,1,213.000000000,,1,0,1,0,203.000000000,,2,0,1,0,170.000000000,,3,0,1,0,TSLA
2024-11-01T08:00:04.443604460Z,2024-11-01T08:00:04.443438209Z,10,2,16244,A,A,1,250.960000000,50,130,166251,295569,249.820000000,250.680000000,100,100,1,1,249.600000000,250.960000000,1000,100,1,2,249.300000000,251.900000000,1000,1000,1,1,247.150000000,253.650000000,400,400,1,1,235.000000000,265.000000000,100,1,1,1,220.000000000,275.000000000,1,4,1,1,214.000000000,960.000000000,5,25,1,1,213.000000000,,1,0,1,0,203.000000000,,2,0,1,0,170.000000000,,3,0,1,0,TSLA
2024-11-01T08:00:04.470413664Z,2024-11-01T08:00:04.470247417Z,10,2,16244,A,A,4,260.000000000,48,130,166247,295623,249.820000000,250.680000000,100,100,1,1,249.600000000,250.960000000,1000,100,1,2,249.300000000,251.900000000,1000,1000,1,1,247.150000000,253.650000000,400,400,1,1,235.000000000,260.000000000,100,48,1,1,220.000000000,265.000000000,1,1,1,1,214.000000000,275.000000000,5,4,1,1,213.000000000,960.000000000,1,25,1,1,203.000000000,,2,0,1,0,170.000000000,,3,0,1,0,TSLA
2024-11-01T08:00:04.497617147Z,2024-11-01T08:00:04.497451271Z,10,2,16244,C,A,1,250.960000000,50,130,165876,295704,249.820000000,250.680000000,100,100,1,1,249.600000000,250.960000000,1000,50,1,1,249.300000000,251.900000000,1000,1000,1,1,247.150000000,253.650000000,400,400,1,1,235.000000000,260.000000000,100,48,1,1,220.000000000,265.000000000,1,1,1,1,214.000000000,275.000000000,5,4,1,1,213.000000000,960.000000000,1,25,1,1,203.000000000,,2,0,1,0,170.000000000,,3,0,1,0,TSLA
2024-11-01T08:00:04.497637192Z,2024-11-01T08:00:04.497470818Z,10,2,16244,A,A,1,250.750000000,50,130,166374,295705,249.820000000,250.680000000,100,100,1,1,249.600000000,250.750000000,1000,50,1,1,249.300000000,251.900000000,1000,1000,1,1,247.150000000,253.650000000,400,400,1,1,235.000000000,260.000000000,100,48,1,1,220.000000000,265.000000000,1,1,1,1,214.000000000,275.000000000,5,4,1,1,213.000000000,960.000000000,1,25,1,1,203.000000000,,2,0,1,0,170.000000000,,3,0,1,0,TSLA
2024-11-01T08:00:04.501706334Z,2024-11-01T08:00:04.501540214Z,10,2,16244,C,B,0,249.820000000,50,130,166120,295725,249.820000000,250.680000000,50,100,1,1,249.600000000,250.750000000,1000,50,1,1,249.300000000,251.900000000,1000,1000,1,1,247.150000000,253.650000000,400,400,1,1,235.000000000,260.000000000,100,48,1,1,220.000000000,265.000000000,1,1,1,1,214.000000000,275.000000000,5,4,1,1,213.000000000,960.000000000,1,25,1,1,203.000000000,,2,0,1,0,170.000000000,,3,0,1,0,TSLA
2024-11-01T08:00:04.514934233Z,2024-11-01T08:00:04.514768318Z,10,2,16244,A,B,8,211.000000000,2,130,165915,295781,249.820000000,250.680000000,50,100,1,1,249.600000000,250.750000000,1000,50,1,1,249.300000000,251.900000000,1000,1000,1,1,247.150000000,253.650000000,400,400,1,1,235.000000000,260.000000000,100,48,1,1,220.000000000,265.000000000,1,1,1,1,214.000000000,275.000000000,5,4,1,1,213.000000000,960.000000000,1,25,1,1,211.000000000,,2,0,1,0,203.000000000,,2,0,1,0,TSLA
2024-11-01T08:00:04.523349487Z,2024-11-01T08:00:04.523183346Z,10,2,11667,C,A,1,136.100000000,1000,130,166141,295798,134.560000000,135.300000000,100,1000,1,1,134.410000000,137.680000000,1,500,1,1,134.210000000,138.870000000,20,1000,1,2,133.100000000,140.740000000,1000,100,1,1,132.000000000,140.880000000,71,1000,2,2,129.050000000,143.000000000,500,1,1,1,129.000000000,143.690000000,10,500,1,1,128.470000000,146.510000000,500,5,1,1,127.680000000,148.000000000,30,5,1,1,127.500000000,,5,0,1,0,NVDA
2024-11-01T08:00:04.534120949Z,2024-11-01T08:00:04.533954375Z,10,2,11667,A,A,1,136.200000000,1000,130,166574,295865,134.560000000,135.300000000,100,1000,1,1,134.410000000,136.200000000,1,1000,1,1,134.210000000,137.680000000,20,500,1,1,133.100000000,138.870000000,1000,1000,1,2,132.000000000,140.740000000,71,100,2,1,129.050000000,140.880000000,500,1000,1,2,129.000000000,143.000000000,10,1,1,1,128.470000000,143.690000000,500,500,1,1,127.680000000,146.510000000,30,5,1,1,127.500000000,148.000000000,5,5,1,1,NVDA
2024-11-01T08:00:04.596259823Z,2024-11-01T08:00:04.596093879Z,10,2,11667,A,A,9,148.000000000,100,130,165944,296072,134.560000000,135.300000000,100,1000,1,1,134.410000000,136.200000000,1,1000,1,1,134.210000000,137.680000000,20,500,1,1,133.100000000,138.870000000,1000,1000,1,2,132.000000000,140.740000000,71,100,2,1,129.050000000,140.880000000,500,1000,1,2,129.000000000,143.000000000,10,1,1,1,128.470000000,143.690000000,500,500,1,1,127.680000000,146.510000000,30,5,1,1,127.500000000,148.000000000,5,105,1,2,NVDA
2024-11-01T08:00:04.724128638Z,2024-11-01T08:00:04.723962496Z,10,2,16244,A,B,7,213.650000000,3,130,166142,296410,249.820000000,250.680000000,50,100,1,1,249.600000000,250.750000000,1000,50,1,1,249.300000000,251.900000000,1000,1000,1,1,247.150000000,253.650000000,400,400,1,1,235.000000000,260.000000000,100,48,1,1,220.000000000,265.000000000,1,1,1,1,214.000000000,275.000000000,5,4,1,1,213.650000000,960.000000000,3,25,1,1,213.000000000,,1,0,1,0,211.000000000,,2,0,1,0,TSLA
2024-11-01T08:00:04.836981943Z,2024-11-01T08:00:04.836815700Z,10,2,16244,A,A,5,264.940000000,7,130,166243,296857,249.820000000,250.680000000,50,100,1,1,249.600000000,250.750000000,1000,50,1,1,249.300000000,251.900000000,1000,1000,1,1,247.150000000,253.650000000,400,400,1,1,235.000000000,260.000000000,100,48,1,1,220.000000000,264.940000000,1,7,1,1,214.000000000,265.000000000,5,1,1,1,213.650000000,275.000000000,3,4,1,1,213.000000000,960.000000000,1,25,1,1,211.000000000,,2,0,1,0,TSLA
2024-11-01T08:00:04.896524829Z,2024-11-01T08:00:04.896358681Z,10,2,10888,A,B,0,410.000000000,1,130,166148,297030,410.000000000,415.070000000,1,246,1,1,404.410000000,420.000000000,246,3,1,1,398.000000000,468.000000000,5,65,1,1,,,0,0,0,0,,,0,0,0,0,,,0,0,0,0,,,0,0,0,0,,,0,0,0,0,,,0,0,0,0,,,0,0,0,0,MSFT
2024-11-01T08:00:05.080861532Z,2024-11-01T08:00:05.080695459Z,10,2,11667,A,B,5,130.000000000,5,130,166073,297402,134.560000000,135.300000000,100,1000,1,1,134.410000000,136.200000000,1,1000,1,1,134.210000000,137.680000000,20,500,1,1,133.100000000,138.870000000,1000,1000,1,2,132.000000000,140.740000000,71,100,2,1,130.000000000,140.880000000,5,1000,1,2,129.050000000,143.000000000,500,1,1,1,129.000000000,143.690000000,10,500,1,1,128.470000000,146.510000000,500,5,1,1,127.680000000,148.000000000,30,105,1,2,NVDA
2024-11-01T08:00:05.125416215Z,2024-11-01T08:00:05.125250462Z,10,2,12463,C,B,0,163.080000000,100,130,165753,297478,,,0,0,0,0,,,0,0,0,0,,,0,0,0,0,,,0,0,0,0,,,0,0,0,0,,,0,0,0,0,,,0,0,0,0,,,0,0,0,0,,,0,0,0,0,,,0,0,0,0,PEP
2024-11-01T08:00:05.150130228Z,2024-11-01T08:00:05.149964125Z,10,2,10888,A,B,1,408.960000000,5,130,166103,297501,410.000000000,415.070000000,1,246,1,1,408.960000000,420.000000000,5,3,1,1,404.410000000,468.000000000,246,65,1,1,398.000000000,,5,0,1,0,,,0,0,0,0,,,0,0,0,0,,,0,0,0,0,,,0,0,0,0,,,0,0,0,0,,,0,0,0,0,MSFT
2024-11-01T08:00:05.220725689Z,2024-11-01T08:00:05.220559245Z,10,2,16244,A,B,5,220.000000000,5,130,166444,297655,249.820000000,250.680000000,50,100,1,1,249.600000000,250.750000000,1000,50,1,1,249.300000000,251.900000000,1000,1000,1,1,247.150000000,253.650000000,400,400,1,1,235.000000000,260.000000000,100,48,1,1,220.000000000,264.940000000,6,7,2,1,214.000000000,265.000000000,5,1,1,1,213.650000000,275.000000000,3,4,1,1,213.000000000,960.000000000,1,25,1,1,211.000000000,,2,0,1,0,TSLA
2024-11-01T08:00:05.242002306Z,2024-11-01T08:00:05.241835967Z,10,2,11667,A,A,0,135.230000000,360,130,166339,297665,134.560000000,135.230000000,100,360,1,1,134.410000000,135.300000000,1,1000,1,1,134.210000000,136.200000000,20,1000,1,1,133.100000000,137.680000000,1000,500,1,1,132.000000000,138.870000000,71,1000,2,2,130.000000000,140.740000000,5,100,1,1,129.050000000,140.880000000,500,1000,1,2,129.000000000,143.000000000,10,1,1,1,128.470000000,143.690000000,500,500,1,1,127.680000000,146.510000000,30,5,1,1,NVDA
2024-11-01T08:00:05.292081938Z,2024-11-01T08:00:05.291915839Z,10,2,16244,A,B,5,220.000000000,20,130,166099,297759,249.820000000,250.680000000,50,100,1,1,249.600000000,250.750000000,1000,50,1,1,249.300000000,251.900000000,1000,1000,1,1,247.150000000,253.650000000,400,400,1,1,235.000000000,260.000000000,100,48,1,1,220.000000000,264.940000000,26,7,3,1,214.000000000,265.000000000,5,1,1,1,213.650000000,275.000000000,3,4,1,1,213.000000000,960.000000000,1,25,1,1,211.000000000,,2,0,1,0,TSLA
2024-11-01T08:00:05.322102932Z,2024-11-01T08:00:05.321936897Z,10,2,11667,A,B,4,132.000000000,1,130,166035,297806,134.560000000,135.230000000,100,360,1,1,134.410000000,135.300000000,1,1000,1,1,134.210000000,136.200000000,20,1000,1,1,133.100000000,137.680000000,1000,500,1,1,132.000000000,138.870000000,72,1000,3,2,130.000000000,140.740000000,5,100,1,1,129.050000000,140.880000000,500,1000,1,2,129.000000000,143.000000000,10,1,1,1,128.470000000,143.690000000,500,500,1,1,127.680000000,146.510000000,30,5,1,1,NVDA
2024-11-01T08:00:05.324142391Z,2024-11-01T08:00:05.323976037Z,10,2,16244,A,B,5,230.000000000,12,130,166354,297807,249.820000000,250.680000000,50,100,1,1,249.600000000,250.750000000,1000,50,1,1,249.300000000,251.900000000,1000,1000,1,1,247.150000000,253.650000000,400,400,1,1,235.000000000,260.000000000,100,48,1,1,230.000000000,264.940000000,12,7,1,1,220.000000000,265.000000000,26,1,3,1,214.000000000,275.000000000,5,4,1,1,213.650000000,960.000000000,3,25,1,1,213.000000000,,1,0,1,0,TSLA
2024-11-01T08:00:05.354302759Z,2024-11-01T08:00:05.354136410Z,10,2,16244,A,B,1,249.770000000,50,130,166349,297865,249.820000000,250.680000000,50,100,1,1,249.770000000,250.750000000,50,50,1,1,249.600000000,251.900000000,1000,1000,1,1,249.300000000,253.650000000,1000,400,1,1,247.150000000,260.000000000,400,48,1,1,235.000000000,264.940000000,100,7,1,1,230.000000000,265.000000000,12,1,1,1,220.000000000,275.000000000,26,4,3,1,214.000000000,960.000000000,5,25,1,1,213.650000000,,3,0,1,0,TSLA
2024-11-01T08:00:05.374782402Z,2024-11-01T08:00:05.374616356Z,10,2,11667,A,A,9,145.000000000,30,130,166046,297883,134.560000000,135.230000000,100,360,1,1,134.410000000,135.300000000,1,1000,1,1,134.210000000,136.200000000,20,1000,1,1,133.100000000,137.680000000,1000,500,1,1,132.000000000,138.870000000,72,1000,3,2,130.000000000,140.740000000,5,100,1,1,129.050000000,140.880000000,500,1000,1,2,129.000000000,143.000000000,10,1,1,1,128.470000000,143.690000000,500,500,1,1,127.680000000,145.000000000,30,30,1,1,NVDA
2024-11-01T08:00:05.429945880Z,2024-11-01T08:00:05.429779649Z,10,2,12463,A,A,0,171.810000000,100,130,166231,297936,,171.810000000,0,100,0,1,,,0,0,0,0,,,0,0,0,0,,,0,0,0,0,,,0,0,0,0,,,0,0,0,0,,,0,0,0,0,,,0,0,0,0,,,0,0,0,0,,,0,0,0,0,PEP
2024-11-01T08:00:05.452312434Z,2024-11-01T08:00:05.452145924Z,10,2,11667,A,B,5,130.520000000,4,130,166510,297963,134.560000000,135.230000000,100,360,1,1,134.410000000,135.300000000,1,1000,1,1,134.210000000,136.200000000,20,1000,1,1,133.100000000,137.680000000,1000,500,1,1,132.000000000,138.870000000,72,1000,3,2,130.520000000,140.740000000,4,100,1,1,130.000000000,140.880000000,5,1000,1,2,129.050000000,143.000000000,500,1,1,1,129.000000000,143.690000000,10,500,1,1,128.470000000,145.000000000,500,30,1,1,NVDA
2024-11-01T08:00:05.478492546Z,2024-11-01T08:00:05.478326529Z,10,2,11667,A,B,8,129.000000000,2,130,166017,298078,134.560000000,135.230000000,100,360,1,1,134.410000000,135.300000000,1,1000,1,1,134.210000000,136.200000000,20,1000,1,1,133.100000000,137.680000000,1000,500,1,1,132.000000000,138.870000000,72,1000,3,2,130.520000000,140.740000000,4,100,1,1,130.000000000,140.880000000,5,1000,1,2,129.050000000,143.000000000,500,1,1,1,129.000000000,143.690000000,12,500,2,1,128.470000000,145.000000000,500,30,1,1,NVDA
2024-11-01T08:00:05.663155685Z,2024-11-01T08:00:05.662989510Z,10,2,16244,A,A,8,300.000000000,7,130,166175,298692,249.820000000,250.680000000,50,100,1,1,249.770000000,250.750000000,50,50,1,1,249.600000000,251.900000000,1000,1000,1,1,249.300000000,253.650000000,1000,400,1,1,247.150000000,260.000000000,400,48,1,1,235.000000000,264.940000000,100,7,1,1,230.000000000,265.000000000,12,1,1,1,220.000000000,275.000000000,26,4,3,1,214.000000000,300.000000000,5,7,1,1,213.650000000,960.000000000,3,25,1,1,TSLA
2024-11-01T08:00:05.777338971Z,2024-11-01T08:00:05.777172581Z,10,2,16244,A,B,1,249.800000000,199,130,166390,298816,249.820000000,250.680000000,50,100,1,1,249.800000000,250.750000000,199,50,1,1,249.770000000,251.900000000,50,1000,1,1,249.600000000,253.650000000,1000,400,1,1,249.300000000,260.000000000,1000,48,1,1,247.150000000,264.940000000,400,7,1,1,235.000000000,265.000000000,100,1,1,1,230.000000000,275.000000000,12,4,1,1,220.000000000,300.000000000,26,7,3,1,214.000000000,960.000000000,5,25,1,1,TSLA
2024-11-01T08:00:05.826373382Z,2024-11-01T08:00:05.826207790Z,10,2,16244,C,A,2,251.900000000,1000,130,165592,298867,249.820000000,250.680000000,50,100,1,1,249.800000000,250.750000000,199,50,1,1,249.770000000,253.650000000,50,400,1,1,249.600000000,260.000000000,1000,48,1,1,249.300000000,264.940000000,1000,7,1,1,247.150000000,265.000000000,400,1,1,1,235.000000000,275.000000000,100,4,1,1,230.000000000,300.000000000,12,7,1,1,220.000000000,960.000000000,26,25,3,1,214.000000000,,5,0,1,0,TSLA
2024-11-01T08:00:05.842040154Z,2024-11-01T08:00:05.841874018Z,10,2,16244,A,A,2,252.100000000,1000,130,166136,298880,249.820000000,250.680000000,50,100,1,1,249.800000000,250.750000000,199,50,1,1,249.770000000,252.100000000,50,1000,1,1,249.600000000,253.650000000,1000,400,1,1,249.300000000,260.000000000,1000,48,1,1,247.150000000,264.940000000,400,7,1,1,235.000000000,265.000000000,100,1,1,1,230.000000000,275.000000000,12,4,1,1,220.000000000,300.000000000,26,7,3,1,214.000000000,960.000000000,5,25,1,1,TSLA
2024-11-01T08:00:05.866605914Z,2024-11-01T08:00:05.866439798Z,10,2,38,A,B,6,100.000000000,1,130,166116,298899,221.200000000,224.400000000,1000,1000,1,1,220.000000000,225.490000000,2,442,1,1,219.690000000,234.000000000,442,20,1,1,217.000000000,240.000000000,1525,150,1,1,190.000000000,,1,0,1,0,180.000000000,,1,0,1,0,100.000000000,,1,0,1,0,,,0,0,0,0,,,0,0,0,0,,,0,0,0,0,AAPL
2024-11-01T08:00:05.869518062Z,2024-11-01T08:00:05.869351689Z,10,2,11667,A,A,2,136.100000000,1000,130,166373,298906,134.560000000,135.230000000,100,360,1,1,134.410000000,135.300000000,1,1000,1,1,134.210000000,136.100000000,20,1000,1,1,133.100000000,136.200000000,1000,1000,1,1,132.000000000,137.680000000,72,500,3,1,130.520000000,138.870000000,4,1000,1,2,130.000000000,140.740000000,5,100,1,1,129.050000000,140.880000000,500,1000,1,2,129.000000000,143.000000000,12,1,2,1,128.470000000,143.690000000,500,500,1,1,NVDA
2024-11-01T08:00:05.869530759Z,2024-11-01T08:00:05.869364967Z,10,2,11667,C,A,3,136.200000000,1000,130,165792,298907,134.560000000,135.230000000,100,360,1,1,134.410000000,135.300000000,1,1000,1,1,134.210000000,136.100000000,20,1000,1,1,133.100000000,137.680000000,1000,500,1,1,132.000000000,138.870000000,72,1000,3,2,130.520000000,140.740000000,4,100,1,1,130.000000000,140.880000000,5,1000,1,2,129.050000000,143.000000000,500,1,1,1,129.000000000,143.690000000,12,500,2,1,128.470000000,145.000000000,500,30,1,1,NVDA
2024-11-01T08:00:05.932102576Z,2024-11-01T08:00:05.931936345Z,10,2,38,A,A,1,225.100000000,2000,130,166231,298989,221.200000000,224.400000000,1000,1000,1,1,220.000000000,225.100000000,2,2000,1,1,219.690000000,225.490000000,442,442,1,1,217.000000000,234.000000000,1525,20,1,1,190.000000000,240.000000000,1,150,1,1,180.000000000,,1,0,1,0,100.000000000,,1,0,1,0,,,0,0,0,0,,,0,0,0,0,,,0,0,0,0,AAPL
2024-11-01T08:00:05.932350098Z,2024-11-01T08:00:05.932183820Z,10,2,38,A,A,0,224.200000000,1000,130,166278,298990,221.200000000,224.200000000,1000,1000,1,1,220.000000000,224.400000000,2,1000,1,1,219.690000000,225.100000000,442,2000,1,1,217.000000000,225.490000000,1525,442,1,1,190.000000000,234.000000000,1,20,1,1,180.000000000,240.000000000,1,150,1,1,100.000000000,,1,0,1,0,,,0,0,0,0,,,0,0,0,0,,,0,0,0,0,AAPL
2024-11-01T08:00:05.933251111Z,2024-11-01T08:00:05.933085429Z,10,2,38,C,A,1,224.400000000,1000,130,165682,298991,221.200000000,224.200000000,1000,1000,1,1,220.000000000,225.100000000,2,2000,1,1,219.690000000,225.490000000,442,442,1,1,217.000000000,234.000000000,1525,20,1,1,190.000000000,240.000000000,1,150,1,1,180.000000000,,1,0,1,0,100.000000000,,1,0,1,0,,,0,0,0,0,,,0,0,0,0,,,0,0,0,0,AAPL
2024-11-01T08:00:05.946422252Z,2024-11-01T08:00:05.946255895Z,10,2,10888,A,B,2,406.000000000,7,130,166357,299003,410.000000000,415.070000000,1,246,1,1,408.960000000,420.000000000,5,3,1,1,406.000000000,468.000000000,7,65,1,1,404.410000000,,246,0,1,0,398.000000000,,5,0,1,0,,,0,0,0,0,,,0,0,0,0,,,0,0,0,0,,,0,0,0,0,,,0,0,0,0,MSFT
2024-11-01T08:00:05.958384234Z,2024-11-01T08:00:05.958218308Z,10,2,11667,C,B,0,134.560000000,100,130,165926,299022,134.410000000,135.230000000,1,360,1,1,134.210000000,135.300000000,20,1000,1,1,133.100000000,136.100000000,1000,1000,1,1,132.000000000,137.680000000,72,500,3,1,130.520000000,138.870000000,4,1000,1,2,130.000000000,140.740000000,5,100,1,1,129.050000000,140.880000000,500,1000,1,2,129.000000000,143.000000000,12,1,2,1,128.470000000,143.690000000,500,500,1,1,128.000000000,145.000000000,21,30,2,1,NVDA
2024-11-01T08:00:05.958397936Z,2024-11-01T08:00:05.958231910Z,10,2,11667,A,B,0,134.440000000,100,130,166026,299023,134.440000000,135.230000000,100,360,1,1,134.410000000,135.300000000,1,1000,1,1,134.210000000,136.100000000,20,1000,1,1,133.100000000,137.680000000,1000,500,1,1,132.000000000,138.870000000,72,1000,3,2,130.520000000,140.740000000,4,100,1,1,130.000000000,140.880000000,5,1000,1,2,129.050000000,143.000000000,500,1,1,1,129.000000000,143.690000000,12,500,2,1,128.470000000,145.000000000,500,30,1,1,NVDA
2024-11-01T08:00:05.961984958Z,2024-11-01T08:00:05.961818767Z,10,2,16244,A,B,0,249.830000000,50,130,166191,299030,249.830000000,250.680000000,50,100,1,1,249.800000000,250.750000000,199,50,1,1,249.770000000,252.100000000,50,1000,1,1,249.600000000,253.650000000,1000,400,1,1,249.300000000,260.000000000,1000,48,1,1,247.150000000,264.940000000,400,7,1,1,235.000000000,265.000000000,100,1,1,1,230.000000000,275.000000000,12,4,1,1,220.000000000,300.000000000,26,7,3,1,214.000000000,960.000000000,5,25,1,1,TSLA
2024-11-01T08:00:05.992007973Z,2024-11-01T08:00:05.991841871Z,10,2,16244,A,B,8,220.000000000,34,130,166102,299054,249.830000000,250.680000000,50,100,1,1,249.800000000,250.750000000,199,50,1,1,249.770000000,252.100000000,50,1000,1,1,249.600000000,253.650000000,1000,400,1,1,249.300000000,260.000000000,1000,48,1,1,247.150000000,264.940000000,400,7,1,1,235.000000000,265.000000000,100,1,1,1,230.000000000,275.000000000,12,4,1,1,220.000000000,300.000000000,60,7,4,1,214.000000000,960.000000000,5,25,1,1,TSLA
2024-11-01T08:00:06.008333344Z,2024-11-01T08:00:06.008167175Z,10,2,16244,A,B,8,225.000000000,8,130,166169,299075,249.830000000,250.680000000,50,100,1,1,249.800000000,250.750000000,199,50,1,1,249.770000000,252.100000000,50,1000,1,1,249.600000000,253.650000000,1000,400,1,1,249.300000000,260.000000000,1000,48,1,1,247.150000000,264.940000000,400,7,1,1,235.000000000,265.000000000,100,1,1,1,230.000000000,275.000000000,12,4,1,1,225.000000000,300.000000000,8,7,1,1,220.000000000,960.000000000,60,25,4,1,TSLA
2024-11-01T08:00:06.030860640Z,2024-11-01T08:00:06.030694395Z,10,2,11667,A,A,0,135.000000000,8,130,166245,299116,134.440000000,135.000000000,100,8,1,1,134.410000000,135.230000000,1,360,1,1,134.210000000,135.300000000,20,1000,1,1,133.100000000,136.100000000,1000,1000,1,1,132.000000000,137.680000000,72,500,3,1,130.520000000,138.870000000,4,1000,1,2,130.000000000,140.740000000,5,100,1,1,129.050000000,140.880000000,500,1000,1,2,129.000000000,143.000000000,12,1,2,1,128.470000000,143.690000000,500,500,1,1,NVDA
2024-11-01T08:00:06.031861392Z,2024-11-01T08:00:06.031695298Z,10,2,16244,A,B,6,235.000000000,30,130,166094,299119,249.830000000,250.680000000,50,100,1,1,249.800000000,250.750000000,199,50,1,1,249.770000000,252.100000000,50,1000,1,1,249.600000000,253.650000000,1000,400,1,1,249.300000000,260.000000000,1000,48,1,1,247.150000000,264.940000000,400,7,1,1,235.000000000,265.000000000,130,1,2,1,230.000000000,275.000000000,12,4,1,1,225.000000000,300.000000000,8,7,1,1,220.000000000,960.000000000,60,25,4,1,TSLA
2024-11-01T08:00:06.052861614Z,2024-11-01T08:00:06.052695502Z,10,2,16244,A,A,7,267.800000000,30,130,166112,299209,249.830000000,250.680000000,50,100,1,1,249.800000000,250.750000000,199,50,1,1,249.770000000,252.100000000,50,1000,1,1,249.600000000,253.650000000,1000,400,1,1,249.300000000,260.000000000,1000,48,1,1,247.150000000,264.940000000,400,7,1,1,235.000000000,265.000000000,130,1,2,1,230.000000000,267.800000000,12,30,1,1,225.000000000,275.000000000,8,4,1,1,220.000000000,300.000000000,60,7,4,1,TSLA
2024-11-01T08:00:06.062906169Z,2024-11-01T08:00:06.062739623Z,10,2,16244,A,A,8,275.000000000,12,130,166546,299266,249.830000000,250.680000000,50,100,1,1,249.800000000,250.750000000,199,50,1,1,249.770000000,252.100000000,50,1000,1,1,249.600000000,253.650000000,1000,400,1,1,249.300000000,260.000000000,1000,48,1,1,247.150000000,264.940000000,400,7,1,1,235.000000000,265.000000000,130,1,2,1,230.000000000,267.800000000,12,30,1,1,225.000000000,275.000000000,8,16,1,2,220.000000000,300.000000000,60,7,4,1,TSLA
2024-11-01T08:00:06.066367690Z,2024-11-01T08:00:06.066201594Z,10,2,16244,A,A,9,300.000000000,1,130,166096,299273,249.830000000,250.680000000,50,100,1,1,249.800000000,250.750000000,199,50,1,1,249.770000000,252.100000000,50,1000,1,1,249.600000000,253.650000000,1000,400,1,1,249.300000000,260.000000000,1000,48,1,1,247.150000000,264.940000000,400,7,1,1,235.000000000,265.000000000,130,1,2,1,230.000000000,267.800000000,12,30,1,1,225.000000000,275.000000000,8,16,1,2,220.000000000,300.000000000,60,8,4,2,TSLA
2024-11-01T08:00:06.078341456Z,2024-11-01T08:00:06.078175284Z,10,2,11667,A,B,1,134.410000000,60,130,166172,299316,134.440000000,135.000000000,100,8,1,1,134.410000000,135.230000000,61,360,2,1,134.210000000,135.300000000,20,1000,1,1,133.100000000,136.100000000,1000,1000,1,1,132.000000000,137.680000000,72,500,3,1,130.520000000,138.870000000,4,1000,1,2,130.000000000,140.740000000,5,100,1,1,129.050000000,140.880000000,500,1000,1,2,129.000000000,143.000000000,12,1,2,1,128.470000000,143.690000000,500,500,1,1,NVDA
2024-11-01T08:00:06.093022196Z,2024-11-01T08:00:06.092855744Z,10,2,16244,A,A,8,273.000000000,1,130,166452,299399,249.830000000,250.680000000,50,100,1,1,249.800000000,250.750000000,199,50,1,1,249.770000000,252.100000000,50,1000,1,1,249.600000000,253.650000000,1000,400,1,1,249.300000000,260.000000000,1000,48,1,1,247.150000000,264.940000000,400,7,1,1,235.000000000,265.000000000,130,1,2,1,230.000000000,267.800000000,12,30,1,1,225.000000000,273.000000000,8,1,1,1,220.000000000,275.000000000,60,16,4,2,TSLA
2024-11-01T08:00:06.125927429Z,2024-11-01T08:00:06.125761515Z,10,2,38,C,A,0,224.200000000,1000,130,165914,299553,221.200000000,225.100000000,1000,2000,1,1,220.000000000,225.490000000,2,442,1,1,219.690000000,234.000000000,442,20,1,1,217.000000000,240.000000000,1525,150,1,1,190.000000000,,1,0,1,0,180.000000000,,1,0,1,0,100.000000000,,1,0,1,0,,,0,0,0,0,,,0,0,0,0,,,0,0,0,0,AAPL
2024-11-01T08:00:06.136524667Z,2024-11-01T08:00:06.136358459Z,10,2,38,A,A,0,224.300000000,1000,130,166208,299579,221.200000000,224.300000000,1000,1000,1,1,220.000000000,225.100000000,2,2000,1,1,219.690000000,225.490000000,442,442,1,1,217.000000000,234.000000000,1525,20,1,1,190.000000000,240.000000000,1,150,1,1,180.000000000,,1,0,1,0,100.000000000,,1,0,1,0,,,0,0,0,0,,,0,0,0,0,,,0,0,0,0,AAPL
2024-11-01T08:00:06.174485927Z,2024-11-01T08:00:06.174319610Z,10,2,16244,A,B,0,249.830000000,50,130,166317,299662,249.830000000,250.680000000,100,100,2,1,249.800000000,250.750000000,199,50,1,1,249.770000000,252.100000000,50,1000,1,1,249.600000000,253.650000000,1000,400,1,1,249.300000000,260.000000000,1000,48,1,1,247.150000000,264.940000000,400,7,1,1,235.000000000,265.000000000,130,1,2,1,230.000000000,267.800000000,12,30,1,1,225.000000000,273.000000000,8,1,1,1,220.000000000,275.000000000,60,16,4,2,TSLA
2024-11-01T08:00:06.178289374Z,2024-11-01T08:00:06.178123098Z,10,2,16244,A,B,4,249.400000000,1000,130,166276,299670,249.830000000,250.680000000,100,100,2,1,249.800000000,250.750000000,199,50,1,1,249.770000000,252.100000000,50,1000,1,1,249.600000000,253.650000000,1000,400,1,1,249.400000000,260.000000000,1000,48,1,1,249.300000000,264.940000000,1000,7,1,1,247.150000000,265.000000000,400,1,1,1,235.000000000,267.800000000,130,30,2,1,230.000000000,273.000000000,12,1,1,1,225.000000000,275.000000000,8,16,1,2,TSLA
2024-11-01T08:00:06.178316655Z,2024-11-01T08:00:06.178150776Z,10,2,16244,C,B,5,249.300000000,1000,130,165879,299671,249.830000000,250.680000000,100,100,2,1,249.800000000,250.750000000,199,50,1,1,249.770000000,252.100000000,50,1000,1,1,249.600000000,253.650000000,1000,400,1,1,249.400000000,260.000000000,1000,48,1,1,247.150000000,264.940000000,400,7,1,1,235.000000000,265.000000000,130,1,2,1,230.000000000,267.800000000,12,30,1,1,225.000000000,273.000000000,8,1,1,1,220.000000000,275.000000000,60,16,4,2,TSLA
2024-11-01T08:00:06.187941659Z,2024-11-01T08:00:06.187775355Z,10,2,16244,A,B,6,245.000000000,50,130,166304,299694,249.830000000,250.680000000,100,100,2,1,249.800000000,250.750000000,199,50,1,1,249.770000000,252.100000000,50,1000,1,1,249.600000000,253.650000000,1000,400,1,1,249.400000000,260.000000000,1000,48,1,1,247.150000000,264.940000000,400,7,1,1,245.000000000,265.000000000,50,1,1,1,235.000000000,267.800000000,130,30,2,1,230.000000000,273.000000000,12,1,1,1,225.000000000,275.000000000,8,16,1,2,TSLA
2024-11-01T08:00:06.188451206Z,2024-11-01T08:00:06.188285188Z,10,2,16244,A,B,5,247.700000000,1000,130,166018,299697,249.830000000,250.680000000,100,100,2,1,249.800000000,250.750000000,199,50,1,1,249.770000000,252.100000000,50,1000,1,1,249.600000000,253.650000000,1000,400,1,1,249.400000000,260.000000000,1000,48,1,1,247.700000000,264.940000000,1000,7,1,1,247.150000000,265.000000000,400,1,1,1,245.000000000,267.800000000,50,30,1,1,235.000000000,273.000000000,130,1,2,1,230.000000000,275.000000000,12,16,1,2,TSLA
2024-11-01T08:00:06.200506093Z,2024-11-01T08:00:06.200339057Z,10,2,16244,A,A,9,274.000000000,86,130,167036,299723,249.830000000,250.680000000,100,100,2,1,249.800000000,250.750000000,199,50,1,1,249.770000000,252.100000000,50,1000,1,1,249.600000000,253.650000000,1000,400,1,1,249.400000000,260.000000000,1000,48,1,1,247.700000000,264.940000000,1000,7,1,1,247.150000000,265.000000000,400,1,1,1,245.000000000,267.800000000,50,30,1,1,235.000000000,273.000000000,130,1,2,1,230.000000000,274.000000000,12,86,1,1,TSLA
2024-11-01T08:00:06.222383091Z,2024-11-01T08:00:06.222216956Z,10,2,10888,A,A,2,448.000000000,5,130,166135,299769,410.000000000,415.070000000,1,246,1,1,408.960000000,420.000000000,5,3,1,1,406.000000000,448.000000000,7,5,1,1,404.410000000,468.000000000,246,65,1,1,398.000000000,,5,0,1,0,,,0,0,0,0,,,0,0,0,0,,,0,0,0,0,,,0,0,0,0,,,0,0,0,0,MSFT
2024-11-01T08:00:06.225043027Z,2024-11-01T08:00:06.224877387Z,10,2,16244,C,B,0,249.830000000,50,130,165640,299780,249.830000000,250.680000000,50,100,1,1,249.800000000,250.750000000,199,50,1,1,249.770000000,252.100000000,50,1000,1,1,249.600000000,253.650000000,1000,400,1,1,249.400000000,260.000000000,1000,48,1,1,247.700000000,264.940000000,1000,7,1,1,247.150000000,265.000000000,400,1,1,1,245.000000000,267.800000000,50,30,1,1,235.000000000,273.000000000,130,1,2,1,230.000000000,274.000000000,12,86,1,1,TSLA
2024-11-01T08:00:06.225057101Z,2024-11-01T08:00:06.224890172Z,10,2,16244,A,B,0,249.860000000,50,130,166929,299781,249.860000000,250.680000000,50,100,1,1,249.800000000,250.750000000,199,50,1,1,249.770000000,252.100000000,50,1000,1,1,249.600000000,253.650000000,1000,400,1,1,249.400000000,260.000000000,1000,48,1,1,247.700000000,264.940000000,1000,7,1,1,247.150000000,265.000000000,400,1,1,1,245.000000000,267.800000000,50,30,1,1,235.000000000,273.000000000,130,1,2,1,230.000000000,274.000000000,12,86,1,1,TSLA
2024-11-01T08:00:06.226385793Z,2024-11-01T08:00:06.226219652Z,10,2,16244,A,B,4,249.500000000,1000,130,166141,299788,249.860000000,250.680000000,50,100,1,1,249.800000000,250.750000000,199,50,1,1,249.770000000,252.100000000,50,1000,1,1,249.600000000,253.650000000,1000,400,1,1,249.500000000,260.000000000,1000,48,1,1,249.400000000,264.940000000,1000,7,1,1,247.700000000,265.000000000,1000,1,1,1,247.150000000,267.800000000,400,30,1,1,245.000000000,273.000000000,50,1,1,1,235.000000000,274.000000000,130,86,2,1,TSLA
2024-11-01T08:00:06.262383478Z,2024-11-01T08:00:06.262217063Z,10,2,10888,A,B,5,385.000000000,50,130,166415,299864,410.000000000,415.070000000,1,246,1,1,408.960000000,420.000000000,5,3,1,1,406.000000000,448.000000000,7,5,1,1,404.410000000,468.000000000,246,65,1,1,398.000000000,,5,0,1,0,385.000000000,,50,0,1,0,,,0,0,0,0,,,0,0,0,0,,,0,0,0,0,,,0,0,0,0,MSFT
2024-11-01T08:00:06.262976803Z,2024-11-01T08:00:06.262810319Z,10,2,10888,A,B,2,406.350000000,2,130,166484,299874,410.000000000,415.070000000,1,246,1,1,408.960000000,420.000000000,5,3,1,1,406.350000000,448.000000000,2,5,1,1,406.000000000,468.000000000,7,65,1,1,404.410000000,,246,0,1,0,398.000000000,,5,0,1,0,385.000000000,,50,0,1,0,,,0,0,0,0,,,0,0,0,0,,,0,0,0,0,MSFT
2024-11-01T08:00:06.284148577Z,2024-11-01T08:00:06.283982285Z,10,2,16244,A,B,0,249.880000000,50,130,166292,299988,249.880000000,250.680000000,50,100,1,1,249.800000000,250.750000000,199,50,1,1,249.770000000,252.100000000,50,1000,1,1,249.600000000,253.650000000,1000,400,1,1,249.500000000,260.000000000,1000,48,1,1,249.400000000,264.940000000,1000,7,1,1,247.700000000,265.000000000,1000,1,1,1,247.150000000,267.800000000,400,30,1,1,245.000000000,273.000000000,50,1,1,1,235.000000000,274.000000000,130,86,2,1,TSLA
2024-11-01T08:00:06.336020477Z,2024-11-01T08:00:06.335854165Z,10,2,10888,A,B,7,380.000000000,10,130,166312,300045,410.000000000,415.070000000,1,246,1,1,408.960000000,420.000000000,5,3,1,1,406.350000000,448.000000000,2,5,1,1,406.000000000,468.000000000,7,65,1,1,404.410000000,,246,0,1,0,398.000000000,,5,0,1,0,385.000000000,,50,0,1,0,380.000000000,,10,0,1,0,,,0,0,0,0,,,0,0,0,0,MSFT
2024-11-01T08:00:06.356470084Z,2024-11-01T08:00:06.356303814Z,10,2,16244,A,A,8,270.000000000,3,130,166270,300060,249.880000000,250.680000000,50,100,1,1,249.800000000,250.750000000,199,50,1,1,249.770000000,252.100000000,50,1000,1,1,249.600000000,253.650000000,1000,400,1,1,249.500000000,260.000000000,1000,48,1,1,249.400000000,264.940000000,1000,7,1,1,247.700000000,265.000000000,1000,1,1,1,247.150000000,267.800000000,400,30,1,1,245.000000000,270.000000000,50,3,1,1,235.000000000,273.000000000,130,1,2,1,TSLA
2024-11-01T08:00:06.357258648Z,2024-11-01T08:00:06.357092454Z,10,2,11667,A,B,3,134.200000000,3,130,166194,300061,134.440000000,135.000000000,100,8,1,1,134.410000000,135.230000000,61,360,2,1,134.210000000,135.300000000,20,1000,1,1,134.200000000,136.100000000,3,1000,1,1,133.100000000,137.680000000,1000,500,1,1,132.000000000,138.870000000,72,1000,3,2,130.520000000,140.740000000,4,100,1,1,130.000000000,140.880000000,5,1000,1,2,129.050000000,143.000000000,500,1,1,1,129.000000000,143.690000000,12,500,2,1,NVDA
2024-11-01T08:00:06.359584924Z,2024-11-01T08:00:06.359418598Z,10,2,16244,A,B,0,249.880000000,50,130,166326,300069,249.880000000,250.680000000,100,100,2,1,249.800000000,250.750000000,199,50,1,1,249.770000000,252.100000000,50,1000,1,1,249.600000000,253.650000000,1000,400,1,1,249.500000000,260.000000000,1000,48,1,1,249.400000000,264.940000000,1000,7,1,1,247.700000000,265.000000000,1000,1,1,1,247.150000000,267.800000000,400,30,1,1,245.000000000,270.000000000,50,3,1,1,235.000000000,273.000000000,130,1,2,1,TSLA
2024-11-01T08:00:06.414302465Z,2024-11-01T08:00:06.414136263Z,10,2,10888,A,B,6,387.000000000,25,130,166202,300131,410.000000000,415.070000000,1,246,1,1,408.960000000,420.000000000,5,3,1,1,406.350000000,448.000000000,2,5,1,1,406.000000000,468.000000000,7,65,1,1,404.410000000,,246,0,1,0,398.000000000,,5,0,1,0,387.000000000,,25,0,1,0,385.000000000,,50,0,1,0,380.000000000,,10,0,1,0,,,0,0,0,0,MSFT
2024-11-01T08:00:06.429906713Z,2024-11-01T08:00:06.429740329Z,10,2,10888,A,B,5,398.900000000,3,130,166384,300137,410.000000000,415.070000000,1,246,1,1,408.960000000,420.000000000,5,3,1,1,406.350000000,448.000000000,2,5,1,1,406.000000000,468.000000000,7,65,1,1,404.410000000,,246,0,1,0,398.900000000,,3,0,1,0,398.000000000,,5,0,1,0,387.000000000,,25,0,1,0,385.000000000,,50,0,1,0,380.000000000,,10,0,1,0,MSFT
2024-11-01T08:00:06.487922637Z,2024-11-01T08:00:06.487756506Z,10,2,11667,C,B,4,133.100000000,1000,130,166131,300204,134.440000000,135.000000000,100,8,1,1,134.410000000,135.230000000,61,360,2,1,134.210000000,135.300000000,20,1000,1,1,134.200000000,136.100000000,3,1000,1,1,132.000000000,137.680000000,72,500,3,1,130.520000000,138.870000000,4,1000,1,2,130.000000000,140.740000000,5,100,1,1,129.050000000,140.880000000,500,1000,1,2,129.000000000,143.000000000,12,1,2,1,128.470000000,143.690000000,500,500,1,1,NVDA
2024-11-01T08:00:06.489155999Z,2024-11-01T08:00:06.488990261Z,10,2,38,C,A,1,225.100000000,1000,130,165738,300206,221.200000000,224.300000000,1000,1000,1,1,220.000000000,225.100000000,2,1000,1,1,219.690000000,225.490000000,442,442,1,1,217.000000000,234.000000000,1525,20,1,1,190.000000000,240.000000000,1,150,1,1,180.000000000,,1,0,1,0,100.000000000,,1,0,1,0,,,0,0,0,0,,,0,0,0,0,,,0,0,0,0,AAPL
2024-11-01T08:00:06.489167808Z,2024-11-01T08:00:06.489001059Z,10,2,38,C,A,0,224.300000000,1000,130,166749,300207,221.200000000,225.100000000,1000,1000,1,1,220.000000000,225.490000000,2,442,1,1,219.690000000,234.000000000,442,20,1,1,217.000000000,240.000000000,1525,150,1,1,190.000000000,,1,0,1,0,180.000000000,,1,0,1,0,100.000000000,,1,0,1,0,,,0,0,0,0,,,0,0,0,0,,,0,0,0,0,AAPL
2024-11-01T08:00:06.499343249Z,2024-11-01T08:00:06.499177058Z,10,2,38,A,A,0,224.600000000,1000,130,166191,300222,221.200000000,224.600000000,1000,1000,1,1,220.000000000,225.100000000,2,1000,1,1,219.690000000,225.490000000,442,442,1,1,217.000000000,234.000000000,1525,20,1,1,190.000000000,240.000000000,1,150,1,1,180.000000000,,1,0,1,0,100.000000000,,1,0,1,0,,,0,0,0,0,,,0,0,0,0,,,0,0,0,0,AAPL
2024-11-01T08:00:06.499393805Z,2024-11-01T08:00:06.499228140Z,10,2,38,C,A,1,225.100000000,1000,130,165665,300223,221.200000000,224.600000000,1000,1000,1,1,220.000000000,225.490000000,2,442,1,1,219.690000000,234.000000000,442,20,1,1,217.000000000,240.000000000,1525,150,1,1,190.000000000,,1,0,1,0,180.000000000,,1,0,1,0,100.000000000,,1,0,1,0,,,0,0,0,0,,,0,0,0,0,,,0,0,0,0,AAPL
2024-11-01T08:00:06.545228230Z,2024-11-01T08:00:06.545061771Z,10,2,11667,A,A,6,139.420000000,1,130,166459,300261,134.440000000,135.000000000,100,8,1,1,134.410000000,135.230000000,61,360,2,1,134.210000000,135.300000000,20,1000,1,1,134.200000000,136.100000000,3,1000,1,1,132.000000000,137.680000000,72,500,3,1,130.520000000,138.870000000,4,1000,1,2,130.000000000,139.420000000,5,1,1,1,129.050000000,140.740000000,500,100,1,1,129.000000000,140.880000000,12,1000,2,2,128.470000000,143.000000000,500,1,1,1,NVDA
2024-11-01T08:00:06.545347211Z,2024-11-01T08:00:06.545181012Z,10,2,11667,A,A,4,137.060000000,1,130,166199,300263,134.440000000,135.000000000,100,8,1,1,134.410000000,135.230000000,61,360,2,1,134.210000000,135.300000000,20,1000,1,1,134.200000000,136.100000000,3,1000,1,1,132.000000000,137.060000000,72,1,3,1,130.520000000,137.680000000,4,500,1,1,130.000000000,138.870000000,5,1000,1,2,129.050000000,139.420000000,500,1,1,1,129.000000000,140.740000000,12,100,2,1,128.470000000,140.880000000,500,1000,1,2,NVDA
2024-11-01T08:00:06.545469038Z,2024-11-01T08:00:06.545301893Z,10,2,11667,A,B,4,133.160000000,1,130,167145,300264,134.440000000,135.000000000,100,8,1,1,134.410000000,135.230000000,61,360,2,1,134.210000000,135.300000000,20,1000,1,1,134.200000000,136.100000000,3,1000,1,1,133.160000000,137.060000000,1,1,1,1,132.000000000,137.680000000,72,500,3,1,130.520000000,138.870000000,4,1000,1,2,130.000000000,139.420000000,5,1,1,1,129.050000000,140.740000000,500,100,1,1,129.000000000,140.880000000,12,1000,2,2,NVDA
2024-11-01T08:00:06.545583895Z,2024-11-01T08:00:06.545417855Z,10,2,11667,A,A,6,138.620000000,1,130,166040,300265,134.440000000,135.000000000,100,8,1,1,134.410000000,135.230000000,61,360,2,1,134.210000000,135.300000000,20,1000,1,1,134.200000000,136.100000000,3,1000,1,1,133.160000000,137.060000000,1,1,1,1,132.000000000,137.680000000,72,500,3,1,130.520000000,138.620000000,4,1,1,1,130.000000000,138.870000000,5,1000,1,2,129.050000000,139.420000000,500,1,1,1,129.000000000,140.740000000,12,100,2,1,NVDA
2024-11-01T08:00:06.545707182Z,2024-11-01T08:00:06.545540553Z,10,2,11667,A,A,8,139.060000000,1,130,166629,300266,134.440000000,135.000000000,100,8,1,1,134.410000000,135.230000000,61,360,2,1,134.210000000,135.300000000,20,1000,1,1,134.200000000,136.100000000,3,1000,1,1,133.160000000,137.060000000,1,1,1,1,132.000000000,137.680000000,72,500,3,1,130.520000000,138.620000000,4,1,1,1,130.000000000,138.870000000,5,1000,1,2,129.050000000,139.060000000,500,1,1,1,129.000000000,139.420000000,12,1,2,1,NVDA
2024-11-01T08:00:06.545906761Z,2024-11-01T08:00:06.545740131Z,10,2,11667,A,A,4,136.220000000,1,130,166630,300268,134.440000000,135.000000000,100,8,1,1,134.410000000,135.230000000,61,360,2,1,134.210000000,135.300000000,20,1000,1,1,134.200000000,136.100000000,3,1000,1,1,133.160000000,136.220000000,1,1,1,1,132.000000000,137.060000000,72,1,3,1,130.520000000,137.680000000,4,500,1,1,130.000000000,138.620000000,5,1,1,1,129.050000000,138.870000000,500,1000,1,2,129.000000000,139.060000000,12,1,2,1,NVDA
2024-11-01T08:00:06.546024337Z,2024-11-01T08:00:06.545857987Z,10,2,11667,A,A,7,137.820000000,1,130,166350,300269,134.440000000,135.000000000,100,8,1,1,134.410000000,135.230000000,61,360,2,1,134.210000000,135.300000000,20,1000,1,1,134.200000000,136.100000000,3,1000,1,1,133.160000000,136.220000000,1,1,1,1,132.000000000,137.060000000,72,1,3,1,130.520000000,137.680000000,4,500,1,1,130.000000000,137.820000000,5,1,1,1,129.050000000,138.620000000,500,1,1,1,129.000000000,138.870000000,12,1000,2,2,NVDA
2024-11-01T08:00:06.546223878Z,2024-11-01T08:00:06.546057605Z,10,2,11667,A,A,5,136.620000000,1,130,166273,300271,134.440000000,135.000000000,100,8,1,1,134.410000000,135.230000000,61,360,2,1,134.210000000,135.300000000,20,1000,1,1,134.200000000,136.100000000,3,1000,1,1,133.160000000,136.220000000,1,1,1,1,132.000000000,136.620000000,72,1,3,1,130.520000000,137.060000000,4,1,1,1,130.000000000,137.680000000,5,500,1,1,129.050000000,137.820000000,500,1,1,1,129.000000000,138.620000000,12,1,2,1,NVDA
2024-11-01T08:00:06.546343926Z,2024-11-01T08:00:06.546177821Z,10,2,11667,A,A,3,135.820000000,1,130,166105,300272,134.440000000,135.000000000,100,8,1,1,134.410000000,135.230000000,61,360,2,1,134.210000000,135.300000000,20,1000,1,1,134.200000000,135.820000000,3,1,1,1,133.160000000,136.100000000,1,1000,1,1,132.000000000,136.220000000,72,1,3,1,130.520000000,136.620000000,4,1,1,1,130.000000000,137.060000000,5,1,1,1,129.050000000,137.680000000,500,500,1,1,129.000000000,137.820000000,12,1,2,1,NVDA
2024-11-01T08:00:06.546425983Z,2024-11-01T08:00:06.546259845Z,10,2,11667,A,A,8,137.420000000,1,130,166138,300273,134.440000000,135.000000000,100,8,1,1,134.410000000,135.230000000,61,360,2,1,134.210000000,135.300000000,20,1000,1,1,134.200000000,135.820000000,3,1,1,1,133.160000000,136.100000000,1,1000,1,1,132.000000000,136.220000000,72,1,3,1,130.520000000,136.620000000,4,1,1,1,130.000000000,137.060000000,5,1,1,1,129.050000000,137.420000000,500,1,1,1,129.000000000,137.680000000,12,500,2,1,NVDA
2024-11-01T08:00:06.604163200Z,2024-11-01T08:00:06.603997329Z,10,2,11667,A,B,7,130.160000000,1,130,165871,300526,134.440000000,135.000000000,100,8,1,1,134.410000000,135.230000000,61,360,2,1,134.210000000,135.300000000,20,1000,1,1,134.200000000,135.820000000,3,1,1,1,133.160000000,136.100000000,1,1000,1,1,132.000000000,136.220000000,72,1,3,1,130.520000000,136.620000000,4,1,1,1,130.160000000,137.060000000,1,1,1,1,130.000000000,137.420000000,5,1,1,1,129.050000000,137.680000000,500,500,1,1,NVDA
2024-11-01T08:00:06.604402754Z,2024-11-01T08:00:06.604236437Z,10,2,11667,A,B,5,132.160000000,1,130,166317,300529,134.440000000,135.000000000,100,8,1,1,134.410000000,135.230000000,61,360,2,1,134.210000000,135.300000000,20,1000,1,1,134.200000000,135.820000000,3,1,1,1,133.160000000,136.100000000,1,1000,1,1,132.160000000,136.220000000,1,1,1,1,132.000000000,136.620000000,72,1,3,1,130.520000000,137.060000000,4,1,1,1,130.160000000,137.420000000,1,1,1,1,130.000000000,137.680000000,5,500,1,1,NVDA
2024-11-01T08:00:06.604482005Z,2024-11-01T08:00:06.604315892Z,10,2,11667,A,B,7,131.660000000,1,130,166113,300530,134.440000000,135.000000000,100,8,1,1,134.410000000,135.230000000,61,360,2,1,134.210000000,135.300000000,20,1000,1,1,134.200000000,135.820000000,3,1,1,1,133.160000000,136.100000000,1,1000,1,1,132.160000000,136.220000000,1,1,1,1,132.000000000,136.620000000,72,1,3,1,131.660000000,137.060000000,1,1,1,1,130.520000000,137.420000000,4,1,1,1,130.160000000,137.680000000,1,500,1,1,NVDA
2024-11-01T08:00:06.604603304Z,2024-11-01T08:00:06.604437230Z,10,2,11667,A,A,3,135.420000000,1,130,166074,300531,134.440000000,135.000000000,100,8,1,1,134.410000000,135.230000000,61,360,2,1,134.210000000,135.300000000,20,1000,1,1,134.200000000,135.420000000,3,1,1,1,133.160000000,135.820000000,1,1,1,1,132.160000000,136.100000000,1,1000,1,1,132.000000000,136.220000000,72,1,3,1,131.660000000,136.620000000,1,1,1,1,130.520000000,137.060000000,4,1,1,1,130.160000000,137.420000000,1,1,1,1,NVDA
2024-11-01T08:00:06.604723966Z,2024-11-01T08:00:06.604556994Z,10,2,11667,A,A,0,134.920000000,1,130,166972,300533,134.440000000,134.920000000,100,1,1,1,134.410000000,135.000000000,61,8,2,1,134.210000000,135.230000000,20,360,1,1,134.200000000,135.300000000,3,1000,1,1,133.160000000,135.420000000,1,1,1,1,132.160000000,135.820000000,1,1,1,1,132.000000000,136.100000000,72,1000,3,1,131.660000000,136.220000000,1,1,1,1,130.520000000,136.620000000,4,1,1,1,130.160000000,137.060000000,1,1,1,1,NVDA
2024-11-01T08:00:06.604844139Z,2024-11-01T08:00:06.604677905Z,10,2,11667,A,B,5,132.660000000,1,130,166234,300534,134.440000000,134.920000000,100,1,1,1,134.410000000,135.000000000,61,8,2,1,134.210000000,135.230000000,20,360,1,1,134.200000000,135.300000000,3,1000,1,1,133.160000000,135.420000000,1,1,1,1,132.660000000,135.820000000,1,1,1,1,132.160000000,136.100000000,1,1000,1,1,132.000000000,136.220000000,72,1,3,1,131.660000000,136.620000000,1,1,1,1,130.520000000,137.060000000,4,1,1,1,NVDA
2024-11-01T08:00:06.604962915Z,2024-11-01T08:00:06.604796654Z,10,2,11667,A,B,9,131.160000000,1,130,166261,300535,134.440000000,134.920000000,100,1,1,1,134.410000000,135.000000000,61,8,2,1,134.210000000,135.230000000,20,360,1,1,134.200000000,135.300000000,3,1000,1,1,133.160000000,135.420000000,1,1,1,1,132.660000000,135.820000000,1,1,1,1,132.160000000,136.100000000,1,1000,1,1,132.000000000,136.220000000,72,1,3,1,131.660000000,136.620000000,1,1,1,1,131.160000000,137.060000000,1,1,1,1,NVDA
2024-11-01T08:00:06.622143213Z,2024-11-01T08:00:06.621976999Z,10,2,16244,A,B,9,243.200000000,15,130,166214,300581,249.880000000,250.680000000,100,100,2,1,249.800000000,250.750000000,199,50,1,1,249.770000000,252.100000000,50,1000,1,1,249.600000000,253.650000000,1000,400,1,1,249.500000000,260.000000000,1000,48,1,1,249.400000000,264.940000000,1000,7,1,1,247.700000000,265.000000000,1000,1,1,1,247.150000000,267.800000000,400,30,1,1,245.000000000,270.000000000,50,3,1,1,243.200000000,273.000000000,15,1,1,1,TSLA
2024-11-01T08:00:06.644817808Z,2024-11-01T08:00:06.644651453Z,10,2,38,A,A,4,370.000000000,100,130,166355,300637,221.200000000,224.600000000,1000,1000,1,1,220.000000000,225.490000000,2,442,1,1,219.690000000,234.000000000,442,20,1,1,217.000000000,240.000000000,1525,150,1,1,190.000000000,370.000000000,1,100,1,1,180.000000000,,1,0,1,0,100.000000000,,1,0,1,0,,,0,0,0,0,,,0,0,0,0,,,0,0,0,0,AAPL
2024-11-01T08:00:06.716302339Z,2024-11-01T08:00:06.716136065Z,10,2,38,A,B,0,221.300000000,1000,130,166274,300753,221.300000000,224.600000000,1000,1000,1,1,221.200000000,225.490000000,1000,442,1,1,220.000000000,234.000000000,2,20,1,1,219.690000000,240.000000000,442,150,1,1,217.000000000,370.000000000,1525,100,1,1,190.000000000,,1,0,1,0,180.000000000,,1,0,1,0,100.000000000,,1,0,1,0,,,0,0,0,0,,,0,0,0,0,AAPL
2024-11-01T08:00:06.716394402Z,2024-11-01T08:00:06.716228524Z,10,2,38,C,B,1,221.200000000,1000,130,165878,300754,221.300000000,224.600000000,1000,1000,1,1,220.000000000,225.490000000,2,442,1,1,219.690000000,234.000000000,442,20,1,1,217.000000000,240.000000000,1525,150,1,1,190.000000000,370.000000000,1,100,1,1,180.000000000,,1,0,1,0,100.000000000,,1,0,1,0,,,0,0,0,0,,,0,0,0,0,,,0,0,0,0,AAPL
2024-11-01T08:00:06.756335271Z,2024-11-01T08:00:06.756168964Z,10,2,11667,A,B,0,134.500000000,500,130,166307,300777,134.500000000,134.920000000,500,1,1,1,134.440000000,135.000000000,100,8,1,1,134.410000000,135.230000000,61,360,2,1,134.210000000,135.300000000,20,1000,1,1,134.200000000,135.420000000,3,1,1,1,133.160000000,135.820000000,1,1,1,1,132.660000000,136.100000000,1,1000,1,1,132.160000000,136.220000000,1,1,1,1,132.000000000,136.620000000,72,1,3,1,131.660000000,137.060000000,1,1,1,1,NVDA
2024-11-01T08:00:06.763688556Z,2024-11-01T08:00:06.763522181Z,10,2,10888,A,B,2,407.600000000,16,130,166375,300780,410.000000000,415.070000000,1,246,1,1,408.960000000,420.000000000,5,3,1,1,407.600000000,448.000000000,16,5,1,1,406.350000000,468.000000000,2,65,1,1,406.000000000,,7,0,1,0,404.410000000,,246,0,1,0,398.900000000,,3,0,1,0,398.000000000,,5,0,1,0,387.000000000,,25,0,1,0,385.000000000,,50,0,1,0,MSFT
2024-11-01T08:00:06.816236941Z,2024-11-01T08:00:06.816070840Z,10,2,11667,A,A,1,135.000000000,10,130,166101,300807,134.500000000,134.920000000,500,1,1,1,134.440000000,135.000000000,100,18,1,2,134.410000000,135.230000000,61,360,2,1,134.210000000,135.300000000,20,1000,1,1,134.200000000,135.420000000,3,1,1,1,133.160000000,135.820000000,1,1,1,1,132.660000000,136.100000000,1,1000,1,1,132.160000000,136.220000000,1,1,1,1,132.000000000,136.620000000,72,1,3,1,131.660000000,137.060000000,1,1,1,1,NVDA
2024-11-01T08:00:06.880701595Z,2024-11-01T08:00:06.880535282Z,10,2,16244,A,B,8,245.000000000,5,130,166313,300879,249.880000000,250.680000000,100,100,2,1,249.800000000,250.750000000,199,50,1,1,249.770000000,252.100000000,50,1000,1,1,249.600000000,253.650000000,1000,400,1,1,249.500000000,260.000000000,1000,48,1,1,249.400000000,264.940000000,1000,7,1,1,247.700000000,265.000000000,1000,1,1,1,247.150000000,267.800000000,400,30,1,1,245.000000000,270.000000000,55,3,2,1,243.200000000,273.000000000,15,1,1,1,TSLA
2024-11-01T08:00:06.991065733Z,2024-11-01T08:00:06.990899411Z,10,2,10888,A,A,2,448.000000000,10,130,166322,300975,410.000000000,415.070000000,1,246,1,1,408.960000000,420.000000000,5,3,1,1,407.600000000,448.000000000,16,15,1,2,406.350000000,468.000000000,2,65,1,1,406.000000000,,7,0,1,0,404.410000000,,246,0,1,0,398.900000000,,3,0,1,0,398.000000000,,5,0,1,0,387.000000000,,25,0,1,0,385.000000000,,50,0,1,0,MSFT
2024-11-01T08:00:07.022666513Z,2024-11-01T08:00:07.022500209Z,10,2,6905,A,B,0,84.040000000,100,130,166304,300993,84.040000000,91.880000000,100,100,1,1,,,0,0,0,0,,,0,0,0,0,,,0,0,0,0,,,0,0,0,0,,,0,0,0,0,,,0,0,0,0,,,0,0,0,0,,,0,0,0,0,,,0,0,0,0,GILD
2024-11-01T08:00:07.027301482Z,2024-11-01T08:00:07.027135394Z,10,2,10888,A,A,3,450.000000000,10,130,166088,301004,410.000000000,415.070000000,1,246,1,1,408.960000000,420.000000000,5,3,1,1,407.600000000,448.000000000,16,15,1,2,406.350000000,450.000000000,2,10,1,1,406.000000000,468.000000000,7,65,1,1,404.410000000,,246,0,1,0,398.900000000,,3,0,1,0,398.000000000,,5,0,1,0,387.000000000,,25,0,1,0,385.000000000,,50,0,1,0,MSFT
2024-11-01T08:00:07.045783632Z,2024-11-01T08:00:07.045617390Z,10,2,10888,A,B,6,400.000000000,10,130,166242,301025,410.000000000,415.070000000,1,246,1,1,408.960000000,420.000000000,5,3,1,1,407.600000000,448.000000000,16,15,1,2,406.350000000,450.000000000,2,10,1,1,406.000000000,468.000000000,7,65,1,1,404.410000000,,246,0,1,0,400.000000000,,10,0,1,0,398.900000000,,3,0,1,0,398.000000000,,5,0,1,0,387.000000000,,25,0,1,0,MSFT
2024-11-01T08:00:07.049111722Z,2024-11-01T08:00:07.048945412Z,10,2,10888,A,A,2,445.000000000,25,130,166310,301026,410.000000000,415.070000000,1,246,1,1,408.960000000,420.000000000,5,3,1,1,407.600000000,445.000000000,16,25,1,1,406.350000000,448.000000000,2,15,1,2,406.000000000,450.000000000,7,10,1,1,404.410000000,468.000000000,246,65,1,1,400.000000000,,10,0,1,0,398.900000000,,3,0,1,0,398.000000000,,5,0,1,0,387.000000000,,25,0,1,0,MSFT
2024-11-01T08:00:07.079894788Z,2024-11-01T08:00:07.079728933Z,10,2,16244,C,A,1,250.750000000,50,130,165855,301044,249.880000000,250.680000000,100,100,2,1,249.800000000,252.100000000,199,1000,1,1,249.770000000,253.650000000,50,400,1,1,249.600000000,260.000000000,1000,48,1,1,249.500000000,264.940000000,1000,7,1,1,249.400000000,265.000000000,1000,1,1,1,247.700000000,267.800000000,1000,30,1,1,247.150000000,270.000000000,400,3,1,1,245.000000000,273.000000000,55,1,2,1,243.200000000,274.000000000,15,86,1,1,TSLA
2024-11-01T08:00:07.089199825Z,2024-11-01T08:00:07.089033596Z,10,2,16244,A,A,1,250.760000000,50,130,166229,301047,249.880000000,250.680000000,100,100,2,1,249.800000000,250.760000000,199,50,1,1,249.770000000,252.100000000,50,1000,1,1,249.600000000,253.650000000,1000,400,1,1,249.500000000,260.000000000,1000,48,1,1,249.400000000,264.940000000,1000,7,1,1,247.700000000,265.000000000,1000,1,1,1,247.150000000,267.800000000,400,30,1,1,245.000000000,270.000000000,55,3,2,1,243.200000000,273.000000000,15,1,1,1,TSLA
2024-11-01T08:00:07.101021468Z,2024-11-01T08:00:07.100855216Z,10,2,10888,A,B,5,405.000000000,10,130,166252,301052,410.000000000,415.070000000,1,246,1,1,408.960000000,420.000000000,5,3,1,1,407.600000000,445.000000000,16,25,1,1,406.350000000,448.000000000,2,15,1,2,406.000000000,450.000000000,7,10,1,1,405.000000000,468.000000000,10,65,1,1,404.410000000,,246,0,1,0,400.000000000,,10,0,1,0,398.900000000,,3,0,1,0,398.000000000,,5,0,1,0,MSFT
2024-11-01T08:00:07.104804757Z,2024-11-01T08:00:07.104638780Z,10,2,16244,C,B,0,249.880000000,50,130,165977,301056,249.880000000,250.680000000,50,100,1,1,249.800000000,250.760000000,199,50,1,1,249.770000000,252.100000000,50,1000,1,1,249.600000000,253.650000000,1000,400,1,1,249.500000000,260.000000000,1000,48,1,1,249.400000000,264.940000000,1000,7,1,1,247.700000000,265.000000000,1000,1,1,1,247.150000000,267.800000000,400,30,1,1,245.000000000,270.000000000,55,3,2,1,243.200000000,273.000000000,15,1,1,1,TSLA
2024-11-01T08:00:07.104820824Z,2024-11-01T08:00:07.104654217Z,10,2,16244,A,B,0,249.890000000,50,130,166607,301057,249.890000000,250.680000000,50,100,1,1,249.800000000,250.760000000,199,50,1,1,249.770000000,252.100000000,50,1000,1,1,249.600000000,253.650000000,1000,400,1,1,249.500000000,260.000000000,1000,48,1,1,249.400000000,264.940000000,1000,7,1,1,247.700000000,265.000000000,1000,1,1,1,247.150000000,267.800000000,400,30,1,1,245.000000000,270.000000000,55,3,2,1,243.200000000,273.000000000,15,1,1,1,TSLA
2024-11-01T08:00:07.120093736Z,2024-11-01T08:00:07.119927482Z,10,2,16244,C,A,0,250.680000000,100,130,166254,301103,249.890000000,250.760000000,50,50,1,1,249.800000000,252.100000000,199,1000,1,1,249.770000000,253.650000000,50,400,1,1,249.600000000,260.000000000,1000,48,1,1,249.500000000,264.940000000,1000,7,1,1,249.400000000,265.000000000,1000,1,1,1,247.700000000,267.800000000,1000,30,1,1,247.150000000,270.000000000,400,3,1,1,245.000000000,273.000000000,55,1,2,1,243.200000000,274.000000000,15,86,1,1,TSLA
2024-11-01T08:00:07.120106510Z,2024-11-01T08:00:07.119940373Z,10,2,16244,A,A,0,250.700000000,100,130,166137,301104,249.890000000,250.700000000,50,100,1,1,249.800000000,250.760000000,199,50,1,1,249.770000000,252.100000000,50,1000,1,1,249.600000000,253.650000000,1000,400,1,1,249.500000000,260.000000000,1000,48,1,1,249.400000000,264.940000000,1000,7,1,1,247.700000000,265.000000000,1000,1,1,1,247.150000000,267.800000000,400,30,1,1,245.000000000,270.000000000,55,3,2,1,243.200000000,273.000000000,15,1,1,1,TSLA
2024-11-01T08:00:07.120191155Z,2024-11-01T08:00:07.120025391Z,10,2,16244,C,A,2,252.100000000,1000,130,165764,301105,249.890000000,250.700000000,50,100,1,1,249.800000000,250.760000000,199,50,1,1,249.770000000,253.650000000,50,400,1,1,249.600000000,260.000000000,1000,48,1,1,249.500000000,264.940000000,1000,7,1,1,249.400000000,265.000000000,1000,1,1,1,247.700000000,267.800000000,1000,30,1,1,247.150000000,270.000000000,400,3,1,1,245.000000000,273.000000000,55,1,2,1,243.200000000,274.000000000,15,86,1,1,TSLA
2024-11-01T08:00:07.120386110Z,2024-11-01T08:00:07.120220561Z,10,2,16244,C,A,0,250.700000000,100,130,165549,301108,249.890000000,250.760000000,50,50,1,1,249.800000000,253.650000000,199,400,1,1,249.770000000,260.000000000,50,48,1,1,249.600000000,264.940000000,1000,7,1,1,249.500000000,265.000000000,1000,1,1,1,249.400000000,267.800000000,1000,30,1,1,247.700000000,270.000000000,1000,3,1,1,247.150000000,273.000000000,400,1,1,1,245.000000000,274.000000000,55,86,2,1,243.200000000,275.000000000,15,16,1,2,TSLA
2024-11-01T08:00:07.120398047Z,2024-11-01T08:00:07.120232340Z,10,2,16244,A,A,0,250.720000000,100,130,165707,301109,249.890000000,250.720000000,50,100,1,1,249.800000000,250.760000000,199,50,1,1,249.770000000,253.650000000,50,400,1,1,249.600000000,260.000000000,1000,48,1,1,249.500000000,264.940000000,1000,7,1,1,249.400000000,265.000000000,1000,1,1,1,247.700000000,267.800000000,1000,30,1,1,247.150000000,270.000000000,400,3,1,1,245.000000000,273.000000000,55,1,2,1,243.200000000,274.000000000,15,86,1,1,TSLA
2024-11-01T08:00:07.132106037Z,2024-11-01T08:00:07.131939916Z,10,2,16244,A,A,2,252.400000000,1000,130,166121,301116,249.890000000,250.720000000,50,100,1,1,249.800000000,250.760000000,199,50,1,1,249.770000000,252.400000000,50,1000,1,1,249.600000000,253.650000000,1000,400,1,1,249.500000000,260.000000000,1000,48,1,1,249.400000000,264.940000000,1000,7,1,1,247.700000000,265.000000000,1000,1,1,1,247.150000000,267.800000000,400,30,1,1,245.000000000,270.000000000,55,3,2,1,243.200000000,273.000000000,15,1,1,1,TSLA
2024-11-01T08:00:07.151742419Z,2024-11-01T08:00:07.151575801Z,10,2,16244,A,B,0,249.890000000,50,130,166618,301134,249.890000000,250.720000000,100,100,2,1,249.800000000,250.760000000,199,50,1,1,249.770000000,252.400000000,50,1000,1,1,249.600000000,253.650000000,1000,400,1,1,249.500000000,260.000000000,1000,48,1,1,249.400000000,264.940000000,1000,7,1,1,247.700000000,265.000000000,1000,1,1,1,247.150000000,267.800000000,400,30,1,1,245.000000000,270.000000000,55,3,2,1,243.200000000,273.000000000,15,1,1,1,TSLA
2024-11-01T08:00:07.160619721Z,2024-11-01T08:00:07.160453770Z,10,2,10888,A,A,3,445.680000000,3,130,165951,301146,410.000000000,415.070000000,1,246,1,1,408.960000000,420.000000000,5,3,1,1,407.600000000,445.000000000,16,25,1,1,406.350000000,445.680000000,2,3,1,1,406.000000000,448.000000000,7,15,1,2,405.000000000,450.000000000,10,10,1,1,404.410000000,468.000000000,246,65,1,1,400.000000000,,10,0,1,0,398.900000000,,3,0,1,0,398.000000000,,5,0,1,0,MSFT
2024-11-01T08:00:07.161215134Z,2024-11-01T08:00:07.161049386Z,10,2,16244,C,B,0,249.890000000,50,130,165748,301158,249.890000000,250.720000000,50,100,1,1,249.800000000,250.760000000,199,50,1,1,249.770000000,252.400000000,50,1000,1,1,249.600000000,253.650000000,1000,400,1,1,249.500000000,260.000000000,1000,48,1,1,249.400000000,264.940000000,1000,7,1,1,247.700000000,265.000000000,1000,1,1,1,247.150000000,267.800000000,400,30,1,1,245.000000000,270.000000000,55,3,2,1,243.200000000,273.000000000,15,1,1,1,TSLA
2024-11-01T08:00:07.161233935Z,2024-11-01T08:00:07.161067733Z,10,2,16244,A,B,0,249.900000000,100,130,166202,301159,249.900000000,250.720000000,100,100,1,1,249.800000000,250.760000000,199,50,1,1,249.770000000,252.400000000,50,1000,1,1,249.600000000,253.650000000,1000,400,1,1,249.500000000,260.000000000,1000,48,1,1,249.400000000,264.940000000,1000,7,1,1,247.700000000,265.000000000,1000,1,1,1,247.150000000,267.800000000,400,30,1,1,245.000000000,270.000000000,55,3,2,1,243.200000000,273.000000000,15,1,1,1,TSLA
2024-11-01T08:00:07.217938771Z,2024-11-01T08:00:07.217772345Z,10,2,16244,A,B,0,249.910000000,100,130,166426,301395,249.910000000,250.720000000,100,100,1,1,249.800000000,250.760000000,199,50,1,1,249.770000000,252.400000000,50,1000,1,1,249.600000000,253.650000000,1000,400,1,1,249.500000000,260.000000000,1000,48,1,1,249.400000000,264.940000000,1000,7,1,1,247.700000000,265.000000000,1000,1,1,1,247.150000000,267.800000000,400,30,1,1,245.000000000,270.000000000,55,3,2,1,243.200000000,273.000000000,15,1,1,1,TSLA
2024-11-01T08:00:07.236243107Z,2024-11-01T08:00:07.236076869Z,10,2,16244,A,B,0,250.050000000,50,130,166238,301456,250.050000000,250.720000000,50,100,1,1,249.800000000,250.760000000,199,50,1,1,249.770000000,252.400000000,50,1000,1,1,249.600000000,253.650000000,1000,400,1,1,249.500000000,260.000000000,1000,48,1,1,249.400000000,264.940000000,1000,7,1,1,247.700000000,265.000000000,1000,1,1,1,247.150000000,267.800000000,400,30,1,1,245.000000000,270.000000000,55,3,2,1,243.200000000,273.000000000,15,1,1,1,TSLA
2024-11-01T08:00:07.287823356Z,2024-11-01T08:00:07.287657137Z,10,2,10888,A,B,5,405.000000000,5,130,166219,301556,410.000000000,415.070000000,1,246,1,1,408.960000000,420.000000000,5,3,1,1,407.600000000,445.000000000,16,25,1,1,406.350000000,445.680000000,2,3,1,1,406.000000000,448.000000000,7,15,1,2,405.000000000,450.000000000,15,10,2,1,404.410000000,468.000000000,246,65,1,1,400.000000000,,10,0,1,0,398.900000000,,3,0,1,0,398.000000000,,5,0,1,0,MSFT
2024-11-01T08:00:07.297644692Z,2024-11-01T08:00:07.297478143Z,10,2,10888,A,B,3,407.000000000,2,130,166549,301584,410.000000000,415.070000000,1,246,1,1,408.960000000,420.000000000,5,3,1,1,407.600000000,445.000000000,16,25,1,1,407.000000000,445.680000000,2,3,1,1,406.350000000,448.000000000,2,15,1,2,406.000000000,450.000000000,7,10,1,1,405.000000000,468.000000000,15,65,2,1,404.410000000,,246,0,1,0,400.000000000,,10,0,1,0,398.900000000,,3,0,1,0,MSFT
2024-11-01T08:00:07.459226879Z,2024-11-01T08:00:07.459060636Z,10,2,38,A,A,3,240.000000000,9,130,166243,302266,221.300000000,224.600000000,1000,1000,1,1,220.000000000,225.490000000,2,442,1,1,219.690000000,234.000000000,442,20,1,1,217.000000000,240.000000000,1525,159,1,2,190.000000000,370.000000000,1,100,1,1,180.000000000,,1,0,1,0,100.000000000,,1,0,1,0,,,0,0,0,0,,,0,0,0,0,,,0,0,0,0,AAPL
2024-11-01T08:00:07.488541467Z,2024-11-01T08:00:07.488374646Z,10,2,10888,A,B,8,404.000000000,4,130,166821,302286,410.000000000,415.070000000,1,246,1,1,408.960000000,420.000000000,5,3,1,1,407.600000000,445.000000000,16,25,1,1,407.000000000,445.680000000,2,3,1,1,406.350000000,448.000000000,2,15,1,2,406.000000000,450.000000000,7,10,1,1,405.000000000,468.000000000,15,65,2,1,404.410000000,,246,0,1,0,404.000000000,,4,0,1,0,400.000000000,,10,0,1,0,MSFT
2024-11-01T08:00:07.508666093Z,2024-11-01T08:00:07.508499615Z,10,2,10888,A,B,9,400.000000000,30,130,166478,302298,410.000000000,415.070000000,1,246,1,1,408.960000000,420.000000000,5,3,1,1,407.600000000,445.000000000,16,25,1,1,407.000000000,445.680000000,2,3,1,1,406.350000000,448.000000000,2,15,1,2,406.000000000,450.000000000,7,10,1,1,405.000000000,468.000000000,15,65,2,1,404.410000000,,246,0,1,0,404.000000000,,4,0,1,0,400.000000000,,40,0,2,0,MSFT
2024-11-01T08:00:07.724724125Z,2024-11-01T08:00:07.724557979Z,10,2,38,A,A,2,233.670000000,5,130,166146,303010,221.300000000,224.600000000,1000,1000,1,1,220.000000000,225.490000000,2,442,1,1,219.690000000,233.670000000,442,5,1,1,217.000000000,234.000000000,1525,20,1,1,190.000000000,240.000000000,1,159,1,2,180.000000000,370.000000000,1,100,1,1,100.000000000,,1,0,1,0,,,0,0,0,0,,,0,0,0,0,,,0,0,0,0,AAPL
2024-11-01T08:00:07.784791813Z,2024-11-01T08:00:07.784625704Z,10,2,10888,A,B,3,407.000000000,2,130,166109,303443,410.000000000,415.070000000,1,246,1,1,408.960000000,420.000000000,5,3,1,1,407.600000000,445.000000000,16,25,1,1,407.000000000,445.680000000,4,3,2,1,406.350000000,448.000000000,2,15,1,2,406.000000000,450.000000000,7,10,1,1,405.000000000,468.000000000,15,65,2,1,404.410000000,,246,0,1,0,404.000000000,,4,0,1,0,400.000000000,,40,0,2,0,MSFT
2024-11-01T08:00:07.786660615Z,2024-11-01T08:00:07.786494249Z,10,2,10888,A,B,9,400.000000000,10,130,166366,303445,410.000000000,415.070000000,1,246,1,1,408.960000000,420.000000000,5,3,1,1,407.600000000,445.000000000,16,25,1,1,407.000000000,445.680000000,4,3,2,1,406.350000000,448.000000000,2,15,1,2,406.000000000,450.000000000,7,10,1,1,405.000000000,468.000000000,15,65,2,1,404.410000000,,246,0,1,0,404.000000000,,4,0,1,0,400.000000000,,50,0,3,0,MSFT
2024-11-01T08:00:07.864801835Z,2024-11-01T08:00:07.864635851Z,10,2,38,A,B,4,200.000000000,30,130,165984,303617,221.300000000,224.600000000,1000,1000,1,1,220.000000000,225.490000000,2,442,1,1,219.690000000,233.670000000,442,5,1,1,217.000000000,234.000000000,1525,20,1,1,200.000000000,240.000000000,30,159,1,2,190.000000000,370.000000000,1,100,1,1,180.000000000,,1,0,1,0,100.000000000,,1,0,1,0,,,0,0,0,0,,,0,0,0,0,AAPL
2024-11-01T08:00:07.902744913Z,2024-11-01T08:00:07.902579178Z,10,2,17709,C,B,1,115.320000000,100,130,165735,303753,116.000000000,118.320000000,100,856,1,1,115.280000000,118.600000000,856,100,1,1,,125.000000000,0,30,0,1,,,0,0,0,0,,,0,0,0,0,,,0,0,0,0,,,0,0,0,0,,,0,0,0,0,,,0,0,0,0,,,0,0,0,0,XOM
2024-11-01T08:00:07.902758379Z,2024-11-01T08:00:07.902592403Z,10,2,17709,A,B,1,115.290000000,100,130,165976,303754,116.000000000,118.320000000,100,856,1,1,115.290000000,118.600000000,100,100,1,1,115.280000000,125.000000000,856,30,1,1,,,0,0,0,0,,,0,0,0,0,,,0,0,0,0,,,0,0,0,0,,,0,0,0,0,,,0,0,0,0,,,0,0,0,0,XOM
2024-11-01T08:00:07.918045505Z,2024-11-01T08:00:07.917879682Z,10,2,38,C,A,0,224.600000000,1000,130,165823,303841,221.300000000,225.490000000,1000,442,1,1,220.000000000,233.670000000,2,5,1,1,219.690000000,234.000000000,442,20,1,1,217.000000000,240.000000000,1525,159,1,2,200.000000000,370.000000000,30,100,1,1,190.000000000,,1,0,1,0,180.000000000,,1,0,1,0,100.000000000,,1,0,1,0,,,0,0,0,0,,,0,0,0,0,AAPL
2024-11-01T08:00:07.923433115Z,2024-11-01T08:00:07.923266918Z,10,2,11667,A,A,1,135.000000000,20,130,166197,303861,134.500000000,134.920000000,500,1,1,1,134.440000000,135.000000000,100,38,1,3,134.410000000,135.230000000,61,360,2,1,134.210000000,135.300000000,20,1000,1,1,134.200000000,135.420000000,3,1,1,1,133.160000000,135.820000000,1,1,1,1,132.660000000,136.100000000,1,1000,1,1,132.160000000,136.220000000,1,1,1,1,132.000000000,136.620000000,72,1,3,1,131.660000000,137.060000000,1,1,1,1,NVDA
2024-11-01T08:00:07.953906001Z,2024-11-01T08:00:07.953739713Z,10,2,38,A,A,0,224.500000000,1000,130,166288,304054,221.300000000,224.500000000,1000,1000,1,1,220.000000000,225.490000000,2,442,1,1,219.690000000,233.670000000,442,5,1,1,217.000000000,234.000000000,1525,20,1,1,200.000000000,240.000000000,30,159,1,2,190.000000000,370.000000000,1,100,1,1,180.000000000,,1,0,1,0,100.000000000,,1,0,1,0,,,0,0,0,0,,,0,0,0,0,AAPL
2024-11-01T08:00:07.954482341Z,2024-11-01T08:00:07.954316501Z,10,2,38,C,B,0,221.300000000,1000,130,165840,304055,220.000000000,224.500000000,2,1000,1,1,219.690000000,225.490000000,442,442,1,1,217.000000000,233.670000000,1525,5,1,1,200.000000000,234.000000000,30,20,1,1,190.000000000,240.000000000,1,159,1,2,180.000000000,370.000000000,1,100,1,1,100.000000000,,1,0,1,0,,,0,0,0,0,,,0,0,0,0,,,0,0,0,0,AAPL
2024-11-01T08:00:07.965087783Z,2024-11-01T08:00:07.964921701Z,10,2,38,A,B,0,221.100000000,1000,130,166082,304077,221.100000000,224.500000000,1000,1000,1,1,220.000000000,225.490000000,2,442,1,1,219.690000000,233.670000000,442,5,1,1,217.000000000,234.000000000,1525,20,1,1,200.000000000,240.000000000,30,159,1,2,190.000000000,370.000000000,1,100,1,1,180.000000000,,1,0,1,0,100.000000000,,1,0,1,0,,,0,0,0,0,,,0,0,0,0,AAPL
2024-11-01T08:00:07.990508533Z,2024-11-01T08:00:07.990342243Z,10,2,10888,A,B,1,408.970000000,12,130,166290,304095,410.000000000,415.070000000,1,246,1,1,408.970000000,420.000000000,12,3,1,1,408.960000000,445.000000000,5,25,1,1,407.600000000,445.680000000,16,3,1,1,407.000000000,448.000000000,4,15,2,2,406.350000000,450.000000000,2,10,1,1,406.000000000,468.000000000,7,65,1,1,405.000000000,,15,0,2,0,404.410000000,,246,0,1,0,404.000000000,,4,0,1,0,MSFT
2024-11-01T08:00:08.030593607Z,2024-11-01T08:00:08.030427054Z,10,2,11667,A,A,9,136.800000000,100,130,166553,304161,134.500000000,134.920000000,500,1,1,1,134.440000000,135.000000000,100,38,1,3,134.410000000,135.230000000,61,360,2,1,134.210000000,135.300000000,20,1000,1,1,134.200000000,135.420000000,3,1,1,1,133.160000000,135.820000000,1,1,1,1,132.660000000,136.100000000,1,1000,1,1,132.160000000,136.220000000,1,1,1,1,132.000000000,136.620000000,72,1,3,1,131.660000000,136.800000000,1,100,1,1,NVDA
2024-11-01T08:00:08.066264961Z,2024-11-01T08:00:08.066098641Z,10,2,16244,C,B,0,250.050000000,50,130,166320,304212,249.800000000,250.720000000,199,100,1,1,249.770000000,250.760000000,50,50,1,1,249.600000000,252.400000000,1000,1000,1,1,249.500000000,253.650000000,1000,400,1,1,249.400000000,260.000000000,1000,48,1,1,247.700000000,264.940000000,1000,7,1,1,247.150000000,265.000000000,400,1,1,1,245.000000000,267.800000000,55,30,2,1,243.200000000,270.000000000,15,3,1,1,235.000000000,273.000000000,130,1,2,1,TSLA
2024-11-01T08:00:08.066277251Z,2024-11-01T08:00:08.066111120Z,10,2,16244,A,B,0,250.030000000,50,130,166131,304213,250.030000000,250.720000000,50,100,1,1,249.800000000,250.760000000,199,50,1,1,249.770000000,252.400000000,50,1000,1,1,249.600000000,253.650000000,1000,400,1,1,249.500000000,260.000000000,1000,48,1,1,249.400000000,264.940000000,1000,7,1,1,247.700000000,265.000000000,1000,1,1,1,247.150000000,267.800000000,400,30,1,1,245.000000000,270.000000000,55,3,2,1,243.200000000,273.000000000,15,1,1,1,TSLA
2024-11-01T08:00:08.088377795Z,2024-11-01T08:00:08.088211541Z,10,2,38,A,A,0,224.400000000,1000,130,166254,304242,221.100000000,224.400000000,1000,1000,1,1,220.000000000,224.500000000,2,1000,1,1,219.690000000,225.490000000,442,442,1,1,217.000000000,233.670000000,1525,5,1,1,200.000000000,234.000000000,30,20,1,1,190.000000000,240.000000000,1,159,1,2,180.000000000,370.000000000,1,100,1,1,100.000000000,,1,0,1,0,,,0,0,0,0,,,0,0,0,0,AAPL
2024-11-01T08:00:08.088836919Z,2024-11-01T08:00:08.088671394Z,10,2,38,C,A,1,224.500000000,1000,130,165525,304245,221.100000000,224.400000000,1000,1000,1,1,220.000000000,225.490000000,2,442,1,1,219.690000000,233.670000000,442,5,1,1,217.000000000,234.000000000,1525,20,1,1,200.000000000,240.000000000,30,159,1,2,190.000000000,370.000000000,1,100,1,1,180.000000000,,1,0,1,0,100.000000000,,1,0,1,0,,,0,0,0,0,,,0,0,0,0,AAPL
2024-11-01T08:00:08.233380835Z,2024-11-01T08:00:08.233214727Z,10,2,10888,A,B,1,409.080000000,2,130,166108,304632,410.000000000,415.070000000,1,246,1,1,409.080000000,420.000000000,2,3,1,1,408.970000000,445.000000000,12,25,1,1,408.960000000,445.680000000,5,3,1,1,407.600000000,448.000000000,16,15,1,2,407.000000000,450.000000000,4,10,2,1,406.350000000,468.000000000,2,65,1,1,406.000000000,,7,0,1,0,405.000000000,,15,0,2,0,404.410000000,,246,0,1,0,MSFT
2024-11-01T08:00:08.251224635Z,2024-11-01T08:00:08.251057874Z,10,2,38,A,A,4,238.760000000,150,128,166761,304717,221.100000000,224.400000000,1000,1000,1,1,220.000000000,225.490000000,2,442,1,1,219.690000000,233.670000000,442,5,1,1,217.000000000,234.000000000,1525,20,1,1,200.000000000,238.760000000,30,150,1,1,190.000000000,240.000000000,1,159,1,2,180.000000000,370.000000000,1,100,1,1,100.000000000,,1,0,1,0,,,0,0,0,0,,,0,0,0,0,AAPL
2024-11-01T08:00:08.257587355Z,2024-11-01T08:00:08.257420922Z,10,2,16244,A,A,4,255.000000000,10,130,166433,304768,250.030000000,250.720000000,50,100,1,1,249.800000000,250.760000000,199,50,1,1,249.770000000,252.400000000,50,1000,1,1,249.600000000,253.650000000,1000,400,1,1,249.500000000,255.000000000,1000,10,1,1,249.400000000,260.000000000,1000,48,1,1,247.700000000,264.940000000,1000,7,1,1,247.150000000,265.000000000,400,1,1,1,245.000000000,267.800000000,55,30,2,1,243.200000000,270.000000000,15,3,1,1,TSLA
2024-11-01T08:00:08.320809942Z,2024-11-01T08:00:08.320643637Z,10,2,16244,A,A,9,269.580000000,100,130,166305,305132,250.030000000,250.720000000,50,100,1,1,249.800000000,250.760000000,199,50,1,1,249.770000000,252.400000000,50,1000,1,1,249.600000000,253.650000000,1000,400,1,1,249.500000000,255.000000000,1000,10,1,1,249.400000000,260.000000000,1000,48,1,1,247.700000000,264.940000000,1000,7,1,1,247.150000000,265.000000000,400,1,1,1,245.000000000,267.800000000,55,30,2,1,243.200000000,269.580000000,15,100,1,1,TSLA
2024-11-01T08:00:08.358327478Z,2024-11-01T08:00:08.358161215Z,10,2,38,A,A,4,235.000000000,2,130,166263,305273,221.100000000,224.400000000,1000,1000,1,1,220.000000000,225.490000000,2,442,1,1,219.690000000,233.670000000,442,5,1,1,217.000000000,234.000000000,1525,20,1,1,200.000000000,235.000000000,30,2,1,1,190.000000000,238.760000000,1,150,1,1,180.000000000,240.000000000,1,159,1,2,100.000000000,370.000000000,1,100,1,1,,,0,0,0,0,,,0,0,0,0,AAPL
2024-11-01T08:00:08.391961765Z,2024-11-01T08:00:08.391794566Z,10,2,11667,T,N,0,134.880000000,10,130,167199,305653,134.500000000,134.920000000,500,1,1,1,134.440000000,135.000000000,100,38,1,3,134.410000000,135.230000000,61,360,2,1,134.210000000,135.300000000,20,1000,1,1,134.200000000,135.420000000,3,1,1,1,133.160000000,135.820000000,1,1,1,1,132.660000000,136.100000000,1,1000,1,1,132.160000000,136.220000000,1,1,1,1,132.000000000,136.620000000,72,1,3,1,131.660000000,136.800000000,1,100,1,1,NVDA
2024-11-01T08:00:08.392059432Z,2024-11-01T08:00:08.391893222Z,10,2,11667,A,B,0,134.690000000,1,130,166210,305656,134.690000000,134.920000000,1,1,1,1,134.500000000,135.000000000,500,38,1,3,134.440000000,135.230000000,100,360,1,1,134.410000000,135.300000000,61,1000,2,1,134.210000000,135.420000000,20,1,1,1,134.200000000,135.820000000,3,1,1,1,133.160000000,136.100000000,1,1000,1,1,132.660000000,136.220000000,1,1,1,1,132.160000000,136.620000000,1,1,1,1,132.000000000,136.800000000,72,100,3,1,NVDA
2024-11-01T08:00:08.392094517Z,2024-11-01T08:00:08.391927988Z,10,2,11667,A,B,1,134.570000000,1,130,166529,305659,134.690000000,134.920000000,1,1,1,1,134.570000000,135.000000000,1,38,1,3,134.500000000,135.230000000,500,360,1,1,134.440000000,135.300000000,100,1000,1,1,134.410000000,135.420000000,61,1,2,1,134.210000000,135.820000000,20,1,1,1,134.200000000,136.100000000,3,1000,1,1,133.160000000,136.220000000,1,1,1,1,132.660000000,136.620000000,1,1,1,1,132.160000000,136.800000000,1,100,1,1,NVDA
2024-11-01T08:00:08.394082611Z,2024-11-01T08:00:08.393916892Z,10,2,11667,C,B,0,134.690000000,1,130,165719,305671,134.570000000,134.920000000,1,1,1,1,134.500000000,135.000000000,500,38,1,3,134.440000000,135.230000000,100,360,1,1,134.410000000,135.300000000,61,1000,2,1,134.210000000,135.420000000,20,1,1,1,134.200000000,135.820000000,3,1,1,1,133.160000000,136.100000000,1,1000,1,1,132.660000000,136.220000000,1,1,1,1,132.160000000,136.620000000,1,1,1,1,132.000000000,136.800000000,72,100,3,1,NVDA
2024-11-01T08:00:08.398037236Z,2024-11-01T08:00:08.397871271Z,10,2,16244,A,B,1,249.930000000,10,130,165965,305707,250.030000000,250.720000000,50,100,1,1,249.930000000,250.760000000,10,50,1,1,249.800000000,252.400000000,199,1000,1,1,249.770000000,253.650000000,50,400,1,1,249.600000000,255.000000000,1000,10,1,1,249.500000000,260.000000000,1000,48,1,1,249.400000000,264.940000000,1000,7,1,1,247.700000000,265.000000000,1000,1,1,1,247.150000000,267.800000000,400,30,1,1,245.000000000,269.580000000,55,100,2,1,TSLA
2024-11-01T08:00:08.432061683Z,2024-11-01T08:00:08.431895654Z,10,2,11667,A,B,4,134.380000000,18,130,166029,305898,134.570000000,134.920000000,1,1,1,1,134.500000000,135.000000000,500,38,1,3,134.440000000,135.230000000,100,360,1,1,134.410000000,135.300000000,61,1000,2,1,134.380000000,135.420000000,18,1,1,1,134.210000000,135.820000000,20,1,1,1,134.200000000,136.100000000,3,1000,1,1,133.160000000,136.220000000,1,1,1,1,132.660000000,136.620000000,1,1,1,1,132.160000000,136.800000000,1,100,1,1,NVDA
2024-11-01T08:00:08.471253747Z,2024-11-01T08:00:08.471087500Z,10,2,38,A,A,2,225.900000000,12,130,166247,306049,221.100000000,224.400000000,1000,1000,1,1,220.000000000,225.490000000,2,442,1,1,219.690000000,225.900000000,442,12,1,1,217.000000000,233.670000000,1525,5,1,1,200.000000000,234.000000000,30,20,1,1,190.000000000,235.000000000,1,2,1,1,180.000000000,238.760000000,1,150,1,1,100.000000000,240.000000000,1,159,1,2,,370.000000000,0,100,0,1,,,0,0,0,0,AAPL
2024-11-01T08:00:08.471369827Z,2024-11-01T08:00:08.471203551Z,10,2,38,A,A,3,229.330000000,3,130,166276,306050,221.100000000,224.400000000,1000,1000,1,1,220.000000000,225.490000000,2,442,1,1,219.690000000,225.900000000,442,12,1,1,217.000000000,229.330000000,1525,3,1,1,200.000000000,233.670000000,30,5,1,1,190.000000000,234.000000000,1,20,1,1,180.000000000,235.000000000,1,2,1,1,100.000000000,238.760000000,1,150,1,1,,240.000000000,0,159,0,2,,370.000000000,0,100,0,1,AAPL
2024-11-01T08:00:08.471449596Z,2024-11-01T08:00:08.471283178Z,10,2,38,A,A,2,225.900000000,20,130,166418,306051,221.100000000,224.400000000,1000,1000,1,1,220.000000000,225.490000000,2,442,1,1,219.690000000,225.900000000,442,32,1,2,217.000000000,229.330000000,1525,3,1,1,200.000000000,233.670000000,30,5,1,1,190.000000000,234.000000000,1,20,1,1,180.000000000,235.000000000,1,2,1,1,100.000000000,238.760000000,1,150,1,1,,240.000000000,0,159,0,2,,370.000000000,0,100,0,1,AAPL
2024-11-01T08:00:08.471569837Z,2024-11-01T08:00:08.471403539Z,10,2,38,A,A,3,229.330000000,6,130,166298,306052,221.100000000,224.400000000,1000,1000,1,1,220.000000000,225.490000000,2,442,1,1,219.690000000,225.900000000,442,32,1,2,217.000000000,229.330000000,1525,9,1,2,200.000000000,233.670000000,30,5,1,1,190.000000000,234.000000000,1,20,1,1,180.000000000,235.000000000,1,2,1,1,100.000000000,238.760000000,1,150,1,1,,240.000000000,0,159,0,2,,370.000000000,0,100,0,1,AAPL
2024-11-01T08:00:08.496635521Z,2024-11-01T08:00:08.496469300Z,10,2,16244,A,A,9,268.670000000,100,130,166221,306180,250.030000000,250.720000000,50,100,1,1,249.930000000,250.760000000,10,50,1,1,249.800000000,252.400000000,199,1000,1,1,249.770000000,253.650000000,50,400,1,1,249.600000000,255.000000000,1000,10,1,1,249.500000000,260.000000000,1000,48,1,1,249.400000000,264.940000000,1000,7,1,1,247.700000000,265.000000000,1000,1,1,1,247.150000000,267.800000000,400,30,1,1,245.000000000,268.670000000,55,100,2,1,TSLA
2024-11-01T08:00:08.501836590Z,2024-11-01T08:00:08.501670252Z,10,2,38,A,A,1,225.360000000,1,130,166338,306206,221.100000000,224.400000000,1000,1000,1,1,220.000000000,225.360000000,2,1,1,1,219.690000000,225.490000000,442,442,1,1,217.000000000,225.900000000,1525,32,1,2,200.000000000,229.330000000,30,9,1,2,190.000000000,233.670000000,1,5,1,1,180.000000000,234.000000000,1,20,1,1,100.000000000,235.000000000,1,2,1,1,,238.760000000,0,150,0,1,,240.000000000,0,159,0,2,AAPL
2024-11-01T08:00:08.645628209Z,2024-11-01T08:00:08.645460736Z,10,2,11667,T,B,0,134.920000000,1,130,167473,307120,134.570000000,134.920000000,1,1,1,1,134.500000000,135.000000000,500,38,1,3,134.440000000,135.230000000,100,360,1,1,134.410000000,135.300000000,61,1000,2,1,134.380000000,135.420000000,18,1,1,1,134.210000000,135.820000000,20,1,1,1,134.200000000,136.100000000,3,1000,1,1,133.160000000,136.220000000,1,1,1,1,132.660000000,136.620000000,1,1,1,1,132.160000000,136.800000000,1,100,1,1,NVDA
2024-11-01T08:00:08.645628209Z,2024-11-01T08:00:08.645460736Z,10,2,11667,C,A,0,134.920000000,1,130,167473,307120,134.570000000,135.000000000,1,38,1,3,134.500000000,135.230000000,500,360,1,1,134.440000000,135.300000000,100,1000,1,1,134.410000000,135.420000000,61,1,2,1,134.380000000,135.820000000,18,1,1,1,134.210000000,136.100000000,20,1000,1,1,134.200000000,136.220000000,3,1,1,1,133.160000000,136.620000000,1,1,1,1,132.660000000,136.800000000,1,100,1,1,132.160000000,137.060000000,1,1,1,1,NVDA
2024-11-01T08:00:08.645674070Z,2024-11-01T08:00:08.645507963Z,10,2,11667,A,B,0,134.740000000,100,130,166107,307121,134.740000000,135.000000000,100,38,1,3,134.570000000,135.230000000,1,360,1,1,134.500000000,135.300000000,500,1000,1,1,134.440000000,135.420000000,100,1,1,1,134.410000000,135.820000000,61,1,2,1,134.380000000,136.100000000,18,1000,1,1,134.210000000,136.220000000,20,1,1,1,134.200000000,136.620000000,3,1,1,1,133.160000000,136.800000000,1,100,1,1,132.660000000,137.060000000,1,1,1,1,NVDA
2024-11-01T08:00:08.645698573Z,2024-11-01T08:00:08.645532373Z,10,2,11667,A,B,1,134.640000000,100,130,166200,307122,134.740000000,135.000000000,100,38,1,3,134.640000000,135.230000000,100,360,1,1,134.570000000,135.300000000,1,1000,1,1,134.500000000,135.420000000,500,1,1,1,134.440000000,135.820000000,100,1,1,1,134.410000000,136.100000000,61,1000,2,1,134.380000000,136.220000000,18,1,1,1,134.210000000,136.620000000,20,1,1,1,134.200000000,136.800000000,3,100,1,1,133.160000000,137.060000000,1,1,1,1,NVDA
2024-11-01T08:00:08.645724092Z,2024-11-01T08:00:08.645557965Z,10,2,11667,A,B,1,134.640000000,100,130,166127,307123,134.740000000,135.000000000,100,38,1,3,134.640000000,135.230000000,200,360,2,1,134.570000000,135.300000000,1,1000,1,1,134.500000000,135.420000000,500,1,1,1,134.440000000,135.820000000,100,1,1,1,134.410000000,136.100000000,61,1000,2,1,134.380000000,136.220000000,18,1,1,1,134.210000000,136.620000000,20,1,1,1,134.200000000,136.800000000,3,100,1,1,133.160000000,137.060000000,1,1,1,1,NVDA
2024-11-01T08:00:08.645736165Z,2024-11-01T08:00:08.645570332Z,10,2,11667,C,B,0,134.740000000,100,130,165833,307124,134.640000000,135.000000000,200,38,2,3,134.570000000,135.230000000,1,360,1,1,134.500000000,135.300000000,500,1000,1,1,134.440000000,135.420000000,100,1,1,1,134.410000000,135.820000000,61,1,2,1,134.380000000,136.100000000,18,1000,1,1,134.210000000,136.220000000,20,1,1,1,134.200000000,136.620000000,3,1,1,1,133.160000000,136.800000000,1,100,1,1,132.660000000,137.060000000,1,1,1,1,NVDA
2024-11-01T08:00:08.645748164Z,2024-11-01T08:00:08.645582623Z,10,2,11667,C,B,0,134.640000000,100,130,165541,307125,134.640000000,135.000000000,100,38,1,3,134.570000000,135.230000000,1,360,1,1,134.500000000,135.300000000,500,1000,1,1,134.440000000,135.420000000,100,1,1,1,134.410000000,135.820000000,61,1,2,1,134.380000000,136.100000000,18,1000,1,1,134.210000000,136.220000000,20,1,1,1,134.200000000,136.620000000,3,1,1,1,133.160000000,136.800000000,1,100,1,1,132.660000000,137.060000000,1,1,1,1,NVDA
2024-11-01T08:00:08.645758283Z,2024-11-01T08:00:08.645592746Z,10,2,11667,C,B,0,134.640000000,100,130,165537,307126,134.570000000,135.000000000,1,38,1,3,134.500000000,135.230000000,500,360,1,1,134.440000000,135.300000000,100,1000,1,1,134.410000000,135.420000000,61,1,2,1,134.380000000,135.820000000,18,1,1,1,134.210000000,136.100000000,20,1000,1,1,134.200000000,136.220000000,3,1,1,1,133.160000000,136.620000000,1,1,1,1,132.660000000,136.800000000,1,100,1,1,132.160000000,137.060000000,1,1,1,1,NVDA
2024-11-01T08:00:08.758580117Z,2024-11-01T08:00:08.758413989Z,10,2,12463,A,A,1,180.000000000,20,130,166128,307256,,171.810000000,0,100,0,1,,180.000000000,0,20,0,1,,,0,0,0,0,,,0,0,0,0,,,0,0,0,0,,,0,0,0,0,,,0,0,0,0,,,0,0,0,0,,,0,0,0,0,,,0,0,0,0,PEP
2024-11-01T08:00:08.766975767Z,2024-11-01T08:00:08.766809735Z,10,2,10888,A,A,7,472.000000000,6,130,166032,307258,410.000000000,415.070000000,1,246,1,1,409.080000000,420.000000000,2,3,1,1,408.970000000,445.000000000,12,25,1,1,408.960000000,445.680000000,5,3,1,1,407.600000000,448.000000000,16,15,1,2,407.000000000,450.000000000,4,10,2,1,406.350000000,468.000000000,2,65,1,1,406.000000000,472.000000000,7,6,1,1,405.000000000,,15,0,2,0,404.410000000,,246,0,1,0,MSFT
2024-11-01T08:00:08.894085102Z,2024-11-01T08:00:08.893919268Z,10,2,11667,C,B,0,134.570000000,1,130,165834,307508,134.500000000,135.000000000,500,38,1,3,134.440000000,135.230000000,100,360,1,1,134.410000000,135.300000000,61,1000,2,1,134.380000000,135.420000000,18,1,1,1,134.210000000,135.820000000,20,1,1,1,134.200000000,136.100000000,3,1000,1,1,133.160000000,136.220000000,1,1,1,1,132.660000000,136.620000000,1,1,1,1,132.160000000,136.800000000,1,100,1,1,132.000000000,137.060000000,74,1,4,1,NVDA
2024-11-01T08:00:08.962661271Z,2024-11-01T08:00:08.962495026Z,10,2,16244,A,A,6,262.660000000,56,130,166245,307561,250.030000000,250.720000000,50,100,1,1,249.930000000,250.760000000,10,50,1,1,249.800000000,252.400000000,199,1000,1,1,249.770000000,253.650000000,50,400,1,1,249.600000000,255.000000000,1000,10,1,1,249.500000000,260.000000000,1000,48,1,1,249.400000000,262.660000000,1000,56,1,1,247.700000000,264.940000000,1000,7,1,1,247.150000000,265.000000000,400,1,1,1,245.000000000,267.800000000,55,30,2,1,TSLA
2024-11-01T08:00:09.003467025Z,2024-11-01T08:00:09.003300754Z,10,2,11667,A,B,7,132.700000000,4,130,166271,307677,134.500000000,135.000000000,500,38,1,3,134.440000000,135.230000000,100,360,1,1,134.410000000,135.300000000,61,1000,2,1,134.380000000,135.420000000,18,1,1,1,134.210000000,135.820000000,20,1,1,1,134.200000000,136.100000000,3,1000,1,1,133.160000000,136.220000000,1,1,1,1,132.700000000,136.620000000,4,1,1,1,132.660000000,136.800000000,1,100,1,1,132.160000000,137.060000000,1,1,1,1,NVDA
2024-11-01T08:00:09.024031465Z,2024-11-01T08:00:09.023865393Z,10,2,11667,A,A,7,136.400000000,11,130,166072,307719,134.500000000,135.000000000,500,38,1,3,134.440000000,135.230000000,100,360,1,1,134.410000000,135.300000000,61,1000,2,1,134.380000000,135.420000000,18,1,1,1,134.210000000,135.820000000,20,1,1,1,134.200000000,136.100000000,3,1000,1,1,133.160000000,136.220000000,1,1,1,1,132.700000000,136.400000000,4,11,1,1,132.660000000,136.620000000,1,1,1,1,132.160000000,136.800000000,1,100,1,1,NVDA
2024-11-01T08:00:09.024229880Z,2024-11-01T08:00:09.024063811Z,10,2,11667,A,A,5,135.990000000,20,130,166069,307721,134.500000000,135.000000000,500,38,1,3,134.440000000,135.230000000,100,360,1,1,134.410000000,135.300000000,61,1000,2,1,134.380000000,135.420000000,18,1,1,1,134.210000000,135.820000000,20,1,1,1,134.200000000,135.990000000,3,20,1,1,133.160000000,136.100000000,1,1000,1,1,132.700000000,136.220000000,4,1,1,1,132.660000000,136.400000000,1,11,1,1,132.160000000,136.620000000,1,1,1,1,NVDA
2024-11-01T08:00:09.024470734Z,2024-11-01T08:00:09.024304348Z,10,2,11667,A,A,3,135.400000000,10,130,166386,307725,134.500000000,135.000000000,500,38,1,3,134.440000000,135.230000000,100,360,1,1,134.410000000,135.300000000,61,1000,2,1,134.380000000,135.400000000,18,10,1,1,134.210000000,135.420000000,20,1,1,1,134.200000000,135.820000000,3,1,1,1,133.160000000,135.990000000,1,20,1,1,132.700000000,136.100000000,4,1000,1,1,132.660000000,136.220000000,1,1,1,1,132.160000000,136.400000000,1,11,1,1,NVDA
2024-11-01T08:00:09.024590866Z,2024-11-01T08:00:09.024424307Z,10,2,11667,A,A,0,134.990000000,10,130,166559,307726,134.500000000,134.990000000,500,10,1,1,134.440000000,135.000000000,100,38,1,3,134.410000000,135.230000000,61,360,2,1,134.380000000,135.300000000,18,1000,1,1,134.210000000,135.400000000,20,10,1,1,134.200000000,135.420000000,3,1,1,1,133.160000000,135.820000000,1,1,1,1,132.700000000,135.990000000,4,20,1,1,132.660000000,136.100000000,1,1000,1,1,132.160000000,136.220000000,1,1,1,1,NVDA
2024-11-01T08:00:09.024710098Z,2024-11-01T08:00:09.024543805Z,10,2,11667,A,A,2,135.100000000,10,130,166293,307727,134.500000000,134.990000000,500,10,1,1,134.440000000,135.000000000,100,38,1,3,134.410000000,135.100000000,61,10,2,1,134.380000000,135.230000000,18,360,1,1,134.210000000,135.300000000,20,1000,1,1,134.200000000,135.400000000,3,10,1,1,133.160000000,135.420000000,1,1,1,1,132.700000000,135.820000000,4,1,1,1,132.660000000,135.990000000,1,20,1,1,132.160000000,136.100000000,1,1000,1,1,NVDA
