ts_recv,ts_event,rtype,publisher_id,instrument_id,action,side,depth,price,size,flags,ts_in_delta,sequence,bid_px_00,ask_px_00,bid_sz_00,ask_sz_00,bid_ct_00,ask_ct_00,bid_px_01,ask_px_01,bid_sz_01,ask_sz_01,bid_ct_01,ask_ct_01,bid_px_02,ask_px_02,bid_sz_02,ask_sz_02,bid_ct_02,ask_ct_02,bid_px_03,ask_px_03,bid_sz_03,ask_sz_03,bid_ct_03,ask_ct_03,bid_px_04,ask_px_04,bid_sz_04,ask_sz_04,bid_ct_04,ask_ct_04,bid_px_05,ask_px_05,bid_sz_05,ask_sz_05,bid_ct_05,ask_ct_05,bid_px_06,ask_px_06,bid_sz_06,ask_sz_06,bid_ct_06,ask_ct_06,bid_px_07,ask_px_07,bid_sz_07,ask_sz_07,bid_ct_07,ask_ct_07,bid_px_08,ask_px_08,bid_sz_08,ask_sz_08,bid_ct_08,ask_ct_08,bid_px_09,ask_px_09,bid_sz_09,ask_sz_09,bid_ct_09,ask_ct_09,symbol
2024-11-01T08:00:15.620353183Z,2024-11-01T08:00:15.620187110Z,10,2,16244,C,B,0,250.150000000,50,130,166073,323788,250.000000000,250.690000000,2,26,2,1,249.930000000,250.750000000,10,26,1,1,249.880000000,250.790000000,4,200,1,1,249.850000000,250.880000000,4,14,1,1,249.800000000,250.940000000,199,100,1,1,249.770000000,251.090000000,50,100,1,1,249.500000000,251.200000000,1000,1000,1,1,249.010000000,251.450000000,3,374,1,2,249.000000000,251.500000000,100,10,1,1,248.500000000,253.350000000,111,23,3,1,TSLA
2024-11-01T08:00:15.620759338Z,2024-11-01T08:00:15.620593416Z,10,2,16244,C,B,6,249.500000000,1000,130,165922,323793,250.000000000,250.690000000,2,26,2,1,249.930000000,250.750000000,10,26,1,1,249.880000000,250.790000000,4,200,1,1,249.850000000,250.880000000,4,14,1,1,249.800000000,250.940000000,199,100,1,1,249.770000000,251.090000000,50,100,1,1,249.010000000,251.200000000,3,1000,1,1,249.000000000,251.450000000,100,374,1,2,248.500000000,251.500000000,111,10,3,1,248.010000000,253.350000000,5,23,1,1,TSLA
2024-11-01T08:00:15.631914524Z,2024-11-01T08:00:15.631748291Z,10,2,16244,A,A,6,251.100000000,1000,130,166233,323800,250.000000000,250.690000000,2,26,2,1,249.930000000,250.750000000,10,26,1,1,249.880000000,250.790000000,4,200,1,1,249.850000000,250.880000000,4,14,1,1,249.800000000,250.940000000,199,100,1,1,249.770000000,251.090000000,50,100,1,1,249.010000000,251.100000000,3,1000,1,1,249.000000000,251.200000000,100,1000,1,1,248.500000000,251.450000000,111,374,3,2,248.010000000,251.500000000,5,10,1,1,TSLA
2024-11-01T08:00:15.631970869Z,2024-11-01T08:00:15.631804912Z,10,2,16244,C,A,7,251.200000000,1000,130,165957,323801,250.000000000,250.690000000,2,26,2,1,249.930000000,250.750000000,10,26,1,1,249.880000000,250.790000000,4,200,1,1,249.850000000,250.880000000,4,14,1,1,249.800000000,250.940000000,199,100,1,1,249.770000000,251.090000000,50,100,1,1,249.010000000,251.100000000,3,1000,1,1,249.000000000,251.450000000,100,374,1,2,248.500000000,251.500000000,111,10,3,1,248.010000000,253.350000000,5,23,1,1,TSLA
2024-11-01T08:00:15.642559716Z,2024-11-01T08:00:15.642393200Z,10,2,16244,A,A,9,252.700000000,1000,130,166516,323811,250.000000000,250.690000000,2,26,2,1,249.930000000,250.750000000,10,26,1,1,249.880000000,250.790000000,4,200,1,1,249.850000000,250.880000000,4,14,1,1,249.800000000,250.940000000,199,100,1,1,249.770000000,251.090000000,50,100,1,1,249.010000000,251.100000000,3,1000,1,1,249.000000000,251.450000000,100,374,1,2,248.500000000,251.500000000,111,10,3,1,248.010000000,252.700000000,5,1000,1,1,TSLA
2024-11-01T08:00:15.657693619Z,2024-11-01T08:00:15.657527530Z,10,2,16244,A,B,6,249.600000000,1000,130,166089,323817,250.000000000,250.690000000,2,26,2,1,249.930000000,250.750000000,10,26,1,1,249.880000000,250.790000000,4,200,1,1,249.850000000,250.880000000,4,14,1,1,249.800000000,250.940000000,199,100,1,1,249.770000000,251.090000000,50,100,1,1,249.600000000,251.100000000,1000,1000,1,1,249.010000000,251.450000000,3,374,1,2,249.000000000,251.500000000,100,10,1,1,248.500000000,252.700000000,111,1000,3,1,TSLA
2024-11-01T08:00:15.685042046Z,2024-11-01T08:00:15.684875510Z,10,2,10888,A,A,0,410.760000000,2,130,166536,323835,410.000000000,410.760000000,31,2,2,1,409.750000000,413.000000000,3,20,1,1,409.740000000,414.000000000,500,468,1,2,409.670000000,415.070000000,100,246,1,1,409.430000000,415.290000000,5,34,1,1,409.250000000,415.350000000,2,84,1,2,409.220000000,419.860000000,22,10,1,1,409.080000000,420.000000000,2,3,1,1,409.000000000,425.000000000,3,50,2,1,408.970000000,430.000000000,12,5,1,1,MSFT
2024-11-01T08:00:15.720391913Z,2024-11-01T08:00:15.720225897Z,10,2,16244,C,A,1,250.750000000,26,130,166016,323853,250.000000000,250.690000000,2,26,2,1,249.930000000,250.790000000,10,200,1,1,249.880000000,250.880000000,4,14,1,1,249.850000000,250.940000000,4,100,1,1,249.800000000,251.090000000,199,100,1,1,249.770000000,251.100000000,50,1000,1,1,249.600000000,251.450000000,1000,374,1,2,249.010000000,251.500000000,3,10,1,1,249.000000000,252.700000000,100,1000,1,1,248.500000000,253.350000000,111,23,3,1,TSLA
2024-11-01T08:00:15.729982297Z,2024-11-01T08:00:15.729815572Z,10,2,16244,A,B,3,249.850000000,50,130,166725,323861,250.000000000,250.690000000,2,26,2,1,249.930000000,250.790000000,10,200,1,1,249.880000000,250.880000000,4,14,1,1,249.850000000,250.940000000,54,100,2,1,249.800000000,251.090000000,199,100,1,1,249.770000000,251.100000000,50,1000,1,1,249.600000000,251.450000000,1000,374,1,2,249.010000000,251.500000000,3,10,1,1,249.000000000,252.700000000,100,1000,1,1,248.500000000,253.350000000,111,23,3,1,TSLA
2024-11-01T08:00:15.730586219Z,2024-11-01T08:00:15.730419554Z,10,2,16244,A,B,6,249.700000000,1000,130,166665,323863,250.000000000,250.690000000,2,26,2,1,249.930000000,250.790000000,10,200,1,1,249.880000000,250.880000000,4,14,1,1,249.850000000,250.940000000,54,100,2,1,249.800000000,251.090000000,199,100,1,1,249.770000000,251.100000000,50,1000,1,1,249.700000000,251.450000000,1000,374,1,2,249.600000000,251.500000000,1000,10,1,1,249.010000000,252.700000000,3,1000,1,1,249.000000000,253.350000000,100,23,1,1,TSLA
2024-11-01T08:00:15.730657474Z,2024-11-01T08:00:15.730491277Z,10,2,16244,A,A,8,252.200000000,1000,130,166197,323865,250.000000000,250.690000000,2,26,2,1,249.930000000,250.790000000,10,200,1,1,249.880000000,250.880000000,4,14,1,1,249.850000000,250.940000000,54,100,2,1,249.800000000,251.090000000,199,100,1,1,249.770000000,251.100000000,50,1000,1,1,249.700000000,251.450000000,1000,374,1,2,249.600000000,251.500000000,1000,10,1,1,249.010000000,252.200000000,3,1000,1,1,249.000000000,252.700000000,100,1000,1,1,TSLA
2024-11-01T08:00:15.730682610Z,2024-11-01T08:00:15.730516801Z,10,2,16244,C,A,9,252.700000000,1000,130,165809,323866,250.000000000,250.690000000,2,26,2,1,249.930000000,250.790000000,10,200,1,1,249.880000000,250.880000000,4,14,1,1,249.850000000,250.940000000,54,100,2,1,249.800000000,251.090000000,199,100,1,1,249.770000000,251.100000000,50,1000,1,1,249.700000000,251.450000000,1000,374,1,2,249.600000000,251.500000000,1000,10,1,1,249.010000000,252.200000000,3,1000,1,1,249.000000000,253.350000000,100,23,1,1,TSLA
2024-11-01T08:00:15.750402676Z,2024-11-01T08:00:15.750236208Z,10,2,16244,A,B,8,249.100000000,1000,130,166468,323882,250.000000000,250.690000000,2,26,2,1,249.930000000,250.790000000,10,200,1,1,249.880000000,250.880000000,4,14,1,1,249.850000000,250.940000000,54,100,2,1,249.800000000,251.090000000,199,100,1,1,249.770000000,251.100000000,50,1000,1,1,249.700000000,251.450000000,1000,374,1,2,249.600000000,251.500000000,1000,10,1,1,249.100000000,252.200000000,1000,1000,1,1,249.010000000,253.350000000,3,23,1,1,TSLA
2024-11-01T08:00:15.773482621Z,2024-11-01T08:00:15.773315620Z,10,2,16244,A,B,3,249.850000000,50,130,167001,323914,250.000000000,250.690000000,2,26,2,1,249.930000000,250.790000000,10,200,1,1,249.880000000,250.880000000,4,14,1,1,249.850000000,250.940000000,104,100,3,1,249.800000000,251.090000000,199,100,1,1,249.770000000,251.100000000,50,1000,1,1,249.700000000,251.450000000,1000,374,1,2,249.600000000,251.500000000,1000,10,1,1,249.100000000,252.200000000,1000,1000,1,1,249.010000000,253.350000000,3,23,1,1,TSLA
2024-11-01T08:00:15.783219903Z,2024-11-01T08:00:15.783054179Z,10,2,16244,C,B,3,249.850000000,50,130,165724,323923,250.000000000,250.690000000,2,26,2,1,249.930000000,250.790000000,10,200,1,1,249.880000000,250.880000000,4,14,1,1,249.850000000,250.940000000,54,100,2,1,249.800000000,251.090000000,199,100,1,1,249.770000000,251.100000000,50,1000,1,1,249.700000000,251.450000000,1000,374,1,2,249.600000000,251.500000000,1000,10,1,1,249.100000000,252.200000000,1000,1000,1,1,249.010000000,253.350000000,3,23,1,1,TSLA
2024-11-01T08:00:15.783236584Z,2024-11-01T08:00:15.783070226Z,10,2,16244,A,B,3,249.860000000,100,130,166358,323924,250.000000000,250.690000000,2,26,2,1,249.930000000,250.790000000,10,200,1,1,249.880000000,250.880000000,4,14,1,1,249.860000000,250.940000000,100,100,1,1,249.850000000,251.090000000,4,100,1,1,249.800000000,251.100000000,199,1000,1,1,249.770000000,251.450000000,50,374,1,2,249.700000000,251.500000000,1000,10,1,1,249.600000000,252.200000000,1000,1000,1,1,249.100000000,253.350000000,1000,23,1,1,TSLA
2024-11-01T08:00:15.784120100Z,2024-11-01T08:00:15.783954349Z,10,2,16244,C,B,9,249.100000000,1000,130,165751,323928,250.000000000,250.690000000,2,26,2,1,249.930000000,250.790000000,10,200,1,1,249.880000000,250.880000000,4,14,1,1,249.860000000,250.940000000,100,100,1,1,249.850000000,251.090000000,4,100,1,1,249.800000000,251.100000000,199,1000,1,1,249.770000000,251.450000000,50,374,1,2,249.700000000,251.500000000,1000,10,1,1,249.600000000,252.200000000,1000,1000,1,1,249.010000000,253.350000000,3,23,1,1,TSLA
2024-11-01T08:00:15.824052748Z,2024-11-01T08:00:15.823886497Z,10,2,16244,A,B,1,249.960000000,50,130,166251,323944,250.000000000,250.690000000,2,26,2,1,249.960000000,250.790000000,50,200,1,1,249.930000000,250.880000000,10,14,1,1,249.880000000,250.940000000,4,100,1,1,249.850000000,251.090000000,4,100,1,1,249.800000000,251.100000000,199,1000,1,1,249.770000000,251.450000000,50,374,1,2,249.700000000,251.500000000,1000,10,1,1,249.600000000,252.200000000,1000,1000,1,1,249.010000000,253.350000000,3,23,1,1,TSLA
2024-11-01T08:00:15.870399197Z,2024-11-01T08:00:15.870232935Z,10,2,16244,C,A,0,250.690000000,26,130,166262,324122,250.000000000,250.790000000,2,200,2,1,249.960000000,250.880000000,50,14,1,1,249.930000000,250.940000000,10,100,1,1,249.880000000,251.090000000,4,100,1,1,249.850000000,251.100000000,4,1000,1,1,249.800000000,251.450000000,199,374,1,2,249.770000000,251.500000000,50,10,1,1,249.700000000,252.200000000,1000,1000,1,1,249.600000000,253.350000000,1000,23,1,1,249.010000000,253.650000000,3,400,1,1,TSLA
2024-11-01T08:00:15.880193778Z,2024-11-01T08:00:15.880027628Z,10,2,16244,A,B,1,249.990000000,50,130,166150,324138,250.000000000,250.790000000,2,200,2,1,249.990000000,250.880000000,50,14,1,1,249.930000000,250.940000000,10,100,1,1,249.880000000,251.090000000,4,100,1,1,249.850000000,251.100000000,4,1000,1,1,249.800000000,251.450000000,199,374,1,2,249.770000000,251.500000000,50,10,1,1,249.700000000,252.200000000,1000,1000,1,1,249.600000000,253.350000000,1000,23,1,1,249.010000000,253.650000000,3,400,1,1,TSLA
2024-11-01T08:00:15.883795450Z,2024-11-01T08:00:15.883629282Z,10,2,38,A,A,6,225.720000000,50,130,166168,324152,221.700000000,223.000000000,24,90,2,1,221.300000000,224.400000000,1000,1000,1,1,221.200000000,224.520000000,10,100,1,1,220.000000000,225.000000000,8,1,2,1,219.960000000,225.360000000,4,1,1,1,219.690000000,225.490000000,442,442,1,1,219.000000000,225.720000000,1,50,1,1,217.000000000,225.900000000,1525,32,1,2,215.000000000,227.000000000,10,35,2,1,214.380000000,229.330000000,27,9,1,2,AAPL
2024-11-01T08:00:15.890547969Z,2024-11-01T08:00:15.890381816Z,10,2,38,A,B,8,215.000000000,50,130,166153,324206,221.700000000,223.000000000,24,90,2,1,221.300000000,224.400000000,1000,1000,1,1,221.200000000,224.520000000,10,100,1,1,220.000000000,225.000000000,8,1,2,1,219.960000000,225.360000000,4,1,1,1,219.690000000,225.490000000,442,442,1,1,219.000000000,225.720000000,1,50,1,1,217.000000000,225.900000000,1525,32,1,2,215.000000000,227.000000000,60,35,3,1,214.380000000,229.330000000,27,9,1,2,AAPL
2024-11-01T08:00:15.890666143Z,2024-11-01T08:00:15.890499553Z,10,2,38,A,A,8,227.000000000,50,130,166590,324207,221.700000000,223.000000000,24,90,2,1,221.300000000,224.400000000,1000,1000,1,1,221.200000000,224.520000000,10,100,1,1,220.000000000,225.000000000,8,1,2,1,219.960000000,225.360000000,4,1,1,1,219.690000000,225.490000000,442,442,1,1,219.000000000,225.720000000,1,50,1,1,217.000000000,225.900000000,1525,32,1,2,215.000000000,227.000000000,60,85,3,2,214.380000000,229.330000000,27,9,1,2,AAPL
2024-11-01T08:00:15.964349349Z,2024-11-01T08:00:15.964183143Z,10,2,11667,A,B,9,133.800000000,100,130,166206,324462,134.800000000,134.970000000,184,100,1,1,134.750000000,134.990000000,500,10,1,1,134.530000000,135.000000000,100,38,1,3,134.500000000,135.100000000,520,10,2,1,134.410000000,135.230000000,61,360,2,1,134.380000000,135.300000000,18,1009,1,2,134.210000000,135.390000000,20,1000,1,1,134.200000000,135.400000000,3,10,1,1,134.000000000,135.420000000,41,1,2,1,133.800000000,135.820000000,105,1,2,1,NVDA
2024-11-01T08:00:15.964941523Z,2024-11-01T08:00:15.964775218Z,10,2,11667,A,B,8,134.090000000,8,130,166305,324466,134.800000000,134.970000000,184,100,1,1,134.750000000,134.990000000,500,10,1,1,134.530000000,135.000000000,100,38,1,3,134.500000000,135.100000000,520,10,2,1,134.410000000,135.230000000,61,360,2,1,134.380000000,135.300000000,18,1009,1,2,134.210000000,135.390000000,20,1000,1,1,134.200000000,135.400000000,3,10,1,1,134.090000000,135.420000000,8,1,1,1,134.000000000,135.820000000,41,1,2,1,NVDA
2024-11-01T08:00:15.966781679Z,2024-11-01T08:00:15.966615437Z,10,2,11667,A,B,2,134.610000000,750,130,166242,324476,134.800000000,134.970000000,184,100,1,1,134.750000000,134.990000000,500,10,1,1,134.610000000,135.000000000,750,38,1,3,134.530000000,135.100000000,100,10,1,1,134.500000000,135.230000000,520,360,2,1,134.410000000,135.300000000,61,1009,2,2,134.380000000,135.390000000,18,1000,1,1,134.210000000,135.400000000,20,10,1,1,134.200000000,135.420000000,3,1,1,1,134.090000000,135.820000000,8,1,1,1,NVDA
2024-11-01T08:00:15.994299092Z,2024-11-01T08:00:15.994133188Z,10,2,38,A,B,0,221.730000000,50,130,165904,324558,221.730000000,223.000000000,50,90,1,1,221.700000000,224.400000000,24,1000,2,1,221.300000000,224.520000000,1000,100,1,1,221.200000000,225.000000000,10,1,1,1,220.000000000,225.360000000,8,1,2,1,219.960000000,225.490000000,4,442,1,1,219.690000000,225.720000000,442,50,1,1,219.000000000,225.900000000,1,32,1,2,217.000000000,227.000000000,1525,85,1,2,215.000000000,229.330000000,60,9,3,2,AAPL
2024-11-01T08:00:15.994539080Z,2024-11-01T08:00:15.994372845Z,10,2,38,A,A,1,223.230000000,50,130,166235,324560,221.730000000,223.000000000,50,90,1,1,221.700000000,223.230000000,24,50,2,1,221.300000000,224.400000000,1000,1000,1,1,221.200000000,224.520000000,10,100,1,1,220.000000000,225.000000000,8,1,2,1,219.960000000,225.360000000,4,1,1,1,219.690000000,225.490000000,442,442,1,1,219.000000000,225.720000000,1,50,1,1,217.000000000,225.900000000,1525,32,1,2,215.000000000,227.000000000,60,85,3,2,AAPL
2024-11-01T08:00:16.051117812Z,2024-11-01T08:00:16.050951677Z,10,2,11667,A,B,4,134.500000000,100,130,166135,324745,134.800000000,134.970000000,184,100,1,1,134.750000000,134.990000000,500,10,1,1,134.610000000,135.000000000,750,38,1,3,134.530000000,135.100000000,100,10,1,1,134.500000000,135.230000000,620,360,3,1,134.410000000,135.300000000,61,1009,2,2,134.380000000,135.390000000,18,1000,1,1,134.210000000,135.400000000,20,10,1,1,134.200000000,135.420000000,3,1,1,1,134.090000000,135.820000000,8,1,1,1,NVDA
2024-11-01T08:00:16.094577755Z,2024-11-01T08:00:16.094411748Z,10,2,16244,C,B,8,249.600000000,1000,130,166007,324905,250.000000000,250.790000000,2,200,2,1,249.990000000,250.880000000,50,14,1,1,249.930000000,250.940000000,10,100,1,1,249.880000000,251.090000000,4,100,1,1,249.850000000,251.100000000,4,1000,1,1,249.800000000,251.450000000,199,374,1,2,249.770000000,251.500000000,50,10,1,1,249.700000000,252.200000000,1000,1000,1,1,249.010000000,253.350000000,3,23,1,1,249.000000000,253.650000000,100,400,1,1,TSLA
2024-11-01T08:00:16.117808231Z,2024-11-01T08:00:16.117642394Z,10,2,16244,C,B,7,249.700000000,1000,130,165837,325017,250.000000000,250.790000000,2,200,2,1,249.990000000,250.880000000,50,14,1,1,249.930000000,250.940000000,10,100,1,1,249.880000000,251.090000000,4,100,1,1,249.850000000,251.100000000,4,1000,1,1,249.800000000,251.450000000,199,374,1,2,249.770000000,251.500000000,50,10,1,1,249.010000000,252.200000000,3,1000,1,1,249.000000000,253.350000000,100,23,1,1,248.500000000,253.650000000,111,400,3,1,TSLA
2024-11-01T08:00:16.128244721Z,2024-11-01T08:00:16.128078622Z,10,2,16244,A,B,7,249.400000000,1000,130,166099,325050,250.000000000,250.790000000,2,200,2,1,249.990000000,250.880000000,50,14,1,1,249.930000000,250.940000000,10,100,1,1,249.880000000,251.090000000,4,100,1,1,249.850000000,251.100000000,4,1000,1,1,249.800000000,251.450000000,199,374,1,2,249.770000000,251.500000000,50,10,1,1,249.400000000,252.200000000,1000,1000,1,1,249.010000000,253.350000000,3,23,1,1,249.000000000,253.650000000,100,400,1,1,TSLA
2024-11-01T08:00:16.300584572Z,2024-11-01T08:00:16.300417886Z,10,2,16244,A,B,0,250.000000000,100,130,166686,325389,250.000000000,250.790000000,102,200,3,1,249.930000000,250.880000000,10,14,1,1,249.880000000,250.940000000,4,100,1,1,249.850000000,251.090000000,4,100,1,1,249.800000000,251.100000000,199,1000,1,1,249.770000000,251.450000000,50,374,1,2,249.400000000,251.500000000,1000,10,1,1,249.010000000,252.200000000,3,1000,1,1,249.000000000,253.350000000,100,23,1,1,248.500000000,253.650000000,111,400,3,1,TSLA
2024-11-01T08:00:16.354028352Z,2024-11-01T08:00:16.353862219Z,10,2,16244,A,B,0,250.100000000,50,130,166133,325445,250.100000000,250.790000000,50,200,1,1,250.000000000,250.880000000,2,14,2,1,249.930000000,250.940000000,10,100,1,1,249.880000000,251.090000000,4,100,1,1,249.850000000,251.100000000,4,1000,1,1,249.800000000,251.450000000,199,374,1,2,249.770000000,251.500000000,50,10,1,1,249.400000000,252.200000000,1000,1000,1,1,249.010000000,253.350000000,3,23,1,1,249.000000000,253.650000000,100,400,1,1,TSLA
2024-11-01T08:00:16.354053942Z,2024-11-01T08:00:16.353887992Z,10,2,16244,A,B,0,250.100000000,50,130,165950,325446,250.100000000,250.790000000,100,200,2,1,250.000000000,250.880000000,2,14,2,1,249.930000000,250.940000000,10,100,1,1,249.880000000,251.090000000,4,100,1,1,249.850000000,251.100000000,4,1000,1,1,249.800000000,251.450000000,199,374,1,2,249.770000000,251.500000000,50,10,1,1,249.400000000,252.200000000,1000,1000,1,1,249.010000000,253.350000000,3,23,1,1,249.000000000,253.650000000,100,400,1,1,TSLA
2024-11-01T08:00:16.405561834Z,2024-11-01T08:00:16.405396007Z,10,2,16244,C,B,0,250.100000000,50,130,165827,325580,250.100000000,250.790000000,50,200,1,1,250.000000000,250.880000000,2,14,2,1,249.930000000,250.940000000,10,100,1,1,249.880000000,251.090000000,4,100,1,1,249.850000000,251.100000000,4,1000,1,1,249.800000000,251.450000000,199,374,1,2,249.770000000,251.500000000,50,10,1,1,249.400000000,252.200000000,1000,1000,1,1,249.010000000,253.350000000,3,23,1,1,249.000000000,253.650000000,100,400,1,1,TSLA
2024-11-01T08:00:16.405576269Z,2024-11-01T08:00:16.405409916Z,10,2,16244,A,B,0,250.130000000,50,130,166353,325581,250.130000000,250.790000000,50,200,1,1,250.000000000,250.880000000,2,14,2,1,249.930000000,250.940000000,10,100,1,1,249.880000000,251.090000000,4,100,1,1,249.850000000,251.100000000,4,1000,1,1,249.800000000,251.450000000,199,374,1,2,249.770000000,251.500000000,50,10,1,1,249.400000000,252.200000000,1000,1000,1,1,249.010000000,253.350000000,3,23,1,1,249.000000000,253.650000000,100,400,1,1,TSLA
2024-11-01T08:00:16.460379702Z,2024-11-01T08:00:16.460213300Z,10,2,16244,A,B,0,250.150000000,50,130,166402,325836,250.150000000,250.790000000,50,200,1,1,250.000000000,250.880000000,2,14,2,1,249.930000000,250.940000000,10,100,1,1,249.880000000,251.090000000,4,100,1,1,249.850000000,251.100000000,4,1000,1,1,249.800000000,251.450000000,199,374,1,2,249.770000000,251.500000000,50,10,1,1,249.400000000,252.200000000,1000,1000,1,1,249.010000000,253.350000000,3,23,1,1,249.000000000,253.650000000,100,400,1,1,TSLA
2024-11-01T08:00:16.462756059Z,2024-11-01T08:00:16.462590054Z,10,2,11667,A,B,9,134.180000000,50,130,166005,325855,134.800000000,134.970000000,184,100,1,1,134.750000000,134.990000000,500,10,1,1,134.610000000,135.000000000,750,38,1,3,134.530000000,135.100000000,100,10,1,1,134.500000000,135.230000000,620,360,3,1,134.410000000,135.300000000,61,1009,2,2,134.380000000,135.390000000,18,1000,1,1,134.210000000,135.400000000,20,10,1,1,134.200000000,135.420000000,3,1,1,1,134.180000000,135.820000000,50,1,1,1,NVDA
2024-11-01T08:00:16.548950655Z,2024-11-01T08:00:16.548784791Z,10,2,16244,C,A,7,252.200000000,1000,130,165864,325935,250.150000000,250.790000000,50,200,1,1,250.000000000,250.880000000,2,14,2,1,249.930000000,250.940000000,10,100,1,1,249.880000000,251.090000000,4,100,1,1,249.850000000,251.100000000,4,1000,1,1,249.800000000,251.450000000,199,374,1,2,249.770000000,251.500000000,50,10,1,1,249.400000000,253.350000000,1000,23,1,1,249.010000000,253.650000000,3,400,1,1,249.000000000,253.880000000,100,8,1,1,TSLA
2024-11-01T08:00:16.559669274Z,2024-11-01T08:00:16.559503246Z,10,2,16244,A,A,7,252.700000000,1000,130,166028,325993,250.150000000,250.790000000,50,200,1,1,250.000000000,250.880000000,2,14,2,1,249.930000000,250.940000000,10,100,1,1,249.880000000,251.090000000,4,100,1,1,249.850000000,251.100000000,4,1000,1,1,249.800000000,251.450000000,199,374,1,2,249.770000000,251.500000000,50,10,1,1,249.400000000,252.700000000,1000,1000,1,1,249.010000000,253.350000000,3,23,1,1,249.000000000,253.650000000,100,400,1,1,TSLA
2024-11-01T08:00:16.685566806Z,2024-11-01T08:00:16.685400907Z,10,2,780,C,B,0,308.380000000,25,130,165899,326968,,330.140000000,0,25,0,1,,,0,0,0,0,,,0,0,0,0,,,0,0,0,0,,,0,0,0,0,,,0,0,0,0,,,0,0,0,0,,,0,0,0,0,,,0,0,0,0,,,0,0,0,0,AMGN
2024-11-01T08:00:16.702668943Z,2024-11-01T08:00:16.702503025Z,10,2,11667,A,B,0,134.890000000,25,130,165918,327016,134.890000000,134.970000000,25,100,1,1,134.800000000,134.990000000,184,10,1,1,134.750000000,135.000000000,500,38,1,3,134.610000000,135.100000000,750,10,1,1,134.530000000,135.230000000,100,360,1,1,134.500000000,135.300000000,620,1009,3,2,134.410000000,135.390000000,61,1000,2,1,134.380000000,135.400000000,18,10,1,1,134.210000000,135.420000000,20,1,1,1,134.200000000,135.820000000,3,1,1,1,NVDA
2024-11-01T08:00:16.702756585Z,2024-11-01T08:00:16.702590401Z,10,2,11667,A,A,4,135.120000000,25,130,166184,327018,134.890000000,134.970000000,25,100,1,1,134.800000000,134.990000000,184,10,1,1,134.750000000,135.000000000,500,38,1,3,134.610000000,135.100000000,750,10,1,1,134.530000000,135.120000000,100,25,1,1,134.500000000,135.230000000,620,360,3,1,134.410000000,135.300000000,61,1009,2,2,134.380000000,135.390000000,18,1000,1,1,134.210000000,135.400000000,20,10,1,1,134.200000000,135.420000000,3,1,1,1,NVDA
2024-11-01T08:00:16.719122164Z,2024-11-01T08:00:16.718955851Z,10,2,38,A,A,0,223.000000000,450,130,166313,327032,221.730000000,223.000000000,50,540,1,2,221.700000000,223.230000000,24,50,2,1,221.300000000,224.400000000,1000,1000,1,1,221.200000000,224.520000000,10,100,1,1,220.000000000,225.000000000,8,1,2,1,219.960000000,225.360000000,4,1,1,1,219.690000000,225.490000000,442,442,1,1,219.000000000,225.720000000,1,50,1,1,217.000000000,225.900000000,1525,32,1,2,215.000000000,227.000000000,60,85,3,2,AAPL
2024-11-01T08:00:16.740901053Z,2024-11-01T08:00:16.740734375Z,10,2,780,A,B,0,308.040000000,25,130,166678,327051,308.040000000,330.140000000,25,25,1,1,,,0,0,0,0,,,0,0,0,0,,,0,0,0,0,,,0,0,0,0,,,0,0,0,0,,,0,0,0,0,,,0,0,0,0,,,0,0,0,0,,,0,0,0,0,AMGN
2024-11-01T08:00:16.767372319Z,2024-11-01T08:00:16.767205919Z,10,2,11667,A,B,1,134.840000000,100,130,166400,327064,134.890000000,134.970000000,25,100,1,1,134.840000000,134.990000000,100,10,1,1,134.800000000,135.000000000,184,38,1,3,134.750000000,135.100000000,500,10,1,1,134.610000000,135.120000000,750,25,1,1,134.500000000,135.230000000,620,360,3,1,134.410000000,135.300000000,61,1009,2,2,134.380000000,135.390000000,18,1000,1,1,134.210000000,135.400000000,20,10,1,1,134.200000000,135.420000000,3,1,1,1,NVDA
2024-11-01T08:00:16.776947837Z,2024-11-01T08:00:16.776781615Z,10,2,11667,A,A,0,134.920000000,1,130,166222,327072,134.890000000,134.920000000,25,1,1,1,134.840000000,134.970000000,100,100,1,1,134.800000000,134.990000000,184,10,1,1,134.750000000,135.000000000,500,38,1,3,134.610000000,135.100000000,750,10,1,1,134.500000000,135.120000000,620,25,3,1,134.410000000,135.230000000,61,360,2,1,134.380000000,135.300000000,18,1009,1,2,134.210000000,135.390000000,20,1000,1,1,134.200000000,135.400000000,3,10,1,1,NVDA
2024-11-01T08:00:16.777748772Z,2024-11-01T08:00:16.777582322Z,10,2,11667,A,A,0,134.920000000,10,130,166450,327074,134.890000000,134.920000000,25,11,1,2,134.840000000,134.970000000,100,100,1,1,134.800000000,134.990000000,184,10,1,1,134.750000000,135.000000000,500,38,1,3,134.610000000,135.100000000,750,10,1,1,134.500000000,135.120000000,620,25,3,1,134.410000000,135.230000000,61,360,2,1,134.380000000,135.300000000,18,1009,1,2,134.210000000,135.390000000,20,1000,1,1,134.200000000,135.400000000,3,10,1,1,NVDA
2024-11-01T08:00:16.799341751Z,2024-11-01T08:00:16.799175317Z,10,2,38,A,A,2,224.300000000,1000,130,166434,327139,221.730000000,223.000000000,50,540,1,2,221.700000000,223.230000000,24,50,2,1,221.300000000,224.300000000,1000,1000,1,1,221.200000000,224.400000000,10,1000,1,1,220.000000000,224.520000000,8,100,2,1,219.960000000,225.000000000,4,1,1,1,219.690000000,225.360000000,442,1,1,1,219.000000000,225.490000000,1,442,1,1,217.000000000,225.720000000,1525,50,1,1,215.000000000,225.900000000,60,32,3,2,AAPL
2024-11-01T08:00:16.799391969Z,2024-11-01T08:00:16.799225480Z,10,2,38,C,A,3,224.400000000,1000,130,166489,327140,221.730000000,223.000000000,50,540,1,2,221.700000000,223.230000000,24,50,2,1,221.300000000,224.300000000,1000,1000,1,1,221.200000000,224.520000000,10,100,1,1,220.000000000,225.000000000,8,1,2,1,219.960000000,225.360000000,4,1,1,1,219.690000000,225.490000000,442,442,1,1,219.000000000,225.720000000,1,50,1,1,217.000000000,225.900000000,1525,32,1,2,215.000000000,227.000000000,60,85,3,2,AAPL
2024-11-01T08:00:16.804379763Z,2024-11-01T08:00:16.804213235Z,10,2,11667,A,B,0,134.900000000,20,130,166528,327144,134.900000000,134.920000000,20,11,1,2,134.890000000,134.970000000,25,100,1,1,134.840000000,134.990000000,100,10,1,1,134.800000000,135.000000000,184,38,1,3,134.750000000,135.100000000,500,10,1,1,134.610000000,135.120000000,750,25,1,1,134.500000000,135.230000000,620,360,3,1,134.410000000,135.300000000,61,1009,2,2,134.380000000,135.390000000,18,1000,1,1,134.210000000,135.400000000,20,10,1,1,NVDA
2024-11-01T08:00:16.878210344Z,2024-11-01T08:00:16.878044511Z,10,2,16244,C,B,2,249.930000000,10,130,165833,327308,250.150000000,250.790000000,50,200,1,1,250.000000000,250.880000000,2,14,2,1,249.880000000,250.940000000,4,100,1,1,249.850000000,251.090000000,4,100,1,1,249.800000000,251.100000000,199,1000,1,1,249.770000000,251.450000000,50,374,1,2,249.400000000,251.500000000,1000,10,1,1,249.010000000,252.700000000,3,1000,1,1,249.000000000,253.350000000,100,23,1,1,248.500000000,253.650000000,111,400,3,1,TSLA
2024-11-01T08:00:16.881998117Z,2024-11-01T08:00:16.881832175Z,10,2,11667,A,A,1,134.950000000,400,130,165942,327314,134.900000000,134.920000000,20,11,1,2,134.890000000,134.950000000,25,400,1,1,134.840000000,134.970000000,100,100,1,1,134.800000000,134.990000000,184,10,1,1,134.750000000,135.000000000,500,38,1,3,134.610000000,135.100000000,750,10,1,1,134.500000000,135.120000000,620,25,3,1,134.410000000,135.230000000,61,360,2,1,134.380000000,135.300000000,18,1009,1,2,134.210000000,135.390000000,20,1000,1,1,NVDA
2024-11-01T08:00:16.884290553Z,2024-11-01T08:00:16.884087991Z,10,2,11667,T,A,0,134.900000000,20,0,202562,327332,134.900000000,134.920000000,20,11,1,2,134.890000000,134.950000000,25,400,1,1,134.840000000,134.970000000,100,100,1,1,134.800000000,134.990000000,184,10,1,1,134.750000000,135.000000000,500,38,1,3,134.610000000,135.100000000,750,10,1,1,134.500000000,135.120000000,620,25,3,1,134.410000000,135.230000000,61,360,2,1,134.380000000,135.300000000,18,1009,1,2,134.210000000,135.390000000,20,1000,1,1,NVDA
2024-11-01T08:00:16.884290553Z,2024-11-01T08:00:16.884087991Z,10,2,11667,T,A,0,134.890000000,25,0,202562,327333,134.890000000,134.920000000,25,11,1,2,134.840000000,134.950000000,100,400,1,1,134.800000000,134.970000000,184,100,1,1,134.750000000,134.990000000,500,10,1,1,134.610000000,135.000000000,750,38,1,3,134.500000000,135.100000000,620,10,3,1,134.410000000,135.120000000,61,25,2,1,134.380000000,135.230000000,18,360,1,1,134.210000000,135.300000000,20,1009,1,2,134.200000000,135.390000000,3,1000,1,1,NVDA
2024-11-01T08:00:16.884290553Z,2024-11-01T08:00:16.884087991Z,10,2,11667,T,A,0,134.840000000,100,0,202562,327334,134.840000000,134.920000000,100,11,1,2,134.800000000,134.950000000,184,400,1,1,134.750000000,134.970000000,500,100,1,1,134.610000000,134.990000000,750,10,1,1,134.500000000,135.000000000,620,38,3,3,134.410000000,135.100000000,61,10,2,1,134.380000000,135.120000000,18,25,1,1,134.210000000,135.230000000,20,360,1,1,134.200000000,135.300000000,3,1009,1,2,134.180000000,135.390000000,50,1000,1,1,NVDA
2024-11-01T08:00:16.884290553Z,2024-11-01T08:00:16.884087991Z,10,2,11667,T,N,0,134.830000000,100,0,202562,327335,134.800000000,134.920000000,184,11,1,2,134.750000000,134.950000000,500,400,1,1,134.610000000,134.970000000,750,100,1,1,134.500000000,134.990000000,620,10,3,1,134.410000000,135.000000000,61,38,2,3,134.380000000,135.100000000,18,10,1,1,134.210000000,135.120000000,20,25,1,1,134.200000000,135.230000000,3,360,1,1,134.180000000,135.300000000,50,1009,1,2,134.090000000,135.390000000,8,1000,1,1,NVDA
2024-11-01T08:00:16.884290553Z,2024-11-01T08:00:16.884087991Z,10,2,11667,T,A,0,134.800000000,55,130,202562,327336,134.800000000,134.920000000,184,11,1,2,134.750000000,134.950000000,500,400,1,1,134.610000000,134.970000000,750,100,1,1,134.500000000,134.990000000,620,10,3,1,134.410000000,135.000000000,61,38,2,3,134.380000000,135.100000000,18,10,1,1,134.210000000,135.120000000,20,25,1,1,134.200000000,135.230000000,3,360,1,1,134.180000000,135.300000000,50,1009,1,2,134.090000000,135.390000000,8,1000,1,1,NVDA
2024-11-01T08:00:16.884290553Z,2024-11-01T08:00:16.884087991Z,10,2,11667,C,B,0,134.800000000,55,130,202562,327336,134.800000000,134.920000000,129,11,1,2,134.750000000,134.950000000,500,400,1,1,134.610000000,134.970000000,750,100,1,1,134.500000000,134.990000000,620,10,3,1,134.410000000,135.000000000,61,38,2,3,134.380000000,135.100000000,18,10,1,1,134.210000000,135.120000000,20,25,1,1,134.200000000,135.230000000,3,360,1,1,134.180000000,135.300000000,50,1009,1,2,134.090000000,135.390000000,8,1000,1,1,NVDA
2024-11-01T08:00:16.884347582Z,2024-11-01T08:00:16.884175530Z,10,2,11667,A,A,0,134.880000000,100,130,172052,327342,134.800000000,134.880000000,129,100,1,1,134.750000000,134.900000000,500,500,1,3,134.610000000,134.910000000,750,100,1,1,134.500000000,134.920000000,620,11,3,2,134.410000000,134.950000000,61,400,2,1,134.380000000,134.970000000,18,100,1,1,134.210000000,134.990000000,20,10,1,1,134.200000000,135.000000000,3,38,1,3,134.180000000,135.100000000,50,10,1,1,134.090000000,135.120000000,8,25,1,1,NVDA
2024-11-01T08:00:16.884356717Z,2024-11-01T08:00:16.884190650Z,10,2,11667,A,A,2,134.910000000,100,130,166067,327347,134.800000000,134.880000000,129,100,1,1,134.750000000,134.900000000,500,500,1,3,134.610000000,134.910000000,750,200,1,2,134.500000000,134.920000000,620,11,3,2,134.410000000,134.950000000,61,400,2,1,134.380000000,134.970000000,18,100,1,1,134.210000000,134.990000000,20,10,1,1,134.200000000,135.000000000,3,38,1,3,134.180000000,135.100000000,50,10,1,1,134.090000000,135.120000000,8,25,1,1,NVDA
2024-11-01T08:00:16.884362910Z,2024-11-01T08:00:16.884196621Z,10,2,11667,A,A,2,134.910000000,100,130,166289,327348,134.800000000,134.880000000,129,100,1,1,134.750000000,134.900000000,500,500,1,3,134.610000000,134.910000000,750,300,1,3,134.500000000,134.920000000,620,11,3,2,134.410000000,134.950000000,61,400,2,1,134.380000000,134.970000000,18,100,1,1,134.210000000,134.990000000,20,10,1,1,134.200000000,135.000000000,3,38,1,3,134.180000000,135.100000000,50,10,1,1,134.090000000,135.120000000,8,25,1,1,NVDA
2024-11-01T08:00:16.884369603Z,2024-11-01T08:00:16.884202519Z,10,2,11667,A,A,0,134.880000000,100,130,167084,327350,134.800000000,134.880000000,129,200,1,2,134.750000000,134.900000000,500,400,1,2,134.610000000,134.910000000,750,300,1,3,134.500000000,134.920000000,620,11,3,2,134.410000000,134.950000000,61,400,2,1,134.380000000,134.970000000,18,100,1,1,134.210000000,134.990000000,20,10,1,1,134.200000000,135.000000000,3,38,1,3,134.180000000,135.100000000,50,10,1,1,134.090000000,135.120000000,8,25,1,1,NVDA
2024-11-01T08:00:16.884380960Z,2024-11-01T08:00:16.884214289Z,10,2,11667,A,A,1,134.900000000,100,130,166671,327353,134.800000000,134.880000000,129,200,1,2,134.750000000,134.900000000,500,500,1,3,134.610000000,134.910000000,750,300,1,3,134.500000000,134.920000000,620,11,3,2,134.410000000,134.950000000,61,400,2,1,134.380000000,134.970000000,18,100,1,1,134.210000000,134.990000000,20,10,1,1,134.200000000,135.000000000,3,38,1,3,134.180000000,135.100000000,50,10,1,1,134.090000000,135.120000000,8,25,1,1,NVDA
2024-11-01T08:00:16.884392825Z,2024-11-01T08:00:16.884226893Z,10,2,11667,C,A,2,134.910000000,100,130,165932,327354,134.800000000,134.880000000,129,200,1,2,134.750000000,134.900000000,500,500,1,3,134.610000000,134.910000000,750,200,1,2,134.500000000,134.920000000,620,11,3,2,134.410000000,134.950000000,61,400,2,1,134.380000000,134.970000000,18,100,1,1,134.210000000,134.990000000,20,10,1,1,134.200000000,135.000000000,3,38,1,3,134.180000000,135.100000000,50,10,1,1,134.090000000,135.120000000,8,25,1,1,NVDA
2024-11-01T08:00:16.884401833Z,2024-11-01T08:00:16.884236144Z,10,2,11667,C,A,2,134.910000000,100,130,165689,327355,134.800000000,134.880000000,129,200,1,2,134.750000000,134.900000000,500,500,1,3,134.610000000,134.910000000,750,100,1,1,134.500000000,134.920000000,620,11,3,2,134.410000000,134.950000000,61,400,2,1,134.380000000,134.970000000,18,100,1,1,134.210000000,134.990000000,20,10,1,1,134.200000000,135.000000000,3,38,1,3,134.180000000,135.100000000,50,10,1,1,134.090000000,135.120000000,8,25,1,1,NVDA
2024-11-01T08:00:16.884412792Z,2024-11-01T08:00:16.884246931Z,10,2,11667,C,A,0,134.880000000,100,130,165861,327356,134.800000000,134.880000000,129,100,1,1,134.750000000,134.900000000,500,500,1,3,134.610000000,134.910000000,750,100,1,1,134.500000000,134.920000000,620,11,3,2,134.410000000,134.950000000,61,400,2,1,134.380000000,134.970000000,18,100,1,1,134.210000000,134.990000000,20,10,1,1,134.200000000,135.000000000,3,38,1,3,134.180000000,135.100000000,50,10,1,1,134.090000000,135.120000000,8,25,1,1,NVDA
2024-11-01T08:00:16.884422902Z,2024-11-01T08:00:16.884257161Z,10,2,11667,C,A,1,134.900000000,100,130,165741,327357,134.800000000,134.880000000,129,100,1,1,134.750000000,134.900000000,500,400,1,2,134.610000000,134.910000000,750,100,1,1,134.500000000,134.920000000,620,11,3,2,134.410000000,134.950000000,61,400,2,1,134.380000000,134.970000000,18,100,1,1,134.210000000,134.990000000,20,10,1,1,134.200000000,135.000000000,3,38,1,3,134.180000000,135.100000000,50,10,1,1,134.090000000,135.120000000,8,25,1,1,NVDA
2024-11-01T08:00:16.884530048Z,2024-11-01T08:00:16.884362195Z,10,2,11667,T,N,0,134.820000000,40,130,167853,327358,134.800000000,134.880000000,129,100,1,1,134.750000000,134.900000000,500,400,1,2,134.610000000,134.910000000,750,100,1,1,134.500000000,134.920000000,620,11,3,2,134.410000000,134.950000000,61,400,2,1,134.380000000,134.970000000,18,100,1,1,134.210000000,134.990000000,20,10,1,1,134.200000000,135.000000000,3,38,1,3,134.180000000,135.100000000,50,10,1,1,134.090000000,135.120000000,8,25,1,1,NVDA
2024-11-01T08:00:16.884582403Z,2024-11-01T08:00:16.884416692Z,10,2,11667,C,A,1,134.900000000,300,130,165711,327359,134.800000000,134.880000000,129,100,1,1,134.750000000,134.900000000,500,100,1,1,134.610000000,134.910000000,750,100,1,1,134.500000000,134.920000000,620,11,3,2,134.410000000,134.950000000,61,400,2,1,134.380000000,134.970000000,18,100,1,1,134.210000000,134.990000000,20,10,1,1,134.200000000,135.000000000,3,38,1,3,134.180000000,135.100000000,50,10,1,1,134.090000000,135.120000000,8,25,1,1,NVDA
2024-11-01T08:00:16.884688079Z,2024-11-01T08:00:16.884521785Z,10,2,11667,A,A,1,134.900000000,300,130,166294,327360,134.800000000,134.880000000,129,100,1,1,134.750000000,134.900000000,500,400,1,2,134.610000000,134.910000000,750,100,1,1,134.500000000,134.920000000,620,11,3,2,134.410000000,134.950000000,61,400,2,1,134.380000000,134.970000000,18,100,1,1,134.210000000,134.990000000,20,10,1,1,134.200000000,135.000000000,3,38,1,3,134.180000000,135.100000000,50,10,1,1,134.090000000,135.120000000,8,25,1,1,NVDA
2024-11-01T08:00:16.884751192Z,2024-11-01T08:00:16.884583691Z,10,2,11667,T,N,0,134.820000000,6,130,167501,327361,134.800000000,134.880000000,129,100,1,1,134.750000000,134.900000000,500,400,1,2,134.610000000,134.910000000,750,100,1,1,134.500000000,134.920000000,620,11,3,2,134.410000000,134.950000000,61,400,2,1,134.380000000,134.970000000,18,100,1,1,134.210000000,134.990000000,20,10,1,1,134.200000000,135.000000000,3,38,1,3,134.180000000,135.100000000,50,10,1,1,134.090000000,135.120000000,8,25,1,1,NVDA
2024-11-01T08:00:16.884779754Z,2024-11-01T08:00:16.884613803Z,10,2,11667,C,A,9,135.120000000,25,130,165951,327362,134.800000000,134.880000000,129,100,1,1,134.750000000,134.900000000,500,400,1,2,134.610000000,134.910000000,750,100,1,1,134.500000000,134.920000000,620,11,3,2,134.410000000,134.950000000,61,400,2,1,134.380000000,134.970000000,18,100,1,1,134.210000000,134.990000000,20,10,1,1,134.200000000,135.000000000,3,38,1,3,134.180000000,135.100000000,50,10,1,1,134.090000000,135.230000000,8,360,1,1,NVDA
2024-11-01T08:00:16.884787847Z,2024-11-01T08:00:16.884620893Z,10,2,11667,T,N,0,134.820000000,42,130,166954,327363,134.800000000,134.880000000,129,100,1,1,134.750000000,134.900000000,500,400,1,2,134.610000000,134.910000000,750,100,1,1,134.500000000,134.920000000,620,11,3,2,134.410000000,134.950000000,61,400,2,1,134.380000000,134.970000000,18,100,1,1,134.210000000,134.990000000,20,10,1,1,134.200000000,135.000000000,3,38,1,3,134.180000000,135.100000000,50,10,1,1,134.090000000,135.230000000,8,360,1,1,NVDA
2024-11-01T08:00:16.884957706Z,2024-11-01T08:00:16.884786629Z,10,2,11667,T,A,0,134.800000000,6,130,171077,327365,134.800000000,134.880000000,129,100,1,1,134.750000000,134.900000000,500,400,1,2,134.610000000,134.910000000,750,100,1,1,134.500000000,134.920000000,620,11,3,2,134.410000000,134.950000000,61,400,2,1,134.380000000,134.970000000,18,100,1,1,134.210000000,134.990000000,20,10,1,1,134.200000000,135.000000000,3,38,1,3,134.180000000,135.100000000,50,10,1,1,134.090000000,135.230000000,8,360,1,1,NVDA
2024-11-01T08:00:16.884957706Z,2024-11-01T08:00:16.884786629Z,10,2,11667,C,B,0,134.800000000,6,130,171077,327365,134.800000000,134.880000000,123,100,1,1,134.750000000,134.900000000,500,400,1,2,134.610000000,134.910000000,750,100,1,1,134.500000000,134.920000000,620,11,3,2,134.410000000,134.950000000,61,400,2,1,134.380000000,134.970000000,18,100,1,1,134.210000000,134.990000000,20,10,1,1,134.200000000,135.000000000,3,38,1,3,134.180000000,135.100000000,50,10,1,1,134.090000000,135.230000000,8,360,1,1,NVDA
2024-11-01T08:00:16.884968731Z,2024-11-01T08:00:16.884801450Z,10,2,11667,T,A,0,134.800000000,1,130,167281,327366,134.800000000,134.880000000,123,100,1,1,134.750000000,134.900000000,500,400,1,2,134.610000000,134.910000000,750,100,1,1,134.500000000,134.920000000,620,11,3,2,134.410000000,134.950000000,61,400,2,1,134.380000000,134.970000000,18,100,1,1,134.210000000,134.990000000,20,10,1,1,134.200000000,135.000000000,3,38,1,3,134.180000000,135.100000000,50,10,1,1,134.090000000,135.230000000,8,360,1,1,NVDA
2024-11-01T08:00:16.884968731Z,2024-11-01T08:00:16.884801450Z,10,2,11667,C,B,0,134.800000000,1,130,167281,327366,134.800000000,134.880000000,122,100,1,1,134.750000000,134.900000000,500,400,1,2,134.610000000,134.910000000,750,100,1,1,134.500000000,134.920000000,620,11,3,2,134.410000000,134.950000000,61,400,2,1,134.380000000,134.970000000,18,100,1,1,134.210000000,134.990000000,20,10,1,1,134.200000000,135.000000000,3,38,1,3,134.180000000,135.100000000,50,10,1,1,134.090000000,135.230000000,8,360,1,1,NVDA
2024-11-01T08:00:16.885004966Z,2024-11-01T08:00:16.884837350Z,10,2,11667,T,A,0,134.800000000,7,128,167616,327367,134.800000000,134.880000000,122,100,1,1,134.750000000,134.900000000,500,400,1,2,134.610000000,134.910000000,750,100,1,1,134.500000000,134.920000000,620,11,3,2,134.410000000,134.950000000,61,400,2,1,134.380000000,134.970000000,18,100,1,1,134.210000000,134.990000000,20,10,1,1,134.200000000,135.000000000,3,38,1,3,134.180000000,135.100000000,50,10,1,1,134.090000000,135.230000000,8,360,1,1,NVDA
2024-11-01T08:00:16.885004966Z,2024-11-01T08:00:16.884837350Z,10,2,11667,C,B,0,134.800000000,7,128,167616,327367,134.800000000,134.880000000,115,100,1,1,134.750000000,134.900000000,500,400,1,2,134.610000000,134.910000000,750,100,1,1,134.500000000,134.920000000,620,11,3,2,134.410000000,134.950000000,61,400,2,1,134.380000000,134.970000000,18,100,1,1,134.210000000,134.990000000,20,10,1,1,134.200000000,135.000000000,3,38,1,3,134.180000000,135.100000000,50,10,1,1,134.090000000,135.230000000,8,360,1,1,NVDA
2024-11-01T08:00:16.885179256Z,2024-11-01T08:00:16.885011824Z,10,2,11667,T,A,0,134.800000000,1,130,167432,327370,134.800000000,134.880000000,115,100,1,1,134.750000000,134.900000000,500,400,1,2,134.610000000,134.910000000,750,100,1,1,134.500000000,134.920000000,620,11,3,2,134.410000000,134.950000000,61,400,2,1,134.380000000,134.970000000,18,100,1,1,134.210000000,134.990000000,20,10,1,1,134.200000000,135.000000000,3,38,1,3,134.180000000,135.100000000,50,10,1,1,134.090000000,135.230000000,8,360,1,1,NVDA
