{"ts_recv":"2024-11-01T08:00:12.311481300Z","hd":{"ts_event":"2024-11-01T08:00:12.311314874Z","rtype":10,"publisher_id":2,"instrument_id":16244},"action":"A","side":"A","depth":1,"price":"251.490000000","size":100,"flags":130,"ts_in_delta":166426,"sequence":315377,"levels":[{"bid_px":"250.170000000","ask_px":"251.150000000","bid_sz":100,"ask_sz":100,"bid_ct":1,"ask_ct":1},{"bid_px":"250.000000000","ask_px":"251.490000000","bid_sz":2,"ask_sz":100,"bid_ct":2,"ask_ct":1},{"bid_px":"249.930000000","ask_px":"252.400000000","bid_sz":10,"ask_sz":1000,"bid_ct":1,"ask_ct":1},{"bid_px":"249.880000000","ask_px":"253.650000000","bid_sz":4,"ask_sz":400,"bid_ct":1,"ask_ct":1},{"bid_px":"249.800000000","ask_px":"255.000000000","bid_sz":199,"ask_sz":85,"bid_ct":1,"ask_ct":2},{"bid_px":"249.770000000","ask_px":"260.000000000","bid_sz":50,"ask_sz":168,"bid_ct":1,"ask_ct":3},{"bid_px":"249.400000000","ask_px":"262.660000000","bid_sz":1000,"ask_sz":56,"bid_ct":1,"ask_ct":1},{"bid_px":"248.500000000","ask_px":"264.940000000","bid_sz":40,"ask_sz":7,"bid_ct":1,"ask_ct":1},{"bid_px":"247.150000000","ask_px":"265.000000000","bid_sz":400,"ask_sz":102,"bid_ct":1,"ask_ct":3},{"bid_px":"247.000000000","ask_px":"267.800000000","bid_sz":12,"ask_sz":30,"bid_ct":1,"ask_ct":1}],"symbol":"TSLA"}
{"ts_recv":"2024-11-01T08:00:12.330113236Z","hd":{"ts_event":"2024-11-01T08:00:12.329946593Z","rtype":10,"publisher_id":2,"instrument_id":16244},"action":"A","side":"A","depth":0,"price":"251.150000000","size":50,"flags":130,"ts_in_delta":166643,"sequence":315397,"levels":[{"bid_px":"250.170000000","ask_px":"251.150000000","bid_sz":100,"ask_sz":150,"bid_ct":1,"ask_ct":2},{"bid_px":"250.000000000","ask_px":"252.400000000","bid_sz":2,"ask_sz":1000,"bid_ct":2,"ask_ct":1},{"bid_px":"249.930000000","ask_px":"253.650000000","bid_sz":10,"ask_sz":400,"bid_ct":1,"ask_ct":1},{"bid_px":"249.880000000","ask_px":"255.000000000","bid_sz":4,"ask_sz":85,"bid_ct":1,"ask_ct":2},{"bid_px":"249.800000000","ask_px":"260.000000000","bid_sz":199,"ask_sz":168,"bid_ct":1,"ask_ct":3},{"bid_px":"249.770000000","ask_px":"262.660000000","bid_sz":50,"ask_sz":56,"bid_ct":1,"ask_ct":1},{"bid_px":"249.400000000","ask_px":"264.940000000","bid_sz":1000,"ask_sz":7,"bid_ct":1,"ask_ct":1},{"bid_px":"248.500000000","ask_px":"265.000000000","bid_sz":40,"ask_sz":102,"bid_ct":1,"ask_ct":3},{"bid_px":"247.150000000","ask_px":"267.800000000","bid_sz":400,"ask_sz":30,"bid_ct":1,"ask_ct":1},{"bid_px":"247.000000000","ask_px":"268.670000000","bid_sz":12,"ask_sz":100,"bid_ct":1,"ask_ct":1}],"symbol":"TSLA"}
{"ts_recv":"2024-11-01T08:00:12.368542254Z","hd":{"ts_event":"2024-11-01T08:00:12.368375429Z","rtype":10,"publisher_id":2,"instrument_id":11667},"action":"A","side":"A","depth":8,"price":"135.910000000","size":100,"flags":130,"ts_in_delta":166825,"sequence":315427,"levels":[{"bid_px":"134.680000000","ask_px":"134.990000000","bid_sz":100,"ask_sz":10,"bid_ct":1,"ask_ct":1},{"bid_px":"134.500000000","ask_px":"135.000000000","bid_sz":520,"ask_sz":38,"bid_ct":2,"ask_ct":3},{"bid_px":"134.410000000","ask_px":"135.100000000","bid_sz":61,"ask_sz":10,"bid_ct":2,"ask_ct":1},{"bid_px":"134.380000000","ask_px":"135.230000000","bid_sz":18,"ask_sz":360,"bid_ct":1,"ask_ct":1},{"bid_px":"134.210000000","ask_px":"135.300000000","bid_sz":20,"ask_sz":1000,"bid_ct":1,"ask_ct":1},{"bid_px":"134.200000000","ask_px":"135.400000000","bid_sz":3,"ask_sz":10,"bid_ct":1,"ask_ct":1},{"bid_px":"134.000000000","ask_px":"135.420000000","bid_sz":1,"ask_sz":1,"bid_ct":1,"ask_ct":1},{"bid_px":"133.800000000","ask_px":"135.820000000","bid_sz":5,"ask_sz":1,"bid_ct":1,"ask_ct":1},{"bid_px":"133.160000000","ask_px":"135.910000000","bid_sz":1,"ask_sz":100,"bid_ct":1,"ask_ct":1},{"bid_px":"132.800000000","ask_px":"135.990000000","bid_sz":89,"ask_sz":20,"bid_ct":1,"ask_ct":1}],"symbol":"NVDA"}
{"ts_recv":"2024-11-01T08:00:12.435561320Z","hd":{"ts_event":"2024-11-01T08:00:12.435395133Z","rtype":10,"publisher_id":2,"instrument_id":10888},"action":"A","side":"B","depth":5,"price":"409.000000000","size":1,"flags":130,"ts_in_delta":166187,"sequence":315488,"levels":[{"bid_px":"410.000000000","ask_px":"414.000000000","bid_sz":1,"ask_sz":468,"bid_ct":1,"ask_ct":2},{"bid_px":"409.750000000","ask_px":"415.070000000","bid_sz":3,"ask_sz":246,"bid_ct":1,"ask_ct":1},{"bid_px":"409.670000000","ask_px":"415.350000000","bid_sz":100,"ask_sz":84,"bid_ct":1,"ask_ct":2},{"bid_px":"409.430000000","ask_px":"420.000000000","bid_sz":5,"ask_sz":3,"bid_ct":1,"ask_ct":1},{"bid_px":"409.080000000","ask_px":"440.000000000","bid_sz":2,"ask_sz":35,"bid_ct":1,"ask_ct":1},{"bid_px":"409.000000000","ask_px":"445.000000000","bid_sz":3,"ask_sz":25,"bid_ct":2,"ask_ct":1},{"bid_px":"408.970000000","ask_px":"445.680000000","bid_sz":12,"ask_sz":3,"bid_ct":1,"ask_ct":1},{"bid_px":"408.960000000","ask_px":"448.000000000","bid_sz":5,"ask_sz":15,"bid_ct":1,"ask_ct":2},{"bid_px":"408.000000000","ask_px":"450.000000000","bid_sz":7,"ask_sz":12,"bid_ct":1,"ask_ct":2},{"bid_px":"407.600000000","ask_px":"455.000000000","bid_sz":16,"ask_sz":5,"bid_ct":1,"ask_ct":1}],"symbol":"MSFT"}
{"ts_recv":"2024-11-01T08:00:12.442102550Z","hd":{"ts_event":"2024-11-01T08:00:12.441936488Z","rtype":10,"publisher_id":2,"instrument_id":16727},"action":"A","side":"A","depth":0,"price":"300.000000000","size":1,"flags":130,"ts_in_delta":166062,"sequence":315491,"levels":[{"bid_px":null,"ask_px":"300.000000000","bid_sz":0,"ask_sz":1,"bid_ct":0,"ask_ct":1},{"bid_px":null,"ask_px":"305.000000000","bid_sz":0,"ask_sz":1,"bid_ct":0,"ask_ct":1},{"bid_px":null,"ask_px":null,"bid_sz":0,"ask_sz":0,"bid_ct":0,"ask_ct":0},{"bid_px":null,"ask_px":null,"bid_sz":0,"ask_sz":0,"bid_ct":0,"ask_ct":0},{"bid_px":null,"ask_px":null,"bid_sz":0,"ask_sz":0,"bid_ct":0,"ask_ct":0},{"bid_px":null,"ask_px":null,"bid_sz":0,"ask_sz":0,"bid_ct":0,"ask_ct":0},{"bid_px":null,"ask_px":null,"bid_sz":0,"ask_sz":0,"bid_ct":0,"ask_ct":0},{"bid_px":null,"ask_px":null,"bid_sz":0,"ask_sz":0,"bid_ct":0,"ask_ct":0},{"bid_px":null,"ask_px":null,"bid_sz":0,"ask_sz":0,"bid_ct":0,"ask_ct":0},{"bid_px":null,"ask_px":null,"bid_sz":0,"ask_sz":0,"bid_ct":0,"ask_ct":0}],"symbol":"V"}
{"ts_recv":"2024-11-01T08:00:12.468992768Z","hd":{"ts_event":"2024-11-01T08:00:12.468826138Z","rtype":10,"publisher_id":2,"instrument_id":12463},"action":"A","side":"B","depth":0,"price":"163.890000000","size":100,"flags":130,"ts_in_delta":166630,"sequence":315560,"levels":[{"bid_px":"163.890000000","ask_px":"171.810000000","bid_sz":100,"ask_sz":100,"bid_ct":1,"ask_ct":1},{"bid_px":null,"ask_px":"180.000000000","bid_sz":0,"ask_sz":20,"bid_ct":0,"ask_ct":1},{"bid_px":null,"ask_px":null,"bid_sz":0,"ask_sz":0,"bid_ct":0,"ask_ct":0},{"bid_px":null,"ask_px":null,"bid_sz":0,"ask_sz":0,"bid_ct":0,"ask_ct":0},{"bid_px":null,"ask_px":null,"bid_sz":0,"ask_sz":0,"bid_ct":0,"ask_ct":0},{"bid_px":null,"ask_px":null,"bid_sz":0,"ask_sz":0,"bid_ct":0,"ask_ct":0},{"bid_px":null,"ask_px":null,"bid_sz":0,"ask_sz":0,"bid_ct":0,"ask_ct":0},{"bid_px":null,"ask_px":null,"bid_sz":0,"ask_sz":0,"bid_ct":0,"ask_ct":0},{"bid_px":null,"ask_px":null,"bid_sz":0,"ask_sz":0,"bid_ct":0,"ask_ct":0},{"bid_px":null,"ask_px":null,"bid_sz":0,"ask_sz":0,"bid_ct":0,"ask_ct":0}],"symbol":"PEP"}
{"ts_recv":"2024-11-01T08:00:12.521061332Z","hd":{"ts_event":"2024-11-01T08:00:12.520894841Z","rtype":10,"publisher_id":2,"instrument_id":16244},"action":"A","side":"A","depth":0,"price":"251.150000000","size":50,"flags":130,"ts_in_delta":166491,"sequence":315732,"levels":[{"bid_px":"250.170000000","ask_px":"251.150000000","bid_sz":100,"ask_sz":200,"bid_ct":1,"ask_ct":3},{"bid_px":"250.000000000","ask_px":"252.400000000","bid_sz":2,"ask_sz":1000,"bid_ct":2,"ask_ct":1},{"bid_px":"249.930000000","ask_px":"253.650000000","bid_sz":10,"ask_sz":400,"bid_ct":1,"ask_ct":1},{"bid_px":"249.880000000","ask_px":"255.000000000","bid_sz":4,"ask_sz":85,"bid_ct":1,"ask_ct":2},{"bid_px":"249.800000000","ask_px":"260.000000000","bid_sz":199,"ask_sz":168,"bid_ct":1,"ask_ct":3},{"bid_px":"249.770000000","ask_px":"262.660000000","bid_sz":50,"ask_sz":56,"bid_ct":1,"ask_ct":1},{"bid_px":"249.400000000","ask_px":"264.940000000","bid_sz":1000,"ask_sz":7,"bid_ct":1,"ask_ct":1},{"bid_px":"248.500000000","ask_px":"265.000000000","bid_sz":40,"ask_sz":102,"bid_ct":1,"ask_ct":3},{"bid_px":"247.150000000","ask_px":"267.800000000","bid_sz":400,"ask_sz":30,"bid_ct":1,"ask_ct":1},{"bid_px":"247.000000000","ask_px":"268.670000000","bid_sz":12,"ask_sz":100,"bid_ct":1,"ask_ct":1}],"symbol":"TSLA"}
{"ts_recv":"2024-11-01T08:00:12.547354063Z","hd":{"ts_event":"2024-11-01T08:00:12.547187209Z","rtype":10,"publisher_id":2,"instrument_id":12463},"action":"A","side":"B","depth":0,"price":"163.980000000","size":100,"flags":130,"ts_in_delta":166854,"sequence":315777,"levels":[{"bid_px":"163.980000000","ask_px":"171.810000000","bid_sz":100,"ask_sz":100,"bid_ct":1,"ask_ct":1},{"bid_px":null,"ask_px":"180.000000000","bid_sz":0,"ask_sz":20,"bid_ct":0,"ask_ct":1},{"bid_px":null,"ask_px":null,"bid_sz":0,"ask_sz":0,"bid_ct":0,"ask_ct":0},{"bid_px":null,"ask_px":null,"bid_sz":0,"ask_sz":0,"bid_ct":0,"ask_ct":0},{"bid_px":null,"ask_px":null,"bid_sz":0,"ask_sz":0,"bid_ct":0,"ask_ct":0},{"bid_px":null,"ask_px":null,"bid_sz":0,"ask_sz":0,"bid_ct":0,"ask_ct":0},{"bid_px":null,"ask_px":null,"bid_sz":0,"ask_sz":0,"bid_ct":0,"ask_ct":0},{"bid_px":null,"ask_px":null,"bid_sz":0,"ask_sz":0,"bid_ct":0,"ask_ct":0},{"bid_px":null,"ask_px":null,"bid_sz":0,"ask_sz":0,"bid_ct":0,"ask_ct":0},{"bid_px":null,"ask_px":null,"bid_sz":0,"ask_sz":0,"bid_ct":0,"ask_ct":0}],"symbol":"PEP"}
{"ts_recv":"2024-11-01T08:00:12.582573885Z","hd":{"ts_event":"2024-11-01T08:00:12.582407140Z","rtype":10,"publisher_id":2,"instrument_id":10888},"action":"A","side":"B","depth":4,"price":"409.250000000","size":2,"flags":130,"ts_in_delta":166745,"sequence":315826,"levels":[{"bid_px":"410.000000000","ask_px":"414.000000000","bid_sz":1,"ask_sz":468,"bid_ct":1,"ask_ct":2},{"bid_px":"409.750000000","ask_px":"415.070000000","bid_sz":3,"ask_sz":246,"bid_ct":1,"ask_ct":1},{"bid_px":"409.670000000","ask_px":"415.350000000","bid_sz":100,"ask_sz":84,"bid_ct":1,"ask_ct":2},{"bid_px":"409.430000000","ask_px":"420.000000000","bid_sz":5,"ask_sz":3,"bid_ct":1,"ask_ct":1},{"bid_px":"409.250000000","ask_px":"440.000000000","bid_sz":2,"ask_sz":35,"bid_ct":1,"ask_ct":1},{"bid_px":"409.080000000","ask_px":"445.000000000","bid_sz":2,"ask_sz":25,"bid_ct":1,"ask_ct":1},{"bid_px":"409.000000000","ask_px":"445.680000000","bid_sz":3,"ask_sz":3,"bid_ct":2,"ask_ct":1},{"bid_px":"408.970000000","ask_px":"448.000000000","bid_sz":12,"ask_sz":15,"bid_ct":1,"ask_ct":2},{"bid_px":"408.960000000","ask_px":"450.000000000","bid_sz":5,"ask_sz":12,"bid_ct":1,"ask_ct":2},{"bid_px":"408.000000000","ask_px":"455.000000000","bid_sz":7,"ask_sz":5,"bid_ct":1,"ask_ct":1}],"symbol":"MSFT"}
{"ts_recv":"2024-11-01T08:00:12.582863368Z","hd":{"ts_event":"2024-11-01T08:00:12.582697080Z","rtype":10,"publisher_id":2,"instrument_id":10888},"action":"A","side":"B","depth":2,"price":"409.740000000","size":500,"flags":130,"ts_in_delta":166288,"sequence":315830,"levels":[{"bid_px":"410.000000000","ask_px":"414.000000000","bid_sz":1,"ask_sz":468,"bid_ct":1,"ask_ct":2},{"bid_px":"409.750000000","ask_px":"415.070000000","bid_sz":3,"ask_sz":246,"bid_ct":1,"ask_ct":1},{"bid_px":"409.740000000","ask_px":"415.350000000","bid_sz":500,"ask_sz":84,"bid_ct":1,"ask_ct":2},{"bid_px":"409.670000000","ask_px":"420.000000000","bid_sz":100,"ask_sz":3,"bid_ct":1,"ask_ct":1},{"bid_px":"409.430000000","ask_px":"440.000000000","bid_sz":5,"ask_sz":35,"bid_ct":1,"ask_ct":1},{"bid_px":"409.250000000","ask_px":"445.000000000","bid_sz":2,"ask_sz":25,"bid_ct":1,"ask_ct":1},{"bid_px":"409.080000000","ask_px":"445.680000000","bid_sz":2,"ask_sz":3,"bid_ct":1,"ask_ct":1},{"bid_px":"409.000000000","ask_px":"448.000000000","bid_sz":3,"ask_sz":15,"bid_ct":2,"ask_ct":2},{"bid_px":"408.970000000","ask_px":"450.000000000","bid_sz":12,"ask_sz":12,"bid_ct":1,"ask_ct":2},{"bid_px":"408.960000000","ask_px":"455.000000000","bid_sz":5,"ask_sz":5,"bid_ct":1,"ask_ct":1}],"symbol":"MSFT"}
{"ts_recv":"2024-11-01T08:00:12.689662015Z","hd":{"ts_event":"2024-11-01T08:00:12.689495698Z","rtype":10,"publisher_id":2,"instrument_id":16244},"action":"A","side":"A","depth":0,"price":"250.770000000","size":6,"flags":130,"ts_in_delta":166317,"sequence":315982,"levels":[{"bid_px":"250.170000000","ask_px":"250.770000000","bid_sz":100,"ask_sz":6,"bid_ct":1,"ask_ct":1},{"bid_px":"250.000000000","ask_px":"251.150000000","bid_sz":2,"ask_sz":200,"bid_ct":2,"ask_ct":3},{"bid_px":"249.930000000","ask_px":"252.400000000","bid_sz":10,"ask_sz":1000,"bid_ct":1,"ask_ct":1},{"bid_px":"249.880000000","ask_px":"253.650000000","bid_sz":4,"ask_sz":400,"bid_ct":1,"ask_ct":1},{"bid_px":"249.800000000","ask_px":"255.000000000","bid_sz":199,"ask_sz":85,"bid_ct":1,"ask_ct":2},{"bid_px":"249.770000000","ask_px":"260.000000000","bid_sz":50,"ask_sz":168,"bid_ct":1,"ask_ct":3},{"bid_px":"249.400000000","ask_px":"262.660000000","bid_sz":1000,"ask_sz":56,"bid_ct":1,"ask_ct":1},{"bid_px":"248.500000000","ask_px":"264.940000000","bid_sz":40,"ask_sz":7,"bid_ct":1,"ask_ct":1},{"bid_px":"247.150000000","ask_px":"265.000000000","bid_sz":400,"ask_sz":102,"bid_ct":1,"ask_ct":3},{"bid_px":"247.000000000","ask_px":"267.800000000","bid_sz":12,"ask_sz":30,"bid_ct":1,"ask_ct":1}],"symbol":"TSLA"}
{"ts_recv":"2024-11-01T08:00:12.722939114Z","hd":{"ts_event":"2024-11-01T08:00:12.722773182Z","rtype":10,"publisher_id":2,"instrument_id":16244},"action":"C","side":"A","depth":1,"price":"251.150000000","size":50,"flags":130,"ts_in_delta":165932,"sequence":316000,"levels":[{"bid_px":"250.170000000","ask_px":"250.770000000","bid_sz":100,"ask_sz":6,"bid_ct":1,"ask_ct":1},{"bid_px":"250.000000000","ask_px":"251.150000000","bid_sz":2,"ask_sz":150,"bid_ct":2,"ask_ct":2},{"bid_px":"249.930000000","ask_px":"252.400000000","bid_sz":10,"ask_sz":1000,"bid_ct":1,"ask_ct":1},{"bid_px":"249.880000000","ask_px":"253.650000000","bid_sz":4,"ask_sz":400,"bid_ct":1,"ask_ct":1},{"bid_px":"249.800000000","ask_px":"255.000000000","bid_sz":199,"ask_sz":85,"bid_ct":1,"ask_ct":2},{"bid_px":"249.770000000","ask_px":"260.000000000","bid_sz":50,"ask_sz":168,"bid_ct":1,"ask_ct":3},{"bid_px":"249.400000000","ask_px":"262.660000000","bid_sz":1000,"ask_sz":56,"bid_ct":1,"ask_ct":1},{"bid_px":"248.500000000","ask_px":"264.940000000","bid_sz":40,"ask_sz":7,"bid_ct":1,"ask_ct":1},{"bid_px":"247.150000000","ask_px":"265.000000000","bid_sz":400,"ask_sz":102,"bid_ct":1,"ask_ct":3},{"bid_px":"247.000000000","ask_px":"267.800000000","bid_sz":12,"ask_sz":30,"bid_ct":1,"ask_ct":1}],"symbol":"TSLA"}
{"ts_recv":"2024-11-01T08:00:12.722953136Z","hd":{"ts_event":"2024-11-01T08:00:12.722786957Z","rtype":10,"publisher_id":2,"instrument_id":16244},"action":"A","side":"A","depth":1,"price":"251.140000000","size":50,"flags":130,"ts_in_delta":166179,"sequence":316001,"levels":[{"bid_px":"250.170000000","ask_px":"250.770000000","bid_sz":100,"ask_sz":6,"bid_ct":1,"ask_ct":1},{"bid_px":"250.000000000","ask_px":"251.140000000","bid_sz":2,"ask_sz":50,"bid_ct":2,"ask_ct":1},{"bid_px":"249.930000000","ask_px":"251.150000000","bid_sz":10,"ask_sz":100,"bid_ct":1,"ask_ct":1},{"bid_px":"249.880000000","ask_px":"252.400000000","bid_sz":4,"ask_sz":1000,"bid_ct":1,"ask_ct":1},{"bid_px":"249.800000000","ask_px":"253.650000000","bid_sz":199,"ask_sz":400,"bid_ct":1,"ask_ct":1},{"bid_px":"249.770000000","ask_px":"255.000000000","bid_sz":50,"ask_sz":85,"bid_ct":1,"ask_ct":2},{"bid_px":"249.400000000","ask_px":"260.000000000","bid_sz":1000,"ask_sz":168,"bid_ct":1,"ask_ct":3},{"bid_px":"248.500000000","ask_px":"262.660000000","bid_sz":40,"ask_sz":56,"bid_ct":1,"ask_ct":1},{"bid_px":"247.150000000","ask_px":"264.940000000","bid_sz":400,"ask_sz":7,"bid_ct":1,"ask_ct":1},{"bid_px":"247.000000000","ask_px":"265.000000000","bid_sz":12,"ask_sz":102,"bid_ct":1,"ask_ct":3}],"symbol":"TSLA"}
{"ts_recv":"2024-11-01T08:00:12.723026482Z","hd":{"ts_event":"2024-11-01T08:00:12.722860394Z","rtype":10,"publisher_id":2,"instrument_id":16244},"action":"C","side":"B","depth":0,"price":"250.170000000","size":50,"flags":130,"ts_in_delta":166088,"sequence":316002,"levels":[{"bid_px":"250.170000000","ask_px":"250.770000000","bid_sz":50,"ask_sz":6,"bid_ct":1,"ask_ct":1},{"bid_px":"250.000000000","ask_px":"251.140000000","bid_sz":2,"ask_sz":50,"bid_ct":2,"ask_ct":1},{"bid_px":"249.930000000","ask_px":"251.150000000","bid_sz":10,"ask_sz":100,"bid_ct":1,"ask_ct":1},{"bid_px":"249.880000000","ask_px":"252.400000000","bid_sz":4,"ask_sz":1000,"bid_ct":1,"ask_ct":1},{"bid_px":"249.800000000","ask_px":"253.650000000","bid_sz":199,"ask_sz":400,"bid_ct":1,"ask_ct":1},{"bid_px":"249.770000000","ask_px":"255.000000000","bid_sz":50,"ask_sz":85,"bid_ct":1,"ask_ct":2},{"bid_px":"249.400000000","ask_px":"260.000000000","bid_sz":1000,"ask_sz":168,"bid_ct":1,"ask_ct":3},{"bid_px":"248.500000000","ask_px":"262.660000000","bid_sz":40,"ask_sz":56,"bid_ct":1,"ask_ct":1},{"bid_px":"247.150000000","ask_px":"264.940000000","bid_sz":400,"ask_sz":7,"bid_ct":1,"ask_ct":1},{"bid_px":"247.000000000","ask_px":"265.000000000","bid_sz":12,"ask_sz":102,"bid_ct":1,"ask_ct":3}],"symbol":"TSLA"}
{"ts_recv":"2024-11-01T08:00:12.757295078Z","hd":{"ts_event":"2024-11-01T08:00:12.757129388Z","rtype":10,"publisher_id":2,"instrument_id":11667},"action":"C","side":"B","depth":0,"price":"134.680000000","size":100,"flags":130,"ts_in_delta":165690,"sequence":316076,"levels":[{"bid_px":"134.500000000","ask_px":"134.990000000","bid_sz":520,"ask_sz":10,"bid_ct":2,"ask_ct":1},{"bid_px":"134.410000000","ask_px":"135.000000000","bid_sz":61,"ask_sz":38,"bid_ct":2,"ask_ct":3},{"bid_px":"134.380000000","ask_px":"135.100000000","bid_sz":18,"ask_sz":10,"bid_ct":1,"ask_ct":1},{"bid_px":"134.210000000","ask_px":"135.230000000","bid_sz":20,"ask_sz":360,"bid_ct":1,"ask_ct":1},{"bid_px":"134.200000000","ask_px":"135.300000000","bid_sz":3,"ask_sz":1000,"bid_ct":1,"ask_ct":1},{"bid_px":"134.000000000","ask_px":"135.400000000","bid_sz":1,"ask_sz":10,"bid_ct":1,"ask_ct":1},{"bid_px":"133.800000000","ask_px":"135.420000000","bid_sz":5,"ask_sz":1,"bid_ct":1,"ask_ct":1},{"bid_px":"133.160000000","ask_px":"135.820000000","bid_sz":1,"ask_sz":1,"bid_ct":1,"ask_ct":1},{"bid_px":"132.800000000","ask_px":"135.910000000","bid_sz":89,"ask_sz":100,"bid_ct":1,"ask_ct":1},{"bid_px":"132.760000000","ask_px":"135.990000000","bid_sz":104,"ask_sz":20,"bid_ct":2,"ask_ct":1}],"symbol":"NVDA"}
{"ts_recv":"2024-11-01T08:00:12.757309141Z","hd":{"ts_event":"2024-11-01T08:00:12.757143145Z","rtype":10,"publisher_id":2,"instrument_id":11667},"action":"A","side":"B","depth":1,"price":"134.410000000","size":100,"flags":130,"ts_in_delta":165996,"sequence":316077,"levels":[{"bid_px":"134.500000000","ask_px":"134.990000000","bid_sz":520,"ask_sz":10,"bid_ct":2,"ask_ct":1},{"bid_px":"134.410000000","ask_px":"135.000000000","bid_sz":161,"ask_sz":38,"bid_ct":3,"ask_ct":3},{"bid_px":"134.380000000","ask_px":"135.100000000","bid_sz":18,"ask_sz":10,"bid_ct":1,"ask_ct":1},{"bid_px":"134.210000000","ask_px":"135.230000000","bid_sz":20,"ask_sz":360,"bid_ct":1,"ask_ct":1},{"bid_px":"134.200000000","ask_px":"135.300000000","bid_sz":3,"ask_sz":1000,"bid_ct":1,"ask_ct":1},{"bid_px":"134.000000000","ask_px":"135.400000000","bid_sz":1,"ask_sz":10,"bid_ct":1,"ask_ct":1},{"bid_px":"133.800000000","ask_px":"135.420000000","bid_sz":5,"ask_sz":1,"bid_ct":1,"ask_ct":1},{"bid_px":"133.160000000","ask_px":"135.820000000","bid_sz":1,"ask_sz":1,"bid_ct":1,"ask_ct":1},{"bid_px":"132.800000000","ask_px":"135.910000000","bid_sz":89,"ask_sz":100,"bid_ct":1,"ask_ct":1},{"bid_px":"132.760000000","ask_px":"135.990000000","bid_sz":104,"ask_sz":20,"bid_ct":2,"ask_ct":1}],"symbol":"NVDA"}
{"ts_recv":"2024-11-01T08:00:12.776818250Z","hd":{"ts_event":"2024-11-01T08:00:12.776652057Z","rtype":10,"publisher_id":2,"instrument_id":11667},"action":"A","side":"A","depth":8,"price":"135.900000000","size":1000,"flags":130,"ts_in_delta":166193,"sequence":316130,"levels":[{"bid_px":"134.500000000","ask_px":"134.990000000","bid_sz":520,"ask_sz":10,"bid_ct":2,"ask_ct":1},{"bid_px":"134.410000000","ask_px":"135.000000000","bid_sz":161,"ask_sz":38,"bid_ct":3,"ask_ct":3},{"bid_px":"134.380000000","ask_px":"135.100000000","bid_sz":18,"ask_sz":10,"bid_ct":1,"ask_ct":1},{"bid_px":"134.210000000","ask_px":"135.230000000","bid_sz":20,"ask_sz":360,"bid_ct":1,"ask_ct":1},{"bid_px":"134.200000000","ask_px":"135.300000000","bid_sz":3,"ask_sz":1000,"bid_ct":1,"ask_ct":1},{"bid_px":"134.000000000","ask_px":"135.400000000","bid_sz":1,"ask_sz":10,"bid_ct":1,"ask_ct":1},{"bid_px":"133.800000000","ask_px":"135.420000000","bid_sz":5,"ask_sz":1,"bid_ct":1,"ask_ct":1},{"bid_px":"133.160000000","ask_px":"135.820000000","bid_sz":1,"ask_sz":1,"bid_ct":1,"ask_ct":1},{"bid_px":"132.800000000","ask_px":"135.900000000","bid_sz":89,"ask_sz":1000,"bid_ct":1,"ask_ct":1},{"bid_px":"132.760000000","ask_px":"135.910000000","bid_sz":104,"ask_sz":100,"bid_ct":2,"ask_ct":1}],"symbol":"NVDA"}
{"ts_recv":"2024-11-01T08:00:12.779810661Z","hd":{"ts_event":"2024-11-01T08:00:12.779644967Z","rtype":10,"publisher_id":2,"instrument_id":11667},"action":"C","side":"A","depth":8,"price":"135.900000000","size":1000,"flags":130,"ts_in_delta":165694,"sequence":316151,"levels":[{"bid_px":"134.500000000","ask_px":"134.990000000","bid_sz":520,"ask_sz":10,"bid_ct":2,"ask_ct":1},{"bid_px":"134.410000000","ask_px":"135.000000000","bid_sz":161,"ask_sz":38,"bid_ct":3,"ask_ct":3},{"bid_px":"134.380000000","ask_px":"135.100000000","bid_sz":18,"ask_sz":10,"bid_ct":1,"ask_ct":1},{"bid_px":"134.210000000","ask_px":"135.230000000","bid_sz":20,"ask_sz":360,"bid_ct":1,"ask_ct":1},{"bid_px":"134.200000000","ask_px":"135.300000000","bid_sz":3,"ask_sz":1000,"bid_ct":1,"ask_ct":1},{"bid_px":"134.000000000","ask_px":"135.400000000","bid_sz":1,"ask_sz":10,"bid_ct":1,"ask_ct":1},{"bid_px":"133.800000000","ask_px":"135.420000000","bid_sz":5,"ask_sz":1,"bid_ct":1,"ask_ct":1},{"bid_px":"133.160000000","ask_px":"135.820000000","bid_sz":1,"ask_sz":1,"bid_ct":1,"ask_ct":1},{"bid_px":"132.800000000","ask_px":"135.910000000","bid_sz":89,"ask_sz":100,"bid_ct":1,"ask_ct":1},{"bid_px":"132.760000000","ask_px":"135.990000000","bid_sz":104,"ask_sz":20,"bid_ct":2,"ask_ct":1}],"symbol":"NVDA"}
{"ts_recv":"2024-11-01T08:00:12.798582176Z","hd":{"ts_event":"2024-11-01T08:00:12.798415686Z","rtype":10,"publisher_id":2,"instrument_id":16727},"action":"A","side":"B","depth":0,"price":"268.000000000","size":25,"flags":130,"ts_in_delta":166490,"sequence":316182,"levels":[{"bid_px":"268.000000000","ask_px":"300.000000000","bid_sz":25,"ask_sz":1,"bid_ct":1,"ask_ct":1},{"bid_px":null,"ask_px":"305.000000000","bid_sz":0,"ask_sz":1,"bid_ct":0,"ask_ct":1},{"bid_px":null,"ask_px":null,"bid_sz":0,"ask_sz":0,"bid_ct":0,"ask_ct":0},{"bid_px":null,"ask_px":null,"bid_sz":0,"ask_sz":0,"bid_ct":0,"ask_ct":0},{"bid_px":null,"ask_px":null,"bid_sz":0,"ask_sz":0,"bid_ct":0,"ask_ct":0},{"bid_px":null,"ask_px":null,"bid_sz":0,"ask_sz":0,"bid_ct":0,"ask_ct":0},{"bid_px":null,"ask_px":null,"bid_sz":0,"ask_sz":0,"bid_ct":0,"ask_ct":0},{"bid_px":null,"ask_px":null,"bid_sz":0,"ask_sz":0,"bid_ct":0,"ask_ct":0},{"bid_px":null,"ask_px":null,"bid_sz":0,"ask_sz":0,"bid_ct":0,"ask_ct":0},{"bid_px":null,"ask_px":null,"bid_sz":0,"ask_sz":0,"bid_ct":0,"ask_ct":0}],"symbol":"V"}
{"ts_recv":"2024-11-01T08:00:12.857072659Z","hd":{"ts_event":"2024-11-01T08:00:12.856906453Z","rtype":10,"publisher_id":2,"instrument_id":11667},"action":"A","side":"B","depth":1,"price":"134.440000000","size":100,"flags":130,"ts_in_delta":166206,"sequence":316275,"levels":[{"bid_px":"134.500000000","ask_px":"134.990000000","bid_sz":520,"ask_sz":10,"bid_ct":2,"ask_ct":1},{"bid_px":"134.440000000","ask_px":"135.000000000","bid_sz":100,"ask_sz":38,"bid_ct":1,"ask_ct":3},{"bid_px":"134.410000000","ask_px":"135.100000000","bid_sz":61,"ask_sz":10,"bid_ct":2,"ask_ct":1},{"bid_px":"134.380000000","ask_px":"135.230000000","bid_sz":18,"ask_sz":360,"bid_ct":1,"ask_ct":1},{"bid_px":"134.210000000","ask_px":"135.300000000","bid_sz":20,"ask_sz":1000,"bid_ct":1,"ask_ct":1},{"bid_px":"134.200000000","ask_px":"135.400000000","bid_sz":3,"ask_sz":10,"bid_ct":1,"ask_ct":1},{"bid_px":"134.000000000","ask_px":"135.420000000","bid_sz":1,"ask_sz":1,"bid_ct":1,"ask_ct":1},{"bid_px":"133.800000000","ask_px":"135.820000000","bid_sz":5,"ask_sz":1,"bid_ct":1,"ask_ct":1},{"bid_px":"133.160000000","ask_px":"135.910000000","bid_sz":1,"ask_sz":100,"bid_ct":1,"ask_ct":1},{"bid_px":"132.800000000","ask_px":"135.990000000","bid_sz":89,"ask_sz":20,"bid_ct":1,"ask_ct":1}],"symbol":"NVDA"}
{"ts_recv":"2024-11-01T08:00:12.923864319Z","hd":{"ts_event":"2024-11-01T08:00:12.923698300Z","rtype":10,"publisher_id":2,"instrument_id":16244},"action":"A","side":"A","depth":4,"price":"253.350000000","size":23,"flags":130,"ts_in_delta":166019,"sequence":316503,"levels":[{"bid_px":"250.170000000","ask_px":"250.770000000","bid_sz":50,"ask_sz":6,"bid_ct":1,"ask_ct":1},{"bid_px":"250.000000000","ask_px":"251.140000000","bid_sz":2,"ask_sz":50,"bid_ct":2,"ask_ct":1},{"bid_px":"249.930000000","ask_px":"251.150000000","bid_sz":10,"ask_sz":100,"bid_ct":1,"ask_ct":1},{"bid_px":"249.880000000","ask_px":"252.400000000","bid_sz":4,"ask_sz":1000,"bid_ct":1,"ask_ct":1},{"bid_px":"249.800000000","ask_px":"253.350000000","bid_sz":199,"ask_sz":23,"bid_ct":1,"ask_ct":1},{"bid_px":"249.770000000","ask_px":"253.650000000","bid_sz":50,"ask_sz":400,"bid_ct":1,"ask_ct":1},{"bid_px":"249.400000000","ask_px":"255.000000000","bid_sz":1000,"ask_sz":85,"bid_ct":1,"ask_ct":2},{"bid_px":"248.500000000","ask_px":"260.000000000","bid_sz":40,"ask_sz":168,"bid_ct":1,"ask_ct":3},{"bid_px":"247.150000000","ask_px":"262.660000000","bid_sz":400,"ask_sz":56,"bid_ct":1,"ask_ct":1},{"bid_px":"247.000000000","ask_px":"264.940000000","bid_sz":12,"ask_sz":7,"bid_ct":1,"ask_ct":1}],"symbol":"TSLA"}
{"ts_recv":"2024-11-01T08:00:12.928285652Z","hd":{"ts_event":"2024-11-01T08:00:12.928119453Z","rtype":10,"publisher_id":2,"instrument_id":16244},"action":"A","side":"A","depth":7,"price":"258.000000000","size":200,"flags":130,"ts_in_delta":166199,"sequence":316520,"levels":[{"bid_px":"250.170000000","ask_px":"250.770000000","bid_sz":50,"ask_sz":6,"bid_ct":1,"ask_ct":1},{"bid_px":"250.000000000","ask_px":"251.140000000","bid_sz":2,"ask_sz":50,"bid_ct":2,"ask_ct":1},{"bid_px":"249.930000000","ask_px":"251.150000000","bid_sz":10,"ask_sz":100,"bid_ct":1,"ask_ct":1},{"bid_px":"249.880000000","ask_px":"252.400000000","bid_sz":4,"ask_sz":1000,"bid_ct":1,"ask_ct":1},{"bid_px":"249.800000000","ask_px":"253.350000000","bid_sz":199,"ask_sz":23,"bid_ct":1,"ask_ct":1},{"bid_px":"249.770000000","ask_px":"253.650000000","bid_sz":50,"ask_sz":400,"bid_ct":1,"ask_ct":1},{"bid_px":"249.400000000","ask_px":"255.000000000","bid_sz":1000,"ask_sz":85,"bid_ct":1,"ask_ct":2},{"bid_px":"248.500000000","ask_px":"258.000000000","bid_sz":40,"ask_sz":200,"bid_ct":1,"ask_ct":1},{"bid_px":"247.150000000","ask_px":"260.000000000","bid_sz":400,"ask_sz":168,"bid_ct":1,"ask_ct":3},{"bid_px":"247.000000000","ask_px":"262.660000000","bid_sz":12,"ask_sz":56,"bid_ct":1,"ask_ct":1}],"symbol":"TSLA"}
{"ts_recv":"2024-11-01T08:00:12.951096555Z","hd":{"ts_event":"2024-11-01T08:00:12.950930146Z","rtype":10,"publisher_id":2,"instrument_id":12463},"action":"A","side":"A","depth":0,"price":"169.560000000","size":100,"flags":130,"ts_in_delta":166409,"sequence":316609,"levels":[{"bid_px":"163.980000000","ask_px":"169.560000000","bid_sz":100,"ask_sz":100,"bid_ct":1,"ask_ct":1},{"bid_px":null,"ask_px":"180.000000000","bid_sz":0,"ask_sz":20,"bid_ct":0,"ask_ct":1},{"bid_px":null,"ask_px":null,"bid_sz":0,"ask_sz":0,"bid_ct":0,"ask_ct":0},{"bid_px":null,"ask_px":null,"bid_sz":0,"ask_sz":0,"bid_ct":0,"ask_ct":0},{"bid_px":null,"ask_px":null,"bid_sz":0,"ask_sz":0,"bid_ct":0,"ask_ct":0},{"bid_px":null,"ask_px":null,"bid_sz":0,"ask_sz":0,"bid_ct":0,"ask_ct":0},{"bid_px":null,"ask_px":null,"bid_sz":0,"ask_sz":0,"bid_ct":0,"ask_ct":0},{"bid_px":null,"ask_px":null,"bid_sz":0,"ask_sz":0,"bid_ct":0,"ask_ct":0},{"bid_px":null,"ask_px":null,"bid_sz":0,"ask_sz":0,"bid_ct":0,"ask_ct":0},{"bid_px":null,"ask_px":null,"bid_sz":0,"ask_sz":0,"bid_ct":0,"ask_ct":0}],"symbol":"PEP"}
{"ts_recv":"2024-11-01T08:00:13.013111583Z","hd":{"ts_event":"2024-11-01T08:00:13.012945480Z","rtype":10,"publisher_id":2,"instrument_id":16244},"action":"A","side":"A","depth":1,"price":"251.140000000","size":50,"flags":130,"ts_in_delta":166103,"sequence":316811,"levels":[{"bid_px":"250.170000000","ask_px":"250.770000000","bid_sz":50,"ask_sz":6,"bid_ct":1,"ask_ct":1},{"bid_px":"250.000000000","ask_px":"251.140000000","bid_sz":2,"ask_sz":100,"bid_ct":2,"ask_ct":2},{"bid_px":"249.930000000","ask_px":"251.150000000","bid_sz":10,"ask_sz":100,"bid_ct":1,"ask_ct":1},{"bid_px":"249.880000000","ask_px":"252.400000000","bid_sz":4,"ask_sz":1000,"bid_ct":1,"ask_ct":1},{"bid_px":"249.800000000","ask_px":"253.350000000","bid_sz":199,"ask_sz":23,"bid_ct":1,"ask_ct":1},{"bid_px":"249.770000000","ask_px":"253.650000000","bid_sz":50,"ask_sz":400,"bid_ct":1,"ask_ct":1},{"bid_px":"249.400000000","ask_px":"255.000000000","bid_sz":1000,"ask_sz":85,"bid_ct":1,"ask_ct":2},{"bid_px":"248.500000000","ask_px":"258.000000000","bid_sz":40,"ask_sz":200,"bid_ct":1,"ask_ct":1},{"bid_px":"247.150000000","ask_px":"260.000000000","bid_sz":400,"ask_sz":168,"bid_ct":1,"ask_ct":3},{"bid_px":"247.000000000","ask_px":"262.660000000","bid_sz":12,"ask_sz":56,"bid_ct":1,"ask_ct":1}],"symbol":"TSLA"}
{"ts_recv":"2024-11-01T08:00:13.021903931Z","hd":{"ts_event":"2024-11-01T08:00:13.021737683Z","rtype":10,"publisher_id":2,"instrument_id":38},"action":"A","side":"B","depth":2,"price":"220.000000000","size":6,"flags":130,"ts_in_delta":166248,"sequence":316839,"levels":[{"bid_px":"221.700000000","ask_px":"224.400000000","bid_sz":10,"ask_sz":1000,"bid_ct":1,"ask_ct":1},{"bid_px":"221.400000000","ask_px":"225.000000000","bid_sz":1000,"ask_sz":1,"bid_ct":1,"ask_ct":1},{"bid_px":"220.000000000","ask_px":"225.360000000","bid_sz":8,"ask_sz":1,"bid_ct":2,"ask_ct":1},{"bid_px":"219.690000000","ask_px":"225.490000000","bid_sz":442,"ask_sz":442,"bid_ct":1,"ask_ct":1},{"bid_px":"219.000000000","ask_px":"225.900000000","bid_sz":1,"ask_sz":32,"bid_ct":1,"ask_ct":2},{"bid_px":"217.000000000","ask_px":"229.330000000","bid_sz":1525,"ask_sz":9,"bid_ct":1,"ask_ct":2},{"bid_px":"215.000000000","ask_px":"233.670000000","bid_sz":5,"ask_sz":5,"bid_ct":1,"ask_ct":1},{"bid_px":"213.000000000","ask_px":"234.000000000","bid_sz":5,"ask_sz":20,"bid_ct":1,"ask_ct":1},{"bid_px":"212.340000000","ask_px":"234.750000000","bid_sz":5,"ask_sz":50,"bid_ct":1,"ask_ct":1},{"bid_px":"210.000000000","ask_px":"235.000000000","bid_sz":1,"ask_sz":2,"bid_ct":1,"ask_ct":1}],"symbol":"AAPL"}
{"ts_recv":"2024-11-01T08:00:13.029462293Z","hd":{"ts_event":"2024-11-01T08:00:13.029295550Z","rtype":10,"publisher_id":2,"instrument_id":12463},"action":"A","side":"A","depth":0,"price":"169.470000000","size":100,"flags":130,"ts_in_delta":166743,"sequence":316862,"levels":[{"bid_px":"163.980000000","ask_px":"169.470000000","bid_sz":100,"ask_sz":100,"bid_ct":1,"ask_ct":1},{"bid_px":null,"ask_px":"180.000000000","bid_sz":0,"ask_sz":20,"bid_ct":0,"ask_ct":1},{"bid_px":null,"ask_px":null,"bid_sz":0,"ask_sz":0,"bid_ct":0,"ask_ct":0},{"bid_px":null,"ask_px":null,"bid_sz":0,"ask_sz":0,"bid_ct":0,"ask_ct":0},{"bid_px":null,"ask_px":null,"bid_sz":0,"ask_sz":0,"bid_ct":0,"ask_ct":0},{"bid_px":null,"ask_px":null,"bid_sz":0,"ask_sz":0,"bid_ct":0,"ask_ct":0},{"bid_px":null,"ask_px":null,"bid_sz":0,"ask_sz":0,"bid_ct":0,"ask_ct":0},{"bid_px":null,"ask_px":null,"bid_sz":0,"ask_sz":0,"bid_ct":0,"ask_ct":0},{"bid_px":null,"ask_px":null,"bid_sz":0,"ask_sz":0,"bid_ct":0,"ask_ct":0},{"bid_px":null,"ask_px":null,"bid_sz":0,"ask_sz":0,"bid_ct":0,"ask_ct":0}],"symbol":"PEP"}
{"ts_recv":"2024-11-01T08:00:13.067295659Z","hd":{"ts_event":"2024-11-01T08:00:13.067129626Z","rtype":10,"publisher_id":2,"instrument_id":16244},"action":"C","side":"A","depth":1,"price":"251.140000000","size":50,"flags":130,"ts_in_delta":166033,"sequence":317010,"levels":[{"bid_px":"250.170000000","ask_px":"250.770000000","bid_sz":50,"ask_sz":6,"bid_ct":1,"ask_ct":1},{"bid_px":"250.000000000","ask_px":"251.140000000","bid_sz":2,"ask_sz":50,"bid_ct":2,"ask_ct":1},{"bid_px":"249.930000000","ask_px":"251.150000000","bid_sz":10,"ask_sz":100,"bid_ct":1,"ask_ct":1},{"bid_px":"249.880000000","ask_px":"252.400000000","bid_sz":4,"ask_sz":1000,"bid_ct":1,"ask_ct":1},{"bid_px":"249.800000000","ask_px":"253.350000000","bid_sz":199,"ask_sz":23,"bid_ct":1,"ask_ct":1},{"bid_px":"249.770000000","ask_px":"253.650000000","bid_sz":50,"ask_sz":400,"bid_ct":1,"ask_ct":1},{"bid_px":"249.400000000","ask_px":"255.000000000","bid_sz":1000,"ask_sz":85,"bid_ct":1,"ask_ct":2},{"bid_px":"248.500000000","ask_px":"258.000000000","bid_sz":40,"ask_sz":200,"bid_ct":1,"ask_ct":1},{"bid_px":"247.150000000","ask_px":"260.000000000","bid_sz":400,"ask_sz":168,"bid_ct":1,"ask_ct":3},{"bid_px":"247.000000000","ask_px":"262.660000000","bid_sz":12,"ask_sz":56,"bid_ct":1,"ask_ct":1}],"symbol":"TSLA"}
{"ts_recv":"2024-11-01T08:00:13.067309448Z","hd":{"ts_event":"2024-11-01T08:00:13.067143347Z","rtype":10,"publisher_id":2,"instrument_id":16244},"action":"A","side":"A","depth":1,"price":"251.130000000","size":50,"flags":130,"ts_in_delta":166101,"sequence":317011,"levels":[{"bid_px":"250.170000000","ask_px":"250.770000000","bid_sz":50,"ask_sz":6,"bid_ct":1,"ask_ct":1},{"bid_px":"250.000000000","ask_px":"251.130000000","bid_sz":2,"ask_sz":50,"bid_ct":2,"ask_ct":1},{"bid_px":"249.930000000","ask_px":"251.150000000","bid_sz":10,"ask_sz":100,"bid_ct":1,"ask_ct":1},{"bid_px":"249.880000000","ask_px":"252.400000000","bid_sz":4,"ask_sz":1000,"bid_ct":1,"ask_ct":1},{"bid_px":"249.800000000","ask_px":"253.350000000","bid_sz":199,"ask_sz":23,"bid_ct":1,"ask_ct":1},{"bid_px":"249.770000000","ask_px":"253.650000000","bid_sz":50,"ask_sz":400,"bid_ct":1,"ask_ct":1},{"bid_px":"249.400000000","ask_px":"255.000000000","bid_sz":1000,"ask_sz":85,"bid_ct":1,"ask_ct":2},{"bid_px":"248.500000000","ask_px":"258.000000000","bid_sz":40,"ask_sz":200,"bid_ct":1,"ask_ct":1},{"bid_px":"247.150000000","ask_px":"260.000000000","bid_sz":400,"ask_sz":168,"bid_ct":1,"ask_ct":3},{"bid_px":"247.000000000","ask_px":"262.660000000","bid_sz":12,"ask_sz":56,"bid_ct":1,"ask_ct":1}],"symbol":"TSLA"}
{"ts_recv":"2024-11-01T08:00:13.083941712Z","hd":{"ts_event":"2024-11-01T08:00:13.083775066Z","rtype":10,"publisher_id":2,"instrument_id":38},"action":"A","side":"B","depth":2,"price":"221.200000000","size":10,"flags":130,"ts_in_delta":166646,"sequence":317081,"levels":[{"bid_px":"221.700000000","ask_px":"224.400000000","bid_sz":10,"ask_sz":1000,"bid_ct":1,"ask_ct":1},{"bid_px":"221.400000000","ask_px":"225.000000000","bid_sz":1000,"ask_sz":1,"bid_ct":1,"ask_ct":1},{"bid_px":"221.200000000","ask_px":"225.360000000","bid_sz":10,"ask_sz":1,"bid_ct":1,"ask_ct":1},{"bid_px":"220.000000000","ask_px":"225.490000000","bid_sz":8,"ask_sz":442,"bid_ct":2,"ask_ct":1},{"bid_px":"219.690000000","ask_px":"225.900000000","bid_sz":442,"ask_sz":32,"bid_ct":1,"ask_ct":2},{"bid_px":"219.000000000","ask_px":"229.330000000","bid_sz":1,"ask_sz":9,"bid_ct":1,"ask_ct":2},{"bid_px":"217.000000000","ask_px":"233.670000000","bid_sz":1525,"ask_sz":5,"bid_ct":1,"ask_ct":1},{"bid_px":"215.000000000","ask_px":"234.000000000","bid_sz":5,"ask_sz":20,"bid_ct":1,"ask_ct":1},{"bid_px":"213.000000000","ask_px":"234.750000000","bid_sz":5,"ask_sz":50,"bid_ct":1,"ask_ct":1},{"bid_px":"212.340000000","ask_px":"235.000000000","bid_sz":5,"ask_sz":2,"bid_ct":1,"ask_ct":1}],"symbol":"AAPL"}
{"ts_recv":"2024-11-01T08:00:13.088143916Z","hd":{"ts_event":"2024-11-01T08:00:13.087977698Z","rtype":10,"publisher_id":2,"instrument_id":38},"action":"A","side":"A","depth":5,"price":"227.000000000","size":35,"flags":130,"ts_in_delta":166218,"sequence":317095,"levels":[{"bid_px":"221.700000000","ask_px":"224.400000000","bid_sz":10,"ask_sz":1000,"bid_ct":1,"ask_ct":1},{"bid_px":"221.400000000","ask_px":"225.000000000","bid_sz":1000,"ask_sz":1,"bid_ct":1,"ask_ct":1},{"bid_px":"221.200000000","ask_px":"225.360000000","bid_sz":10,"ask_sz":1,"bid_ct":1,"ask_ct":1},{"bid_px":"220.000000000","ask_px":"225.490000000","bid_sz":8,"ask_sz":442,"bid_ct":2,"ask_ct":1},{"bid_px":"219.690000000","ask_px":"225.900000000","bid_sz":442,"ask_sz":32,"bid_ct":1,"ask_ct":2},{"bid_px":"219.000000000","ask_px":"227.000000000","bid_sz":1,"ask_sz":35,"bid_ct":1,"ask_ct":1},{"bid_px":"217.000000000","ask_px":"229.330000000","bid_sz":1525,"ask_sz":9,"bid_ct":1,"ask_ct":2},{"bid_px":"215.000000000","ask_px":"233.670000000","bid_sz":5,"ask_sz":5,"bid_ct":1,"ask_ct":1},{"bid_px":"213.000000000","ask_px":"234.000000000","bid_sz":5,"ask_sz":20,"bid_ct":1,"ask_ct":1},{"bid_px":"212.340000000","ask_px":"234.750000000","bid_sz":5,"ask_sz":50,"bid_ct":1,"ask_ct":1}],"symbol":"AAPL"}
{"ts_recv":"2024-11-01T08:00:13.132843278Z","hd":{"ts_event":"2024-11-01T08:00:13.132677034Z","rtype":10,"publisher_id":2,"instrument_id":16244},"action":"A","side":"B","depth":7,"price":"249.000000000","size":100,"flags":130,"ts_in_delta":166244,"sequence":317239,"levels":[{"bid_px":"250.170000000","ask_px":"250.770000000","bid_sz":50,"ask_sz":6,"bid_ct":1,"ask_ct":1},{"bid_px":"250.000000000","ask_px":"251.130000000","bid_sz":2,"ask_sz":50,"bid_ct":2,"ask_ct":1},{"bid_px":"249.930000000","ask_px":"251.150000000","bid_sz":10,"ask_sz":100,"bid_ct":1,"ask_ct":1},{"bid_px":"249.880000000","ask_px":"252.400000000","bid_sz":4,"ask_sz":1000,"bid_ct":1,"ask_ct":1},{"bid_px":"249.800000000","ask_px":"253.350000000","bid_sz":199,"ask_sz":23,"bid_ct":1,"ask_ct":1},{"bid_px":"249.770000000","ask_px":"253.650000000","bid_sz":50,"ask_sz":400,"bid_ct":1,"ask_ct":1},{"bid_px":"249.400000000","ask_px":"255.000000000","bid_sz":1000,"ask_sz":85,"bid_ct":1,"ask_ct":2},{"bid_px":"249.000000000","ask_px":"258.000000000","bid_sz":100,"ask_sz":200,"bid_ct":1,"ask_ct":1},{"bid_px":"248.500000000","ask_px":"260.000000000","bid_sz":40,"ask_sz":168,"bid_ct":1,"ask_ct":3},{"bid_px":"247.150000000","ask_px":"262.660000000","bid_sz":400,"ask_sz":56,"bid_ct":1,"ask_ct":1}],"symbol":"TSLA"}
{"ts_recv":"2024-11-01T08:00:13.134571071Z","hd":{"ts_event":"2024-11-01T08:00:13.134404595Z","rtype":10,"publisher_id":2,"instrument_id":16244},"action":"A","side":"A","depth":8,"price":"260.000000000","size":1,"flags":130,"ts_in_delta":166476,"sequence":317253,"levels":[{"bid_px":"250.170000000","ask_px":"250.770000000","bid_sz":50,"ask_sz":6,"bid_ct":1,"ask_ct":1},{"bid_px":"250.000000000","ask_px":"251.130000000","bid_sz":2,"ask_sz":50,"bid_ct":2,"ask_ct":1},{"bid_px":"249.930000000","ask_px":"251.150000000","bid_sz":10,"ask_sz":100,"bid_ct":1,"ask_ct":1},{"bid_px":"249.880000000","ask_px":"252.400000000","bid_sz":4,"ask_sz":1000,"bid_ct":1,"ask_ct":1},{"bid_px":"249.800000000","ask_px":"253.350000000","bid_sz":199,"ask_sz":23,"bid_ct":1,"ask_ct":1},{"bid_px":"249.770000000","ask_px":"253.650000000","bid_sz":50,"ask_sz":400,"bid_ct":1,"ask_ct":1},{"bid_px":"249.400000000","ask_px":"255.000000000","bid_sz":1000,"ask_sz":85,"bid_ct":1,"ask_ct":2},{"bid_px":"249.000000000","ask_px":"258.000000000","bid_sz":100,"ask_sz":200,"bid_ct":1,"ask_ct":1},{"bid_px":"248.500000000","ask_px":"260.000000000","bid_sz":40,"ask_sz":169,"bid_ct":1,"ask_ct":4},{"bid_px":"247.150000000","ask_px":"262.660000000","bid_sz":400,"ask_sz":56,"bid_ct":1,"ask_ct":1}],"symbol":"TSLA"}
{"ts_recv":"2024-11-01T08:00:13.137893281Z","hd":{"ts_event":"2024-11-01T08:00:13.137727086Z","rtype":10,"publisher_id":2,"instrument_id":16244},"action":"C","side":"B","depth":0,"price":"250.170000000","size":50,"flags":130,"ts_in_delta":166195,"sequence":317269,"levels":[{"bid_px":"250.000000000","ask_px":"250.770000000","bid_sz":2,"ask_sz":6,"bid_ct":2,"ask_ct":1},{"bid_px":"249.930000000","ask_px":"251.130000000","bid_sz":10,"ask_sz":50,"bid_ct":1,"ask_ct":1},{"bid_px":"249.880000000","ask_px":"251.150000000","bid_sz":4,"ask_sz":100,"bid_ct":1,"ask_ct":1},{"bid_px":"249.800000000","ask_px":"252.400000000","bid_sz":199,"ask_sz":1000,"bid_ct":1,"ask_ct":1},{"bid_px":"249.770000000","ask_px":"253.350000000","bid_sz":50,"ask_sz":23,"bid_ct":1,"ask_ct":1},{"bid_px":"249.400000000","ask_px":"253.650000000","bid_sz":1000,"ask_sz":400,"bid_ct":1,"ask_ct":1},{"bid_px":"249.000000000","ask_px":"255.000000000","bid_sz":100,"ask_sz":85,"bid_ct":1,"ask_ct":2},{"bid_px":"248.500000000","ask_px":"258.000000000","bid_sz":40,"ask_sz":200,"bid_ct":1,"ask_ct":1},{"bid_px":"247.150000000","ask_px":"260.000000000","bid_sz":400,"ask_sz":169,"bid_ct":1,"ask_ct":4},{"bid_px":"247.000000000","ask_px":"262.660000000","bid_sz":12,"ask_sz":56,"bid_ct":1,"ask_ct":1}],"symbol":"TSLA"}
{"ts_recv":"2024-11-01T08:00:13.137906177Z","hd":{"ts_event":"2024-11-01T08:00:13.137739685Z","rtype":10,"publisher_id":2,"instrument_id":16244},"action":"A","side":"B","depth":0,"price":"250.150000000","size":50,"flags":130,"ts_in_delta":166492,"sequence":317270,"levels":[{"bid_px":"250.150000000","ask_px":"250.770000000","bid_sz":50,"ask_sz":6,"bid_ct":1,"ask_ct":1},{"bid_px":"250.000000000","ask_px":"251.130000000","bid_sz":2,"ask_sz":50,"bid_ct":2,"ask_ct":1},{"bid_px":"249.930000000","ask_px":"251.150000000","bid_sz":10,"ask_sz":100,"bid_ct":1,"ask_ct":1},{"bid_px":"249.880000000","ask_px":"252.400000000","bid_sz":4,"ask_sz":1000,"bid_ct":1,"ask_ct":1},{"bid_px":"249.800000000","ask_px":"253.350000000","bid_sz":199,"ask_sz":23,"bid_ct":1,"ask_ct":1},{"bid_px":"249.770000000","ask_px":"253.650000000","bid_sz":50,"ask_sz":400,"bid_ct":1,"ask_ct":1},{"bid_px":"249.400000000","ask_px":"255.000000000","bid_sz":1000,"ask_sz":85,"bid_ct":1,"ask_ct":2},{"bid_px":"249.000000000","ask_px":"258.000000000","bid_sz":100,"ask_sz":200,"bid_ct":1,"ask_ct":1},{"bid_px":"248.500000000","ask_px":"260.000000000","bid_sz":40,"ask_sz":169,"bid_ct":1,"ask_ct":4},{"bid_px":"247.150000000","ask_px":"262.660000000","bid_sz":400,"ask_sz":56,"bid_ct":1,"ask_ct":1}],"symbol":"TSLA"}
{"ts_recv":"2024-11-01T08:00:13.234563518Z","hd":{"ts_event":"2024-11-01T08:00:13.234395636Z","rtype":10,"publisher_id":2,"instrument_id":16244},"action":"A","side":"A","depth":9,"price":"262.560000000","size":50,"flags":130,"ts_in_delta":167882,"sequence":317926,"levels":[{"bid_px":"250.150000000","ask_px":"250.770000000","bid_sz":50,"ask_sz":6,"bid_ct":1,"ask_ct":1},{"bid_px":"250.000000000","ask_px":"251.130000000","bid_sz":2,"ask_sz":50,"bid_ct":2,"ask_ct":1},{"bid_px":"249.930000000","ask_px":"251.150000000","bid_sz":10,"ask_sz":100,"bid_ct":1,"ask_ct":1},{"bid_px":"249.880000000","ask_px":"252.400000000","bid_sz":4,"ask_sz":1000,"bid_ct":1,"ask_ct":1},{"bid_px":"249.800000000","ask_px":"253.350000000","bid_sz":199,"ask_sz":23,"bid_ct":1,"ask_ct":1},{"bid_px":"249.770000000","ask_px":"253.650000000","bid_sz":50,"ask_sz":400,"bid_ct":1,"ask_ct":1},{"bid_px":"249.400000000","ask_px":"255.000000000","bid_sz":1000,"ask_sz":85,"bid_ct":1,"ask_ct":2},{"bid_px":"249.000000000","ask_px":"258.000000000","bid_sz":100,"ask_sz":200,"bid_ct":1,"ask_ct":1},{"bid_px":"248.500000000","ask_px":"260.000000000","bid_sz":40,"ask_sz":169,"bid_ct":1,"ask_ct":4},{"bid_px":"247.150000000","ask_px":"262.560000000","bid_sz":400,"ask_sz":50,"bid_ct":1,"ask_ct":1}],"symbol":"TSLA"}
{"ts_recv":"2024-11-01T08:00:13.247459338Z","hd":{"ts_event":"2024-11-01T08:00:13.247293005Z","rtype":10,"publisher_id":2,"instrument_id":16244},"action":"A","side":"B","depth":8,"price":"248.500000000","size":5,"flags":130,"ts_in_delta":166333,"sequence":317958,"levels":[{"bid_px":"250.150000000","ask_px":"250.770000000","bid_sz":50,"ask_sz":6,"bid_ct":1,"ask_ct":1},{"bid_px":"250.000000000","ask_px":"251.130000000","bid_sz":2,"ask_sz":50,"bid_ct":2,"ask_ct":1},{"bid_px":"249.930000000","ask_px":"251.150000000","bid_sz":10,"ask_sz":100,"bid_ct":1,"ask_ct":1},{"bid_px":"249.880000000","ask_px":"252.400000000","bid_sz":4,"ask_sz":1000,"bid_ct":1,"ask_ct":1},{"bid_px":"249.800000000","ask_px":"253.350000000","bid_sz":199,"ask_sz":23,"bid_ct":1,"ask_ct":1},{"bid_px":"249.770000000","ask_px":"253.650000000","bid_sz":50,"ask_sz":400,"bid_ct":1,"ask_ct":1},{"bid_px":"249.400000000","ask_px":"255.000000000","bid_sz":1000,"ask_sz":85,"bid_ct":1,"ask_ct":2},{"bid_px":"249.000000000","ask_px":"258.000000000","bid_sz":100,"ask_sz":200,"bid_ct":1,"ask_ct":1},{"bid_px":"248.500000000","ask_px":"260.000000000","bid_sz":45,"ask_sz":169,"bid_ct":2,"ask_ct":4},{"bid_px":"247.150000000","ask_px":"262.560000000","bid_sz":400,"ask_sz":50,"bid_ct":1,"ask_ct":1}],"symbol":"TSLA"}
{"ts_recv":"2024-11-01T08:00:13.302095598Z","hd":{"ts_event":"2024-11-01T08:00:13.301929105Z","rtype":10,"publisher_id":2,"instrument_id":10888},"action":"A","side":"A","depth":3,"price":"419.860000000","size":10,"flags":130,"ts_in_delta":166493,"sequence":318048,"levels":[{"bid_px":"410.000000000","ask_px":"414.000000000","bid_sz":1,"ask_sz":468,"bid_ct":1,"ask_ct":2},{"bid_px":"409.750000000","ask_px":"415.070000000","bid_sz":3,"ask_sz":246,"bid_ct":1,"ask_ct":1},{"bid_px":"409.740000000","ask_px":"415.350000000","bid_sz":500,"ask_sz":84,"bid_ct":1,"ask_ct":2},{"bid_px":"409.670000000","ask_px":"419.860000000","bid_sz":100,"ask_sz":10,"bid_ct":1,"ask_ct":1},{"bid_px":"409.430000000","ask_px":"420.000000000","bid_sz":5,"ask_sz":3,"bid_ct":1,"ask_ct":1},{"bid_px":"409.250000000","ask_px":"440.000000000","bid_sz":2,"ask_sz":35,"bid_ct":1,"ask_ct":1},{"bid_px":"409.080000000","ask_px":"445.000000000","bid_sz":2,"ask_sz":25,"bid_ct":1,"ask_ct":1},{"bid_px":"409.000000000","ask_px":"445.680000000","bid_sz":3,"ask_sz":3,"bid_ct":2,"ask_ct":1},{"bid_px":"408.970000000","ask_px":"448.000000000","bid_sz":12,"ask_sz":15,"bid_ct":1,"ask_ct":2},{"bid_px":"408.960000000","ask_px":"450.000000000","bid_sz":5,"ask_sz":12,"bid_ct":1,"ask_ct":2}],"symbol":"MSFT"}
{"ts_recv":"2024-11-01T08:00:13.310387215Z","hd":{"ts_event":"2024-11-01T08:00:13.310221021Z","rtype":10,"publisher_id":2,"instrument_id":16244},"action":"A","side":"A","depth":3,"price":"251.500000000","size":10,"flags":130,"ts_in_delta":166194,"sequence":318064,"levels":[{"bid_px":"250.150000000","ask_px":"250.770000000","bid_sz":50,"ask_sz":6,"bid_ct":1,"ask_ct":1},{"bid_px":"250.000000000","ask_px":"251.130000000","bid_sz":2,"ask_sz":50,"bid_ct":2,"ask_ct":1},{"bid_px":"249.930000000","ask_px":"251.150000000","bid_sz":10,"ask_sz":100,"bid_ct":1,"ask_ct":1},{"bid_px":"249.880000000","ask_px":"251.500000000","bid_sz":4,"ask_sz":10,"bid_ct":1,"ask_ct":1},{"bid_px":"249.800000000","ask_px":"252.400000000","bid_sz":199,"ask_sz":1000,"bid_ct":1,"ask_ct":1},{"bid_px":"249.770000000","ask_px":"253.350000000","bid_sz":50,"ask_sz":23,"bid_ct":1,"ask_ct":1},{"bid_px":"249.400000000","ask_px":"253.650000000","bid_sz":1000,"ask_sz":400,"bid_ct":1,"ask_ct":1},{"bid_px":"249.000000000","ask_px":"255.000000000","bid_sz":100,"ask_sz":85,"bid_ct":1,"ask_ct":2},{"bid_px":"248.500000000","ask_px":"258.000000000","bid_sz":45,"ask_sz":200,"bid_ct":2,"ask_ct":1},{"bid_px":"247.150000000","ask_px":"260.000000000","bid_sz":400,"ask_sz":169,"bid_ct":1,"ask_ct":4}],"symbol":"TSLA"}
{"ts_recv":"2024-11-01T08:00:13.310747707Z","hd":{"ts_event":"2024-11-01T08:00:13.310581079Z","rtype":10,"publisher_id":2,"instrument_id":16244},"action":"A","side":"B","depth":8,"price":"248.500000000","size":66,"flags":130,"ts_in_delta":166628,"sequence":318065,"levels":[{"bid_px":"250.150000000","ask_px":"250.770000000","bid_sz":50,"ask_sz":6,"bid_ct":1,"ask_ct":1},{"bid_px":"250.000000000","ask_px":"251.130000000","bid_sz":2,"ask_sz":50,"bid_ct":2,"ask_ct":1},{"bid_px":"249.930000000","ask_px":"251.150000000","bid_sz":10,"ask_sz":100,"bid_ct":1,"ask_ct":1},{"bid_px":"249.880000000","ask_px":"251.500000000","bid_sz":4,"ask_sz":10,"bid_ct":1,"ask_ct":1},{"bid_px":"249.800000000","ask_px":"252.400000000","bid_sz":199,"ask_sz":1000,"bid_ct":1,"ask_ct":1},{"bid_px":"249.770000000","ask_px":"253.350000000","bid_sz":50,"ask_sz":23,"bid_ct":1,"ask_ct":1},{"bid_px":"249.400000000","ask_px":"253.650000000","bid_sz":1000,"ask_sz":400,"bid_ct":1,"ask_ct":1},{"bid_px":"249.000000000","ask_px":"255.000000000","bid_sz":100,"ask_sz":85,"bid_ct":1,"ask_ct":2},{"bid_px":"248.500000000","ask_px":"258.000000000","bid_sz":111,"ask_sz":200,"bid_ct":3,"ask_ct":1},{"bid_px":"247.150000000","ask_px":"260.000000000","bid_sz":400,"ask_sz":169,"bid_ct":1,"ask_ct":4}],"symbol":"TSLA"}
{"ts_recv":"2024-11-01T08:00:13.339369155Z","hd":{"ts_event":"2024-11-01T08:00:13.339203039Z","rtype":10,"publisher_id":2,"instrument_id":16244},"action":"A","side":"B","depth":6,"price":"249.500000000","size":1000,"flags":130,"ts_in_delta":166116,"sequence":318138,"levels":[{"bid_px":"250.150000000","ask_px":"250.770000000","bid_sz":50,"ask_sz":6,"bid_ct":1,"ask_ct":1},{"bid_px":"250.000000000","ask_px":"251.130000000","bid_sz":2,"ask_sz":50,"bid_ct":2,"ask_ct":1},{"bid_px":"249.930000000","ask_px":"251.150000000","bid_sz":10,"ask_sz":100,"bid_ct":1,"ask_ct":1},{"bid_px":"249.880000000","ask_px":"251.500000000","bid_sz":4,"ask_sz":10,"bid_ct":1,"ask_ct":1},{"bid_px":"249.800000000","ask_px":"252.400000000","bid_sz":199,"ask_sz":1000,"bid_ct":1,"ask_ct":1},{"bid_px":"249.770000000","ask_px":"253.350000000","bid_sz":50,"ask_sz":23,"bid_ct":1,"ask_ct":1},{"bid_px":"249.500000000","ask_px":"253.650000000","bid_sz":1000,"ask_sz":400,"bid_ct":1,"ask_ct":1},{"bid_px":"249.400000000","ask_px":"255.000000000","bid_sz":1000,"ask_sz":85,"bid_ct":1,"ask_ct":2},{"bid_px":"249.000000000","ask_px":"258.000000000","bid_sz":100,"ask_sz":200,"bid_ct":1,"ask_ct":1},{"bid_px":"248.500000000","ask_px":"260.000000000","bid_sz":111,"ask_sz":169,"bid_ct":3,"ask_ct":4}],"symbol":"TSLA"}
{"ts_recv":"2024-11-01T08:00:13.339409856Z","hd":{"ts_event":"2024-11-01T08:00:13.339243947Z","rtype":10,"publisher_id":2,"instrument_id":16244},"action":"C","side":"B","depth":7,"price":"249.400000000","size":1000,"flags":130,"ts_in_delta":165909,"sequence":318139,"levels":[{"bid_px":"250.150000000","ask_px":"250.770000000","bid_sz":50,"ask_sz":6,"bid_ct":1,"ask_ct":1},{"bid_px":"250.000000000","ask_px":"251.130000000","bid_sz":2,"ask_sz":50,"bid_ct":2,"ask_ct":1},{"bid_px":"249.930000000","ask_px":"251.150000000","bid_sz":10,"ask_sz":100,"bid_ct":1,"ask_ct":1},{"bid_px":"249.880000000","ask_px":"251.500000000","bid_sz":4,"ask_sz":10,"bid_ct":1,"ask_ct":1},{"bid_px":"249.800000000","ask_px":"252.400000000","bid_sz":199,"ask_sz":1000,"bid_ct":1,"ask_ct":1},{"bid_px":"249.770000000","ask_px":"253.350000000","bid_sz":50,"ask_sz":23,"bid_ct":1,"ask_ct":1},{"bid_px":"249.500000000","ask_px":"253.650000000","bid_sz":1000,"ask_sz":400,"bid_ct":1,"ask_ct":1},{"bid_px":"249.000000000","ask_px":"255.000000000","bid_sz":100,"ask_sz":85,"bid_ct":1,"ask_ct":2},{"bid_px":"248.500000000","ask_px":"258.000000000","bid_sz":111,"ask_sz":200,"bid_ct":3,"ask_ct":1},{"bid_px":"247.150000000","ask_px":"260.000000000","bid_sz":400,"ask_sz":169,"bid_ct":1,"ask_ct":4}],"symbol":"TSLA"}
{"ts_recv":"2024-11-01T08:00:13.413851896Z","hd":{"ts_event":"2024-11-01T08:00:13.413685637Z","rtype":10,"publisher_id":2,"instrument_id":11667},"action":"A","side":"B","depth":0,"price":"134.930000000","size":400,"flags":130,"ts_in_delta":166259,"sequence":318348,"levels":[{"bid_px":"134.930000000","ask_px":"134.990000000","bid_sz":400,"ask_sz":10,"bid_ct":1,"ask_ct":1},{"bid_px":"134.500000000","ask_px":"135.000000000","bid_sz":520,"ask_sz":38,"bid_ct":2,"ask_ct":3},{"bid_px":"134.440000000","ask_px":"135.100000000","bid_sz":100,"ask_sz":10,"bid_ct":1,"ask_ct":1},{"bid_px":"134.410000000","ask_px":"135.230000000","bid_sz":61,"ask_sz":360,"bid_ct":2,"ask_ct":1},{"bid_px":"134.380000000","ask_px":"135.300000000","bid_sz":18,"ask_sz":1000,"bid_ct":1,"ask_ct":1},{"bid_px":"134.210000000","ask_px":"135.400000000","bid_sz":20,"ask_sz":10,"bid_ct":1,"ask_ct":1},{"bid_px":"134.200000000","ask_px":"135.420000000","bid_sz":3,"ask_sz":1,"bid_ct":1,"ask_ct":1},{"bid_px":"134.000000000","ask_px":"135.820000000","bid_sz":1,"ask_sz":1,"bid_ct":1,"ask_ct":1},{"bid_px":"133.800000000","ask_px":"135.910000000","bid_sz":5,"ask_sz":100,"bid_ct":1,"ask_ct":1},{"bid_px":"133.160000000","ask_px":"135.990000000","bid_sz":1,"ask_sz":20,"bid_ct":1,"ask_ct":1}],"symbol":"NVDA"}
{"ts_recv":"2024-11-01T08:00:13.413997525Z","hd":{"ts_event":"2024-11-01T08:00:13.413831456Z","rtype":10,"publisher_id":2,"instrument_id":11667},"action":"A","side":"A","depth":4,"price":"135.300000000","size":9,"flags":130,"ts_in_delta":166069,"sequence":318351,"levels":[{"bid_px":"134.930000000","ask_px":"134.990000000","bid_sz":400,"ask_sz":10,"bid_ct":1,"ask_ct":1},{"bid_px":"134.500000000","ask_px":"135.000000000","bid_sz":520,"ask_sz":38,"bid_ct":2,"ask_ct":3},{"bid_px":"134.440000000","ask_px":"135.100000000","bid_sz":100,"ask_sz":10,"bid_ct":1,"ask_ct":1},{"bid_px":"134.410000000","ask_px":"135.230000000","bid_sz":61,"ask_sz":360,"bid_ct":2,"ask_ct":1},{"bid_px":"134.380000000","ask_px":"135.300000000","bid_sz":18,"ask_sz":1009,"bid_ct":1,"ask_ct":2},{"bid_px":"134.210000000","ask_px":"135.400000000","bid_sz":20,"ask_sz":10,"bid_ct":1,"ask_ct":1},{"bid_px":"134.200000000","ask_px":"135.420000000","bid_sz":3,"ask_sz":1,"bid_ct":1,"ask_ct":1},{"bid_px":"134.000000000","ask_px":"135.820000000","bid_sz":1,"ask_sz":1,"bid_ct":1,"ask_ct":1},{"bid_px":"133.800000000","ask_px":"135.910000000","bid_sz":5,"ask_sz":100,"bid_ct":1,"ask_ct":1},{"bid_px":"133.160000000","ask_px":"135.990000000","bid_sz":1,"ask_sz":20,"bid_ct":1,"ask_ct":1}],"symbol":"NVDA"}
{"ts_recv":"2024-11-01T08:00:13.414120505Z","hd":{"ts_event":"2024-11-01T08:00:13.413952864Z","rtype":10,"publisher_id":2,"instrument_id":11667},"action":"T","side":"A","depth":0,"price":"134.930000000","size":18,"flags":130,"ts_in_delta":167641,"sequence":318352,"levels":[{"bid_px":"134.930000000","ask_px":"134.990000000","bid_sz":400,"ask_sz":10,"bid_ct":1,"ask_ct":1},{"bid_px":"134.500000000","ask_px":"135.000000000","bid_sz":520,"ask_sz":38,"bid_ct":2,"ask_ct":3},{"bid_px":"134.440000000","ask_px":"135.100000000","bid_sz":100,"ask_sz":10,"bid_ct":1,"ask_ct":1},{"bid_px":"134.410000000","ask_px":"135.230000000","bid_sz":61,"ask_sz":360,"bid_ct":2,"ask_ct":1},{"bid_px":"134.380000000","ask_px":"135.300000000","bid_sz":18,"ask_sz":1009,"bid_ct":1,"ask_ct":2},{"bid_px":"134.210000000","ask_px":"135.400000000","bid_sz":20,"ask_sz":10,"bid_ct":1,"ask_ct":1},{"bid_px":"134.200000000","ask_px":"135.420000000","bid_sz":3,"ask_sz":1,"bid_ct":1,"ask_ct":1},{"bid_px":"134.000000000","ask_px":"135.820000000","bid_sz":1,"ask_sz":1,"bid_ct":1,"ask_ct":1},{"bid_px":"133.800000000","ask_px":"135.910000000","bid_sz":5,"ask_sz":100,"bid_ct":1,"ask_ct":1},{"bid_px":"133.160000000","ask_px":"135.990000000","bid_sz":1,"ask_sz":20,"bid_ct":1,"ask_ct":1}],"symbol":"NVDA"}
{"ts_recv":"2024-11-01T08:00:13.414120505Z","hd":{"ts_event":"2024-11-01T08:00:13.413952864Z","rtype":10,"publisher_id":2,"instrument_id":11667},"action":"C","side":"B","depth":0,"price":"134.930000000","size":18,"flags":130,"ts_in_delta":167641,"sequence":318352,"levels":[{"bid_px":"134.930000000","ask_px":"134.990000000","bid_sz":382,"ask_sz":10,"bid_ct":1,"ask_ct":1},{"bid_px":"134.500000000","ask_px":"135.000000000","bid_sz":520,"ask_sz":38,"bid_ct":2,"ask_ct":3},{"bid_px":"134.440000000","ask_px":"135.100000000","bid_sz":100,"ask_sz":10,"bid_ct":1,"ask_ct":1},{"bid_px":"134.410000000","ask_px":"135.230000000","bid_sz":61,"ask_sz":360,"bid_ct":2,"ask_ct":1},{"bid_px":"134.380000000","ask_px":"135.300000000","bid_sz":18,"ask_sz":1009,"bid_ct":1,"ask_ct":2},{"bid_px":"134.210000000","ask_px":"135.400000000","bid_sz":20,"ask_sz":10,"bid_ct":1,"ask_ct":1},{"bid_px":"134.200000000","ask_px":"135.420000000","bid_sz":3,"ask_sz":1,"bid_ct":1,"ask_ct":1},{"bid_px":"134.000000000","ask_px":"135.820000000","bid_sz":1,"ask_sz":1,"bid_ct":1,"ask_ct":1},{"bid_px":"133.800000000","ask_px":"135.910000000","bid_sz":5,"ask_sz":100,"bid_ct":1,"ask_ct":1},{"bid_px":"133.160000000","ask_px":"135.990000000","bid_sz":1,"ask_sz":20,"bid_ct":1,"ask_ct":1}],"symbol":"NVDA"}
{"ts_recv":"2024-11-01T08:00:13.414270832Z","hd":{"ts_event":"2024-11-01T08:00:13.414104004Z","rtype":10,"publisher_id":2,"instrument_id":11667},"action":"T","side":"A","depth":0,"price":"134.930000000","size":9,"flags":130,"ts_in_delta":166828,"sequence":318354,"levels":[{"bid_px":"134.930000000","ask_px":"134.990000000","bid_sz":382,"ask_sz":10,"bid_ct":1,"ask_ct":1},{"bid_px":"134.500000000","ask_px":"135.000000000","bid_sz":520,"ask_sz":38,"bid_ct":2,"ask_ct":3},{"bid_px":"134.440000000","ask_px":"135.100000000","bid_sz":100,"ask_sz":10,"bid_ct":1,"ask_ct":1},{"bid_px":"134.410000000","ask_px":"135.230000000","bid_sz":61,"ask_sz":360,"bid_ct":2,"ask_ct":1},{"bid_px":"134.380000000","ask_px":"135.300000000","bid_sz":18,"ask_sz":1009,"bid_ct":1,"ask_ct":2},{"bid_px":"134.210000000","ask_px":"135.400000000","bid_sz":20,"ask_sz":10,"bid_ct":1,"ask_ct":1},{"bid_px":"134.200000000","ask_px":"135.420000000","bid_sz":3,"ask_sz":1,"bid_ct":1,"ask_ct":1},{"bid_px":"134.000000000","ask_px":"135.820000000","bid_sz":1,"ask_sz":1,"bid_ct":1,"ask_ct":1},{"bid_px":"133.800000000","ask_px":"135.910000000","bid_sz":5,"ask_sz":100,"bid_ct":1,"ask_ct":1},{"bid_px":"133.160000000","ask_px":"135.990000000","bid_sz":1,"ask_sz":20,"bid_ct":1,"ask_ct":1}],"symbol":"NVDA"}
{"ts_recv":"2024-11-01T08:00:13.414270832Z","hd":{"ts_event":"2024-11-01T08:00:13.414104004Z","rtype":10,"publisher_id":2,"instrument_id":11667},"action":"C","side":"B","depth":0,"price":"134.930000000","size":9,"flags":130,"ts_in_delta":166828,"sequence":318354,"levels":[{"bid_px":"134.930000000","ask_px":"134.990000000","bid_sz":373,"ask_sz":10,"bid_ct":1,"ask_ct":1},{"bid_px":"134.500000000","ask_px":"135.000000000","bid_sz":520,"ask_sz":38,"bid_ct":2,"ask_ct":3},{"bid_px":"134.440000000","ask_px":"135.100000000","bid_sz":100,"ask_sz":10,"bid_ct":1,"ask_ct":1},{"bid_px":"134.410000000","ask_px":"135.230000000","bid_sz":61,"ask_sz":360,"bid_ct":2,"ask_ct":1},{"bid_px":"134.380000000","ask_px":"135.300000000","bid_sz":18,"ask_sz":1009,"bid_ct":1,"ask_ct":2},{"bid_px":"134.210000000","ask_px":"135.400000000","bid_sz":20,"ask_sz":10,"bid_ct":1,"ask_ct":1},{"bid_px":"134.200000000","ask_px":"135.420000000","bid_sz":3,"ask_sz":1,"bid_ct":1,"ask_ct":1},{"bid_px":"134.000000000","ask_px":"135.820000000","bid_sz":1,"ask_sz":1,"bid_ct":1,"ask_ct":1},{"bid_px":"133.800000000","ask_px":"135.910000000","bid_sz":5,"ask_sz":100,"bid_ct":1,"ask_ct":1},{"bid_px":"133.160000000","ask_px":"135.990000000","bid_sz":1,"ask_sz":20,"bid_ct":1,"ask_ct":1}],"symbol":"NVDA"}
{"ts_recv":"2024-11-01T08:00:13.414337768Z","hd":{"ts_event":"2024-11-01T08:00:13.414170732Z","rtype":10,"publisher_id":2,"instrument_id":11667},"action":"T","side":"A","depth":0,"price":"134.930000000","size":3,"flags":130,"ts_in_delta":167036,"sequence":318355,"levels":[{"bid_px":"134.930000000","ask_px":"134.990000000","bid_sz":373,"ask_sz":10,"bid_ct":1,"ask_ct":1},{"bid_px":"134.500000000","ask_px":"135.000000000","bid_sz":520,"ask_sz":38,"bid_ct":2,"ask_ct":3},{"bid_px":"134.440000000","ask_px":"135.100000000","bid_sz":100,"ask_sz":10,"bid_ct":1,"ask_ct":1},{"bid_px":"134.410000000","ask_px":"135.230000000","bid_sz":61,"ask_sz":360,"bid_ct":2,"ask_ct":1},{"bid_px":"134.380000000","ask_px":"135.300000000","bid_sz":18,"ask_sz":1009,"bid_ct":1,"ask_ct":2},{"bid_px":"134.210000000","ask_px":"135.400000000","bid_sz":20,"ask_sz":10,"bid_ct":1,"ask_ct":1},{"bid_px":"134.200000000","ask_px":"135.420000000","bid_sz":3,"ask_sz":1,"bid_ct":1,"ask_ct":1},{"bid_px":"134.000000000","ask_px":"135.820000000","bid_sz":1,"ask_sz":1,"bid_ct":1,"ask_ct":1},{"bid_px":"133.800000000","ask_px":"135.910000000","bid_sz":5,"ask_sz":100,"bid_ct":1,"ask_ct":1},{"bid_px":"133.160000000","ask_px":"135.990000000","bid_sz":1,"ask_sz":20,"bid_ct":1,"ask_ct":1}],"symbol":"NVDA"}
{"ts_recv":"2024-11-01T08:00:13.414337768Z","hd":{"ts_event":"2024-11-01T08:00:13.414170732Z","rtype":10,"publisher_id":2,"instrument_id":11667},"action":"C","side":"B","depth":0,"price":"134.930000000","size":3,"flags":130,"ts_in_delta":167036,"sequence":318355,"levels":[{"bid_px":"134.930000000","ask_px":"134.990000000","bid_sz":370,"ask_sz":10,"bid_ct":1,"ask_ct":1},{"bid_px":"134.500000000","ask_px":"135.000000000","bid_sz":520,"ask_sz":38,"bid_ct":2,"ask_ct":3},{"bid_px":"134.440000000","ask_px":"135.100000000","bid_sz":100,"ask_sz":10,"bid_ct":1,"ask_ct":1},{"bid_px":"134.410000000","ask_px":"135.230000000","bid_sz":61,"ask_sz":360,"bid_ct":2,"ask_ct":1},{"bid_px":"134.380000000","ask_px":"135.300000000","bid_sz":18,"ask_sz":1009,"bid_ct":1,"ask_ct":2},{"bid_px":"134.210000000","ask_px":"135.400000000","bid_sz":20,"ask_sz":10,"bid_ct":1,"ask_ct":1},{"bid_px":"134.200000000","ask_px":"135.420000000","bid_sz":3,"ask_sz":1,"bid_ct":1,"ask_ct":1},{"bid_px":"134.000000000","ask_px":"135.820000000","bid_sz":1,"ask_sz":1,"bid_ct":1,"ask_ct":1},{"bid_px":"133.800000000","ask_px":"135.910000000","bid_sz":5,"ask_sz":100,"bid_ct":1,"ask_ct":1},{"bid_px":"133.160000000","ask_px":"135.990000000","bid_sz":1,"ask_sz":20,"bid_ct":1,"ask_ct":1}],"symbol":"NVDA"}
{"ts_recv":"2024-11-01T08:00:13.414369017Z","hd":{"ts_event":"2024-11-01T08:00:13.414202196Z","rtype":10,"publisher_id":2,"instrument_id":11667},"action":"T","side":"A","depth":0,"price":"134.930000000","size":29,"flags":130,"ts_in_delta":166821,"sequence":318356,"levels":[{"bid_px":"134.930000000","ask_px":"134.990000000","bid_sz":370,"ask_sz":10,"bid_ct":1,"ask_ct":1},{"bid_px":"134.500000000","ask_px":"135.000000000","bid_sz":520,"ask_sz":38,"bid_ct":2,"ask_ct":3},{"bid_px":"134.440000000","ask_px":"135.100000000","bid_sz":100,"ask_sz":10,"bid_ct":1,"ask_ct":1},{"bid_px":"134.410000000","ask_px":"135.230000000","bid_sz":61,"ask_sz":360,"bid_ct":2,"ask_ct":1},{"bid_px":"134.380000000","ask_px":"135.300000000","bid_sz":18,"ask_sz":1009,"bid_ct":1,"ask_ct":2},{"bid_px":"134.210000000","ask_px":"135.400000000","bid_sz":20,"ask_sz":10,"bid_ct":1,"ask_ct":1},{"bid_px":"134.200000000","ask_px":"135.420000000","bid_sz":3,"ask_sz":1,"bid_ct":1,"ask_ct":1},{"bid_px":"134.000000000","ask_px":"135.820000000","bid_sz":1,"ask_sz":1,"bid_ct":1,"ask_ct":1},{"bid_px":"133.800000000","ask_px":"135.910000000","bid_sz":5,"ask_sz":100,"bid_ct":1,"ask_ct":1},{"bid_px":"133.160000000","ask_px":"135.990000000","bid_sz":1,"ask_sz":20,"bid_ct":1,"ask_ct":1}],"symbol":"NVDA"}
{"ts_recv":"2024-11-01T08:00:13.414369017Z","hd":{"ts_event":"2024-11-01T08:00:13.414202196Z","rtype":10,"publisher_id":2,"instrument_id":11667},"action":"C","side":"B","depth":0,"price":"134.930000000","size":29,"flags":130,"ts_in_delta":166821,"sequence":318356,"levels":[{"bid_px":"134.930000000","ask_px":"134.990000000","bid_sz":341,"ask_sz":10,"bid_ct":1,"ask_ct":1},{"bid_px":"134.500000000","ask_px":"135.000000000","bid_sz":520,"ask_sz":38,"bid_ct":2,"ask_ct":3},{"bid_px":"134.440000000","ask_px":"135.100000000","bid_sz":100,"ask_sz":10,"bid_ct":1,"ask_ct":1},{"bid_px":"134.410000000","ask_px":"135.230000000","bid_sz":61,"ask_sz":360,"bid_ct":2,"ask_ct":1},{"bid_px":"134.380000000","ask_px":"135.300000000","bid_sz":18,"ask_sz":1009,"bid_ct":1,"ask_ct":2},{"bid_px":"134.210000000","ask_px":"135.400000000","bid_sz":20,"ask_sz":10,"bid_ct":1,"ask_ct":1},{"bid_px":"134.200000000","ask_px":"135.420000000","bid_sz":3,"ask_sz":1,"bid_ct":1,"ask_ct":1},{"bid_px":"134.000000000","ask_px":"135.820000000","bid_sz":1,"ask_sz":1,"bid_ct":1,"ask_ct":1},{"bid_px":"133.800000000","ask_px":"135.910000000","bid_sz":5,"ask_sz":100,"bid_ct":1,"ask_ct":1},{"bid_px":"133.160000000","ask_px":"135.990000000","bid_sz":1,"ask_sz":20,"bid_ct":1,"ask_ct":1}],"symbol":"NVDA"}
{"ts_recv":"2024-11-01T08:00:13.414485326Z","hd":{"ts_event":"2024-11-01T08:00:13.414318861Z","rtype":10,"publisher_id":2,"instrument_id":11667},"action":"T","side":"A","depth":0,"price":"134.930000000","size":1,"flags":130,"ts_in_delta":166465,"sequence":318357,"levels":[{"bid_px":"134.930000000","ask_px":"134.990000000","bid_sz":341,"ask_sz":10,"bid_ct":1,"ask_ct":1},{"bid_px":"134.500000000","ask_px":"135.000000000","bid_sz":520,"ask_sz":38,"bid_ct":2,"ask_ct":3},{"bid_px":"134.440000000","ask_px":"135.100000000","bid_sz":100,"ask_sz":10,"bid_ct":1,"ask_ct":1},{"bid_px":"134.410000000","ask_px":"135.230000000","bid_sz":61,"ask_sz":360,"bid_ct":2,"ask_ct":1},{"bid_px":"134.380000000","ask_px":"135.300000000","bid_sz":18,"ask_sz":1009,"bid_ct":1,"ask_ct":2},{"bid_px":"134.210000000","ask_px":"135.400000000","bid_sz":20,"ask_sz":10,"bid_ct":1,"ask_ct":1},{"bid_px":"134.200000000","ask_px":"135.420000000","bid_sz":3,"ask_sz":1,"bid_ct":1,"ask_ct":1},{"bid_px":"134.000000000","ask_px":"135.820000000","bid_sz":1,"ask_sz":1,"bid_ct":1,"ask_ct":1},{"bid_px":"133.800000000","ask_px":"135.910000000","bid_sz":5,"ask_sz":100,"bid_ct":1,"ask_ct":1},{"bid_px":"133.160000000","ask_px":"135.990000000","bid_sz":1,"ask_sz":20,"bid_ct":1,"ask_ct":1}],"symbol":"NVDA"}
{"ts_recv":"2024-11-01T08:00:13.414485326Z","hd":{"ts_event":"2024-11-01T08:00:13.414318861Z","rtype":10,"publisher_id":2,"instrument_id":11667},"action":"C","side":"B","depth":0,"price":"134.930000000","size":1,"flags":130,"ts_in_delta":166465,"sequence":318357,"levels":[{"bid_px":"134.930000000","ask_px":"134.990000000","bid_sz":340,"ask_sz":10,"bid_ct":1,"ask_ct":1},{"bid_px":"134.500000000","ask_px":"135.000000000","bid_sz":520,"ask_sz":38,"bid_ct":2,"ask_ct":3},{"bid_px":"134.440000000","ask_px":"135.100000000","bid_sz":100,"ask_sz":10,"bid_ct":1,"ask_ct":1},{"bid_px":"134.410000000","ask_px":"135.230000000","bid_sz":61,"ask_sz":360,"bid_ct":2,"ask_ct":1},{"bid_px":"134.380000000","ask_px":"135.300000000","bid_sz":18,"ask_sz":1009,"bid_ct":1,"ask_ct":2},{"bid_px":"134.210000000","ask_px":"135.400000000","bid_sz":20,"ask_sz":10,"bid_ct":1,"ask_ct":1},{"bid_px":"134.200000000","ask_px":"135.420000000","bid_sz":3,"ask_sz":1,"bid_ct":1,"ask_ct":1},{"bid_px":"134.000000000","ask_px":"135.820000000","bid_sz":1,"ask_sz":1,"bid_ct":1,"ask_ct":1},{"bid_px":"133.800000000","ask_px":"135.910000000","bid_sz":5,"ask_sz":100,"bid_ct":1,"ask_ct":1},{"bid_px":"133.160000000","ask_px":"135.990000000","bid_sz":1,"ask_sz":20,"bid_ct":1,"ask_ct":1}],"symbol":"NVDA"}
{"ts_recv":"2024-11-01T08:00:13.414546146Z","hd":{"ts_event":"2024-11-01T08:00:13.414370627Z","rtype":10,"publisher_id":2,"instrument_id":11667},"action":"T","side":"A","depth":0,"price":"134.930000000","size":3,"flags":130,"ts_in_delta":175519,"sequence":318358,"levels":[{"bid_px":"134.930000000","ask_px":"134.990000000","bid_sz":340,"ask_sz":10,"bid_ct":1,"ask_ct":1},{"bid_px":"134.500000000","ask_px":"135.000000000","bid_sz":520,"ask_sz":38,"bid_ct":2,"ask_ct":3},{"bid_px":"134.440000000","ask_px":"135.100000000","bid_sz":100,"ask_sz":10,"bid_ct":1,"ask_ct":1},{"bid_px":"134.410000000","ask_px":"135.230000000","bid_sz":61,"ask_sz":360,"bid_ct":2,"ask_ct":1},{"bid_px":"134.380000000","ask_px":"135.300000000","bid_sz":18,"ask_sz":1009,"bid_ct":1,"ask_ct":2},{"bid_px":"134.210000000","ask_px":"135.400000000","bid_sz":20,"ask_sz":10,"bid_ct":1,"ask_ct":1},{"bid_px":"134.200000000","ask_px":"135.420000000","bid_sz":3,"ask_sz":1,"bid_ct":1,"ask_ct":1},{"bid_px":"134.000000000","ask_px":"135.820000000","bid_sz":1,"ask_sz":1,"bid_ct":1,"ask_ct":1},{"bid_px":"133.800000000","ask_px":"135.910000000","bid_sz":5,"ask_sz":100,"bid_ct":1,"ask_ct":1},{"bid_px":"133.160000000","ask_px":"135.990000000","bid_sz":1,"ask_sz":20,"bid_ct":1,"ask_ct":1}],"symbol":"NVDA"}
{"ts_recv":"2024-11-01T08:00:13.414546146Z","hd":{"ts_event":"2024-11-01T08:00:13.414370627Z","rtype":10,"publisher_id":2,"instrument_id":11667},"action":"C","side":"B","depth":0,"price":"134.930000000","size":3,"flags":130,"ts_in_delta":175519,"sequence":318358,"levels":[{"bid_px":"134.930000000","ask_px":"134.990000000","bid_sz":337,"ask_sz":10,"bid_ct":1,"ask_ct":1},{"bid_px":"134.500000000","ask_px":"135.000000000","bid_sz":520,"ask_sz":38,"bid_ct":2,"ask_ct":3},{"bid_px":"134.440000000","ask_px":"135.100000000","bid_sz":100,"ask_sz":10,"bid_ct":1,"ask_ct":1},{"bid_px":"134.410000000","ask_px":"135.230000000","bid_sz":61,"ask_sz":360,"bid_ct":2,"ask_ct":1},{"bid_px":"134.380000000","ask_px":"135.300000000","bid_sz":18,"ask_sz":1009,"bid_ct":1,"ask_ct":2},{"bid_px":"134.210000000","ask_px":"135.400000000","bid_sz":20,"ask_sz":10,"bid_ct":1,"ask_ct":1},{"bid_px":"134.200000000","ask_px":"135.420000000","bid_sz":3,"ask_sz":1,"bid_ct":1,"ask_ct":1},{"bid_px":"134.000000000","ask_px":"135.820000000","bid_sz":1,"ask_sz":1,"bid_ct":1,"ask_ct":1},{"bid_px":"133.800000000","ask_px":"135.910000000","bid_sz":5,"ask_sz":100,"bid_ct":1,"ask_ct":1},{"bid_px":"133.160000000","ask_px":"135.990000000","bid_sz":1,"ask_sz":20,"bid_ct":1,"ask_ct":1}],"symbol":"NVDA"}
{"ts_recv":"2024-11-01T08:00:13.414583816Z","hd":{"ts_event":"2024-11-01T08:00:13.414417344Z","rtype":10,"publisher_id":2,"instrument_id":11667},"action":"T","side":"A","depth":0,"price":"134.930000000","size":5,"flags":130,"ts_in_delta":166472,"sequence":318359,"levels":[{"bid_px":"134.930000000","ask_px":"134.990000000","bid_sz":337,"ask_sz":10,"bid_ct":1,"ask_ct":1},{"bid_px":"134.500000000","ask_px":"135.000000000","bid_sz":520,"ask_sz":38,"bid_ct":2,"ask_ct":3},{"bid_px":"134.440000000","ask_px":"135.100000000","bid_sz":100,"ask_sz":10,"bid_ct":1,"ask_ct":1},{"bid_px":"134.410000000","ask_px":"135.230000000","bid_sz":61,"ask_sz":360,"bid_ct":2,"ask_ct":1},{"bid_px":"134.380000000","ask_px":"135.300000000","bid_sz":18,"ask_sz":1009,"bid_ct":1,"ask_ct":2},{"bid_px":"134.210000000","ask_px":"135.400000000","bid_sz":20,"ask_sz":10,"bid_ct":1,"ask_ct":1},{"bid_px":"134.200000000","ask_px":"135.420000000","bid_sz":3,"ask_sz":1,"bid_ct":1,"ask_ct":1},{"bid_px":"134.000000000","ask_px":"135.820000000","bid_sz":1,"ask_sz":1,"bid_ct":1,"ask_ct":1},{"bid_px":"133.800000000","ask_px":"135.910000000","bid_sz":5,"ask_sz":100,"bid_ct":1,"ask_ct":1},{"bid_px":"133.160000000","ask_px":"135.990000000","bid_sz":1,"ask_sz":20,"bid_ct":1,"ask_ct":1}],"symbol":"NVDA"}
{"ts_recv":"2024-11-01T08:00:13.414583816Z","hd":{"ts_event":"2024-11-01T08:00:13.414417344Z","rtype":10,"publisher_id":2,"instrument_id":11667},"action":"C","side":"B","depth":0,"price":"134.930000000","size":5,"flags":130,"ts_in_delta":166472,"sequence":318359,"levels":[{"bid_px":"134.930000000","ask_px":"134.990000000","bid_sz":332,"ask_sz":10,"bid_ct":1,"ask_ct":1},{"bid_px":"134.500000000","ask_px":"135.000000000","bid_sz":520,"ask_sz":38,"bid_ct":2,"ask_ct":3},{"bid_px":"134.440000000","ask_px":"135.100000000","bid_sz":100,"ask_sz":10,"bid_ct":1,"ask_ct":1},{"bid_px":"134.410000000","ask_px":"135.230000000","bid_sz":61,"ask_sz":360,"bid_ct":2,"ask_ct":1},{"bid_px":"134.380000000","ask_px":"135.300000000","bid_sz":18,"ask_sz":1009,"bid_ct":1,"ask_ct":2},{"bid_px":"134.210000000","ask_px":"135.400000000","bid_sz":20,"ask_sz":10,"bid_ct":1,"ask_ct":1},{"bid_px":"134.200000000","ask_px":"135.420000000","bid_sz":3,"ask_sz":1,"bid_ct":1,"ask_ct":1},{"bid_px":"134.000000000","ask_px":"135.820000000","bid_sz":1,"ask_sz":1,"bid_ct":1,"ask_ct":1},{"bid_px":"133.800000000","ask_px":"135.910000000","bid_sz":5,"ask_sz":100,"bid_ct":1,"ask_ct":1},{"bid_px":"133.160000000","ask_px":"135.990000000","bid_sz":1,"ask_sz":20,"bid_ct":1,"ask_ct":1}],"symbol":"NVDA"}
{"ts_recv":"2024-11-01T08:00:13.414688138Z","hd":{"ts_event":"2024-11-01T08:00:13.414520069Z","rtype":10,"publisher_id":2,"instrument_id":11667},"action":"T","side":"A","depth":0,"price":"134.930000000","size":1,"flags":128,"ts_in_delta":168069,"sequence":318360,"levels":[{"bid_px":"134.930000000","ask_px":"134.990000000","bid_sz":332,"ask_sz":10,"bid_ct":1,"ask_ct":1},{"bid_px":"134.500000000","ask_px":"135.000000000","bid_sz":520,"ask_sz":38,"bid_ct":2,"ask_ct":3},{"bid_px":"134.440000000","ask_px":"135.100000000","bid_sz":100,"ask_sz":10,"bid_ct":1,"ask_ct":1},{"bid_px":"134.410000000","ask_px":"135.230000000","bid_sz":61,"ask_sz":360,"bid_ct":2,"ask_ct":1},{"bid_px":"134.380000000","ask_px":"135.300000000","bid_sz":18,"ask_sz":1009,"bid_ct":1,"ask_ct":2},{"bid_px":"134.210000000","ask_px":"135.400000000","bid_sz":20,"ask_sz":10,"bid_ct":1,"ask_ct":1},{"bid_px":"134.200000000","ask_px":"135.420000000","bid_sz":3,"ask_sz":1,"bid_ct":1,"ask_ct":1},{"bid_px":"134.000000000","ask_px":"135.820000000","bid_sz":1,"ask_sz":1,"bid_ct":1,"ask_ct":1},{"bid_px":"133.800000000","ask_px":"135.910000000","bid_sz":5,"ask_sz":100,"bid_ct":1,"ask_ct":1},{"bid_px":"133.160000000","ask_px":"135.990000000","bid_sz":1,"ask_sz":20,"bid_ct":1,"ask_ct":1}],"symbol":"NVDA"}
{"ts_recv":"2024-11-01T08:00:13.414688138Z","hd":{"ts_event":"2024-11-01T08:00:13.414520069Z","rtype":10,"publisher_id":2,"instrument_id":11667},"action":"C","side":"B","depth":0,"price":"134.930000000","size":1,"flags":128,"ts_in_delta":168069,"sequence":318360,"levels":[{"bid_px":"134.930000000","ask_px":"134.990000000","bid_sz":331,"ask_sz":10,"bid_ct":1,"ask_ct":1},{"bid_px":"134.500000000","ask_px":"135.000000000","bid_sz":520,"ask_sz":38,"bid_ct":2,"ask_ct":3},{"bid_px":"134.440000000","ask_px":"135.100000000","bid_sz":100,"ask_sz":10,"bid_ct":1,"ask_ct":1},{"bid_px":"134.410000000","ask_px":"135.230000000","bid_sz":61,"ask_sz":360,"bid_ct":2,"ask_ct":1},{"bid_px":"134.380000000","ask_px":"135.300000000","bid_sz":18,"ask_sz":1009,"bid_ct":1,"ask_ct":2},{"bid_px":"134.210000000","ask_px":"135.400000000","bid_sz":20,"ask_sz":10,"bid_ct":1,"ask_ct":1},{"bid_px":"134.200000000","ask_px":"135.420000000","bid_sz":3,"ask_sz":1,"bid_ct":1,"ask_ct":1},{"bid_px":"134.000000000","ask_px":"135.820000000","bid_sz":1,"ask_sz":1,"bid_ct":1,"ask_ct":1},{"bid_px":"133.800000000","ask_px":"135.910000000","bid_sz":5,"ask_sz":100,"bid_ct":1,"ask_ct":1},{"bid_px":"133.160000000","ask_px":"135.990000000","bid_sz":1,"ask_sz":20,"bid_ct":1,"ask_ct":1}],"symbol":"NVDA"}
{"ts_recv":"2024-11-01T08:00:13.414798341Z","hd":{"ts_event":"2024-11-01T08:00:13.414631570Z","rtype":10,"publisher_id":2,"instrument_id":11667},"action":"T","side":"A","depth":0,"price":"134.930000000","size":1,"flags":130,"ts_in_delta":166771,"sequence":318362,"levels":[{"bid_px":"134.930000000","ask_px":"134.990000000","bid_sz":331,"ask_sz":10,"bid_ct":1,"ask_ct":1},{"bid_px":"134.500000000","ask_px":"135.000000000","bid_sz":520,"ask_sz":38,"bid_ct":2,"ask_ct":3},{"bid_px":"134.440000000","ask_px":"135.100000000","bid_sz":100,"ask_sz":10,"bid_ct":1,"ask_ct":1},{"bid_px":"134.410000000","ask_px":"135.230000000","bid_sz":61,"ask_sz":360,"bid_ct":2,"ask_ct":1},{"bid_px":"134.380000000","ask_px":"135.300000000","bid_sz":18,"ask_sz":1009,"bid_ct":1,"ask_ct":2},{"bid_px":"134.210000000","ask_px":"135.400000000","bid_sz":20,"ask_sz":10,"bid_ct":1,"ask_ct":1},{"bid_px":"134.200000000","ask_px":"135.420000000","bid_sz":3,"ask_sz":1,"bid_ct":1,"ask_ct":1},{"bid_px":"134.000000000","ask_px":"135.820000000","bid_sz":1,"ask_sz":1,"bid_ct":1,"ask_ct":1},{"bid_px":"133.800000000","ask_px":"135.910000000","bid_sz":5,"ask_sz":100,"bid_ct":1,"ask_ct":1},{"bid_px":"133.160000000","ask_px":"135.990000000","bid_sz":1,"ask_sz":20,"bid_ct":1,"ask_ct":1}],"symbol":"NVDA"}
{"ts_recv":"2024-11-01T08:00:13.414798341Z","hd":{"ts_event":"2024-11-01T08:00:13.414631570Z","rtype":10,"publisher_id":2,"instrument_id":11667},"action":"C","side":"B","depth":0,"price":"134.930000000","size":1,"flags":130,"ts_in_delta":166771,"sequence":318362,"levels":[{"bid_px":"134.930000000","ask_px":"134.990000000","bid_sz":330,"ask_sz":10,"bid_ct":1,"ask_ct":1},{"bid_px":"134.500000000","ask_px":"135.000000000","bid_sz":520,"ask_sz":38,"bid_ct":2,"ask_ct":3},{"bid_px":"134.440000000","ask_px":"135.100000000","bid_sz":100,"ask_sz":10,"bid_ct":1,"ask_ct":1},{"bid_px":"134.410000000","ask_px":"135.230000000","bid_sz":61,"ask_sz":360,"bid_ct":2,"ask_ct":1},{"bid_px":"134.380000000","ask_px":"135.300000000","bid_sz":18,"ask_sz":1009,"bid_ct":1,"ask_ct":2},{"bid_px":"134.210000000","ask_px":"135.400000000","bid_sz":20,"ask_sz":10,"bid_ct":1,"ask_ct":1},{"bid_px":"134.200000000","ask_px":"135.420000000","bid_sz":3,"ask_sz":1,"bid_ct":1,"ask_ct":1},{"bid_px":"134.000000000","ask_px":"135.820000000","bid_sz":1,"ask_sz":1,"bid_ct":1,"ask_ct":1},{"bid_px":"133.800000000","ask_px":"135.910000000","bid_sz":5,"ask_sz":100,"bid_ct":1,"ask_ct":1},{"bid_px":"133.160000000","ask_px":"135.990000000","bid_sz":1,"ask_sz":20,"bid_ct":1,"ask_ct":1}],"symbol":"NVDA"}
{"ts_recv":"2024-11-01T08:00:13.415031779Z","hd":{"ts_event":"2024-11-01T08:00:13.414865847Z","rtype":10,"publisher_id":2,"instrument_id":11667},"action":"A","side":"B","depth":1,"price":"134.660000000","size":54,"flags":130,"ts_in_delta":165932,"sequence":318364,"levels":[{"bid_px":"134.930000000","ask_px":"134.990000000","bid_sz":330,"ask_sz":10,"bid_ct":1,"ask_ct":1},{"bid_px":"134.660000000","ask_px":"135.000000000","bid_sz":54,"ask_sz":38,"bid_ct":1,"ask_ct":3},{"bid_px":"134.500000000","ask_px":"135.100000000","bid_sz":520,"ask_sz":10,"bid_ct":2,"ask_ct":1},{"bid_px":"134.440000000","ask_px":"135.230000000","bid_sz":100,"ask_sz":360,"bid_ct":1,"ask_ct":1},{"bid_px":"134.410000000","ask_px":"135.300000000","bid_sz":61,"ask_sz":1009,"bid_ct":2,"ask_ct":2},{"bid_px":"134.380000000","ask_px":"135.400000000","bid_sz":18,"ask_sz":10,"bid_ct":1,"ask_ct":1},{"bid_px":"134.210000000","ask_px":"135.420000000","bid_sz":20,"ask_sz":1,"bid_ct":1,"ask_ct":1},{"bid_px":"134.200000000","ask_px":"135.820000000","bid_sz":3,"ask_sz":1,"bid_ct":1,"ask_ct":1},{"bid_px":"134.000000000","ask_px":"135.910000000","bid_sz":1,"ask_sz":100,"bid_ct":1,"ask_ct":1},{"bid_px":"133.800000000","ask_px":"135.990000000","bid_sz":5,"ask_sz":20,"bid_ct":1,"ask_ct":1}],"symbol":"NVDA"}
{"ts_recv":"2024-11-01T08:00:13.415352573Z","hd":{"ts_event":"2024-11-01T08:00:13.415185963Z","rtype":10,"publisher_id":2,"instrument_id":11667},"action":"T","side":"A","depth":0,"price":"134.930000000","size":14,"flags":130,"ts_in_delta":166610,"sequence":318365,"levels":[{"bid_px":"134.930000000","ask_px":"134.990000000","bid_sz":330,"ask_sz":10,"bid_ct":1,"ask_ct":1},{"bid_px":"134.660000000","ask_px":"135.000000000","bid_sz":54,"ask_sz":38,"bid_ct":1,"ask_ct":3},{"bid_px":"134.500000000","ask_px":"135.100000000","bid_sz":520,"ask_sz":10,"bid_ct":2,"ask_ct":1},{"bid_px":"134.440000000","ask_px":"135.230000000","bid_sz":100,"ask_sz":360,"bid_ct":1,"ask_ct":1},{"bid_px":"134.410000000","ask_px":"135.300000000","bid_sz":61,"ask_sz":1009,"bid_ct":2,"ask_ct":2},{"bid_px":"134.380000000","ask_px":"135.400000000","bid_sz":18,"ask_sz":10,"bid_ct":1,"ask_ct":1},{"bid_px":"134.210000000","ask_px":"135.420000000","bid_sz":20,"ask_sz":1,"bid_ct":1,"ask_ct":1},{"bid_px":"134.200000000","ask_px":"135.820000000","bid_sz":3,"ask_sz":1,"bid_ct":1,"ask_ct":1},{"bid_px":"134.000000000","ask_px":"135.910000000","bid_sz":1,"ask_sz":100,"bid_ct":1,"ask_ct":1},{"bid_px":"133.800000000","ask_px":"135.990000000","bid_sz":5,"ask_sz":20,"bid_ct":1,"ask_ct":1}],"symbol":"NVDA"}
{"ts_recv":"2024-11-01T08:00:13.415352573Z","hd":{"ts_event":"2024-11-01T08:00:13.415185963Z","rtype":10,"publisher_id":2,"instrument_id":11667},"action":"C","side":"B","depth":0,"price":"134.930000000","size":14,"flags":130,"ts_in_delta":166610,"sequence":318365,"levels":[{"bid_px":"134.930000000","ask_px":"134.990000000","bid_sz":316,"ask_sz":10,"bid_ct":1,"ask_ct":1},{"bid_px":"134.660000000","ask_px":"135.000000000","bid_sz":54,"ask_sz":38,"bid_ct":1,"ask_ct":3},{"bid_px":"134.500000000","ask_px":"135.100000000","bid_sz":520,"ask_sz":10,"bid_ct":2,"ask_ct":1},{"bid_px":"134.440000000","ask_px":"135.230000000","bid_sz":100,"ask_sz":360,"bid_ct":1,"ask_ct":1},{"bid_px":"134.410000000","ask_px":"135.300000000","bid_sz":61,"ask_sz":1009,"bid_ct":2,"ask_ct":2},{"bid_px":"134.380000000","ask_px":"135.400000000","bid_sz":18,"ask_sz":10,"bid_ct":1,"ask_ct":1},{"bid_px":"134.210000000","ask_px":"135.420000000","bid_sz":20,"ask_sz":1,"bid_ct":1,"ask_ct":1},{"bid_px":"134.200000000","ask_px":"135.820000000","bid_sz":3,"ask_sz":1,"bid_ct":1,"ask_ct":1},{"bid_px":"134.000000000","ask_px":"135.910000000","bid_sz":1,"ask_sz":100,"bid_ct":1,"ask_ct":1},{"bid_px":"133.800000000","ask_px":"135.990000000","bid_sz":5,"ask_sz":20,"bid_ct":1,"ask_ct":1}],"symbol":"NVDA"}
{"ts_recv":"2024-11-01T08:00:13.420067566Z","hd":{"ts_event":"2024-11-01T08:00:13.419900772Z","rtype":10,"publisher_id":2,"instrument_id":11667},"action":"T","side":"A","depth":0,"price":"134.930000000","size":1,"flags":130,"ts_in_delta":166794,"sequence":318375,"levels":[{"bid_px":"134.930000000","ask_px":"134.990000000","bid_sz":316,"ask_sz":10,"bid_ct":1,"ask_ct":1},{"bid_px":"134.660000000","ask_px":"135.000000000","bid_sz":54,"ask_sz":38,"bid_ct":1,"ask_ct":3},{"bid_px":"134.500000000","ask_px":"135.100000000","bid_sz":520,"ask_sz":10,"bid_ct":2,"ask_ct":1},{"bid_px":"134.440000000","ask_px":"135.230000000","bid_sz":100,"ask_sz":360,"bid_ct":1,"ask_ct":1},{"bid_px":"134.410000000","ask_px":"135.300000000","bid_sz":61,"ask_sz":1009,"bid_ct":2,"ask_ct":2},{"bid_px":"134.380000000","ask_px":"135.400000000","bid_sz":18,"ask_sz":10,"bid_ct":1,"ask_ct":1},{"bid_px":"134.210000000","ask_px":"135.420000000","bid_sz":20,"ask_sz":1,"bid_ct":1,"ask_ct":1},{"bid_px":"134.200000000","ask_px":"135.820000000","bid_sz":3,"ask_sz":1,"bid_ct":1,"ask_ct":1},{"bid_px":"134.000000000","ask_px":"135.910000000","bid_sz":1,"ask_sz":100,"bid_ct":1,"ask_ct":1},{"bid_px":"133.800000000","ask_px":"135.990000000","bid_sz":5,"ask_sz":20,"bid_ct":1,"ask_ct":1}],"symbol":"NVDA"}
{"ts_recv":"2024-11-01T08:00:13.420067566Z","hd":{"ts_event":"2024-11-01T08:00:13.419900772Z","rtype":10,"publisher_id":2,"instrument_id":11667},"action":"C","side":"B","depth":0,"price":"134.930000000","size":1,"flags":130,"ts_in_delta":166794,"sequence":318375,"levels":[{"bid_px":"134.930000000","ask_px":"134.990000000","bid_sz":315,"ask_sz":10,"bid_ct":1,"ask_ct":1},{"bid_px":"134.660000000","ask_px":"135.000000000","bid_sz":54,"ask_sz":38,"bid_ct":1,"ask_ct":3},{"bid_px":"134.500000000","ask_px":"135.100000000","bid_sz":520,"ask_sz":10,"bid_ct":2,"ask_ct":1},{"bid_px":"134.440000000","ask_px":"135.230000000","bid_sz":100,"ask_sz":360,"bid_ct":1,"ask_ct":1},{"bid_px":"134.410000000","ask_px":"135.300000000","bid_sz":61,"ask_sz":1009,"bid_ct":2,"ask_ct":2},{"bid_px":"134.380000000","ask_px":"135.400000000","bid_sz":18,"ask_sz":10,"bid_ct":1,"ask_ct":1},{"bid_px":"134.210000000","ask_px":"135.420000000","bid_sz":20,"ask_sz":1,"bid_ct":1,"ask_ct":1},{"bid_px":"134.200000000","ask_px":"135.820000000","bid_sz":3,"ask_sz":1,"bid_ct":1,"ask_ct":1},{"bid_px":"134.000000000","ask_px":"135.910000000","bid_sz":1,"ask_sz":100,"bid_ct":1,"ask_ct":1},{"bid_px":"133.800000000","ask_px":"135.990000000","bid_sz":5,"ask_sz":20,"bid_ct":1,"ask_ct":1}],"symbol":"NVDA"}
{"ts_recv":"2024-11-01T08:00:13.426205548Z","hd":{"ts_event":"2024-11-01T08:00:13.426039238Z","rtype":10,"publisher_id":2,"instrument_id":10888},"action":"A","side":"A","depth":9,"price":"450.000000000","size":36,"flags":130,"ts_in_delta":166310,"sequence":318399,"levels":[{"bid_px":"410.000000000","ask_px":"414.000000000","bid_sz":1,"ask_sz":468,"bid_ct":1,"ask_ct":2},{"bid_px":"409.750000000","ask_px":"415.070000000","bid_sz":3,"ask_sz":246,"bid_ct":1,"ask_ct":1},{"bid_px":"409.740000000","ask_px":"415.350000000","bid_sz":500,"ask_sz":84,"bid_ct":1,"ask_ct":2},{"bid_px":"409.670000000","ask_px":"419.860000000","bid_sz":100,"ask_sz":10,"bid_ct":1,"ask_ct":1},{"bid_px":"409.430000000","ask_px":"420.000000000","bid_sz":5,"ask_sz":3,"bid_ct":1,"ask_ct":1},{"bid_px":"409.250000000","ask_px":"440.000000000","bid_sz":2,"ask_sz":35,"bid_ct":1,"ask_ct":1},{"bid_px":"409.080000000","ask_px":"445.000000000","bid_sz":2,"ask_sz":25,"bid_ct":1,"ask_ct":1},{"bid_px":"409.000000000","ask_px":"445.680000000","bid_sz":3,"ask_sz":3,"bid_ct":2,"ask_ct":1},{"bid_px":"408.970000000","ask_px":"448.000000000","bid_sz":12,"ask_sz":15,"bid_ct":1,"ask_ct":2},{"bid_px":"408.960000000","ask_px":"450.000000000","bid_sz":5,"ask_sz":48,"bid_ct":1,"ask_ct":3}],"symbol":"MSFT"}
{"ts_recv":"2024-11-01T08:00:13.436280559Z","hd":{"ts_event":"2024-11-01T08:00:13.436114452Z","rtype":10,"publisher_id":2,"instrument_id":11667},"action":"A","side":"B","depth":3,"price":"134.440000000","size":100,"flags":130,"ts_in_delta":166107,"sequence":318414,"levels":[{"bid_px":"134.930000000","ask_px":"134.990000000","bid_sz":315,"ask_sz":10,"bid_ct":1,"ask_ct":1},{"bid_px":"134.660000000","ask_px":"135.000000000","bid_sz":54,"ask_sz":38,"bid_ct":1,"ask_ct":3},{"bid_px":"134.500000000","ask_px":"135.100000000","bid_sz":520,"ask_sz":10,"bid_ct":2,"ask_ct":1},{"bid_px":"134.440000000","ask_px":"135.230000000","bid_sz":200,"ask_sz":360,"bid_ct":2,"ask_ct":1},{"bid_px":"134.410000000","ask_px":"135.300000000","bid_sz":61,"ask_sz":1009,"bid_ct":2,"ask_ct":2},{"bid_px":"134.380000000","ask_px":"135.400000000","bid_sz":18,"ask_sz":10,"bid_ct":1,"ask_ct":1},{"bid_px":"134.210000000","ask_px":"135.420000000","bid_sz":20,"ask_sz":1,"bid_ct":1,"ask_ct":1},{"bid_px":"134.200000000","ask_px":"135.820000000","bid_sz":3,"ask_sz":1,"bid_ct":1,"ask_ct":1},{"bid_px":"134.000000000","ask_px":"135.910000000","bid_sz":1,"ask_sz":100,"bid_ct":1,"ask_ct":1},{"bid_px":"133.800000000","ask_px":"135.990000000","bid_sz":5,"ask_sz":20,"bid_ct":1,"ask_ct":1}],"symbol":"NVDA"}
{"ts_recv":"2024-11-01T08:00:13.438080735Z","hd":{"ts_event":"2024-11-01T08:00:13.437915091Z","rtype":10,"publisher_id":2,"instrument_id":11667},"action":"C","side":"B","depth":1,"price":"134.660000000","size":54,"flags":130,"ts_in_delta":165644,"sequence":318419,"levels":[{"bid_px":"134.930000000","ask_px":"134.990000000","bid_sz":315,"ask_sz":10,"bid_ct":1,"ask_ct":1},{"bid_px":"134.500000000","ask_px":"135.000000000","bid_sz":520,"ask_sz":38,"bid_ct":2,"ask_ct":3},{"bid_px":"134.440000000","ask_px":"135.100000000","bid_sz":200,"ask_sz":10,"bid_ct":2,"ask_ct":1},{"bid_px":"134.410000000","ask_px":"135.230000000","bid_sz":61,"ask_sz":360,"bid_ct":2,"ask_ct":1},{"bid_px":"134.380000000","ask_px":"135.300000000","bid_sz":18,"ask_sz":1009,"bid_ct":1,"ask_ct":2},{"bid_px":"134.210000000","ask_px":"135.400000000","bid_sz":20,"ask_sz":10,"bid_ct":1,"ask_ct":1},{"bid_px":"134.200000000","ask_px":"135.420000000","bid_sz":3,"ask_sz":1,"bid_ct":1,"ask_ct":1},{"bid_px":"134.000000000","ask_px":"135.820000000","bid_sz":1,"ask_sz":1,"bid_ct":1,"ask_ct":1},{"bid_px":"133.800000000","ask_px":"135.910000000","bid_sz":5,"ask_sz":100,"bid_ct":1,"ask_ct":1},{"bid_px":"133.160000000","ask_px":"135.990000000","bid_sz":1,"ask_sz":20,"bid_ct":1,"ask_ct":1}],"symbol":"NVDA"}
{"ts_recv":"2024-11-01T08:00:13.442108136Z","hd":{"ts_event":"2024-11-01T08:00:13.441942088Z","rtype":10,"publisher_id":2,"instrument_id":16244},"action":"A","side":"A","depth":7,"price":"254.990000000","size":5,"flags":130,"ts_in_delta":166048,"sequence":318427,"levels":[{"bid_px":"250.150000000","ask_px":"250.770000000","bid_sz":50,"ask_sz":6,"bid_ct":1,"ask_ct":1},{"bid_px":"250.000000000","ask_px":"251.130000000","bid_sz":2,"ask_sz":50,"bid_ct":2,"ask_ct":1},{"bid_px":"249.930000000","ask_px":"251.150000000","bid_sz":10,"ask_sz":100,"bid_ct":1,"ask_ct":1},{"bid_px":"249.880000000","ask_px":"251.500000000","bid_sz":4,"ask_sz":10,"bid_ct":1,"ask_ct":1},{"bid_px":"249.800000000","ask_px":"252.400000000","bid_sz":199,"ask_sz":1000,"bid_ct":1,"ask_ct":1},{"bid_px":"249.770000000","ask_px":"253.350000000","bid_sz":50,"ask_sz":23,"bid_ct":1,"ask_ct":1},{"bid_px":"249.500000000","ask_px":"253.650000000","bid_sz":1000,"ask_sz":400,"bid_ct":1,"ask_ct":1},{"bid_px":"249.000000000","ask_px":"254.990000000","bid_sz":100,"ask_sz":5,"bid_ct":1,"ask_ct":1},{"bid_px":"248.500000000","ask_px":"255.000000000","bid_sz":111,"ask_sz":85,"bid_ct":3,"ask_ct":2},{"bid_px":"247.150000000","ask_px":"258.000000000","bid_sz":400,"ask_sz":200,"bid_ct":1,"ask_ct":1}],"symbol":"TSLA"}
{"ts_recv":"2024-11-01T08:00:13.452403627Z","hd":{"ts_event":"2024-11-01T08:00:13.452236643Z","rtype":10,"publisher_id":2,"instrument_id":16244},"action":"T","side":"N","depth":0,"price":"250.760000000","size":6,"flags":130,"ts_in_delta":166984,"sequence":318449,"levels":[{"bid_px":"250.150000000","ask_px":"250.770000000","bid_sz":50,"ask_sz":6,"bid_ct":1,"ask_ct":1},{"bid_px":"250.000000000","ask_px":"251.130000000","bid_sz":2,"ask_sz":50,"bid_ct":2,"ask_ct":1},{"bid_px":"249.930000000","ask_px":"251.150000000","bid_sz":10,"ask_sz":100,"bid_ct":1,"ask_ct":1},{"bid_px":"249.880000000","ask_px":"251.500000000","bid_sz":4,"ask_sz":10,"bid_ct":1,"ask_ct":1},{"bid_px":"249.800000000","ask_px":"252.400000000","bid_sz":199,"ask_sz":1000,"bid_ct":1,"ask_ct":1},{"bid_px":"249.770000000","ask_px":"253.350000000","bid_sz":50,"ask_sz":23,"bid_ct":1,"ask_ct":1},{"bid_px":"249.500000000","ask_px":"253.650000000","bid_sz":1000,"ask_sz":400,"bid_ct":1,"ask_ct":1},{"bid_px":"249.000000000","ask_px":"254.990000000","bid_sz":100,"ask_sz":5,"bid_ct":1,"ask_ct":1},{"bid_px":"248.500000000","ask_px":"255.000000000","bid_sz":111,"ask_sz":85,"bid_ct":3,"ask_ct":2},{"bid_px":"247.150000000","ask_px":"258.000000000","bid_sz":400,"ask_sz":200,"bid_ct":1,"ask_ct":1}],"symbol":"TSLA"}
{"ts_recv":"2024-11-01T08:00:13.452455678Z","hd":{"ts_event":"2024-11-01T08:00:13.452289609Z","rtype":10,"publisher_id":2,"instrument_id":16244},"action":"A","side":"B","depth":0,"price":"250.450000000","size":1,"flags":130,"ts_in_delta":166069,"sequence":318450,"levels":[{"bid_px":"250.450000000","ask_px":"250.770000000","bid_sz":1,"ask_sz":6,"bid_ct":1,"ask_ct":1},{"bid_px":"250.150000000","ask_px":"251.130000000","bid_sz":50,"ask_sz":50,"bid_ct":1,"ask_ct":1},{"bid_px":"250.000000000","ask_px":"251.150000000","bid_sz":2,"ask_sz":100,"bid_ct":2,"ask_ct":1},{"bid_px":"249.930000000","ask_px":"251.500000000","bid_sz":10,"ask_sz":10,"bid_ct":1,"ask_ct":1},{"bid_px":"249.880000000","ask_px":"252.400000000","bid_sz":4,"ask_sz":1000,"bid_ct":1,"ask_ct":1},{"bid_px":"249.800000000","ask_px":"253.350000000","bid_sz":199,"ask_sz":23,"bid_ct":1,"ask_ct":1},{"bid_px":"249.770000000","ask_px":"253.650000000","bid_sz":50,"ask_sz":400,"bid_ct":1,"ask_ct":1},{"bid_px":"249.500000000","ask_px":"254.990000000","bid_sz":1000,"ask_sz":5,"bid_ct":1,"ask_ct":1},{"bid_px":"249.000000000","ask_px":"255.000000000","bid_sz":100,"ask_sz":85,"bid_ct":1,"ask_ct":2},{"bid_px":"248.500000000","ask_px":"258.000000000","bid_sz":111,"ask_sz":200,"bid_ct":3,"ask_ct":1}],"symbol":"TSLA"}
{"ts_recv":"2024-11-01T08:00:13.452480070Z","hd":{"ts_event":"2024-11-01T08:00:13.452313759Z","rtype":10,"publisher_id":2,"instrument_id":16244},"action":"A","side":"B","depth":1,"price":"250.270000000","size":1,"flags":130,"ts_in_delta":166311,"sequence":318451,"levels":[{"bid_px":"250.450000000","ask_px":"250.770000000","bid_sz":1,"ask_sz":6,"bid_ct":1,"ask_ct":1},{"bid_px":"250.270000000","ask_px":"251.130000000","bid_sz":1,"ask_sz":50,"bid_ct":1,"ask_ct":1},{"bid_px":"250.150000000","ask_px":"251.150000000","bid_sz":50,"ask_sz":100,"bid_ct":1,"ask_ct":1},{"bid_px":"250.000000000","ask_px":"251.500000000","bid_sz":2,"ask_sz":10,"bid_ct":2,"ask_ct":1},{"bid_px":"249.930000000","ask_px":"252.400000000","bid_sz":10,"ask_sz":1000,"bid_ct":1,"ask_ct":1},{"bid_px":"249.880000000","ask_px":"253.350000000","bid_sz":4,"ask_sz":23,"bid_ct":1,"ask_ct":1},{"bid_px":"249.800000000","ask_px":"253.650000000","bid_sz":199,"ask_sz":400,"bid_ct":1,"ask_ct":1},{"bid_px":"249.770000000","ask_px":"254.990000000","bid_sz":50,"ask_sz":5,"bid_ct":1,"ask_ct":1},{"bid_px":"249.500000000","ask_px":"255.000000000","bid_sz":1000,"ask_sz":85,"bid_ct":1,"ask_ct":2},{"bid_px":"249.000000000","ask_px":"258.000000000","bid_sz":100,"ask_sz":200,"bid_ct":1,"ask_ct":1}],"symbol":"TSLA"}
{"ts_recv":"2024-11-01T08:00:13.452978654Z","hd":{"ts_event":"2024-11-01T08:00:13.452811833Z","rtype":10,"publisher_id":2,"instrument_id":16244},"action":"T","side":"B","depth":0,"price":"250.770000000","size":6,"flags":130,"ts_in_delta":166821,"sequence":318455,"levels":[{"bid_px":"250.450000000","ask_px":"250.770000000","bid_sz":1,"ask_sz":6,"bid_ct":1,"ask_ct":1},{"bid_px":"250.270000000","ask_px":"251.130000000","bid_sz":1,"ask_sz":50,"bid_ct":1,"ask_ct":1},{"bid_px":"250.150000000","ask_px":"251.150000000","bid_sz":50,"ask_sz":100,"bid_ct":1,"ask_ct":1},{"bid_px":"250.000000000","ask_px":"251.500000000","bid_sz":2,"ask_sz":10,"bid_ct":2,"ask_ct":1},{"bid_px":"249.930000000","ask_px":"252.400000000","bid_sz":10,"ask_sz":1000,"bid_ct":1,"ask_ct":1},{"bid_px":"249.880000000","ask_px":"253.350000000","bid_sz":4,"ask_sz":23,"bid_ct":1,"ask_ct":1},{"bid_px":"249.800000000","ask_px":"253.650000000","bid_sz":199,"ask_sz":400,"bid_ct":1,"ask_ct":1},{"bid_px":"249.770000000","ask_px":"254.990000000","bid_sz":50,"ask_sz":5,"bid_ct":1,"ask_ct":1},{"bid_px":"249.500000000","ask_px":"255.000000000","bid_sz":1000,"ask_sz":85,"bid_ct":1,"ask_ct":2},{"bid_px":"249.000000000","ask_px":"258.000000000","bid_sz":100,"ask_sz":200,"bid_ct":1,"ask_ct":1}],"symbol":"TSLA"}
{"ts_recv":"2024-11-01T08:00:13.452978654Z","hd":{"ts_event":"2024-11-01T08:00:13.452811833Z","rtype":10,"publisher_id":2,"instrument_id":16244},"action":"C","side":"A","depth":0,"price":"250.770000000","size":6,"flags":130,"ts_in_delta":166821,"sequence":318455,"levels":[{"bid_px":"250.450000000","ask_px":"251.130000000","bid_sz":1,"ask_sz":50,"bid_ct":1,"ask_ct":1},{"bid_px":"250.270000000","ask_px":"251.150000000","bid_sz":1,"ask_sz":100,"bid_ct":1,"ask_ct":1},{"bid_px":"250.150000000","ask_px":"251.500000000","bid_sz":50,"ask_sz":10,"bid_ct":1,"ask_ct":1},{"bid_px":"250.000000000","ask_px":"252.400000000","bid_sz":2,"ask_sz":1000,"bid_ct":2,"ask_ct":1},{"bid_px":"249.930000000","ask_px":"253.350000000","bid_sz":10,"ask_sz":23,"bid_ct":1,"ask_ct":1},{"bid_px":"249.880000000","ask_px":"253.650000000","bid_sz":4,"ask_sz":400,"bid_ct":1,"ask_ct":1},{"bid_px":"249.800000000","ask_px":"254.990000000","bid_sz":199,"ask_sz":5,"bid_ct":1,"ask_ct":1},{"bid_px":"249.770000000","ask_px":"255.000000000","bid_sz":50,"ask_sz":85,"bid_ct":1,"ask_ct":2},{"bid_px":"249.500000000","ask_px":"258.000000000","bid_sz":1000,"ask_sz":200,"bid_ct":1,"ask_ct":1},{"bid_px":"249.000000000","ask_px":"260.000000000","bid_sz":100,"ask_sz":169,"bid_ct":1,"ask_ct":4}],"symbol":"TSLA"}
{"ts_recv":"2024-11-01T08:00:13.453000958Z","hd":{"ts_event":"2024-11-01T08:00:13.452833319Z","rtype":10,"publisher_id":2,"instrument_id":16244},"action":"A","side":"B","depth":0,"price":"250.520000000","size":100,"flags":130,"ts_in_delta":167639,"sequence":318456,"levels":[{"bid_px":"250.520000000","ask_px":"251.130000000","bid_sz":100,"ask_sz":50,"bid_ct":1,"ask_ct":1},{"bid_px":"250.450000000","ask_px":"251.150000000","bid_sz":1,"ask_sz":100,"bid_ct":1,"ask_ct":1},{"bid_px":"250.270000000","ask_px":"251.500000000","bid_sz":1,"ask_sz":10,"bid_ct":1,"ask_ct":1},{"bid_px":"250.150000000","ask_px":"252.400000000","bid_sz":50,"ask_sz":1000,"bid_ct":1,"ask_ct":1},{"bid_px":"250.000000000","ask_px":"253.350000000","bid_sz":2,"ask_sz":23,"bid_ct":2,"ask_ct":1},{"bid_px":"249.930000000","ask_px":"253.650000000","bid_sz":10,"ask_sz":400,"bid_ct":1,"ask_ct":1},{"bid_px":"249.880000000","ask_px":"254.990000000","bid_sz":4,"ask_sz":5,"bid_ct":1,"ask_ct":1},{"bid_px":"249.800000000","ask_px":"255.000000000","bid_sz":199,"ask_sz":85,"bid_ct":1,"ask_ct":2},{"bid_px":"249.770000000","ask_px":"258.000000000","bid_sz":50,"ask_sz":200,"bid_ct":1,"ask_ct":1},{"bid_px":"249.500000000","ask_px":"260.000000000","bid_sz":1000,"ask_sz":169,"bid_ct":1,"ask_ct":4}],"symbol":"TSLA"}
{"ts_recv":"2024-11-01T08:00:13.453012249Z","hd":{"ts_event":"2024-11-01T08:00:13.452846044Z","rtype":10,"publisher_id":2,"instrument_id":16244},"action":"A","side":"B","depth":0,"price":"250.610000000","size":26,"flags":130,"ts_in_delta":166205,"sequence":318458,"levels":[{"bid_px":"250.610000000","ask_px":"251.130000000","bid_sz":26,"ask_sz":50,"bid_ct":1,"ask_ct":1},{"bid_px":"250.520000000","ask_px":"251.150000000","bid_sz":100,"ask_sz":100,"bid_ct":1,"ask_ct":1},{"bid_px":"250.450000000","ask_px":"251.500000000","bid_sz":1,"ask_sz":10,"bid_ct":1,"ask_ct":1},{"bid_px":"250.270000000","ask_px":"252.400000000","bid_sz":1,"ask_sz":1000,"bid_ct":1,"ask_ct":1},{"bid_px":"250.150000000","ask_px":"253.350000000","bid_sz":50,"ask_sz":23,"bid_ct":1,"ask_ct":1},{"bid_px":"250.000000000","ask_px":"253.650000000","bid_sz":2,"ask_sz":400,"bid_ct":2,"ask_ct":1},{"bid_px":"249.930000000","ask_px":"254.990000000","bid_sz":10,"ask_sz":5,"bid_ct":1,"ask_ct":1},{"bid_px":"249.880000000","ask_px":"255.000000000","bid_sz":4,"ask_sz":85,"bid_ct":1,"ask_ct":2},{"bid_px":"249.800000000","ask_px":"258.000000000","bid_sz":199,"ask_sz":200,"bid_ct":1,"ask_ct":1},{"bid_px":"249.770000000","ask_px":"260.000000000","bid_sz":50,"ask_sz":169,"bid_ct":1,"ask_ct":4}],"symbol":"TSLA"}
{"ts_recv":"2024-11-01T08:00:13.453014645Z","hd":{"ts_event":"2024-11-01T08:00:13.452849113Z","rtype":10,"publisher_id":2,"instrument_id":16244},"action":"C","side":"B","depth":1,"price":"250.520000000","size":100,"flags":130,"ts_in_delta":165532,"sequence":318459,"levels":[{"bid_px":"250.610000000","ask_px":"251.130000000","bid_sz":26,"ask_sz":50,"bid_ct":1,"ask_ct":1},{"bid_px":"250.450000000","ask_px":"251.150000000","bid_sz":1,"ask_sz":100,"bid_ct":1,"ask_ct":1},{"bid_px":"250.270000000","ask_px":"251.500000000","bid_sz":1,"ask_sz":10,"bid_ct":1,"ask_ct":1},{"bid_px":"250.150000000","ask_px":"252.400000000","bid_sz":50,"ask_sz":1000,"bid_ct":1,"ask_ct":1},{"bid_px":"250.000000000","ask_px":"253.350000000","bid_sz":2,"ask_sz":23,"bid_ct":2,"ask_ct":1},{"bid_px":"249.930000000","ask_px":"253.650000000","bid_sz":10,"ask_sz":400,"bid_ct":1,"ask_ct":1},{"bid_px":"249.880000000","ask_px":"254.990000000","bid_sz":4,"ask_sz":5,"bid_ct":1,"ask_ct":1},{"bid_px":"249.800000000","ask_px":"255.000000000","bid_sz":199,"ask_sz":85,"bid_ct":1,"ask_ct":2},{"bid_px":"249.770000000","ask_px":"258.000000000","bid_sz":50,"ask_sz":200,"bid_ct":1,"ask_ct":1},{"bid_px":"249.500000000","ask_px":"260.000000000","bid_sz":1000,"ask_sz":169,"bid_ct":1,"ask_ct":4}],"symbol":"TSLA"}
{"ts_recv":"2024-11-01T08:00:13.453042680Z","hd":{"ts_event":"2024-11-01T08:00:13.452876693Z","rtype":10,"publisher_id":2,"instrument_id":16244},"action":"A","side":"B","depth":1,"price":"250.510000000","size":26,"flags":130,"ts_in_delta":165987,"sequence":318460,"levels":[{"bid_px":"250.610000000","ask_px":"251.130000000","bid_sz":26,"ask_sz":50,"bid_ct":1,"ask_ct":1},{"bid_px":"250.510000000","ask_px":"251.150000000","bid_sz":26,"ask_sz":100,"bid_ct":1,"ask_ct":1},{"bid_px":"250.450000000","ask_px":"251.500000000","bid_sz":1,"ask_sz":10,"bid_ct":1,"ask_ct":1},{"bid_px":"250.270000000","ask_px":"252.400000000","bid_sz":1,"ask_sz":1000,"bid_ct":1,"ask_ct":1},{"bid_px":"250.150000000","ask_px":"253.350000000","bid_sz":50,"ask_sz":23,"bid_ct":1,"ask_ct":1},{"bid_px":"250.000000000","ask_px":"253.650000000","bid_sz":2,"ask_sz":400,"bid_ct":2,"ask_ct":1},{"bid_px":"249.930000000","ask_px":"254.990000000","bid_sz":10,"ask_sz":5,"bid_ct":1,"ask_ct":1},{"bid_px":"249.880000000","ask_px":"255.000000000","bid_sz":4,"ask_sz":85,"bid_ct":1,"ask_ct":2},{"bid_px":"249.800000000","ask_px":"258.000000000","bid_sz":199,"ask_sz":200,"bid_ct":1,"ask_ct":1},{"bid_px":"249.770000000","ask_px":"260.000000000","bid_sz":50,"ask_sz":169,"bid_ct":1,"ask_ct":4}],"symbol":"TSLA"}
{"ts_recv":"2024-11-01T08:00:13.453082155Z","hd":{"ts_event":"2024-11-01T08:00:13.452915842Z","rtype":10,"publisher_id":2,"instrument_id":16244},"action":"A","side":"B","depth":1,"price":"250.510000000","size":67,"flags":130,"ts_in_delta":166313,"sequence":318461,"levels":[{"bid_px":"250.610000000","ask_px":"251.130000000","bid_sz":26,"ask_sz":50,"bid_ct":1,"ask_ct":1},{"bid_px":"250.510000000","ask_px":"251.150000000","bid_sz":93,"ask_sz":100,"bid_ct":2,"ask_ct":1},{"bid_px":"250.450000000","ask_px":"251.500000000","bid_sz":1,"ask_sz":10,"bid_ct":1,"ask_ct":1},{"bid_px":"250.270000000","ask_px":"252.400000000","bid_sz":1,"ask_sz":1000,"bid_ct":1,"ask_ct":1},{"bid_px":"250.150000000","ask_px":"253.350000000","bid_sz":50,"ask_sz":23,"bid_ct":1,"ask_ct":1},{"bid_px":"250.000000000","ask_px":"253.650000000","bid_sz":2,"ask_sz":400,"bid_ct":2,"ask_ct":1},{"bid_px":"249.930000000","ask_px":"254.990000000","bid_sz":10,"ask_sz":5,"bid_ct":1,"ask_ct":1},{"bid_px":"249.880000000","ask_px":"255.000000000","bid_sz":4,"ask_sz":85,"bid_ct":1,"ask_ct":2},{"bid_px":"249.800000000","ask_px":"258.000000000","bid_sz":199,"ask_sz":200,"bid_ct":1,"ask_ct":1},{"bid_px":"249.770000000","ask_px":"260.000000000","bid_sz":50,"ask_sz":169,"bid_ct":1,"ask_ct":4}],"symbol":"TSLA"}
{"ts_recv":"2024-11-01T08:00:13.453093819Z","hd":{"ts_event":"2024-11-01T08:00:13.452928000Z","rtype":10,"publisher_id":2,"instrument_id":16244},"action":"C","side":"B","depth":0,"price":"250.610000000","size":26,"flags":130,"ts_in_delta":165819,"sequence":318462,"levels":[{"bid_px":"250.510000000","ask_px":"251.130000000","bid_sz":93,"ask_sz":50,"bid_ct":2,"ask_ct":1},{"bid_px":"250.450000000","ask_px":"251.150000000","bid_sz":1,"ask_sz":100,"bid_ct":1,"ask_ct":1},{"bid_px":"250.270000000","ask_px":"251.500000000","bid_sz":1,"ask_sz":10,"bid_ct":1,"ask_ct":1},{"bid_px":"250.150000000","ask_px":"252.400000000","bid_sz":50,"ask_sz":1000,"bid_ct":1,"ask_ct":1},{"bid_px":"250.000000000","ask_px":"253.350000000","bid_sz":2,"ask_sz":23,"bid_ct":2,"ask_ct":1},{"bid_px":"249.930000000","ask_px":"253.650000000","bid_sz":10,"ask_sz":400,"bid_ct":1,"ask_ct":1},{"bid_px":"249.880000000","ask_px":"254.990000000","bid_sz":4,"ask_sz":5,"bid_ct":1,"ask_ct":1},{"bid_px":"249.800000000","ask_px":"255.000000000","bid_sz":199,"ask_sz":85,"bid_ct":1,"ask_ct":2},{"bid_px":"249.770000000","ask_px":"258.000000000","bid_sz":50,"ask_sz":200,"bid_ct":1,"ask_ct":1},{"bid_px":"249.500000000","ask_px":"260.000000000","bid_sz":1000,"ask_sz":169,"bid_ct":1,"ask_ct":4}],"symbol":"TSLA"}
{"ts_recv":"2024-11-01T08:00:13.453106450Z","hd":{"ts_event":"2024-11-01T08:00:13.452940931Z","rtype":10,"publisher_id":2,"instrument_id":16244},"action":"C","side":"B","depth":0,"price":"250.510000000","size":26,"flags":130,"ts_in_delta":165519,"sequence":318463,"levels":[{"bid_px":"250.510000000","ask_px":"251.130000000","bid_sz":67,"ask_sz":50,"bid_ct":1,"ask_ct":1},{"bid_px":"250.450000000","ask_px":"251.150000000","bid_sz":1,"ask_sz":100,"bid_ct":1,"ask_ct":1},{"bid_px":"250.270000000","ask_px":"251.500000000","bid_sz":1,"ask_sz":10,"bid_ct":1,"ask_ct":1},{"bid_px":"250.150000000","ask_px":"252.400000000","bid_sz":50,"ask_sz":1000,"bid_ct":1,"ask_ct":1},{"bid_px":"250.000000000","ask_px":"253.350000000","bid_sz":2,"ask_sz":23,"bid_ct":2,"ask_ct":1},{"bid_px":"249.930000000","ask_px":"253.650000000","bid_sz":10,"ask_sz":400,"bid_ct":1,"ask_ct":1},{"bid_px":"249.880000000","ask_px":"254.990000000","bid_sz":4,"ask_sz":5,"bid_ct":1,"ask_ct":1},{"bid_px":"249.800000000","ask_px":"255.000000000","bid_sz":199,"ask_sz":85,"bid_ct":1,"ask_ct":2},{"bid_px":"249.770000000","ask_px":"258.000000000","bid_sz":50,"ask_sz":200,"bid_ct":1,"ask_ct":1},{"bid_px":"249.500000000","ask_px":"260.000000000","bid_sz":1000,"ask_sz":169,"bid_ct":1,"ask_ct":4}],"symbol":"TSLA"}
{"ts_recv":"2024-11-01T08:00:13.453121984Z","hd":{"ts_event":"2024-11-01T08:00:13.452951117Z","rtype":10,"publisher_id":2,"instrument_id":16244},"action":"C","side":"B","depth":0,"price":"250.510000000","size":67,"flags":130,"ts_in_delta":170867,"sequence":318464,"levels":[{"bid_px":"250.450000000","ask_px":"251.130000000","bid_sz":1,"ask_sz":50,"bid_ct":1,"ask_ct":1},{"bid_px":"250.270000000","ask_px":"251.150000000","bid_sz":1,"ask_sz":100,"bid_ct":1,"ask_ct":1},{"bid_px":"250.150000000","ask_px":"251.500000000","bid_sz":50,"ask_sz":10,"bid_ct":1,"ask_ct":1},{"bid_px":"250.000000000","ask_px":"252.400000000","bid_sz":2,"ask_sz":1000,"bid_ct":2,"ask_ct":1},{"bid_px":"249.930000000","ask_px":"253.350000000","bid_sz":10,"ask_sz":23,"bid_ct":1,"ask_ct":1},{"bid_px":"249.880000000","ask_px":"253.650000000","bid_sz":4,"ask_sz":400,"bid_ct":1,"ask_ct":1},{"bid_px":"249.800000000","ask_px":"254.990000000","bid_sz":199,"ask_sz":5,"bid_ct":1,"ask_ct":1},{"bid_px":"249.770000000","ask_px":"255.000000000","bid_sz":50,"ask_sz":85,"bid_ct":1,"ask_ct":2},{"bid_px":"249.500000000","ask_px":"258.000000000","bid_sz":1000,"ask_sz":200,"bid_ct":1,"ask_ct":1},{"bid_px":"249.000000000","ask_px":"260.000000000","bid_sz":100,"ask_sz":169,"bid_ct":1,"ask_ct":4}],"symbol":"TSLA"}
{"ts_recv":"2024-11-01T08:00:13.453847021Z","hd":{"ts_event":"2024-11-01T08:00:13.453681294Z","rtype":10,"publisher_id":2,"instrument_id":16244},"action":"C","side":"B","depth":0,"price":"250.450000000","size":1,"flags":130,"ts_in_delta":165727,"sequence":318468,"levels":[{"bid_px":"250.270000000","ask_px":"251.130000000","bid_sz":1,"ask_sz":50,"bid_ct":1,"ask_ct":1},{"bid_px":"250.150000000","ask_px":"251.150000000","bid_sz":50,"ask_sz":100,"bid_ct":1,"ask_ct":1},{"bid_px":"250.000000000","ask_px":"251.500000000","bid_sz":2,"ask_sz":10,"bid_ct":2,"ask_ct":1},{"bid_px":"249.930000000","ask_px":"252.400000000","bid_sz":10,"ask_sz":1000,"bid_ct":1,"ask_ct":1},{"bid_px":"249.880000000","ask_px":"253.350000000","bid_sz":4,"ask_sz":23,"bid_ct":1,"ask_ct":1},{"bid_px":"249.800000000","ask_px":"253.650000000","bid_sz":199,"ask_sz":400,"bid_ct":1,"ask_ct":1},{"bid_px":"249.770000000","ask_px":"254.990000000","bid_sz":50,"ask_sz":5,"bid_ct":1,"ask_ct":1},{"bid_px":"249.500000000","ask_px":"255.000000000","bid_sz":1000,"ask_sz":85,"bid_ct":1,"ask_ct":2},{"bid_px":"249.000000000","ask_px":"258.000000000","bid_sz":100,"ask_sz":200,"bid_ct":1,"ask_ct":1},{"bid_px":"248.500000000","ask_px":"260.000000000","bid_sz":111,"ask_sz":169,"bid_ct":3,"ask_ct":4}],"symbol":"TSLA"}
{"ts_recv":"2024-11-01T08:00:13.464929853Z","hd":{"ts_event":"2024-11-01T08:00:13.464763555Z","rtype":10,"publisher_id":2,"instrument_id":16244},"action":"A","side":"B","depth":5,"price":"249.850000000","size":4,"flags":130,"ts_in_delta":166298,"sequence":318477,"levels":[{"bid_px":"250.270000000","ask_px":"251.130000000","bid_sz":1,"ask_sz":50,"bid_ct":1,"ask_ct":1},{"bid_px":"250.150000000","ask_px":"251.150000000","bid_sz":50,"ask_sz":100,"bid_ct":1,"ask_ct":1},{"bid_px":"250.000000000","ask_px":"251.500000000","bid_sz":2,"ask_sz":10,"bid_ct":2,"ask_ct":1},{"bid_px":"249.930000000","ask_px":"252.400000000","bid_sz":10,"ask_sz":1000,"bid_ct":1,"ask_ct":1},{"bid_px":"249.880000000","ask_px":"253.350000000","bid_sz":4,"ask_sz":23,"bid_ct":1,"ask_ct":1},{"bid_px":"249.850000000","ask_px":"253.650000000","bid_sz":4,"ask_sz":400,"bid_ct":1,"ask_ct":1},{"bid_px":"249.800000000","ask_px":"254.990000000","bid_sz":199,"ask_sz":5,"bid_ct":1,"ask_ct":1},{"bid_px":"249.770000000","ask_px":"255.000000000","bid_sz":50,"ask_sz":85,"bid_ct":1,"ask_ct":2},{"bid_px":"249.500000000","ask_px":"258.000000000","bid_sz":1000,"ask_sz":200,"bid_ct":1,"ask_ct":1},{"bid_px":"249.000000000","ask_px":"260.000000000","bid_sz":100,"ask_sz":169,"bid_ct":1,"ask_ct":4}],"symbol":"TSLA"}
{"ts_recv":"2024-11-01T08:00:13.482904385Z","hd":{"ts_event":"2024-11-01T08:00:13.482738113Z","rtype":10,"publisher_id":2,"instrument_id":9155},"action":"A","side":"B","depth":1,"price":"220.000000000","size":3,"flags":130,"ts_in_delta":166272,"sequence":318513,"levels":[{"bid_px":"221.850000000","ask_px":"224.940000000","bid_sz":3,"ask_sz":450,"bid_ct":1,"ask_ct":1},{"bid_px":"220.000000000","ask_px":"226.800000000","bid_sz":3,"ask_sz":100,"bid_ct":1,"ask_ct":1},{"bid_px":"219.160000000","ask_px":null,"bid_sz":450,"ask_sz":0,"bid_ct":1,"ask_ct":0},{"bid_px":"218.080000000","ask_px":null,"bid_sz":100,"ask_sz":0,"bid_ct":1,"ask_ct":0},{"bid_px":null,"ask_px":null,"bid_sz":0,"ask_sz":0,"bid_ct":0,"ask_ct":0},{"bid_px":null,"ask_px":null,"bid_sz":0,"ask_sz":0,"bid_ct":0,"ask_ct":0},{"bid_px":null,"ask_px":null,"bid_sz":0,"ask_sz":0,"bid_ct":0,"ask_ct":0},{"bid_px":null,"ask_px":null,"bid_sz":0,"ask_sz":0,"bid_ct":0,"ask_ct":0},{"bid_px":null,"ask_px":null,"bid_sz":0,"ask_sz":0,"bid_ct":0,"ask_ct":0},{"bid_px":null,"ask_px":null,"bid_sz":0,"ask_sz":0,"bid_ct":0,"ask_ct":0}],"symbol":"JPM"}
{"ts_recv":"2024-11-01T08:00:13.497208830Z","hd":{"ts_event":"2024-11-01T08:00:13.497042990Z","rtype":10,"publisher_id":2,"instrument_id":11667},"action":"C","side":"B","depth":2,"price":"134.440000000","size":100,"flags":130,"ts_in_delta":165840,"sequence":318545,"levels":[{"bid_px":"134.930000000","ask_px":"134.990000000","bid_sz":315,"ask_sz":10,"bid_ct":1,"ask_ct":1},{"bid_px":"134.500000000","ask_px":"135.000000000","bid_sz":520,"ask_sz":38,"bid_ct":2,"ask_ct":3},{"bid_px":"134.440000000","ask_px":"135.100000000","bid_sz":100,"ask_sz":10,"bid_ct":1,"ask_ct":1},{"bid_px":"134.410000000","ask_px":"135.230000000","bid_sz":61,"ask_sz":360,"bid_ct":2,"ask_ct":1},{"bid_px":"134.380000000","ask_px":"135.300000000","bid_sz":18,"ask_sz":1009,"bid_ct":1,"ask_ct":2},{"bid_px":"134.210000000","ask_px":"135.400000000","bid_sz":20,"ask_sz":10,"bid_ct":1,"ask_ct":1},{"bid_px":"134.200000000","ask_px":"135.420000000","bid_sz":3,"ask_sz":1,"bid_ct":1,"ask_ct":1},{"bid_px":"134.000000000","ask_px":"135.820000000","bid_sz":1,"ask_sz":1,"bid_ct":1,"ask_ct":1},{"bid_px":"133.800000000","ask_px":"135.910000000","bid_sz":5,"ask_sz":100,"bid_ct":1,"ask_ct":1},{"bid_px":"133.160000000","ask_px":"135.990000000","bid_sz":1,"ask_sz":20,"bid_ct":1,"ask_ct":1}],"symbol":"NVDA"}
{"ts_recv":"2024-11-01T08:00:13.497223541Z","hd":{"ts_event":"2024-11-01T08:00:13.497057443Z","rtype":10,"publisher_id":2,"instrument_id":11667},"action":"A","side":"B","depth":2,"price":"134.450000000","size":200,"flags":130,"ts_in_delta":166098,"sequence":318546,"levels":[{"bid_px":"134.930000000","ask_px":"134.990000000","bid_sz":315,"ask_sz":10,"bid_ct":1,"ask_ct":1},{"bid_px":"134.500000000","ask_px":"135.000000000","bid_sz":520,"ask_sz":38,"bid_ct":2,"ask_ct":3},{"bid_px":"134.450000000","ask_px":"135.100000000","bid_sz":200,"ask_sz":10,"bid_ct":1,"ask_ct":1},{"bid_px":"134.410000000","ask_px":"135.230000000","bid_sz":61,"ask_sz":360,"bid_ct":2,"ask_ct":1},{"bid_px":"134.380000000","ask_px":"135.300000000","bid_sz":18,"ask_sz":1009,"bid_ct":1,"ask_ct":2},{"bid_px":"134.210000000","ask_px":"135.400000000","bid_sz":20,"ask_sz":10,"bid_ct":1,"ask_ct":1},{"bid_px":"134.200000000","ask_px":"135.420000000","bid_sz":3,"ask_sz":1,"bid_ct":1,"ask_ct":1},{"bid_px":"134.000000000","ask_px":"135.820000000","bid_sz":1,"ask_sz":1,"bid_ct":1,"ask_ct":1},{"bid_px":"133.800000000","ask_px":"135.910000000","bid_sz":5,"ask_sz":100,"bid_ct":1,"ask_ct":1},{"bid_px":"133.160000000","ask_px":"135.990000000","bid_sz":1,"ask_sz":20,"bid_ct":1,"ask_ct":1}],"symbol":"NVDA"}
{"ts_recv":"2024-11-01T08:00:13.517343137Z","hd":{"ts_event":"2024-11-01T08:00:13.517176848Z","rtype":10,"publisher_id":2,"instrument_id":11667},"action":"A","side":"B","depth":1,"price":"134.830000000","size":100,"flags":130,"ts_in_delta":166289,"sequence":318654,"levels":[{"bid_px":"134.930000000","ask_px":"134.990000000","bid_sz":315,"ask_sz":10,"bid_ct":1,"ask_ct":1},{"bid_px":"134.830000000","ask_px":"135.000000000","bid_sz":100,"ask_sz":38,"bid_ct":1,"ask_ct":3},{"bid_px":"134.500000000","ask_px":"135.100000000","bid_sz":520,"ask_sz":10,"bid_ct":2,"ask_ct":1},{"bid_px":"134.410000000","ask_px":"135.230000000","bid_sz":61,"ask_sz":360,"bid_ct":2,"ask_ct":1},{"bid_px":"134.380000000","ask_px":"135.300000000","bid_sz":18,"ask_sz":1009,"bid_ct":1,"ask_ct":2},{"bid_px":"134.210000000","ask_px":"135.400000000","bid_sz":20,"ask_sz":10,"bid_ct":1,"ask_ct":1},{"bid_px":"134.200000000","ask_px":"135.420000000","bid_sz":3,"ask_sz":1,"bid_ct":1,"ask_ct":1},{"bid_px":"134.000000000","ask_px":"135.820000000","bid_sz":1,"ask_sz":1,"bid_ct":1,"ask_ct":1},{"bid_px":"133.800000000","ask_px":"135.910000000","bid_sz":5,"ask_sz":100,"bid_ct":1,"ask_ct":1},{"bid_px":"133.160000000","ask_px":"135.990000000","bid_sz":1,"ask_sz":20,"bid_ct":1,"ask_ct":1}],"symbol":"NVDA"}
{"ts_recv":"2024-11-01T08:00:13.853492934Z","hd":{"ts_event":"2024-11-01T08:00:13.853326813Z","rtype":10,"publisher_id":2,"instrument_id":10888},"action":"A","side":"B","depth":0,"price":"410.000000000","size":30,"flags":130,"ts_in_delta":166121,"sequence":319208,"levels":[{"bid_px":"410.000000000","ask_px":"414.000000000","bid_sz":31,"ask_sz":468,"bid_ct":2,"ask_ct":2},{"bid_px":"409.750000000","ask_px":"415.070000000","bid_sz":3,"ask_sz":246,"bid_ct":1,"ask_ct":1},{"bid_px":"409.740000000","ask_px":"415.350000000","bid_sz":500,"ask_sz":84,"bid_ct":1,"ask_ct":2},{"bid_px":"409.670000000","ask_px":"419.860000000","bid_sz":100,"ask_sz":10,"bid_ct":1,"ask_ct":1},{"bid_px":"409.430000000","ask_px":"420.000000000","bid_sz":5,"ask_sz":3,"bid_ct":1,"ask_ct":1},{"bid_px":"409.250000000","ask_px":"440.000000000","bid_sz":2,"ask_sz":35,"bid_ct":1,"ask_ct":1},{"bid_px":"409.080000000","ask_px":"445.000000000","bid_sz":2,"ask_sz":25,"bid_ct":1,"ask_ct":1},{"bid_px":"409.000000000","ask_px":"445.680000000","bid_sz":3,"ask_sz":3,"bid_ct":2,"ask_ct":1},{"bid_px":"408.970000000","ask_px":"448.000000000","bid_sz":12,"ask_sz":15,"bid_ct":1,"ask_ct":2},{"bid_px":"408.960000000","ask_px":"450.000000000","bid_sz":5,"ask_sz":48,"bid_ct":1,"ask_ct":3}],"symbol":"MSFT"}
{"ts_recv":"2024-11-01T08:00:13.877129516Z","hd":{"ts_event":"2024-11-01T08:00:13.876961906Z","rtype":10,"publisher_id":2,"instrument_id":11667},"action":"T","side":"A","depth":0,"price":"134.930000000","size":5,"flags":130,"ts_in_delta":167610,"sequence":319269,"levels":[{"bid_px":"134.930000000","ask_px":"134.990000000","bid_sz":315,"ask_sz":10,"bid_ct":1,"ask_ct":1},{"bid_px":"134.830000000","ask_px":"135.000000000","bid_sz":100,"ask_sz":38,"bid_ct":1,"ask_ct":3},{"bid_px":"134.500000000","ask_px":"135.100000000","bid_sz":520,"ask_sz":10,"bid_ct":2,"ask_ct":1},{"bid_px":"134.410000000","ask_px":"135.230000000","bid_sz":61,"ask_sz":360,"bid_ct":2,"ask_ct":1},{"bid_px":"134.380000000","ask_px":"135.300000000","bid_sz":18,"ask_sz":1009,"bid_ct":1,"ask_ct":2},{"bid_px":"134.210000000","ask_px":"135.400000000","bid_sz":20,"ask_sz":10,"bid_ct":1,"ask_ct":1},{"bid_px":"134.200000000","ask_px":"135.420000000","bid_sz":3,"ask_sz":1,"bid_ct":1,"ask_ct":1},{"bid_px":"134.000000000","ask_px":"135.820000000","bid_sz":1,"ask_sz":1,"bid_ct":1,"ask_ct":1},{"bid_px":"133.800000000","ask_px":"135.910000000","bid_sz":5,"ask_sz":100,"bid_ct":1,"ask_ct":1},{"bid_px":"133.160000000","ask_px":"135.990000000","bid_sz":1,"ask_sz":20,"bid_ct":1,"ask_ct":1}],"symbol":"NVDA"}
{"ts_recv":"2024-11-01T08:00:13.877129516Z","hd":{"ts_event":"2024-11-01T08:00:13.876961906Z","rtype":10,"publisher_id":2,"instrument_id":11667},"action":"C","side":"B","depth":0,"price":"134.930000000","size":5,"flags":130,"ts_in_delta":167610,"sequence":319269,"levels":[{"bid_px":"134.930000000","ask_px":"134.990000000","bid_sz":310,"ask_sz":10,"bid_ct":1,"ask_ct":1},{"bid_px":"134.830000000","ask_px":"135.000000000","bid_sz":100,"ask_sz":38,"bid_ct":1,"ask_ct":3},{"bid_px":"134.500000000","ask_px":"135.100000000","bid_sz":520,"ask_sz":10,"bid_ct":2,"ask_ct":1},{"bid_px":"134.410000000","ask_px":"135.230000000","bid_sz":61,"ask_sz":360,"bid_ct":2,"ask_ct":1},{"bid_px":"134.380000000","ask_px":"135.300000000","bid_sz":18,"ask_sz":1009,"bid_ct":1,"ask_ct":2},{"bid_px":"134.210000000","ask_px":"135.400000000","bid_sz":20,"ask_sz":10,"bid_ct":1,"ask_ct":1},{"bid_px":"134.200000000","ask_px":"135.420000000","bid_sz":3,"ask_sz":1,"bid_ct":1,"ask_ct":1},{"bid_px":"134.000000000","ask_px":"135.820000000","bid_sz":1,"ask_sz":1,"bid_ct":1,"ask_ct":1},{"bid_px":"133.800000000","ask_px":"135.910000000","bid_sz":5,"ask_sz":100,"bid_ct":1,"ask_ct":1},{"bid_px":"133.160000000","ask_px":"135.990000000","bid_sz":1,"ask_sz":20,"bid_ct":1,"ask_ct":1}],"symbol":"NVDA"}
{"ts_recv":"2024-11-01T08:00:13.960272379Z","hd":{"ts_event":"2024-11-01T08:00:13.960106672Z","rtype":10,"publisher_id":2,"instrument_id":16244},"action":"C","side":"B","depth":0,"price":"250.270000000","size":1,"flags":130,"ts_in_delta":165707,"sequence":319530,"levels":[{"bid_px":"250.150000000","ask_px":"251.130000000","bid_sz":50,"ask_sz":50,"bid_ct":1,"ask_ct":1},{"bid_px":"250.000000000","ask_px":"251.150000000","bid_sz":2,"ask_sz":100,"bid_ct":2,"ask_ct":1},{"bid_px":"249.930000000","ask_px":"251.500000000","bid_sz":10,"ask_sz":10,"bid_ct":1,"ask_ct":1},{"bid_px":"249.880000000","ask_px":"252.400000000","bid_sz":4,"ask_sz":1000,"bid_ct":1,"ask_ct":1},{"bid_px":"249.850000000","ask_px":"253.350000000","bid_sz":4,"ask_sz":23,"bid_ct":1,"ask_ct":1},{"bid_px":"249.800000000","ask_px":"253.650000000","bid_sz":199,"ask_sz":400,"bid_ct":1,"ask_ct":1},{"bid_px":"249.770000000","ask_px":"254.990000000","bid_sz":50,"ask_sz":5,"bid_ct":1,"ask_ct":1},{"bid_px":"249.500000000","ask_px":"255.000000000","bid_sz":1000,"ask_sz":85,"bid_ct":1,"ask_ct":2},{"bid_px":"249.000000000","ask_px":"258.000000000","bid_sz":100,"ask_sz":200,"bid_ct":1,"ask_ct":1},{"bid_px":"248.500000000","ask_px":"260.000000000","bid_sz":111,"ask_sz":169,"bid_ct":3,"ask_ct":4}],"symbol":"TSLA"}
{"ts_recv":"2024-11-01T08:00:14.022169941Z","hd":{"ts_event":"2024-11-01T08:00:14.022003134Z","rtype":10,"publisher_id":2,"instrument_id":11667},"action":"T","side":"A","depth":0,"price":"134.930000000","size":58,"flags":130,"ts_in_delta":166807,"sequence":319675,"levels":[{"bid_px":"134.930000000","ask_px":"134.990000000","bid_sz":310,"ask_sz":10,"bid_ct":1,"ask_ct":1},{"bid_px":"134.830000000","ask_px":"135.000000000","bid_sz":100,"ask_sz":38,"bid_ct":1,"ask_ct":3},{"bid_px":"134.500000000","ask_px":"135.100000000","bid_sz":520,"ask_sz":10,"bid_ct":2,"ask_ct":1},{"bid_px":"134.410000000","ask_px":"135.230000000","bid_sz":61,"ask_sz":360,"bid_ct":2,"ask_ct":1},{"bid_px":"134.380000000","ask_px":"135.300000000","bid_sz":18,"ask_sz":1009,"bid_ct":1,"ask_ct":2},{"bid_px":"134.210000000","ask_px":"135.400000000","bid_sz":20,"ask_sz":10,"bid_ct":1,"ask_ct":1},{"bid_px":"134.200000000","ask_px":"135.420000000","bid_sz":3,"ask_sz":1,"bid_ct":1,"ask_ct":1},{"bid_px":"134.000000000","ask_px":"135.820000000","bid_sz":1,"ask_sz":1,"bid_ct":1,"ask_ct":1},{"bid_px":"133.800000000","ask_px":"135.910000000","bid_sz":5,"ask_sz":100,"bid_ct":1,"ask_ct":1},{"bid_px":"133.160000000","ask_px":"135.990000000","bid_sz":1,"ask_sz":20,"bid_ct":1,"ask_ct":1}],"symbol":"NVDA"}
{"ts_recv":"2024-11-01T08:00:14.022169941Z","hd":{"ts_event":"2024-11-01T08:00:14.022003134Z","rtype":10,"publisher_id":2,"instrument_id":11667},"action":"C","side":"B","depth":0,"price":"134.930000000","size":58,"flags":130,"ts_in_delta":166807,"sequence":319675,"levels":[{"bid_px":"134.930000000","ask_px":"134.990000000","bid_sz":252,"ask_sz":10,"bid_ct":1,"ask_ct":1},{"bid_px":"134.830000000","ask_px":"135.000000000","bid_sz":100,"ask_sz":38,"bid_ct":1,"ask_ct":3},{"bid_px":"134.500000000","ask_px":"135.100000000","bid_sz":520,"ask_sz":10,"bid_ct":2,"ask_ct":1},{"bid_px":"134.410000000","ask_px":"135.230000000","bid_sz":61,"ask_sz":360,"bid_ct":2,"ask_ct":1},{"bid_px":"134.380000000","ask_px":"135.300000000","bid_sz":18,"ask_sz":1009,"bid_ct":1,"ask_ct":2},{"bid_px":"134.210000000","ask_px":"135.400000000","bid_sz":20,"ask_sz":10,"bid_ct":1,"ask_ct":1},{"bid_px":"134.200000000","ask_px":"135.420000000","bid_sz":3,"ask_sz":1,"bid_ct":1,"ask_ct":1},{"bid_px":"134.000000000","ask_px":"135.820000000","bid_sz":1,"ask_sz":1,"bid_ct":1,"ask_ct":1},{"bid_px":"133.800000000","ask_px":"135.910000000","bid_sz":5,"ask_sz":100,"bid_ct":1,"ask_ct":1},{"bid_px":"133.160000000","ask_px":"135.990000000","bid_sz":1,"ask_sz":20,"bid_ct":1,"ask_ct":1}],"symbol":"NVDA"}
{"ts_recv":"2024-11-01T08:00:14.022415716Z","hd":{"ts_event":"2024-11-01T08:00:14.022249021Z","rtype":10,"publisher_id":2,"instrument_id":11667},"action":"T","side":"A","depth":0,"price":"134.930000000","size":6,"flags":130,"ts_in_delta":166695,"sequence":319676,"levels":[{"bid_px":"134.930000000","ask_px":"134.990000000","bid_sz":252,"ask_sz":10,"bid_ct":1,"ask_ct":1},{"bid_px":"134.830000000","ask_px":"135.000000000","bid_sz":100,"ask_sz":38,"bid_ct":1,"ask_ct":3},{"bid_px":"134.500000000","ask_px":"135.100000000","bid_sz":520,"ask_sz":10,"bid_ct":2,"ask_ct":1},{"bid_px":"134.410000000","ask_px":"135.230000000","bid_sz":61,"ask_sz":360,"bid_ct":2,"ask_ct":1},{"bid_px":"134.380000000","ask_px":"135.300000000","bid_sz":18,"ask_sz":1009,"bid_ct":1,"ask_ct":2},{"bid_px":"134.210000000","ask_px":"135.400000000","bid_sz":20,"ask_sz":10,"bid_ct":1,"ask_ct":1},{"bid_px":"134.200000000","ask_px":"135.420000000","bid_sz":3,"ask_sz":1,"bid_ct":1,"ask_ct":1},{"bid_px":"134.000000000","ask_px":"135.820000000","bid_sz":1,"ask_sz":1,"bid_ct":1,"ask_ct":1},{"bid_px":"133.800000000","ask_px":"135.910000000","bid_sz":5,"ask_sz":100,"bid_ct":1,"ask_ct":1},{"bid_px":"133.160000000","ask_px":"135.990000000","bid_sz":1,"ask_sz":20,"bid_ct":1,"ask_ct":1}],"symbol":"NVDA"}
{"ts_recv":"2024-11-01T08:00:14.022415716Z","hd":{"ts_event":"2024-11-01T08:00:14.022249021Z","rtype":10,"publisher_id":2,"instrument_id":11667},"action":"C","side":"B","depth":0,"price":"134.930000000","size":6,"flags":130,"ts_in_delta":166695,"sequence":319676,"levels":[{"bid_px":"134.930000000","ask_px":"134.990000000","bid_sz":246,"ask_sz":10,"bid_ct":1,"ask_ct":1},{"bid_px":"134.830000000","ask_px":"135.000000000","bid_sz":100,"ask_sz":38,"bid_ct":1,"ask_ct":3},{"bid_px":"134.500000000","ask_px":"135.100000000","bid_sz":520,"ask_sz":10,"bid_ct":2,"ask_ct":1},{"bid_px":"134.410000000","ask_px":"135.230000000","bid_sz":61,"ask_sz":360,"bid_ct":2,"ask_ct":1},{"bid_px":"134.380000000","ask_px":"135.300000000","bid_sz":18,"ask_sz":1009,"bid_ct":1,"ask_ct":2},{"bid_px":"134.210000000","ask_px":"135.400000000","bid_sz":20,"ask_sz":10,"bid_ct":1,"ask_ct":1},{"bid_px":"134.200000000","ask_px":"135.420000000","bid_sz":3,"ask_sz":1,"bid_ct":1,"ask_ct":1},{"bid_px":"134.000000000","ask_px":"135.820000000","bid_sz":1,"ask_sz":1,"bid_ct":1,"ask_ct":1},{"bid_px":"133.800000000","ask_px":"135.910000000","bid_sz":5,"ask_sz":100,"bid_ct":1,"ask_ct":1},{"bid_px":"133.160000000","ask_px":"135.990000000","bid_sz":1,"ask_sz":20,"bid_ct":1,"ask_ct":1}],"symbol":"NVDA"}
{"ts_recv":"2024-11-01T08:00:14.022625994Z","hd":{"ts_event":"2024-11-01T08:00:14.022459549Z","rtype":10,"publisher_id":2,"instrument_id":11667},"action":"T","side":"A","depth":0,"price":"134.930000000","size":4,"flags":130,"ts_in_delta":166445,"sequence":319677,"levels":[{"bid_px":"134.930000000","ask_px":"134.990000000","bid_sz":246,"ask_sz":10,"bid_ct":1,"ask_ct":1},{"bid_px":"134.830000000","ask_px":"135.000000000","bid_sz":100,"ask_sz":38,"bid_ct":1,"ask_ct":3},{"bid_px":"134.500000000","ask_px":"135.100000000","bid_sz":520,"ask_sz":10,"bid_ct":2,"ask_ct":1},{"bid_px":"134.410000000","ask_px":"135.230000000","bid_sz":61,"ask_sz":360,"bid_ct":2,"ask_ct":1},{"bid_px":"134.380000000","ask_px":"135.300000000","bid_sz":18,"ask_sz":1009,"bid_ct":1,"ask_ct":2},{"bid_px":"134.210000000","ask_px":"135.400000000","bid_sz":20,"ask_sz":10,"bid_ct":1,"ask_ct":1},{"bid_px":"134.200000000","ask_px":"135.420000000","bid_sz":3,"ask_sz":1,"bid_ct":1,"ask_ct":1},{"bid_px":"134.000000000","ask_px":"135.820000000","bid_sz":1,"ask_sz":1,"bid_ct":1,"ask_ct":1},{"bid_px":"133.800000000","ask_px":"135.910000000","bid_sz":5,"ask_sz":100,"bid_ct":1,"ask_ct":1},{"bid_px":"133.160000000","ask_px":"135.990000000","bid_sz":1,"ask_sz":20,"bid_ct":1,"ask_ct":1}],"symbol":"NVDA"}
{"ts_recv":"2024-11-01T08:00:14.022625994Z","hd":{"ts_event":"2024-11-01T08:00:14.022459549Z","rtype":10,"publisher_id":2,"instrument_id":11667},"action":"C","side":"B","depth":0,"price":"134.930000000","size":4,"flags":130,"ts_in_delta":166445,"sequence":319677,"levels":[{"bid_px":"134.930000000","ask_px":"134.990000000","bid_sz":242,"ask_sz":10,"bid_ct":1,"ask_ct":1},{"bid_px":"134.830000000","ask_px":"135.000000000","bid_sz":100,"ask_sz":38,"bid_ct":1,"ask_ct":3},{"bid_px":"134.500000000","ask_px":"135.100000000","bid_sz":520,"ask_sz":10,"bid_ct":2,"ask_ct":1},{"bid_px":"134.410000000","ask_px":"135.230000000","bid_sz":61,"ask_sz":360,"bid_ct":2,"ask_ct":1},{"bid_px":"134.380000000","ask_px":"135.300000000","bid_sz":18,"ask_sz":1009,"bid_ct":1,"ask_ct":2},{"bid_px":"134.210000000","ask_px":"135.400000000","bid_sz":20,"ask_sz":10,"bid_ct":1,"ask_ct":1},{"bid_px":"134.200000000","ask_px":"135.420000000","bid_sz":3,"ask_sz":1,"bid_ct":1,"ask_ct":1},{"bid_px":"134.000000000","ask_px":"135.820000000","bid_sz":1,"ask_sz":1,"bid_ct":1,"ask_ct":1},{"bid_px":"133.800000000","ask_px":"135.910000000","bid_sz":5,"ask_sz":100,"bid_ct":1,"ask_ct":1},{"bid_px":"133.160000000","ask_px":"135.990000000","bid_sz":1,"ask_sz":20,"bid_ct":1,"ask_ct":1}],"symbol":"NVDA"}
{"ts_recv":"2024-11-01T08:00:14.022631628Z","hd":{"ts_event":"2024-11-01T08:00:14.022465132Z","rtype":10,"publisher_id":2,"instrument_id":11667},"action":"T","side":"A","depth":0,"price":"134.930000000","size":1,"flags":130,"ts_in_delta":166496,"sequence":319678,"levels":[{"bid_px":"134.930000000","ask_px":"134.990000000","bid_sz":242,"ask_sz":10,"bid_ct":1,"ask_ct":1},{"bid_px":"134.830000000","ask_px":"135.000000000","bid_sz":100,"ask_sz":38,"bid_ct":1,"ask_ct":3},{"bid_px":"134.500000000","ask_px":"135.100000000","bid_sz":520,"ask_sz":10,"bid_ct":2,"ask_ct":1},{"bid_px":"134.410000000","ask_px":"135.230000000","bid_sz":61,"ask_sz":360,"bid_ct":2,"ask_ct":1},{"bid_px":"134.380000000","ask_px":"135.300000000","bid_sz":18,"ask_sz":1009,"bid_ct":1,"ask_ct":2},{"bid_px":"134.210000000","ask_px":"135.400000000","bid_sz":20,"ask_sz":10,"bid_ct":1,"ask_ct":1},{"bid_px":"134.200000000","ask_px":"135.420000000","bid_sz":3,"ask_sz":1,"bid_ct":1,"ask_ct":1},{"bid_px":"134.000000000","ask_px":"135.820000000","bid_sz":1,"ask_sz":1,"bid_ct":1,"ask_ct":1},{"bid_px":"133.800000000","ask_px":"135.910000000","bid_sz":5,"ask_sz":100,"bid_ct":1,"ask_ct":1},{"bid_px":"133.160000000","ask_px":"135.990000000","bid_sz":1,"ask_sz":20,"bid_ct":1,"ask_ct":1}],"symbol":"NVDA"}
{"ts_recv":"2024-11-01T08:00:14.022631628Z","hd":{"ts_event":"2024-11-01T08:00:14.022465132Z","rtype":10,"publisher_id":2,"instrument_id":11667},"action":"C","side":"B","depth":0,"price":"134.930000000","size":1,"flags":130,"ts_in_delta":166496,"sequence":319678,"levels":[{"bid_px":"134.930000000","ask_px":"134.990000000","bid_sz":241,"ask_sz":10,"bid_ct":1,"ask_ct":1},{"bid_px":"134.830000000","ask_px":"135.000000000","bid_sz":100,"ask_sz":38,"bid_ct":1,"ask_ct":3},{"bid_px":"134.500000000","ask_px":"135.100000000","bid_sz":520,"ask_sz":10,"bid_ct":2,"ask_ct":1},{"bid_px":"134.410000000","ask_px":"135.230000000","bid_sz":61,"ask_sz":360,"bid_ct":2,"ask_ct":1},{"bid_px":"134.380000000","ask_px":"135.300000000","bid_sz":18,"ask_sz":1009,"bid_ct":1,"ask_ct":2},{"bid_px":"134.210000000","ask_px":"135.400000000","bid_sz":20,"ask_sz":10,"bid_ct":1,"ask_ct":1},{"bid_px":"134.200000000","ask_px":"135.420000000","bid_sz":3,"ask_sz":1,"bid_ct":1,"ask_ct":1},{"bid_px":"134.000000000","ask_px":"135.820000000","bid_sz":1,"ask_sz":1,"bid_ct":1,"ask_ct":1},{"bid_px":"133.800000000","ask_px":"135.910000000","bid_sz":5,"ask_sz":100,"bid_ct":1,"ask_ct":1},{"bid_px":"133.160000000","ask_px":"135.990000000","bid_sz":1,"ask_sz":20,"bid_ct":1,"ask_ct":1}],"symbol":"NVDA"}
{"ts_recv":"2024-11-01T08:00:14.022832250Z","hd":{"ts_event":"2024-11-01T08:00:14.022665702Z","rtype":10,"publisher_id":2,"instrument_id":11667},"action":"T","side":"A","depth":0,"price":"134.930000000","size":1,"flags":130,"ts_in_delta":166548,"sequence":319680,"levels":[{"bid_px":"134.930000000","ask_px":"134.990000000","bid_sz":241,"ask_sz":10,"bid_ct":1,"ask_ct":1},{"bid_px":"134.830000000","ask_px":"135.000000000","bid_sz":100,"ask_sz":38,"bid_ct":1,"ask_ct":3},{"bid_px":"134.500000000","ask_px":"135.100000000","bid_sz":520,"ask_sz":10,"bid_ct":2,"ask_ct":1},{"bid_px":"134.410000000","ask_px":"135.230000000","bid_sz":61,"ask_sz":360,"bid_ct":2,"ask_ct":1},{"bid_px":"134.380000000","ask_px":"135.300000000","bid_sz":18,"ask_sz":1009,"bid_ct":1,"ask_ct":2},{"bid_px":"134.210000000","ask_px":"135.400000000","bid_sz":20,"ask_sz":10,"bid_ct":1,"ask_ct":1},{"bid_px":"134.200000000","ask_px":"135.420000000","bid_sz":3,"ask_sz":1,"bid_ct":1,"ask_ct":1},{"bid_px":"134.000000000","ask_px":"135.820000000","bid_sz":1,"ask_sz":1,"bid_ct":1,"ask_ct":1},{"bid_px":"133.800000000","ask_px":"135.910000000","bid_sz":5,"ask_sz":100,"bid_ct":1,"ask_ct":1},{"bid_px":"133.160000000","ask_px":"135.990000000","bid_sz":1,"ask_sz":20,"bid_ct":1,"ask_ct":1}],"symbol":"NVDA"}
{"ts_recv":"2024-11-01T08:00:14.022832250Z","hd":{"ts_event":"2024-11-01T08:00:14.022665702Z","rtype":10,"publisher_id":2,"instrument_id":11667},"action":"C","side":"B","depth":0,"price":"134.930000000","size":1,"flags":130,"ts_in_delta":166548,"sequence":319680,"levels":[{"bid_px":"134.930000000","ask_px":"134.990000000","bid_sz":240,"ask_sz":10,"bid_ct":1,"ask_ct":1},{"bid_px":"134.830000000","ask_px":"135.000000000","bid_sz":100,"ask_sz":38,"bid_ct":1,"ask_ct":3},{"bid_px":"134.500000000","ask_px":"135.100000000","bid_sz":520,"ask_sz":10,"bid_ct":2,"ask_ct":1},{"bid_px":"134.410000000","ask_px":"135.230000000","bid_sz":61,"ask_sz":360,"bid_ct":2,"ask_ct":1},{"bid_px":"134.380000000","ask_px":"135.300000000","bid_sz":18,"ask_sz":1009,"bid_ct":1,"ask_ct":2},{"bid_px":"134.210000000","ask_px":"135.400000000","bid_sz":20,"ask_sz":10,"bid_ct":1,"ask_ct":1},{"bid_px":"134.200000000","ask_px":"135.420000000","bid_sz":3,"ask_sz":1,"bid_ct":1,"ask_ct":1},{"bid_px":"134.000000000","ask_px":"135.820000000","bid_sz":1,"ask_sz":1,"bid_ct":1,"ask_ct":1},{"bid_px":"133.800000000","ask_px":"135.910000000","bid_sz":5,"ask_sz":100,"bid_ct":1,"ask_ct":1},{"bid_px":"133.160000000","ask_px":"135.990000000","bid_sz":1,"ask_sz":20,"bid_ct":1,"ask_ct":1}],"symbol":"NVDA"}
{"ts_recv":"2024-11-01T08:00:14.023048308Z","hd":{"ts_event":"2024-11-01T08:00:14.022881174Z","rtype":10,"publisher_id":2,"instrument_id":11667},"action":"T","side":"A","depth":0,"price":"134.930000000","size":1,"flags":130,"ts_in_delta":167134,"sequence":319685,"levels":[{"bid_px":"134.930000000","ask_px":"134.990000000","bid_sz":240,"ask_sz":10,"bid_ct":1,"ask_ct":1},{"bid_px":"134.830000000","ask_px":"135.000000000","bid_sz":100,"ask_sz":38,"bid_ct":1,"ask_ct":3},{"bid_px":"134.500000000","ask_px":"135.100000000","bid_sz":520,"ask_sz":10,"bid_ct":2,"ask_ct":1},{"bid_px":"134.410000000","ask_px":"135.230000000","bid_sz":61,"ask_sz":360,"bid_ct":2,"ask_ct":1},{"bid_px":"134.380000000","ask_px":"135.300000000","bid_sz":18,"ask_sz":1009,"bid_ct":1,"ask_ct":2},{"bid_px":"134.210000000","ask_px":"135.400000000","bid_sz":20,"ask_sz":10,"bid_ct":1,"ask_ct":1},{"bid_px":"134.200000000","ask_px":"135.420000000","bid_sz":3,"ask_sz":1,"bid_ct":1,"ask_ct":1},{"bid_px":"134.000000000","ask_px":"135.820000000","bid_sz":1,"ask_sz":1,"bid_ct":1,"ask_ct":1},{"bid_px":"133.800000000","ask_px":"135.910000000","bid_sz":5,"ask_sz":100,"bid_ct":1,"ask_ct":1},{"bid_px":"133.160000000","ask_px":"135.990000000","bid_sz":1,"ask_sz":20,"bid_ct":1,"ask_ct":1}],"symbol":"NVDA"}
{"ts_recv":"2024-11-01T08:00:14.023048308Z","hd":{"ts_event":"2024-11-01T08:00:14.022881174Z","rtype":10,"publisher_id":2,"instrument_id":11667},"action":"C","side":"B","depth":0,"price":"134.930000000","size":1,"flags":130,"ts_in_delta":167134,"sequence":319685,"levels":[{"bid_px":"134.930000000","ask_px":"134.990000000","bid_sz":239,"ask_sz":10,"bid_ct":1,"ask_ct":1},{"bid_px":"134.830000000","ask_px":"135.000000000","bid_sz":100,"ask_sz":38,"bid_ct":1,"ask_ct":3},{"bid_px":"134.500000000","ask_px":"135.100000000","bid_sz":520,"ask_sz":10,"bid_ct":2,"ask_ct":1},{"bid_px":"134.410000000","ask_px":"135.230000000","bid_sz":61,"ask_sz":360,"bid_ct":2,"ask_ct":1},{"bid_px":"134.380000000","ask_px":"135.300000000","bid_sz":18,"ask_sz":1009,"bid_ct":1,"ask_ct":2},{"bid_px":"134.210000000","ask_px":"135.400000000","bid_sz":20,"ask_sz":10,"bid_ct":1,"ask_ct":1},{"bid_px":"134.200000000","ask_px":"135.420000000","bid_sz":3,"ask_sz":1,"bid_ct":1,"ask_ct":1},{"bid_px":"134.000000000","ask_px":"135.820000000","bid_sz":1,"ask_sz":1,"bid_ct":1,"ask_ct":1},{"bid_px":"133.800000000","ask_px":"135.910000000","bid_sz":5,"ask_sz":100,"bid_ct":1,"ask_ct":1},{"bid_px":"133.160000000","ask_px":"135.990000000","bid_sz":1,"ask_sz":20,"bid_ct":1,"ask_ct":1}],"symbol":"NVDA"}
{"ts_recv":"2024-11-01T08:00:14.059816709Z","hd":{"ts_event":"2024-11-01T08:00:14.059650349Z","rtype":10,"publisher_id":2,"instrument_id":16244},"action":"A","side":"A","depth":0,"price":"250.880000000","size":23,"flags":130,"ts_in_delta":166360,"sequence":319767,"levels":[{"bid_px":"250.150000000","ask_px":"250.880000000","bid_sz":50,"ask_sz":23,"bid_ct":1,"ask_ct":1},{"bid_px":"250.000000000","ask_px":"251.130000000","bid_sz":2,"ask_sz":50,"bid_ct":2,"ask_ct":1},{"bid_px":"249.930000000","ask_px":"251.150000000","bid_sz":10,"ask_sz":100,"bid_ct":1,"ask_ct":1},{"bid_px":"249.880000000","ask_px":"251.500000000","bid_sz":4,"ask_sz":10,"bid_ct":1,"ask_ct":1},{"bid_px":"249.850000000","ask_px":"252.400000000","bid_sz":4,"ask_sz":1000,"bid_ct":1,"ask_ct":1},{"bid_px":"249.800000000","ask_px":"253.350000000","bid_sz":199,"ask_sz":23,"bid_ct":1,"ask_ct":1},{"bid_px":"249.770000000","ask_px":"253.650000000","bid_sz":50,"ask_sz":400,"bid_ct":1,"ask_ct":1},{"bid_px":"249.500000000","ask_px":"254.990000000","bid_sz":1000,"ask_sz":5,"bid_ct":1,"ask_ct":1},{"bid_px":"249.000000000","ask_px":"255.000000000","bid_sz":100,"ask_sz":85,"bid_ct":1,"ask_ct":2},{"bid_px":"248.500000000","ask_px":"258.000000000","bid_sz":111,"ask_sz":200,"bid_ct":3,"ask_ct":1}],"symbol":"TSLA"}
{"ts_recv":"2024-11-01T08:00:14.061115915Z","hd":{"ts_event":"2024-11-01T08:00:14.060949344Z","rtype":10,"publisher_id":2,"instrument_id":16244},"action":"A","side":"A","depth":8,"price":"255.000000000","size":20,"flags":130,"ts_in_delta":166571,"sequence":319780,"levels":[{"bid_px":"250.150000000","ask_px":"250.880000000","bid_sz":50,"ask_sz":23,"bid_ct":1,"ask_ct":1},{"bid_px":"250.000000000","ask_px":"251.130000000","bid_sz":2,"ask_sz":50,"bid_ct":2,"ask_ct":1},{"bid_px":"249.930000000","ask_px":"251.150000000","bid_sz":10,"ask_sz":100,"bid_ct":1,"ask_ct":1},{"bid_px":"249.880000000","ask_px":"251.500000000","bid_sz":4,"ask_sz":10,"bid_ct":1,"ask_ct":1},{"bid_px":"249.850000000","ask_px":"252.400000000","bid_sz":4,"ask_sz":1000,"bid_ct":1,"ask_ct":1},{"bid_px":"249.800000000","ask_px":"253.350000000","bid_sz":199,"ask_sz":23,"bid_ct":1,"ask_ct":1},{"bid_px":"249.770000000","ask_px":"253.650000000","bid_sz":50,"ask_sz":400,"bid_ct":1,"ask_ct":1},{"bid_px":"249.500000000","ask_px":"254.990000000","bid_sz":1000,"ask_sz":5,"bid_ct":1,"ask_ct":1},{"bid_px":"249.000000000","ask_px":"255.000000000","bid_sz":100,"ask_sz":105,"bid_ct":1,"ask_ct":3},{"bid_px":"248.500000000","ask_px":"258.000000000","bid_sz":111,"ask_sz":200,"bid_ct":3,"ask_ct":1}],"symbol":"TSLA"}
{"ts_recv":"2024-11-01T08:00:14.100987514Z","hd":{"ts_event":"2024-11-01T08:00:14.100821560Z","rtype":10,"publisher_id":2,"instrument_id":17709},"action":"C","side":"B","depth":2,"price":"115.280000000","size":856,"flags":130,"ts_in_delta":165954,"sequence":319861,"levels":[{"bid_px":"116.000000000","ask_px":"118.320000000","bid_sz":100,"ask_sz":856,"bid_ct":1,"ask_ct":1},{"bid_px":"115.290000000","ask_px":"118.600000000","bid_sz":100,"ask_sz":100,"bid_ct":1,"ask_ct":1},{"bid_px":null,"ask_px":"125.000000000","bid_sz":0,"ask_sz":30,"bid_ct":0,"ask_ct":1},{"bid_px":null,"ask_px":null,"bid_sz":0,"ask_sz":0,"bid_ct":0,"ask_ct":0},{"bid_px":null,"ask_px":null,"bid_sz":0,"ask_sz":0,"bid_ct":0,"ask_ct":0},{"bid_px":null,"ask_px":null,"bid_sz":0,"ask_sz":0,"bid_ct":0,"ask_ct":0},{"bid_px":null,"ask_px":null,"bid_sz":0,"ask_sz":0,"bid_ct":0,"ask_ct":0},{"bid_px":null,"ask_px":null,"bid_sz":0,"ask_sz":0,"bid_ct":0,"ask_ct":0},{"bid_px":null,"ask_px":null,"bid_sz":0,"ask_sz":0,"bid_ct":0,"ask_ct":0},{"bid_px":null,"ask_px":null,"bid_sz":0,"ask_sz":0,"bid_ct":0,"ask_ct":0}],"symbol":"XOM"}
{"ts_recv":"2024-11-01T08:00:14.101502438Z","hd":{"ts_event":"2024-11-01T08:00:14.101336367Z","rtype":10,"publisher_id":2,"instrument_id":17709},"action":"C","side":"A","depth":0,"price":"118.320000000","size":856,"flags":130,"ts_in_delta":166071,"sequence":319865,"levels":[{"bid_px":"116.000000000","ask_px":"118.600000000","bid_sz":100,"ask_sz":100,"bid_ct":1,"ask_ct":1},{"bid_px":"115.290000000","ask_px":"125.000000000","bid_sz":100,"ask_sz":30,"bid_ct":1,"ask_ct":1},{"bid_px":null,"ask_px":null,"bid_sz":0,"ask_sz":0,"bid_ct":0,"ask_ct":0},{"bid_px":null,"ask_px":null,"bid_sz":0,"ask_sz":0,"bid_ct":0,"ask_ct":0},{"bid_px":null,"ask_px":null,"bid_sz":0,"ask_sz":0,"bid_ct":0,"ask_ct":0},{"bid_px":null,"ask_px":null,"bid_sz":0,"ask_sz":0,"bid_ct":0,"ask_ct":0},{"bid_px":null,"ask_px":null,"bid_sz":0,"ask_sz":0,"bid_ct":0,"ask_ct":0},{"bid_px":null,"ask_px":null,"bid_sz":0,"ask_sz":0,"bid_ct":0,"ask_ct":0},{"bid_px":null,"ask_px":null,"bid_sz":0,"ask_sz":0,"bid_ct":0,"ask_ct":0},{"bid_px":null,"ask_px":null,"bid_sz":0,"ask_sz":0,"bid_ct":0,"ask_ct":0}],"symbol":"XOM"}
{"ts_recv":"2024-11-01T08:00:14.103942544Z","hd":{"ts_event":"2024-11-01T08:00:14.103774190Z","rtype":10,"publisher_id":2,"instrument_id":16244},"action":"T","side":"N","depth":0,"price":"250.870000000","size":12,"flags":0,"ts_in_delta":168354,"sequence":319875,"levels":[{"bid_px":"250.150000000","ask_px":"250.880000000","bid_sz":50,"ask_sz":23,"bid_ct":1,"ask_ct":1},{"bid_px":"250.000000000","ask_px":"251.130000000","bid_sz":2,"ask_sz":50,"bid_ct":2,"ask_ct":1},{"bid_px":"249.930000000","ask_px":"251.150000000","bid_sz":10,"ask_sz":100,"bid_ct":1,"ask_ct":1},{"bid_px":"249.880000000","ask_px":"251.500000000","bid_sz":4,"ask_sz":10,"bid_ct":1,"ask_ct":1},{"bid_px":"249.850000000","ask_px":"252.400000000","bid_sz":4,"ask_sz":1000,"bid_ct":1,"ask_ct":1},{"bid_px":"249.800000000","ask_px":"253.350000000","bid_sz":199,"ask_sz":23,"bid_ct":1,"ask_ct":1},{"bid_px":"249.770000000","ask_px":"253.650000000","bid_sz":50,"ask_sz":400,"bid_ct":1,"ask_ct":1},{"bid_px":"249.500000000","ask_px":"254.990000000","bid_sz":1000,"ask_sz":5,"bid_ct":1,"ask_ct":1},{"bid_px":"249.000000000","ask_px":"255.000000000","bid_sz":100,"ask_sz":105,"bid_ct":1,"ask_ct":3},{"bid_px":"248.500000000","ask_px":"258.000000000","bid_sz":111,"ask_sz":200,"bid_ct":3,"ask_ct":1}],"symbol":"TSLA"}
{"ts_recv":"2024-11-01T08:00:14.103942544Z","hd":{"ts_event":"2024-11-01T08:00:14.103774190Z","rtype":10,"publisher_id":2,"instrument_id":16244},"action":"T","side":"B","depth":0,"price":"250.880000000","size":9,"flags":130,"ts_in_delta":168354,"sequence":319876,"levels":[{"bid_px":"250.150000000","ask_px":"250.880000000","bid_sz":50,"ask_sz":23,"bid_ct":1,"ask_ct":1},{"bid_px":"250.000000000","ask_px":"251.130000000","bid_sz":2,"ask_sz":50,"bid_ct":2,"ask_ct":1},{"bid_px":"249.930000000","ask_px":"251.150000000","bid_sz":10,"ask_sz":100,"bid_ct":1,"ask_ct":1},{"bid_px":"249.880000000","ask_px":"251.500000000","bid_sz":4,"ask_sz":10,"bid_ct":1,"ask_ct":1},{"bid_px":"249.850000000","ask_px":"252.400000000","bid_sz":4,"ask_sz":1000,"bid_ct":1,"ask_ct":1},{"bid_px":"249.800000000","ask_px":"253.350000000","bid_sz":199,"ask_sz":23,"bid_ct":1,"ask_ct":1},{"bid_px":"249.770000000","ask_px":"253.650000000","bid_sz":50,"ask_sz":400,"bid_ct":1,"ask_ct":1},{"bid_px":"249.500000000","ask_px":"254.990000000","bid_sz":1000,"ask_sz":5,"bid_ct":1,"ask_ct":1},{"bid_px":"249.000000000","ask_px":"255.000000000","bid_sz":100,"ask_sz":105,"bid_ct":1,"ask_ct":3},{"bid_px":"248.500000000","ask_px":"258.000000000","bid_sz":111,"ask_sz":200,"bid_ct":3,"ask_ct":1}],"symbol":"TSLA"}
{"ts_recv":"2024-11-01T08:00:14.103942544Z","hd":{"ts_event":"2024-11-01T08:00:14.103774190Z","rtype":10,"publisher_id":2,"instrument_id":16244},"action":"C","side":"A","depth":0,"price":"250.880000000","size":9,"flags":130,"ts_in_delta":168354,"sequence":319876,"levels":[{"bid_px":"250.150000000","ask_px":"250.880000000","bid_sz":50,"ask_sz":14,"bid_ct":1,"ask_ct":1},{"bid_px":"250.000000000","ask_px":"251.130000000","bid_sz":2,"ask_sz":50,"bid_ct":2,"ask_ct":1},{"bid_px":"249.930000000","ask_px":"251.150000000","bid_sz":10,"ask_sz":100,"bid_ct":1,"ask_ct":1},{"bid_px":"249.880000000","ask_px":"251.500000000","bid_sz":4,"ask_sz":10,"bid_ct":1,"ask_ct":1},{"bid_px":"249.850000000","ask_px":"252.400000000","bid_sz":4,"ask_sz":1000,"bid_ct":1,"ask_ct":1},{"bid_px":"249.800000000","ask_px":"253.350000000","bid_sz":199,"ask_sz":23,"bid_ct":1,"ask_ct":1},{"bid_px":"249.770000000","ask_px":"253.650000000","bid_sz":50,"ask_sz":400,"bid_ct":1,"ask_ct":1},{"bid_px":"249.500000000","ask_px":"254.990000000","bid_sz":1000,"ask_sz":5,"bid_ct":1,"ask_ct":1},{"bid_px":"249.000000000","ask_px":"255.000000000","bid_sz":100,"ask_sz":105,"bid_ct":1,"ask_ct":3},{"bid_px":"248.500000000","ask_px":"258.000000000","bid_sz":111,"ask_sz":200,"bid_ct":3,"ask_ct":1}],"symbol":"TSLA"}
{"ts_recv":"2024-11-01T08:00:14.103983462Z","hd":{"ts_event":"2024-11-01T08:00:14.103817271Z","rtype":10,"publisher_id":2,"instrument_id":16244},"action":"A","side":"B","depth":0,"price":"250.510000000","size":1,"flags":130,"ts_in_delta":166191,"sequence":319878,"levels":[{"bid_px":"250.510000000","ask_px":"250.880000000","bid_sz":1,"ask_sz":14,"bid_ct":1,"ask_ct":1},{"bid_px":"250.150000000","ask_px":"251.130000000","bid_sz":50,"ask_sz":50,"bid_ct":1,"ask_ct":1},{"bid_px":"250.000000000","ask_px":"251.150000000","bid_sz":2,"ask_sz":100,"bid_ct":2,"ask_ct":1},{"bid_px":"249.930000000","ask_px":"251.500000000","bid_sz":10,"ask_sz":10,"bid_ct":1,"ask_ct":1},{"bid_px":"249.880000000","ask_px":"252.400000000","bid_sz":4,"ask_sz":1000,"bid_ct":1,"ask_ct":1},{"bid_px":"249.850000000","ask_px":"253.350000000","bid_sz":4,"ask_sz":23,"bid_ct":1,"ask_ct":1},{"bid_px":"249.800000000","ask_px":"253.650000000","bid_sz":199,"ask_sz":400,"bid_ct":1,"ask_ct":1},{"bid_px":"249.770000000","ask_px":"254.990000000","bid_sz":50,"ask_sz":5,"bid_ct":1,"ask_ct":1},{"bid_px":"249.500000000","ask_px":"255.000000000","bid_sz":1000,"ask_sz":105,"bid_ct":1,"ask_ct":3},{"bid_px":"249.000000000","ask_px":"258.000000000","bid_sz":100,"ask_sz":200,"bid_ct":1,"ask_ct":1}],"symbol":"TSLA"}
{"ts_recv":"2024-11-01T08:00:14.104001263Z","hd":{"ts_event":"2024-11-01T08:00:14.103834859Z","rtype":10,"publisher_id":2,"instrument_id":16244},"action":"A","side":"B","depth":1,"price":"250.290000000","size":1,"flags":130,"ts_in_delta":166404,"sequence":319879,"levels":[{"bid_px":"250.510000000","ask_px":"250.880000000","bid_sz":1,"ask_sz":14,"bid_ct":1,"ask_ct":1},{"bid_px":"250.290000000","ask_px":"251.130000000","bid_sz":1,"ask_sz":50,"bid_ct":1,"ask_ct":1},{"bid_px":"250.150000000","ask_px":"251.150000000","bid_sz":50,"ask_sz":100,"bid_ct":1,"ask_ct":1},{"bid_px":"250.000000000","ask_px":"251.500000000","bid_sz":2,"ask_sz":10,"bid_ct":2,"ask_ct":1},{"bid_px":"249.930000000","ask_px":"252.400000000","bid_sz":10,"ask_sz":1000,"bid_ct":1,"ask_ct":1},{"bid_px":"249.880000000","ask_px":"253.350000000","bid_sz":4,"ask_sz":23,"bid_ct":1,"ask_ct":1},{"bid_px":"249.850000000","ask_px":"253.650000000","bid_sz":4,"ask_sz":400,"bid_ct":1,"ask_ct":1},{"bid_px":"249.800000000","ask_px":"254.990000000","bid_sz":199,"ask_sz":5,"bid_ct":1,"ask_ct":1},{"bid_px":"249.770000000","ask_px":"255.000000000","bid_sz":50,"ask_sz":105,"bid_ct":1,"ask_ct":3},{"bid_px":"249.500000000","ask_px":"258.000000000","bid_sz":1000,"ask_sz":200,"bid_ct":1,"ask_ct":1}],"symbol":"TSLA"}
{"ts_recv":"2024-11-01T08:00:14.110389232Z","hd":{"ts_event":"2024-11-01T08:00:14.110223085Z","rtype":10,"publisher_id":2,"instrument_id":16244},"action":"C","side":"B","depth":0,"price":"250.510000000","size":1,"flags":130,"ts_in_delta":166147,"sequence":319882,"levels":[{"bid_px":"250.290000000","ask_px":"250.880000000","bid_sz":1,"ask_sz":14,"bid_ct":1,"ask_ct":1},{"bid_px":"250.150000000","ask_px":"251.130000000","bid_sz":50,"ask_sz":50,"bid_ct":1,"ask_ct":1},{"bid_px":"250.000000000","ask_px":"251.150000000","bid_sz":2,"ask_sz":100,"bid_ct":2,"ask_ct":1},{"bid_px":"249.930000000","ask_px":"251.500000000","bid_sz":10,"ask_sz":10,"bid_ct":1,"ask_ct":1},{"bid_px":"249.880000000","ask_px":"252.400000000","bid_sz":4,"ask_sz":1000,"bid_ct":1,"ask_ct":1},{"bid_px":"249.850000000","ask_px":"253.350000000","bid_sz":4,"ask_sz":23,"bid_ct":1,"ask_ct":1},{"bid_px":"249.800000000","ask_px":"253.650000000","bid_sz":199,"ask_sz":400,"bid_ct":1,"ask_ct":1},{"bid_px":"249.770000000","ask_px":"254.990000000","bid_sz":50,"ask_sz":5,"bid_ct":1,"ask_ct":1},{"bid_px":"249.500000000","ask_px":"255.000000000","bid_sz":1000,"ask_sz":105,"bid_ct":1,"ask_ct":3},{"bid_px":"249.000000000","ask_px":"258.000000000","bid_sz":100,"ask_sz":200,"bid_ct":1,"ask_ct":1}],"symbol":"TSLA"}
{"ts_recv":"2024-11-01T08:00:14.166791492Z","hd":{"ts_event":"2024-11-01T08:00:14.166625216Z","rtype":10,"publisher_id":2,"instrument_id":17709},"action":"A","side":"A","depth":2,"price":"9900.000000000","size":11,"flags":130,"ts_in_delta":166276,"sequence":320064,"levels":[{"bid_px":"116.000000000","ask_px":"118.600000000","bid_sz":100,"ask_sz":100,"bid_ct":1,"ask_ct":1},{"bid_px":"115.290000000","ask_px":"125.000000000","bid_sz":100,"ask_sz":30,"bid_ct":1,"ask_ct":1},{"bid_px":null,"ask_px":"9900.000000000","bid_sz":0,"ask_sz":11,"bid_ct":0,"ask_ct":1},{"bid_px":null,"ask_px":null,"bid_sz":0,"ask_sz":0,"bid_ct":0,"ask_ct":0},{"bid_px":null,"ask_px":null,"bid_sz":0,"ask_sz":0,"bid_ct":0,"ask_ct":0},{"bid_px":null,"ask_px":null,"bid_sz":0,"ask_sz":0,"bid_ct":0,"ask_ct":0},{"bid_px":null,"ask_px":null,"bid_sz":0,"ask_sz":0,"bid_ct":0,"ask_ct":0},{"bid_px":null,"ask_px":null,"bid_sz":0,"ask_sz":0,"bid_ct":0,"ask_ct":0},{"bid_px":null,"ask_px":null,"bid_sz":0,"ask_sz":0,"bid_ct":0,"ask_ct":0},{"bid_px":null,"ask_px":null,"bid_sz":0,"ask_sz":0,"bid_ct":0,"ask_ct":0}],"symbol":"XOM"}
{"ts_recv":"2024-11-01T08:00:14.193592237Z","hd":{"ts_event":"2024-11-01T08:00:14.193426478Z","rtype":10,"publisher_id":2,"instrument_id":38},"action":"C","side":"B","depth":1,"price":"221.400000000","size":1000,"flags":130,"ts_in_delta":165759,"sequence":320200,"levels":[{"bid_px":"221.700000000","ask_px":"224.400000000","bid_sz":10,"ask_sz":1000,"bid_ct":1,"ask_ct":1},{"bid_px":"221.200000000","ask_px":"225.000000000","bid_sz":10,"ask_sz":1,"bid_ct":1,"ask_ct":1},{"bid_px":"220.000000000","ask_px":"225.360000000","bid_sz":8,"ask_sz":1,"bid_ct":2,"ask_ct":1},{"bid_px":"219.690000000","ask_px":"225.490000000","bid_sz":442,"ask_sz":442,"bid_ct":1,"ask_ct":1},{"bid_px":"219.000000000","ask_px":"225.900000000","bid_sz":1,"ask_sz":32,"bid_ct":1,"ask_ct":2},{"bid_px":"217.000000000","ask_px":"227.000000000","bid_sz":1525,"ask_sz":35,"bid_ct":1,"ask_ct":1},{"bid_px":"215.000000000","ask_px":"229.330000000","bid_sz":5,"ask_sz":9,"bid_ct":1,"ask_ct":2},{"bid_px":"213.000000000","ask_px":"233.670000000","bid_sz":5,"ask_sz":5,"bid_ct":1,"ask_ct":1},{"bid_px":"212.340000000","ask_px":"234.000000000","bid_sz":5,"ask_sz":20,"bid_ct":1,"ask_ct":1},{"bid_px":"210.000000000","ask_px":"234.750000000","bid_sz":6,"ask_sz":50,"bid_ct":2,"ask_ct":1}],"symbol":"AAPL"}
{"ts_recv":"2024-11-01T08:00:14.204321367Z","hd":{"ts_event":"2024-11-01T08:00:14.204155394Z","rtype":10,"publisher_id":2,"instrument_id":38},"action":"A","side":"B","depth":1,"price":"221.300000000","size":1000,"flags":130,"ts_in_delta":165973,"sequence":320299,"levels":[{"bid_px":"221.700000000","ask_px":"224.400000000","bid_sz":10,"ask_sz":1000,"bid_ct":1,"ask_ct":1},{"bid_px":"221.300000000","ask_px":"225.000000000","bid_sz":1000,"ask_sz":1,"bid_ct":1,"ask_ct":1},{"bid_px":"221.200000000","ask_px":"225.360000000","bid_sz":10,"ask_sz":1,"bid_ct":1,"ask_ct":1},{"bid_px":"220.000000000","ask_px":"225.490000000","bid_sz":8,"ask_sz":442,"bid_ct":2,"ask_ct":1},{"bid_px":"219.690000000","ask_px":"225.900000000","bid_sz":442,"ask_sz":32,"bid_ct":1,"ask_ct":2},{"bid_px":"219.000000000","ask_px":"227.000000000","bid_sz":1,"ask_sz":35,"bid_ct":1,"ask_ct":1},{"bid_px":"217.000000000","ask_px":"229.330000000","bid_sz":1525,"ask_sz":9,"bid_ct":1,"ask_ct":2},{"bid_px":"215.000000000","ask_px":"233.670000000","bid_sz":5,"ask_sz":5,"bid_ct":1,"ask_ct":1},{"bid_px":"213.000000000","ask_px":"234.000000000","bid_sz":5,"ask_sz":20,"bid_ct":1,"ask_ct":1},{"bid_px":"212.340000000","ask_px":"234.750000000","bid_sz":5,"ask_sz":50,"bid_ct":1,"ask_ct":1}],"symbol":"AAPL"}
{"ts_recv":"2024-11-01T08:00:14.239148320Z","hd":{"ts_event":"2024-11-01T08:00:14.238982209Z","rtype":10,"publisher_id":2,"instrument_id":16727},"action":"A","side":"B","depth":0,"price":"273.000000000","size":2,"flags":130,"ts_in_delta":166111,"sequence":320677,"levels":[{"bid_px":"273.000000000","ask_px":"300.000000000","bid_sz":2,"ask_sz":1,"bid_ct":1,"ask_ct":1},{"bid_px":"268.000000000","ask_px":"305.000000000","bid_sz":25,"ask_sz":1,"bid_ct":1,"ask_ct":1},{"bid_px":null,"ask_px":null,"bid_sz":0,"ask_sz":0,"bid_ct":0,"ask_ct":0},{"bid_px":null,"ask_px":null,"bid_sz":0,"ask_sz":0,"bid_ct":0,"ask_ct":0},{"bid_px":null,"ask_px":null,"bid_sz":0,"ask_sz":0,"bid_ct":0,"ask_ct":0},{"bid_px":null,"ask_px":null,"bid_sz":0,"ask_sz":0,"bid_ct":0,"ask_ct":0},{"bid_px":null,"ask_px":null,"bid_sz":0,"ask_sz":0,"bid_ct":0,"ask_ct":0},{"bid_px":null,"ask_px":null,"bid_sz":0,"ask_sz":0,"bid_ct":0,"ask_ct":0},{"bid_px":null,"ask_px":null,"bid_sz":0,"ask_sz":0,"bid_ct":0,"ask_ct":0},{"bid_px":null,"ask_px":null,"bid_sz":0,"ask_sz":0,"bid_ct":0,"ask_ct":0}],"symbol":"V"}
{"ts_recv":"2024-11-01T08:00:14.263062898Z","hd":{"ts_event":"2024-11-01T08:00:14.262896339Z","rtype":10,"publisher_id":2,"instrument_id":16727},"action":"A","side":"A","depth":0,"price":"295.000000000","size":5,"flags":130,"ts_in_delta":166559,"sequence":320728,"levels":[{"bid_px":"273.000000000","ask_px":"295.000000000","bid_sz":2,"ask_sz":5,"bid_ct":1,"ask_ct":1},{"bid_px":"268.000000000","ask_px":"300.000000000","bid_sz":25,"ask_sz":1,"bid_ct":1,"ask_ct":1},{"bid_px":null,"ask_px":"305.000000000","bid_sz":0,"ask_sz":1,"bid_ct":0,"ask_ct":1},{"bid_px":null,"ask_px":null,"bid_sz":0,"ask_sz":0,"bid_ct":0,"ask_ct":0},{"bid_px":null,"ask_px":null,"bid_sz":0,"ask_sz":0,"bid_ct":0,"ask_ct":0},{"bid_px":null,"ask_px":null,"bid_sz":0,"ask_sz":0,"bid_ct":0,"ask_ct":0},{"bid_px":null,"ask_px":null,"bid_sz":0,"ask_sz":0,"bid_ct":0,"ask_ct":0},{"bid_px":null,"ask_px":null,"bid_sz":0,"ask_sz":0,"bid_ct":0,"ask_ct":0},{"bid_px":null,"ask_px":null,"bid_sz":0,"ask_sz":0,"bid_ct":0,"ask_ct":0},{"bid_px":null,"ask_px":null,"bid_sz":0,"ask_sz":0,"bid_ct":0,"ask_ct":0}],"symbol":"V"}
{"ts_recv":"2024-11-01T08:00:14.268163964Z","hd":{"ts_event":"2024-11-01T08:00:14.267997708Z","rtype":10,"publisher_id":2,"instrument_id":10888},"action":"A","side":"A","depth":6,"price":"445.000000000","size":2,"flags":130,"ts_in_delta":166256,"sequence":320759,"levels":[{"bid_px":"410.000000000","ask_px":"414.000000000","bid_sz":31,"ask_sz":468,"bid_ct":2,"ask_ct":2},{"bid_px":"409.750000000","ask_px":"415.070000000","bid_sz":3,"ask_sz":246,"bid_ct":1,"ask_ct":1},{"bid_px":"409.740000000","ask_px":"415.350000000","bid_sz":500,"ask_sz":84,"bid_ct":1,"ask_ct":2},{"bid_px":"409.670000000","ask_px":"419.860000000","bid_sz":100,"ask_sz":10,"bid_ct":1,"ask_ct":1},{"bid_px":"409.430000000","ask_px":"420.000000000","bid_sz":5,"ask_sz":3,"bid_ct":1,"ask_ct":1},{"bid_px":"409.250000000","ask_px":"440.000000000","bid_sz":2,"ask_sz":35,"bid_ct":1,"ask_ct":1},{"bid_px":"409.080000000","ask_px":"445.000000000","bid_sz":2,"ask_sz":27,"bid_ct":1,"ask_ct":2},{"bid_px":"409.000000000","ask_px":"445.680000000","bid_sz":3,"ask_sz":3,"bid_ct":2,"ask_ct":1},{"bid_px":"408.970000000","ask_px":"448.000000000","bid_sz":12,"ask_sz":15,"bid_ct":1,"ask_ct":2},{"bid_px":"408.960000000","ask_px":"450.000000000","bid_sz":5,"ask_sz":48,"bid_ct":1,"ask_ct":3}],"symbol":"MSFT"}
{"ts_recv":"2024-11-01T08:00:14.337263072Z","hd":{"ts_event":"2024-11-01T08:00:14.337096409Z","rtype":10,"publisher_id":2,"instrument_id":16727},"action":"A","side":"B","depth":0,"price":"275.000000000","size":2,"flags":130,"ts_in_delta":166663,"sequence":320986,"levels":[{"bid_px":"275.000000000","ask_px":"295.000000000","bid_sz":2,"ask_sz":5,"bid_ct":1,"ask_ct":1},{"bid_px":"273.000000000","ask_px":"300.000000000","bid_sz":2,"ask_sz":1,"bid_ct":1,"ask_ct":1},{"bid_px":"268.000000000","ask_px":"305.000000000","bid_sz":25,"ask_sz":1,"bid_ct":1,"ask_ct":1},{"bid_px":null,"ask_px":null,"bid_sz":0,"ask_sz":0,"bid_ct":0,"ask_ct":0},{"bid_px":null,"ask_px":null,"bid_sz":0,"ask_sz":0,"bid_ct":0,"ask_ct":0},{"bid_px":null,"ask_px":null,"bid_sz":0,"ask_sz":0,"bid_ct":0,"ask_ct":0},{"bid_px":null,"ask_px":null,"bid_sz":0,"ask_sz":0,"bid_ct":0,"ask_ct":0},{"bid_px":null,"ask_px":null,"bid_sz":0,"ask_sz":0,"bid_ct":0,"ask_ct":0},{"bid_px":null,"ask_px":null,"bid_sz":0,"ask_sz":0,"bid_ct":0,"ask_ct":0},{"bid_px":null,"ask_px":null,"bid_sz":0,"ask_sz":0,"bid_ct":0,"ask_ct":0}],"symbol":"V"}
{"ts_recv":"2024-11-01T08:00:14.368303065Z","hd":{"ts_event":"2024-11-01T08:00:14.368136838Z","rtype":10,"publisher_id":2,"instrument_id":16727},"action":"A","side":"A","depth":1,"price":"298.000000000","size":7,"flags":130,"ts_in_delta":166227,"sequence":321054,"levels":[{"bid_px":"275.000000000","ask_px":"295.000000000","bid_sz":2,"ask_sz":5,"bid_ct":1,"ask_ct":1},{"bid_px":"273.000000000","ask_px":"298.000000000","bid_sz":2,"ask_sz":7,"bid_ct":1,"ask_ct":1},{"bid_px":"268.000000000","ask_px":"300.000000000","bid_sz":25,"ask_sz":1,"bid_ct":1,"ask_ct":1},{"bid_px":null,"ask_px":"305.000000000","bid_sz":0,"ask_sz":1,"bid_ct":0,"ask_ct":1},{"bid_px":null,"ask_px":null,"bid_sz":0,"ask_sz":0,"bid_ct":0,"ask_ct":0},{"bid_px":null,"ask_px":null,"bid_sz":0,"ask_sz":0,"bid_ct":0,"ask_ct":0},{"bid_px":null,"ask_px":null,"bid_sz":0,"ask_sz":0,"bid_ct":0,"ask_ct":0},{"bid_px":null,"ask_px":null,"bid_sz":0,"ask_sz":0,"bid_ct":0,"ask_ct":0},{"bid_px":null,"ask_px":null,"bid_sz":0,"ask_sz":0,"bid_ct":0,"ask_ct":0},{"bid_px":null,"ask_px":null,"bid_sz":0,"ask_sz":0,"bid_ct":0,"ask_ct":0}],"symbol":"V"}
{"ts_recv":"2024-11-01T08:00:14.372789135Z","hd":{"ts_event":"2024-11-01T08:00:14.372622693Z","rtype":10,"publisher_id":2,"instrument_id":16244},"action":"A","side":"B","depth":0,"price":"250.590000000","size":2,"flags":130,"ts_in_delta":166442,"sequence":321093,"levels":[{"bid_px":"250.590000000","ask_px":"250.880000000","bid_sz":2,"ask_sz":14,"bid_ct":1,"ask_ct":1},{"bid_px":"250.290000000","ask_px":"251.130000000","bid_sz":1,"ask_sz":50,"bid_ct":1,"ask_ct":1},{"bid_px":"250.150000000","ask_px":"251.150000000","bid_sz":50,"ask_sz":100,"bid_ct":1,"ask_ct":1},{"bid_px":"250.000000000","ask_px":"251.500000000","bid_sz":2,"ask_sz":10,"bid_ct":2,"ask_ct":1},{"bid_px":"249.930000000","ask_px":"252.400000000","bid_sz":10,"ask_sz":1000,"bid_ct":1,"ask_ct":1},{"bid_px":"249.880000000","ask_px":"253.350000000","bid_sz":4,"ask_sz":23,"bid_ct":1,"ask_ct":1},{"bid_px":"249.850000000","ask_px":"253.650000000","bid_sz":4,"ask_sz":400,"bid_ct":1,"ask_ct":1},{"bid_px":"249.800000000","ask_px":"254.990000000","bid_sz":199,"ask_sz":5,"bid_ct":1,"ask_ct":1},{"bid_px":"249.770000000","ask_px":"255.000000000","bid_sz":50,"ask_sz":105,"bid_ct":1,"ask_ct":3},{"bid_px":"249.500000000","ask_px":"258.000000000","bid_sz":1000,"ask_sz":200,"bid_ct":1,"ask_ct":1}],"symbol":"TSLA"}
{"ts_recv":"2024-11-01T08:00:14.372951976Z","hd":{"ts_event":"2024-11-01T08:00:14.372785914Z","rtype":10,"publisher_id":2,"instrument_id":16244},"action":"A","side":"B","depth":0,"price":"250.590000000","size":1,"flags":130,"ts_in_delta":166062,"sequence":321096,"levels":[{"bid_px":"250.590000000","ask_px":"250.880000000","bid_sz":3,"ask_sz":14,"bid_ct":2,"ask_ct":1},{"bid_px":"250.290000000","ask_px":"251.130000000","bid_sz":1,"ask_sz":50,"bid_ct":1,"ask_ct":1},{"bid_px":"250.150000000","ask_px":"251.150000000","bid_sz":50,"ask_sz":100,"bid_ct":1,"ask_ct":1},{"bid_px":"250.000000000","ask_px":"251.500000000","bid_sz":2,"ask_sz":10,"bid_ct":2,"ask_ct":1},{"bid_px":"249.930000000","ask_px":"252.400000000","bid_sz":10,"ask_sz":1000,"bid_ct":1,"ask_ct":1},{"bid_px":"249.880000000","ask_px":"253.350000000","bid_sz":4,"ask_sz":23,"bid_ct":1,"ask_ct":1},{"bid_px":"249.850000000","ask_px":"253.650000000","bid_sz":4,"ask_sz":400,"bid_ct":1,"ask_ct":1},{"bid_px":"249.800000000","ask_px":"254.990000000","bid_sz":199,"ask_sz":5,"bid_ct":1,"ask_ct":1},{"bid_px":"249.770000000","ask_px":"255.000000000","bid_sz":50,"ask_sz":105,"bid_ct":1,"ask_ct":3},{"bid_px":"249.500000000","ask_px":"258.000000000","bid_sz":1000,"ask_sz":200,"bid_ct":1,"ask_ct":1}],"symbol":"TSLA"}
{"ts_recv":"2024-11-01T08:00:14.373237946Z","hd":{"ts_event":"2024-11-01T08:00:14.373071835Z","rtype":10,"publisher_id":2,"instrument_id":16244},"action":"A","side":"A","depth":3,"price":"251.450000000","size":157,"flags":130,"ts_in_delta":166111,"sequence":321101,"levels":[{"bid_px":"250.590000000","ask_px":"250.880000000","bid_sz":3,"ask_sz":14,"bid_ct":2,"ask_ct":1},{"bid_px":"250.290000000","ask_px":"251.130000000","bid_sz":1,"ask_sz":50,"bid_ct":1,"ask_ct":1},{"bid_px":"250.150000000","ask_px":"251.150000000","bid_sz":50,"ask_sz":100,"bid_ct":1,"ask_ct":1},{"bid_px":"250.000000000","ask_px":"251.450000000","bid_sz":2,"ask_sz":157,"bid_ct":2,"ask_ct":1},{"bid_px":"249.930000000","ask_px":"251.500000000","bid_sz":10,"ask_sz":10,"bid_ct":1,"ask_ct":1},{"bid_px":"249.880000000","ask_px":"252.400000000","bid_sz":4,"ask_sz":1000,"bid_ct":1,"ask_ct":1},{"bid_px":"249.850000000","ask_px":"253.350000000","bid_sz":4,"ask_sz":23,"bid_ct":1,"ask_ct":1},{"bid_px":"249.800000000","ask_px":"253.650000000","bid_sz":199,"ask_sz":400,"bid_ct":1,"ask_ct":1},{"bid_px":"249.770000000","ask_px":"254.990000000","bid_sz":50,"ask_sz":5,"bid_ct":1,"ask_ct":1},{"bid_px":"249.500000000","ask_px":"255.000000000","bid_sz":1000,"ask_sz":105,"bid_ct":1,"ask_ct":3}],"symbol":"TSLA"}
{"ts_recv":"2024-11-01T08:00:14.373786027Z","hd":{"ts_event":"2024-11-01T08:00:14.373619762Z","rtype":10,"publisher_id":2,"instrument_id":16244},"action":"A","side":"A","depth":9,"price":"255.000000000","size":50,"flags":130,"ts_in_delta":166265,"sequence":321109,"levels":[{"bid_px":"250.590000000","ask_px":"250.880000000","bid_sz":3,"ask_sz":14,"bid_ct":2,"ask_ct":1},{"bid_px":"250.290000000","ask_px":"251.130000000","bid_sz":1,"ask_sz":50,"bid_ct":1,"ask_ct":1},{"bid_px":"250.150000000","ask_px":"251.150000000","bid_sz":50,"ask_sz":100,"bid_ct":1,"ask_ct":1},{"bid_px":"250.000000000","ask_px":"251.450000000","bid_sz":2,"ask_sz":157,"bid_ct":2,"ask_ct":1},{"bid_px":"249.930000000","ask_px":"251.500000000","bid_sz":10,"ask_sz":10,"bid_ct":1,"ask_ct":1},{"bid_px":"249.880000000","ask_px":"252.400000000","bid_sz":4,"ask_sz":1000,"bid_ct":1,"ask_ct":1},{"bid_px":"249.850000000","ask_px":"253.350000000","bid_sz":4,"ask_sz":23,"bid_ct":1,"ask_ct":1},{"bid_px":"249.800000000","ask_px":"253.650000000","bid_sz":199,"ask_sz":400,"bid_ct":1,"ask_ct":1},{"bid_px":"249.770000000","ask_px":"254.990000000","bid_sz":50,"ask_sz":5,"bid_ct":1,"ask_ct":1},{"bid_px":"249.500000000","ask_px":"255.000000000","bid_sz":1000,"ask_sz":155,"bid_ct":1,"ask_ct":4}],"symbol":"TSLA"}
{"ts_recv":"2024-11-01T08:00:14.389979179Z","hd":{"ts_event":"2024-11-01T08:00:14.389813052Z","rtype":10,"publisher_id":2,"instrument_id":38},"action":"A","side":"B","depth":0,"price":"221.700000000","size":14,"flags":130,"ts_in_delta":166127,"sequence":321190,"levels":[{"bid_px":"221.700000000","ask_px":"224.400000000","bid_sz":24,"ask_sz":1000,"bid_ct":2,"ask_ct":1},{"bid_px":"221.300000000","ask_px":"225.000000000","bid_sz":1000,"ask_sz":1,"bid_ct":1,"ask_ct":1},{"bid_px":"221.200000000","ask_px":"225.360000000","bid_sz":10,"ask_sz":1,"bid_ct":1,"ask_ct":1},{"bid_px":"220.000000000","ask_px":"225.490000000","bid_sz":8,"ask_sz":442,"bid_ct":2,"ask_ct":1},{"bid_px":"219.690000000","ask_px":"225.900000000","bid_sz":442,"ask_sz":32,"bid_ct":1,"ask_ct":2},{"bid_px":"219.000000000","ask_px":"227.000000000","bid_sz":1,"ask_sz":35,"bid_ct":1,"ask_ct":1},{"bid_px":"217.000000000","ask_px":"229.330000000","bid_sz":1525,"ask_sz":9,"bid_ct":1,"ask_ct":2},{"bid_px":"215.000000000","ask_px":"233.670000000","bid_sz":5,"ask_sz":5,"bid_ct":1,"ask_ct":1},{"bid_px":"213.000000000","ask_px":"234.000000000","bid_sz":5,"ask_sz":20,"bid_ct":1,"ask_ct":1},{"bid_px":"212.340000000","ask_px":"234.750000000","bid_sz":5,"ask_sz":50,"bid_ct":1,"ask_ct":1}],"symbol":"AAPL"}
{"ts_recv":"2024-11-01T08:00:14.399904537Z","hd":{"ts_event":"2024-11-01T08:00:14.399738320Z","rtype":10,"publisher_id":2,"instrument_id":12463},"action":"A","side":"A","depth":1,"price":"175.000000000","size":4,"flags":130,"ts_in_delta":166217,"sequence":321199,"levels":[{"bid_px":"163.980000000","ask_px":"169.470000000","bid_sz":100,"ask_sz":100,"bid_ct":1,"ask_ct":1},{"bid_px":null,"ask_px":"175.000000000","bid_sz":0,"ask_sz":4,"bid_ct":0,"ask_ct":1},{"bid_px":null,"ask_px":"180.000000000","bid_sz":0,"ask_sz":20,"bid_ct":0,"ask_ct":1},{"bid_px":null,"ask_px":null,"bid_sz":0,"ask_sz":0,"bid_ct":0,"ask_ct":0},{"bid_px":null,"ask_px":null,"bid_sz":0,"ask_sz":0,"bid_ct":0,"ask_ct":0},{"bid_px":null,"ask_px":null,"bid_sz":0,"ask_sz":0,"bid_ct":0,"ask_ct":0},{"bid_px":null,"ask_px":null,"bid_sz":0,"ask_sz":0,"bid_ct":0,"ask_ct":0},{"bid_px":null,"ask_px":null,"bid_sz":0,"ask_sz":0,"bid_ct":0,"ask_ct":0},{"bid_px":null,"ask_px":null,"bid_sz":0,"ask_sz":0,"bid_ct":0,"ask_ct":0},{"bid_px":null,"ask_px":null,"bid_sz":0,"ask_sz":0,"bid_ct":0,"ask_ct":0}],"symbol":"PEP"}
{"ts_recv":"2024-11-01T08:00:14.421150070Z","hd":{"ts_event":"2024-11-01T08:00:14.420983738Z","rtype":10,"publisher_id":2,"instrument_id":16244},"action":"A","side":"A","depth":9,"price":"255.000000000","size":5,"flags":130,"ts_in_delta":166332,"sequence":321243,"levels":[{"bid_px":"250.590000000","ask_px":"250.880000000","bid_sz":3,"ask_sz":14,"bid_ct":2,"ask_ct":1},{"bid_px":"250.290000000","ask_px":"251.130000000","bid_sz":1,"ask_sz":50,"bid_ct":1,"ask_ct":1},{"bid_px":"250.150000000","ask_px":"251.150000000","bid_sz":50,"ask_sz":100,"bid_ct":1,"ask_ct":1},{"bid_px":"250.000000000","ask_px":"251.450000000","bid_sz":2,"ask_sz":157,"bid_ct":2,"ask_ct":1},{"bid_px":"249.930000000","ask_px":"251.500000000","bid_sz":10,"ask_sz":10,"bid_ct":1,"ask_ct":1},{"bid_px":"249.880000000","ask_px":"252.400000000","bid_sz":4,"ask_sz":1000,"bid_ct":1,"ask_ct":1},{"bid_px":"249.850000000","ask_px":"253.350000000","bid_sz":4,"ask_sz":23,"bid_ct":1,"ask_ct":1},{"bid_px":"249.800000000","ask_px":"253.650000000","bid_sz":199,"ask_sz":400,"bid_ct":1,"ask_ct":1},{"bid_px":"249.770000000","ask_px":"254.990000000","bid_sz":50,"ask_sz":5,"bid_ct":1,"ask_ct":1},{"bid_px":"249.500000000","ask_px":"255.000000000","bid_sz":1000,"ask_sz":160,"bid_ct":1,"ask_ct":5}],"symbol":"TSLA"}
{"ts_recv":"2024-11-01T08:00:14.422030836Z","hd":{"ts_event":"2024-11-01T08:00:14.421864617Z","rtype":10,"publisher_id":2,"instrument_id":16244},"action":"A","side":"A","depth":3,"price":"251.450000000","size":217,"flags":130,"ts_in_delta":166219,"sequence":321257,"levels":[{"bid_px":"250.590000000","ask_px":"250.880000000","bid_sz":3,"ask_sz":14,"bid_ct":2,"ask_ct":1},{"bid_px":"250.290000000","ask_px":"251.130000000","bid_sz":1,"ask_sz":50,"bid_ct":1,"ask_ct":1},{"bid_px":"250.150000000","ask_px":"251.150000000","bid_sz":50,"ask_sz":100,"bid_ct":1,"ask_ct":1},{"bid_px":"250.000000000","ask_px":"251.450000000","bid_sz":2,"ask_sz":374,"bid_ct":2,"ask_ct":2},{"bid_px":"249.930000000","ask_px":"251.500000000","bid_sz":10,"ask_sz":10,"bid_ct":1,"ask_ct":1},{"bid_px":"249.880000000","ask_px":"252.400000000","bid_sz":4,"ask_sz":1000,"bid_ct":1,"ask_ct":1},{"bid_px":"249.850000000","ask_px":"253.350000000","bid_sz":4,"ask_sz":23,"bid_ct":1,"ask_ct":1},{"bid_px":"249.800000000","ask_px":"253.650000000","bid_sz":199,"ask_sz":400,"bid_ct":1,"ask_ct":1},{"bid_px":"249.770000000","ask_px":"254.990000000","bid_sz":50,"ask_sz":5,"bid_ct":1,"ask_ct":1},{"bid_px":"249.500000000","ask_px":"255.000000000","bid_sz":1000,"ask_sz":160,"bid_ct":1,"ask_ct":5}],"symbol":"TSLA"}
{"ts_recv":"2024-11-01T08:00:14.452294541Z","hd":{"ts_event":"2024-11-01T08:00:14.452128117Z","rtype":10,"publisher_id":2,"instrument_id":10888},"action":"A","side":"A","depth":9,"price":"449.970000000","size":30,"flags":130,"ts_in_delta":166424,"sequence":321286,"levels":[{"bid_px":"410.000000000","ask_px":"414.000000000","bid_sz":31,"ask_sz":468,"bid_ct":2,"ask_ct":2},{"bid_px":"409.750000000","ask_px":"415.070000000","bid_sz":3,"ask_sz":246,"bid_ct":1,"ask_ct":1},{"bid_px":"409.740000000","ask_px":"415.350000000","bid_sz":500,"ask_sz":84,"bid_ct":1,"ask_ct":2},{"bid_px":"409.670000000","ask_px":"419.860000000","bid_sz":100,"ask_sz":10,"bid_ct":1,"ask_ct":1},{"bid_px":"409.430000000","ask_px":"420.000000000","bid_sz":5,"ask_sz":3,"bid_ct":1,"ask_ct":1},{"bid_px":"409.250000000","ask_px":"440.000000000","bid_sz":2,"ask_sz":35,"bid_ct":1,"ask_ct":1},{"bid_px":"409.080000000","ask_px":"445.000000000","bid_sz":2,"ask_sz":27,"bid_ct":1,"ask_ct":2},{"bid_px":"409.000000000","ask_px":"445.680000000","bid_sz":3,"ask_sz":3,"bid_ct":2,"ask_ct":1},{"bid_px":"408.970000000","ask_px":"448.000000000","bid_sz":12,"ask_sz":15,"bid_ct":1,"ask_ct":2},{"bid_px":"408.960000000","ask_px":"449.970000000","bid_sz":5,"ask_sz":30,"bid_ct":1,"ask_ct":1}],"symbol":"MSFT"}
{"ts_recv":"2024-11-01T08:00:14.474154694Z","hd":{"ts_event":"2024-11-01T08:00:14.473988644Z","rtype":10,"publisher_id":2,"instrument_id":16244},"action":"A","side":"B","depth":0,"price":"250.590000000","size":4,"flags":130,"ts_in_delta":166050,"sequence":321323,"levels":[{"bid_px":"250.590000000","ask_px":"250.880000000","bid_sz":7,"ask_sz":14,"bid_ct":3,"ask_ct":1},{"bid_px":"250.290000000","ask_px":"251.130000000","bid_sz":1,"ask_sz":50,"bid_ct":1,"ask_ct":1},{"bid_px":"250.150000000","ask_px":"251.150000000","bid_sz":50,"ask_sz":100,"bid_ct":1,"ask_ct":1},{"bid_px":"250.000000000","ask_px":"251.450000000","bid_sz":2,"ask_sz":374,"bid_ct":2,"ask_ct":2},{"bid_px":"249.930000000","ask_px":"251.500000000","bid_sz":10,"ask_sz":10,"bid_ct":1,"ask_ct":1},{"bid_px":"249.880000000","ask_px":"252.400000000","bid_sz":4,"ask_sz":1000,"bid_ct":1,"ask_ct":1},{"bid_px":"249.850000000","ask_px":"253.350000000","bid_sz":4,"ask_sz":23,"bid_ct":1,"ask_ct":1},{"bid_px":"249.800000000","ask_px":"253.650000000","bid_sz":199,"ask_sz":400,"bid_ct":1,"ask_ct":1},{"bid_px":"249.770000000","ask_px":"254.990000000","bid_sz":50,"ask_sz":5,"bid_ct":1,"ask_ct":1},{"bid_px":"249.500000000","ask_px":"255.000000000","bid_sz":1000,"ask_sz":160,"bid_ct":1,"ask_ct":5}],"symbol":"TSLA"}
{"ts_recv":"2024-11-01T08:00:14.475259273Z","hd":{"ts_event":"2024-11-01T08:00:14.475093049Z","rtype":10,"publisher_id":2,"instrument_id":16244},"action":"A","side":"A","depth":8,"price":"253.880000000","size":8,"flags":130,"ts_in_delta":166224,"sequence":321336,"levels":[{"bid_px":"250.590000000","ask_px":"250.880000000","bid_sz":7,"ask_sz":14,"bid_ct":3,"ask_ct":1},{"bid_px":"250.290000000","ask_px":"251.130000000","bid_sz":1,"ask_sz":50,"bid_ct":1,"ask_ct":1},{"bid_px":"250.150000000","ask_px":"251.150000000","bid_sz":50,"ask_sz":100,"bid_ct":1,"ask_ct":1},{"bid_px":"250.000000000","ask_px":"251.450000000","bid_sz":2,"ask_sz":374,"bid_ct":2,"ask_ct":2},{"bid_px":"249.930000000","ask_px":"251.500000000","bid_sz":10,"ask_sz":10,"bid_ct":1,"ask_ct":1},{"bid_px":"249.880000000","ask_px":"252.400000000","bid_sz":4,"ask_sz":1000,"bid_ct":1,"ask_ct":1},{"bid_px":"249.850000000","ask_px":"253.350000000","bid_sz":4,"ask_sz":23,"bid_ct":1,"ask_ct":1},{"bid_px":"249.800000000","ask_px":"253.650000000","bid_sz":199,"ask_sz":400,"bid_ct":1,"ask_ct":1},{"bid_px":"249.770000000","ask_px":"253.880000000","bid_sz":50,"ask_sz":8,"bid_ct":1,"ask_ct":1},{"bid_px":"249.500000000","ask_px":"254.990000000","bid_sz":1000,"ask_sz":5,"bid_ct":1,"ask_ct":1}],"symbol":"TSLA"}
{"ts_recv":"2024-11-01T08:00:14.480435975Z","hd":{"ts_event":"2024-11-01T08:00:14.480269714Z","rtype":10,"publisher_id":2,"instrument_id":10888},"action":"A","side":"A","depth":0,"price":"413.000000000","size":20,"flags":130,"ts_in_delta":166261,"sequence":321390,"levels":[{"bid_px":"410.000000000","ask_px":"413.000000000","bid_sz":31,"ask_sz":20,"bid_ct":2,"ask_ct":1},{"bid_px":"409.750000000","ask_px":"414.000000000","bid_sz":3,"ask_sz":468,"bid_ct":1,"ask_ct":2},{"bid_px":"409.740000000","ask_px":"415.070000000","bid_sz":500,"ask_sz":246,"bid_ct":1,"ask_ct":1},{"bid_px":"409.670000000","ask_px":"415.350000000","bid_sz":100,"ask_sz":84,"bid_ct":1,"ask_ct":2},{"bid_px":"409.430000000","ask_px":"419.860000000","bid_sz":5,"ask_sz":10,"bid_ct":1,"ask_ct":1},{"bid_px":"409.250000000","ask_px":"420.000000000","bid_sz":2,"ask_sz":3,"bid_ct":1,"ask_ct":1},{"bid_px":"409.080000000","ask_px":"440.000000000","bid_sz":2,"ask_sz":35,"bid_ct":1,"ask_ct":1},{"bid_px":"409.000000000","ask_px":"445.000000000","bid_sz":3,"ask_sz":27,"bid_ct":2,"ask_ct":2},{"bid_px":"408.970000000","ask_px":"445.680000000","bid_sz":12,"ask_sz":3,"bid_ct":1,"ask_ct":1},{"bid_px":"408.960000000","ask_px":"448.000000000","bid_sz":5,"ask_sz":15,"bid_ct":1,"ask_ct":2}],"symbol":"MSFT"}
{"ts_recv":"2024-11-01T08:00:14.480656467Z","hd":{"ts_event":"2024-11-01T08:00:14.480490127Z","rtype":10,"publisher_id":2,"instrument_id":10888},"action":"A","side":"A","depth":3,"price":"415.290000000","size":34,"flags":130,"ts_in_delta":166340,"sequence":321394,"levels":[{"bid_px":"410.000000000","ask_px":"413.000000000","bid_sz":31,"ask_sz":20,"bid_ct":2,"ask_ct":1},{"bid_px":"409.750000000","ask_px":"414.000000000","bid_sz":3,"ask_sz":468,"bid_ct":1,"ask_ct":2},{"bid_px":"409.740000000","ask_px":"415.070000000","bid_sz":500,"ask_sz":246,"bid_ct":1,"ask_ct":1},{"bid_px":"409.670000000","ask_px":"415.290000000","bid_sz":100,"ask_sz":34,"bid_ct":1,"ask_ct":1},{"bid_px":"409.430000000","ask_px":"415.350000000","bid_sz":5,"ask_sz":84,"bid_ct":1,"ask_ct":2},{"bid_px":"409.250000000","ask_px":"419.860000000","bid_sz":2,"ask_sz":10,"bid_ct":1,"ask_ct":1},{"bid_px":"409.080000000","ask_px":"420.000000000","bid_sz":2,"ask_sz":3,"bid_ct":1,"ask_ct":1},{"bid_px":"409.000000000","ask_px":"440.000000000","bid_sz":3,"ask_sz":35,"bid_ct":2,"ask_ct":1},{"bid_px":"408.970000000","ask_px":"445.000000000","bid_sz":12,"ask_sz":27,"bid_ct":1,"ask_ct":2},{"bid_px":"408.960000000","ask_px":"445.680000000","bid_sz":5,"ask_sz":3,"bid_ct":1,"ask_ct":1}],"symbol":"MSFT"}
{"ts_recv":"2024-11-01T08:00:14.496381540Z","hd":{"ts_event":"2024-11-01T08:00:14.496215309Z","rtype":10,"publisher_id":2,"instrument_id":38},"action":"A","side":"B","depth":7,"price":"215.000000000","size":5,"flags":130,"ts_in_delta":166231,"sequence":321443,"levels":[{"bid_px":"221.700000000","ask_px":"224.400000000","bid_sz":24,"ask_sz":1000,"bid_ct":2,"ask_ct":1},{"bid_px":"221.300000000","ask_px":"225.000000000","bid_sz":1000,"ask_sz":1,"bid_ct":1,"ask_ct":1},{"bid_px":"221.200000000","ask_px":"225.360000000","bid_sz":10,"ask_sz":1,"bid_ct":1,"ask_ct":1},{"bid_px":"220.000000000","ask_px":"225.490000000","bid_sz":8,"ask_sz":442,"bid_ct":2,"ask_ct":1},{"bid_px":"219.690000000","ask_px":"225.900000000","bid_sz":442,"ask_sz":32,"bid_ct":1,"ask_ct":2},{"bid_px":"219.000000000","ask_px":"227.000000000","bid_sz":1,"ask_sz":35,"bid_ct":1,"ask_ct":1},{"bid_px":"217.000000000","ask_px":"229.330000000","bid_sz":1525,"ask_sz":9,"bid_ct":1,"ask_ct":2},{"bid_px":"215.000000000","ask_px":"233.670000000","bid_sz":10,"ask_sz":5,"bid_ct":2,"ask_ct":1},{"bid_px":"213.000000000","ask_px":"234.000000000","bid_sz":5,"ask_sz":20,"bid_ct":1,"ask_ct":1},{"bid_px":"212.340000000","ask_px":"234.750000000","bid_sz":5,"ask_sz":50,"bid_ct":1,"ask_ct":1}],"symbol":"AAPL"}
{"ts_recv":"2024-11-01T08:00:14.500711884Z","hd":{"ts_event":"2024-11-01T08:00:14.500545397Z","rtype":10,"publisher_id":2,"instrument_id":38},"action":"A","side":"A","depth":0,"price":"223.000000000","size":90,"flags":130,"ts_in_delta":166487,"sequence":321451,"levels":[{"bid_px":"221.700000000","ask_px":"223.000000000","bid_sz":24,"ask_sz":90,"bid_ct":2,"ask_ct":1},{"bid_px":"221.300000000","ask_px":"224.400000000","bid_sz":1000,"ask_sz":1000,"bid_ct":1,"ask_ct":1},{"bid_px":"221.200000000","ask_px":"225.000000000","bid_sz":10,"ask_sz":1,"bid_ct":1,"ask_ct":1},{"bid_px":"220.000000000","ask_px":"225.360000000","bid_sz":8,"ask_sz":1,"bid_ct":2,"ask_ct":1},{"bid_px":"219.690000000","ask_px":"225.490000000","bid_sz":442,"ask_sz":442,"bid_ct":1,"ask_ct":1},{"bid_px":"219.000000000","ask_px":"225.900000000","bid_sz":1,"ask_sz":32,"bid_ct":1,"ask_ct":2},{"bid_px":"217.000000000","ask_px":"227.000000000","bid_sz":1525,"ask_sz":35,"bid_ct":1,"ask_ct":1},{"bid_px":"215.000000000","ask_px":"229.330000000","bid_sz":10,"ask_sz":9,"bid_ct":2,"ask_ct":2},{"bid_px":"213.000000000","ask_px":"233.670000000","bid_sz":5,"ask_sz":5,"bid_ct":1,"ask_ct":1},{"bid_px":"212.340000000","ask_px":"234.000000000","bid_sz":5,"ask_sz":20,"bid_ct":1,"ask_ct":1}],"symbol":"AAPL"}
{"ts_recv":"2024-11-01T08:00:14.557536036Z","hd":{"ts_event":"2024-11-01T08:00:14.557369854Z","rtype":10,"publisher_id":2,"instrument_id":10888},"action":"A","side":"A","depth":7,"price":"440.000000000","size":630,"flags":130,"ts_in_delta":166182,"sequence":321552,"levels":[{"bid_px":"410.000000000","ask_px":"413.000000000","bid_sz":31,"ask_sz":20,"bid_ct":2,"ask_ct":1},{"bid_px":"409.750000000","ask_px":"414.000000000","bid_sz":3,"ask_sz":468,"bid_ct":1,"ask_ct":2},{"bid_px":"409.740000000","ask_px":"415.070000000","bid_sz":500,"ask_sz":246,"bid_ct":1,"ask_ct":1},{"bid_px":"409.670000000","ask_px":"415.290000000","bid_sz":100,"ask_sz":34,"bid_ct":1,"ask_ct":1},{"bid_px":"409.430000000","ask_px":"415.350000000","bid_sz":5,"ask_sz":84,"bid_ct":1,"ask_ct":2},{"bid_px":"409.250000000","ask_px":"419.860000000","bid_sz":2,"ask_sz":10,"bid_ct":1,"ask_ct":1},{"bid_px":"409.080000000","ask_px":"420.000000000","bid_sz":2,"ask_sz":3,"bid_ct":1,"ask_ct":1},{"bid_px":"409.000000000","ask_px":"440.000000000","bid_sz":3,"ask_sz":665,"bid_ct":2,"ask_ct":2},{"bid_px":"408.970000000","ask_px":"445.000000000","bid_sz":12,"ask_sz":27,"bid_ct":1,"ask_ct":2},{"bid_px":"408.960000000","ask_px":"445.680000000","bid_sz":5,"ask_sz":3,"bid_ct":1,"ask_ct":1}],"symbol":"MSFT"}
{"ts_recv":"2024-11-01T08:00:14.558418220Z","hd":{"ts_event":"2024-11-01T08:00:14.558251663Z","rtype":10,"publisher_id":2,"instrument_id":10888},"action":"A","side":"A","depth":7,"price":"435.000000000","size":1,"flags":130,"ts_in_delta":166557,"sequence":321564,"levels":[{"bid_px":"410.000000000","ask_px":"413.000000000","bid_sz":31,"ask_sz":20,"bid_ct":2,"ask_ct":1},{"bid_px":"409.750000000","ask_px":"414.000000000","bid_sz":3,"ask_sz":468,"bid_ct":1,"ask_ct":2},{"bid_px":"409.740000000","ask_px":"415.070000000","bid_sz":500,"ask_sz":246,"bid_ct":1,"ask_ct":1},{"bid_px":"409.670000000","ask_px":"415.290000000","bid_sz":100,"ask_sz":34,"bid_ct":1,"ask_ct":1},{"bid_px":"409.430000000","ask_px":"415.350000000","bid_sz":5,"ask_sz":84,"bid_ct":1,"ask_ct":2},{"bid_px":"409.250000000","ask_px":"419.860000000","bid_sz":2,"ask_sz":10,"bid_ct":1,"ask_ct":1},{"bid_px":"409.080000000","ask_px":"420.000000000","bid_sz":2,"ask_sz":3,"bid_ct":1,"ask_ct":1},{"bid_px":"409.000000000","ask_px":"435.000000000","bid_sz":3,"ask_sz":1,"bid_ct":2,"ask_ct":1},{"bid_px":"408.970000000","ask_px":"440.000000000","bid_sz":12,"ask_sz":665,"bid_ct":1,"ask_ct":2},{"bid_px":"408.960000000","ask_px":"445.000000000","bid_sz":5,"ask_sz":27,"bid_ct":1,"ask_ct":2}],"symbol":"MSFT"}
{"ts_recv":"2024-11-01T08:00:14.558905587Z","hd":{"ts_event":"2024-11-01T08:00:14.558739383Z","rtype":10,"publisher_id":2,"instrument_id":10888},"action":"A","side":"A","depth":7,"price":"430.000000000","size":5,"flags":130,"ts_in_delta":166204,"sequence":321568,"levels":[{"bid_px":"410.000000000","ask_px":"413.000000000","bid_sz":31,"ask_sz":20,"bid_ct":2,"ask_ct":1},{"bid_px":"409.750000000","ask_px":"414.000000000","bid_sz":3,"ask_sz":468,"bid_ct":1,"ask_ct":2},{"bid_px":"409.740000000","ask_px":"415.070000000","bid_sz":500,"ask_sz":246,"bid_ct":1,"ask_ct":1},{"bid_px":"409.670000000","ask_px":"415.290000000","bid_sz":100,"ask_sz":34,"bid_ct":1,"ask_ct":1},{"bid_px":"409.430000000","ask_px":"415.350000000","bid_sz":5,"ask_sz":84,"bid_ct":1,"ask_ct":2},{"bid_px":"409.250000000","ask_px":"419.860000000","bid_sz":2,"ask_sz":10,"bid_ct":1,"ask_ct":1},{"bid_px":"409.080000000","ask_px":"420.000000000","bid_sz":2,"ask_sz":3,"bid_ct":1,"ask_ct":1},{"bid_px":"409.000000000","ask_px":"430.000000000","bid_sz":3,"ask_sz":5,"bid_ct":2,"ask_ct":1},{"bid_px":"408.970000000","ask_px":"435.000000000","bid_sz":12,"ask_sz":1,"bid_ct":1,"ask_ct":1},{"bid_px":"408.960000000","ask_px":"440.000000000","bid_sz":5,"ask_sz":665,"bid_ct":1,"ask_ct":2}],"symbol":"MSFT"}
{"ts_recv":"2024-11-01T08:00:14.559050499Z","hd":{"ts_event":"2024-11-01T08:00:14.558884326Z","rtype":10,"publisher_id":2,"instrument_id":10888},"action":"A","side":"A","depth":7,"price":"425.000000000","size":50,"flags":130,"ts_in_delta":166173,"sequence":321570,"levels":[{"bid_px":"410.000000000","ask_px":"413.000000000","bid_sz":31,"ask_sz":20,"bid_ct":2,"ask_ct":1},{"bid_px":"409.750000000","ask_px":"414.000000000","bid_sz":3,"ask_sz":468,"bid_ct":1,"ask_ct":2},{"bid_px":"409.740000000","ask_px":"415.070000000","bid_sz":500,"ask_sz":246,"bid_ct":1,"ask_ct":1},{"bid_px":"409.670000000","ask_px":"415.290000000","bid_sz":100,"ask_sz":34,"bid_ct":1,"ask_ct":1},{"bid_px":"409.430000000","ask_px":"415.350000000","bid_sz":5,"ask_sz":84,"bid_ct":1,"ask_ct":2},{"bid_px":"409.250000000","ask_px":"419.860000000","bid_sz":2,"ask_sz":10,"bid_ct":1,"ask_ct":1},{"bid_px":"409.080000000","ask_px":"420.000000000","bid_sz":2,"ask_sz":3,"bid_ct":1,"ask_ct":1},{"bid_px":"409.000000000","ask_px":"425.000000000","bid_sz":3,"ask_sz":50,"bid_ct":2,"ask_ct":1},{"bid_px":"408.970000000","ask_px":"430.000000000","bid_sz":12,"ask_sz":5,"bid_ct":1,"ask_ct":1},{"bid_px":"408.960000000","ask_px":"435.000000000","bid_sz":5,"ask_sz":1,"bid_ct":1,"ask_ct":1}],"symbol":"MSFT"}
{"ts_recv":"2024-11-01T08:00:14.559367322Z","hd":{"ts_event":"2024-11-01T08:00:14.559201061Z","rtype":10,"publisher_id":2,"instrument_id":10888},"action":"A","side":"A","depth":9,"price":"435.000000000","size":1,"flags":130,"ts_in_delta":166261,"sequence":321574,"levels":[{"bid_px":"410.000000000","ask_px":"413.000000000","bid_sz":31,"ask_sz":20,"bid_ct":2,"ask_ct":1},{"bid_px":"409.750000000","ask_px":"414.000000000","bid_sz":3,"ask_sz":468,"bid_ct":1,"ask_ct":2},{"bid_px":"409.740000000","ask_px":"415.070000000","bid_sz":500,"ask_sz":246,"bid_ct":1,"ask_ct":1},{"bid_px":"409.670000000","ask_px":"415.290000000","bid_sz":100,"ask_sz":34,"bid_ct":1,"ask_ct":1},{"bid_px":"409.430000000","ask_px":"415.350000000","bid_sz":5,"ask_sz":84,"bid_ct":1,"ask_ct":2},{"bid_px":"409.250000000","ask_px":"419.860000000","bid_sz":2,"ask_sz":10,"bid_ct":1,"ask_ct":1},{"bid_px":"409.080000000","ask_px":"420.000000000","bid_sz":2,"ask_sz":3,"bid_ct":1,"ask_ct":1},{"bid_px":"409.000000000","ask_px":"425.000000000","bid_sz":3,"ask_sz":50,"bid_ct":2,"ask_ct":1},{"bid_px":"408.970000000","ask_px":"430.000000000","bid_sz":12,"ask_sz":5,"bid_ct":1,"ask_ct":1},{"bid_px":"408.960000000","ask_px":"435.000000000","bid_sz":5,"ask_sz":2,"bid_ct":1,"ask_ct":2}],"symbol":"MSFT"}
{"ts_recv":"2024-11-01T08:00:14.561172921Z","hd":{"ts_event":"2024-11-01T08:00:14.561006642Z","rtype":10,"publisher_id":2,"instrument_id":16244},"action":"A","side":"B","depth":2,"price":"250.150000000","size":50,"flags":130,"ts_in_delta":166279,"sequence":321582,"levels":[{"bid_px":"250.590000000","ask_px":"250.880000000","bid_sz":7,"ask_sz":14,"bid_ct":3,"ask_ct":1},{"bid_px":"250.290000000","ask_px":"251.130000000","bid_sz":1,"ask_sz":50,"bid_ct":1,"ask_ct":1},{"bid_px":"250.150000000","ask_px":"251.150000000","bid_sz":100,"ask_sz":100,"bid_ct":2,"ask_ct":1},{"bid_px":"250.000000000","ask_px":"251.450000000","bid_sz":2,"ask_sz":374,"bid_ct":2,"ask_ct":2},{"bid_px":"249.930000000","ask_px":"251.500000000","bid_sz":10,"ask_sz":10,"bid_ct":1,"ask_ct":1},{"bid_px":"249.880000000","ask_px":"252.400000000","bid_sz":4,"ask_sz":1000,"bid_ct":1,"ask_ct":1},{"bid_px":"249.850000000","ask_px":"253.350000000","bid_sz":4,"ask_sz":23,"bid_ct":1,"ask_ct":1},{"bid_px":"249.800000000","ask_px":"253.650000000","bid_sz":199,"ask_sz":400,"bid_ct":1,"ask_ct":1},{"bid_px":"249.770000000","ask_px":"253.880000000","bid_sz":50,"ask_sz":8,"bid_ct":1,"ask_ct":1},{"bid_px":"249.500000000","ask_px":"254.990000000","bid_sz":1000,"ask_sz":5,"bid_ct":1,"ask_ct":1}],"symbol":"TSLA"}
{"ts_recv":"2024-11-01T08:00:14.602015068Z","hd":{"ts_event":"2024-11-01T08:00:14.601848870Z","rtype":10,"publisher_id":2,"instrument_id":38},"action":"A","side":"B","depth":4,"price":"219.960000000","size":4,"flags":130,"ts_in_delta":166198,"sequence":321678,"levels":[{"bid_px":"221.700000000","ask_px":"223.000000000","bid_sz":24,"ask_sz":90,"bid_ct":2,"ask_ct":1},{"bid_px":"221.300000000","ask_px":"224.400000000","bid_sz":1000,"ask_sz":1000,"bid_ct":1,"ask_ct":1},{"bid_px":"221.200000000","ask_px":"225.000000000","bid_sz":10,"ask_sz":1,"bid_ct":1,"ask_ct":1},{"bid_px":"220.000000000","ask_px":"225.360000000","bid_sz":8,"ask_sz":1,"bid_ct":2,"ask_ct":1},{"bid_px":"219.960000000","ask_px":"225.490000000","bid_sz":4,"ask_sz":442,"bid_ct":1,"ask_ct":1},{"bid_px":"219.690000000","ask_px":"225.900000000","bid_sz":442,"ask_sz":32,"bid_ct":1,"ask_ct":2},{"bid_px":"219.000000000","ask_px":"227.000000000","bid_sz":1,"ask_sz":35,"bid_ct":1,"ask_ct":1},{"bid_px":"217.000000000","ask_px":"229.330000000","bid_sz":1525,"ask_sz":9,"bid_ct":1,"ask_ct":2},{"bid_px":"215.000000000","ask_px":"233.670000000","bid_sz":10,"ask_sz":5,"bid_ct":2,"ask_ct":1},{"bid_px":"213.000000000","ask_px":"234.000000000","bid_sz":5,"ask_sz":20,"bid_ct":1,"ask_ct":1}],"symbol":"AAPL"}
{"ts_recv":"2024-11-01T08:00:14.609094522Z","hd":{"ts_event":"2024-11-01T08:00:14.608928632Z","rtype":10,"publisher_id":2,"instrument_id":16244},"action":"C","side":"B","depth":1,"price":"250.290000000","size":1,"flags":130,"ts_in_delta":165890,"sequence":321698,"levels":[{"bid_px":"250.590000000","ask_px":"250.880000000","bid_sz":7,"ask_sz":14,"bid_ct":3,"ask_ct":1},{"bid_px":"250.150000000","ask_px":"251.130000000","bid_sz":100,"ask_sz":50,"bid_ct":2,"ask_ct":1},{"bid_px":"250.000000000","ask_px":"251.150000000","bid_sz":2,"ask_sz":100,"bid_ct":2,"ask_ct":1},{"bid_px":"249.930000000","ask_px":"251.450000000","bid_sz":10,"ask_sz":374,"bid_ct":1,"ask_ct":2},{"bid_px":"249.880000000","ask_px":"251.500000000","bid_sz":4,"ask_sz":10,"bid_ct":1,"ask_ct":1},{"bid_px":"249.850000000","ask_px":"252.400000000","bid_sz":4,"ask_sz":1000,"bid_ct":1,"ask_ct":1},{"bid_px":"249.800000000","ask_px":"253.350000000","bid_sz":199,"ask_sz":23,"bid_ct":1,"ask_ct":1},{"bid_px":"249.770000000","ask_px":"253.650000000","bid_sz":50,"ask_sz":400,"bid_ct":1,"ask_ct":1},{"bid_px":"249.500000000","ask_px":"253.880000000","bid_sz":1000,"ask_sz":8,"bid_ct":1,"ask_ct":1},{"bid_px":"249.010000000","ask_px":"254.990000000","bid_sz":3,"ask_sz":5,"bid_ct":1,"ask_ct":1}],"symbol":"TSLA"}
{"ts_recv":"2024-11-01T08:00:14.663031535Z","hd":{"ts_event":"2024-11-01T08:00:14.662865164Z","rtype":10,"publisher_id":2,"instrument_id":10888},"action":"A","side":"B","depth":6,"price":"409.220000000","size":22,"flags":130,"ts_in_delta":166371,"sequence":321878,"levels":[{"bid_px":"410.000000000","ask_px":"413.000000000","bid_sz":31,"ask_sz":20,"bid_ct":2,"ask_ct":1},{"bid_px":"409.750000000","ask_px":"414.000000000","bid_sz":3,"ask_sz":468,"bid_ct":1,"ask_ct":2},{"bid_px":"409.740000000","ask_px":"415.070000000","bid_sz":500,"ask_sz":246,"bid_ct":1,"ask_ct":1},{"bid_px":"409.670000000","ask_px":"415.290000000","bid_sz":100,"ask_sz":34,"bid_ct":1,"ask_ct":1},{"bid_px":"409.430000000","ask_px":"415.350000000","bid_sz":5,"ask_sz":84,"bid_ct":1,"ask_ct":2},{"bid_px":"409.250000000","ask_px":"419.860000000","bid_sz":2,"ask_sz":10,"bid_ct":1,"ask_ct":1},{"bid_px":"409.220000000","ask_px":"420.000000000","bid_sz":22,"ask_sz":3,"bid_ct":1,"ask_ct":1},{"bid_px":"409.080000000","ask_px":"425.000000000","bid_sz":2,"ask_sz":50,"bid_ct":1,"ask_ct":1},{"bid_px":"409.000000000","ask_px":"430.000000000","bid_sz":3,"ask_sz":5,"bid_ct":2,"ask_ct":1},{"bid_px":"408.970000000","ask_px":"435.000000000","bid_sz":12,"ask_sz":2,"bid_ct":1,"ask_ct":2}],"symbol":"MSFT"}
{"ts_recv":"2024-11-01T08:00:14.683704535Z","hd":{"ts_event":"2024-11-01T08:00:14.683538439Z","rtype":10,"publisher_id":2,"instrument_id":17709},"action":"A","side":"B","depth":2,"price":"101.000000000","size":10,"flags":130,"ts_in_delta":166096,"sequence":322011,"levels":[{"bid_px":"116.000000000","ask_px":"118.600000000","bid_sz":100,"ask_sz":100,"bid_ct":1,"ask_ct":1},{"bid_px":"115.290000000","ask_px":"125.000000000","bid_sz":100,"ask_sz":30,"bid_ct":1,"ask_ct":1},{"bid_px":"101.000000000","ask_px":"9900.000000000","bid_sz":10,"ask_sz":11,"bid_ct":1,"ask_ct":1},{"bid_px":null,"ask_px":null,"bid_sz":0,"ask_sz":0,"bid_ct":0,"ask_ct":0},{"bid_px":null,"ask_px":null,"bid_sz":0,"ask_sz":0,"bid_ct":0,"ask_ct":0},{"bid_px":null,"ask_px":null,"bid_sz":0,"ask_sz":0,"bid_ct":0,"ask_ct":0},{"bid_px":null,"ask_px":null,"bid_sz":0,"ask_sz":0,"bid_ct":0,"ask_ct":0},{"bid_px":null,"ask_px":null,"bid_sz":0,"ask_sz":0,"bid_ct":0,"ask_ct":0},{"bid_px":null,"ask_px":null,"bid_sz":0,"ask_sz":0,"bid_ct":0,"ask_ct":0},{"bid_px":null,"ask_px":null,"bid_sz":0,"ask_sz":0,"bid_ct":0,"ask_ct":0}],"symbol":"XOM"}
{"ts_recv":"2024-11-01T08:00:14.700697929Z","hd":{"ts_event":"2024-11-01T08:00:14.700522417Z","rtype":10,"publisher_id":2,"instrument_id":38},"action":"A","side":"A","depth":2,"price":"224.520000000","size":100,"flags":130,"ts_in_delta":175512,"sequence":322078,"levels":[{"bid_px":"221.700000000","ask_px":"223.000000000","bid_sz":24,"ask_sz":90,"bid_ct":2,"ask_ct":1},{"bid_px":"221.300000000","ask_px":"224.400000000","bid_sz":1000,"ask_sz":1000,"bid_ct":1,"ask_ct":1},{"bid_px":"221.200000000","ask_px":"224.520000000","bid_sz":10,"ask_sz":100,"bid_ct":1,"ask_ct":1},{"bid_px":"220.000000000","ask_px":"225.000000000","bid_sz":8,"ask_sz":1,"bid_ct":2,"ask_ct":1},{"bid_px":"219.960000000","ask_px":"225.360000000","bid_sz":4,"ask_sz":1,"bid_ct":1,"ask_ct":1},{"bid_px":"219.690000000","ask_px":"225.490000000","bid_sz":442,"ask_sz":442,"bid_ct":1,"ask_ct":1},{"bid_px":"219.000000000","ask_px":"225.900000000","bid_sz":1,"ask_sz":32,"bid_ct":1,"ask_ct":2},{"bid_px":"217.000000000","ask_px":"227.000000000","bid_sz":1525,"ask_sz":35,"bid_ct":1,"ask_ct":1},{"bid_px":"215.000000000","ask_px":"229.330000000","bid_sz":10,"ask_sz":9,"bid_ct":2,"ask_ct":2},{"bid_px":"213.000000000","ask_px":"233.670000000","bid_sz":5,"ask_sz":5,"bid_ct":1,"ask_ct":1}],"symbol":"AAPL"}
{"ts_recv":"2024-11-01T08:00:14.700751383Z","hd":{"ts_event":"2024-11-01T08:00:14.700585164Z","rtype":10,"publisher_id":2,"instrument_id":38},"action":"A","side":"B","depth":9,"price":"214.380000000","size":27,"flags":130,"ts_in_delta":166219,"sequence":322079,"levels":[{"bid_px":"221.700000000","ask_px":"223.000000000","bid_sz":24,"ask_sz":90,"bid_ct":2,"ask_ct":1},{"bid_px":"221.300000000","ask_px":"224.400000000","bid_sz":1000,"ask_sz":1000,"bid_ct":1,"ask_ct":1},{"bid_px":"221.200000000","ask_px":"224.520000000","bid_sz":10,"ask_sz":100,"bid_ct":1,"ask_ct":1},{"bid_px":"220.000000000","ask_px":"225.000000000","bid_sz":8,"ask_sz":1,"bid_ct":2,"ask_ct":1},{"bid_px":"219.960000000","ask_px":"225.360000000","bid_sz":4,"ask_sz":1,"bid_ct":1,"ask_ct":1},{"bid_px":"219.690000000","ask_px":"225.490000000","bid_sz":442,"ask_sz":442,"bid_ct":1,"ask_ct":1},{"bid_px":"219.000000000","ask_px":"225.900000000","bid_sz":1,"ask_sz":32,"bid_ct":1,"ask_ct":2},{"bid_px":"217.000000000","ask_px":"227.000000000","bid_sz":1525,"ask_sz":35,"bid_ct":1,"ask_ct":1},{"bid_px":"215.000000000","ask_px":"229.330000000","bid_sz":10,"ask_sz":9,"bid_ct":2,"ask_ct":2},{"bid_px":"214.380000000","ask_px":"233.670000000","bid_sz":27,"ask_sz":5,"bid_ct":1,"ask_ct":1}],"symbol":"AAPL"}
{"ts_recv":"2024-11-01T08:00:14.737892197Z","hd":{"ts_event":"2024-11-01T08:00:14.737725942Z","rtype":10,"publisher_id":2,"instrument_id":16244},"action":"A","side":"A","depth":0,"price":"250.790000000","size":200,"flags":130,"ts_in_delta":166255,"sequence":322141,"levels":[{"bid_px":"250.590000000","ask_px":"250.790000000","bid_sz":7,"ask_sz":200,"bid_ct":3,"ask_ct":1},{"bid_px":"250.150000000","ask_px":"250.880000000","bid_sz":100,"ask_sz":14,"bid_ct":2,"ask_ct":1},{"bid_px":"250.000000000","ask_px":"251.130000000","bid_sz":2,"ask_sz":50,"bid_ct":2,"ask_ct":1},{"bid_px":"249.930000000","ask_px":"251.150000000","bid_sz":10,"ask_sz":100,"bid_ct":1,"ask_ct":1},{"bid_px":"249.880000000","ask_px":"251.450000000","bid_sz":4,"ask_sz":374,"bid_ct":1,"ask_ct":2},{"bid_px":"249.850000000","ask_px":"251.500000000","bid_sz":4,"ask_sz":10,"bid_ct":1,"ask_ct":1},{"bid_px":"249.800000000","ask_px":"252.400000000","bid_sz":199,"ask_sz":1000,"bid_ct":1,"ask_ct":1},{"bid_px":"249.770000000","ask_px":"253.350000000","bid_sz":50,"ask_sz":23,"bid_ct":1,"ask_ct":1},{"bid_px":"249.500000000","ask_px":"253.650000000","bid_sz":1000,"ask_sz":400,"bid_ct":1,"ask_ct":1},{"bid_px":"249.010000000","ask_px":"253.880000000","bid_sz":3,"ask_sz":8,"bid_ct":1,"ask_ct":1}],"symbol":"TSLA"}
{"ts_recv":"2024-11-01T08:00:14.746954322Z","hd":{"ts_event":"2024-11-01T08:00:14.746786698Z","rtype":10,"publisher_id":2,"instrument_id":11667},"action":"T","side":"A","depth":0,"price":"134.930000000","size":5,"flags":130,"ts_in_delta":167624,"sequence":322150,"levels":[{"bid_px":"134.930000000","ask_px":"134.990000000","bid_sz":239,"ask_sz":10,"bid_ct":1,"ask_ct":1},{"bid_px":"134.830000000","ask_px":"135.000000000","bid_sz":100,"ask_sz":38,"bid_ct":1,"ask_ct":3},{"bid_px":"134.500000000","ask_px":"135.100000000","bid_sz":520,"ask_sz":10,"bid_ct":2,"ask_ct":1},{"bid_px":"134.410000000","ask_px":"135.230000000","bid_sz":61,"ask_sz":360,"bid_ct":2,"ask_ct":1},{"bid_px":"134.380000000","ask_px":"135.300000000","bid_sz":18,"ask_sz":1009,"bid_ct":1,"ask_ct":2},{"bid_px":"134.210000000","ask_px":"135.400000000","bid_sz":20,"ask_sz":10,"bid_ct":1,"ask_ct":1},{"bid_px":"134.200000000","ask_px":"135.420000000","bid_sz":3,"ask_sz":1,"bid_ct":1,"ask_ct":1},{"bid_px":"134.000000000","ask_px":"135.820000000","bid_sz":1,"ask_sz":1,"bid_ct":1,"ask_ct":1},{"bid_px":"133.800000000","ask_px":"135.910000000","bid_sz":5,"ask_sz":100,"bid_ct":1,"ask_ct":1},{"bid_px":"133.160000000","ask_px":"135.990000000","bid_sz":1,"ask_sz":20,"bid_ct":1,"ask_ct":1}],"symbol":"NVDA"}
{"ts_recv":"2024-11-01T08:00:14.746954322Z","hd":{"ts_event":"2024-11-01T08:00:14.746786698Z","rtype":10,"publisher_id":2,"instrument_id":11667},"action":"C","side":"B","depth":0,"price":"134.930000000","size":5,"flags":130,"ts_in_delta":167624,"sequence":322150,"levels":[{"bid_px":"134.930000000","ask_px":"134.990000000","bid_sz":234,"ask_sz":10,"bid_ct":1,"ask_ct":1},{"bid_px":"134.830000000","ask_px":"135.000000000","bid_sz":100,"ask_sz":38,"bid_ct":1,"ask_ct":3},{"bid_px":"134.500000000","ask_px":"135.100000000","bid_sz":520,"ask_sz":10,"bid_ct":2,"ask_ct":1},{"bid_px":"134.410000000","ask_px":"135.230000000","bid_sz":61,"ask_sz":360,"bid_ct":2,"ask_ct":1},{"bid_px":"134.380000000","ask_px":"135.300000000","bid_sz":18,"ask_sz":1009,"bid_ct":1,"ask_ct":2},{"bid_px":"134.210000000","ask_px":"135.400000000","bid_sz":20,"ask_sz":10,"bid_ct":1,"ask_ct":1},{"bid_px":"134.200000000","ask_px":"135.420000000","bid_sz":3,"ask_sz":1,"bid_ct":1,"ask_ct":1},{"bid_px":"134.000000000","ask_px":"135.820000000","bid_sz":1,"ask_sz":1,"bid_ct":1,"ask_ct":1},{"bid_px":"133.800000000","ask_px":"135.910000000","bid_sz":5,"ask_sz":100,"bid_ct":1,"ask_ct":1},{"bid_px":"133.160000000","ask_px":"135.990000000","bid_sz":1,"ask_sz":20,"bid_ct":1,"ask_ct":1}],"symbol":"NVDA"}
{"ts_recv":"2024-11-01T08:00:14.749487202Z","hd":{"ts_event":"2024-11-01T08:00:14.749320310Z","rtype":10,"publisher_id":2,"instrument_id":16244},"action":"A","side":"A","depth":4,"price":"251.400000000","size":1000,"flags":130,"ts_in_delta":166892,"sequence":322153,"levels":[{"bid_px":"250.590000000","ask_px":"250.790000000","bid_sz":7,"ask_sz":200,"bid_ct":3,"ask_ct":1},{"bid_px":"250.150000000","ask_px":"250.880000000","bid_sz":100,"ask_sz":14,"bid_ct":2,"ask_ct":1},{"bid_px":"250.000000000","ask_px":"251.130000000","bid_sz":2,"ask_sz":50,"bid_ct":2,"ask_ct":1},{"bid_px":"249.930000000","ask_px":"251.150000000","bid_sz":10,"ask_sz":100,"bid_ct":1,"ask_ct":1},{"bid_px":"249.880000000","ask_px":"251.400000000","bid_sz":4,"ask_sz":1000,"bid_ct":1,"ask_ct":1},{"bid_px":"249.850000000","ask_px":"251.450000000","bid_sz":4,"ask_sz":374,"bid_ct":1,"ask_ct":2},{"bid_px":"249.800000000","ask_px":"251.500000000","bid_sz":199,"ask_sz":10,"bid_ct":1,"ask_ct":1},{"bid_px":"249.770000000","ask_px":"252.400000000","bid_sz":50,"ask_sz":1000,"bid_ct":1,"ask_ct":1},{"bid_px":"249.500000000","ask_px":"253.350000000","bid_sz":1000,"ask_sz":23,"bid_ct":1,"ask_ct":1},{"bid_px":"249.010000000","ask_px":"253.650000000","bid_sz":3,"ask_sz":400,"bid_ct":1,"ask_ct":1}],"symbol":"TSLA"}
{"ts_recv":"2024-11-01T08:00:14.749537643Z","hd":{"ts_event":"2024-11-01T08:00:14.749371488Z","rtype":10,"publisher_id":2,"instrument_id":16244},"action":"C","side":"A","depth":7,"price":"252.400000000","size":1000,"flags":130,"ts_in_delta":166155,"sequence":322154,"levels":[{"bid_px":"250.590000000","ask_px":"250.790000000","bid_sz":7,"ask_sz":200,"bid_ct":3,"ask_ct":1},{"bid_px":"250.150000000","ask_px":"250.880000000","bid_sz":100,"ask_sz":14,"bid_ct":2,"ask_ct":1},{"bid_px":"250.000000000","ask_px":"251.130000000","bid_sz":2,"ask_sz":50,"bid_ct":2,"ask_ct":1},{"bid_px":"249.930000000","ask_px":"251.150000000","bid_sz":10,"ask_sz":100,"bid_ct":1,"ask_ct":1},{"bid_px":"249.880000000","ask_px":"251.400000000","bid_sz":4,"ask_sz":1000,"bid_ct":1,"ask_ct":1},{"bid_px":"249.850000000","ask_px":"251.450000000","bid_sz":4,"ask_sz":374,"bid_ct":1,"ask_ct":2},{"bid_px":"249.800000000","ask_px":"251.500000000","bid_sz":199,"ask_sz":10,"bid_ct":1,"ask_ct":1},{"bid_px":"249.770000000","ask_px":"253.350000000","bid_sz":50,"ask_sz":23,"bid_ct":1,"ask_ct":1},{"bid_px":"249.500000000","ask_px":"253.650000000","bid_sz":1000,"ask_sz":400,"bid_ct":1,"ask_ct":1},{"bid_px":"249.010000000","ask_px":"253.880000000","bid_sz":3,"ask_sz":8,"bid_ct":1,"ask_ct":1}],"symbol":"TSLA"}
{"ts_recv":"2024-11-01T08:00:14.768424321Z","hd":{"ts_event":"2024-11-01T08:00:14.768258475Z","rtype":10,"publisher_id":2,"instrument_id":16244},"action":"C","side":"A","depth":4,"price":"251.400000000","size":1000,"flags":130,"ts_in_delta":165846,"sequence":322175,"levels":[{"bid_px":"250.590000000","ask_px":"250.790000000","bid_sz":7,"ask_sz":200,"bid_ct":3,"ask_ct":1},{"bid_px":"250.150000000","ask_px":"250.880000000","bid_sz":100,"ask_sz":14,"bid_ct":2,"ask_ct":1},{"bid_px":"250.000000000","ask_px":"251.130000000","bid_sz":2,"ask_sz":50,"bid_ct":2,"ask_ct":1},{"bid_px":"249.930000000","ask_px":"251.150000000","bid_sz":10,"ask_sz":100,"bid_ct":1,"ask_ct":1},{"bid_px":"249.880000000","ask_px":"251.450000000","bid_sz":4,"ask_sz":374,"bid_ct":1,"ask_ct":2},{"bid_px":"249.850000000","ask_px":"251.500000000","bid_sz":4,"ask_sz":10,"bid_ct":1,"ask_ct":1},{"bid_px":"249.800000000","ask_px":"253.350000000","bid_sz":199,"ask_sz":23,"bid_ct":1,"ask_ct":1},{"bid_px":"249.770000000","ask_px":"253.650000000","bid_sz":50,"ask_sz":400,"bid_ct":1,"ask_ct":1},{"bid_px":"249.500000000","ask_px":"253.880000000","bid_sz":1000,"ask_sz":8,"bid_ct":1,"ask_ct":1},{"bid_px":"249.010000000","ask_px":"254.990000000","bid_sz":3,"ask_sz":5,"bid_ct":1,"ask_ct":1}],"symbol":"TSLA"}
{"ts_recv":"2024-11-01T08:00:14.779854583Z","hd":{"ts_event":"2024-11-01T08:00:14.779688487Z","rtype":10,"publisher_id":2,"instrument_id":16244},"action":"A","side":"A","depth":6,"price":"252.100000000","size":1000,"flags":130,"ts_in_delta":166096,"sequence":322200,"levels":[{"bid_px":"250.590000000","ask_px":"250.790000000","bid_sz":7,"ask_sz":200,"bid_ct":3,"ask_ct":1},{"bid_px":"250.150000000","ask_px":"250.880000000","bid_sz":100,"ask_sz":14,"bid_ct":2,"ask_ct":1},{"bid_px":"250.000000000","ask_px":"251.130000000","bid_sz":2,"ask_sz":50,"bid_ct":2,"ask_ct":1},{"bid_px":"249.930000000","ask_px":"251.150000000","bid_sz":10,"ask_sz":100,"bid_ct":1,"ask_ct":1},{"bid_px":"249.880000000","ask_px":"251.450000000","bid_sz":4,"ask_sz":374,"bid_ct":1,"ask_ct":2},{"bid_px":"249.850000000","ask_px":"251.500000000","bid_sz":4,"ask_sz":10,"bid_ct":1,"ask_ct":1},{"bid_px":"249.800000000","ask_px":"252.100000000","bid_sz":199,"ask_sz":1000,"bid_ct":1,"ask_ct":1},{"bid_px":"249.770000000","ask_px":"253.350000000","bid_sz":50,"ask_sz":23,"bid_ct":1,"ask_ct":1},{"bid_px":"249.500000000","ask_px":"253.650000000","bid_sz":1000,"ask_sz":400,"bid_ct":1,"ask_ct":1},{"bid_px":"249.010000000","ask_px":"253.880000000","bid_sz":3,"ask_sz":8,"bid_ct":1,"ask_ct":1}],"symbol":"TSLA"}
{"ts_recv":"2024-11-01T08:00:14.780606166Z","hd":{"ts_event":"2024-11-01T08:00:14.780439656Z","rtype":10,"publisher_id":2,"instrument_id":16244},"action":"A","side":"A","depth":3,"price":"251.150000000","size":100,"flags":130,"ts_in_delta":166510,"sequence":322202,"levels":[{"bid_px":"250.590000000","ask_px":"250.790000000","bid_sz":7,"ask_sz":200,"bid_ct":3,"ask_ct":1},{"bid_px":"250.150000000","ask_px":"250.880000000","bid_sz":100,"ask_sz":14,"bid_ct":2,"ask_ct":1},{"bid_px":"250.000000000","ask_px":"251.130000000","bid_sz":2,"ask_sz":50,"bid_ct":2,"ask_ct":1},{"bid_px":"249.930000000","ask_px":"251.150000000","bid_sz":10,"ask_sz":200,"bid_ct":1,"ask_ct":2},{"bid_px":"249.880000000","ask_px":"251.450000000","bid_sz":4,"ask_sz":374,"bid_ct":1,"ask_ct":2},{"bid_px":"249.850000000","ask_px":"251.500000000","bid_sz":4,"ask_sz":10,"bid_ct":1,"ask_ct":1},{"bid_px":"249.800000000","ask_px":"252.100000000","bid_sz":199,"ask_sz":1000,"bid_ct":1,"ask_ct":1},{"bid_px":"249.770000000","ask_px":"253.350000000","bid_sz":50,"ask_sz":23,"bid_ct":1,"ask_ct":1},{"bid_px":"249.500000000","ask_px":"253.650000000","bid_sz":1000,"ask_sz":400,"bid_ct":1,"ask_ct":1},{"bid_px":"249.010000000","ask_px":"253.880000000","bid_sz":3,"ask_sz":8,"bid_ct":1,"ask_ct":1}],"symbol":"TSLA"}
{"ts_recv":"2024-11-01T08:00:14.797344069Z","hd":{"ts_event":"2024-11-01T08:00:14.797177638Z","rtype":10,"publisher_id":2,"instrument_id":9155},"action":"A","side":"B","depth":4,"price":"200.000000000","size":2,"flags":130,"ts_in_delta":166431,"sequence":322229,"levels":[{"bid_px":"221.850000000","ask_px":"224.940000000","bid_sz":3,"ask_sz":450,"bid_ct":1,"ask_ct":1},{"bid_px":"220.000000000","ask_px":"226.800000000","bid_sz":3,"ask_sz":100,"bid_ct":1,"ask_ct":1},{"bid_px":"219.160000000","ask_px":null,"bid_sz":450,"ask_sz":0,"bid_ct":1,"ask_ct":0},{"bid_px":"218.080000000","ask_px":null,"bid_sz":100,"ask_sz":0,"bid_ct":1,"ask_ct":0},{"bid_px":"200.000000000","ask_px":null,"bid_sz":2,"ask_sz":0,"bid_ct":1,"ask_ct":0},{"bid_px":null,"ask_px":null,"bid_sz":0,"ask_sz":0,"bid_ct":0,"ask_ct":0},{"bid_px":null,"ask_px":null,"bid_sz":0,"ask_sz":0,"bid_ct":0,"ask_ct":0},{"bid_px":null,"ask_px":null,"bid_sz":0,"ask_sz":0,"bid_ct":0,"ask_ct":0},{"bid_px":null,"ask_px":null,"bid_sz":0,"ask_sz":0,"bid_ct":0,"ask_ct":0},{"bid_px":null,"ask_px":null,"bid_sz":0,"ask_sz":0,"bid_ct":0,"ask_ct":0}],"symbol":"JPM"}
