{"ts_recv":"2024-11-01T08:00:05.220725689Z","hd":{"ts_event":"2024-11-01T08:00:05.220559245Z","rtype":10,"publisher_id":2,"instrument_id":16244},"action":"A","side":"B","depth":5,"price":"220.000000000","size":5,"flags":130,"ts_in_delta":166444,"sequence":297655,"levels":[{"bid_px":"249.820000000","ask_px":"250.680000000","bid_sz":50,"ask_sz":100,"bid_ct":1,"ask_ct":1},{"bid_px":"249.600000000","ask_px":"250.750000000","bid_sz":1000,"ask_sz":50,"bid_ct":1,"ask_ct":1},{"bid_px":"249.300000000","ask_px":"251.900000000","bid_sz":1000,"ask_sz":1000,"bid_ct":1,"ask_ct":1},{"bid_px":"247.150000000","ask_px":"253.650000000","bid_sz":400,"ask_sz":400,"bid_ct":1,"ask_ct":1},{"bid_px":"235.000000000","ask_px":"260.000000000","bid_sz":100,"ask_sz":48,"bid_ct":1,"ask_ct":1},{"bid_px":"220.000000000","ask_px":"264.940000000","bid_sz":6,"ask_sz":7,"bid_ct":2,"ask_ct":1},{"bid_px":"214.000000000","ask_px":"265.000000000","bid_sz":5,"ask_sz":1,"bid_ct":1,"ask_ct":1},{"bid_px":"213.650000000","ask_px":"275.000000000","bid_sz":3,"ask_sz":4,"bid_ct":1,"ask_ct":1},{"bid_px":"213.000000000","ask_px":"960.000000000","bid_sz":1,"ask_sz":25,"bid_ct":1,"ask_ct":1},{"bid_px":"211.000000000","ask_px":null,"bid_sz":2,"ask_sz":0,"bid_ct":1,"ask_ct":0}],"symbol":"TSLA"}
{"ts_recv":"2024-11-01T08:00:05.242002306Z","hd":{"ts_event":"2024-11-01T08:00:05.241835967Z","rtype":10,"publisher_id":2,"instrument_id":11667},"action":"A","side":"A","depth":0,"price":"135.230000000","size":360,"flags":130,"ts_in_delta":166339,"sequence":297665,"levels":[{"bid_px":"134.560000000","ask_px":"135.230000000","bid_sz":100,"ask_sz":360,"bid_ct":1,"ask_ct":1},{"bid_px":"134.410000000","ask_px":"135.300000000","bid_sz":1,"ask_sz":1000,"bid_ct":1,"ask_ct":1},{"bid_px":"134.210000000","ask_px":"136.200000000","bid_sz":20,"ask_sz":1000,"bid_ct":1,"ask_ct":1},{"bid_px":"133.100000000","ask_px":"137.680000000","bid_sz":1000,"ask_sz":500,"bid_ct":1,"ask_ct":1},{"bid_px":"132.000000000","ask_px":"138.870000000","bid_sz":71,"ask_sz":1000,"bid_ct":2,"ask_ct":2},{"bid_px":"130.000000000","ask_px":"140.740000000","bid_sz":5,"ask_sz":100,"bid_ct":1,"ask_ct":1},{"bid_px":"129.050000000","ask_px":"140.880000000","bid_sz":500,"ask_sz":1000,"bid_ct":1,"ask_ct":2},{"bid_px":"129.000000000","ask_px":"143.000000000","bid_sz":10,"ask_sz":1,"bid_ct":1,"ask_ct":1},{"bid_px":"128.470000000","ask_px":"143.690000000","bid_sz":500,"ask_sz":500,"bid_ct":1,"ask_ct":1},{"bid_px":"127.680000000","ask_px":"146.510000000","bid_sz":30,"ask_sz":5,"bid_ct":1,"ask_ct":1}],"symbol":"NVDA"}
{"ts_recv":"2024-11-01T08:00:05.292081938Z","hd":{"ts_event":"2024-11-01T08:00:05.291915839Z","rtype":10,"publisher_id":2,"instrument_id":16244},"action":"A","side":"B","depth":5,"price":"220.000000000","size":20,"flags":130,"ts_in_delta":166099,"sequence":297759,"levels":[{"bid_px":"249.820000000","ask_px":"250.680000000","bid_sz":50,"ask_sz":100,"bid_ct":1,"ask_ct":1},{"bid_px":"249.600000000","ask_px":"250.750000000","bid_sz":1000,"ask_sz":50,"bid_ct":1,"ask_ct":1},{"bid_px":"249.300000000","ask_px":"251.900000000","bid_sz":1000,"ask_sz":1000,"bid_ct":1,"ask_ct":1},{"bid_px":"247.150000000","ask_px":"253.650000000","bid_sz":400,"ask_sz":400,"bid_ct":1,"ask_ct":1},{"bid_px":"235.000000000","ask_px":"260.000000000","bid_sz":100,"ask_sz":48,"bid_ct":1,"ask_ct":1},{"bid_px":"220.000000000","ask_px":"264.940000000","bid_sz":26,"ask_sz":7,"bid_ct":3,"ask_ct":1},{"bid_px":"214.000000000","ask_px":"265.000000000","bid_sz":5,"ask_sz":1,"bid_ct":1,"ask_ct":1},{"bid_px":"213.650000000","ask_px":"275.000000000","bid_sz":3,"ask_sz":4,"bid_ct":1,"ask_ct":1},{"bid_px":"213.000000000","ask_px":"960.000000000","bid_sz":1,"ask_sz":25,"bid_ct":1,"ask_ct":1},{"bid_px":"211.000000000","ask_px":null,"bid_sz":2,"ask_sz":0,"bid_ct":1,"ask_ct":0}],"symbol":"TSLA"}
{"ts_recv":"2024-11-01T08:00:05.322102932Z","hd":{"ts_event":"2024-11-01T08:00:05.321936897Z","rtype":10,"publisher_id":2,"instrument_id":11667},"action":"A","side":"B","depth":4,"price":"132.000000000","size":1,"flags":130,"ts_in_delta":166035,"sequence":297806,"levels":[{"bid_px":"134.560000000","ask_px":"135.230000000","bid_sz":100,"ask_sz":360,"bid_ct":1,"ask_ct":1},{"bid_px":"134.410000000","ask_px":"135.300000000","bid_sz":1,"ask_sz":1000,"bid_ct":1,"ask_ct":1},{"bid_px":"134.210000000","ask_px":"136.200000000","bid_sz":20,"ask_sz":1000,"bid_ct":1,"ask_ct":1},{"bid_px":"133.100000000","ask_px":"137.680000000","bid_sz":1000,"ask_sz":500,"bid_ct":1,"ask_ct":1},{"bid_px":"132.000000000","ask_px":"138.870000000","bid_sz":72,"ask_sz":1000,"bid_ct":3,"ask_ct":2},{"bid_px":"130.000000000","ask_px":"140.740000000","bid_sz":5,"ask_sz":100,"bid_ct":1,"ask_ct":1},{"bid_px":"129.050000000","ask_px":"140.880000000","bid_sz":500,"ask_sz":1000,"bid_ct":1,"ask_ct":2},{"bid_px":"129.000000000","ask_px":"143.000000000","bid_sz":10,"ask_sz":1,"bid_ct":1,"ask_ct":1},{"bid_px":"128.470000000","ask_px":"143.690000000","bid_sz":500,"ask_sz":500,"bid_ct":1,"ask_ct":1},{"bid_px":"127.680000000","ask_px":"146.510000000","bid_sz":30,"ask_sz":5,"bid_ct":1,"ask_ct":1}],"symbol":"NVDA"}
{"ts_recv":"2024-11-01T08:00:05.324142391Z","hd":{"ts_event":"2024-11-01T08:00:05.323976037Z","rtype":10,"publisher_id":2,"instrument_id":16244},"action":"A","side":"B","depth":5,"price":"230.000000000","size":12,"flags":130,"ts_in_delta":166354,"sequence":297807,"levels":[{"bid_px":"249.820000000","ask_px":"250.680000000","bid_sz":50,"ask_sz":100,"bid_ct":1,"ask_ct":1},{"bid_px":"249.600000000","ask_px":"250.750000000","bid_sz":1000,"ask_sz":50,"bid_ct":1,"ask_ct":1},{"bid_px":"249.300000000","ask_px":"251.900000000","bid_sz":1000,"ask_sz":1000,"bid_ct":1,"ask_ct":1},{"bid_px":"247.150000000","ask_px":"253.650000000","bid_sz":400,"ask_sz":400,"bid_ct":1,"ask_ct":1},{"bid_px":"235.000000000","ask_px":"260.000000000","bid_sz":100,"ask_sz":48,"bid_ct":1,"ask_ct":1},{"bid_px":"230.000000000","ask_px":"264.940000000","bid_sz":12,"ask_sz":7,"bid_ct":1,"ask_ct":1},{"bid_px":"220.000000000","ask_px":"265.000000000","bid_sz":26,"ask_sz":1,"bid_ct":3,"ask_ct":1},{"bid_px":"214.000000000","ask_px":"275.000000000","bid_sz":5,"ask_sz":4,"bid_ct":1,"ask_ct":1},{"bid_px":"213.650000000","ask_px":"960.000000000","bid_sz":3,"ask_sz":25,"bid_ct":1,"ask_ct":1},{"bid_px":"213.000000000","ask_px":null,"bid_sz":1,"ask_sz":0,"bid_ct":1,"ask_ct":0}],"symbol":"TSLA"}
{"ts_recv":"2024-11-01T08:00:05.354302759Z","hd":{"ts_event":"2024-11-01T08:00:05.354136410Z","rtype":10,"publisher_id":2,"instrument_id":16244},"action":"A","side":"B","depth":1,"price":"249.770000000","size":50,"flags":130,"ts_in_delta":166349,"sequence":297865,"levels":[{"bid_px":"249.820000000","ask_px":"250.680000000","bid_sz":50,"ask_sz":100,"bid_ct":1,"ask_ct":1},{"bid_px":"249.770000000","ask_px":"250.750000000","bid_sz":50,"ask_sz":50,"bid_ct":1,"ask_ct":1},{"bid_px":"249.600000000","ask_px":"251.900000000","bid_sz":1000,"ask_sz":1000,"bid_ct":1,"ask_ct":1},{"bid_px":"249.300000000","ask_px":"253.650000000","bid_sz":1000,"ask_sz":400,"bid_ct":1,"ask_ct":1},{"bid_px":"247.150000000","ask_px":"260.000000000","bid_sz":400,"ask_sz":48,"bid_ct":1,"ask_ct":1},{"bid_px":"235.000000000","ask_px":"264.940000000","bid_sz":100,"ask_sz":7,"bid_ct":1,"ask_ct":1},{"bid_px":"230.000000000","ask_px":"265.000000000","bid_sz":12,"ask_sz":1,"bid_ct":1,"ask_ct":1},{"bid_px":"220.000000000","ask_px":"275.000000000","bid_sz":26,"ask_sz":4,"bid_ct":3,"ask_ct":1},{"bid_px":"214.000000000","ask_px":"960.000000000","bid_sz":5,"ask_sz":25,"bid_ct":1,"ask_ct":1},{"bid_px":"213.650000000","ask_px":null,"bid_sz":3,"ask_sz":0,"bid_ct":1,"ask_ct":0}],"symbol":"TSLA"}
{"ts_recv":"2024-11-01T08:00:05.374782402Z","hd":{"ts_event":"2024-11-01T08:00:05.374616356Z","rtype":10,"publisher_id":2,"instrument_id":11667},"action":"A","side":"A","depth":9,"price":"145.000000000","size":30,"flags":130,"ts_in_delta":166046,"sequence":297883,"levels":[{"bid_px":"134.560000000","ask_px":"135.230000000","bid_sz":100,"ask_sz":360,"bid_ct":1,"ask_ct":1},{"bid_px":"134.410000000","ask_px":"135.300000000","bid_sz":1,"ask_sz":1000,"bid_ct":1,"ask_ct":1},{"bid_px":"134.210000000","ask_px":"136.200000000","bid_sz":20,"ask_sz":1000,"bid_ct":1,"ask_ct":1},{"bid_px":"133.100000000","ask_px":"137.680000000","bid_sz":1000,"ask_sz":500,"bid_ct":1,"ask_ct":1},{"bid_px":"132.000000000","ask_px":"138.870000000","bid_sz":72,"ask_sz":1000,"bid_ct":3,"ask_ct":2},{"bid_px":"130.000000000","ask_px":"140.740000000","bid_sz":5,"ask_sz":100,"bid_ct":1,"ask_ct":1},{"bid_px":"129.050000000","ask_px":"140.880000000","bid_sz":500,"ask_sz":1000,"bid_ct":1,"ask_ct":2},{"bid_px":"129.000000000","ask_px":"143.000000000","bid_sz":10,"ask_sz":1,"bid_ct":1,"ask_ct":1},{"bid_px":"128.470000000","ask_px":"143.690000000","bid_sz":500,"ask_sz":500,"bid_ct":1,"ask_ct":1},{"bid_px":"127.680000000","ask_px":"145.000000000","bid_sz":30,"ask_sz":30,"bid_ct":1,"ask_ct":1}],"symbol":"NVDA"}
{"ts_recv":"2024-11-01T08:00:05.429945880Z","hd":{"ts_event":"2024-11-01T08:00:05.429779649Z","rtype":10,"publisher_id":2,"instrument_id":12463},"action":"A","side":"A","depth":0,"price":"171.810000000","size":100,"flags":130,"ts_in_delta":166231,"sequence":297936,"levels":[{"bid_px":null,"ask_px":"171.810000000","bid_sz":0,"ask_sz":100,"bid_ct":0,"ask_ct":1},{"bid_px":null,"ask_px":null,"bid_sz":0,"ask_sz":0,"bid_ct":0,"ask_ct":0},{"bid_px":null,"ask_px":null,"bid_sz":0,"ask_sz":0,"bid_ct":0,"ask_ct":0},{"bid_px":null,"ask_px":null,"bid_sz":0,"ask_sz":0,"bid_ct":0,"ask_ct":0},{"bid_px":null,"ask_px":null,"bid_sz":0,"ask_sz":0,"bid_ct":0,"ask_ct":0},{"bid_px":null,"ask_px":null,"bid_sz":0,"ask_sz":0,"bid_ct":0,"ask_ct":0},{"bid_px":null,"ask_px":null,"bid_sz":0,"ask_sz":0,"bid_ct":0,"ask_ct":0},{"bid_px":null,"ask_px":null,"bid_sz":0,"ask_sz":0,"bid_ct":0,"ask_ct":0},{"bid_px":null,"ask_px":null,"bid_sz":0,"ask_sz":0,"bid_ct":0,"ask_ct":0},{"bid_px":null,"ask_px":null,"bid_sz":0,"ask_sz":0,"bid_ct":0,"ask_ct":0}],"symbol":"PEP"}
{"ts_recv":"2024-11-01T08:00:05.452312434Z","hd":{"ts_event":"2024-11-01T08:00:05.452145924Z","rtype":10,"publisher_id":2,"instrument_id":11667},"action":"A","side":"B","depth":5,"price":"130.520000000","size":4,"flags":130,"ts_in_delta":166510,"sequence":297963,"levels":[{"bid_px":"134.560000000","ask_px":"135.230000000","bid_sz":100,"ask_sz":360,"bid_ct":1,"ask_ct":1},{"bid_px":"134.410000000","ask_px":"135.300000000","bid_sz":1,"ask_sz":1000,"bid_ct":1,"ask_ct":1},{"bid_px":"134.210000000","ask_px":"136.200000000","bid_sz":20,"ask_sz":1000,"bid_ct":1,"ask_ct":1},{"bid_px":"133.100000000","ask_px":"137.680000000","bid_sz":1000,"ask_sz":500,"bid_ct":1,"ask_ct":1},{"bid_px":"132.000000000","ask_px":"138.870000000","bid_sz":72,"ask_sz":1000,"bid_ct":3,"ask_ct":2},{"bid_px":"130.520000000","ask_px":"140.740000000","bid_sz":4,"ask_sz":100,"bid_ct":1,"ask_ct":1},{"bid_px":"130.000000000","ask_px":"140.880000000","bid_sz":5,"ask_sz":1000,"bid_ct":1,"ask_ct":2},{"bid_px":"129.050000000","ask_px":"143.000000000","bid_sz":500,"ask_sz":1,"bid_ct":1,"ask_ct":1},{"bid_px":"129.000000000","ask_px":"143.690000000","bid_sz":10,"ask_sz":500,"bid_ct":1,"ask_ct":1},{"bid_px":"128.470000000","ask_px":"145.000000000","bid_sz":500,"ask_sz":30,"bid_ct":1,"ask_ct":1}],"symbol":"NVDA"}
{"ts_recv":"2024-11-01T08:00:05.478492546Z","hd":{"ts_event":"2024-11-01T08:00:05.478326529Z","rtype":10,"publisher_id":2,"instrument_id":11667},"action":"A","side":"B","depth":8,"price":"129.000000000","size":2,"flags":130,"ts_in_delta":166017,"sequence":298078,"levels":[{"bid_px":"134.560000000","ask_px":"135.230000000","bid_sz":100,"ask_sz":360,"bid_ct":1,"ask_ct":1},{"bid_px":"134.410000000","ask_px":"135.300000000","bid_sz":1,"ask_sz":1000,"bid_ct":1,"ask_ct":1},{"bid_px":"134.210000000","ask_px":"136.200000000","bid_sz":20,"ask_sz":1000,"bid_ct":1,"ask_ct":1},{"bid_px":"133.100000000","ask_px":"137.680000000","bid_sz":1000,"ask_sz":500,"bid_ct":1,"ask_ct":1},{"bid_px":"132.000000000","ask_px":"138.870000000","bid_sz":72,"ask_sz":1000,"bid_ct":3,"ask_ct":2},{"bid_px":"130.520000000","ask_px":"140.740000000","bid_sz":4,"ask_sz":100,"bid_ct":1,"ask_ct":1},{"bid_px":"130.000000000","ask_px":"140.880000000","bid_sz":5,"ask_sz":1000,"bid_ct":1,"ask_ct":2},{"bid_px":"129.050000000","ask_px":"143.000000000","bid_sz":500,"ask_sz":1,"bid_ct":1,"ask_ct":1},{"bid_px":"129.000000000","ask_px":"143.690000000","bid_sz":12,"ask_sz":500,"bid_ct":2,"ask_ct":1},{"bid_px":"128.470000000","ask_px":"145.000000000","bid_sz":500,"ask_sz":30,"bid_ct":1,"ask_ct":1}],"symbol":"NVDA"}
{"ts_recv":"2024-11-01T08:00:05.663155685Z","hd":{"ts_event":"2024-11-01T08:00:05.662989510Z","rtype":10,"publisher_id":2,"instrument_id":16244},"action":"A","side":"A","depth":8,"price":"300.000000000","size":7,"flags":130,"ts_in_delta":166175,"sequence":298692,"levels":[{"bid_px":"249.820000000","ask_px":"250.680000000","bid_sz":50,"ask_sz":100,"bid_ct":1,"ask_ct":1},{"bid_px":"249.770000000","ask_px":"250.750000000","bid_sz":50,"ask_sz":50,"bid_ct":1,"ask_ct":1},{"bid_px":"249.600000000","ask_px":"251.900000000","bid_sz":1000,"ask_sz":1000,"bid_ct":1,"ask_ct":1},{"bid_px":"249.300000000","ask_px":"253.650000000","bid_sz":1000,"ask_sz":400,"bid_ct":1,"ask_ct":1},{"bid_px":"247.150000000","ask_px":"260.000000000","bid_sz":400,"ask_sz":48,"bid_ct":1,"ask_ct":1},{"bid_px":"235.000000000","ask_px":"264.940000000","bid_sz":100,"ask_sz":7,"bid_ct":1,"ask_ct":1},{"bid_px":"230.000000000","ask_px":"265.000000000","bid_sz":12,"ask_sz":1,"bid_ct":1,"ask_ct":1},{"bid_px":"220.000000000","ask_px":"275.000000000","bid_sz":26,"ask_sz":4,"bid_ct":3,"ask_ct":1},{"bid_px":"214.000000000","ask_px":"300.000000000","bid_sz":5,"ask_sz":7,"bid_ct":1,"ask_ct":1},{"bid_px":"213.650000000","ask_px":"960.000000000","bid_sz":3,"ask_sz":25,"bid_ct":1,"ask_ct":1}],"symbol":"TSLA"}
{"ts_recv":"2024-11-01T08:00:05.777338971Z","hd":{"ts_event":"2024-11-01T08:00:05.777172581Z","rtype":10,"publisher_id":2,"instrument_id":16244},"action":"A","side":"B","depth":1,"price":"249.800000000","size":199,"flags":130,"ts_in_delta":166390,"sequence":298816,"levels":[{"bid_px":"249.820000000","ask_px":"250.680000000","bid_sz":50,"ask_sz":100,"bid_ct":1,"ask_ct":1},{"bid_px":"249.800000000","ask_px":"250.750000000","bid_sz":199,"ask_sz":50,"bid_ct":1,"ask_ct":1},{"bid_px":"249.770000000","ask_px":"251.900000000","bid_sz":50,"ask_sz":1000,"bid_ct":1,"ask_ct":1},{"bid_px":"249.600000000","ask_px":"253.650000000","bid_sz":1000,"ask_sz":400,"bid_ct":1,"ask_ct":1},{"bid_px":"249.300000000","ask_px":"260.000000000","bid_sz":1000,"ask_sz":48,"bid_ct":1,"ask_ct":1},{"bid_px":"247.150000000","ask_px":"264.940000000","bid_sz":400,"ask_sz":7,"bid_ct":1,"ask_ct":1},{"bid_px":"235.000000000","ask_px":"265.000000000","bid_sz":100,"ask_sz":1,"bid_ct":1,"ask_ct":1},{"bid_px":"230.000000000","ask_px":"275.000000000","bid_sz":12,"ask_sz":4,"bid_ct":1,"ask_ct":1},{"bid_px":"220.000000000","ask_px":"300.000000000","bid_sz":26,"ask_sz":7,"bid_ct":3,"ask_ct":1},{"bid_px":"214.000000000","ask_px":"960.000000000","bid_sz":5,"ask_sz":25,"bid_ct":1,"ask_ct":1}],"symbol":"TSLA"}
{"ts_recv":"2024-11-01T08:00:05.826373382Z","hd":{"ts_event":"2024-11-01T08:00:05.826207790Z","rtype":10,"publisher_id":2,"instrument_id":16244},"action":"C","side":"A","depth":2,"price":"251.900000000","size":1000,"flags":130,"ts_in_delta":165592,"sequence":298867,"levels":[{"bid_px":"249.820000000","ask_px":"250.680000000","bid_sz":50,"ask_sz":100,"bid_ct":1,"ask_ct":1},{"bid_px":"249.800000000","ask_px":"250.750000000","bid_sz":199,"ask_sz":50,"bid_ct":1,"ask_ct":1},{"bid_px":"249.770000000","ask_px":"253.650000000","bid_sz":50,"ask_sz":400,"bid_ct":1,"ask_ct":1},{"bid_px":"249.600000000","ask_px":"260.000000000","bid_sz":1000,"ask_sz":48,"bid_ct":1,"ask_ct":1},{"bid_px":"249.300000000","ask_px":"264.940000000","bid_sz":1000,"ask_sz":7,"bid_ct":1,"ask_ct":1},{"bid_px":"247.150000000","ask_px":"265.000000000","bid_sz":400,"ask_sz":1,"bid_ct":1,"ask_ct":1},{"bid_px":"235.000000000","ask_px":"275.000000000","bid_sz":100,"ask_sz":4,"bid_ct":1,"ask_ct":1},{"bid_px":"230.000000000","ask_px":"300.000000000","bid_sz":12,"ask_sz":7,"bid_ct":1,"ask_ct":1},{"bid_px":"220.000000000","ask_px":"960.000000000","bid_sz":26,"ask_sz":25,"bid_ct":3,"ask_ct":1},{"bid_px":"214.000000000","ask_px":null,"bid_sz":5,"ask_sz":0,"bid_ct":1,"ask_ct":0}],"symbol":"TSLA"}
{"ts_recv":"2024-11-01T08:00:05.842040154Z","hd":{"ts_event":"2024-11-01T08:00:05.841874018Z","rtype":10,"publisher_id":2,"instrument_id":16244},"action":"A","side":"A","depth":2,"price":"252.100000000","size":1000,"flags":130,"ts_in_delta":166136,"sequence":298880,"levels":[{"bid_px":"249.820000000","ask_px":"250.680000000","bid_sz":50,"ask_sz":100,"bid_ct":1,"ask_ct":1},{"bid_px":"249.800000000","ask_px":"250.750000000","bid_sz":199,"ask_sz":50,"bid_ct":1,"ask_ct":1},{"bid_px":"249.770000000","ask_px":"252.100000000","bid_sz":50,"ask_sz":1000,"bid_ct":1,"ask_ct":1},{"bid_px":"249.600000000","ask_px":"253.650000000","bid_sz":1000,"ask_sz":400,"bid_ct":1,"ask_ct":1},{"bid_px":"249.300000000","ask_px":"260.000000000","bid_sz":1000,"ask_sz":48,"bid_ct":1,"ask_ct":1},{"bid_px":"247.150000000","ask_px":"264.940000000","bid_sz":400,"ask_sz":7,"bid_ct":1,"ask_ct":1},{"bid_px":"235.000000000","ask_px":"265.000000000","bid_sz":100,"ask_sz":1,"bid_ct":1,"ask_ct":1},{"bid_px":"230.000000000","ask_px":"275.000000000","bid_sz":12,"ask_sz":4,"bid_ct":1,"ask_ct":1},{"bid_px":"220.000000000","ask_px":"300.000000000","bid_sz":26,"ask_sz":7,"bid_ct":3,"ask_ct":1},{"bid_px":"214.000000000","ask_px":"960.000000000","bid_sz":5,"ask_sz":25,"bid_ct":1,"ask_ct":1}],"symbol":"TSLA"}
{"ts_recv":"2024-11-01T08:00:05.866605914Z","hd":{"ts_event":"2024-11-01T08:00:05.866439798Z","rtype":10,"publisher_id":2,"instrument_id":38},"action":"A","side":"B","depth":6,"price":"100.000000000","size":1,"flags":130,"ts_in_delta":166116,"sequence":298899,"levels":[{"bid_px":"221.200000000","ask_px":"224.400000000","bid_sz":1000,"ask_sz":1000,"bid_ct":1,"ask_ct":1},{"bid_px":"220.000000000","ask_px":"225.490000000","bid_sz":2,"ask_sz":442,"bid_ct":1,"ask_ct":1},{"bid_px":"219.690000000","ask_px":"234.000000000","bid_sz":442,"ask_sz":20,"bid_ct":1,"ask_ct":1},{"bid_px":"217.000000000","ask_px":"240.000000000","bid_sz":1525,"ask_sz":150,"bid_ct":1,"ask_ct":1},{"bid_px":"190.000000000","ask_px":null,"bid_sz":1,"ask_sz":0,"bid_ct":1,"ask_ct":0},{"bid_px":"180.000000000","ask_px":null,"bid_sz":1,"ask_sz":0,"bid_ct":1,"ask_ct":0},{"bid_px":"100.000000000","ask_px":null,"bid_sz":1,"ask_sz":0,"bid_ct":1,"ask_ct":0},{"bid_px":null,"ask_px":null,"bid_sz":0,"ask_sz":0,"bid_ct":0,"ask_ct":0},{"bid_px":null,"ask_px":null,"bid_sz":0,"ask_sz":0,"bid_ct":0,"ask_ct":0},{"bid_px":null,"ask_px":null,"bid_sz":0,"ask_sz":0,"bid_ct":0,"ask_ct":0}],"symbol":"AAPL"}
{"ts_recv":"2024-11-01T08:00:05.869518062Z","hd":{"ts_event":"2024-11-01T08:00:05.869351689Z","rtype":10,"publisher_id":2,"instrument_id":11667},"action":"A","side":"A","depth":2,"price":"136.100000000","size":1000,"flags":130,"ts_in_delta":166373,"sequence":298906,"levels":[{"bid_px":"134.560000000","ask_px":"135.230000000","bid_sz":100,"ask_sz":360,"bid_ct":1,"ask_ct":1},{"bid_px":"134.410000000","ask_px":"135.300000000","bid_sz":1,"ask_sz":1000,"bid_ct":1,"ask_ct":1},{"bid_px":"134.210000000","ask_px":"136.100000000","bid_sz":20,"ask_sz":1000,"bid_ct":1,"ask_ct":1},{"bid_px":"133.100000000","ask_px":"136.200000000","bid_sz":1000,"ask_sz":1000,"bid_ct":1,"ask_ct":1},{"bid_px":"132.000000000","ask_px":"137.680000000","bid_sz":72,"ask_sz":500,"bid_ct":3,"ask_ct":1},{"bid_px":"130.520000000","ask_px":"138.870000000","bid_sz":4,"ask_sz":1000,"bid_ct":1,"ask_ct":2},{"bid_px":"130.000000000","ask_px":"140.740000000","bid_sz":5,"ask_sz":100,"bid_ct":1,"ask_ct":1},{"bid_px":"129.050000000","ask_px":"140.880000000","bid_sz":500,"ask_sz":1000,"bid_ct":1,"ask_ct":2},{"bid_px":"129.000000000","ask_px":"143.000000000","bid_sz":12,"ask_sz":1,"bid_ct":2,"ask_ct":1},{"bid_px":"128.470000000","ask_px":"143.690000000","bid_sz":500,"ask_sz":500,"bid_ct":1,"ask_ct":1}],"symbol":"NVDA"}
{"ts_recv":"2024-11-01T08:00:05.869530759Z","hd":{"ts_event":"2024-11-01T08:00:05.869364967Z","rtype":10,"publisher_id":2,"instrument_id":11667},"action":"C","side":"A","depth":3,"price":"136.200000000","size":1000,"flags":130,"ts_in_delta":165792,"sequence":298907,"levels":[{"bid_px":"134.560000000","ask_px":"135.230000000","bid_sz":100,"ask_sz":360,"bid_ct":1,"ask_ct":1},{"bid_px":"134.410000000","ask_px":"135.300000000","bid_sz":1,"ask_sz":1000,"bid_ct":1,"ask_ct":1},{"bid_px":"134.210000000","ask_px":"136.100000000","bid_sz":20,"ask_sz":1000,"bid_ct":1,"ask_ct":1},{"bid_px":"133.100000000","ask_px":"137.680000000","bid_sz":1000,"ask_sz":500,"bid_ct":1,"ask_ct":1},{"bid_px":"132.000000000","ask_px":"138.870000000","bid_sz":72,"ask_sz":1000,"bid_ct":3,"ask_ct":2},{"bid_px":"130.520000000","ask_px":"140.740000000","bid_sz":4,"ask_sz":100,"bid_ct":1,"ask_ct":1},{"bid_px":"130.000000000","ask_px":"140.880000000","bid_sz":5,"ask_sz":1000,"bid_ct":1,"ask_ct":2},{"bid_px":"129.050000000","ask_px":"143.000000000","bid_sz":500,"ask_sz":1,"bid_ct":1,"ask_ct":1},{"bid_px":"129.000000000","ask_px":"143.690000000","bid_sz":12,"ask_sz":500,"bid_ct":2,"ask_ct":1},{"bid_px":"128.470000000","ask_px":"145.000000000","bid_sz":500,"ask_sz":30,"bid_ct":1,"ask_ct":1}],"symbol":"NVDA"}
{"ts_recv":"2024-11-01T08:00:05.932102576Z","hd":{"ts_event":"2024-11-01T08:00:05.931936345Z","rtype":10,"publisher_id":2,"instrument_id":38},"action":"A","side":"A","depth":1,"price":"225.100000000","size":2000,"flags":130,"ts_in_delta":166231,"sequence":298989,"levels":[{"bid_px":"221.200000000","ask_px":"224.400000000","bid_sz":1000,"ask_sz":1000,"bid_ct":1,"ask_ct":1},{"bid_px":"220.000000000","ask_px":"225.100000000","bid_sz":2,"ask_sz":2000,"bid_ct":1,"ask_ct":1},{"bid_px":"219.690000000","ask_px":"225.490000000","bid_sz":442,"ask_sz":442,"bid_ct":1,"ask_ct":1},{"bid_px":"217.000000000","ask_px":"234.000000000","bid_sz":1525,"ask_sz":20,"bid_ct":1,"ask_ct":1},{"bid_px":"190.000000000","ask_px":"240.000000000","bid_sz":1,"ask_sz":150,"bid_ct":1,"ask_ct":1},{"bid_px":"180.000000000","ask_px":null,"bid_sz":1,"ask_sz":0,"bid_ct":1,"ask_ct":0},{"bid_px":"100.000000000","ask_px":null,"bid_sz":1,"ask_sz":0,"bid_ct":1,"ask_ct":0},{"bid_px":null,"ask_px":null,"bid_sz":0,"ask_sz":0,"bid_ct":0,"ask_ct":0},{"bid_px":null,"ask_px":null,"bid_sz":0,"ask_sz":0,"bid_ct":0,"ask_ct":0},{"bid_px":null,"ask_px":null,"bid_sz":0,"ask_sz":0,"bid_ct":0,"ask_ct":0}],"symbol":"AAPL"}
{"ts_recv":"2024-11-01T08:00:05.932350098Z","hd":{"ts_event":"2024-11-01T08:00:05.932183820Z","rtype":10,"publisher_id":2,"instrument_id":38},"action":"A","side":"A","depth":0,"price":"224.200000000","size":1000,"flags":130,"ts_in_delta":166278,"sequence":298990,"levels":[{"bid_px":"221.200000000","ask_px":"224.200000000","bid_sz":1000,"ask_sz":1000,"bid_ct":1,"ask_ct":1},{"bid_px":"220.000000000","ask_px":"224.400000000","bid_sz":2,"ask_sz":1000,"bid_ct":1,"ask_ct":1},{"bid_px":"219.690000000","ask_px":"225.100000000","bid_sz":442,"ask_sz":2000,"bid_ct":1,"ask_ct":1},{"bid_px":"217.000000000","ask_px":"225.490000000","bid_sz":1525,"ask_sz":442,"bid_ct":1,"ask_ct":1},{"bid_px":"190.000000000","ask_px":"234.000000000","bid_sz":1,"ask_sz":20,"bid_ct":1,"ask_ct":1},{"bid_px":"180.000000000","ask_px":"240.000000000","bid_sz":1,"ask_sz":150,"bid_ct":1,"ask_ct":1},{"bid_px":"100.000000000","ask_px":null,"bid_sz":1,"ask_sz":0,"bid_ct":1,"ask_ct":0},{"bid_px":null,"ask_px":null,"bid_sz":0,"ask_sz":0,"bid_ct":0,"ask_ct":0},{"bid_px":null,"ask_px":null,"bid_sz":0,"ask_sz":0,"bid_ct":0,"ask_ct":0},{"bid_px":null,"ask_px":null,"bid_sz":0,"ask_sz":0,"bid_ct":0,"ask_ct":0}],"symbol":"AAPL"}
{"ts_recv":"2024-11-01T08:00:05.933251111Z","hd":{"ts_event":"2024-11-01T08:00:05.933085429Z","rtype":10,"publisher_id":2,"instrument_id":38},"action":"C","side":"A","depth":1,"price":"224.400000000","size":1000,"flags":130,"ts_in_delta":165682,"sequence":298991,"levels":[{"bid_px":"221.200000000","ask_px":"224.200000000","bid_sz":1000,"ask_sz":1000,"bid_ct":1,"ask_ct":1},{"bid_px":"220.000000000","ask_px":"225.100000000","bid_sz":2,"ask_sz":2000,"bid_ct":1,"ask_ct":1},{"bid_px":"219.690000000","ask_px":"225.490000000","bid_sz":442,"ask_sz":442,"bid_ct":1,"ask_ct":1},{"bid_px":"217.000000000","ask_px":"234.000000000","bid_sz":1525,"ask_sz":20,"bid_ct":1,"ask_ct":1},{"bid_px":"190.000000000","ask_px":"240.000000000","bid_sz":1,"ask_sz":150,"bid_ct":1,"ask_ct":1},{"bid_px":"180.000000000","ask_px":null,"bid_sz":1,"ask_sz":0,"bid_ct":1,"ask_ct":0},{"bid_px":"100.000000000","ask_px":null,"bid_sz":1,"ask_sz":0,"bid_ct":1,"ask_ct":0},{"bid_px":null,"ask_px":null,"bid_sz":0,"ask_sz":0,"bid_ct":0,"ask_ct":0},{"bid_px":null,"ask_px":null,"bid_sz":0,"ask_sz":0,"bid_ct":0,"ask_ct":0},{"bid_px":null,"ask_px":null,"bid_sz":0,"ask_sz":0,"bid_ct":0,"ask_ct":0}],"symbol":"AAPL"}
{"ts_recv":"2024-11-01T08:00:05.946422252Z","hd":{"ts_event":"2024-11-01T08:00:05.946255895Z","rtype":10,"publisher_id":2,"instrument_id":10888},"action":"A","side":"B","depth":2,"price":"406.000000000","size":7,"flags":130,"ts_in_delta":166357,"sequence":299003,"levels":[{"bid_px":"410.000000000","ask_px":"415.070000000","bid_sz":1,"ask_sz":246,"bid_ct":1,"ask_ct":1},{"bid_px":"408.960000000","ask_px":"420.000000000","bid_sz":5,"ask_sz":3,"bid_ct":1,"ask_ct":1},{"bid_px":"406.000000000","ask_px":"468.000000000","bid_sz":7,"ask_sz":65,"bid_ct":1,"ask_ct":1},{"bid_px":"404.410000000","ask_px":null,"bid_sz":246,"ask_sz":0,"bid_ct":1,"ask_ct":0},{"bid_px":"398.000000000","ask_px":null,"bid_sz":5,"ask_sz":0,"bid_ct":1,"ask_ct":0},{"bid_px":null,"ask_px":null,"bid_sz":0,"ask_sz":0,"bid_ct":0,"ask_ct":0},{"bid_px":null,"ask_px":null,"bid_sz":0,"ask_sz":0,"bid_ct":0,"ask_ct":0},{"bid_px":null,"ask_px":null,"bid_sz":0,"ask_sz":0,"bid_ct":0,"ask_ct":0},{"bid_px":null,"ask_px":null,"bid_sz":0,"ask_sz":0,"bid_ct":0,"ask_ct":0},{"bid_px":null,"ask_px":null,"bid_sz":0,"ask_sz":0,"bid_ct":0,"ask_ct":0}],"symbol":"MSFT"}
{"ts_recv":"2024-11-01T08:00:05.958384234Z","hd":{"ts_event":"2024-11-01T08:00:05.958218308Z","rtype":10,"publisher_id":2,"instrument_id":11667},"action":"C","side":"B","depth":0,"price":"134.560000000","size":100,"flags":130,"ts_in_delta":165926,"sequence":299022,"levels":[{"bid_px":"134.410000000","ask_px":"135.230000000","bid_sz":1,"ask_sz":360,"bid_ct":1,"ask_ct":1},{"bid_px":"134.210000000","ask_px":"135.300000000","bid_sz":20,"ask_sz":1000,"bid_ct":1,"ask_ct":1},{"bid_px":"133.100000000","ask_px":"136.100000000","bid_sz":1000,"ask_sz":1000,"bid_ct":1,"ask_ct":1},{"bid_px":"132.000000000","ask_px":"137.680000000","bid_sz":72,"ask_sz":500,"bid_ct":3,"ask_ct":1},{"bid_px":"130.520000000","ask_px":"138.870000000","bid_sz":4,"ask_sz":1000,"bid_ct":1,"ask_ct":2},{"bid_px":"130.000000000","ask_px":"140.740000000","bid_sz":5,"ask_sz":100,"bid_ct":1,"ask_ct":1},{"bid_px":"129.050000000","ask_px":"140.880000000","bid_sz":500,"ask_sz":1000,"bid_ct":1,"ask_ct":2},{"bid_px":"129.000000000","ask_px":"143.000000000","bid_sz":12,"ask_sz":1,"bid_ct":2,"ask_ct":1},{"bid_px":"128.470000000","ask_px":"143.690000000","bid_sz":500,"ask_sz":500,"bid_ct":1,"ask_ct":1},{"bid_px":"128.000000000","ask_px":"145.000000000","bid_sz":21,"ask_sz":30,"bid_ct":2,"ask_ct":1}],"symbol":"NVDA"}
{"ts_recv":"2024-11-01T08:00:05.958397936Z","hd":{"ts_event":"2024-11-01T08:00:05.958231910Z","rtype":10,"publisher_id":2,"instrument_id":11667},"action":"A","side":"B","depth":0,"price":"134.440000000","size":100,"flags":130,"ts_in_delta":166026,"sequence":299023,"levels":[{"bid_px":"134.440000000","ask_px":"135.230000000","bid_sz":100,"ask_sz":360,"bid_ct":1,"ask_ct":1},{"bid_px":"134.410000000","ask_px":"135.300000000","bid_sz":1,"ask_sz":1000,"bid_ct":1,"ask_ct":1},{"bid_px":"134.210000000","ask_px":"136.100000000","bid_sz":20,"ask_sz":1000,"bid_ct":1,"ask_ct":1},{"bid_px":"133.100000000","ask_px":"137.680000000","bid_sz":1000,"ask_sz":500,"bid_ct":1,"ask_ct":1},{"bid_px":"132.000000000","ask_px":"138.870000000","bid_sz":72,"ask_sz":1000,"bid_ct":3,"ask_ct":2},{"bid_px":"130.520000000","ask_px":"140.740000000","bid_sz":4,"ask_sz":100,"bid_ct":1,"ask_ct":1},{"bid_px":"130.000000000","ask_px":"140.880000000","bid_sz":5,"ask_sz":1000,"bid_ct":1,"ask_ct":2},{"bid_px":"129.050000000","ask_px":"143.000000000","bid_sz":500,"ask_sz":1,"bid_ct":1,"ask_ct":1},{"bid_px":"129.000000000","ask_px":"143.690000000","bid_sz":12,"ask_sz":500,"bid_ct":2,"ask_ct":1},{"bid_px":"128.470000000","ask_px":"145.000000000","bid_sz":500,"ask_sz":30,"bid_ct":1,"ask_ct":1}],"symbol":"NVDA"}
{"ts_recv":"2024-11-01T08:00:05.961984958Z","hd":{"ts_event":"2024-11-01T08:00:05.961818767Z","rtype":10,"publisher_id":2,"instrument_id":16244},"action":"A","side":"B","depth":0,"price":"249.830000000","size":50,"flags":130,"ts_in_delta":166191,"sequence":299030,"levels":[{"bid_px":"249.830000000","ask_px":"250.680000000","bid_sz":50,"ask_sz":100,"bid_ct":1,"ask_ct":1},{"bid_px":"249.800000000","ask_px":"250.750000000","bid_sz":199,"ask_sz":50,"bid_ct":1,"ask_ct":1},{"bid_px":"249.770000000","ask_px":"252.100000000","bid_sz":50,"ask_sz":1000,"bid_ct":1,"ask_ct":1},{"bid_px":"249.600000000","ask_px":"253.650000000","bid_sz":1000,"ask_sz":400,"bid_ct":1,"ask_ct":1},{"bid_px":"249.300000000","ask_px":"260.000000000","bid_sz":1000,"ask_sz":48,"bid_ct":1,"ask_ct":1},{"bid_px":"247.150000000","ask_px":"264.940000000","bid_sz":400,"ask_sz":7,"bid_ct":1,"ask_ct":1},{"bid_px":"235.000000000","ask_px":"265.000000000","bid_sz":100,"ask_sz":1,"bid_ct":1,"ask_ct":1},{"bid_px":"230.000000000","ask_px":"275.000000000","bid_sz":12,"ask_sz":4,"bid_ct":1,"ask_ct":1},{"bid_px":"220.000000000","ask_px":"300.000000000","bid_sz":26,"ask_sz":7,"bid_ct":3,"ask_ct":1},{"bid_px":"214.000000000","ask_px":"960.000000000","bid_sz":5,"ask_sz":25,"bid_ct":1,"ask_ct":1}],"symbol":"TSLA"}
{"ts_recv":"2024-11-01T08:00:05.992007973Z","hd":{"ts_event":"2024-11-01T08:00:05.991841871Z","rtype":10,"publisher_id":2,"instrument_id":16244},"action":"A","side":"B","depth":8,"price":"220.000000000","size":34,"flags":130,"ts_in_delta":166102,"sequence":299054,"levels":[{"bid_px":"249.830000000","ask_px":"250.680000000","bid_sz":50,"ask_sz":100,"bid_ct":1,"ask_ct":1},{"bid_px":"249.800000000","ask_px":"250.750000000","bid_sz":199,"ask_sz":50,"bid_ct":1,"ask_ct":1},{"bid_px":"249.770000000","ask_px":"252.100000000","bid_sz":50,"ask_sz":1000,"bid_ct":1,"ask_ct":1},{"bid_px":"249.600000000","ask_px":"253.650000000","bid_sz":1000,"ask_sz":400,"bid_ct":1,"ask_ct":1},{"bid_px":"249.300000000","ask_px":"260.000000000","bid_sz":1000,"ask_sz":48,"bid_ct":1,"ask_ct":1},{"bid_px":"247.150000000","ask_px":"264.940000000","bid_sz":400,"ask_sz":7,"bid_ct":1,"ask_ct":1},{"bid_px":"235.000000000","ask_px":"265.000000000","bid_sz":100,"ask_sz":1,"bid_ct":1,"ask_ct":1},{"bid_px":"230.000000000","ask_px":"275.000000000","bid_sz":12,"ask_sz":4,"bid_ct":1,"ask_ct":1},{"bid_px":"220.000000000","ask_px":"300.000000000","bid_sz":60,"ask_sz":7,"bid_ct":4,"ask_ct":1},{"bid_px":"214.000000000","ask_px":"960.000000000","bid_sz":5,"ask_sz":25,"bid_ct":1,"ask_ct":1}],"symbol":"TSLA"}
{"ts_recv":"2024-11-01T08:00:06.008333344Z","hd":{"ts_event":"2024-11-01T08:00:06.008167175Z","rtype":10,"publisher_id":2,"instrument_id":16244},"action":"A","side":"B","depth":8,"price":"225.000000000","size":8,"flags":130,"ts_in_delta":166169,"sequence":299075,"levels":[{"bid_px":"249.830000000","ask_px":"250.680000000","bid_sz":50,"ask_sz":100,"bid_ct":1,"ask_ct":1},{"bid_px":"249.800000000","ask_px":"250.750000000","bid_sz":199,"ask_sz":50,"bid_ct":1,"ask_ct":1},{"bid_px":"249.770000000","ask_px":"252.100000000","bid_sz":50,"ask_sz":1000,"bid_ct":1,"ask_ct":1},{"bid_px":"249.600000000","ask_px":"253.650000000","bid_sz":1000,"ask_sz":400,"bid_ct":1,"ask_ct":1},{"bid_px":"249.300000000","ask_px":"260.000000000","bid_sz":1000,"ask_sz":48,"bid_ct":1,"ask_ct":1},{"bid_px":"247.150000000","ask_px":"264.940000000","bid_sz":400,"ask_sz":7,"bid_ct":1,"ask_ct":1},{"bid_px":"235.000000000","ask_px":"265.000000000","bid_sz":100,"ask_sz":1,"bid_ct":1,"ask_ct":1},{"bid_px":"230.000000000","ask_px":"275.000000000","bid_sz":12,"ask_sz":4,"bid_ct":1,"ask_ct":1},{"bid_px":"225.000000000","ask_px":"300.000000000","bid_sz":8,"ask_sz":7,"bid_ct":1,"ask_ct":1},{"bid_px":"220.000000000","ask_px":"960.000000000","bid_sz":60,"ask_sz":25,"bid_ct":4,"ask_ct":1}],"symbol":"TSLA"}
{"ts_recv":"2024-11-01T08:00:06.030860640Z","hd":{"ts_event":"2024-11-01T08:00:06.030694395Z","rtype":10,"publisher_id":2,"instrument_id":11667},"action":"A","side":"A","depth":0,"price":"135.000000000","size":8,"flags":130,"ts_in_delta":166245,"sequence":299116,"levels":[{"bid_px":"134.440000000","ask_px":"135.000000000","bid_sz":100,"ask_sz":8,"bid_ct":1,"ask_ct":1},{"bid_px":"134.410000000","ask_px":"135.230000000","bid_sz":1,"ask_sz":360,"bid_ct":1,"ask_ct":1},{"bid_px":"134.210000000","ask_px":"135.300000000","bid_sz":20,"ask_sz":1000,"bid_ct":1,"ask_ct":1},{"bid_px":"133.100000000","ask_px":"136.100000000","bid_sz":1000,"ask_sz":1000,"bid_ct":1,"ask_ct":1},{"bid_px":"132.000000000","ask_px":"137.680000000","bid_sz":72,"ask_sz":500,"bid_ct":3,"ask_ct":1},{"bid_px":"130.520000000","ask_px":"138.870000000","bid_sz":4,"ask_sz":1000,"bid_ct":1,"ask_ct":2},{"bid_px":"130.000000000","ask_px":"140.740000000","bid_sz":5,"ask_sz":100,"bid_ct":1,"ask_ct":1},{"bid_px":"129.050000000","ask_px":"140.880000000","bid_sz":500,"ask_sz":1000,"bid_ct":1,"ask_ct":2},{"bid_px":"129.000000000","ask_px":"143.000000000","bid_sz":12,"ask_sz":1,"bid_ct":2,"ask_ct":1},{"bid_px":"128.470000000","ask_px":"143.690000000","bid_sz":500,"ask_sz":500,"bid_ct":1,"ask_ct":1}],"symbol":"NVDA"}
{"ts_recv":"2024-11-01T08:00:06.031861392Z","hd":{"ts_event":"2024-11-01T08:00:06.031695298Z","rtype":10,"publisher_id":2,"instrument_id":16244},"action":"A","side":"B","depth":6,"price":"235.000000000","size":30,"flags":130,"ts_in_delta":166094,"sequence":299119,"levels":[{"bid_px":"249.830000000","ask_px":"250.680000000","bid_sz":50,"ask_sz":100,"bid_ct":1,"ask_ct":1},{"bid_px":"249.800000000","ask_px":"250.750000000","bid_sz":199,"ask_sz":50,"bid_ct":1,"ask_ct":1},{"bid_px":"249.770000000","ask_px":"252.100000000","bid_sz":50,"ask_sz":1000,"bid_ct":1,"ask_ct":1},{"bid_px":"249.600000000","ask_px":"253.650000000","bid_sz":1000,"ask_sz":400,"bid_ct":1,"ask_ct":1},{"bid_px":"249.300000000","ask_px":"260.000000000","bid_sz":1000,"ask_sz":48,"bid_ct":1,"ask_ct":1},{"bid_px":"247.150000000","ask_px":"264.940000000","bid_sz":400,"ask_sz":7,"bid_ct":1,"ask_ct":1},{"bid_px":"235.000000000","ask_px":"265.000000000","bid_sz":130,"ask_sz":1,"bid_ct":2,"ask_ct":1},{"bid_px":"230.000000000","ask_px":"275.000000000","bid_sz":12,"ask_sz":4,"bid_ct":1,"ask_ct":1},{"bid_px":"225.000000000","ask_px":"300.000000000","bid_sz":8,"ask_sz":7,"bid_ct":1,"ask_ct":1},{"bid_px":"220.000000000","ask_px":"960.000000000","bid_sz":60,"ask_sz":25,"bid_ct":4,"ask_ct":1}],"symbol":"TSLA"}
{"ts_recv":"2024-11-01T08:00:06.052861614Z","hd":{"ts_event":"2024-11-01T08:00:06.052695502Z","rtype":10,"publisher_id":2,"instrument_id":16244},"action":"A","side":"A","depth":7,"price":"267.800000000","size":30,"flags":130,"ts_in_delta":166112,"sequence":299209,"levels":[{"bid_px":"249.830000000","ask_px":"250.680000000","bid_sz":50,"ask_sz":100,"bid_ct":1,"ask_ct":1},{"bid_px":"249.800000000","ask_px":"250.750000000","bid_sz":199,"ask_sz":50,"bid_ct":1,"ask_ct":1},{"bid_px":"249.770000000","ask_px":"252.100000000","bid_sz":50,"ask_sz":1000,"bid_ct":1,"ask_ct":1},{"bid_px":"249.600000000","ask_px":"253.650000000","bid_sz":1000,"ask_sz":400,"bid_ct":1,"ask_ct":1},{"bid_px":"249.300000000","ask_px":"260.000000000","bid_sz":1000,"ask_sz":48,"bid_ct":1,"ask_ct":1},{"bid_px":"247.150000000","ask_px":"264.940000000","bid_sz":400,"ask_sz":7,"bid_ct":1,"ask_ct":1},{"bid_px":"235.000000000","ask_px":"265.000000000","bid_sz":130,"ask_sz":1,"bid_ct":2,"ask_ct":1},{"bid_px":"230.000000000","ask_px":"267.800000000","bid_sz":12,"ask_sz":30,"bid_ct":1,"ask_ct":1},{"bid_px":"225.000000000","ask_px":"275.000000000","bid_sz":8,"ask_sz":4,"bid_ct":1,"ask_ct":1},{"bid_px":"220.000000000","ask_px":"300.000000000","bid_sz":60,"ask_sz":7,"bid_ct":4,"ask_ct":1}],"symbol":"TSLA"}
{"ts_recv":"2024-11-01T08:00:06.062906169Z","hd":{"ts_event":"2024-11-01T08:00:06.062739623Z","rtype":10,"publisher_id":2,"instrument_id":16244},"action":"A","side":"A","depth":8,"price":"275.000000000","size":12,"flags":130,"ts_in_delta":166546,"sequence":299266,"levels":[{"bid_px":"249.830000000","ask_px":"250.680000000","bid_sz":50,"ask_sz":100,"bid_ct":1,"ask_ct":1},{"bid_px":"249.800000000","ask_px":"250.750000000","bid_sz":199,"ask_sz":50,"bid_ct":1,"ask_ct":1},{"bid_px":"249.770000000","ask_px":"252.100000000","bid_sz":50,"ask_sz":1000,"bid_ct":1,"ask_ct":1},{"bid_px":"249.600000000","ask_px":"253.650000000","bid_sz":1000,"ask_sz":400,"bid_ct":1,"ask_ct":1},{"bid_px":"249.300000000","ask_px":"260.000000000","bid_sz":1000,"ask_sz":48,"bid_ct":1,"ask_ct":1},{"bid_px":"247.150000000","ask_px":"264.940000000","bid_sz":400,"ask_sz":7,"bid_ct":1,"ask_ct":1},{"bid_px":"235.000000000","ask_px":"265.000000000","bid_sz":130,"ask_sz":1,"bid_ct":2,"ask_ct":1},{"bid_px":"230.000000000","ask_px":"267.800000000","bid_sz":12,"ask_sz":30,"bid_ct":1,"ask_ct":1},{"bid_px":"225.000000000","ask_px":"275.000000000","bid_sz":8,"ask_sz":16,"bid_ct":1,"ask_ct":2},{"bid_px":"220.000000000","ask_px":"300.000000000","bid_sz":60,"ask_sz":7,"bid_ct":4,"ask_ct":1}],"symbol":"TSLA"}
{"ts_recv":"2024-11-01T08:00:06.066367690Z","hd":{"ts_event":"2024-11-01T08:00:06.066201594Z","rtype":10,"publisher_id":2,"instrument_id":16244},"action":"A","side":"A","depth":9,"price":"300.000000000","size":1,"flags":130,"ts_in_delta":166096,"sequence":299273,"levels":[{"bid_px":"249.830000000","ask_px":"250.680000000","bid_sz":50,"ask_sz":100,"bid_ct":1,"ask_ct":1},{"bid_px":"249.800000000","ask_px":"250.750000000","bid_sz":199,"ask_sz":50,"bid_ct":1,"ask_ct":1},{"bid_px":"249.770000000","ask_px":"252.100000000","bid_sz":50,"ask_sz":1000,"bid_ct":1,"ask_ct":1},{"bid_px":"249.600000000","ask_px":"253.650000000","bid_sz":1000,"ask_sz":400,"bid_ct":1,"ask_ct":1},{"bid_px":"249.300000000","ask_px":"260.000000000","bid_sz":1000,"ask_sz":48,"bid_ct":1,"ask_ct":1},{"bid_px":"247.150000000","ask_px":"264.940000000","bid_sz":400,"ask_sz":7,"bid_ct":1,"ask_ct":1},{"bid_px":"235.000000000","ask_px":"265.000000000","bid_sz":130,"ask_sz":1,"bid_ct":2,"ask_ct":1},{"bid_px":"230.000000000","ask_px":"267.800000000","bid_sz":12,"ask_sz":30,"bid_ct":1,"ask_ct":1},{"bid_px":"225.000000000","ask_px":"275.000000000","bid_sz":8,"ask_sz":16,"bid_ct":1,"ask_ct":2},{"bid_px":"220.000000000","ask_px":"300.000000000","bid_sz":60,"ask_sz":8,"bid_ct":4,"ask_ct":2}],"symbol":"TSLA"}
{"ts_recv":"2024-11-01T08:00:06.078341456Z","hd":{"ts_event":"2024-11-01T08:00:06.078175284Z","rtype":10,"publisher_id":2,"instrument_id":11667},"action":"A","side":"B","depth":1,"price":"134.410000000","size":60,"flags":130,"ts_in_delta":166172,"sequence":299316,"levels":[{"bid_px":"134.440000000","ask_px":"135.000000000","bid_sz":100,"ask_sz":8,"bid_ct":1,"ask_ct":1},{"bid_px":"134.410000000","ask_px":"135.230000000","bid_sz":61,"ask_sz":360,"bid_ct":2,"ask_ct":1},{"bid_px":"134.210000000","ask_px":"135.300000000","bid_sz":20,"ask_sz":1000,"bid_ct":1,"ask_ct":1},{"bid_px":"133.100000000","ask_px":"136.100000000","bid_sz":1000,"ask_sz":1000,"bid_ct":1,"ask_ct":1},{"bid_px":"132.000000000","ask_px":"137.680000000","bid_sz":72,"ask_sz":500,"bid_ct":3,"ask_ct":1},{"bid_px":"130.520000000","ask_px":"138.870000000","bid_sz":4,"ask_sz":1000,"bid_ct":1,"ask_ct":2},{"bid_px":"130.000000000","ask_px":"140.740000000","bid_sz":5,"ask_sz":100,"bid_ct":1,"ask_ct":1},{"bid_px":"129.050000000","ask_px":"140.880000000","bid_sz":500,"ask_sz":1000,"bid_ct":1,"ask_ct":2},{"bid_px":"129.000000000","ask_px":"143.000000000","bid_sz":12,"ask_sz":1,"bid_ct":2,"ask_ct":1},{"bid_px":"128.470000000","ask_px":"143.690000000","bid_sz":500,"ask_sz":500,"bid_ct":1,"ask_ct":1}],"symbol":"NVDA"}
{"ts_recv":"2024-11-01T08:00:06.093022196Z","hd":{"ts_event":"2024-11-01T08:00:06.092855744Z","rtype":10,"publisher_id":2,"instrument_id":16244},"action":"A","side":"A","depth":8,"price":"273.000000000","size":1,"flags":130,"ts_in_delta":166452,"sequence":299399,"levels":[{"bid_px":"249.830000000","ask_px":"250.680000000","bid_sz":50,"ask_sz":100,"bid_ct":1,"ask_ct":1},{"bid_px":"249.800000000","ask_px":"250.750000000","bid_sz":199,"ask_sz":50,"bid_ct":1,"ask_ct":1},{"bid_px":"249.770000000","ask_px":"252.100000000","bid_sz":50,"ask_sz":1000,"bid_ct":1,"ask_ct":1},{"bid_px":"249.600000000","ask_px":"253.650000000","bid_sz":1000,"ask_sz":400,"bid_ct":1,"ask_ct":1},{"bid_px":"249.300000000","ask_px":"260.000000000","bid_sz":1000,"ask_sz":48,"bid_ct":1,"ask_ct":1},{"bid_px":"247.150000000","ask_px":"264.940000000","bid_sz":400,"ask_sz":7,"bid_ct":1,"ask_ct":1},{"bid_px":"235.000000000","ask_px":"265.000000000","bid_sz":130,"ask_sz":1,"bid_ct":2,"ask_ct":1},{"bid_px":"230.000000000","ask_px":"267.800000000","bid_sz":12,"ask_sz":30,"bid_ct":1,"ask_ct":1},{"bid_px":"225.000000000","ask_px":"273.000000000","bid_sz":8,"ask_sz":1,"bid_ct":1,"ask_ct":1},{"bid_px":"220.000000000","ask_px":"275.000000000","bid_sz":60,"ask_sz":16,"bid_ct":4,"ask_ct":2}],"symbol":"TSLA"}
{"ts_recv":"2024-11-01T08:00:06.125927429Z","hd":{"ts_event":"2024-11-01T08:00:06.125761515Z","rtype":10,"publisher_id":2,"instrument_id":38},"action":"C","side":"A","depth":0,"price":"224.200000000","size":1000,"flags":130,"ts_in_delta":165914,"sequence":299553,"levels":[{"bid_px":"221.200000000","ask_px":"225.100000000","bid_sz":1000,"ask_sz":2000,"bid_ct":1,"ask_ct":1},{"bid_px":"220.000000000","ask_px":"225.490000000","bid_sz":2,"ask_sz":442,"bid_ct":1,"ask_ct":1},{"bid_px":"219.690000000","ask_px":"234.000000000","bid_sz":442,"ask_sz":20,"bid_ct":1,"ask_ct":1},{"bid_px":"217.000000000","ask_px":"240.000000000","bid_sz":1525,"ask_sz":150,"bid_ct":1,"ask_ct":1},{"bid_px":"190.000000000","ask_px":null,"bid_sz":1,"ask_sz":0,"bid_ct":1,"ask_ct":0},{"bid_px":"180.000000000","ask_px":null,"bid_sz":1,"ask_sz":0,"bid_ct":1,"ask_ct":0},{"bid_px":"100.000000000","ask_px":null,"bid_sz":1,"ask_sz":0,"bid_ct":1,"ask_ct":0},{"bid_px":null,"ask_px":null,"bid_sz":0,"ask_sz":0,"bid_ct":0,"ask_ct":0},{"bid_px":null,"ask_px":null,"bid_sz":0,"ask_sz":0,"bid_ct":0,"ask_ct":0},{"bid_px":null,"ask_px":null,"bid_sz":0,"ask_sz":0,"bid_ct":0,"ask_ct":0}],"symbol":"AAPL"}
{"ts_recv":"2024-11-01T08:00:06.136524667Z","hd":{"ts_event":"2024-11-01T08:00:06.136358459Z","rtype":10,"publisher_id":2,"instrument_id":38},"action":"A","side":"A","depth":0,"price":"224.300000000","size":1000,"flags":130,"ts_in_delta":166208,"sequence":299579,"levels":[{"bid_px":"221.200000000","ask_px":"224.300000000","bid_sz":1000,"ask_sz":1000,"bid_ct":1,"ask_ct":1},{"bid_px":"220.000000000","ask_px":"225.100000000","bid_sz":2,"ask_sz":2000,"bid_ct":1,"ask_ct":1},{"bid_px":"219.690000000","ask_px":"225.490000000","bid_sz":442,"ask_sz":442,"bid_ct":1,"ask_ct":1},{"bid_px":"217.000000000","ask_px":"234.000000000","bid_sz":1525,"ask_sz":20,"bid_ct":1,"ask_ct":1},{"bid_px":"190.000000000","ask_px":"240.000000000","bid_sz":1,"ask_sz":150,"bid_ct":1,"ask_ct":1},{"bid_px":"180.000000000","ask_px":null,"bid_sz":1,"ask_sz":0,"bid_ct":1,"ask_ct":0},{"bid_px":"100.000000000","ask_px":null,"bid_sz":1,"ask_sz":0,"bid_ct":1,"ask_ct":0},{"bid_px":null,"ask_px":null,"bid_sz":0,"ask_sz":0,"bid_ct":0,"ask_ct":0},{"bid_px":null,"ask_px":null,"bid_sz":0,"ask_sz":0,"bid_ct":0,"ask_ct":0},{"bid_px":null,"ask_px":null,"bid_sz":0,"ask_sz":0,"bid_ct":0,"ask_ct":0}],"symbol":"AAPL"}
{"ts_recv":"2024-11-01T08:00:06.174485927Z","hd":{"ts_event":"2024-11-01T08:00:06.174319610Z","rtype":10,"publisher_id":2,"instrument_id":16244},"action":"A","side":"B","depth":0,"price":"249.830000000","size":50,"flags":130,"ts_in_delta":166317,"sequence":299662,"levels":[{"bid_px":"249.830000000","ask_px":"250.680000000","bid_sz":100,"ask_sz":100,"bid_ct":2,"ask_ct":1},{"bid_px":"249.800000000","ask_px":"250.750000000","bid_sz":199,"ask_sz":50,"bid_ct":1,"ask_ct":1},{"bid_px":"249.770000000","ask_px":"252.100000000","bid_sz":50,"ask_sz":1000,"bid_ct":1,"ask_ct":1},{"bid_px":"249.600000000","ask_px":"253.650000000","bid_sz":1000,"ask_sz":400,"bid_ct":1,"ask_ct":1},{"bid_px":"249.300000000","ask_px":"260.000000000","bid_sz":1000,"ask_sz":48,"bid_ct":1,"ask_ct":1},{"bid_px":"247.150000000","ask_px":"264.940000000","bid_sz":400,"ask_sz":7,"bid_ct":1,"ask_ct":1},{"bid_px":"235.000000000","ask_px":"265.000000000","bid_sz":130,"ask_sz":1,"bid_ct":2,"ask_ct":1},{"bid_px":"230.000000000","ask_px":"267.800000000","bid_sz":12,"ask_sz":30,"bid_ct":1,"ask_ct":1},{"bid_px":"225.000000000","ask_px":"273.000000000","bid_sz":8,"ask_sz":1,"bid_ct":1,"ask_ct":1},{"bid_px":"220.000000000","ask_px":"275.000000000","bid_sz":60,"ask_sz":16,"bid_ct":4,"ask_ct":2}],"symbol":"TSLA"}
{"ts_recv":"2024-11-01T08:00:06.178289374Z","hd":{"ts_event":"2024-11-01T08:00:06.178123098Z","rtype":10,"publisher_id":2,"instrument_id":16244},"action":"A","side":"B","depth":4,"price":"249.400000000","size":1000,"flags":130,"ts_in_delta":166276,"sequence":299670,"levels":[{"bid_px":"249.830000000","ask_px":"250.680000000","bid_sz":100,"ask_sz":100,"bid_ct":2,"ask_ct":1},{"bid_px":"249.800000000","ask_px":"250.750000000","bid_sz":199,"ask_sz":50,"bid_ct":1,"ask_ct":1},{"bid_px":"249.770000000","ask_px":"252.100000000","bid_sz":50,"ask_sz":1000,"bid_ct":1,"ask_ct":1},{"bid_px":"249.600000000","ask_px":"253.650000000","bid_sz":1000,"ask_sz":400,"bid_ct":1,"ask_ct":1},{"bid_px":"249.400000000","ask_px":"260.000000000","bid_sz":1000,"ask_sz":48,"bid_ct":1,"ask_ct":1},{"bid_px":"249.300000000","ask_px":"264.940000000","bid_sz":1000,"ask_sz":7,"bid_ct":1,"ask_ct":1},{"bid_px":"247.150000000","ask_px":"265.000000000","bid_sz":400,"ask_sz":1,"bid_ct":1,"ask_ct":1},{"bid_px":"235.000000000","ask_px":"267.800000000","bid_sz":130,"ask_sz":30,"bid_ct":2,"ask_ct":1},{"bid_px":"230.000000000","ask_px":"273.000000000","bid_sz":12,"ask_sz":1,"bid_ct":1,"ask_ct":1},{"bid_px":"225.000000000","ask_px":"275.000000000","bid_sz":8,"ask_sz":16,"bid_ct":1,"ask_ct":2}],"symbol":"TSLA"}
{"ts_recv":"2024-11-01T08:00:06.178316655Z","hd":{"ts_event":"2024-11-01T08:00:06.178150776Z","rtype":10,"publisher_id":2,"instrument_id":16244},"action":"C","side":"B","depth":5,"price":"249.300000000","size":1000,"flags":130,"ts_in_delta":165879,"sequence":299671,"levels":[{"bid_px":"249.830000000","ask_px":"250.680000000","bid_sz":100,"ask_sz":100,"bid_ct":2,"ask_ct":1},{"bid_px":"249.800000000","ask_px":"250.750000000","bid_sz":199,"ask_sz":50,"bid_ct":1,"ask_ct":1},{"bid_px":"249.770000000","ask_px":"252.100000000","bid_sz":50,"ask_sz":1000,"bid_ct":1,"ask_ct":1},{"bid_px":"249.600000000","ask_px":"253.650000000","bid_sz":1000,"ask_sz":400,"bid_ct":1,"ask_ct":1},{"bid_px":"249.400000000","ask_px":"260.000000000","bid_sz":1000,"ask_sz":48,"bid_ct":1,"ask_ct":1},{"bid_px":"247.150000000","ask_px":"264.940000000","bid_sz":400,"ask_sz":7,"bid_ct":1,"ask_ct":1},{"bid_px":"235.000000000","ask_px":"265.000000000","bid_sz":130,"ask_sz":1,"bid_ct":2,"ask_ct":1},{"bid_px":"230.000000000","ask_px":"267.800000000","bid_sz":12,"ask_sz":30,"bid_ct":1,"ask_ct":1},{"bid_px":"225.000000000","ask_px":"273.000000000","bid_sz":8,"ask_sz":1,"bid_ct":1,"ask_ct":1},{"bid_px":"220.000000000","ask_px":"275.000000000","bid_sz":60,"ask_sz":16,"bid_ct":4,"ask_ct":2}],"symbol":"TSLA"}
{"ts_recv":"2024-11-01T08:00:06.187941659Z","hd":{"ts_event":"2024-11-01T08:00:06.187775355Z","rtype":10,"publisher_id":2,"instrument_id":16244},"action":"A","side":"B","depth":6,"price":"245.000000000","size":50,"flags":130,"ts_in_delta":166304,"sequence":299694,"levels":[{"bid_px":"249.830000000","ask_px":"250.680000000","bid_sz":100,"ask_sz":100,"bid_ct":2,"ask_ct":1},{"bid_px":"249.800000000","ask_px":"250.750000000","bid_sz":199,"ask_sz":50,"bid_ct":1,"ask_ct":1},{"bid_px":"249.770000000","ask_px":"252.100000000","bid_sz":50,"ask_sz":1000,"bid_ct":1,"ask_ct":1},{"bid_px":"249.600000000","ask_px":"253.650000000","bid_sz":1000,"ask_sz":400,"bid_ct":1,"ask_ct":1},{"bid_px":"249.400000000","ask_px":"260.000000000","bid_sz":1000,"ask_sz":48,"bid_ct":1,"ask_ct":1},{"bid_px":"247.150000000","ask_px":"264.940000000","bid_sz":400,"ask_sz":7,"bid_ct":1,"ask_ct":1},{"bid_px":"245.000000000","ask_px":"265.000000000","bid_sz":50,"ask_sz":1,"bid_ct":1,"ask_ct":1},{"bid_px":"235.000000000","ask_px":"267.800000000","bid_sz":130,"ask_sz":30,"bid_ct":2,"ask_ct":1},{"bid_px":"230.000000000","ask_px":"273.000000000","bid_sz":12,"ask_sz":1,"bid_ct":1,"ask_ct":1},{"bid_px":"225.000000000","ask_px":"275.000000000","bid_sz":8,"ask_sz":16,"bid_ct":1,"ask_ct":2}],"symbol":"TSLA"}
{"ts_recv":"2024-11-01T08:00:06.188451206Z","hd":{"ts_event":"2024-11-01T08:00:06.188285188Z","rtype":10,"publisher_id":2,"instrument_id":16244},"action":"A","side":"B","depth":5,"price":"247.700000000","size":1000,"flags":130,"ts_in_delta":166018,"sequence":299697,"levels":[{"bid_px":"249.830000000","ask_px":"250.680000000","bid_sz":100,"ask_sz":100,"bid_ct":2,"ask_ct":1},{"bid_px":"249.800000000","ask_px":"250.750000000","bid_sz":199,"ask_sz":50,"bid_ct":1,"ask_ct":1},{"bid_px":"249.770000000","ask_px":"252.100000000","bid_sz":50,"ask_sz":1000,"bid_ct":1,"ask_ct":1},{"bid_px":"249.600000000","ask_px":"253.650000000","bid_sz":1000,"ask_sz":400,"bid_ct":1,"ask_ct":1},{"bid_px":"249.400000000","ask_px":"260.000000000","bid_sz":1000,"ask_sz":48,"bid_ct":1,"ask_ct":1},{"bid_px":"247.700000000","ask_px":"264.940000000","bid_sz":1000,"ask_sz":7,"bid_ct":1,"ask_ct":1},{"bid_px":"247.150000000","ask_px":"265.000000000","bid_sz":400,"ask_sz":1,"bid_ct":1,"ask_ct":1},{"bid_px":"245.000000000","ask_px":"267.800000000","bid_sz":50,"ask_sz":30,"bid_ct":1,"ask_ct":1},{"bid_px":"235.000000000","ask_px":"273.000000000","bid_sz":130,"ask_sz":1,"bid_ct":2,"ask_ct":1},{"bid_px":"230.000000000","ask_px":"275.000000000","bid_sz":12,"ask_sz":16,"bid_ct":1,"ask_ct":2}],"symbol":"TSLA"}
{"ts_recv":"2024-11-01T08:00:06.200506093Z","hd":{"ts_event":"2024-11-01T08:00:06.200339057Z","rtype":10,"publisher_id":2,"instrument_id":16244},"action":"A","side":"A","depth":9,"price":"274.000000000","size":86,"flags":130,"ts_in_delta":167036,"sequence":299723,"levels":[{"bid_px":"249.830000000","ask_px":"250.680000000","bid_sz":100,"ask_sz":100,"bid_ct":2,"ask_ct":1},{"bid_px":"249.800000000","ask_px":"250.750000000","bid_sz":199,"ask_sz":50,"bid_ct":1,"ask_ct":1},{"bid_px":"249.770000000","ask_px":"252.100000000","bid_sz":50,"ask_sz":1000,"bid_ct":1,"ask_ct":1},{"bid_px":"249.600000000","ask_px":"253.650000000","bid_sz":1000,"ask_sz":400,"bid_ct":1,"ask_ct":1},{"bid_px":"249.400000000","ask_px":"260.000000000","bid_sz":1000,"ask_sz":48,"bid_ct":1,"ask_ct":1},{"bid_px":"247.700000000","ask_px":"264.940000000","bid_sz":1000,"ask_sz":7,"bid_ct":1,"ask_ct":1},{"bid_px":"247.150000000","ask_px":"265.000000000","bid_sz":400,"ask_sz":1,"bid_ct":1,"ask_ct":1},{"bid_px":"245.000000000","ask_px":"267.800000000","bid_sz":50,"ask_sz":30,"bid_ct":1,"ask_ct":1},{"bid_px":"235.000000000","ask_px":"273.000000000","bid_sz":130,"ask_sz":1,"bid_ct":2,"ask_ct":1},{"bid_px":"230.000000000","ask_px":"274.000000000","bid_sz":12,"ask_sz":86,"bid_ct":1,"ask_ct":1}],"symbol":"TSLA"}
{"ts_recv":"2024-11-01T08:00:06.222383091Z","hd":{"ts_event":"2024-11-01T08:00:06.222216956Z","rtype":10,"publisher_id":2,"instrument_id":10888},"action":"A","side":"A","depth":2,"price":"448.000000000","size":5,"flags":130,"ts_in_delta":166135,"sequence":299769,"levels":[{"bid_px":"410.000000000","ask_px":"415.070000000","bid_sz":1,"ask_sz":246,"bid_ct":1,"ask_ct":1},{"bid_px":"408.960000000","ask_px":"420.000000000","bid_sz":5,"ask_sz":3,"bid_ct":1,"ask_ct":1},{"bid_px":"406.000000000","ask_px":"448.000000000","bid_sz":7,"ask_sz":5,"bid_ct":1,"ask_ct":1},{"bid_px":"404.410000000","ask_px":"468.000000000","bid_sz":246,"ask_sz":65,"bid_ct":1,"ask_ct":1},{"bid_px":"398.000000000","ask_px":null,"bid_sz":5,"ask_sz":0,"bid_ct":1,"ask_ct":0},{"bid_px":null,"ask_px":null,"bid_sz":0,"ask_sz":0,"bid_ct":0,"ask_ct":0},{"bid_px":null,"ask_px":null,"bid_sz":0,"ask_sz":0,"bid_ct":0,"ask_ct":0},{"bid_px":null,"ask_px":null,"bid_sz":0,"ask_sz":0,"bid_ct":0,"ask_ct":0},{"bid_px":null,"ask_px":null,"bid_sz":0,"ask_sz":0,"bid_ct":0,"ask_ct":0},{"bid_px":null,"ask_px":null,"bid_sz":0,"ask_sz":0,"bid_ct":0,"ask_ct":0}],"symbol":"MSFT"}
{"ts_recv":"2024-11-01T08:00:06.225043027Z","hd":{"ts_event":"2024-11-01T08:00:06.224877387Z","rtype":10,"publisher_id":2,"instrument_id":16244},"action":"C","side":"B","depth":0,"price":"249.830000000","size":50,"flags":130,"ts_in_delta":165640,"sequence":299780,"levels":[{"bid_px":"249.830000000","ask_px":"250.680000000","bid_sz":50,"ask_sz":100,"bid_ct":1,"ask_ct":1},{"bid_px":"249.800000000","ask_px":"250.750000000","bid_sz":199,"ask_sz":50,"bid_ct":1,"ask_ct":1},{"bid_px":"249.770000000","ask_px":"252.100000000","bid_sz":50,"ask_sz":1000,"bid_ct":1,"ask_ct":1},{"bid_px":"249.600000000","ask_px":"253.650000000","bid_sz":1000,"ask_sz":400,"bid_ct":1,"ask_ct":1},{"bid_px":"249.400000000","ask_px":"260.000000000","bid_sz":1000,"ask_sz":48,"bid_ct":1,"ask_ct":1},{"bid_px":"247.700000000","ask_px":"264.940000000","bid_sz":1000,"ask_sz":7,"bid_ct":1,"ask_ct":1},{"bid_px":"247.150000000","ask_px":"265.000000000","bid_sz":400,"ask_sz":1,"bid_ct":1,"ask_ct":1},{"bid_px":"245.000000000","ask_px":"267.800000000","bid_sz":50,"ask_sz":30,"bid_ct":1,"ask_ct":1},{"bid_px":"235.000000000","ask_px":"273.000000000","bid_sz":130,"ask_sz":1,"bid_ct":2,"ask_ct":1},{"bid_px":"230.000000000","ask_px":"274.000000000","bid_sz":12,"ask_sz":86,"bid_ct":1,"ask_ct":1}],"symbol":"TSLA"}
{"ts_recv":"2024-11-01T08:00:06.225057101Z","hd":{"ts_event":"2024-11-01T08:00:06.224890172Z","rtype":10,"publisher_id":2,"instrument_id":16244},"action":"A","side":"B","depth":0,"price":"249.860000000","size":50,"flags":130,"ts_in_delta":166929,"sequence":299781,"levels":[{"bid_px":"249.860000000","ask_px":"250.680000000","bid_sz":50,"ask_sz":100,"bid_ct":1,"ask_ct":1},{"bid_px":"249.800000000","ask_px":"250.750000000","bid_sz":199,"ask_sz":50,"bid_ct":1,"ask_ct":1},{"bid_px":"249.770000000","ask_px":"252.100000000","bid_sz":50,"ask_sz":1000,"bid_ct":1,"ask_ct":1},{"bid_px":"249.600000000","ask_px":"253.650000000","bid_sz":1000,"ask_sz":400,"bid_ct":1,"ask_ct":1},{"bid_px":"249.400000000","ask_px":"260.000000000","bid_sz":1000,"ask_sz":48,"bid_ct":1,"ask_ct":1},{"bid_px":"247.700000000","ask_px":"264.940000000","bid_sz":1000,"ask_sz":7,"bid_ct":1,"ask_ct":1},{"bid_px":"247.150000000","ask_px":"265.000000000","bid_sz":400,"ask_sz":1,"bid_ct":1,"ask_ct":1},{"bid_px":"245.000000000","ask_px":"267.800000000","bid_sz":50,"ask_sz":30,"bid_ct":1,"ask_ct":1},{"bid_px":"235.000000000","ask_px":"273.000000000","bid_sz":130,"ask_sz":1,"bid_ct":2,"ask_ct":1},{"bid_px":"230.000000000","ask_px":"274.000000000","bid_sz":12,"ask_sz":86,"bid_ct":1,"ask_ct":1}],"symbol":"TSLA"}
{"ts_recv":"2024-11-01T08:00:06.226385793Z","hd":{"ts_event":"2024-11-01T08:00:06.226219652Z","rtype":10,"publisher_id":2,"instrument_id":16244},"action":"A","side":"B","depth":4,"price":"249.500000000","size":1000,"flags":130,"ts_in_delta":166141,"sequence":299788,"levels":[{"bid_px":"249.860000000","ask_px":"250.680000000","bid_sz":50,"ask_sz":100,"bid_ct":1,"ask_ct":1},{"bid_px":"249.800000000","ask_px":"250.750000000","bid_sz":199,"ask_sz":50,"bid_ct":1,"ask_ct":1},{"bid_px":"249.770000000","ask_px":"252.100000000","bid_sz":50,"ask_sz":1000,"bid_ct":1,"ask_ct":1},{"bid_px":"249.600000000","ask_px":"253.650000000","bid_sz":1000,"ask_sz":400,"bid_ct":1,"ask_ct":1},{"bid_px":"249.500000000","ask_px":"260.000000000","bid_sz":1000,"ask_sz":48,"bid_ct":1,"ask_ct":1},{"bid_px":"249.400000000","ask_px":"264.940000000","bid_sz":1000,"ask_sz":7,"bid_ct":1,"ask_ct":1},{"bid_px":"247.700000000","ask_px":"265.000000000","bid_sz":1000,"ask_sz":1,"bid_ct":1,"ask_ct":1},{"bid_px":"247.150000000","ask_px":"267.800000000","bid_sz":400,"ask_sz":30,"bid_ct":1,"ask_ct":1},{"bid_px":"245.000000000","ask_px":"273.000000000","bid_sz":50,"ask_sz":1,"bid_ct":1,"ask_ct":1},{"bid_px":"235.000000000","ask_px":"274.000000000","bid_sz":130,"ask_sz":86,"bid_ct":2,"ask_ct":1}],"symbol":"TSLA"}
{"ts_recv":"2024-11-01T08:00:06.262383478Z","hd":{"ts_event":"2024-11-01T08:00:06.262217063Z","rtype":10,"publisher_id":2,"instrument_id":10888},"action":"A","side":"B","depth":5,"price":"385.000000000","size":50,"flags":130,"ts_in_delta":166415,"sequence":299864,"levels":[{"bid_px":"410.000000000","ask_px":"415.070000000","bid_sz":1,"ask_sz":246,"bid_ct":1,"ask_ct":1},{"bid_px":"408.960000000","ask_px":"420.000000000","bid_sz":5,"ask_sz":3,"bid_ct":1,"ask_ct":1},{"bid_px":"406.000000000","ask_px":"448.000000000","bid_sz":7,"ask_sz":5,"bid_ct":1,"ask_ct":1},{"bid_px":"404.410000000","ask_px":"468.000000000","bid_sz":246,"ask_sz":65,"bid_ct":1,"ask_ct":1},{"bid_px":"398.000000000","ask_px":null,"bid_sz":5,"ask_sz":0,"bid_ct":1,"ask_ct":0},{"bid_px":"385.000000000","ask_px":null,"bid_sz":50,"ask_sz":0,"bid_ct":1,"ask_ct":0},{"bid_px":null,"ask_px":null,"bid_sz":0,"ask_sz":0,"bid_ct":0,"ask_ct":0},{"bid_px":null,"ask_px":null,"bid_sz":0,"ask_sz":0,"bid_ct":0,"ask_ct":0},{"bid_px":null,"ask_px":null,"bid_sz":0,"ask_sz":0,"bid_ct":0,"ask_ct":0},{"bid_px":null,"ask_px":null,"bid_sz":0,"ask_sz":0,"bid_ct":0,"ask_ct":0}],"symbol":"MSFT"}
{"ts_recv":"2024-11-01T08:00:06.262976803Z","hd":{"ts_event":"2024-11-01T08:00:06.262810319Z","rtype":10,"publisher_id":2,"instrument_id":10888},"action":"A","side":"B","depth":2,"price":"406.350000000","size":2,"flags":130,"ts_in_delta":166484,"sequence":299874,"levels":[{"bid_px":"410.000000000","ask_px":"415.070000000","bid_sz":1,"ask_sz":246,"bid_ct":1,"ask_ct":1},{"bid_px":"408.960000000","ask_px":"420.000000000","bid_sz":5,"ask_sz":3,"bid_ct":1,"ask_ct":1},{"bid_px":"406.350000000","ask_px":"448.000000000","bid_sz":2,"ask_sz":5,"bid_ct":1,"ask_ct":1},{"bid_px":"406.000000000","ask_px":"468.000000000","bid_sz":7,"ask_sz":65,"bid_ct":1,"ask_ct":1},{"bid_px":"404.410000000","ask_px":null,"bid_sz":246,"ask_sz":0,"bid_ct":1,"ask_ct":0},{"bid_px":"398.000000000","ask_px":null,"bid_sz":5,"ask_sz":0,"bid_ct":1,"ask_ct":0},{"bid_px":"385.000000000","ask_px":null,"bid_sz":50,"ask_sz":0,"bid_ct":1,"ask_ct":0},{"bid_px":null,"ask_px":null,"bid_sz":0,"ask_sz":0,"bid_ct":0,"ask_ct":0},{"bid_px":null,"ask_px":null,"bid_sz":0,"ask_sz":0,"bid_ct":0,"ask_ct":0},{"bid_px":null,"ask_px":null,"bid_sz":0,"ask_sz":0,"bid_ct":0,"ask_ct":0}],"symbol":"MSFT"}
{"ts_recv":"2024-11-01T08:00:06.284148577Z","hd":{"ts_event":"2024-11-01T08:00:06.283982285Z","rtype":10,"publisher_id":2,"instrument_id":16244},"action":"A","side":"B","depth":0,"price":"249.880000000","size":50,"flags":130,"ts_in_delta":166292,"sequence":299988,"levels":[{"bid_px":"249.880000000","ask_px":"250.680000000","bid_sz":50,"ask_sz":100,"bid_ct":1,"ask_ct":1},{"bid_px":"249.800000000","ask_px":"250.750000000","bid_sz":199,"ask_sz":50,"bid_ct":1,"ask_ct":1},{"bid_px":"249.770000000","ask_px":"252.100000000","bid_sz":50,"ask_sz":1000,"bid_ct":1,"ask_ct":1},{"bid_px":"249.600000000","ask_px":"253.650000000","bid_sz":1000,"ask_sz":400,"bid_ct":1,"ask_ct":1},{"bid_px":"249.500000000","ask_px":"260.000000000","bid_sz":1000,"ask_sz":48,"bid_ct":1,"ask_ct":1},{"bid_px":"249.400000000","ask_px":"264.940000000","bid_sz":1000,"ask_sz":7,"bid_ct":1,"ask_ct":1},{"bid_px":"247.700000000","ask_px":"265.000000000","bid_sz":1000,"ask_sz":1,"bid_ct":1,"ask_ct":1},{"bid_px":"247.150000000","ask_px":"267.800000000","bid_sz":400,"ask_sz":30,"bid_ct":1,"ask_ct":1},{"bid_px":"245.000000000","ask_px":"273.000000000","bid_sz":50,"ask_sz":1,"bid_ct":1,"ask_ct":1},{"bid_px":"235.000000000","ask_px":"274.000000000","bid_sz":130,"ask_sz":86,"bid_ct":2,"ask_ct":1}],"symbol":"TSLA"}
{"ts_recv":"2024-11-01T08:00:06.336020477Z","hd":{"ts_event":"2024-11-01T08:00:06.335854165Z","rtype":10,"publisher_id":2,"instrument_id":10888},"action":"A","side":"B","depth":7,"price":"380.000000000","size":10,"flags":130,"ts_in_delta":166312,"sequence":300045,"levels":[{"bid_px":"410.000000000","ask_px":"415.070000000","bid_sz":1,"ask_sz":246,"bid_ct":1,"ask_ct":1},{"bid_px":"408.960000000","ask_px":"420.000000000","bid_sz":5,"ask_sz":3,"bid_ct":1,"ask_ct":1},{"bid_px":"406.350000000","ask_px":"448.000000000","bid_sz":2,"ask_sz":5,"bid_ct":1,"ask_ct":1},{"bid_px":"406.000000000","ask_px":"468.000000000","bid_sz":7,"ask_sz":65,"bid_ct":1,"ask_ct":1},{"bid_px":"404.410000000","ask_px":null,"bid_sz":246,"ask_sz":0,"bid_ct":1,"ask_ct":0},{"bid_px":"398.000000000","ask_px":null,"bid_sz":5,"ask_sz":0,"bid_ct":1,"ask_ct":0},{"bid_px":"385.000000000","ask_px":null,"bid_sz":50,"ask_sz":0,"bid_ct":1,"ask_ct":0},{"bid_px":"380.000000000","ask_px":null,"bid_sz":10,"ask_sz":0,"bid_ct":1,"ask_ct":0},{"bid_px":null,"ask_px":null,"bid_sz":0,"ask_sz":0,"bid_ct":0,"ask_ct":0},{"bid_px":null,"ask_px":null,"bid_sz":0,"ask_sz":0,"bid_ct":0,"ask_ct":0}],"symbol":"MSFT"}
{"ts_recv":"2024-11-01T08:00:06.356470084Z","hd":{"ts_event":"2024-11-01T08:00:06.356303814Z","rtype":10,"publisher_id":2,"instrument_id":16244},"action":"A","side":"A","depth":8,"price":"270.000000000","size":3,"flags":130,"ts_in_delta":166270,"sequence":300060,"levels":[{"bid_px":"249.880000000","ask_px":"250.680000000","bid_sz":50,"ask_sz":100,"bid_ct":1,"ask_ct":1},{"bid_px":"249.800000000","ask_px":"250.750000000","bid_sz":199,"ask_sz":50,"bid_ct":1,"ask_ct":1},{"bid_px":"249.770000000","ask_px":"252.100000000","bid_sz":50,"ask_sz":1000,"bid_ct":1,"ask_ct":1},{"bid_px":"249.600000000","ask_px":"253.650000000","bid_sz":1000,"ask_sz":400,"bid_ct":1,"ask_ct":1},{"bid_px":"249.500000000","ask_px":"260.000000000","bid_sz":1000,"ask_sz":48,"bid_ct":1,"ask_ct":1},{"bid_px":"249.400000000","ask_px":"264.940000000","bid_sz":1000,"ask_sz":7,"bid_ct":1,"ask_ct":1},{"bid_px":"247.700000000","ask_px":"265.000000000","bid_sz":1000,"ask_sz":1,"bid_ct":1,"ask_ct":1},{"bid_px":"247.150000000","ask_px":"267.800000000","bid_sz":400,"ask_sz":30,"bid_ct":1,"ask_ct":1},{"bid_px":"245.000000000","ask_px":"270.000000000","bid_sz":50,"ask_sz":3,"bid_ct":1,"ask_ct":1},{"bid_px":"235.000000000","ask_px":"273.000000000","bid_sz":130,"ask_sz":1,"bid_ct":2,"ask_ct":1}],"symbol":"TSLA"}
{"ts_recv":"2024-11-01T08:00:06.357258648Z","hd":{"ts_event":"2024-11-01T08:00:06.357092454Z","rtype":10,"publisher_id":2,"instrument_id":11667},"action":"A","side":"B","depth":3,"price":"134.200000000","size":3,"flags":130,"ts_in_delta":166194,"sequence":300061,"levels":[{"bid_px":"134.440000000","ask_px":"135.000000000","bid_sz":100,"ask_sz":8,"bid_ct":1,"ask_ct":1},{"bid_px":"134.410000000","ask_px":"135.230000000","bid_sz":61,"ask_sz":360,"bid_ct":2,"ask_ct":1},{"bid_px":"134.210000000","ask_px":"135.300000000","bid_sz":20,"ask_sz":1000,"bid_ct":1,"ask_ct":1},{"bid_px":"134.200000000","ask_px":"136.100000000","bid_sz":3,"ask_sz":1000,"bid_ct":1,"ask_ct":1},{"bid_px":"133.100000000","ask_px":"137.680000000","bid_sz":1000,"ask_sz":500,"bid_ct":1,"ask_ct":1},{"bid_px":"132.000000000","ask_px":"138.870000000","bid_sz":72,"ask_sz":1000,"bid_ct":3,"ask_ct":2},{"bid_px":"130.520000000","ask_px":"140.740000000","bid_sz":4,"ask_sz":100,"bid_ct":1,"ask_ct":1},{"bid_px":"130.000000000","ask_px":"140.880000000","bid_sz":5,"ask_sz":1000,"bid_ct":1,"ask_ct":2},{"bid_px":"129.050000000","ask_px":"143.000000000","bid_sz":500,"ask_sz":1,"bid_ct":1,"ask_ct":1},{"bid_px":"129.000000000","ask_px":"143.690000000","bid_sz":12,"ask_sz":500,"bid_ct":2,"ask_ct":1}],"symbol":"NVDA"}
{"ts_recv":"2024-11-01T08:00:06.359584924Z","hd":{"ts_event":"2024-11-01T08:00:06.359418598Z","rtype":10,"publisher_id":2,"instrument_id":16244},"action":"A","side":"B","depth":0,"price":"249.880000000","size":50,"flags":130,"ts_in_delta":166326,"sequence":300069,"levels":[{"bid_px":"249.880000000","ask_px":"250.680000000","bid_sz":100,"ask_sz":100,"bid_ct":2,"ask_ct":1},{"bid_px":"249.800000000","ask_px":"250.750000000","bid_sz":199,"ask_sz":50,"bid_ct":1,"ask_ct":1},{"bid_px":"249.770000000","ask_px":"252.100000000","bid_sz":50,"ask_sz":1000,"bid_ct":1,"ask_ct":1},{"bid_px":"249.600000000","ask_px":"253.650000000","bid_sz":1000,"ask_sz":400,"bid_ct":1,"ask_ct":1},{"bid_px":"249.500000000","ask_px":"260.000000000","bid_sz":1000,"ask_sz":48,"bid_ct":1,"ask_ct":1},{"bid_px":"249.400000000","ask_px":"264.940000000","bid_sz":1000,"ask_sz":7,"bid_ct":1,"ask_ct":1},{"bid_px":"247.700000000","ask_px":"265.000000000","bid_sz":1000,"ask_sz":1,"bid_ct":1,"ask_ct":1},{"bid_px":"247.150000000","ask_px":"267.800000000","bid_sz":400,"ask_sz":30,"bid_ct":1,"ask_ct":1},{"bid_px":"245.000000000","ask_px":"270.000000000","bid_sz":50,"ask_sz":3,"bid_ct":1,"ask_ct":1},{"bid_px":"235.000000000","ask_px":"273.000000000","bid_sz":130,"ask_sz":1,"bid_ct":2,"ask_ct":1}],"symbol":"TSLA"}
{"ts_recv":"2024-11-01T08:00:06.414302465Z","hd":{"ts_event":"2024-11-01T08:00:06.414136263Z","rtype":10,"publisher_id":2,"instrument_id":10888},"action":"A","side":"B","depth":6,"price":"387.000000000","size":25,"flags":130,"ts_in_delta":166202,"sequence":300131,"levels":[{"bid_px":"410.000000000","ask_px":"415.070000000","bid_sz":1,"ask_sz":246,"bid_ct":1,"ask_ct":1},{"bid_px":"408.960000000","ask_px":"420.000000000","bid_sz":5,"ask_sz":3,"bid_ct":1,"ask_ct":1},{"bid_px":"406.350000000","ask_px":"448.000000000","bid_sz":2,"ask_sz":5,"bid_ct":1,"ask_ct":1},{"bid_px":"406.000000000","ask_px":"468.000000000","bid_sz":7,"ask_sz":65,"bid_ct":1,"ask_ct":1},{"bid_px":"404.410000000","ask_px":null,"bid_sz":246,"ask_sz":0,"bid_ct":1,"ask_ct":0},{"bid_px":"398.000000000","ask_px":null,"bid_sz":5,"ask_sz":0,"bid_ct":1,"ask_ct":0},{"bid_px":"387.000000000","ask_px":null,"bid_sz":25,"ask_sz":0,"bid_ct":1,"ask_ct":0},{"bid_px":"385.000000000","ask_px":null,"bid_sz":50,"ask_sz":0,"bid_ct":1,"ask_ct":0},{"bid_px":"380.000000000","ask_px":null,"bid_sz":10,"ask_sz":0,"bid_ct":1,"ask_ct":0},{"bid_px":null,"ask_px":null,"bid_sz":0,"ask_sz":0,"bid_ct":0,"ask_ct":0}],"symbol":"MSFT"}
{"ts_recv":"2024-11-01T08:00:06.429906713Z","hd":{"ts_event":"2024-11-01T08:00:06.429740329Z","rtype":10,"publisher_id":2,"instrument_id":10888},"action":"A","side":"B","depth":5,"price":"398.900000000","size":3,"flags":130,"ts_in_delta":166384,"sequence":300137,"levels":[{"bid_px":"410.000000000","ask_px":"415.070000000","bid_sz":1,"ask_sz":246,"bid_ct":1,"ask_ct":1},{"bid_px":"408.960000000","ask_px":"420.000000000","bid_sz":5,"ask_sz":3,"bid_ct":1,"ask_ct":1},{"bid_px":"406.350000000","ask_px":"448.000000000","bid_sz":2,"ask_sz":5,"bid_ct":1,"ask_ct":1},{"bid_px":"406.000000000","ask_px":"468.000000000","bid_sz":7,"ask_sz":65,"bid_ct":1,"ask_ct":1},{"bid_px":"404.410000000","ask_px":null,"bid_sz":246,"ask_sz":0,"bid_ct":1,"ask_ct":0},{"bid_px":"398.900000000","ask_px":null,"bid_sz":3,"ask_sz":0,"bid_ct":1,"ask_ct":0},{"bid_px":"398.000000000","ask_px":null,"bid_sz":5,"ask_sz":0,"bid_ct":1,"ask_ct":0},{"bid_px":"387.000000000","ask_px":null,"bid_sz":25,"ask_sz":0,"bid_ct":1,"ask_ct":0},{"bid_px":"385.000000000","ask_px":null,"bid_sz":50,"ask_sz":0,"bid_ct":1,"ask_ct":0},{"bid_px":"380.000000000","ask_px":null,"bid_sz":10,"ask_sz":0,"bid_ct":1,"ask_ct":0}],"symbol":"MSFT"}
{"ts_recv":"2024-11-01T08:00:06.487922637Z","hd":{"ts_event":"2024-11-01T08:00:06.487756506Z","rtype":10,"publisher_id":2,"instrument_id":11667},"action":"C","side":"B","depth":4,"price":"133.100000000","size":1000,"flags":130,"ts_in_delta":166131,"sequence":300204,"levels":[{"bid_px":"134.440000000","ask_px":"135.000000000","bid_sz":100,"ask_sz":8,"bid_ct":1,"ask_ct":1},{"bid_px":"134.410000000","ask_px":"135.230000000","bid_sz":61,"ask_sz":360,"bid_ct":2,"ask_ct":1},{"bid_px":"134.210000000","ask_px":"135.300000000","bid_sz":20,"ask_sz":1000,"bid_ct":1,"ask_ct":1},{"bid_px":"134.200000000","ask_px":"136.100000000","bid_sz":3,"ask_sz":1000,"bid_ct":1,"ask_ct":1},{"bid_px":"132.000000000","ask_px":"137.680000000","bid_sz":72,"ask_sz":500,"bid_ct":3,"ask_ct":1},{"bid_px":"130.520000000","ask_px":"138.870000000","bid_sz":4,"ask_sz":1000,"bid_ct":1,"ask_ct":2},{"bid_px":"130.000000000","ask_px":"140.740000000","bid_sz":5,"ask_sz":100,"bid_ct":1,"ask_ct":1},{"bid_px":"129.050000000","ask_px":"140.880000000","bid_sz":500,"ask_sz":1000,"bid_ct":1,"ask_ct":2},{"bid_px":"129.000000000","ask_px":"143.000000000","bid_sz":12,"ask_sz":1,"bid_ct":2,"ask_ct":1},{"bid_px":"128.470000000","ask_px":"143.690000000","bid_sz":500,"ask_sz":500,"bid_ct":1,"ask_ct":1}],"symbol":"NVDA"}
{"ts_recv":"2024-11-01T08:00:06.489155999Z","hd":{"ts_event":"2024-11-01T08:00:06.488990261Z","rtype":10,"publisher_id":2,"instrument_id":38},"action":"C","side":"A","depth":1,"price":"225.100000000","size":1000,"flags":130,"ts_in_delta":165738,"sequence":300206,"levels":[{"bid_px":"221.200000000","ask_px":"224.300000000","bid_sz":1000,"ask_sz":1000,"bid_ct":1,"ask_ct":1},{"bid_px":"220.000000000","ask_px":"225.100000000","bid_sz":2,"ask_sz":1000,"bid_ct":1,"ask_ct":1},{"bid_px":"219.690000000","ask_px":"225.490000000","bid_sz":442,"ask_sz":442,"bid_ct":1,"ask_ct":1},{"bid_px":"217.000000000","ask_px":"234.000000000","bid_sz":1525,"ask_sz":20,"bid_ct":1,"ask_ct":1},{"bid_px":"190.000000000","ask_px":"240.000000000","bid_sz":1,"ask_sz":150,"bid_ct":1,"ask_ct":1},{"bid_px":"180.000000000","ask_px":null,"bid_sz":1,"ask_sz":0,"bid_ct":1,"ask_ct":0},{"bid_px":"100.000000000","ask_px":null,"bid_sz":1,"ask_sz":0,"bid_ct":1,"ask_ct":0},{"bid_px":null,"ask_px":null,"bid_sz":0,"ask_sz":0,"bid_ct":0,"ask_ct":0},{"bid_px":null,"ask_px":null,"bid_sz":0,"ask_sz":0,"bid_ct":0,"ask_ct":0},{"bid_px":null,"ask_px":null,"bid_sz":0,"ask_sz":0,"bid_ct":0,"ask_ct":0}],"symbol":"AAPL"}
{"ts_recv":"2024-11-01T08:00:06.489167808Z","hd":{"ts_event":"2024-11-01T08:00:06.489001059Z","rtype":10,"publisher_id":2,"instrument_id":38},"action":"C","side":"A","depth":0,"price":"224.300000000","size":1000,"flags":130,"ts_in_delta":166749,"sequence":300207,"levels":[{"bid_px":"221.200000000","ask_px":"225.100000000","bid_sz":1000,"ask_sz":1000,"bid_ct":1,"ask_ct":1},{"bid_px":"220.000000000","ask_px":"225.490000000","bid_sz":2,"ask_sz":442,"bid_ct":1,"ask_ct":1},{"bid_px":"219.690000000","ask_px":"234.000000000","bid_sz":442,"ask_sz":20,"bid_ct":1,"ask_ct":1},{"bid_px":"217.000000000","ask_px":"240.000000000","bid_sz":1525,"ask_sz":150,"bid_ct":1,"ask_ct":1},{"bid_px":"190.000000000","ask_px":null,"bid_sz":1,"ask_sz":0,"bid_ct":1,"ask_ct":0},{"bid_px":"180.000000000","ask_px":null,"bid_sz":1,"ask_sz":0,"bid_ct":1,"ask_ct":0},{"bid_px":"100.000000000","ask_px":null,"bid_sz":1,"ask_sz":0,"bid_ct":1,"ask_ct":0},{"bid_px":null,"ask_px":null,"bid_sz":0,"ask_sz":0,"bid_ct":0,"ask_ct":0},{"bid_px":null,"ask_px":null,"bid_sz":0,"ask_sz":0,"bid_ct":0,"ask_ct":0},{"bid_px":null,"ask_px":null,"bid_sz":0,"ask_sz":0,"bid_ct":0,"ask_ct":0}],"symbol":"AAPL"}
{"ts_recv":"2024-11-01T08:00:06.499343249Z","hd":{"ts_event":"2024-11-01T08:00:06.499177058Z","rtype":10,"publisher_id":2,"instrument_id":38},"action":"A","side":"A","depth":0,"price":"224.600000000","size":1000,"flags":130,"ts_in_delta":166191,"sequence":300222,"levels":[{"bid_px":"221.200000000","ask_px":"224.600000000","bid_sz":1000,"ask_sz":1000,"bid_ct":1,"ask_ct":1},{"bid_px":"220.000000000","ask_px":"225.100000000","bid_sz":2,"ask_sz":1000,"bid_ct":1,"ask_ct":1},{"bid_px":"219.690000000","ask_px":"225.490000000","bid_sz":442,"ask_sz":442,"bid_ct":1,"ask_ct":1},{"bid_px":"217.000000000","ask_px":"234.000000000","bid_sz":1525,"ask_sz":20,"bid_ct":1,"ask_ct":1},{"bid_px":"190.000000000","ask_px":"240.000000000","bid_sz":1,"ask_sz":150,"bid_ct":1,"ask_ct":1},{"bid_px":"180.000000000","ask_px":null,"bid_sz":1,"ask_sz":0,"bid_ct":1,"ask_ct":0},{"bid_px":"100.000000000","ask_px":null,"bid_sz":1,"ask_sz":0,"bid_ct":1,"ask_ct":0},{"bid_px":null,"ask_px":null,"bid_sz":0,"ask_sz":0,"bid_ct":0,"ask_ct":0},{"bid_px":null,"ask_px":null,"bid_sz":0,"ask_sz":0,"bid_ct":0,"ask_ct":0},{"bid_px":null,"ask_px":null,"bid_sz":0,"ask_sz":0,"bid_ct":0,"ask_ct":0}],"symbol":"AAPL"}
{"ts_recv":"2024-11-01T08:00:06.499393805Z","hd":{"ts_event":"2024-11-01T08:00:06.499228140Z","rtype":10,"publisher_id":2,"instrument_id":38},"action":"C","side":"A","depth":1,"price":"225.100000000","size":1000,"flags":130,"ts_in_delta":165665,"sequence":300223,"levels":[{"bid_px":"221.200000000","ask_px":"224.600000000","bid_sz":1000,"ask_sz":1000,"bid_ct":1,"ask_ct":1},{"bid_px":"220.000000000","ask_px":"225.490000000","bid_sz":2,"ask_sz":442,"bid_ct":1,"ask_ct":1},{"bid_px":"219.690000000","ask_px":"234.000000000","bid_sz":442,"ask_sz":20,"bid_ct":1,"ask_ct":1},{"bid_px":"217.000000000","ask_px":"240.000000000","bid_sz":1525,"ask_sz":150,"bid_ct":1,"ask_ct":1},{"bid_px":"190.000000000","ask_px":null,"bid_sz":1,"ask_sz":0,"bid_ct":1,"ask_ct":0},{"bid_px":"180.000000000","ask_px":null,"bid_sz":1,"ask_sz":0,"bid_ct":1,"ask_ct":0},{"bid_px":"100.000000000","ask_px":null,"bid_sz":1,"ask_sz":0,"bid_ct":1,"ask_ct":0},{"bid_px":null,"ask_px":null,"bid_sz":0,"ask_sz":0,"bid_ct":0,"ask_ct":0},{"bid_px":null,"ask_px":null,"bid_sz":0,"ask_sz":0,"bid_ct":0,"ask_ct":0},{"bid_px":null,"ask_px":null,"bid_sz":0,"ask_sz":0,"bid_ct":0,"ask_ct":0}],"symbol":"AAPL"}
{"ts_recv":"2024-11-01T08:00:06.545228230Z","hd":{"ts_event":"2024-11-01T08:00:06.545061771Z","rtype":10,"publisher_id":2,"instrument_id":11667},"action":"A","side":"A","depth":6,"price":"139.420000000","size":1,"flags":130,"ts_in_delta":166459,"sequence":300261,"levels":[{"bid_px":"134.440000000","ask_px":"135.000000000","bid_sz":100,"ask_sz":8,"bid_ct":1,"ask_ct":1},{"bid_px":"134.410000000","ask_px":"135.230000000","bid_sz":61,"ask_sz":360,"bid_ct":2,"ask_ct":1},{"bid_px":"134.210000000","ask_px":"135.300000000","bid_sz":20,"ask_sz":1000,"bid_ct":1,"ask_ct":1},{"bid_px":"134.200000000","ask_px":"136.100000000","bid_sz":3,"ask_sz":1000,"bid_ct":1,"ask_ct":1},{"bid_px":"132.000000000","ask_px":"137.680000000","bid_sz":72,"ask_sz":500,"bid_ct":3,"ask_ct":1},{"bid_px":"130.520000000","ask_px":"138.870000000","bid_sz":4,"ask_sz":1000,"bid_ct":1,"ask_ct":2},{"bid_px":"130.000000000","ask_px":"139.420000000","bid_sz":5,"ask_sz":1,"bid_ct":1,"ask_ct":1},{"bid_px":"129.050000000","ask_px":"140.740000000","bid_sz":500,"ask_sz":100,"bid_ct":1,"ask_ct":1},{"bid_px":"129.000000000","ask_px":"140.880000000","bid_sz":12,"ask_sz":1000,"bid_ct":2,"ask_ct":2},{"bid_px":"128.470000000","ask_px":"143.000000000","bid_sz":500,"ask_sz":1,"bid_ct":1,"ask_ct":1}],"symbol":"NVDA"}
{"ts_recv":"2024-11-01T08:00:06.545347211Z","hd":{"ts_event":"2024-11-01T08:00:06.545181012Z","rtype":10,"publisher_id":2,"instrument_id":11667},"action":"A","side":"A","depth":4,"price":"137.060000000","size":1,"flags":130,"ts_in_delta":166199,"sequence":300263,"levels":[{"bid_px":"134.440000000","ask_px":"135.000000000","bid_sz":100,"ask_sz":8,"bid_ct":1,"ask_ct":1},{"bid_px":"134.410000000","ask_px":"135.230000000","bid_sz":61,"ask_sz":360,"bid_ct":2,"ask_ct":1},{"bid_px":"134.210000000","ask_px":"135.300000000","bid_sz":20,"ask_sz":1000,"bid_ct":1,"ask_ct":1},{"bid_px":"134.200000000","ask_px":"136.100000000","bid_sz":3,"ask_sz":1000,"bid_ct":1,"ask_ct":1},{"bid_px":"132.000000000","ask_px":"137.060000000","bid_sz":72,"ask_sz":1,"bid_ct":3,"ask_ct":1},{"bid_px":"130.520000000","ask_px":"137.680000000","bid_sz":4,"ask_sz":500,"bid_ct":1,"ask_ct":1},{"bid_px":"130.000000000","ask_px":"138.870000000","bid_sz":5,"ask_sz":1000,"bid_ct":1,"ask_ct":2},{"bid_px":"129.050000000","ask_px":"139.420000000","bid_sz":500,"ask_sz":1,"bid_ct":1,"ask_ct":1},{"bid_px":"129.000000000","ask_px":"140.740000000","bid_sz":12,"ask_sz":100,"bid_ct":2,"ask_ct":1},{"bid_px":"128.470000000","ask_px":"140.880000000","bid_sz":500,"ask_sz":1000,"bid_ct":1,"ask_ct":2}],"symbol":"NVDA"}
{"ts_recv":"2024-11-01T08:00:06.545469038Z","hd":{"ts_event":"2024-11-01T08:00:06.545301893Z","rtype":10,"publisher_id":2,"instrument_id":11667},"action":"A","side":"B","depth":4,"price":"133.160000000","size":1,"flags":130,"ts_in_delta":167145,"sequence":300264,"levels":[{"bid_px":"134.440000000","ask_px":"135.000000000","bid_sz":100,"ask_sz":8,"bid_ct":1,"ask_ct":1},{"bid_px":"134.410000000","ask_px":"135.230000000","bid_sz":61,"ask_sz":360,"bid_ct":2,"ask_ct":1},{"bid_px":"134.210000000","ask_px":"135.300000000","bid_sz":20,"ask_sz":1000,"bid_ct":1,"ask_ct":1},{"bid_px":"134.200000000","ask_px":"136.100000000","bid_sz":3,"ask_sz":1000,"bid_ct":1,"ask_ct":1},{"bid_px":"133.160000000","ask_px":"137.060000000","bid_sz":1,"ask_sz":1,"bid_ct":1,"ask_ct":1},{"bid_px":"132.000000000","ask_px":"137.680000000","bid_sz":72,"ask_sz":500,"bid_ct":3,"ask_ct":1},{"bid_px":"130.520000000","ask_px":"138.870000000","bid_sz":4,"ask_sz":1000,"bid_ct":1,"ask_ct":2},{"bid_px":"130.000000000","ask_px":"139.420000000","bid_sz":5,"ask_sz":1,"bid_ct":1,"ask_ct":1},{"bid_px":"129.050000000","ask_px":"140.740000000","bid_sz":500,"ask_sz":100,"bid_ct":1,"ask_ct":1},{"bid_px":"129.000000000","ask_px":"140.880000000","bid_sz":12,"ask_sz":1000,"bid_ct":2,"ask_ct":2}],"symbol":"NVDA"}
{"ts_recv":"2024-11-01T08:00:06.545583895Z","hd":{"ts_event":"2024-11-01T08:00:06.545417855Z","rtype":10,"publisher_id":2,"instrument_id":11667},"action":"A","side":"A","depth":6,"price":"138.620000000","size":1,"flags":130,"ts_in_delta":166040,"sequence":300265,"levels":[{"bid_px":"134.440000000","ask_px":"135.000000000","bid_sz":100,"ask_sz":8,"bid_ct":1,"ask_ct":1},{"bid_px":"134.410000000","ask_px":"135.230000000","bid_sz":61,"ask_sz":360,"bid_ct":2,"ask_ct":1},{"bid_px":"134.210000000","ask_px":"135.300000000","bid_sz":20,"ask_sz":1000,"bid_ct":1,"ask_ct":1},{"bid_px":"134.200000000","ask_px":"136.100000000","bid_sz":3,"ask_sz":1000,"bid_ct":1,"ask_ct":1},{"bid_px":"133.160000000","ask_px":"137.060000000","bid_sz":1,"ask_sz":1,"bid_ct":1,"ask_ct":1},{"bid_px":"132.000000000","ask_px":"137.680000000","bid_sz":72,"ask_sz":500,"bid_ct":3,"ask_ct":1},{"bid_px":"130.520000000","ask_px":"138.620000000","bid_sz":4,"ask_sz":1,"bid_ct":1,"ask_ct":1},{"bid_px":"130.000000000","ask_px":"138.870000000","bid_sz":5,"ask_sz":1000,"bid_ct":1,"ask_ct":2},{"bid_px":"129.050000000","ask_px":"139.420000000","bid_sz":500,"ask_sz":1,"bid_ct":1,"ask_ct":1},{"bid_px":"129.000000000","ask_px":"140.740000000","bid_sz":12,"ask_sz":100,"bid_ct":2,"ask_ct":1}],"symbol":"NVDA"}
{"ts_recv":"2024-11-01T08:00:06.545707182Z","hd":{"ts_event":"2024-11-01T08:00:06.545540553Z","rtype":10,"publisher_id":2,"instrument_id":11667},"action":"A","side":"A","depth":8,"price":"139.060000000","size":1,"flags":130,"ts_in_delta":166629,"sequence":300266,"levels":[{"bid_px":"134.440000000","ask_px":"135.000000000","bid_sz":100,"ask_sz":8,"bid_ct":1,"ask_ct":1},{"bid_px":"134.410000000","ask_px":"135.230000000","bid_sz":61,"ask_sz":360,"bid_ct":2,"ask_ct":1},{"bid_px":"134.210000000","ask_px":"135.300000000","bid_sz":20,"ask_sz":1000,"bid_ct":1,"ask_ct":1},{"bid_px":"134.200000000","ask_px":"136.100000000","bid_sz":3,"ask_sz":1000,"bid_ct":1,"ask_ct":1},{"bid_px":"133.160000000","ask_px":"137.060000000","bid_sz":1,"ask_sz":1,"bid_ct":1,"ask_ct":1},{"bid_px":"132.000000000","ask_px":"137.680000000","bid_sz":72,"ask_sz":500,"bid_ct":3,"ask_ct":1},{"bid_px":"130.520000000","ask_px":"138.620000000","bid_sz":4,"ask_sz":1,"bid_ct":1,"ask_ct":1},{"bid_px":"130.000000000","ask_px":"138.870000000","bid_sz":5,"ask_sz":1000,"bid_ct":1,"ask_ct":2},{"bid_px":"129.050000000","ask_px":"139.060000000","bid_sz":500,"ask_sz":1,"bid_ct":1,"ask_ct":1},{"bid_px":"129.000000000","ask_px":"139.420000000","bid_sz":12,"ask_sz":1,"bid_ct":2,"ask_ct":1}],"symbol":"NVDA"}
{"ts_recv":"2024-11-01T08:00:06.545906761Z","hd":{"ts_event":"2024-11-01T08:00:06.545740131Z","rtype":10,"publisher_id":2,"instrument_id":11667},"action":"A","side":"A","depth":4,"price":"136.220000000","size":1,"flags":130,"ts_in_delta":166630,"sequence":300268,"levels":[{"bid_px":"134.440000000","ask_px":"135.000000000","bid_sz":100,"ask_sz":8,"bid_ct":1,"ask_ct":1},{"bid_px":"134.410000000","ask_px":"135.230000000","bid_sz":61,"ask_sz":360,"bid_ct":2,"ask_ct":1},{"bid_px":"134.210000000","ask_px":"135.300000000","bid_sz":20,"ask_sz":1000,"bid_ct":1,"ask_ct":1},{"bid_px":"134.200000000","ask_px":"136.100000000","bid_sz":3,"ask_sz":1000,"bid_ct":1,"ask_ct":1},{"bid_px":"133.160000000","ask_px":"136.220000000","bid_sz":1,"ask_sz":1,"bid_ct":1,"ask_ct":1},{"bid_px":"132.000000000","ask_px":"137.060000000","bid_sz":72,"ask_sz":1,"bid_ct":3,"ask_ct":1},{"bid_px":"130.520000000","ask_px":"137.680000000","bid_sz":4,"ask_sz":500,"bid_ct":1,"ask_ct":1},{"bid_px":"130.000000000","ask_px":"138.620000000","bid_sz":5,"ask_sz":1,"bid_ct":1,"ask_ct":1},{"bid_px":"129.050000000","ask_px":"138.870000000","bid_sz":500,"ask_sz":1000,"bid_ct":1,"ask_ct":2},{"bid_px":"129.000000000","ask_px":"139.060000000","bid_sz":12,"ask_sz":1,"bid_ct":2,"ask_ct":1}],"symbol":"NVDA"}
{"ts_recv":"2024-11-01T08:00:06.546024337Z","hd":{"ts_event":"2024-11-01T08:00:06.545857987Z","rtype":10,"publisher_id":2,"instrument_id":11667},"action":"A","side":"A","depth":7,"price":"137.820000000","size":1,"flags":130,"ts_in_delta":166350,"sequence":300269,"levels":[{"bid_px":"134.440000000","ask_px":"135.000000000","bid_sz":100,"ask_sz":8,"bid_ct":1,"ask_ct":1},{"bid_px":"134.410000000","ask_px":"135.230000000","bid_sz":61,"ask_sz":360,"bid_ct":2,"ask_ct":1},{"bid_px":"134.210000000","ask_px":"135.300000000","bid_sz":20,"ask_sz":1000,"bid_ct":1,"ask_ct":1},{"bid_px":"134.200000000","ask_px":"136.100000000","bid_sz":3,"ask_sz":1000,"bid_ct":1,"ask_ct":1},{"bid_px":"133.160000000","ask_px":"136.220000000","bid_sz":1,"ask_sz":1,"bid_ct":1,"ask_ct":1},{"bid_px":"132.000000000","ask_px":"137.060000000","bid_sz":72,"ask_sz":1,"bid_ct":3,"ask_ct":1},{"bid_px":"130.520000000","ask_px":"137.680000000","bid_sz":4,"ask_sz":500,"bid_ct":1,"ask_ct":1},{"bid_px":"130.000000000","ask_px":"137.820000000","bid_sz":5,"ask_sz":1,"bid_ct":1,"ask_ct":1},{"bid_px":"129.050000000","ask_px":"138.620000000","bid_sz":500,"ask_sz":1,"bid_ct":1,"ask_ct":1},{"bid_px":"129.000000000","ask_px":"138.870000000","bid_sz":12,"ask_sz":1000,"bid_ct":2,"ask_ct":2}],"symbol":"NVDA"}
{"ts_recv":"2024-11-01T08:00:06.546223878Z","hd":{"ts_event":"2024-11-01T08:00:06.546057605Z","rtype":10,"publisher_id":2,"instrument_id":11667},"action":"A","side":"A","depth":5,"price":"136.620000000","size":1,"flags":130,"ts_in_delta":166273,"sequence":300271,"levels":[{"bid_px":"134.440000000","ask_px":"135.000000000","bid_sz":100,"ask_sz":8,"bid_ct":1,"ask_ct":1},{"bid_px":"134.410000000","ask_px":"135.230000000","bid_sz":61,"ask_sz":360,"bid_ct":2,"ask_ct":1},{"bid_px":"134.210000000","ask_px":"135.300000000","bid_sz":20,"ask_sz":1000,"bid_ct":1,"ask_ct":1},{"bid_px":"134.200000000","ask_px":"136.100000000","bid_sz":3,"ask_sz":1000,"bid_ct":1,"ask_ct":1},{"bid_px":"133.160000000","ask_px":"136.220000000","bid_sz":1,"ask_sz":1,"bid_ct":1,"ask_ct":1},{"bid_px":"132.000000000","ask_px":"136.620000000","bid_sz":72,"ask_sz":1,"bid_ct":3,"ask_ct":1},{"bid_px":"130.520000000","ask_px":"137.060000000","bid_sz":4,"ask_sz":1,"bid_ct":1,"ask_ct":1},{"bid_px":"130.000000000","ask_px":"137.680000000","bid_sz":5,"ask_sz":500,"bid_ct":1,"ask_ct":1},{"bid_px":"129.050000000","ask_px":"137.820000000","bid_sz":500,"ask_sz":1,"bid_ct":1,"ask_ct":1},{"bid_px":"129.000000000","ask_px":"138.620000000","bid_sz":12,"ask_sz":1,"bid_ct":2,"ask_ct":1}],"symbol":"NVDA"}
{"ts_recv":"2024-11-01T08:00:06.546343926Z","hd":{"ts_event":"2024-11-01T08:00:06.546177821Z","rtype":10,"publisher_id":2,"instrument_id":11667},"action":"A","side":"A","depth":3,"price":"135.820000000","size":1,"flags":130,"ts_in_delta":166105,"sequence":300272,"levels":[{"bid_px":"134.440000000","ask_px":"135.000000000","bid_sz":100,"ask_sz":8,"bid_ct":1,"ask_ct":1},{"bid_px":"134.410000000","ask_px":"135.230000000","bid_sz":61,"ask_sz":360,"bid_ct":2,"ask_ct":1},{"bid_px":"134.210000000","ask_px":"135.300000000","bid_sz":20,"ask_sz":1000,"bid_ct":1,"ask_ct":1},{"bid_px":"134.200000000","ask_px":"135.820000000","bid_sz":3,"ask_sz":1,"bid_ct":1,"ask_ct":1},{"bid_px":"133.160000000","ask_px":"136.100000000","bid_sz":1,"ask_sz":1000,"bid_ct":1,"ask_ct":1},{"bid_px":"132.000000000","ask_px":"136.220000000","bid_sz":72,"ask_sz":1,"bid_ct":3,"ask_ct":1},{"bid_px":"130.520000000","ask_px":"136.620000000","bid_sz":4,"ask_sz":1,"bid_ct":1,"ask_ct":1},{"bid_px":"130.000000000","ask_px":"137.060000000","bid_sz":5,"ask_sz":1,"bid_ct":1,"ask_ct":1},{"bid_px":"129.050000000","ask_px":"137.680000000","bid_sz":500,"ask_sz":500,"bid_ct":1,"ask_ct":1},{"bid_px":"129.000000000","ask_px":"137.820000000","bid_sz":12,"ask_sz":1,"bid_ct":2,"ask_ct":1}],"symbol":"NVDA"}
{"ts_recv":"2024-11-01T08:00:06.546425983Z","hd":{"ts_event":"2024-11-01T08:00:06.546259845Z","rtype":10,"publisher_id":2,"instrument_id":11667},"action":"A","side":"A","depth":8,"price":"137.420000000","size":1,"flags":130,"ts_in_delta":166138,"sequence":300273,"levels":[{"bid_px":"134.440000000","ask_px":"135.000000000","bid_sz":100,"ask_sz":8,"bid_ct":1,"ask_ct":1},{"bid_px":"134.410000000","ask_px":"135.230000000","bid_sz":61,"ask_sz":360,"bid_ct":2,"ask_ct":1},{"bid_px":"134.210000000","ask_px":"135.300000000","bid_sz":20,"ask_sz":1000,"bid_ct":1,"ask_ct":1},{"bid_px":"134.200000000","ask_px":"135.820000000","bid_sz":3,"ask_sz":1,"bid_ct":1,"ask_ct":1},{"bid_px":"133.160000000","ask_px":"136.100000000","bid_sz":1,"ask_sz":1000,"bid_ct":1,"ask_ct":1},{"bid_px":"132.000000000","ask_px":"136.220000000","bid_sz":72,"ask_sz":1,"bid_ct":3,"ask_ct":1},{"bid_px":"130.520000000","ask_px":"136.620000000","bid_sz":4,"ask_sz":1,"bid_ct":1,"ask_ct":1},{"bid_px":"130.000000000","ask_px":"137.060000000","bid_sz":5,"ask_sz":1,"bid_ct":1,"ask_ct":1},{"bid_px":"129.050000000","ask_px":"137.420000000","bid_sz":500,"ask_sz":1,"bid_ct":1,"ask_ct":1},{"bid_px":"129.000000000","ask_px":"137.680000000","bid_sz":12,"ask_sz":500,"bid_ct":2,"ask_ct":1}],"symbol":"NVDA"}
{"ts_recv":"2024-11-01T08:00:06.604163200Z","hd":{"ts_event":"2024-11-01T08:00:06.603997329Z","rtype":10,"publisher_id":2,"instrument_id":11667},"action":"A","side":"B","depth":7,"price":"130.160000000","size":1,"flags":130,"ts_in_delta":165871,"sequence":300526,"levels":[{"bid_px":"134.440000000","ask_px":"135.000000000","bid_sz":100,"ask_sz":8,"bid_ct":1,"ask_ct":1},{"bid_px":"134.410000000","ask_px":"135.230000000","bid_sz":61,"ask_sz":360,"bid_ct":2,"ask_ct":1},{"bid_px":"134.210000000","ask_px":"135.300000000","bid_sz":20,"ask_sz":1000,"bid_ct":1,"ask_ct":1},{"bid_px":"134.200000000","ask_px":"135.820000000","bid_sz":3,"ask_sz":1,"bid_ct":1,"ask_ct":1},{"bid_px":"133.160000000","ask_px":"136.100000000","bid_sz":1,"ask_sz":1000,"bid_ct":1,"ask_ct":1},{"bid_px":"132.000000000","ask_px":"136.220000000","bid_sz":72,"ask_sz":1,"bid_ct":3,"ask_ct":1},{"bid_px":"130.520000000","ask_px":"136.620000000","bid_sz":4,"ask_sz":1,"bid_ct":1,"ask_ct":1},{"bid_px":"130.160000000","ask_px":"137.060000000","bid_sz":1,"ask_sz":1,"bid_ct":1,"ask_ct":1},{"bid_px":"130.000000000","ask_px":"137.420000000","bid_sz":5,"ask_sz":1,"bid_ct":1,"ask_ct":1},{"bid_px":"129.050000000","ask_px":"137.680000000","bid_sz":500,"ask_sz":500,"bid_ct":1,"ask_ct":1}],"symbol":"NVDA"}
{"ts_recv":"2024-11-01T08:00:06.604402754Z","hd":{"ts_event":"2024-11-01T08:00:06.604236437Z","rtype":10,"publisher_id":2,"instrument_id":11667},"action":"A","side":"B","depth":5,"price":"132.160000000","size":1,"flags":130,"ts_in_delta":166317,"sequence":300529,"levels":[{"bid_px":"134.440000000","ask_px":"135.000000000","bid_sz":100,"ask_sz":8,"bid_ct":1,"ask_ct":1},{"bid_px":"134.410000000","ask_px":"135.230000000","bid_sz":61,"ask_sz":360,"bid_ct":2,"ask_ct":1},{"bid_px":"134.210000000","ask_px":"135.300000000","bid_sz":20,"ask_sz":1000,"bid_ct":1,"ask_ct":1},{"bid_px":"134.200000000","ask_px":"135.820000000","bid_sz":3,"ask_sz":1,"bid_ct":1,"ask_ct":1},{"bid_px":"133.160000000","ask_px":"136.100000000","bid_sz":1,"ask_sz":1000,"bid_ct":1,"ask_ct":1},{"bid_px":"132.160000000","ask_px":"136.220000000","bid_sz":1,"ask_sz":1,"bid_ct":1,"ask_ct":1},{"bid_px":"132.000000000","ask_px":"136.620000000","bid_sz":72,"ask_sz":1,"bid_ct":3,"ask_ct":1},{"bid_px":"130.520000000","ask_px":"137.060000000","bid_sz":4,"ask_sz":1,"bid_ct":1,"ask_ct":1},{"bid_px":"130.160000000","ask_px":"137.420000000","bid_sz":1,"ask_sz":1,"bid_ct":1,"ask_ct":1},{"bid_px":"130.000000000","ask_px":"137.680000000","bid_sz":5,"ask_sz":500,"bid_ct":1,"ask_ct":1}],"symbol":"NVDA"}
{"ts_recv":"2024-11-01T08:00:06.604482005Z","hd":{"ts_event":"2024-11-01T08:00:06.604315892Z","rtype":10,"publisher_id":2,"instrument_id":11667},"action":"A","side":"B","depth":7,"price":"131.660000000","size":1,"flags":130,"ts_in_delta":166113,"sequence":300530,"levels":[{"bid_px":"134.440000000","ask_px":"135.000000000","bid_sz":100,"ask_sz":8,"bid_ct":1,"ask_ct":1},{"bid_px":"134.410000000","ask_px":"135.230000000","bid_sz":61,"ask_sz":360,"bid_ct":2,"ask_ct":1},{"bid_px":"134.210000000","ask_px":"135.300000000","bid_sz":20,"ask_sz":1000,"bid_ct":1,"ask_ct":1},{"bid_px":"134.200000000","ask_px":"135.820000000","bid_sz":3,"ask_sz":1,"bid_ct":1,"ask_ct":1},{"bid_px":"133.160000000","ask_px":"136.100000000","bid_sz":1,"ask_sz":1000,"bid_ct":1,"ask_ct":1},{"bid_px":"132.160000000","ask_px":"136.220000000","bid_sz":1,"ask_sz":1,"bid_ct":1,"ask_ct":1},{"bid_px":"132.000000000","ask_px":"136.620000000","bid_sz":72,"ask_sz":1,"bid_ct":3,"ask_ct":1},{"bid_px":"131.660000000","ask_px":"137.060000000","bid_sz":1,"ask_sz":1,"bid_ct":1,"ask_ct":1},{"bid_px":"130.520000000","ask_px":"137.420000000","bid_sz":4,"ask_sz":1,"bid_ct":1,"ask_ct":1},{"bid_px":"130.160000000","ask_px":"137.680000000","bid_sz":1,"ask_sz":500,"bid_ct":1,"ask_ct":1}],"symbol":"NVDA"}
{"ts_recv":"2024-11-01T08:00:06.604603304Z","hd":{"ts_event":"2024-11-01T08:00:06.604437230Z","rtype":10,"publisher_id":2,"instrument_id":11667},"action":"A","side":"A","depth":3,"price":"135.420000000","size":1,"flags":130,"ts_in_delta":166074,"sequence":300531,"levels":[{"bid_px":"134.440000000","ask_px":"135.000000000","bid_sz":100,"ask_sz":8,"bid_ct":1,"ask_ct":1},{"bid_px":"134.410000000","ask_px":"135.230000000","bid_sz":61,"ask_sz":360,"bid_ct":2,"ask_ct":1},{"bid_px":"134.210000000","ask_px":"135.300000000","bid_sz":20,"ask_sz":1000,"bid_ct":1,"ask_ct":1},{"bid_px":"134.200000000","ask_px":"135.420000000","bid_sz":3,"ask_sz":1,"bid_ct":1,"ask_ct":1},{"bid_px":"133.160000000","ask_px":"135.820000000","bid_sz":1,"ask_sz":1,"bid_ct":1,"ask_ct":1},{"bid_px":"132.160000000","ask_px":"136.100000000","bid_sz":1,"ask_sz":1000,"bid_ct":1,"ask_ct":1},{"bid_px":"132.000000000","ask_px":"136.220000000","bid_sz":72,"ask_sz":1,"bid_ct":3,"ask_ct":1},{"bid_px":"131.660000000","ask_px":"136.620000000","bid_sz":1,"ask_sz":1,"bid_ct":1,"ask_ct":1},{"bid_px":"130.520000000","ask_px":"137.060000000","bid_sz":4,"ask_sz":1,"bid_ct":1,"ask_ct":1},{"bid_px":"130.160000000","ask_px":"137.420000000","bid_sz":1,"ask_sz":1,"bid_ct":1,"ask_ct":1}],"symbol":"NVDA"}
{"ts_recv":"2024-11-01T08:00:06.604723966Z","hd":{"ts_event":"2024-11-01T08:00:06.604556994Z","rtype":10,"publisher_id":2,"instrument_id":11667},"action":"A","side":"A","depth":0,"price":"134.920000000","size":1,"flags":130,"ts_in_delta":166972,"sequence":300533,"levels":[{"bid_px":"134.440000000","ask_px":"134.920000000","bid_sz":100,"ask_sz":1,"bid_ct":1,"ask_ct":1},{"bid_px":"134.410000000","ask_px":"135.000000000","bid_sz":61,"ask_sz":8,"bid_ct":2,"ask_ct":1},{"bid_px":"134.210000000","ask_px":"135.230000000","bid_sz":20,"ask_sz":360,"bid_ct":1,"ask_ct":1},{"bid_px":"134.200000000","ask_px":"135.300000000","bid_sz":3,"ask_sz":1000,"bid_ct":1,"ask_ct":1},{"bid_px":"133.160000000","ask_px":"135.420000000","bid_sz":1,"ask_sz":1,"bid_ct":1,"ask_ct":1},{"bid_px":"132.160000000","ask_px":"135.820000000","bid_sz":1,"ask_sz":1,"bid_ct":1,"ask_ct":1},{"bid_px":"132.000000000","ask_px":"136.100000000","bid_sz":72,"ask_sz":1000,"bid_ct":3,"ask_ct":1},{"bid_px":"131.660000000","ask_px":"136.220000000","bid_sz":1,"ask_sz":1,"bid_ct":1,"ask_ct":1},{"bid_px":"130.520000000","ask_px":"136.620000000","bid_sz":4,"ask_sz":1,"bid_ct":1,"ask_ct":1},{"bid_px":"130.160000000","ask_px":"137.060000000","bid_sz":1,"ask_sz":1,"bid_ct":1,"ask_ct":1}],"symbol":"NVDA"}
{"ts_recv":"2024-11-01T08:00:06.604844139Z","hd":{"ts_event":"2024-11-01T08:00:06.604677905Z","rtype":10,"publisher_id":2,"instrument_id":11667},"action":"A","side":"B","depth":5,"price":"132.660000000","size":1,"flags":130,"ts_in_delta":166234,"sequence":300534,"levels":[{"bid_px":"134.440000000","ask_px":"134.920000000","bid_sz":100,"ask_sz":1,"bid_ct":1,"ask_ct":1},{"bid_px":"134.410000000","ask_px":"135.000000000","bid_sz":61,"ask_sz":8,"bid_ct":2,"ask_ct":1},{"bid_px":"134.210000000","ask_px":"135.230000000","bid_sz":20,"ask_sz":360,"bid_ct":1,"ask_ct":1},{"bid_px":"134.200000000","ask_px":"135.300000000","bid_sz":3,"ask_sz":1000,"bid_ct":1,"ask_ct":1},{"bid_px":"133.160000000","ask_px":"135.420000000","bid_sz":1,"ask_sz":1,"bid_ct":1,"ask_ct":1},{"bid_px":"132.660000000","ask_px":"135.820000000","bid_sz":1,"ask_sz":1,"bid_ct":1,"ask_ct":1},{"bid_px":"132.160000000","ask_px":"136.100000000","bid_sz":1,"ask_sz":1000,"bid_ct":1,"ask_ct":1},{"bid_px":"132.000000000","ask_px":"136.220000000","bid_sz":72,"ask_sz":1,"bid_ct":3,"ask_ct":1},{"bid_px":"131.660000000","ask_px":"136.620000000","bid_sz":1,"ask_sz":1,"bid_ct":1,"ask_ct":1},{"bid_px":"130.520000000","ask_px":"137.060000000","bid_sz":4,"ask_sz":1,"bid_ct":1,"ask_ct":1}],"symbol":"NVDA"}
{"ts_recv":"2024-11-01T08:00:06.604962915Z","hd":{"ts_event":"2024-11-01T08:00:06.604796654Z","rtype":10,"publisher_id":2,"instrument_id":11667},"action":"A","side":"B","depth":9,"price":"131.160000000","size":1,"flags":130,"ts_in_delta":166261,"sequence":300535,"levels":[{"bid_px":"134.440000000","ask_px":"134.920000000","bid_sz":100,"ask_sz":1,"bid_ct":1,"ask_ct":1},{"bid_px":"134.410000000","ask_px":"135.000000000","bid_sz":61,"ask_sz":8,"bid_ct":2,"ask_ct":1},{"bid_px":"134.210000000","ask_px":"135.230000000","bid_sz":20,"ask_sz":360,"bid_ct":1,"ask_ct":1},{"bid_px":"134.200000000","ask_px":"135.300000000","bid_sz":3,"ask_sz":1000,"bid_ct":1,"ask_ct":1},{"bid_px":"133.160000000","ask_px":"135.420000000","bid_sz":1,"ask_sz":1,"bid_ct":1,"ask_ct":1},{"bid_px":"132.660000000","ask_px":"135.820000000","bid_sz":1,"ask_sz":1,"bid_ct":1,"ask_ct":1},{"bid_px":"132.160000000","ask_px":"136.100000000","bid_sz":1,"ask_sz":1000,"bid_ct":1,"ask_ct":1},{"bid_px":"132.000000000","ask_px":"136.220000000","bid_sz":72,"ask_sz":1,"bid_ct":3,"ask_ct":1},{"bid_px":"131.660000000","ask_px":"136.620000000","bid_sz":1,"ask_sz":1,"bid_ct":1,"ask_ct":1},{"bid_px":"131.160000000","ask_px":"137.060000000","bid_sz":1,"ask_sz":1,"bid_ct":1,"ask_ct":1}],"symbol":"NVDA"}
{"ts_recv":"2024-11-01T08:00:06.622143213Z","hd":{"ts_event":"2024-11-01T08:00:06.621976999Z","rtype":10,"publisher_id":2,"instrument_id":16244},"action":"A","side":"B","depth":9,"price":"243.200000000","size":15,"flags":130,"ts_in_delta":166214,"sequence":300581,"levels":[{"bid_px":"249.880000000","ask_px":"250.680000000","bid_sz":100,"ask_sz":100,"bid_ct":2,"ask_ct":1},{"bid_px":"249.800000000","ask_px":"250.750000000","bid_sz":199,"ask_sz":50,"bid_ct":1,"ask_ct":1},{"bid_px":"249.770000000","ask_px":"252.100000000","bid_sz":50,"ask_sz":1000,"bid_ct":1,"ask_ct":1},{"bid_px":"249.600000000","ask_px":"253.650000000","bid_sz":1000,"ask_sz":400,"bid_ct":1,"ask_ct":1},{"bid_px":"249.500000000","ask_px":"260.000000000","bid_sz":1000,"ask_sz":48,"bid_ct":1,"ask_ct":1},{"bid_px":"249.400000000","ask_px":"264.940000000","bid_sz":1000,"ask_sz":7,"bid_ct":1,"ask_ct":1},{"bid_px":"247.700000000","ask_px":"265.000000000","bid_sz":1000,"ask_sz":1,"bid_ct":1,"ask_ct":1},{"bid_px":"247.150000000","ask_px":"267.800000000","bid_sz":400,"ask_sz":30,"bid_ct":1,"ask_ct":1},{"bid_px":"245.000000000","ask_px":"270.000000000","bid_sz":50,"ask_sz":3,"bid_ct":1,"ask_ct":1},{"bid_px":"243.200000000","ask_px":"273.000000000","bid_sz":15,"ask_sz":1,"bid_ct":1,"ask_ct":1}],"symbol":"TSLA"}
{"ts_recv":"2024-11-01T08:00:06.644817808Z","hd":{"ts_event":"2024-11-01T08:00:06.644651453Z","rtype":10,"publisher_id":2,"instrument_id":38},"action":"A","side":"A","depth":4,"price":"370.000000000","size":100,"flags":130,"ts_in_delta":166355,"sequence":300637,"levels":[{"bid_px":"221.200000000","ask_px":"224.600000000","bid_sz":1000,"ask_sz":1000,"bid_ct":1,"ask_ct":1},{"bid_px":"220.000000000","ask_px":"225.490000000","bid_sz":2,"ask_sz":442,"bid_ct":1,"ask_ct":1},{"bid_px":"219.690000000","ask_px":"234.000000000","bid_sz":442,"ask_sz":20,"bid_ct":1,"ask_ct":1},{"bid_px":"217.000000000","ask_px":"240.000000000","bid_sz":1525,"ask_sz":150,"bid_ct":1,"ask_ct":1},{"bid_px":"190.000000000","ask_px":"370.000000000","bid_sz":1,"ask_sz":100,"bid_ct":1,"ask_ct":1},{"bid_px":"180.000000000","ask_px":null,"bid_sz":1,"ask_sz":0,"bid_ct":1,"ask_ct":0},{"bid_px":"100.000000000","ask_px":null,"bid_sz":1,"ask_sz":0,"bid_ct":1,"ask_ct":0},{"bid_px":null,"ask_px":null,"bid_sz":0,"ask_sz":0,"bid_ct":0,"ask_ct":0},{"bid_px":null,"ask_px":null,"bid_sz":0,"ask_sz":0,"bid_ct":0,"ask_ct":0},{"bid_px":null,"ask_px":null,"bid_sz":0,"ask_sz":0,"bid_ct":0,"ask_ct":0}],"symbol":"AAPL"}
{"ts_recv":"2024-11-01T08:00:06.716302339Z","hd":{"ts_event":"2024-11-01T08:00:06.716136065Z","rtype":10,"publisher_id":2,"instrument_id":38},"action":"A","side":"B","depth":0,"price":"221.300000000","size":1000,"flags":130,"ts_in_delta":166274,"sequence":300753,"levels":[{"bid_px":"221.300000000","ask_px":"224.600000000","bid_sz":1000,"ask_sz":1000,"bid_ct":1,"ask_ct":1},{"bid_px":"221.200000000","ask_px":"225.490000000","bid_sz":1000,"ask_sz":442,"bid_ct":1,"ask_ct":1},{"bid_px":"220.000000000","ask_px":"234.000000000","bid_sz":2,"ask_sz":20,"bid_ct":1,"ask_ct":1},{"bid_px":"219.690000000","ask_px":"240.000000000","bid_sz":442,"ask_sz":150,"bid_ct":1,"ask_ct":1},{"bid_px":"217.000000000","ask_px":"370.000000000","bid_sz":1525,"ask_sz":100,"bid_ct":1,"ask_ct":1},{"bid_px":"190.000000000","ask_px":null,"bid_sz":1,"ask_sz":0,"bid_ct":1,"ask_ct":0},{"bid_px":"180.000000000","ask_px":null,"bid_sz":1,"ask_sz":0,"bid_ct":1,"ask_ct":0},{"bid_px":"100.000000000","ask_px":null,"bid_sz":1,"ask_sz":0,"bid_ct":1,"ask_ct":0},{"bid_px":null,"ask_px":null,"bid_sz":0,"ask_sz":0,"bid_ct":0,"ask_ct":0},{"bid_px":null,"ask_px":null,"bid_sz":0,"ask_sz":0,"bid_ct":0,"ask_ct":0}],"symbol":"AAPL"}
{"ts_recv":"2024-11-01T08:00:06.716394402Z","hd":{"ts_event":"2024-11-01T08:00:06.716228524Z","rtype":10,"publisher_id":2,"instrument_id":38},"action":"C","side":"B","depth":1,"price":"221.200000000","size":1000,"flags":130,"ts_in_delta":165878,"sequence":300754,"levels":[{"bid_px":"221.300000000","ask_px":"224.600000000","bid_sz":1000,"ask_sz":1000,"bid_ct":1,"ask_ct":1},{"bid_px":"220.000000000","ask_px":"225.490000000","bid_sz":2,"ask_sz":442,"bid_ct":1,"ask_ct":1},{"bid_px":"219.690000000","ask_px":"234.000000000","bid_sz":442,"ask_sz":20,"bid_ct":1,"ask_ct":1},{"bid_px":"217.000000000","ask_px":"240.000000000","bid_sz":1525,"ask_sz":150,"bid_ct":1,"ask_ct":1},{"bid_px":"190.000000000","ask_px":"370.000000000","bid_sz":1,"ask_sz":100,"bid_ct":1,"ask_ct":1},{"bid_px":"180.000000000","ask_px":null,"bid_sz":1,"ask_sz":0,"bid_ct":1,"ask_ct":0},{"bid_px":"100.000000000","ask_px":null,"bid_sz":1,"ask_sz":0,"bid_ct":1,"ask_ct":0},{"bid_px":null,"ask_px":null,"bid_sz":0,"ask_sz":0,"bid_ct":0,"ask_ct":0},{"bid_px":null,"ask_px":null,"bid_sz":0,"ask_sz":0,"bid_ct":0,"ask_ct":0},{"bid_px":null,"ask_px":null,"bid_sz":0,"ask_sz":0,"bid_ct":0,"ask_ct":0}],"symbol":"AAPL"}
{"ts_recv":"2024-11-01T08:00:06.756335271Z","hd":{"ts_event":"2024-11-01T08:00:06.756168964Z","rtype":10,"publisher_id":2,"instrument_id":11667},"action":"A","side":"B","depth":0,"price":"134.500000000","size":500,"flags":130,"ts_in_delta":166307,"sequence":300777,"levels":[{"bid_px":"134.500000000","ask_px":"134.920000000","bid_sz":500,"ask_sz":1,"bid_ct":1,"ask_ct":1},{"bid_px":"134.440000000","ask_px":"135.000000000","bid_sz":100,"ask_sz":8,"bid_ct":1,"ask_ct":1},{"bid_px":"134.410000000","ask_px":"135.230000000","bid_sz":61,"ask_sz":360,"bid_ct":2,"ask_ct":1},{"bid_px":"134.210000000","ask_px":"135.300000000","bid_sz":20,"ask_sz":1000,"bid_ct":1,"ask_ct":1},{"bid_px":"134.200000000","ask_px":"135.420000000","bid_sz":3,"ask_sz":1,"bid_ct":1,"ask_ct":1},{"bid_px":"133.160000000","ask_px":"135.820000000","bid_sz":1,"ask_sz":1,"bid_ct":1,"ask_ct":1},{"bid_px":"132.660000000","ask_px":"136.100000000","bid_sz":1,"ask_sz":1000,"bid_ct":1,"ask_ct":1},{"bid_px":"132.160000000","ask_px":"136.220000000","bid_sz":1,"ask_sz":1,"bid_ct":1,"ask_ct":1},{"bid_px":"132.000000000","ask_px":"136.620000000","bid_sz":72,"ask_sz":1,"bid_ct":3,"ask_ct":1},{"bid_px":"131.660000000","ask_px":"137.060000000","bid_sz":1,"ask_sz":1,"bid_ct":1,"ask_ct":1}],"symbol":"NVDA"}
{"ts_recv":"2024-11-01T08:00:06.763688556Z","hd":{"ts_event":"2024-11-01T08:00:06.763522181Z","rtype":10,"publisher_id":2,"instrument_id":10888},"action":"A","side":"B","depth":2,"price":"407.600000000","size":16,"flags":130,"ts_in_delta":166375,"sequence":300780,"levels":[{"bid_px":"410.000000000","ask_px":"415.070000000","bid_sz":1,"ask_sz":246,"bid_ct":1,"ask_ct":1},{"bid_px":"408.960000000","ask_px":"420.000000000","bid_sz":5,"ask_sz":3,"bid_ct":1,"ask_ct":1},{"bid_px":"407.600000000","ask_px":"448.000000000","bid_sz":16,"ask_sz":5,"bid_ct":1,"ask_ct":1},{"bid_px":"406.350000000","ask_px":"468.000000000","bid_sz":2,"ask_sz":65,"bid_ct":1,"ask_ct":1},{"bid_px":"406.000000000","ask_px":null,"bid_sz":7,"ask_sz":0,"bid_ct":1,"ask_ct":0},{"bid_px":"404.410000000","ask_px":null,"bid_sz":246,"ask_sz":0,"bid_ct":1,"ask_ct":0},{"bid_px":"398.900000000","ask_px":null,"bid_sz":3,"ask_sz":0,"bid_ct":1,"ask_ct":0},{"bid_px":"398.000000000","ask_px":null,"bid_sz":5,"ask_sz":0,"bid_ct":1,"ask_ct":0},{"bid_px":"387.000000000","ask_px":null,"bid_sz":25,"ask_sz":0,"bid_ct":1,"ask_ct":0},{"bid_px":"385.000000000","ask_px":null,"bid_sz":50,"ask_sz":0,"bid_ct":1,"ask_ct":0}],"symbol":"MSFT"}
{"ts_recv":"2024-11-01T08:00:06.816236941Z","hd":{"ts_event":"2024-11-01T08:00:06.816070840Z","rtype":10,"publisher_id":2,"instrument_id":11667},"action":"A","side":"A","depth":1,"price":"135.000000000","size":10,"flags":130,"ts_in_delta":166101,"sequence":300807,"levels":[{"bid_px":"134.500000000","ask_px":"134.920000000","bid_sz":500,"ask_sz":1,"bid_ct":1,"ask_ct":1},{"bid_px":"134.440000000","ask_px":"135.000000000","bid_sz":100,"ask_sz":18,"bid_ct":1,"ask_ct":2},{"bid_px":"134.410000000","ask_px":"135.230000000","bid_sz":61,"ask_sz":360,"bid_ct":2,"ask_ct":1},{"bid_px":"134.210000000","ask_px":"135.300000000","bid_sz":20,"ask_sz":1000,"bid_ct":1,"ask_ct":1},{"bid_px":"134.200000000","ask_px":"135.420000000","bid_sz":3,"ask_sz":1,"bid_ct":1,"ask_ct":1},{"bid_px":"133.160000000","ask_px":"135.820000000","bid_sz":1,"ask_sz":1,"bid_ct":1,"ask_ct":1},{"bid_px":"132.660000000","ask_px":"136.100000000","bid_sz":1,"ask_sz":1000,"bid_ct":1,"ask_ct":1},{"bid_px":"132.160000000","ask_px":"136.220000000","bid_sz":1,"ask_sz":1,"bid_ct":1,"ask_ct":1},{"bid_px":"132.000000000","ask_px":"136.620000000","bid_sz":72,"ask_sz":1,"bid_ct":3,"ask_ct":1},{"bid_px":"131.660000000","ask_px":"137.060000000","bid_sz":1,"ask_sz":1,"bid_ct":1,"ask_ct":1}],"symbol":"NVDA"}
{"ts_recv":"2024-11-01T08:00:06.880701595Z","hd":{"ts_event":"2024-11-01T08:00:06.880535282Z","rtype":10,"publisher_id":2,"instrument_id":16244},"action":"A","side":"B","depth":8,"price":"245.000000000","size":5,"flags":130,"ts_in_delta":166313,"sequence":300879,"levels":[{"bid_px":"249.880000000","ask_px":"250.680000000","bid_sz":100,"ask_sz":100,"bid_ct":2,"ask_ct":1},{"bid_px":"249.800000000","ask_px":"250.750000000","bid_sz":199,"ask_sz":50,"bid_ct":1,"ask_ct":1},{"bid_px":"249.770000000","ask_px":"252.100000000","bid_sz":50,"ask_sz":1000,"bid_ct":1,"ask_ct":1},{"bid_px":"249.600000000","ask_px":"253.650000000","bid_sz":1000,"ask_sz":400,"bid_ct":1,"ask_ct":1},{"bid_px":"249.500000000","ask_px":"260.000000000","bid_sz":1000,"ask_sz":48,"bid_ct":1,"ask_ct":1},{"bid_px":"249.400000000","ask_px":"264.940000000","bid_sz":1000,"ask_sz":7,"bid_ct":1,"ask_ct":1},{"bid_px":"247.700000000","ask_px":"265.000000000","bid_sz":1000,"ask_sz":1,"bid_ct":1,"ask_ct":1},{"bid_px":"247.150000000","ask_px":"267.800000000","bid_sz":400,"ask_sz":30,"bid_ct":1,"ask_ct":1},{"bid_px":"245.000000000","ask_px":"270.000000000","bid_sz":55,"ask_sz":3,"bid_ct":2,"ask_ct":1},{"bid_px":"243.200000000","ask_px":"273.000000000","bid_sz":15,"ask_sz":1,"bid_ct":1,"ask_ct":1}],"symbol":"TSLA"}
{"ts_recv":"2024-11-01T08:00:06.991065733Z","hd":{"ts_event":"2024-11-01T08:00:06.990899411Z","rtype":10,"publisher_id":2,"instrument_id":10888},"action":"A","side":"A","depth":2,"price":"448.000000000","size":10,"flags":130,"ts_in_delta":166322,"sequence":300975,"levels":[{"bid_px":"410.000000000","ask_px":"415.070000000","bid_sz":1,"ask_sz":246,"bid_ct":1,"ask_ct":1},{"bid_px":"408.960000000","ask_px":"420.000000000","bid_sz":5,"ask_sz":3,"bid_ct":1,"ask_ct":1},{"bid_px":"407.600000000","ask_px":"448.000000000","bid_sz":16,"ask_sz":15,"bid_ct":1,"ask_ct":2},{"bid_px":"406.350000000","ask_px":"468.000000000","bid_sz":2,"ask_sz":65,"bid_ct":1,"ask_ct":1},{"bid_px":"406.000000000","ask_px":null,"bid_sz":7,"ask_sz":0,"bid_ct":1,"ask_ct":0},{"bid_px":"404.410000000","ask_px":null,"bid_sz":246,"ask_sz":0,"bid_ct":1,"ask_ct":0},{"bid_px":"398.900000000","ask_px":null,"bid_sz":3,"ask_sz":0,"bid_ct":1,"ask_ct":0},{"bid_px":"398.000000000","ask_px":null,"bid_sz":5,"ask_sz":0,"bid_ct":1,"ask_ct":0},{"bid_px":"387.000000000","ask_px":null,"bid_sz":25,"ask_sz":0,"bid_ct":1,"ask_ct":0},{"bid_px":"385.000000000","ask_px":null,"bid_sz":50,"ask_sz":0,"bid_ct":1,"ask_ct":0}],"symbol":"MSFT"}
{"ts_recv":"2024-11-01T08:00:07.022666513Z","hd":{"ts_event":"2024-11-01T08:00:07.022500209Z","rtype":10,"publisher_id":2,"instrument_id":6905},"action":"A","side":"B","depth":0,"price":"84.040000000","size":100,"flags":130,"ts_in_delta":166304,"sequence":300993,"levels":[{"bid_px":"84.040000000","ask_px":"91.880000000","bid_sz":100,"ask_sz":100,"bid_ct":1,"ask_ct":1},{"bid_px":null,"ask_px":null,"bid_sz":0,"ask_sz":0,"bid_ct":0,"ask_ct":0},{"bid_px":null,"ask_px":null,"bid_sz":0,"ask_sz":0,"bid_ct":0,"ask_ct":0},{"bid_px":null,"ask_px":null,"bid_sz":0,"ask_sz":0,"bid_ct":0,"ask_ct":0},{"bid_px":null,"ask_px":null,"bid_sz":0,"ask_sz":0,"bid_ct":0,"ask_ct":0},{"bid_px":null,"ask_px":null,"bid_sz":0,"ask_sz":0,"bid_ct":0,"ask_ct":0},{"bid_px":null,"ask_px":null,"bid_sz":0,"ask_sz":0,"bid_ct":0,"ask_ct":0},{"bid_px":null,"ask_px":null,"bid_sz":0,"ask_sz":0,"bid_ct":0,"ask_ct":0},{"bid_px":null,"ask_px":null,"bid_sz":0,"ask_sz":0,"bid_ct":0,"ask_ct":0},{"bid_px":null,"ask_px":null,"bid_sz":0,"ask_sz":0,"bid_ct":0,"ask_ct":0}],"symbol":"GILD"}
{"ts_recv":"2024-11-01T08:00:07.027301482Z","hd":{"ts_event":"2024-11-01T08:00:07.027135394Z","rtype":10,"publisher_id":2,"instrument_id":10888},"action":"A","side":"A","depth":3,"price":"450.000000000","size":10,"flags":130,"ts_in_delta":166088,"sequence":301004,"levels":[{"bid_px":"410.000000000","ask_px":"415.070000000","bid_sz":1,"ask_sz":246,"bid_ct":1,"ask_ct":1},{"bid_px":"408.960000000","ask_px":"420.000000000","bid_sz":5,"ask_sz":3,"bid_ct":1,"ask_ct":1},{"bid_px":"407.600000000","ask_px":"448.000000000","bid_sz":16,"ask_sz":15,"bid_ct":1,"ask_ct":2},{"bid_px":"406.350000000","ask_px":"450.000000000","bid_sz":2,"ask_sz":10,"bid_ct":1,"ask_ct":1},{"bid_px":"406.000000000","ask_px":"468.000000000","bid_sz":7,"ask_sz":65,"bid_ct":1,"ask_ct":1},{"bid_px":"404.410000000","ask_px":null,"bid_sz":246,"ask_sz":0,"bid_ct":1,"ask_ct":0},{"bid_px":"398.900000000","ask_px":null,"bid_sz":3,"ask_sz":0,"bid_ct":1,"ask_ct":0},{"bid_px":"398.000000000","ask_px":null,"bid_sz":5,"ask_sz":0,"bid_ct":1,"ask_ct":0},{"bid_px":"387.000000000","ask_px":null,"bid_sz":25,"ask_sz":0,"bid_ct":1,"ask_ct":0},{"bid_px":"385.000000000","ask_px":null,"bid_sz":50,"ask_sz":0,"bid_ct":1,"ask_ct":0}],"symbol":"MSFT"}
{"ts_recv":"2024-11-01T08:00:07.045783632Z","hd":{"ts_event":"2024-11-01T08:00:07.045617390Z","rtype":10,"publisher_id":2,"instrument_id":10888},"action":"A","side":"B","depth":6,"price":"400.000000000","size":10,"flags":130,"ts_in_delta":166242,"sequence":301025,"levels":[{"bid_px":"410.000000000","ask_px":"415.070000000","bid_sz":1,"ask_sz":246,"bid_ct":1,"ask_ct":1},{"bid_px":"408.960000000","ask_px":"420.000000000","bid_sz":5,"ask_sz":3,"bid_ct":1,"ask_ct":1},{"bid_px":"407.600000000","ask_px":"448.000000000","bid_sz":16,"ask_sz":15,"bid_ct":1,"ask_ct":2},{"bid_px":"406.350000000","ask_px":"450.000000000","bid_sz":2,"ask_sz":10,"bid_ct":1,"ask_ct":1},{"bid_px":"406.000000000","ask_px":"468.000000000","bid_sz":7,"ask_sz":65,"bid_ct":1,"ask_ct":1},{"bid_px":"404.410000000","ask_px":null,"bid_sz":246,"ask_sz":0,"bid_ct":1,"ask_ct":0},{"bid_px":"400.000000000","ask_px":null,"bid_sz":10,"ask_sz":0,"bid_ct":1,"ask_ct":0},{"bid_px":"398.900000000","ask_px":null,"bid_sz":3,"ask_sz":0,"bid_ct":1,"ask_ct":0},{"bid_px":"398.000000000","ask_px":null,"bid_sz":5,"ask_sz":0,"bid_ct":1,"ask_ct":0},{"bid_px":"387.000000000","ask_px":null,"bid_sz":25,"ask_sz":0,"bid_ct":1,"ask_ct":0}],"symbol":"MSFT"}
{"ts_recv":"2024-11-01T08:00:07.049111722Z","hd":{"ts_event":"2024-11-01T08:00:07.048945412Z","rtype":10,"publisher_id":2,"instrument_id":10888},"action":"A","side":"A","depth":2,"price":"445.000000000","size":25,"flags":130,"ts_in_delta":166310,"sequence":301026,"levels":[{"bid_px":"410.000000000","ask_px":"415.070000000","bid_sz":1,"ask_sz":246,"bid_ct":1,"ask_ct":1},{"bid_px":"408.960000000","ask_px":"420.000000000","bid_sz":5,"ask_sz":3,"bid_ct":1,"ask_ct":1},{"bid_px":"407.600000000","ask_px":"445.000000000","bid_sz":16,"ask_sz":25,"bid_ct":1,"ask_ct":1},{"bid_px":"406.350000000","ask_px":"448.000000000","bid_sz":2,"ask_sz":15,"bid_ct":1,"ask_ct":2},{"bid_px":"406.000000000","ask_px":"450.000000000","bid_sz":7,"ask_sz":10,"bid_ct":1,"ask_ct":1},{"bid_px":"404.410000000","ask_px":"468.000000000","bid_sz":246,"ask_sz":65,"bid_ct":1,"ask_ct":1},{"bid_px":"400.000000000","ask_px":null,"bid_sz":10,"ask_sz":0,"bid_ct":1,"ask_ct":0},{"bid_px":"398.900000000","ask_px":null,"bid_sz":3,"ask_sz":0,"bid_ct":1,"ask_ct":0},{"bid_px":"398.000000000","ask_px":null,"bid_sz":5,"ask_sz":0,"bid_ct":1,"ask_ct":0},{"bid_px":"387.000000000","ask_px":null,"bid_sz":25,"ask_sz":0,"bid_ct":1,"ask_ct":0}],"symbol":"MSFT"}
{"ts_recv":"2024-11-01T08:00:07.079894788Z","hd":{"ts_event":"2024-11-01T08:00:07.079728933Z","rtype":10,"publisher_id":2,"instrument_id":16244},"action":"C","side":"A","depth":1,"price":"250.750000000","size":50,"flags":130,"ts_in_delta":165855,"sequence":301044,"levels":[{"bid_px":"249.880000000","ask_px":"250.680000000","bid_sz":100,"ask_sz":100,"bid_ct":2,"ask_ct":1},{"bid_px":"249.800000000","ask_px":"252.100000000","bid_sz":199,"ask_sz":1000,"bid_ct":1,"ask_ct":1},{"bid_px":"249.770000000","ask_px":"253.650000000","bid_sz":50,"ask_sz":400,"bid_ct":1,"ask_ct":1},{"bid_px":"249.600000000","ask_px":"260.000000000","bid_sz":1000,"ask_sz":48,"bid_ct":1,"ask_ct":1},{"bid_px":"249.500000000","ask_px":"264.940000000","bid_sz":1000,"ask_sz":7,"bid_ct":1,"ask_ct":1},{"bid_px":"249.400000000","ask_px":"265.000000000","bid_sz":1000,"ask_sz":1,"bid_ct":1,"ask_ct":1},{"bid_px":"247.700000000","ask_px":"267.800000000","bid_sz":1000,"ask_sz":30,"bid_ct":1,"ask_ct":1},{"bid_px":"247.150000000","ask_px":"270.000000000","bid_sz":400,"ask_sz":3,"bid_ct":1,"ask_ct":1},{"bid_px":"245.000000000","ask_px":"273.000000000","bid_sz":55,"ask_sz":1,"bid_ct":2,"ask_ct":1},{"bid_px":"243.200000000","ask_px":"274.000000000","bid_sz":15,"ask_sz":86,"bid_ct":1,"ask_ct":1}],"symbol":"TSLA"}
{"ts_recv":"2024-11-01T08:00:07.089199825Z","hd":{"ts_event":"2024-11-01T08:00:07.089033596Z","rtype":10,"publisher_id":2,"instrument_id":16244},"action":"A","side":"A","depth":1,"price":"250.760000000","size":50,"flags":130,"ts_in_delta":166229,"sequence":301047,"levels":[{"bid_px":"249.880000000","ask_px":"250.680000000","bid_sz":100,"ask_sz":100,"bid_ct":2,"ask_ct":1},{"bid_px":"249.800000000","ask_px":"250.760000000","bid_sz":199,"ask_sz":50,"bid_ct":1,"ask_ct":1},{"bid_px":"249.770000000","ask_px":"252.100000000","bid_sz":50,"ask_sz":1000,"bid_ct":1,"ask_ct":1},{"bid_px":"249.600000000","ask_px":"253.650000000","bid_sz":1000,"ask_sz":400,"bid_ct":1,"ask_ct":1},{"bid_px":"249.500000000","ask_px":"260.000000000","bid_sz":1000,"ask_sz":48,"bid_ct":1,"ask_ct":1},{"bid_px":"249.400000000","ask_px":"264.940000000","bid_sz":1000,"ask_sz":7,"bid_ct":1,"ask_ct":1},{"bid_px":"247.700000000","ask_px":"265.000000000","bid_sz":1000,"ask_sz":1,"bid_ct":1,"ask_ct":1},{"bid_px":"247.150000000","ask_px":"267.800000000","bid_sz":400,"ask_sz":30,"bid_ct":1,"ask_ct":1},{"bid_px":"245.000000000","ask_px":"270.000000000","bid_sz":55,"ask_sz":3,"bid_ct":2,"ask_ct":1},{"bid_px":"243.200000000","ask_px":"273.000000000","bid_sz":15,"ask_sz":1,"bid_ct":1,"ask_ct":1}],"symbol":"TSLA"}
{"ts_recv":"2024-11-01T08:00:07.101021468Z","hd":{"ts_event":"2024-11-01T08:00:07.100855216Z","rtype":10,"publisher_id":2,"instrument_id":10888},"action":"A","side":"B","depth":5,"price":"405.000000000","size":10,"flags":130,"ts_in_delta":166252,"sequence":301052,"levels":[{"bid_px":"410.000000000","ask_px":"415.070000000","bid_sz":1,"ask_sz":246,"bid_ct":1,"ask_ct":1},{"bid_px":"408.960000000","ask_px":"420.000000000","bid_sz":5,"ask_sz":3,"bid_ct":1,"ask_ct":1},{"bid_px":"407.600000000","ask_px":"445.000000000","bid_sz":16,"ask_sz":25,"bid_ct":1,"ask_ct":1},{"bid_px":"406.350000000","ask_px":"448.000000000","bid_sz":2,"ask_sz":15,"bid_ct":1,"ask_ct":2},{"bid_px":"406.000000000","ask_px":"450.000000000","bid_sz":7,"ask_sz":10,"bid_ct":1,"ask_ct":1},{"bid_px":"405.000000000","ask_px":"468.000000000","bid_sz":10,"ask_sz":65,"bid_ct":1,"ask_ct":1},{"bid_px":"404.410000000","ask_px":null,"bid_sz":246,"ask_sz":0,"bid_ct":1,"ask_ct":0},{"bid_px":"400.000000000","ask_px":null,"bid_sz":10,"ask_sz":0,"bid_ct":1,"ask_ct":0},{"bid_px":"398.900000000","ask_px":null,"bid_sz":3,"ask_sz":0,"bid_ct":1,"ask_ct":0},{"bid_px":"398.000000000","ask_px":null,"bid_sz":5,"ask_sz":0,"bid_ct":1,"ask_ct":0}],"symbol":"MSFT"}
{"ts_recv":"2024-11-01T08:00:07.104804757Z","hd":{"ts_event":"2024-11-01T08:00:07.104638780Z","rtype":10,"publisher_id":2,"instrument_id":16244},"action":"C","side":"B","depth":0,"price":"249.880000000","size":50,"flags":130,"ts_in_delta":165977,"sequence":301056,"levels":[{"bid_px":"249.880000000","ask_px":"250.680000000","bid_sz":50,"ask_sz":100,"bid_ct":1,"ask_ct":1},{"bid_px":"249.800000000","ask_px":"250.760000000","bid_sz":199,"ask_sz":50,"bid_ct":1,"ask_ct":1},{"bid_px":"249.770000000","ask_px":"252.100000000","bid_sz":50,"ask_sz":1000,"bid_ct":1,"ask_ct":1},{"bid_px":"249.600000000","ask_px":"253.650000000","bid_sz":1000,"ask_sz":400,"bid_ct":1,"ask_ct":1},{"bid_px":"249.500000000","ask_px":"260.000000000","bid_sz":1000,"ask_sz":48,"bid_ct":1,"ask_ct":1},{"bid_px":"249.400000000","ask_px":"264.940000000","bid_sz":1000,"ask_sz":7,"bid_ct":1,"ask_ct":1},{"bid_px":"247.700000000","ask_px":"265.000000000","bid_sz":1000,"ask_sz":1,"bid_ct":1,"ask_ct":1},{"bid_px":"247.150000000","ask_px":"267.800000000","bid_sz":400,"ask_sz":30,"bid_ct":1,"ask_ct":1},{"bid_px":"245.000000000","ask_px":"270.000000000","bid_sz":55,"ask_sz":3,"bid_ct":2,"ask_ct":1},{"bid_px":"243.200000000","ask_px":"273.000000000","bid_sz":15,"ask_sz":1,"bid_ct":1,"ask_ct":1}],"symbol":"TSLA"}
{"ts_recv":"2024-11-01T08:00:07.104820824Z","hd":{"ts_event":"2024-11-01T08:00:07.104654217Z","rtype":10,"publisher_id":2,"instrument_id":16244},"action":"A","side":"B","depth":0,"price":"249.890000000","size":50,"flags":130,"ts_in_delta":166607,"sequence":301057,"levels":[{"bid_px":"249.890000000","ask_px":"250.680000000","bid_sz":50,"ask_sz":100,"bid_ct":1,"ask_ct":1},{"bid_px":"249.800000000","ask_px":"250.760000000","bid_sz":199,"ask_sz":50,"bid_ct":1,"ask_ct":1},{"bid_px":"249.770000000","ask_px":"252.100000000","bid_sz":50,"ask_sz":1000,"bid_ct":1,"ask_ct":1},{"bid_px":"249.600000000","ask_px":"253.650000000","bid_sz":1000,"ask_sz":400,"bid_ct":1,"ask_ct":1},{"bid_px":"249.500000000","ask_px":"260.000000000","bid_sz":1000,"ask_sz":48,"bid_ct":1,"ask_ct":1},{"bid_px":"249.400000000","ask_px":"264.940000000","bid_sz":1000,"ask_sz":7,"bid_ct":1,"ask_ct":1},{"bid_px":"247.700000000","ask_px":"265.000000000","bid_sz":1000,"ask_sz":1,"bid_ct":1,"ask_ct":1},{"bid_px":"247.150000000","ask_px":"267.800000000","bid_sz":400,"ask_sz":30,"bid_ct":1,"ask_ct":1},{"bid_px":"245.000000000","ask_px":"270.000000000","bid_sz":55,"ask_sz":3,"bid_ct":2,"ask_ct":1},{"bid_px":"243.200000000","ask_px":"273.000000000","bid_sz":15,"ask_sz":1,"bid_ct":1,"ask_ct":1}],"symbol":"TSLA"}
{"ts_recv":"2024-11-01T08:00:07.120093736Z","hd":{"ts_event":"2024-11-01T08:00:07.119927482Z","rtype":10,"publisher_id":2,"instrument_id":16244},"action":"C","side":"A","depth":0,"price":"250.680000000","size":100,"flags":130,"ts_in_delta":166254,"sequence":301103,"levels":[{"bid_px":"249.890000000","ask_px":"250.760000000","bid_sz":50,"ask_sz":50,"bid_ct":1,"ask_ct":1},{"bid_px":"249.800000000","ask_px":"252.100000000","bid_sz":199,"ask_sz":1000,"bid_ct":1,"ask_ct":1},{"bid_px":"249.770000000","ask_px":"253.650000000","bid_sz":50,"ask_sz":400,"bid_ct":1,"ask_ct":1},{"bid_px":"249.600000000","ask_px":"260.000000000","bid_sz":1000,"ask_sz":48,"bid_ct":1,"ask_ct":1},{"bid_px":"249.500000000","ask_px":"264.940000000","bid_sz":1000,"ask_sz":7,"bid_ct":1,"ask_ct":1},{"bid_px":"249.400000000","ask_px":"265.000000000","bid_sz":1000,"ask_sz":1,"bid_ct":1,"ask_ct":1},{"bid_px":"247.700000000","ask_px":"267.800000000","bid_sz":1000,"ask_sz":30,"bid_ct":1,"ask_ct":1},{"bid_px":"247.150000000","ask_px":"270.000000000","bid_sz":400,"ask_sz":3,"bid_ct":1,"ask_ct":1},{"bid_px":"245.000000000","ask_px":"273.000000000","bid_sz":55,"ask_sz":1,"bid_ct":2,"ask_ct":1},{"bid_px":"243.200000000","ask_px":"274.000000000","bid_sz":15,"ask_sz":86,"bid_ct":1,"ask_ct":1}],"symbol":"TSLA"}
{"ts_recv":"2024-11-01T08:00:07.120106510Z","hd":{"ts_event":"2024-11-01T08:00:07.119940373Z","rtype":10,"publisher_id":2,"instrument_id":16244},"action":"A","side":"A","depth":0,"price":"250.700000000","size":100,"flags":130,"ts_in_delta":166137,"sequence":301104,"levels":[{"bid_px":"249.890000000","ask_px":"250.700000000","bid_sz":50,"ask_sz":100,"bid_ct":1,"ask_ct":1},{"bid_px":"249.800000000","ask_px":"250.760000000","bid_sz":199,"ask_sz":50,"bid_ct":1,"ask_ct":1},{"bid_px":"249.770000000","ask_px":"252.100000000","bid_sz":50,"ask_sz":1000,"bid_ct":1,"ask_ct":1},{"bid_px":"249.600000000","ask_px":"253.650000000","bid_sz":1000,"ask_sz":400,"bid_ct":1,"ask_ct":1},{"bid_px":"249.500000000","ask_px":"260.000000000","bid_sz":1000,"ask_sz":48,"bid_ct":1,"ask_ct":1},{"bid_px":"249.400000000","ask_px":"264.940000000","bid_sz":1000,"ask_sz":7,"bid_ct":1,"ask_ct":1},{"bid_px":"247.700000000","ask_px":"265.000000000","bid_sz":1000,"ask_sz":1,"bid_ct":1,"ask_ct":1},{"bid_px":"247.150000000","ask_px":"267.800000000","bid_sz":400,"ask_sz":30,"bid_ct":1,"ask_ct":1},{"bid_px":"245.000000000","ask_px":"270.000000000","bid_sz":55,"ask_sz":3,"bid_ct":2,"ask_ct":1},{"bid_px":"243.200000000","ask_px":"273.000000000","bid_sz":15,"ask_sz":1,"bid_ct":1,"ask_ct":1}],"symbol":"TSLA"}
{"ts_recv":"2024-11-01T08:00:07.120191155Z","hd":{"ts_event":"2024-11-01T08:00:07.120025391Z","rtype":10,"publisher_id":2,"instrument_id":16244},"action":"C","side":"A","depth":2,"price":"252.100000000","size":1000,"flags":130,"ts_in_delta":165764,"sequence":301105,"levels":[{"bid_px":"249.890000000","ask_px":"250.700000000","bid_sz":50,"ask_sz":100,"bid_ct":1,"ask_ct":1},{"bid_px":"249.800000000","ask_px":"250.760000000","bid_sz":199,"ask_sz":50,"bid_ct":1,"ask_ct":1},{"bid_px":"249.770000000","ask_px":"253.650000000","bid_sz":50,"ask_sz":400,"bid_ct":1,"ask_ct":1},{"bid_px":"249.600000000","ask_px":"260.000000000","bid_sz":1000,"ask_sz":48,"bid_ct":1,"ask_ct":1},{"bid_px":"249.500000000","ask_px":"264.940000000","bid_sz":1000,"ask_sz":7,"bid_ct":1,"ask_ct":1},{"bid_px":"249.400000000","ask_px":"265.000000000","bid_sz":1000,"ask_sz":1,"bid_ct":1,"ask_ct":1},{"bid_px":"247.700000000","ask_px":"267.800000000","bid_sz":1000,"ask_sz":30,"bid_ct":1,"ask_ct":1},{"bid_px":"247.150000000","ask_px":"270.000000000","bid_sz":400,"ask_sz":3,"bid_ct":1,"ask_ct":1},{"bid_px":"245.000000000","ask_px":"273.000000000","bid_sz":55,"ask_sz":1,"bid_ct":2,"ask_ct":1},{"bid_px":"243.200000000","ask_px":"274.000000000","bid_sz":15,"ask_sz":86,"bid_ct":1,"ask_ct":1}],"symbol":"TSLA"}
{"ts_recv":"2024-11-01T08:00:07.120386110Z","hd":{"ts_event":"2024-11-01T08:00:07.120220561Z","rtype":10,"publisher_id":2,"instrument_id":16244},"action":"C","side":"A","depth":0,"price":"250.700000000","size":100,"flags":130,"ts_in_delta":165549,"sequence":301108,"levels":[{"bid_px":"249.890000000","ask_px":"250.760000000","bid_sz":50,"ask_sz":50,"bid_ct":1,"ask_ct":1},{"bid_px":"249.800000000","ask_px":"253.650000000","bid_sz":199,"ask_sz":400,"bid_ct":1,"ask_ct":1},{"bid_px":"249.770000000","ask_px":"260.000000000","bid_sz":50,"ask_sz":48,"bid_ct":1,"ask_ct":1},{"bid_px":"249.600000000","ask_px":"264.940000000","bid_sz":1000,"ask_sz":7,"bid_ct":1,"ask_ct":1},{"bid_px":"249.500000000","ask_px":"265.000000000","bid_sz":1000,"ask_sz":1,"bid_ct":1,"ask_ct":1},{"bid_px":"249.400000000","ask_px":"267.800000000","bid_sz":1000,"ask_sz":30,"bid_ct":1,"ask_ct":1},{"bid_px":"247.700000000","ask_px":"270.000000000","bid_sz":1000,"ask_sz":3,"bid_ct":1,"ask_ct":1},{"bid_px":"247.150000000","ask_px":"273.000000000","bid_sz":400,"ask_sz":1,"bid_ct":1,"ask_ct":1},{"bid_px":"245.000000000","ask_px":"274.000000000","bid_sz":55,"ask_sz":86,"bid_ct":2,"ask_ct":1},{"bid_px":"243.200000000","ask_px":"275.000000000","bid_sz":15,"ask_sz":16,"bid_ct":1,"ask_ct":2}],"symbol":"TSLA"}
{"ts_recv":"2024-11-01T08:00:07.120398047Z","hd":{"ts_event":"2024-11-01T08:00:07.120232340Z","rtype":10,"publisher_id":2,"instrument_id":16244},"action":"A","side":"A","depth":0,"price":"250.720000000","size":100,"flags":130,"ts_in_delta":165707,"sequence":301109,"levels":[{"bid_px":"249.890000000","ask_px":"250.720000000","bid_sz":50,"ask_sz":100,"bid_ct":1,"ask_ct":1},{"bid_px":"249.800000000","ask_px":"250.760000000","bid_sz":199,"ask_sz":50,"bid_ct":1,"ask_ct":1},{"bid_px":"249.770000000","ask_px":"253.650000000","bid_sz":50,"ask_sz":400,"bid_ct":1,"ask_ct":1},{"bid_px":"249.600000000","ask_px":"260.000000000","bid_sz":1000,"ask_sz":48,"bid_ct":1,"ask_ct":1},{"bid_px":"249.500000000","ask_px":"264.940000000","bid_sz":1000,"ask_sz":7,"bid_ct":1,"ask_ct":1},{"bid_px":"249.400000000","ask_px":"265.000000000","bid_sz":1000,"ask_sz":1,"bid_ct":1,"ask_ct":1},{"bid_px":"247.700000000","ask_px":"267.800000000","bid_sz":1000,"ask_sz":30,"bid_ct":1,"ask_ct":1},{"bid_px":"247.150000000","ask_px":"270.000000000","bid_sz":400,"ask_sz":3,"bid_ct":1,"ask_ct":1},{"bid_px":"245.000000000","ask_px":"273.000000000","bid_sz":55,"ask_sz":1,"bid_ct":2,"ask_ct":1},{"bid_px":"243.200000000","ask_px":"274.000000000","bid_sz":15,"ask_sz":86,"bid_ct":1,"ask_ct":1}],"symbol":"TSLA"}
{"ts_recv":"2024-11-01T08:00:07.132106037Z","hd":{"ts_event":"2024-11-01T08:00:07.131939916Z","rtype":10,"publisher_id":2,"instrument_id":16244},"action":"A","side":"A","depth":2,"price":"252.400000000","size":1000,"flags":130,"ts_in_delta":166121,"sequence":301116,"levels":[{"bid_px":"249.890000000","ask_px":"250.720000000","bid_sz":50,"ask_sz":100,"bid_ct":1,"ask_ct":1},{"bid_px":"249.800000000","ask_px":"250.760000000","bid_sz":199,"ask_sz":50,"bid_ct":1,"ask_ct":1},{"bid_px":"249.770000000","ask_px":"252.400000000","bid_sz":50,"ask_sz":1000,"bid_ct":1,"ask_ct":1},{"bid_px":"249.600000000","ask_px":"253.650000000","bid_sz":1000,"ask_sz":400,"bid_ct":1,"ask_ct":1},{"bid_px":"249.500000000","ask_px":"260.000000000","bid_sz":1000,"ask_sz":48,"bid_ct":1,"ask_ct":1},{"bid_px":"249.400000000","ask_px":"264.940000000","bid_sz":1000,"ask_sz":7,"bid_ct":1,"ask_ct":1},{"bid_px":"247.700000000","ask_px":"265.000000000","bid_sz":1000,"ask_sz":1,"bid_ct":1,"ask_ct":1},{"bid_px":"247.150000000","ask_px":"267.800000000","bid_sz":400,"ask_sz":30,"bid_ct":1,"ask_ct":1},{"bid_px":"245.000000000","ask_px":"270.000000000","bid_sz":55,"ask_sz":3,"bid_ct":2,"ask_ct":1},{"bid_px":"243.200000000","ask_px":"273.000000000","bid_sz":15,"ask_sz":1,"bid_ct":1,"ask_ct":1}],"symbol":"TSLA"}
{"ts_recv":"2024-11-01T08:00:07.151742419Z","hd":{"ts_event":"2024-11-01T08:00:07.151575801Z","rtype":10,"publisher_id":2,"instrument_id":16244},"action":"A","side":"B","depth":0,"price":"249.890000000","size":50,"flags":130,"ts_in_delta":166618,"sequence":301134,"levels":[{"bid_px":"249.890000000","ask_px":"250.720000000","bid_sz":100,"ask_sz":100,"bid_ct":2,"ask_ct":1},{"bid_px":"249.800000000","ask_px":"250.760000000","bid_sz":199,"ask_sz":50,"bid_ct":1,"ask_ct":1},{"bid_px":"249.770000000","ask_px":"252.400000000","bid_sz":50,"ask_sz":1000,"bid_ct":1,"ask_ct":1},{"bid_px":"249.600000000","ask_px":"253.650000000","bid_sz":1000,"ask_sz":400,"bid_ct":1,"ask_ct":1},{"bid_px":"249.500000000","ask_px":"260.000000000","bid_sz":1000,"ask_sz":48,"bid_ct":1,"ask_ct":1},{"bid_px":"249.400000000","ask_px":"264.940000000","bid_sz":1000,"ask_sz":7,"bid_ct":1,"ask_ct":1},{"bid_px":"247.700000000","ask_px":"265.000000000","bid_sz":1000,"ask_sz":1,"bid_ct":1,"ask_ct":1},{"bid_px":"247.150000000","ask_px":"267.800000000","bid_sz":400,"ask_sz":30,"bid_ct":1,"ask_ct":1},{"bid_px":"245.000000000","ask_px":"270.000000000","bid_sz":55,"ask_sz":3,"bid_ct":2,"ask_ct":1},{"bid_px":"243.200000000","ask_px":"273.000000000","bid_sz":15,"ask_sz":1,"bid_ct":1,"ask_ct":1}],"symbol":"TSLA"}
{"ts_recv":"2024-11-01T08:00:07.160619721Z","hd":{"ts_event":"2024-11-01T08:00:07.160453770Z","rtype":10,"publisher_id":2,"instrument_id":10888},"action":"A","side":"A","depth":3,"price":"445.680000000","size":3,"flags":130,"ts_in_delta":165951,"sequence":301146,"levels":[{"bid_px":"410.000000000","ask_px":"415.070000000","bid_sz":1,"ask_sz":246,"bid_ct":1,"ask_ct":1},{"bid_px":"408.960000000","ask_px":"420.000000000","bid_sz":5,"ask_sz":3,"bid_ct":1,"ask_ct":1},{"bid_px":"407.600000000","ask_px":"445.000000000","bid_sz":16,"ask_sz":25,"bid_ct":1,"ask_ct":1},{"bid_px":"406.350000000","ask_px":"445.680000000","bid_sz":2,"ask_sz":3,"bid_ct":1,"ask_ct":1},{"bid_px":"406.000000000","ask_px":"448.000000000","bid_sz":7,"ask_sz":15,"bid_ct":1,"ask_ct":2},{"bid_px":"405.000000000","ask_px":"450.000000000","bid_sz":10,"ask_sz":10,"bid_ct":1,"ask_ct":1},{"bid_px":"404.410000000","ask_px":"468.000000000","bid_sz":246,"ask_sz":65,"bid_ct":1,"ask_ct":1},{"bid_px":"400.000000000","ask_px":null,"bid_sz":10,"ask_sz":0,"bid_ct":1,"ask_ct":0},{"bid_px":"398.900000000","ask_px":null,"bid_sz":3,"ask_sz":0,"bid_ct":1,"ask_ct":0},{"bid_px":"398.000000000","ask_px":null,"bid_sz":5,"ask_sz":0,"bid_ct":1,"ask_ct":0}],"symbol":"MSFT"}
{"ts_recv":"2024-11-01T08:00:07.161215134Z","hd":{"ts_event":"2024-11-01T08:00:07.161049386Z","rtype":10,"publisher_id":2,"instrument_id":16244},"action":"C","side":"B","depth":0,"price":"249.890000000","size":50,"flags":130,"ts_in_delta":165748,"sequence":301158,"levels":[{"bid_px":"249.890000000","ask_px":"250.720000000","bid_sz":50,"ask_sz":100,"bid_ct":1,"ask_ct":1},{"bid_px":"249.800000000","ask_px":"250.760000000","bid_sz":199,"ask_sz":50,"bid_ct":1,"ask_ct":1},{"bid_px":"249.770000000","ask_px":"252.400000000","bid_sz":50,"ask_sz":1000,"bid_ct":1,"ask_ct":1},{"bid_px":"249.600000000","ask_px":"253.650000000","bid_sz":1000,"ask_sz":400,"bid_ct":1,"ask_ct":1},{"bid_px":"249.500000000","ask_px":"260.000000000","bid_sz":1000,"ask_sz":48,"bid_ct":1,"ask_ct":1},{"bid_px":"249.400000000","ask_px":"264.940000000","bid_sz":1000,"ask_sz":7,"bid_ct":1,"ask_ct":1},{"bid_px":"247.700000000","ask_px":"265.000000000","bid_sz":1000,"ask_sz":1,"bid_ct":1,"ask_ct":1},{"bid_px":"247.150000000","ask_px":"267.800000000","bid_sz":400,"ask_sz":30,"bid_ct":1,"ask_ct":1},{"bid_px":"245.000000000","ask_px":"270.000000000","bid_sz":55,"ask_sz":3,"bid_ct":2,"ask_ct":1},{"bid_px":"243.200000000","ask_px":"273.000000000","bid_sz":15,"ask_sz":1,"bid_ct":1,"ask_ct":1}],"symbol":"TSLA"}
{"ts_recv":"2024-11-01T08:00:07.161233935Z","hd":{"ts_event":"2024-11-01T08:00:07.161067733Z","rtype":10,"publisher_id":2,"instrument_id":16244},"action":"A","side":"B","depth":0,"price":"249.900000000","size":100,"flags":130,"ts_in_delta":166202,"sequence":301159,"levels":[{"bid_px":"249.900000000","ask_px":"250.720000000","bid_sz":100,"ask_sz":100,"bid_ct":1,"ask_ct":1},{"bid_px":"249.800000000","ask_px":"250.760000000","bid_sz":199,"ask_sz":50,"bid_ct":1,"ask_ct":1},{"bid_px":"249.770000000","ask_px":"252.400000000","bid_sz":50,"ask_sz":1000,"bid_ct":1,"ask_ct":1},{"bid_px":"249.600000000","ask_px":"253.650000000","bid_sz":1000,"ask_sz":400,"bid_ct":1,"ask_ct":1},{"bid_px":"249.500000000","ask_px":"260.000000000","bid_sz":1000,"ask_sz":48,"bid_ct":1,"ask_ct":1},{"bid_px":"249.400000000","ask_px":"264.940000000","bid_sz":1000,"ask_sz":7,"bid_ct":1,"ask_ct":1},{"bid_px":"247.700000000","ask_px":"265.000000000","bid_sz":1000,"ask_sz":1,"bid_ct":1,"ask_ct":1},{"bid_px":"247.150000000","ask_px":"267.800000000","bid_sz":400,"ask_sz":30,"bid_ct":1,"ask_ct":1},{"bid_px":"245.000000000","ask_px":"270.000000000","bid_sz":55,"ask_sz":3,"bid_ct":2,"ask_ct":1},{"bid_px":"243.200000000","ask_px":"273.000000000","bid_sz":15,"ask_sz":1,"bid_ct":1,"ask_ct":1}],"symbol":"TSLA"}
{"ts_recv":"2024-11-01T08:00:07.217938771Z","hd":{"ts_event":"2024-11-01T08:00:07.217772345Z","rtype":10,"publisher_id":2,"instrument_id":16244},"action":"A","side":"B","depth":0,"price":"249.910000000","size":100,"flags":130,"ts_in_delta":166426,"sequence":301395,"levels":[{"bid_px":"249.910000000","ask_px":"250.720000000","bid_sz":100,"ask_sz":100,"bid_ct":1,"ask_ct":1},{"bid_px":"249.800000000","ask_px":"250.760000000","bid_sz":199,"ask_sz":50,"bid_ct":1,"ask_ct":1},{"bid_px":"249.770000000","ask_px":"252.400000000","bid_sz":50,"ask_sz":1000,"bid_ct":1,"ask_ct":1},{"bid_px":"249.600000000","ask_px":"253.650000000","bid_sz":1000,"ask_sz":400,"bid_ct":1,"ask_ct":1},{"bid_px":"249.500000000","ask_px":"260.000000000","bid_sz":1000,"ask_sz":48,"bid_ct":1,"ask_ct":1},{"bid_px":"249.400000000","ask_px":"264.940000000","bid_sz":1000,"ask_sz":7,"bid_ct":1,"ask_ct":1},{"bid_px":"247.700000000","ask_px":"265.000000000","bid_sz":1000,"ask_sz":1,"bid_ct":1,"ask_ct":1},{"bid_px":"247.150000000","ask_px":"267.800000000","bid_sz":400,"ask_sz":30,"bid_ct":1,"ask_ct":1},{"bid_px":"245.000000000","ask_px":"270.000000000","bid_sz":55,"ask_sz":3,"bid_ct":2,"ask_ct":1},{"bid_px":"243.200000000","ask_px":"273.000000000","bid_sz":15,"ask_sz":1,"bid_ct":1,"ask_ct":1}],"symbol":"TSLA"}
{"ts_recv":"2024-11-01T08:00:07.236243107Z","hd":{"ts_event":"2024-11-01T08:00:07.236076869Z","rtype":10,"publisher_id":2,"instrument_id":16244},"action":"A","side":"B","depth":0,"price":"250.050000000","size":50,"flags":130,"ts_in_delta":166238,"sequence":301456,"levels":[{"bid_px":"250.050000000","ask_px":"250.720000000","bid_sz":50,"ask_sz":100,"bid_ct":1,"ask_ct":1},{"bid_px":"249.800000000","ask_px":"250.760000000","bid_sz":199,"ask_sz":50,"bid_ct":1,"ask_ct":1},{"bid_px":"249.770000000","ask_px":"252.400000000","bid_sz":50,"ask_sz":1000,"bid_ct":1,"ask_ct":1},{"bid_px":"249.600000000","ask_px":"253.650000000","bid_sz":1000,"ask_sz":400,"bid_ct":1,"ask_ct":1},{"bid_px":"249.500000000","ask_px":"260.000000000","bid_sz":1000,"ask_sz":48,"bid_ct":1,"ask_ct":1},{"bid_px":"249.400000000","ask_px":"264.940000000","bid_sz":1000,"ask_sz":7,"bid_ct":1,"ask_ct":1},{"bid_px":"247.700000000","ask_px":"265.000000000","bid_sz":1000,"ask_sz":1,"bid_ct":1,"ask_ct":1},{"bid_px":"247.150000000","ask_px":"267.800000000","bid_sz":400,"ask_sz":30,"bid_ct":1,"ask_ct":1},{"bid_px":"245.000000000","ask_px":"270.000000000","bid_sz":55,"ask_sz":3,"bid_ct":2,"ask_ct":1},{"bid_px":"243.200000000","ask_px":"273.000000000","bid_sz":15,"ask_sz":1,"bid_ct":1,"ask_ct":1}],"symbol":"TSLA"}
{"ts_recv":"2024-11-01T08:00:07.287823356Z","hd":{"ts_event":"2024-11-01T08:00:07.287657137Z","rtype":10,"publisher_id":2,"instrument_id":10888},"action":"A","side":"B","depth":5,"price":"405.000000000","size":5,"flags":130,"ts_in_delta":166219,"sequence":301556,"levels":[{"bid_px":"410.000000000","ask_px":"415.070000000","bid_sz":1,"ask_sz":246,"bid_ct":1,"ask_ct":1},{"bid_px":"408.960000000","ask_px":"420.000000000","bid_sz":5,"ask_sz":3,"bid_ct":1,"ask_ct":1},{"bid_px":"407.600000000","ask_px":"445.000000000","bid_sz":16,"ask_sz":25,"bid_ct":1,"ask_ct":1},{"bid_px":"406.350000000","ask_px":"445.680000000","bid_sz":2,"ask_sz":3,"bid_ct":1,"ask_ct":1},{"bid_px":"406.000000000","ask_px":"448.000000000","bid_sz":7,"ask_sz":15,"bid_ct":1,"ask_ct":2},{"bid_px":"405.000000000","ask_px":"450.000000000","bid_sz":15,"ask_sz":10,"bid_ct":2,"ask_ct":1},{"bid_px":"404.410000000","ask_px":"468.000000000","bid_sz":246,"ask_sz":65,"bid_ct":1,"ask_ct":1},{"bid_px":"400.000000000","ask_px":null,"bid_sz":10,"ask_sz":0,"bid_ct":1,"ask_ct":0},{"bid_px":"398.900000000","ask_px":null,"bid_sz":3,"ask_sz":0,"bid_ct":1,"ask_ct":0},{"bid_px":"398.000000000","ask_px":null,"bid_sz":5,"ask_sz":0,"bid_ct":1,"ask_ct":0}],"symbol":"MSFT"}
{"ts_recv":"2024-11-01T08:00:07.297644692Z","hd":{"ts_event":"2024-11-01T08:00:07.297478143Z","rtype":10,"publisher_id":2,"instrument_id":10888},"action":"A","side":"B","depth":3,"price":"407.000000000","size":2,"flags":130,"ts_in_delta":166549,"sequence":301584,"levels":[{"bid_px":"410.000000000","ask_px":"415.070000000","bid_sz":1,"ask_sz":246,"bid_ct":1,"ask_ct":1},{"bid_px":"408.960000000","ask_px":"420.000000000","bid_sz":5,"ask_sz":3,"bid_ct":1,"ask_ct":1},{"bid_px":"407.600000000","ask_px":"445.000000000","bid_sz":16,"ask_sz":25,"bid_ct":1,"ask_ct":1},{"bid_px":"407.000000000","ask_px":"445.680000000","bid_sz":2,"ask_sz":3,"bid_ct":1,"ask_ct":1},{"bid_px":"406.350000000","ask_px":"448.000000000","bid_sz":2,"ask_sz":15,"bid_ct":1,"ask_ct":2},{"bid_px":"406.000000000","ask_px":"450.000000000","bid_sz":7,"ask_sz":10,"bid_ct":1,"ask_ct":1},{"bid_px":"405.000000000","ask_px":"468.000000000","bid_sz":15,"ask_sz":65,"bid_ct":2,"ask_ct":1},{"bid_px":"404.410000000","ask_px":null,"bid_sz":246,"ask_sz":0,"bid_ct":1,"ask_ct":0},{"bid_px":"400.000000000","ask_px":null,"bid_sz":10,"ask_sz":0,"bid_ct":1,"ask_ct":0},{"bid_px":"398.900000000","ask_px":null,"bid_sz":3,"ask_sz":0,"bid_ct":1,"ask_ct":0}],"symbol":"MSFT"}
{"ts_recv":"2024-11-01T08:00:07.459226879Z","hd":{"ts_event":"2024-11-01T08:00:07.459060636Z","rtype":10,"publisher_id":2,"instrument_id":38},"action":"A","side":"A","depth":3,"price":"240.000000000","size":9,"flags":130,"ts_in_delta":166243,"sequence":302266,"levels":[{"bid_px":"221.300000000","ask_px":"224.600000000","bid_sz":1000,"ask_sz":1000,"bid_ct":1,"ask_ct":1},{"bid_px":"220.000000000","ask_px":"225.490000000","bid_sz":2,"ask_sz":442,"bid_ct":1,"ask_ct":1},{"bid_px":"219.690000000","ask_px":"234.000000000","bid_sz":442,"ask_sz":20,"bid_ct":1,"ask_ct":1},{"bid_px":"217.000000000","ask_px":"240.000000000","bid_sz":1525,"ask_sz":159,"bid_ct":1,"ask_ct":2},{"bid_px":"190.000000000","ask_px":"370.000000000","bid_sz":1,"ask_sz":100,"bid_ct":1,"ask_ct":1},{"bid_px":"180.000000000","ask_px":null,"bid_sz":1,"ask_sz":0,"bid_ct":1,"ask_ct":0},{"bid_px":"100.000000000","ask_px":null,"bid_sz":1,"ask_sz":0,"bid_ct":1,"ask_ct":0},{"bid_px":null,"ask_px":null,"bid_sz":0,"ask_sz":0,"bid_ct":0,"ask_ct":0},{"bid_px":null,"ask_px":null,"bid_sz":0,"ask_sz":0,"bid_ct":0,"ask_ct":0},{"bid_px":null,"ask_px":null,"bid_sz":0,"ask_sz":0,"bid_ct":0,"ask_ct":0}],"symbol":"AAPL"}
{"ts_recv":"2024-11-01T08:00:07.488541467Z","hd":{"ts_event":"2024-11-01T08:00:07.488374646Z","rtype":10,"publisher_id":2,"instrument_id":10888},"action":"A","side":"B","depth":8,"price":"404.000000000","size":4,"flags":130,"ts_in_delta":166821,"sequence":302286,"levels":[{"bid_px":"410.000000000","ask_px":"415.070000000","bid_sz":1,"ask_sz":246,"bid_ct":1,"ask_ct":1},{"bid_px":"408.960000000","ask_px":"420.000000000","bid_sz":5,"ask_sz":3,"bid_ct":1,"ask_ct":1},{"bid_px":"407.600000000","ask_px":"445.000000000","bid_sz":16,"ask_sz":25,"bid_ct":1,"ask_ct":1},{"bid_px":"407.000000000","ask_px":"445.680000000","bid_sz":2,"ask_sz":3,"bid_ct":1,"ask_ct":1},{"bid_px":"406.350000000","ask_px":"448.000000000","bid_sz":2,"ask_sz":15,"bid_ct":1,"ask_ct":2},{"bid_px":"406.000000000","ask_px":"450.000000000","bid_sz":7,"ask_sz":10,"bid_ct":1,"ask_ct":1},{"bid_px":"405.000000000","ask_px":"468.000000000","bid_sz":15,"ask_sz":65,"bid_ct":2,"ask_ct":1},{"bid_px":"404.410000000","ask_px":null,"bid_sz":246,"ask_sz":0,"bid_ct":1,"ask_ct":0},{"bid_px":"404.000000000","ask_px":null,"bid_sz":4,"ask_sz":0,"bid_ct":1,"ask_ct":0},{"bid_px":"400.000000000","ask_px":null,"bid_sz":10,"ask_sz":0,"bid_ct":1,"ask_ct":0}],"symbol":"MSFT"}
{"ts_recv":"2024-11-01T08:00:07.508666093Z","hd":{"ts_event":"2024-11-01T08:00:07.508499615Z","rtype":10,"publisher_id":2,"instrument_id":10888},"action":"A","side":"B","depth":9,"price":"400.000000000","size":30,"flags":130,"ts_in_delta":166478,"sequence":302298,"levels":[{"bid_px":"410.000000000","ask_px":"415.070000000","bid_sz":1,"ask_sz":246,"bid_ct":1,"ask_ct":1},{"bid_px":"408.960000000","ask_px":"420.000000000","bid_sz":5,"ask_sz":3,"bid_ct":1,"ask_ct":1},{"bid_px":"407.600000000","ask_px":"445.000000000","bid_sz":16,"ask_sz":25,"bid_ct":1,"ask_ct":1},{"bid_px":"407.000000000","ask_px":"445.680000000","bid_sz":2,"ask_sz":3,"bid_ct":1,"ask_ct":1},{"bid_px":"406.350000000","ask_px":"448.000000000","bid_sz":2,"ask_sz":15,"bid_ct":1,"ask_ct":2},{"bid_px":"406.000000000","ask_px":"450.000000000","bid_sz":7,"ask_sz":10,"bid_ct":1,"ask_ct":1},{"bid_px":"405.000000000","ask_px":"468.000000000","bid_sz":15,"ask_sz":65,"bid_ct":2,"ask_ct":1},{"bid_px":"404.410000000","ask_px":null,"bid_sz":246,"ask_sz":0,"bid_ct":1,"ask_ct":0},{"bid_px":"404.000000000","ask_px":null,"bid_sz":4,"ask_sz":0,"bid_ct":1,"ask_ct":0},{"bid_px":"400.000000000","ask_px":null,"bid_sz":40,"ask_sz":0,"bid_ct":2,"ask_ct":0}],"symbol":"MSFT"}
{"ts_recv":"2024-11-01T08:00:07.724724125Z","hd":{"ts_event":"2024-11-01T08:00:07.724557979Z","rtype":10,"publisher_id":2,"instrument_id":38},"action":"A","side":"A","depth":2,"price":"233.670000000","size":5,"flags":130,"ts_in_delta":166146,"sequence":303010,"levels":[{"bid_px":"221.300000000","ask_px":"224.600000000","bid_sz":1000,"ask_sz":1000,"bid_ct":1,"ask_ct":1},{"bid_px":"220.000000000","ask_px":"225.490000000","bid_sz":2,"ask_sz":442,"bid_ct":1,"ask_ct":1},{"bid_px":"219.690000000","ask_px":"233.670000000","bid_sz":442,"ask_sz":5,"bid_ct":1,"ask_ct":1},{"bid_px":"217.000000000","ask_px":"234.000000000","bid_sz":1525,"ask_sz":20,"bid_ct":1,"ask_ct":1},{"bid_px":"190.000000000","ask_px":"240.000000000","bid_sz":1,"ask_sz":159,"bid_ct":1,"ask_ct":2},{"bid_px":"180.000000000","ask_px":"370.000000000","bid_sz":1,"ask_sz":100,"bid_ct":1,"ask_ct":1},{"bid_px":"100.000000000","ask_px":null,"bid_sz":1,"ask_sz":0,"bid_ct":1,"ask_ct":0},{"bid_px":null,"ask_px":null,"bid_sz":0,"ask_sz":0,"bid_ct":0,"ask_ct":0},{"bid_px":null,"ask_px":null,"bid_sz":0,"ask_sz":0,"bid_ct":0,"ask_ct":0},{"bid_px":null,"ask_px":null,"bid_sz":0,"ask_sz":0,"bid_ct":0,"ask_ct":0}],"symbol":"AAPL"}
{"ts_recv":"2024-11-01T08:00:07.784791813Z","hd":{"ts_event":"2024-11-01T08:00:07.784625704Z","rtype":10,"publisher_id":2,"instrument_id":10888},"action":"A","side":"B","depth":3,"price":"407.000000000","size":2,"flags":130,"ts_in_delta":166109,"sequence":303443,"levels":[{"bid_px":"410.000000000","ask_px":"415.070000000","bid_sz":1,"ask_sz":246,"bid_ct":1,"ask_ct":1},{"bid_px":"408.960000000","ask_px":"420.000000000","bid_sz":5,"ask_sz":3,"bid_ct":1,"ask_ct":1},{"bid_px":"407.600000000","ask_px":"445.000000000","bid_sz":16,"ask_sz":25,"bid_ct":1,"ask_ct":1},{"bid_px":"407.000000000","ask_px":"445.680000000","bid_sz":4,"ask_sz":3,"bid_ct":2,"ask_ct":1},{"bid_px":"406.350000000","ask_px":"448.000000000","bid_sz":2,"ask_sz":15,"bid_ct":1,"ask_ct":2},{"bid_px":"406.000000000","ask_px":"450.000000000","bid_sz":7,"ask_sz":10,"bid_ct":1,"ask_ct":1},{"bid_px":"405.000000000","ask_px":"468.000000000","bid_sz":15,"ask_sz":65,"bid_ct":2,"ask_ct":1},{"bid_px":"404.410000000","ask_px":null,"bid_sz":246,"ask_sz":0,"bid_ct":1,"ask_ct":0},{"bid_px":"404.000000000","ask_px":null,"bid_sz":4,"ask_sz":0,"bid_ct":1,"ask_ct":0},{"bid_px":"400.000000000","ask_px":null,"bid_sz":40,"ask_sz":0,"bid_ct":2,"ask_ct":0}],"symbol":"MSFT"}
{"ts_recv":"2024-11-01T08:00:07.786660615Z","hd":{"ts_event":"2024-11-01T08:00:07.786494249Z","rtype":10,"publisher_id":2,"instrument_id":10888},"action":"A","side":"B","depth":9,"price":"400.000000000","size":10,"flags":130,"ts_in_delta":166366,"sequence":303445,"levels":[{"bid_px":"410.000000000","ask_px":"415.070000000","bid_sz":1,"ask_sz":246,"bid_ct":1,"ask_ct":1},{"bid_px":"408.960000000","ask_px":"420.000000000","bid_sz":5,"ask_sz":3,"bid_ct":1,"ask_ct":1},{"bid_px":"407.600000000","ask_px":"445.000000000","bid_sz":16,"ask_sz":25,"bid_ct":1,"ask_ct":1},{"bid_px":"407.000000000","ask_px":"445.680000000","bid_sz":4,"ask_sz":3,"bid_ct":2,"ask_ct":1},{"bid_px":"406.350000000","ask_px":"448.000000000","bid_sz":2,"ask_sz":15,"bid_ct":1,"ask_ct":2},{"bid_px":"406.000000000","ask_px":"450.000000000","bid_sz":7,"ask_sz":10,"bid_ct":1,"ask_ct":1},{"bid_px":"405.000000000","ask_px":"468.000000000","bid_sz":15,"ask_sz":65,"bid_ct":2,"ask_ct":1},{"bid_px":"404.410000000","ask_px":null,"bid_sz":246,"ask_sz":0,"bid_ct":1,"ask_ct":0},{"bid_px":"404.000000000","ask_px":null,"bid_sz":4,"ask_sz":0,"bid_ct":1,"ask_ct":0},{"bid_px":"400.000000000","ask_px":null,"bid_sz":50,"ask_sz":0,"bid_ct":3,"ask_ct":0}],"symbol":"MSFT"}
{"ts_recv":"2024-11-01T08:00:07.864801835Z","hd":{"ts_event":"2024-11-01T08:00:07.864635851Z","rtype":10,"publisher_id":2,"instrument_id":38},"action":"A","side":"B","depth":4,"price":"200.000000000","size":30,"flags":130,"ts_in_delta":165984,"sequence":303617,"levels":[{"bid_px":"221.300000000","ask_px":"224.600000000","bid_sz":1000,"ask_sz":1000,"bid_ct":1,"ask_ct":1},{"bid_px":"220.000000000","ask_px":"225.490000000","bid_sz":2,"ask_sz":442,"bid_ct":1,"ask_ct":1},{"bid_px":"219.690000000","ask_px":"233.670000000","bid_sz":442,"ask_sz":5,"bid_ct":1,"ask_ct":1},{"bid_px":"217.000000000","ask_px":"234.000000000","bid_sz":1525,"ask_sz":20,"bid_ct":1,"ask_ct":1},{"bid_px":"200.000000000","ask_px":"240.000000000","bid_sz":30,"ask_sz":159,"bid_ct":1,"ask_ct":2},{"bid_px":"190.000000000","ask_px":"370.000000000","bid_sz":1,"ask_sz":100,"bid_ct":1,"ask_ct":1},{"bid_px":"180.000000000","ask_px":null,"bid_sz":1,"ask_sz":0,"bid_ct":1,"ask_ct":0},{"bid_px":"100.000000000","ask_px":null,"bid_sz":1,"ask_sz":0,"bid_ct":1,"ask_ct":0},{"bid_px":null,"ask_px":null,"bid_sz":0,"ask_sz":0,"bid_ct":0,"ask_ct":0},{"bid_px":null,"ask_px":null,"bid_sz":0,"ask_sz":0,"bid_ct":0,"ask_ct":0}],"symbol":"AAPL"}
{"ts_recv":"2024-11-01T08:00:07.902744913Z","hd":{"ts_event":"2024-11-01T08:00:07.902579178Z","rtype":10,"publisher_id":2,"instrument_id":17709},"action":"C","side":"B","depth":1,"price":"115.320000000","size":100,"flags":130,"ts_in_delta":165735,"sequence":303753,"levels":[{"bid_px":"116.000000000","ask_px":"118.320000000","bid_sz":100,"ask_sz":856,"bid_ct":1,"ask_ct":1},{"bid_px":"115.280000000","ask_px":"118.600000000","bid_sz":856,"ask_sz":100,"bid_ct":1,"ask_ct":1},{"bid_px":null,"ask_px":"125.000000000","bid_sz":0,"ask_sz":30,"bid_ct":0,"ask_ct":1},{"bid_px":null,"ask_px":null,"bid_sz":0,"ask_sz":0,"bid_ct":0,"ask_ct":0},{"bid_px":null,"ask_px":null,"bid_sz":0,"ask_sz":0,"bid_ct":0,"ask_ct":0},{"bid_px":null,"ask_px":null,"bid_sz":0,"ask_sz":0,"bid_ct":0,"ask_ct":0},{"bid_px":null,"ask_px":null,"bid_sz":0,"ask_sz":0,"bid_ct":0,"ask_ct":0},{"bid_px":null,"ask_px":null,"bid_sz":0,"ask_sz":0,"bid_ct":0,"ask_ct":0},{"bid_px":null,"ask_px":null,"bid_sz":0,"ask_sz":0,"bid_ct":0,"ask_ct":0},{"bid_px":null,"ask_px":null,"bid_sz":0,"ask_sz":0,"bid_ct":0,"ask_ct":0}],"symbol":"XOM"}
{"ts_recv":"2024-11-01T08:00:07.902758379Z","hd":{"ts_event":"2024-11-01T08:00:07.902592403Z","rtype":10,"publisher_id":2,"instrument_id":17709},"action":"A","side":"B","depth":1,"price":"115.290000000","size":100,"flags":130,"ts_in_delta":165976,"sequence":303754,"levels":[{"bid_px":"116.000000000","ask_px":"118.320000000","bid_sz":100,"ask_sz":856,"bid_ct":1,"ask_ct":1},{"bid_px":"115.290000000","ask_px":"118.600000000","bid_sz":100,"ask_sz":100,"bid_ct":1,"ask_ct":1},{"bid_px":"115.280000000","ask_px":"125.000000000","bid_sz":856,"ask_sz":30,"bid_ct":1,"ask_ct":1},{"bid_px":null,"ask_px":null,"bid_sz":0,"ask_sz":0,"bid_ct":0,"ask_ct":0},{"bid_px":null,"ask_px":null,"bid_sz":0,"ask_sz":0,"bid_ct":0,"ask_ct":0},{"bid_px":null,"ask_px":null,"bid_sz":0,"ask_sz":0,"bid_ct":0,"ask_ct":0},{"bid_px":null,"ask_px":null,"bid_sz":0,"ask_sz":0,"bid_ct":0,"ask_ct":0},{"bid_px":null,"ask_px":null,"bid_sz":0,"ask_sz":0,"bid_ct":0,"ask_ct":0},{"bid_px":null,"ask_px":null,"bid_sz":0,"ask_sz":0,"bid_ct":0,"ask_ct":0},{"bid_px":null,"ask_px":null,"bid_sz":0,"ask_sz":0,"bid_ct":0,"ask_ct":0}],"symbol":"XOM"}
{"ts_recv":"2024-11-01T08:00:07.918045505Z","hd":{"ts_event":"2024-11-01T08:00:07.917879682Z","rtype":10,"publisher_id":2,"instrument_id":38},"action":"C","side":"A","depth":0,"price":"224.600000000","size":1000,"flags":130,"ts_in_delta":165823,"sequence":303841,"levels":[{"bid_px":"221.300000000","ask_px":"225.490000000","bid_sz":1000,"ask_sz":442,"bid_ct":1,"ask_ct":1},{"bid_px":"220.000000000","ask_px":"233.670000000","bid_sz":2,"ask_sz":5,"bid_ct":1,"ask_ct":1},{"bid_px":"219.690000000","ask_px":"234.000000000","bid_sz":442,"ask_sz":20,"bid_ct":1,"ask_ct":1},{"bid_px":"217.000000000","ask_px":"240.000000000","bid_sz":1525,"ask_sz":159,"bid_ct":1,"ask_ct":2},{"bid_px":"200.000000000","ask_px":"370.000000000","bid_sz":30,"ask_sz":100,"bid_ct":1,"ask_ct":1},{"bid_px":"190.000000000","ask_px":null,"bid_sz":1,"ask_sz":0,"bid_ct":1,"ask_ct":0},{"bid_px":"180.000000000","ask_px":null,"bid_sz":1,"ask_sz":0,"bid_ct":1,"ask_ct":0},{"bid_px":"100.000000000","ask_px":null,"bid_sz":1,"ask_sz":0,"bid_ct":1,"ask_ct":0},{"bid_px":null,"ask_px":null,"bid_sz":0,"ask_sz":0,"bid_ct":0,"ask_ct":0},{"bid_px":null,"ask_px":null,"bid_sz":0,"ask_sz":0,"bid_ct":0,"ask_ct":0}],"symbol":"AAPL"}
{"ts_recv":"2024-11-01T08:00:07.923433115Z","hd":{"ts_event":"2024-11-01T08:00:07.923266918Z","rtype":10,"publisher_id":2,"instrument_id":11667},"action":"A","side":"A","depth":1,"price":"135.000000000","size":20,"flags":130,"ts_in_delta":166197,"sequence":303861,"levels":[{"bid_px":"134.500000000","ask_px":"134.920000000","bid_sz":500,"ask_sz":1,"bid_ct":1,"ask_ct":1},{"bid_px":"134.440000000","ask_px":"135.000000000","bid_sz":100,"ask_sz":38,"bid_ct":1,"ask_ct":3},{"bid_px":"134.410000000","ask_px":"135.230000000","bid_sz":61,"ask_sz":360,"bid_ct":2,"ask_ct":1},{"bid_px":"134.210000000","ask_px":"135.300000000","bid_sz":20,"ask_sz":1000,"bid_ct":1,"ask_ct":1},{"bid_px":"134.200000000","ask_px":"135.420000000","bid_sz":3,"ask_sz":1,"bid_ct":1,"ask_ct":1},{"bid_px":"133.160000000","ask_px":"135.820000000","bid_sz":1,"ask_sz":1,"bid_ct":1,"ask_ct":1},{"bid_px":"132.660000000","ask_px":"136.100000000","bid_sz":1,"ask_sz":1000,"bid_ct":1,"ask_ct":1},{"bid_px":"132.160000000","ask_px":"136.220000000","bid_sz":1,"ask_sz":1,"bid_ct":1,"ask_ct":1},{"bid_px":"132.000000000","ask_px":"136.620000000","bid_sz":72,"ask_sz":1,"bid_ct":3,"ask_ct":1},{"bid_px":"131.660000000","ask_px":"137.060000000","bid_sz":1,"ask_sz":1,"bid_ct":1,"ask_ct":1}],"symbol":"NVDA"}
{"ts_recv":"2024-11-01T08:00:07.953906001Z","hd":{"ts_event":"2024-11-01T08:00:07.953739713Z","rtype":10,"publisher_id":2,"instrument_id":38},"action":"A","side":"A","depth":0,"price":"224.500000000","size":1000,"flags":130,"ts_in_delta":166288,"sequence":304054,"levels":[{"bid_px":"221.300000000","ask_px":"224.500000000","bid_sz":1000,"ask_sz":1000,"bid_ct":1,"ask_ct":1},{"bid_px":"220.000000000","ask_px":"225.490000000","bid_sz":2,"ask_sz":442,"bid_ct":1,"ask_ct":1},{"bid_px":"219.690000000","ask_px":"233.670000000","bid_sz":442,"ask_sz":5,"bid_ct":1,"ask_ct":1},{"bid_px":"217.000000000","ask_px":"234.000000000","bid_sz":1525,"ask_sz":20,"bid_ct":1,"ask_ct":1},{"bid_px":"200.000000000","ask_px":"240.000000000","bid_sz":30,"ask_sz":159,"bid_ct":1,"ask_ct":2},{"bid_px":"190.000000000","ask_px":"370.000000000","bid_sz":1,"ask_sz":100,"bid_ct":1,"ask_ct":1},{"bid_px":"180.000000000","ask_px":null,"bid_sz":1,"ask_sz":0,"bid_ct":1,"ask_ct":0},{"bid_px":"100.000000000","ask_px":null,"bid_sz":1,"ask_sz":0,"bid_ct":1,"ask_ct":0},{"bid_px":null,"ask_px":null,"bid_sz":0,"ask_sz":0,"bid_ct":0,"ask_ct":0},{"bid_px":null,"ask_px":null,"bid_sz":0,"ask_sz":0,"bid_ct":0,"ask_ct":0}],"symbol":"AAPL"}
{"ts_recv":"2024-11-01T08:00:07.954482341Z","hd":{"ts_event":"2024-11-01T08:00:07.954316501Z","rtype":10,"publisher_id":2,"instrument_id":38},"action":"C","side":"B","depth":0,"price":"221.300000000","size":1000,"flags":130,"ts_in_delta":165840,"sequence":304055,"levels":[{"bid_px":"220.000000000","ask_px":"224.500000000","bid_sz":2,"ask_sz":1000,"bid_ct":1,"ask_ct":1},{"bid_px":"219.690000000","ask_px":"225.490000000","bid_sz":442,"ask_sz":442,"bid_ct":1,"ask_ct":1},{"bid_px":"217.000000000","ask_px":"233.670000000","bid_sz":1525,"ask_sz":5,"bid_ct":1,"ask_ct":1},{"bid_px":"200.000000000","ask_px":"234.000000000","bid_sz":30,"ask_sz":20,"bid_ct":1,"ask_ct":1},{"bid_px":"190.000000000","ask_px":"240.000000000","bid_sz":1,"ask_sz":159,"bid_ct":1,"ask_ct":2},{"bid_px":"180.000000000","ask_px":"370.000000000","bid_sz":1,"ask_sz":100,"bid_ct":1,"ask_ct":1},{"bid_px":"100.000000000","ask_px":null,"bid_sz":1,"ask_sz":0,"bid_ct":1,"ask_ct":0},{"bid_px":null,"ask_px":null,"bid_sz":0,"ask_sz":0,"bid_ct":0,"ask_ct":0},{"bid_px":null,"ask_px":null,"bid_sz":0,"ask_sz":0,"bid_ct":0,"ask_ct":0},{"bid_px":null,"ask_px":null,"bid_sz":0,"ask_sz":0,"bid_ct":0,"ask_ct":0}],"symbol":"AAPL"}
{"ts_recv":"2024-11-01T08:00:07.965087783Z","hd":{"ts_event":"2024-11-01T08:00:07.964921701Z","rtype":10,"publisher_id":2,"instrument_id":38},"action":"A","side":"B","depth":0,"price":"221.100000000","size":1000,"flags":130,"ts_in_delta":166082,"sequence":304077,"levels":[{"bid_px":"221.100000000","ask_px":"224.500000000","bid_sz":1000,"ask_sz":1000,"bid_ct":1,"ask_ct":1},{"bid_px":"220.000000000","ask_px":"225.490000000","bid_sz":2,"ask_sz":442,"bid_ct":1,"ask_ct":1},{"bid_px":"219.690000000","ask_px":"233.670000000","bid_sz":442,"ask_sz":5,"bid_ct":1,"ask_ct":1},{"bid_px":"217.000000000","ask_px":"234.000000000","bid_sz":1525,"ask_sz":20,"bid_ct":1,"ask_ct":1},{"bid_px":"200.000000000","ask_px":"240.000000000","bid_sz":30,"ask_sz":159,"bid_ct":1,"ask_ct":2},{"bid_px":"190.000000000","ask_px":"370.000000000","bid_sz":1,"ask_sz":100,"bid_ct":1,"ask_ct":1},{"bid_px":"180.000000000","ask_px":null,"bid_sz":1,"ask_sz":0,"bid_ct":1,"ask_ct":0},{"bid_px":"100.000000000","ask_px":null,"bid_sz":1,"ask_sz":0,"bid_ct":1,"ask_ct":0},{"bid_px":null,"ask_px":null,"bid_sz":0,"ask_sz":0,"bid_ct":0,"ask_ct":0},{"bid_px":null,"ask_px":null,"bid_sz":0,"ask_sz":0,"bid_ct":0,"ask_ct":0}],"symbol":"AAPL"}
{"ts_recv":"2024-11-01T08:00:07.990508533Z","hd":{"ts_event":"2024-11-01T08:00:07.990342243Z","rtype":10,"publisher_id":2,"instrument_id":10888},"action":"A","side":"B","depth":1,"price":"408.970000000","size":12,"flags":130,"ts_in_delta":166290,"sequence":304095,"levels":[{"bid_px":"410.000000000","ask_px":"415.070000000","bid_sz":1,"ask_sz":246,"bid_ct":1,"ask_ct":1},{"bid_px":"408.970000000","ask_px":"420.000000000","bid_sz":12,"ask_sz":3,"bid_ct":1,"ask_ct":1},{"bid_px":"408.960000000","ask_px":"445.000000000","bid_sz":5,"ask_sz":25,"bid_ct":1,"ask_ct":1},{"bid_px":"407.600000000","ask_px":"445.680000000","bid_sz":16,"ask_sz":3,"bid_ct":1,"ask_ct":1},{"bid_px":"407.000000000","ask_px":"448.000000000","bid_sz":4,"ask_sz":15,"bid_ct":2,"ask_ct":2},{"bid_px":"406.350000000","ask_px":"450.000000000","bid_sz":2,"ask_sz":10,"bid_ct":1,"ask_ct":1},{"bid_px":"406.000000000","ask_px":"468.000000000","bid_sz":7,"ask_sz":65,"bid_ct":1,"ask_ct":1},{"bid_px":"405.000000000","ask_px":null,"bid_sz":15,"ask_sz":0,"bid_ct":2,"ask_ct":0},{"bid_px":"404.410000000","ask_px":null,"bid_sz":246,"ask_sz":0,"bid_ct":1,"ask_ct":0},{"bid_px":"404.000000000","ask_px":null,"bid_sz":4,"ask_sz":0,"bid_ct":1,"ask_ct":0}],"symbol":"MSFT"}
{"ts_recv":"2024-11-01T08:00:08.030593607Z","hd":{"ts_event":"2024-11-01T08:00:08.030427054Z","rtype":10,"publisher_id":2,"instrument_id":11667},"action":"A","side":"A","depth":9,"price":"136.800000000","size":100,"flags":130,"ts_in_delta":166553,"sequence":304161,"levels":[{"bid_px":"134.500000000","ask_px":"134.920000000","bid_sz":500,"ask_sz":1,"bid_ct":1,"ask_ct":1},{"bid_px":"134.440000000","ask_px":"135.000000000","bid_sz":100,"ask_sz":38,"bid_ct":1,"ask_ct":3},{"bid_px":"134.410000000","ask_px":"135.230000000","bid_sz":61,"ask_sz":360,"bid_ct":2,"ask_ct":1},{"bid_px":"134.210000000","ask_px":"135.300000000","bid_sz":20,"ask_sz":1000,"bid_ct":1,"ask_ct":1},{"bid_px":"134.200000000","ask_px":"135.420000000","bid_sz":3,"ask_sz":1,"bid_ct":1,"ask_ct":1},{"bid_px":"133.160000000","ask_px":"135.820000000","bid_sz":1,"ask_sz":1,"bid_ct":1,"ask_ct":1},{"bid_px":"132.660000000","ask_px":"136.100000000","bid_sz":1,"ask_sz":1000,"bid_ct":1,"ask_ct":1},{"bid_px":"132.160000000","ask_px":"136.220000000","bid_sz":1,"ask_sz":1,"bid_ct":1,"ask_ct":1},{"bid_px":"132.000000000","ask_px":"136.620000000","bid_sz":72,"ask_sz":1,"bid_ct":3,"ask_ct":1},{"bid_px":"131.660000000","ask_px":"136.800000000","bid_sz":1,"ask_sz":100,"bid_ct":1,"ask_ct":1}],"symbol":"NVDA"}
{"ts_recv":"2024-11-01T08:00:08.066264961Z","hd":{"ts_event":"2024-11-01T08:00:08.066098641Z","rtype":10,"publisher_id":2,"instrument_id":16244},"action":"C","side":"B","depth":0,"price":"250.050000000","size":50,"flags":130,"ts_in_delta":166320,"sequence":304212,"levels":[{"bid_px":"249.800000000","ask_px":"250.720000000","bid_sz":199,"ask_sz":100,"bid_ct":1,"ask_ct":1},{"bid_px":"249.770000000","ask_px":"250.760000000","bid_sz":50,"ask_sz":50,"bid_ct":1,"ask_ct":1},{"bid_px":"249.600000000","ask_px":"252.400000000","bid_sz":1000,"ask_sz":1000,"bid_ct":1,"ask_ct":1},{"bid_px":"249.500000000","ask_px":"253.650000000","bid_sz":1000,"ask_sz":400,"bid_ct":1,"ask_ct":1},{"bid_px":"249.400000000","ask_px":"260.000000000","bid_sz":1000,"ask_sz":48,"bid_ct":1,"ask_ct":1},{"bid_px":"247.700000000","ask_px":"264.940000000","bid_sz":1000,"ask_sz":7,"bid_ct":1,"ask_ct":1},{"bid_px":"247.150000000","ask_px":"265.000000000","bid_sz":400,"ask_sz":1,"bid_ct":1,"ask_ct":1},{"bid_px":"245.000000000","ask_px":"267.800000000","bid_sz":55,"ask_sz":30,"bid_ct":2,"ask_ct":1},{"bid_px":"243.200000000","ask_px":"270.000000000","bid_sz":15,"ask_sz":3,"bid_ct":1,"ask_ct":1},{"bid_px":"235.000000000","ask_px":"273.000000000","bid_sz":130,"ask_sz":1,"bid_ct":2,"ask_ct":1}],"symbol":"TSLA"}
{"ts_recv":"2024-11-01T08:00:08.066277251Z","hd":{"ts_event":"2024-11-01T08:00:08.066111120Z","rtype":10,"publisher_id":2,"instrument_id":16244},"action":"A","side":"B","depth":0,"price":"250.030000000","size":50,"flags":130,"ts_in_delta":166131,"sequence":304213,"levels":[{"bid_px":"250.030000000","ask_px":"250.720000000","bid_sz":50,"ask_sz":100,"bid_ct":1,"ask_ct":1},{"bid_px":"249.800000000","ask_px":"250.760000000","bid_sz":199,"ask_sz":50,"bid_ct":1,"ask_ct":1},{"bid_px":"249.770000000","ask_px":"252.400000000","bid_sz":50,"ask_sz":1000,"bid_ct":1,"ask_ct":1},{"bid_px":"249.600000000","ask_px":"253.650000000","bid_sz":1000,"ask_sz":400,"bid_ct":1,"ask_ct":1},{"bid_px":"249.500000000","ask_px":"260.000000000","bid_sz":1000,"ask_sz":48,"bid_ct":1,"ask_ct":1},{"bid_px":"249.400000000","ask_px":"264.940000000","bid_sz":1000,"ask_sz":7,"bid_ct":1,"ask_ct":1},{"bid_px":"247.700000000","ask_px":"265.000000000","bid_sz":1000,"ask_sz":1,"bid_ct":1,"ask_ct":1},{"bid_px":"247.150000000","ask_px":"267.800000000","bid_sz":400,"ask_sz":30,"bid_ct":1,"ask_ct":1},{"bid_px":"245.000000000","ask_px":"270.000000000","bid_sz":55,"ask_sz":3,"bid_ct":2,"ask_ct":1},{"bid_px":"243.200000000","ask_px":"273.000000000","bid_sz":15,"ask_sz":1,"bid_ct":1,"ask_ct":1}],"symbol":"TSLA"}
{"ts_recv":"2024-11-01T08:00:08.088377795Z","hd":{"ts_event":"2024-11-01T08:00:08.088211541Z","rtype":10,"publisher_id":2,"instrument_id":38},"action":"A","side":"A","depth":0,"price":"224.400000000","size":1000,"flags":130,"ts_in_delta":166254,"sequence":304242,"levels":[{"bid_px":"221.100000000","ask_px":"224.400000000","bid_sz":1000,"ask_sz":1000,"bid_ct":1,"ask_ct":1},{"bid_px":"220.000000000","ask_px":"224.500000000","bid_sz":2,"ask_sz":1000,"bid_ct":1,"ask_ct":1},{"bid_px":"219.690000000","ask_px":"225.490000000","bid_sz":442,"ask_sz":442,"bid_ct":1,"ask_ct":1},{"bid_px":"217.000000000","ask_px":"233.670000000","bid_sz":1525,"ask_sz":5,"bid_ct":1,"ask_ct":1},{"bid_px":"200.000000000","ask_px":"234.000000000","bid_sz":30,"ask_sz":20,"bid_ct":1,"ask_ct":1},{"bid_px":"190.000000000","ask_px":"240.000000000","bid_sz":1,"ask_sz":159,"bid_ct":1,"ask_ct":2},{"bid_px":"180.000000000","ask_px":"370.000000000","bid_sz":1,"ask_sz":100,"bid_ct":1,"ask_ct":1},{"bid_px":"100.000000000","ask_px":null,"bid_sz":1,"ask_sz":0,"bid_ct":1,"ask_ct":0},{"bid_px":null,"ask_px":null,"bid_sz":0,"ask_sz":0,"bid_ct":0,"ask_ct":0},{"bid_px":null,"ask_px":null,"bid_sz":0,"ask_sz":0,"bid_ct":0,"ask_ct":0}],"symbol":"AAPL"}
{"ts_recv":"2024-11-01T08:00:08.088836919Z","hd":{"ts_event":"2024-11-01T08:00:08.088671394Z","rtype":10,"publisher_id":2,"instrument_id":38},"action":"C","side":"A","depth":1,"price":"224.500000000","size":1000,"flags":130,"ts_in_delta":165525,"sequence":304245,"levels":[{"bid_px":"221.100000000","ask_px":"224.400000000","bid_sz":1000,"ask_sz":1000,"bid_ct":1,"ask_ct":1},{"bid_px":"220.000000000","ask_px":"225.490000000","bid_sz":2,"ask_sz":442,"bid_ct":1,"ask_ct":1},{"bid_px":"219.690000000","ask_px":"233.670000000","bid_sz":442,"ask_sz":5,"bid_ct":1,"ask_ct":1},{"bid_px":"217.000000000","ask_px":"234.000000000","bid_sz":1525,"ask_sz":20,"bid_ct":1,"ask_ct":1},{"bid_px":"200.000000000","ask_px":"240.000000000","bid_sz":30,"ask_sz":159,"bid_ct":1,"ask_ct":2},{"bid_px":"190.000000000","ask_px":"370.000000000","bid_sz":1,"ask_sz":100,"bid_ct":1,"ask_ct":1},{"bid_px":"180.000000000","ask_px":null,"bid_sz":1,"ask_sz":0,"bid_ct":1,"ask_ct":0},{"bid_px":"100.000000000","ask_px":null,"bid_sz":1,"ask_sz":0,"bid_ct":1,"ask_ct":0},{"bid_px":null,"ask_px":null,"bid_sz":0,"ask_sz":0,"bid_ct":0,"ask_ct":0},{"bid_px":null,"ask_px":null,"bid_sz":0,"ask_sz":0,"bid_ct":0,"ask_ct":0}],"symbol":"AAPL"}
{"ts_recv":"2024-11-01T08:00:08.233380835Z","hd":{"ts_event":"2024-11-01T08:00:08.233214727Z","rtype":10,"publisher_id":2,"instrument_id":10888},"action":"A","side":"B","depth":1,"price":"409.080000000","size":2,"flags":130,"ts_in_delta":166108,"sequence":304632,"levels":[{"bid_px":"410.000000000","ask_px":"415.070000000","bid_sz":1,"ask_sz":246,"bid_ct":1,"ask_ct":1},{"bid_px":"409.080000000","ask_px":"420.000000000","bid_sz":2,"ask_sz":3,"bid_ct":1,"ask_ct":1},{"bid_px":"408.970000000","ask_px":"445.000000000","bid_sz":12,"ask_sz":25,"bid_ct":1,"ask_ct":1},{"bid_px":"408.960000000","ask_px":"445.680000000","bid_sz":5,"ask_sz":3,"bid_ct":1,"ask_ct":1},{"bid_px":"407.600000000","ask_px":"448.000000000","bid_sz":16,"ask_sz":15,"bid_ct":1,"ask_ct":2},{"bid_px":"407.000000000","ask_px":"450.000000000","bid_sz":4,"ask_sz":10,"bid_ct":2,"ask_ct":1},{"bid_px":"406.350000000","ask_px":"468.000000000","bid_sz":2,"ask_sz":65,"bid_ct":1,"ask_ct":1},{"bid_px":"406.000000000","ask_px":null,"bid_sz":7,"ask_sz":0,"bid_ct":1,"ask_ct":0},{"bid_px":"405.000000000","ask_px":null,"bid_sz":15,"ask_sz":0,"bid_ct":2,"ask_ct":0},{"bid_px":"404.410000000","ask_px":null,"bid_sz":246,"ask_sz":0,"bid_ct":1,"ask_ct":0}],"symbol":"MSFT"}
{"ts_recv":"2024-11-01T08:00:08.251224635Z","hd":{"ts_event":"2024-11-01T08:00:08.251057874Z","rtype":10,"publisher_id":2,"instrument_id":38},"action":"A","side":"A","depth":4,"price":"238.760000000","size":150,"flags":128,"ts_in_delta":166761,"sequence":304717,"levels":[{"bid_px":"221.100000000","ask_px":"224.400000000","bid_sz":1000,"ask_sz":1000,"bid_ct":1,"ask_ct":1},{"bid_px":"220.000000000","ask_px":"225.490000000","bid_sz":2,"ask_sz":442,"bid_ct":1,"ask_ct":1},{"bid_px":"219.690000000","ask_px":"233.670000000","bid_sz":442,"ask_sz":5,"bid_ct":1,"ask_ct":1},{"bid_px":"217.000000000","ask_px":"234.000000000","bid_sz":1525,"ask_sz":20,"bid_ct":1,"ask_ct":1},{"bid_px":"200.000000000","ask_px":"238.760000000","bid_sz":30,"ask_sz":150,"bid_ct":1,"ask_ct":1},{"bid_px":"190.000000000","ask_px":"240.000000000","bid_sz":1,"ask_sz":159,"bid_ct":1,"ask_ct":2},{"bid_px":"180.000000000","ask_px":"370.000000000","bid_sz":1,"ask_sz":100,"bid_ct":1,"ask_ct":1},{"bid_px":"100.000000000","ask_px":null,"bid_sz":1,"ask_sz":0,"bid_ct":1,"ask_ct":0},{"bid_px":null,"ask_px":null,"bid_sz":0,"ask_sz":0,"bid_ct":0,"ask_ct":0},{"bid_px":null,"ask_px":null,"bid_sz":0,"ask_sz":0,"bid_ct":0,"ask_ct":0}],"symbol":"AAPL"}
{"ts_recv":"2024-11-01T08:00:08.257587355Z","hd":{"ts_event":"2024-11-01T08:00:08.257420922Z","rtype":10,"publisher_id":2,"instrument_id":16244},"action":"A","side":"A","depth":4,"price":"255.000000000","size":10,"flags":130,"ts_in_delta":166433,"sequence":304768,"levels":[{"bid_px":"250.030000000","ask_px":"250.720000000","bid_sz":50,"ask_sz":100,"bid_ct":1,"ask_ct":1},{"bid_px":"249.800000000","ask_px":"250.760000000","bid_sz":199,"ask_sz":50,"bid_ct":1,"ask_ct":1},{"bid_px":"249.770000000","ask_px":"252.400000000","bid_sz":50,"ask_sz":1000,"bid_ct":1,"ask_ct":1},{"bid_px":"249.600000000","ask_px":"253.650000000","bid_sz":1000,"ask_sz":400,"bid_ct":1,"ask_ct":1},{"bid_px":"249.500000000","ask_px":"255.000000000","bid_sz":1000,"ask_sz":10,"bid_ct":1,"ask_ct":1},{"bid_px":"249.400000000","ask_px":"260.000000000","bid_sz":1000,"ask_sz":48,"bid_ct":1,"ask_ct":1},{"bid_px":"247.700000000","ask_px":"264.940000000","bid_sz":1000,"ask_sz":7,"bid_ct":1,"ask_ct":1},{"bid_px":"247.150000000","ask_px":"265.000000000","bid_sz":400,"ask_sz":1,"bid_ct":1,"ask_ct":1},{"bid_px":"245.000000000","ask_px":"267.800000000","bid_sz":55,"ask_sz":30,"bid_ct":2,"ask_ct":1},{"bid_px":"243.200000000","ask_px":"270.000000000","bid_sz":15,"ask_sz":3,"bid_ct":1,"ask_ct":1}],"symbol":"TSLA"}
{"ts_recv":"2024-11-01T08:00:08.320809942Z","hd":{"ts_event":"2024-11-01T08:00:08.320643637Z","rtype":10,"publisher_id":2,"instrument_id":16244},"action":"A","side":"A","depth":9,"price":"269.580000000","size":100,"flags":130,"ts_in_delta":166305,"sequence":305132,"levels":[{"bid_px":"250.030000000","ask_px":"250.720000000","bid_sz":50,"ask_sz":100,"bid_ct":1,"ask_ct":1},{"bid_px":"249.800000000","ask_px":"250.760000000","bid_sz":199,"ask_sz":50,"bid_ct":1,"ask_ct":1},{"bid_px":"249.770000000","ask_px":"252.400000000","bid_sz":50,"ask_sz":1000,"bid_ct":1,"ask_ct":1},{"bid_px":"249.600000000","ask_px":"253.650000000","bid_sz":1000,"ask_sz":400,"bid_ct":1,"ask_ct":1},{"bid_px":"249.500000000","ask_px":"255.000000000","bid_sz":1000,"ask_sz":10,"bid_ct":1,"ask_ct":1},{"bid_px":"249.400000000","ask_px":"260.000000000","bid_sz":1000,"ask_sz":48,"bid_ct":1,"ask_ct":1},{"bid_px":"247.700000000","ask_px":"264.940000000","bid_sz":1000,"ask_sz":7,"bid_ct":1,"ask_ct":1},{"bid_px":"247.150000000","ask_px":"265.000000000","bid_sz":400,"ask_sz":1,"bid_ct":1,"ask_ct":1},{"bid_px":"245.000000000","ask_px":"267.800000000","bid_sz":55,"ask_sz":30,"bid_ct":2,"ask_ct":1},{"bid_px":"243.200000000","ask_px":"269.580000000","bid_sz":15,"ask_sz":100,"bid_ct":1,"ask_ct":1}],"symbol":"TSLA"}
{"ts_recv":"2024-11-01T08:00:08.358327478Z","hd":{"ts_event":"2024-11-01T08:00:08.358161215Z","rtype":10,"publisher_id":2,"instrument_id":38},"action":"A","side":"A","depth":4,"price":"235.000000000","size":2,"flags":130,"ts_in_delta":166263,"sequence":305273,"levels":[{"bid_px":"221.100000000","ask_px":"224.400000000","bid_sz":1000,"ask_sz":1000,"bid_ct":1,"ask_ct":1},{"bid_px":"220.000000000","ask_px":"225.490000000","bid_sz":2,"ask_sz":442,"bid_ct":1,"ask_ct":1},{"bid_px":"219.690000000","ask_px":"233.670000000","bid_sz":442,"ask_sz":5,"bid_ct":1,"ask_ct":1},{"bid_px":"217.000000000","ask_px":"234.000000000","bid_sz":1525,"ask_sz":20,"bid_ct":1,"ask_ct":1},{"bid_px":"200.000000000","ask_px":"235.000000000","bid_sz":30,"ask_sz":2,"bid_ct":1,"ask_ct":1},{"bid_px":"190.000000000","ask_px":"238.760000000","bid_sz":1,"ask_sz":150,"bid_ct":1,"ask_ct":1},{"bid_px":"180.000000000","ask_px":"240.000000000","bid_sz":1,"ask_sz":159,"bid_ct":1,"ask_ct":2},{"bid_px":"100.000000000","ask_px":"370.000000000","bid_sz":1,"ask_sz":100,"bid_ct":1,"ask_ct":1},{"bid_px":null,"ask_px":null,"bid_sz":0,"ask_sz":0,"bid_ct":0,"ask_ct":0},{"bid_px":null,"ask_px":null,"bid_sz":0,"ask_sz":0,"bid_ct":0,"ask_ct":0}],"symbol":"AAPL"}
{"ts_recv":"2024-11-01T08:00:08.391961765Z","hd":{"ts_event":"2024-11-01T08:00:08.391794566Z","rtype":10,"publisher_id":2,"instrument_id":11667},"action":"T","side":"N","depth":0,"price":"134.880000000","size":10,"flags":130,"ts_in_delta":167199,"sequence":305653,"levels":[{"bid_px":"134.500000000","ask_px":"134.920000000","bid_sz":500,"ask_sz":1,"bid_ct":1,"ask_ct":1},{"bid_px":"134.440000000","ask_px":"135.000000000","bid_sz":100,"ask_sz":38,"bid_ct":1,"ask_ct":3},{"bid_px":"134.410000000","ask_px":"135.230000000","bid_sz":61,"ask_sz":360,"bid_ct":2,"ask_ct":1},{"bid_px":"134.210000000","ask_px":"135.300000000","bid_sz":20,"ask_sz":1000,"bid_ct":1,"ask_ct":1},{"bid_px":"134.200000000","ask_px":"135.420000000","bid_sz":3,"ask_sz":1,"bid_ct":1,"ask_ct":1},{"bid_px":"133.160000000","ask_px":"135.820000000","bid_sz":1,"ask_sz":1,"bid_ct":1,"ask_ct":1},{"bid_px":"132.660000000","ask_px":"136.100000000","bid_sz":1,"ask_sz":1000,"bid_ct":1,"ask_ct":1},{"bid_px":"132.160000000","ask_px":"136.220000000","bid_sz":1,"ask_sz":1,"bid_ct":1,"ask_ct":1},{"bid_px":"132.000000000","ask_px":"136.620000000","bid_sz":72,"ask_sz":1,"bid_ct":3,"ask_ct":1},{"bid_px":"131.660000000","ask_px":"136.800000000","bid_sz":1,"ask_sz":100,"bid_ct":1,"ask_ct":1}],"symbol":"NVDA"}
{"ts_recv":"2024-11-01T08:00:08.392059432Z","hd":{"ts_event":"2024-11-01T08:00:08.391893222Z","rtype":10,"publisher_id":2,"instrument_id":11667},"action":"A","side":"B","depth":0,"price":"134.690000000","size":1,"flags":130,"ts_in_delta":166210,"sequence":305656,"levels":[{"bid_px":"134.690000000","ask_px":"134.920000000","bid_sz":1,"ask_sz":1,"bid_ct":1,"ask_ct":1},{"bid_px":"134.500000000","ask_px":"135.000000000","bid_sz":500,"ask_sz":38,"bid_ct":1,"ask_ct":3},{"bid_px":"134.440000000","ask_px":"135.230000000","bid_sz":100,"ask_sz":360,"bid_ct":1,"ask_ct":1},{"bid_px":"134.410000000","ask_px":"135.300000000","bid_sz":61,"ask_sz":1000,"bid_ct":2,"ask_ct":1},{"bid_px":"134.210000000","ask_px":"135.420000000","bid_sz":20,"ask_sz":1,"bid_ct":1,"ask_ct":1},{"bid_px":"134.200000000","ask_px":"135.820000000","bid_sz":3,"ask_sz":1,"bid_ct":1,"ask_ct":1},{"bid_px":"133.160000000","ask_px":"136.100000000","bid_sz":1,"ask_sz":1000,"bid_ct":1,"ask_ct":1},{"bid_px":"132.660000000","ask_px":"136.220000000","bid_sz":1,"ask_sz":1,"bid_ct":1,"ask_ct":1},{"bid_px":"132.160000000","ask_px":"136.620000000","bid_sz":1,"ask_sz":1,"bid_ct":1,"ask_ct":1},{"bid_px":"132.000000000","ask_px":"136.800000000","bid_sz":72,"ask_sz":100,"bid_ct":3,"ask_ct":1}],"symbol":"NVDA"}
{"ts_recv":"2024-11-01T08:00:08.392094517Z","hd":{"ts_event":"2024-11-01T08:00:08.391927988Z","rtype":10,"publisher_id":2,"instrument_id":11667},"action":"A","side":"B","depth":1,"price":"134.570000000","size":1,"flags":130,"ts_in_delta":166529,"sequence":305659,"levels":[{"bid_px":"134.690000000","ask_px":"134.920000000","bid_sz":1,"ask_sz":1,"bid_ct":1,"ask_ct":1},{"bid_px":"134.570000000","ask_px":"135.000000000","bid_sz":1,"ask_sz":38,"bid_ct":1,"ask_ct":3},{"bid_px":"134.500000000","ask_px":"135.230000000","bid_sz":500,"ask_sz":360,"bid_ct":1,"ask_ct":1},{"bid_px":"134.440000000","ask_px":"135.300000000","bid_sz":100,"ask_sz":1000,"bid_ct":1,"ask_ct":1},{"bid_px":"134.410000000","ask_px":"135.420000000","bid_sz":61,"ask_sz":1,"bid_ct":2,"ask_ct":1},{"bid_px":"134.210000000","ask_px":"135.820000000","bid_sz":20,"ask_sz":1,"bid_ct":1,"ask_ct":1},{"bid_px":"134.200000000","ask_px":"136.100000000","bid_sz":3,"ask_sz":1000,"bid_ct":1,"ask_ct":1},{"bid_px":"133.160000000","ask_px":"136.220000000","bid_sz":1,"ask_sz":1,"bid_ct":1,"ask_ct":1},{"bid_px":"132.660000000","ask_px":"136.620000000","bid_sz":1,"ask_sz":1,"bid_ct":1,"ask_ct":1},{"bid_px":"132.160000000","ask_px":"136.800000000","bid_sz":1,"ask_sz":100,"bid_ct":1,"ask_ct":1}],"symbol":"NVDA"}
{"ts_recv":"2024-11-01T08:00:08.394082611Z","hd":{"ts_event":"2024-11-01T08:00:08.393916892Z","rtype":10,"publisher_id":2,"instrument_id":11667},"action":"C","side":"B","depth":0,"price":"134.690000000","size":1,"flags":130,"ts_in_delta":165719,"sequence":305671,"levels":[{"bid_px":"134.570000000","ask_px":"134.920000000","bid_sz":1,"ask_sz":1,"bid_ct":1,"ask_ct":1},{"bid_px":"134.500000000","ask_px":"135.000000000","bid_sz":500,"ask_sz":38,"bid_ct":1,"ask_ct":3},{"bid_px":"134.440000000","ask_px":"135.230000000","bid_sz":100,"ask_sz":360,"bid_ct":1,"ask_ct":1},{"bid_px":"134.410000000","ask_px":"135.300000000","bid_sz":61,"ask_sz":1000,"bid_ct":2,"ask_ct":1},{"bid_px":"134.210000000","ask_px":"135.420000000","bid_sz":20,"ask_sz":1,"bid_ct":1,"ask_ct":1},{"bid_px":"134.200000000","ask_px":"135.820000000","bid_sz":3,"ask_sz":1,"bid_ct":1,"ask_ct":1},{"bid_px":"133.160000000","ask_px":"136.100000000","bid_sz":1,"ask_sz":1000,"bid_ct":1,"ask_ct":1},{"bid_px":"132.660000000","ask_px":"136.220000000","bid_sz":1,"ask_sz":1,"bid_ct":1,"ask_ct":1},{"bid_px":"132.160000000","ask_px":"136.620000000","bid_sz":1,"ask_sz":1,"bid_ct":1,"ask_ct":1},{"bid_px":"132.000000000","ask_px":"136.800000000","bid_sz":72,"ask_sz":100,"bid_ct":3,"ask_ct":1}],"symbol":"NVDA"}
{"ts_recv":"2024-11-01T08:00:08.398037236Z","hd":{"ts_event":"2024-11-01T08:00:08.397871271Z","rtype":10,"publisher_id":2,"instrument_id":16244},"action":"A","side":"B","depth":1,"price":"249.930000000","size":10,"flags":130,"ts_in_delta":165965,"sequence":305707,"levels":[{"bid_px":"250.030000000","ask_px":"250.720000000","bid_sz":50,"ask_sz":100,"bid_ct":1,"ask_ct":1},{"bid_px":"249.930000000","ask_px":"250.760000000","bid_sz":10,"ask_sz":50,"bid_ct":1,"ask_ct":1},{"bid_px":"249.800000000","ask_px":"252.400000000","bid_sz":199,"ask_sz":1000,"bid_ct":1,"ask_ct":1},{"bid_px":"249.770000000","ask_px":"253.650000000","bid_sz":50,"ask_sz":400,"bid_ct":1,"ask_ct":1},{"bid_px":"249.600000000","ask_px":"255.000000000","bid_sz":1000,"ask_sz":10,"bid_ct":1,"ask_ct":1},{"bid_px":"249.500000000","ask_px":"260.000000000","bid_sz":1000,"ask_sz":48,"bid_ct":1,"ask_ct":1},{"bid_px":"249.400000000","ask_px":"264.940000000","bid_sz":1000,"ask_sz":7,"bid_ct":1,"ask_ct":1},{"bid_px":"247.700000000","ask_px":"265.000000000","bid_sz":1000,"ask_sz":1,"bid_ct":1,"ask_ct":1},{"bid_px":"247.150000000","ask_px":"267.800000000","bid_sz":400,"ask_sz":30,"bid_ct":1,"ask_ct":1},{"bid_px":"245.000000000","ask_px":"269.580000000","bid_sz":55,"ask_sz":100,"bid_ct":2,"ask_ct":1}],"symbol":"TSLA"}
{"ts_recv":"2024-11-01T08:00:08.432061683Z","hd":{"ts_event":"2024-11-01T08:00:08.431895654Z","rtype":10,"publisher_id":2,"instrument_id":11667},"action":"A","side":"B","depth":4,"price":"134.380000000","size":18,"flags":130,"ts_in_delta":166029,"sequence":305898,"levels":[{"bid_px":"134.570000000","ask_px":"134.920000000","bid_sz":1,"ask_sz":1,"bid_ct":1,"ask_ct":1},{"bid_px":"134.500000000","ask_px":"135.000000000","bid_sz":500,"ask_sz":38,"bid_ct":1,"ask_ct":3},{"bid_px":"134.440000000","ask_px":"135.230000000","bid_sz":100,"ask_sz":360,"bid_ct":1,"ask_ct":1},{"bid_px":"134.410000000","ask_px":"135.300000000","bid_sz":61,"ask_sz":1000,"bid_ct":2,"ask_ct":1},{"bid_px":"134.380000000","ask_px":"135.420000000","bid_sz":18,"ask_sz":1,"bid_ct":1,"ask_ct":1},{"bid_px":"134.210000000","ask_px":"135.820000000","bid_sz":20,"ask_sz":1,"bid_ct":1,"ask_ct":1},{"bid_px":"134.200000000","ask_px":"136.100000000","bid_sz":3,"ask_sz":1000,"bid_ct":1,"ask_ct":1},{"bid_px":"133.160000000","ask_px":"136.220000000","bid_sz":1,"ask_sz":1,"bid_ct":1,"ask_ct":1},{"bid_px":"132.660000000","ask_px":"136.620000000","bid_sz":1,"ask_sz":1,"bid_ct":1,"ask_ct":1},{"bid_px":"132.160000000","ask_px":"136.800000000","bid_sz":1,"ask_sz":100,"bid_ct":1,"ask_ct":1}],"symbol":"NVDA"}
{"ts_recv":"2024-11-01T08:00:08.471253747Z","hd":{"ts_event":"2024-11-01T08:00:08.471087500Z","rtype":10,"publisher_id":2,"instrument_id":38},"action":"A","side":"A","depth":2,"price":"225.900000000","size":12,"flags":130,"ts_in_delta":166247,"sequence":306049,"levels":[{"bid_px":"221.100000000","ask_px":"224.400000000","bid_sz":1000,"ask_sz":1000,"bid_ct":1,"ask_ct":1},{"bid_px":"220.000000000","ask_px":"225.490000000","bid_sz":2,"ask_sz":442,"bid_ct":1,"ask_ct":1},{"bid_px":"219.690000000","ask_px":"225.900000000","bid_sz":442,"ask_sz":12,"bid_ct":1,"ask_ct":1},{"bid_px":"217.000000000","ask_px":"233.670000000","bid_sz":1525,"ask_sz":5,"bid_ct":1,"ask_ct":1},{"bid_px":"200.000000000","ask_px":"234.000000000","bid_sz":30,"ask_sz":20,"bid_ct":1,"ask_ct":1},{"bid_px":"190.000000000","ask_px":"235.000000000","bid_sz":1,"ask_sz":2,"bid_ct":1,"ask_ct":1},{"bid_px":"180.000000000","ask_px":"238.760000000","bid_sz":1,"ask_sz":150,"bid_ct":1,"ask_ct":1},{"bid_px":"100.000000000","ask_px":"240.000000000","bid_sz":1,"ask_sz":159,"bid_ct":1,"ask_ct":2},{"bid_px":null,"ask_px":"370.000000000","bid_sz":0,"ask_sz":100,"bid_ct":0,"ask_ct":1},{"bid_px":null,"ask_px":null,"bid_sz":0,"ask_sz":0,"bid_ct":0,"ask_ct":0}],"symbol":"AAPL"}
{"ts_recv":"2024-11-01T08:00:08.471369827Z","hd":{"ts_event":"2024-11-01T08:00:08.471203551Z","rtype":10,"publisher_id":2,"instrument_id":38},"action":"A","side":"A","depth":3,"price":"229.330000000","size":3,"flags":130,"ts_in_delta":166276,"sequence":306050,"levels":[{"bid_px":"221.100000000","ask_px":"224.400000000","bid_sz":1000,"ask_sz":1000,"bid_ct":1,"ask_ct":1},{"bid_px":"220.000000000","ask_px":"225.490000000","bid_sz":2,"ask_sz":442,"bid_ct":1,"ask_ct":1},{"bid_px":"219.690000000","ask_px":"225.900000000","bid_sz":442,"ask_sz":12,"bid_ct":1,"ask_ct":1},{"bid_px":"217.000000000","ask_px":"229.330000000","bid_sz":1525,"ask_sz":3,"bid_ct":1,"ask_ct":1},{"bid_px":"200.000000000","ask_px":"233.670000000","bid_sz":30,"ask_sz":5,"bid_ct":1,"ask_ct":1},{"bid_px":"190.000000000","ask_px":"234.000000000","bid_sz":1,"ask_sz":20,"bid_ct":1,"ask_ct":1},{"bid_px":"180.000000000","ask_px":"235.000000000","bid_sz":1,"ask_sz":2,"bid_ct":1,"ask_ct":1},{"bid_px":"100.000000000","ask_px":"238.760000000","bid_sz":1,"ask_sz":150,"bid_ct":1,"ask_ct":1},{"bid_px":null,"ask_px":"240.000000000","bid_sz":0,"ask_sz":159,"bid_ct":0,"ask_ct":2},{"bid_px":null,"ask_px":"370.000000000","bid_sz":0,"ask_sz":100,"bid_ct":0,"ask_ct":1}],"symbol":"AAPL"}
{"ts_recv":"2024-11-01T08:00:08.471449596Z","hd":{"ts_event":"2024-11-01T08:00:08.471283178Z","rtype":10,"publisher_id":2,"instrument_id":38},"action":"A","side":"A","depth":2,"price":"225.900000000","size":20,"flags":130,"ts_in_delta":166418,"sequence":306051,"levels":[{"bid_px":"221.100000000","ask_px":"224.400000000","bid_sz":1000,"ask_sz":1000,"bid_ct":1,"ask_ct":1},{"bid_px":"220.000000000","ask_px":"225.490000000","bid_sz":2,"ask_sz":442,"bid_ct":1,"ask_ct":1},{"bid_px":"219.690000000","ask_px":"225.900000000","bid_sz":442,"ask_sz":32,"bid_ct":1,"ask_ct":2},{"bid_px":"217.000000000","ask_px":"229.330000000","bid_sz":1525,"ask_sz":3,"bid_ct":1,"ask_ct":1},{"bid_px":"200.000000000","ask_px":"233.670000000","bid_sz":30,"ask_sz":5,"bid_ct":1,"ask_ct":1},{"bid_px":"190.000000000","ask_px":"234.000000000","bid_sz":1,"ask_sz":20,"bid_ct":1,"ask_ct":1},{"bid_px":"180.000000000","ask_px":"235.000000000","bid_sz":1,"ask_sz":2,"bid_ct":1,"ask_ct":1},{"bid_px":"100.000000000","ask_px":"238.760000000","bid_sz":1,"ask_sz":150,"bid_ct":1,"ask_ct":1},{"bid_px":null,"ask_px":"240.000000000","bid_sz":0,"ask_sz":159,"bid_ct":0,"ask_ct":2},{"bid_px":null,"ask_px":"370.000000000","bid_sz":0,"ask_sz":100,"bid_ct":0,"ask_ct":1}],"symbol":"AAPL"}
{"ts_recv":"2024-11-01T08:00:08.471569837Z","hd":{"ts_event":"2024-11-01T08:00:08.471403539Z","rtype":10,"publisher_id":2,"instrument_id":38},"action":"A","side":"A","depth":3,"price":"229.330000000","size":6,"flags":130,"ts_in_delta":166298,"sequence":306052,"levels":[{"bid_px":"221.100000000","ask_px":"224.400000000","bid_sz":1000,"ask_sz":1000,"bid_ct":1,"ask_ct":1},{"bid_px":"220.000000000","ask_px":"225.490000000","bid_sz":2,"ask_sz":442,"bid_ct":1,"ask_ct":1},{"bid_px":"219.690000000","ask_px":"225.900000000","bid_sz":442,"ask_sz":32,"bid_ct":1,"ask_ct":2},{"bid_px":"217.000000000","ask_px":"229.330000000","bid_sz":1525,"ask_sz":9,"bid_ct":1,"ask_ct":2},{"bid_px":"200.000000000","ask_px":"233.670000000","bid_sz":30,"ask_sz":5,"bid_ct":1,"ask_ct":1},{"bid_px":"190.000000000","ask_px":"234.000000000","bid_sz":1,"ask_sz":20,"bid_ct":1,"ask_ct":1},{"bid_px":"180.000000000","ask_px":"235.000000000","bid_sz":1,"ask_sz":2,"bid_ct":1,"ask_ct":1},{"bid_px":"100.000000000","ask_px":"238.760000000","bid_sz":1,"ask_sz":150,"bid_ct":1,"ask_ct":1},{"bid_px":null,"ask_px":"240.000000000","bid_sz":0,"ask_sz":159,"bid_ct":0,"ask_ct":2},{"bid_px":null,"ask_px":"370.000000000","bid_sz":0,"ask_sz":100,"bid_ct":0,"ask_ct":1}],"symbol":"AAPL"}
{"ts_recv":"2024-11-01T08:00:08.496635521Z","hd":{"ts_event":"2024-11-01T08:00:08.496469300Z","rtype":10,"publisher_id":2,"instrument_id":16244},"action":"A","side":"A","depth":9,"price":"268.670000000","size":100,"flags":130,"ts_in_delta":166221,"sequence":306180,"levels":[{"bid_px":"250.030000000","ask_px":"250.720000000","bid_sz":50,"ask_sz":100,"bid_ct":1,"ask_ct":1},{"bid_px":"249.930000000","ask_px":"250.760000000","bid_sz":10,"ask_sz":50,"bid_ct":1,"ask_ct":1},{"bid_px":"249.800000000","ask_px":"252.400000000","bid_sz":199,"ask_sz":1000,"bid_ct":1,"ask_ct":1},{"bid_px":"249.770000000","ask_px":"253.650000000","bid_sz":50,"ask_sz":400,"bid_ct":1,"ask_ct":1},{"bid_px":"249.600000000","ask_px":"255.000000000","bid_sz":1000,"ask_sz":10,"bid_ct":1,"ask_ct":1},{"bid_px":"249.500000000","ask_px":"260.000000000","bid_sz":1000,"ask_sz":48,"bid_ct":1,"ask_ct":1},{"bid_px":"249.400000000","ask_px":"264.940000000","bid_sz":1000,"ask_sz":7,"bid_ct":1,"ask_ct":1},{"bid_px":"247.700000000","ask_px":"265.000000000","bid_sz":1000,"ask_sz":1,"bid_ct":1,"ask_ct":1},{"bid_px":"247.150000000","ask_px":"267.800000000","bid_sz":400,"ask_sz":30,"bid_ct":1,"ask_ct":1},{"bid_px":"245.000000000","ask_px":"268.670000000","bid_sz":55,"ask_sz":100,"bid_ct":2,"ask_ct":1}],"symbol":"TSLA"}
{"ts_recv":"2024-11-01T08:00:08.501836590Z","hd":{"ts_event":"2024-11-01T08:00:08.501670252Z","rtype":10,"publisher_id":2,"instrument_id":38},"action":"A","side":"A","depth":1,"price":"225.360000000","size":1,"flags":130,"ts_in_delta":166338,"sequence":306206,"levels":[{"bid_px":"221.100000000","ask_px":"224.400000000","bid_sz":1000,"ask_sz":1000,"bid_ct":1,"ask_ct":1},{"bid_px":"220.000000000","ask_px":"225.360000000","bid_sz":2,"ask_sz":1,"bid_ct":1,"ask_ct":1},{"bid_px":"219.690000000","ask_px":"225.490000000","bid_sz":442,"ask_sz":442,"bid_ct":1,"ask_ct":1},{"bid_px":"217.000000000","ask_px":"225.900000000","bid_sz":1525,"ask_sz":32,"bid_ct":1,"ask_ct":2},{"bid_px":"200.000000000","ask_px":"229.330000000","bid_sz":30,"ask_sz":9,"bid_ct":1,"ask_ct":2},{"bid_px":"190.000000000","ask_px":"233.670000000","bid_sz":1,"ask_sz":5,"bid_ct":1,"ask_ct":1},{"bid_px":"180.000000000","ask_px":"234.000000000","bid_sz":1,"ask_sz":20,"bid_ct":1,"ask_ct":1},{"bid_px":"100.000000000","ask_px":"235.000000000","bid_sz":1,"ask_sz":2,"bid_ct":1,"ask_ct":1},{"bid_px":null,"ask_px":"238.760000000","bid_sz":0,"ask_sz":150,"bid_ct":0,"ask_ct":1},{"bid_px":null,"ask_px":"240.000000000","bid_sz":0,"ask_sz":159,"bid_ct":0,"ask_ct":2}],"symbol":"AAPL"}
{"ts_recv":"2024-11-01T08:00:08.645628209Z","hd":{"ts_event":"2024-11-01T08:00:08.645460736Z","rtype":10,"publisher_id":2,"instrument_id":11667},"action":"T","side":"B","depth":0,"price":"134.920000000","size":1,"flags":130,"ts_in_delta":167473,"sequence":307120,"levels":[{"bid_px":"134.570000000","ask_px":"134.920000000","bid_sz":1,"ask_sz":1,"bid_ct":1,"ask_ct":1},{"bid_px":"134.500000000","ask_px":"135.000000000","bid_sz":500,"ask_sz":38,"bid_ct":1,"ask_ct":3},{"bid_px":"134.440000000","ask_px":"135.230000000","bid_sz":100,"ask_sz":360,"bid_ct":1,"ask_ct":1},{"bid_px":"134.410000000","ask_px":"135.300000000","bid_sz":61,"ask_sz":1000,"bid_ct":2,"ask_ct":1},{"bid_px":"134.380000000","ask_px":"135.420000000","bid_sz":18,"ask_sz":1,"bid_ct":1,"ask_ct":1},{"bid_px":"134.210000000","ask_px":"135.820000000","bid_sz":20,"ask_sz":1,"bid_ct":1,"ask_ct":1},{"bid_px":"134.200000000","ask_px":"136.100000000","bid_sz":3,"ask_sz":1000,"bid_ct":1,"ask_ct":1},{"bid_px":"133.160000000","ask_px":"136.220000000","bid_sz":1,"ask_sz":1,"bid_ct":1,"ask_ct":1},{"bid_px":"132.660000000","ask_px":"136.620000000","bid_sz":1,"ask_sz":1,"bid_ct":1,"ask_ct":1},{"bid_px":"132.160000000","ask_px":"136.800000000","bid_sz":1,"ask_sz":100,"bid_ct":1,"ask_ct":1}],"symbol":"NVDA"}
{"ts_recv":"2024-11-01T08:00:08.645628209Z","hd":{"ts_event":"2024-11-01T08:00:08.645460736Z","rtype":10,"publisher_id":2,"instrument_id":11667},"action":"C","side":"A","depth":0,"price":"134.920000000","size":1,"flags":130,"ts_in_delta":167473,"sequence":307120,"levels":[{"bid_px":"134.570000000","ask_px":"135.000000000","bid_sz":1,"ask_sz":38,"bid_ct":1,"ask_ct":3},{"bid_px":"134.500000000","ask_px":"135.230000000","bid_sz":500,"ask_sz":360,"bid_ct":1,"ask_ct":1},{"bid_px":"134.440000000","ask_px":"135.300000000","bid_sz":100,"ask_sz":1000,"bid_ct":1,"ask_ct":1},{"bid_px":"134.410000000","ask_px":"135.420000000","bid_sz":61,"ask_sz":1,"bid_ct":2,"ask_ct":1},{"bid_px":"134.380000000","ask_px":"135.820000000","bid_sz":18,"ask_sz":1,"bid_ct":1,"ask_ct":1},{"bid_px":"134.210000000","ask_px":"136.100000000","bid_sz":20,"ask_sz":1000,"bid_ct":1,"ask_ct":1},{"bid_px":"134.200000000","ask_px":"136.220000000","bid_sz":3,"ask_sz":1,"bid_ct":1,"ask_ct":1},{"bid_px":"133.160000000","ask_px":"136.620000000","bid_sz":1,"ask_sz":1,"bid_ct":1,"ask_ct":1},{"bid_px":"132.660000000","ask_px":"136.800000000","bid_sz":1,"ask_sz":100,"bid_ct":1,"ask_ct":1},{"bid_px":"132.160000000","ask_px":"137.060000000","bid_sz":1,"ask_sz":1,"bid_ct":1,"ask_ct":1}],"symbol":"NVDA"}
{"ts_recv":"2024-11-01T08:00:08.645674070Z","hd":{"ts_event":"2024-11-01T08:00:08.645507963Z","rtype":10,"publisher_id":2,"instrument_id":11667},"action":"A","side":"B","depth":0,"price":"134.740000000","size":100,"flags":130,"ts_in_delta":166107,"sequence":307121,"levels":[{"bid_px":"134.740000000","ask_px":"135.000000000","bid_sz":100,"ask_sz":38,"bid_ct":1,"ask_ct":3},{"bid_px":"134.570000000","ask_px":"135.230000000","bid_sz":1,"ask_sz":360,"bid_ct":1,"ask_ct":1},{"bid_px":"134.500000000","ask_px":"135.300000000","bid_sz":500,"ask_sz":1000,"bid_ct":1,"ask_ct":1},{"bid_px":"134.440000000","ask_px":"135.420000000","bid_sz":100,"ask_sz":1,"bid_ct":1,"ask_ct":1},{"bid_px":"134.410000000","ask_px":"135.820000000","bid_sz":61,"ask_sz":1,"bid_ct":2,"ask_ct":1},{"bid_px":"134.380000000","ask_px":"136.100000000","bid_sz":18,"ask_sz":1000,"bid_ct":1,"ask_ct":1},{"bid_px":"134.210000000","ask_px":"136.220000000","bid_sz":20,"ask_sz":1,"bid_ct":1,"ask_ct":1},{"bid_px":"134.200000000","ask_px":"136.620000000","bid_sz":3,"ask_sz":1,"bid_ct":1,"ask_ct":1},{"bid_px":"133.160000000","ask_px":"136.800000000","bid_sz":1,"ask_sz":100,"bid_ct":1,"ask_ct":1},{"bid_px":"132.660000000","ask_px":"137.060000000","bid_sz":1,"ask_sz":1,"bid_ct":1,"ask_ct":1}],"symbol":"NVDA"}
{"ts_recv":"2024-11-01T08:00:08.645698573Z","hd":{"ts_event":"2024-11-01T08:00:08.645532373Z","rtype":10,"publisher_id":2,"instrument_id":11667},"action":"A","side":"B","depth":1,"price":"134.640000000","size":100,"flags":130,"ts_in_delta":166200,"sequence":307122,"levels":[{"bid_px":"134.740000000","ask_px":"135.000000000","bid_sz":100,"ask_sz":38,"bid_ct":1,"ask_ct":3},{"bid_px":"134.640000000","ask_px":"135.230000000","bid_sz":100,"ask_sz":360,"bid_ct":1,"ask_ct":1},{"bid_px":"134.570000000","ask_px":"135.300000000","bid_sz":1,"ask_sz":1000,"bid_ct":1,"ask_ct":1},{"bid_px":"134.500000000","ask_px":"135.420000000","bid_sz":500,"ask_sz":1,"bid_ct":1,"ask_ct":1},{"bid_px":"134.440000000","ask_px":"135.820000000","bid_sz":100,"ask_sz":1,"bid_ct":1,"ask_ct":1},{"bid_px":"134.410000000","ask_px":"136.100000000","bid_sz":61,"ask_sz":1000,"bid_ct":2,"ask_ct":1},{"bid_px":"134.380000000","ask_px":"136.220000000","bid_sz":18,"ask_sz":1,"bid_ct":1,"ask_ct":1},{"bid_px":"134.210000000","ask_px":"136.620000000","bid_sz":20,"ask_sz":1,"bid_ct":1,"ask_ct":1},{"bid_px":"134.200000000","ask_px":"136.800000000","bid_sz":3,"ask_sz":100,"bid_ct":1,"ask_ct":1},{"bid_px":"133.160000000","ask_px":"137.060000000","bid_sz":1,"ask_sz":1,"bid_ct":1,"ask_ct":1}],"symbol":"NVDA"}
{"ts_recv":"2024-11-01T08:00:08.645724092Z","hd":{"ts_event":"2024-11-01T08:00:08.645557965Z","rtype":10,"publisher_id":2,"instrument_id":11667},"action":"A","side":"B","depth":1,"price":"134.640000000","size":100,"flags":130,"ts_in_delta":166127,"sequence":307123,"levels":[{"bid_px":"134.740000000","ask_px":"135.000000000","bid_sz":100,"ask_sz":38,"bid_ct":1,"ask_ct":3},{"bid_px":"134.640000000","ask_px":"135.230000000","bid_sz":200,"ask_sz":360,"bid_ct":2,"ask_ct":1},{"bid_px":"134.570000000","ask_px":"135.300000000","bid_sz":1,"ask_sz":1000,"bid_ct":1,"ask_ct":1},{"bid_px":"134.500000000","ask_px":"135.420000000","bid_sz":500,"ask_sz":1,"bid_ct":1,"ask_ct":1},{"bid_px":"134.440000000","ask_px":"135.820000000","bid_sz":100,"ask_sz":1,"bid_ct":1,"ask_ct":1},{"bid_px":"134.410000000","ask_px":"136.100000000","bid_sz":61,"ask_sz":1000,"bid_ct":2,"ask_ct":1},{"bid_px":"134.380000000","ask_px":"136.220000000","bid_sz":18,"ask_sz":1,"bid_ct":1,"ask_ct":1},{"bid_px":"134.210000000","ask_px":"136.620000000","bid_sz":20,"ask_sz":1,"bid_ct":1,"ask_ct":1},{"bid_px":"134.200000000","ask_px":"136.800000000","bid_sz":3,"ask_sz":100,"bid_ct":1,"ask_ct":1},{"bid_px":"133.160000000","ask_px":"137.060000000","bid_sz":1,"ask_sz":1,"bid_ct":1,"ask_ct":1}],"symbol":"NVDA"}
{"ts_recv":"2024-11-01T08:00:08.645736165Z","hd":{"ts_event":"2024-11-01T08:00:08.645570332Z","rtype":10,"publisher_id":2,"instrument_id":11667},"action":"C","side":"B","depth":0,"price":"134.740000000","size":100,"flags":130,"ts_in_delta":165833,"sequence":307124,"levels":[{"bid_px":"134.640000000","ask_px":"135.000000000","bid_sz":200,"ask_sz":38,"bid_ct":2,"ask_ct":3},{"bid_px":"134.570000000","ask_px":"135.230000000","bid_sz":1,"ask_sz":360,"bid_ct":1,"ask_ct":1},{"bid_px":"134.500000000","ask_px":"135.300000000","bid_sz":500,"ask_sz":1000,"bid_ct":1,"ask_ct":1},{"bid_px":"134.440000000","ask_px":"135.420000000","bid_sz":100,"ask_sz":1,"bid_ct":1,"ask_ct":1},{"bid_px":"134.410000000","ask_px":"135.820000000","bid_sz":61,"ask_sz":1,"bid_ct":2,"ask_ct":1},{"bid_px":"134.380000000","ask_px":"136.100000000","bid_sz":18,"ask_sz":1000,"bid_ct":1,"ask_ct":1},{"bid_px":"134.210000000","ask_px":"136.220000000","bid_sz":20,"ask_sz":1,"bid_ct":1,"ask_ct":1},{"bid_px":"134.200000000","ask_px":"136.620000000","bid_sz":3,"ask_sz":1,"bid_ct":1,"ask_ct":1},{"bid_px":"133.160000000","ask_px":"136.800000000","bid_sz":1,"ask_sz":100,"bid_ct":1,"ask_ct":1},{"bid_px":"132.660000000","ask_px":"137.060000000","bid_sz":1,"ask_sz":1,"bid_ct":1,"ask_ct":1}],"symbol":"NVDA"}
{"ts_recv":"2024-11-01T08:00:08.645748164Z","hd":{"ts_event":"2024-11-01T08:00:08.645582623Z","rtype":10,"publisher_id":2,"instrument_id":11667},"action":"C","side":"B","depth":0,"price":"134.640000000","size":100,"flags":130,"ts_in_delta":165541,"sequence":307125,"levels":[{"bid_px":"134.640000000","ask_px":"135.000000000","bid_sz":100,"ask_sz":38,"bid_ct":1,"ask_ct":3},{"bid_px":"134.570000000","ask_px":"135.230000000","bid_sz":1,"ask_sz":360,"bid_ct":1,"ask_ct":1},{"bid_px":"134.500000000","ask_px":"135.300000000","bid_sz":500,"ask_sz":1000,"bid_ct":1,"ask_ct":1},{"bid_px":"134.440000000","ask_px":"135.420000000","bid_sz":100,"ask_sz":1,"bid_ct":1,"ask_ct":1},{"bid_px":"134.410000000","ask_px":"135.820000000","bid_sz":61,"ask_sz":1,"bid_ct":2,"ask_ct":1},{"bid_px":"134.380000000","ask_px":"136.100000000","bid_sz":18,"ask_sz":1000,"bid_ct":1,"ask_ct":1},{"bid_px":"134.210000000","ask_px":"136.220000000","bid_sz":20,"ask_sz":1,"bid_ct":1,"ask_ct":1},{"bid_px":"134.200000000","ask_px":"136.620000000","bid_sz":3,"ask_sz":1,"bid_ct":1,"ask_ct":1},{"bid_px":"133.160000000","ask_px":"136.800000000","bid_sz":1,"ask_sz":100,"bid_ct":1,"ask_ct":1},{"bid_px":"132.660000000","ask_px":"137.060000000","bid_sz":1,"ask_sz":1,"bid_ct":1,"ask_ct":1}],"symbol":"NVDA"}
{"ts_recv":"2024-11-01T08:00:08.645758283Z","hd":{"ts_event":"2024-11-01T08:00:08.645592746Z","rtype":10,"publisher_id":2,"instrument_id":11667},"action":"C","side":"B","depth":0,"price":"134.640000000","size":100,"flags":130,"ts_in_delta":165537,"sequence":307126,"levels":[{"bid_px":"134.570000000","ask_px":"135.000000000","bid_sz":1,"ask_sz":38,"bid_ct":1,"ask_ct":3},{"bid_px":"134.500000000","ask_px":"135.230000000","bid_sz":500,"ask_sz":360,"bid_ct":1,"ask_ct":1},{"bid_px":"134.440000000","ask_px":"135.300000000","bid_sz":100,"ask_sz":1000,"bid_ct":1,"ask_ct":1},{"bid_px":"134.410000000","ask_px":"135.420000000","bid_sz":61,"ask_sz":1,"bid_ct":2,"ask_ct":1},{"bid_px":"134.380000000","ask_px":"135.820000000","bid_sz":18,"ask_sz":1,"bid_ct":1,"ask_ct":1},{"bid_px":"134.210000000","ask_px":"136.100000000","bid_sz":20,"ask_sz":1000,"bid_ct":1,"ask_ct":1},{"bid_px":"134.200000000","ask_px":"136.220000000","bid_sz":3,"ask_sz":1,"bid_ct":1,"ask_ct":1},{"bid_px":"133.160000000","ask_px":"136.620000000","bid_sz":1,"ask_sz":1,"bid_ct":1,"ask_ct":1},{"bid_px":"132.660000000","ask_px":"136.800000000","bid_sz":1,"ask_sz":100,"bid_ct":1,"ask_ct":1},{"bid_px":"132.160000000","ask_px":"137.060000000","bid_sz":1,"ask_sz":1,"bid_ct":1,"ask_ct":1}],"symbol":"NVDA"}
{"ts_recv":"2024-11-01T08:00:08.758580117Z","hd":{"ts_event":"2024-11-01T08:00:08.758413989Z","rtype":10,"publisher_id":2,"instrument_id":12463},"action":"A","side":"A","depth":1,"price":"180.000000000","size":20,"flags":130,"ts_in_delta":166128,"sequence":307256,"levels":[{"bid_px":null,"ask_px":"171.810000000","bid_sz":0,"ask_sz":100,"bid_ct":0,"ask_ct":1},{"bid_px":null,"ask_px":"180.000000000","bid_sz":0,"ask_sz":20,"bid_ct":0,"ask_ct":1},{"bid_px":null,"ask_px":null,"bid_sz":0,"ask_sz":0,"bid_ct":0,"ask_ct":0},{"bid_px":null,"ask_px":null,"bid_sz":0,"ask_sz":0,"bid_ct":0,"ask_ct":0},{"bid_px":null,"ask_px":null,"bid_sz":0,"ask_sz":0,"bid_ct":0,"ask_ct":0},{"bid_px":null,"ask_px":null,"bid_sz":0,"ask_sz":0,"bid_ct":0,"ask_ct":0},{"bid_px":null,"ask_px":null,"bid_sz":0,"ask_sz":0,"bid_ct":0,"ask_ct":0},{"bid_px":null,"ask_px":null,"bid_sz":0,"ask_sz":0,"bid_ct":0,"ask_ct":0},{"bid_px":null,"ask_px":null,"bid_sz":0,"ask_sz":0,"bid_ct":0,"ask_ct":0},{"bid_px":null,"ask_px":null,"bid_sz":0,"ask_sz":0,"bid_ct":0,"ask_ct":0}],"symbol":"PEP"}
{"ts_recv":"2024-11-01T08:00:08.766975767Z","hd":{"ts_event":"2024-11-01T08:00:08.766809735Z","rtype":10,"publisher_id":2,"instrument_id":10888},"action":"A","side":"A","depth":7,"price":"472.000000000","size":6,"flags":130,"ts_in_delta":166032,"sequence":307258,"levels":[{"bid_px":"410.000000000","ask_px":"415.070000000","bid_sz":1,"ask_sz":246,"bid_ct":1,"ask_ct":1},{"bid_px":"409.080000000","ask_px":"420.000000000","bid_sz":2,"ask_sz":3,"bid_ct":1,"ask_ct":1},{"bid_px":"408.970000000","ask_px":"445.000000000","bid_sz":12,"ask_sz":25,"bid_ct":1,"ask_ct":1},{"bid_px":"408.960000000","ask_px":"445.680000000","bid_sz":5,"ask_sz":3,"bid_ct":1,"ask_ct":1},{"bid_px":"407.600000000","ask_px":"448.000000000","bid_sz":16,"ask_sz":15,"bid_ct":1,"ask_ct":2},{"bid_px":"407.000000000","ask_px":"450.000000000","bid_sz":4,"ask_sz":10,"bid_ct":2,"ask_ct":1},{"bid_px":"406.350000000","ask_px":"468.000000000","bid_sz":2,"ask_sz":65,"bid_ct":1,"ask_ct":1},{"bid_px":"406.000000000","ask_px":"472.000000000","bid_sz":7,"ask_sz":6,"bid_ct":1,"ask_ct":1},{"bid_px":"405.000000000","ask_px":null,"bid_sz":15,"ask_sz":0,"bid_ct":2,"ask_ct":0},{"bid_px":"404.410000000","ask_px":null,"bid_sz":246,"ask_sz":0,"bid_ct":1,"ask_ct":0}],"symbol":"MSFT"}
{"ts_recv":"2024-11-01T08:00:08.894085102Z","hd":{"ts_event":"2024-11-01T08:00:08.893919268Z","rtype":10,"publisher_id":2,"instrument_id":11667},"action":"C","side":"B","depth":0,"price":"134.570000000","size":1,"flags":130,"ts_in_delta":165834,"sequence":307508,"levels":[{"bid_px":"134.500000000","ask_px":"135.000000000","bid_sz":500,"ask_sz":38,"bid_ct":1,"ask_ct":3},{"bid_px":"134.440000000","ask_px":"135.230000000","bid_sz":100,"ask_sz":360,"bid_ct":1,"ask_ct":1},{"bid_px":"134.410000000","ask_px":"135.300000000","bid_sz":61,"ask_sz":1000,"bid_ct":2,"ask_ct":1},{"bid_px":"134.380000000","ask_px":"135.420000000","bid_sz":18,"ask_sz":1,"bid_ct":1,"ask_ct":1},{"bid_px":"134.210000000","ask_px":"135.820000000","bid_sz":20,"ask_sz":1,"bid_ct":1,"ask_ct":1},{"bid_px":"134.200000000","ask_px":"136.100000000","bid_sz":3,"ask_sz":1000,"bid_ct":1,"ask_ct":1},{"bid_px":"133.160000000","ask_px":"136.220000000","bid_sz":1,"ask_sz":1,"bid_ct":1,"ask_ct":1},{"bid_px":"132.660000000","ask_px":"136.620000000","bid_sz":1,"ask_sz":1,"bid_ct":1,"ask_ct":1},{"bid_px":"132.160000000","ask_px":"136.800000000","bid_sz":1,"ask_sz":100,"bid_ct":1,"ask_ct":1},{"bid_px":"132.000000000","ask_px":"137.060000000","bid_sz":74,"ask_sz":1,"bid_ct":4,"ask_ct":1}],"symbol":"NVDA"}
{"ts_recv":"2024-11-01T08:00:08.962661271Z","hd":{"ts_event":"2024-11-01T08:00:08.962495026Z","rtype":10,"publisher_id":2,"instrument_id":16244},"action":"A","side":"A","depth":6,"price":"262.660000000","size":56,"flags":130,"ts_in_delta":166245,"sequence":307561,"levels":[{"bid_px":"250.030000000","ask_px":"250.720000000","bid_sz":50,"ask_sz":100,"bid_ct":1,"ask_ct":1},{"bid_px":"249.930000000","ask_px":"250.760000000","bid_sz":10,"ask_sz":50,"bid_ct":1,"ask_ct":1},{"bid_px":"249.800000000","ask_px":"252.400000000","bid_sz":199,"ask_sz":1000,"bid_ct":1,"ask_ct":1},{"bid_px":"249.770000000","ask_px":"253.650000000","bid_sz":50,"ask_sz":400,"bid_ct":1,"ask_ct":1},{"bid_px":"249.600000000","ask_px":"255.000000000","bid_sz":1000,"ask_sz":10,"bid_ct":1,"ask_ct":1},{"bid_px":"249.500000000","ask_px":"260.000000000","bid_sz":1000,"ask_sz":48,"bid_ct":1,"ask_ct":1},{"bid_px":"249.400000000","ask_px":"262.660000000","bid_sz":1000,"ask_sz":56,"bid_ct":1,"ask_ct":1},{"bid_px":"247.700000000","ask_px":"264.940000000","bid_sz":1000,"ask_sz":7,"bid_ct":1,"ask_ct":1},{"bid_px":"247.150000000","ask_px":"265.000000000","bid_sz":400,"ask_sz":1,"bid_ct":1,"ask_ct":1},{"bid_px":"245.000000000","ask_px":"267.800000000","bid_sz":55,"ask_sz":30,"bid_ct":2,"ask_ct":1}],"symbol":"TSLA"}
{"ts_recv":"2024-11-01T08:00:09.003467025Z","hd":{"ts_event":"2024-11-01T08:00:09.003300754Z","rtype":10,"publisher_id":2,"instrument_id":11667},"action":"A","side":"B","depth":7,"price":"132.700000000","size":4,"flags":130,"ts_in_delta":166271,"sequence":307677,"levels":[{"bid_px":"134.500000000","ask_px":"135.000000000","bid_sz":500,"ask_sz":38,"bid_ct":1,"ask_ct":3},{"bid_px":"134.440000000","ask_px":"135.230000000","bid_sz":100,"ask_sz":360,"bid_ct":1,"ask_ct":1},{"bid_px":"134.410000000","ask_px":"135.300000000","bid_sz":61,"ask_sz":1000,"bid_ct":2,"ask_ct":1},{"bid_px":"134.380000000","ask_px":"135.420000000","bid_sz":18,"ask_sz":1,"bid_ct":1,"ask_ct":1},{"bid_px":"134.210000000","ask_px":"135.820000000","bid_sz":20,"ask_sz":1,"bid_ct":1,"ask_ct":1},{"bid_px":"134.200000000","ask_px":"136.100000000","bid_sz":3,"ask_sz":1000,"bid_ct":1,"ask_ct":1},{"bid_px":"133.160000000","ask_px":"136.220000000","bid_sz":1,"ask_sz":1,"bid_ct":1,"ask_ct":1},{"bid_px":"132.700000000","ask_px":"136.620000000","bid_sz":4,"ask_sz":1,"bid_ct":1,"ask_ct":1},{"bid_px":"132.660000000","ask_px":"136.800000000","bid_sz":1,"ask_sz":100,"bid_ct":1,"ask_ct":1},{"bid_px":"132.160000000","ask_px":"137.060000000","bid_sz":1,"ask_sz":1,"bid_ct":1,"ask_ct":1}],"symbol":"NVDA"}
{"ts_recv":"2024-11-01T08:00:09.024031465Z","hd":{"ts_event":"2024-11-01T08:00:09.023865393Z","rtype":10,"publisher_id":2,"instrument_id":11667},"action":"A","side":"A","depth":7,"price":"136.400000000","size":11,"flags":130,"ts_in_delta":166072,"sequence":307719,"levels":[{"bid_px":"134.500000000","ask_px":"135.000000000","bid_sz":500,"ask_sz":38,"bid_ct":1,"ask_ct":3},{"bid_px":"134.440000000","ask_px":"135.230000000","bid_sz":100,"ask_sz":360,"bid_ct":1,"ask_ct":1},{"bid_px":"134.410000000","ask_px":"135.300000000","bid_sz":61,"ask_sz":1000,"bid_ct":2,"ask_ct":1},{"bid_px":"134.380000000","ask_px":"135.420000000","bid_sz":18,"ask_sz":1,"bid_ct":1,"ask_ct":1},{"bid_px":"134.210000000","ask_px":"135.820000000","bid_sz":20,"ask_sz":1,"bid_ct":1,"ask_ct":1},{"bid_px":"134.200000000","ask_px":"136.100000000","bid_sz":3,"ask_sz":1000,"bid_ct":1,"ask_ct":1},{"bid_px":"133.160000000","ask_px":"136.220000000","bid_sz":1,"ask_sz":1,"bid_ct":1,"ask_ct":1},{"bid_px":"132.700000000","ask_px":"136.400000000","bid_sz":4,"ask_sz":11,"bid_ct":1,"ask_ct":1},{"bid_px":"132.660000000","ask_px":"136.620000000","bid_sz":1,"ask_sz":1,"bid_ct":1,"ask_ct":1},{"bid_px":"132.160000000","ask_px":"136.800000000","bid_sz":1,"ask_sz":100,"bid_ct":1,"ask_ct":1}],"symbol":"NVDA"}
{"ts_recv":"2024-11-01T08:00:09.024229880Z","hd":{"ts_event":"2024-11-01T08:00:09.024063811Z","rtype":10,"publisher_id":2,"instrument_id":11667},"action":"A","side":"A","depth":5,"price":"135.990000000","size":20,"flags":130,"ts_in_delta":166069,"sequence":307721,"levels":[{"bid_px":"134.500000000","ask_px":"135.000000000","bid_sz":500,"ask_sz":38,"bid_ct":1,"ask_ct":3},{"bid_px":"134.440000000","ask_px":"135.230000000","bid_sz":100,"ask_sz":360,"bid_ct":1,"ask_ct":1},{"bid_px":"134.410000000","ask_px":"135.300000000","bid_sz":61,"ask_sz":1000,"bid_ct":2,"ask_ct":1},{"bid_px":"134.380000000","ask_px":"135.420000000","bid_sz":18,"ask_sz":1,"bid_ct":1,"ask_ct":1},{"bid_px":"134.210000000","ask_px":"135.820000000","bid_sz":20,"ask_sz":1,"bid_ct":1,"ask_ct":1},{"bid_px":"134.200000000","ask_px":"135.990000000","bid_sz":3,"ask_sz":20,"bid_ct":1,"ask_ct":1},{"bid_px":"133.160000000","ask_px":"136.100000000","bid_sz":1,"ask_sz":1000,"bid_ct":1,"ask_ct":1},{"bid_px":"132.700000000","ask_px":"136.220000000","bid_sz":4,"ask_sz":1,"bid_ct":1,"ask_ct":1},{"bid_px":"132.660000000","ask_px":"136.400000000","bid_sz":1,"ask_sz":11,"bid_ct":1,"ask_ct":1},{"bid_px":"132.160000000","ask_px":"136.620000000","bid_sz":1,"ask_sz":1,"bid_ct":1,"ask_ct":1}],"symbol":"NVDA"}
