{"ts_recv":"2024-11-01T08:00:02.659429599Z","hd":{"ts_event":"2024-11-01T08:00:02.659263539Z","rtype":10,"publisher_id":2,"instrument_id":16244},"action":"A","side":"B","depth":2,"price":"249.500000000","size":1000,"flags":130,"ts_in_delta":166060,"sequence":292454,"levels":[{"bid_px":"249.700000000","ask_px":"250.940000000","bid_sz":1000,"ask_sz":200,"bid_ct":1,"ask_ct":2},{"bid_px":"249.600000000","ask_px":"252.300000000","bid_sz":1000,"ask_sz":1000,"bid_ct":1,"ask_ct":1},{"bid_px":"249.500000000","ask_px":"253.650000000","bid_sz":1000,"ask_sz":400,"bid_ct":1,"ask_ct":1},{"bid_px":"247.150000000","ask_px":"960.000000000","bid_sz":400,"ask_sz":25,"bid_ct":1,"ask_ct":1},{"bid_px":"235.000000000","ask_px":null,"bid_sz":100,"ask_sz":0,"bid_ct":1,"ask_ct":0},{"bid_px":"203.000000000","ask_px":null,"bid_sz":2,"ask_sz":0,"bid_ct":1,"ask_ct":0},{"bid_px":null,"ask_px":null,"bid_sz":0,"ask_sz":0,"bid_ct":0,"ask_ct":0},{"bid_px":null,"ask_px":null,"bid_sz":0,"ask_sz":0,"bid_ct":0,"ask_ct":0},{"bid_px":null,"ask_px":null,"bid_sz":0,"ask_sz":0,"bid_ct":0,"ask_ct":0},{"bid_px":null,"ask_px":null,"bid_sz":0,"ask_sz":0,"bid_ct":0,"ask_ct":0}],"symbol":"TSLA"}
{"ts_recv":"2024-11-01T08:00:02.690780625Z","hd":{"ts_event":"2024-11-01T08:00:02.690614817Z","rtype":10,"publisher_id":2,"instrument_id":16244},"action":"C","side":"B","depth":2,"price":"249.500000000","size":1000,"flags":130,"ts_in_delta":165808,"sequence":292490,"levels":[{"bid_px":"249.700000000","ask_px":"250.940000000","bid_sz":1000,"ask_sz":200,"bid_ct":1,"ask_ct":2},{"bid_px":"249.600000000","ask_px":"252.300000000","bid_sz":1000,"ask_sz":1000,"bid_ct":1,"ask_ct":1},{"bid_px":"247.150000000","ask_px":"253.650000000","bid_sz":400,"ask_sz":400,"bid_ct":1,"ask_ct":1},{"bid_px":"235.000000000","ask_px":"960.000000000","bid_sz":100,"ask_sz":25,"bid_ct":1,"ask_ct":1},{"bid_px":"203.000000000","ask_px":null,"bid_sz":2,"ask_sz":0,"bid_ct":1,"ask_ct":0},{"bid_px":null,"ask_px":null,"bid_sz":0,"ask_sz":0,"bid_ct":0,"ask_ct":0},{"bid_px":null,"ask_px":null,"bid_sz":0,"ask_sz":0,"bid_ct":0,"ask_ct":0},{"bid_px":null,"ask_px":null,"bid_sz":0,"ask_sz":0,"bid_ct":0,"ask_ct":0},{"bid_px":null,"ask_px":null,"bid_sz":0,"ask_sz":0,"bid_ct":0,"ask_ct":0},{"bid_px":null,"ask_px":null,"bid_sz":0,"ask_sz":0,"bid_ct":0,"ask_ct":0}],"symbol":"TSLA"}
{"ts_recv":"2024-11-01T08:00:02.701304590Z","hd":{"ts_event":"2024-11-01T08:00:02.701138373Z","rtype":10,"publisher_id":2,"instrument_id":16244},"action":"A","side":"B","depth":0,"price":"249.800000000","size":1000,"flags":130,"ts_in_delta":166217,"sequence":292499,"levels":[{"bid_px":"249.800000000","ask_px":"250.940000000","bid_sz":1000,"ask_sz":200,"bid_ct":1,"ask_ct":2},{"bid_px":"249.700000000","ask_px":"252.300000000","bid_sz":1000,"ask_sz":1000,"bid_ct":1,"ask_ct":1},{"bid_px":"249.600000000","ask_px":"253.650000000","bid_sz":1000,"ask_sz":400,"bid_ct":1,"ask_ct":1},{"bid_px":"247.150000000","ask_px":"960.000000000","bid_sz":400,"ask_sz":25,"bid_ct":1,"ask_ct":1},{"bid_px":"235.000000000","ask_px":null,"bid_sz":100,"ask_sz":0,"bid_ct":1,"ask_ct":0},{"bid_px":"203.000000000","ask_px":null,"bid_sz":2,"ask_sz":0,"bid_ct":1,"ask_ct":0},{"bid_px":null,"ask_px":null,"bid_sz":0,"ask_sz":0,"bid_ct":0,"ask_ct":0},{"bid_px":null,"ask_px":null,"bid_sz":0,"ask_sz":0,"bid_ct":0,"ask_ct":0},{"bid_px":null,"ask_px":null,"bid_sz":0,"ask_sz":0,"bid_ct":0,"ask_ct":0},{"bid_px":null,"ask_px":null,"bid_sz":0,"ask_sz":0,"bid_ct":0,"ask_ct":0}],"symbol":"TSLA"}
{"ts_recv":"2024-11-01T08:00:02.701353470Z","hd":{"ts_event":"2024-11-01T08:00:02.701187733Z","rtype":10,"publisher_id":2,"instrument_id":16244},"action":"C","side":"B","depth":1,"price":"249.700000000","size":1000,"flags":130,"ts_in_delta":165737,"sequence":292500,"levels":[{"bid_px":"249.800000000","ask_px":"250.940000000","bid_sz":1000,"ask_sz":200,"bid_ct":1,"ask_ct":2},{"bid_px":"249.600000000","ask_px":"252.300000000","bid_sz":1000,"ask_sz":1000,"bid_ct":1,"ask_ct":1},{"bid_px":"247.150000000","ask_px":"253.650000000","bid_sz":400,"ask_sz":400,"bid_ct":1,"ask_ct":1},{"bid_px":"235.000000000","ask_px":"960.000000000","bid_sz":100,"ask_sz":25,"bid_ct":1,"ask_ct":1},{"bid_px":"203.000000000","ask_px":null,"bid_sz":2,"ask_sz":0,"bid_ct":1,"ask_ct":0},{"bid_px":null,"ask_px":null,"bid_sz":0,"ask_sz":0,"bid_ct":0,"ask_ct":0},{"bid_px":null,"ask_px":null,"bid_sz":0,"ask_sz":0,"bid_ct":0,"ask_ct":0},{"bid_px":null,"ask_px":null,"bid_sz":0,"ask_sz":0,"bid_ct":0,"ask_ct":0},{"bid_px":null,"ask_px":null,"bid_sz":0,"ask_sz":0,"bid_ct":0,"ask_ct":0},{"bid_px":null,"ask_px":null,"bid_sz":0,"ask_sz":0,"bid_ct":0,"ask_ct":0}],"symbol":"TSLA"}
{"ts_recv":"2024-11-01T08:00:02.710429594Z","hd":{"ts_event":"2024-11-01T08:00:02.710263894Z","rtype":10,"publisher_id":2,"instrument_id":16244},"action":"C","side":"A","depth":0,"price":"250.940000000","size":100,"flags":130,"ts_in_delta":165700,"sequence":292504,"levels":[{"bid_px":"249.800000000","ask_px":"250.940000000","bid_sz":1000,"ask_sz":100,"bid_ct":1,"ask_ct":1},{"bid_px":"249.600000000","ask_px":"252.300000000","bid_sz":1000,"ask_sz":1000,"bid_ct":1,"ask_ct":1},{"bid_px":"247.150000000","ask_px":"253.650000000","bid_sz":400,"ask_sz":400,"bid_ct":1,"ask_ct":1},{"bid_px":"235.000000000","ask_px":"960.000000000","bid_sz":100,"ask_sz":25,"bid_ct":1,"ask_ct":1},{"bid_px":"203.000000000","ask_px":null,"bid_sz":2,"ask_sz":0,"bid_ct":1,"ask_ct":0},{"bid_px":null,"ask_px":null,"bid_sz":0,"ask_sz":0,"bid_ct":0,"ask_ct":0},{"bid_px":null,"ask_px":null,"bid_sz":0,"ask_sz":0,"bid_ct":0,"ask_ct":0},{"bid_px":null,"ask_px":null,"bid_sz":0,"ask_sz":0,"bid_ct":0,"ask_ct":0},{"bid_px":null,"ask_px":null,"bid_sz":0,"ask_sz":0,"bid_ct":0,"ask_ct":0},{"bid_px":null,"ask_px":null,"bid_sz":0,"ask_sz":0,"bid_ct":0,"ask_ct":0}],"symbol":"TSLA"}
{"ts_recv":"2024-11-01T08:00:02.710450991Z","hd":{"ts_event":"2024-11-01T08:00:02.710284708Z","rtype":10,"publisher_id":2,"instrument_id":16244},"action":"A","side":"A","depth":0,"price":"250.830000000","size":100,"flags":130,"ts_in_delta":166283,"sequence":292505,"levels":[{"bid_px":"249.800000000","ask_px":"250.830000000","bid_sz":1000,"ask_sz":100,"bid_ct":1,"ask_ct":1},{"bid_px":"249.600000000","ask_px":"252.300000000","bid_sz":1000,"ask_sz":1000,"bid_ct":1,"ask_ct":1},{"bid_px":"247.150000000","ask_px":"253.650000000","bid_sz":400,"ask_sz":400,"bid_ct":1,"ask_ct":1},{"bid_px":"235.000000000","ask_px":"960.000000000","bid_sz":100,"ask_sz":25,"bid_ct":1,"ask_ct":1},{"bid_px":"203.000000000","ask_px":null,"bid_sz":2,"ask_sz":0,"bid_ct":1,"ask_ct":0},{"bid_px":null,"ask_px":null,"bid_sz":0,"ask_sz":0,"bid_ct":0,"ask_ct":0},{"bid_px":null,"ask_px":null,"bid_sz":0,"ask_sz":0,"bid_ct":0,"ask_ct":0},{"bid_px":null,"ask_px":null,"bid_sz":0,"ask_sz":0,"bid_ct":0,"ask_ct":0},{"bid_px":null,"ask_px":null,"bid_sz":0,"ask_sz":0,"bid_ct":0,"ask_ct":0},{"bid_px":null,"ask_px":null,"bid_sz":0,"ask_sz":0,"bid_ct":0,"ask_ct":0}],"symbol":"TSLA"}
{"ts_recv":"2024-11-01T08:00:02.710481000Z","hd":{"ts_event":"2024-11-01T08:00:02.710313713Z","rtype":10,"publisher_id":2,"instrument_id":16244},"action":"A","side":"B","depth":1,"price":"249.600000000","size":50,"flags":130,"ts_in_delta":167287,"sequence":292506,"levels":[{"bid_px":"249.800000000","ask_px":"250.830000000","bid_sz":1000,"ask_sz":100,"bid_ct":1,"ask_ct":1},{"bid_px":"249.600000000","ask_px":"252.300000000","bid_sz":1050,"ask_sz":1000,"bid_ct":2,"ask_ct":1},{"bid_px":"247.150000000","ask_px":"253.650000000","bid_sz":400,"ask_sz":400,"bid_ct":1,"ask_ct":1},{"bid_px":"235.000000000","ask_px":"960.000000000","bid_sz":100,"ask_sz":25,"bid_ct":1,"ask_ct":1},{"bid_px":"203.000000000","ask_px":null,"bid_sz":2,"ask_sz":0,"bid_ct":1,"ask_ct":0},{"bid_px":null,"ask_px":null,"bid_sz":0,"ask_sz":0,"bid_ct":0,"ask_ct":0},{"bid_px":null,"ask_px":null,"bid_sz":0,"ask_sz":0,"bid_ct":0,"ask_ct":0},{"bid_px":null,"ask_px":null,"bid_sz":0,"ask_sz":0,"bid_ct":0,"ask_ct":0},{"bid_px":null,"ask_px":null,"bid_sz":0,"ask_sz":0,"bid_ct":0,"ask_ct":0},{"bid_px":null,"ask_px":null,"bid_sz":0,"ask_sz":0,"bid_ct":0,"ask_ct":0}],"symbol":"TSLA"}
{"ts_recv":"2024-11-01T08:00:02.721528719Z","hd":{"ts_event":"2024-11-01T08:00:02.721362015Z","rtype":10,"publisher_id":2,"instrument_id":16244},"action":"A","side":"B","depth":2,"price":"248.700000000","size":1000,"flags":130,"ts_in_delta":166704,"sequence":292528,"levels":[{"bid_px":"249.800000000","ask_px":"250.830000000","bid_sz":1000,"ask_sz":100,"bid_ct":1,"ask_ct":1},{"bid_px":"249.600000000","ask_px":"252.300000000","bid_sz":1050,"ask_sz":1000,"bid_ct":2,"ask_ct":1},{"bid_px":"248.700000000","ask_px":"253.650000000","bid_sz":1000,"ask_sz":400,"bid_ct":1,"ask_ct":1},{"bid_px":"247.150000000","ask_px":"960.000000000","bid_sz":400,"ask_sz":25,"bid_ct":1,"ask_ct":1},{"bid_px":"235.000000000","ask_px":null,"bid_sz":100,"ask_sz":0,"bid_ct":1,"ask_ct":0},{"bid_px":"203.000000000","ask_px":null,"bid_sz":2,"ask_sz":0,"bid_ct":1,"ask_ct":0},{"bid_px":null,"ask_px":null,"bid_sz":0,"ask_sz":0,"bid_ct":0,"ask_ct":0},{"bid_px":null,"ask_px":null,"bid_sz":0,"ask_sz":0,"bid_ct":0,"ask_ct":0},{"bid_px":null,"ask_px":null,"bid_sz":0,"ask_sz":0,"bid_ct":0,"ask_ct":0},{"bid_px":null,"ask_px":null,"bid_sz":0,"ask_sz":0,"bid_ct":0,"ask_ct":0}],"symbol":"TSLA"}
{"ts_recv":"2024-11-01T08:00:02.721574031Z","hd":{"ts_event":"2024-11-01T08:00:02.721408022Z","rtype":10,"publisher_id":2,"instrument_id":16244},"action":"A","side":"B","depth":1,"price":"249.600000000","size":50,"flags":130,"ts_in_delta":166009,"sequence":292529,"levels":[{"bid_px":"249.800000000","ask_px":"250.830000000","bid_sz":1000,"ask_sz":100,"bid_ct":1,"ask_ct":1},{"bid_px":"249.600000000","ask_px":"252.300000000","bid_sz":1100,"ask_sz":1000,"bid_ct":3,"ask_ct":1},{"bid_px":"248.700000000","ask_px":"253.650000000","bid_sz":1000,"ask_sz":400,"bid_ct":1,"ask_ct":1},{"bid_px":"247.150000000","ask_px":"960.000000000","bid_sz":400,"ask_sz":25,"bid_ct":1,"ask_ct":1},{"bid_px":"235.000000000","ask_px":null,"bid_sz":100,"ask_sz":0,"bid_ct":1,"ask_ct":0},{"bid_px":"203.000000000","ask_px":null,"bid_sz":2,"ask_sz":0,"bid_ct":1,"ask_ct":0},{"bid_px":null,"ask_px":null,"bid_sz":0,"ask_sz":0,"bid_ct":0,"ask_ct":0},{"bid_px":null,"ask_px":null,"bid_sz":0,"ask_sz":0,"bid_ct":0,"ask_ct":0},{"bid_px":null,"ask_px":null,"bid_sz":0,"ask_sz":0,"bid_ct":0,"ask_ct":0},{"bid_px":null,"ask_px":null,"bid_sz":0,"ask_sz":0,"bid_ct":0,"ask_ct":0}],"symbol":"TSLA"}
{"ts_recv":"2024-11-01T08:00:02.721791756Z","hd":{"ts_event":"2024-11-01T08:00:02.721626204Z","rtype":10,"publisher_id":2,"instrument_id":16244},"action":"C","side":"B","depth":2,"price":"248.700000000","size":1000,"flags":130,"ts_in_delta":165552,"sequence":292531,"levels":[{"bid_px":"249.800000000","ask_px":"250.830000000","bid_sz":1000,"ask_sz":100,"bid_ct":1,"ask_ct":1},{"bid_px":"249.600000000","ask_px":"252.300000000","bid_sz":1100,"ask_sz":1000,"bid_ct":3,"ask_ct":1},{"bid_px":"247.150000000","ask_px":"253.650000000","bid_sz":400,"ask_sz":400,"bid_ct":1,"ask_ct":1},{"bid_px":"235.000000000","ask_px":"960.000000000","bid_sz":100,"ask_sz":25,"bid_ct":1,"ask_ct":1},{"bid_px":"203.000000000","ask_px":null,"bid_sz":2,"ask_sz":0,"bid_ct":1,"ask_ct":0},{"bid_px":null,"ask_px":null,"bid_sz":0,"ask_sz":0,"bid_ct":0,"ask_ct":0},{"bid_px":null,"ask_px":null,"bid_sz":0,"ask_sz":0,"bid_ct":0,"ask_ct":0},{"bid_px":null,"ask_px":null,"bid_sz":0,"ask_sz":0,"bid_ct":0,"ask_ct":0},{"bid_px":null,"ask_px":null,"bid_sz":0,"ask_sz":0,"bid_ct":0,"ask_ct":0},{"bid_px":null,"ask_px":null,"bid_sz":0,"ask_sz":0,"bid_ct":0,"ask_ct":0}],"symbol":"TSLA"}
{"ts_recv":"2024-11-01T08:00:02.732345694Z","hd":{"ts_event":"2024-11-01T08:00:02.732179390Z","rtype":10,"publisher_id":2,"instrument_id":16244},"action":"A","side":"B","depth":2,"price":"248.500000000","size":1000,"flags":130,"ts_in_delta":166304,"sequence":292547,"levels":[{"bid_px":"249.800000000","ask_px":"250.830000000","bid_sz":1000,"ask_sz":100,"bid_ct":1,"ask_ct":1},{"bid_px":"249.600000000","ask_px":"252.300000000","bid_sz":1100,"ask_sz":1000,"bid_ct":3,"ask_ct":1},{"bid_px":"248.500000000","ask_px":"253.650000000","bid_sz":1000,"ask_sz":400,"bid_ct":1,"ask_ct":1},{"bid_px":"247.150000000","ask_px":"960.000000000","bid_sz":400,"ask_sz":25,"bid_ct":1,"ask_ct":1},{"bid_px":"235.000000000","ask_px":null,"bid_sz":100,"ask_sz":0,"bid_ct":1,"ask_ct":0},{"bid_px":"203.000000000","ask_px":null,"bid_sz":2,"ask_sz":0,"bid_ct":1,"ask_ct":0},{"bid_px":null,"ask_px":null,"bid_sz":0,"ask_sz":0,"bid_ct":0,"ask_ct":0},{"bid_px":null,"ask_px":null,"bid_sz":0,"ask_sz":0,"bid_ct":0,"ask_ct":0},{"bid_px":null,"ask_px":null,"bid_sz":0,"ask_sz":0,"bid_ct":0,"ask_ct":0},{"bid_px":null,"ask_px":null,"bid_sz":0,"ask_sz":0,"bid_ct":0,"ask_ct":0}],"symbol":"TSLA"}
{"ts_recv":"2024-11-01T08:00:02.769927085Z","hd":{"ts_event":"2024-11-01T08:00:02.769760727Z","rtype":10,"publisher_id":2,"instrument_id":16244},"action":"C","side":"B","depth":1,"price":"249.600000000","size":50,"flags":130,"ts_in_delta":166358,"sequence":292585,"levels":[{"bid_px":"249.800000000","ask_px":"250.830000000","bid_sz":1000,"ask_sz":100,"bid_ct":1,"ask_ct":1},{"bid_px":"249.600000000","ask_px":"252.300000000","bid_sz":1050,"ask_sz":1000,"bid_ct":2,"ask_ct":1},{"bid_px":"248.500000000","ask_px":"253.650000000","bid_sz":1000,"ask_sz":400,"bid_ct":1,"ask_ct":1},{"bid_px":"247.150000000","ask_px":"960.000000000","bid_sz":400,"ask_sz":25,"bid_ct":1,"ask_ct":1},{"bid_px":"235.000000000","ask_px":null,"bid_sz":100,"ask_sz":0,"bid_ct":1,"ask_ct":0},{"bid_px":"203.000000000","ask_px":null,"bid_sz":2,"ask_sz":0,"bid_ct":1,"ask_ct":0},{"bid_px":null,"ask_px":null,"bid_sz":0,"ask_sz":0,"bid_ct":0,"ask_ct":0},{"bid_px":null,"ask_px":null,"bid_sz":0,"ask_sz":0,"bid_ct":0,"ask_ct":0},{"bid_px":null,"ask_px":null,"bid_sz":0,"ask_sz":0,"bid_ct":0,"ask_ct":0},{"bid_px":null,"ask_px":null,"bid_sz":0,"ask_sz":0,"bid_ct":0,"ask_ct":0}],"symbol":"TSLA"}
{"ts_recv":"2024-11-01T08:00:02.769946788Z","hd":{"ts_event":"2024-11-01T08:00:02.769780516Z","rtype":10,"publisher_id":2,"instrument_id":16244},"action":"A","side":"B","depth":1,"price":"249.610000000","size":100,"flags":130,"ts_in_delta":166272,"sequence":292586,"levels":[{"bid_px":"249.800000000","ask_px":"250.830000000","bid_sz":1000,"ask_sz":100,"bid_ct":1,"ask_ct":1},{"bid_px":"249.610000000","ask_px":"252.300000000","bid_sz":100,"ask_sz":1000,"bid_ct":1,"ask_ct":1},{"bid_px":"249.600000000","ask_px":"253.650000000","bid_sz":1000,"ask_sz":400,"bid_ct":1,"ask_ct":1},{"bid_px":"248.500000000","ask_px":"960.000000000","bid_sz":1000,"ask_sz":25,"bid_ct":1,"ask_ct":1},{"bid_px":"247.150000000","ask_px":null,"bid_sz":400,"ask_sz":0,"bid_ct":1,"ask_ct":0},{"bid_px":"235.000000000","ask_px":null,"bid_sz":100,"ask_sz":0,"bid_ct":1,"ask_ct":0},{"bid_px":"203.000000000","ask_px":null,"bid_sz":2,"ask_sz":0,"bid_ct":1,"ask_ct":0},{"bid_px":null,"ask_px":null,"bid_sz":0,"ask_sz":0,"bid_ct":0,"ask_ct":0},{"bid_px":null,"ask_px":null,"bid_sz":0,"ask_sz":0,"bid_ct":0,"ask_ct":0},{"bid_px":null,"ask_px":null,"bid_sz":0,"ask_sz":0,"bid_ct":0,"ask_ct":0}],"symbol":"TSLA"}
{"ts_recv":"2024-11-01T08:00:02.781101894Z","hd":{"ts_event":"2024-11-01T08:00:02.780935559Z","rtype":10,"publisher_id":2,"instrument_id":16244},"action":"A","side":"B","depth":0,"price":"249.870000000","size":50,"flags":130,"ts_in_delta":166335,"sequence":292595,"levels":[{"bid_px":"249.870000000","ask_px":"250.830000000","bid_sz":50,"ask_sz":100,"bid_ct":1,"ask_ct":1},{"bid_px":"249.800000000","ask_px":"252.300000000","bid_sz":1000,"ask_sz":1000,"bid_ct":1,"ask_ct":1},{"bid_px":"249.600000000","ask_px":"253.650000000","bid_sz":1000,"ask_sz":400,"bid_ct":1,"ask_ct":1},{"bid_px":"248.500000000","ask_px":"960.000000000","bid_sz":1000,"ask_sz":25,"bid_ct":1,"ask_ct":1},{"bid_px":"247.150000000","ask_px":null,"bid_sz":400,"ask_sz":0,"bid_ct":1,"ask_ct":0},{"bid_px":"235.000000000","ask_px":null,"bid_sz":100,"ask_sz":0,"bid_ct":1,"ask_ct":0},{"bid_px":"203.000000000","ask_px":null,"bid_sz":2,"ask_sz":0,"bid_ct":1,"ask_ct":0},{"bid_px":null,"ask_px":null,"bid_sz":0,"ask_sz":0,"bid_ct":0,"ask_ct":0},{"bid_px":null,"ask_px":null,"bid_sz":0,"ask_sz":0,"bid_ct":0,"ask_ct":0},{"bid_px":null,"ask_px":null,"bid_sz":0,"ask_sz":0,"bid_ct":0,"ask_ct":0}],"symbol":"TSLA"}
{"ts_recv":"2024-11-01T08:00:02.813321525Z","hd":{"ts_event":"2024-11-01T08:00:02.813155243Z","rtype":10,"publisher_id":2,"instrument_id":16244},"action":"A","side":"B","depth":7,"price":"170.000000000","size":3,"flags":130,"ts_in_delta":166282,"sequence":292603,"levels":[{"bid_px":"249.870000000","ask_px":"250.830000000","bid_sz":50,"ask_sz":100,"bid_ct":1,"ask_ct":1},{"bid_px":"249.800000000","ask_px":"252.300000000","bid_sz":1000,"ask_sz":1000,"bid_ct":1,"ask_ct":1},{"bid_px":"249.600000000","ask_px":"253.650000000","bid_sz":1000,"ask_sz":400,"bid_ct":1,"ask_ct":1},{"bid_px":"248.500000000","ask_px":"960.000000000","bid_sz":1000,"ask_sz":25,"bid_ct":1,"ask_ct":1},{"bid_px":"247.150000000","ask_px":null,"bid_sz":400,"ask_sz":0,"bid_ct":1,"ask_ct":0},{"bid_px":"235.000000000","ask_px":null,"bid_sz":100,"ask_sz":0,"bid_ct":1,"ask_ct":0},{"bid_px":"203.000000000","ask_px":null,"bid_sz":2,"ask_sz":0,"bid_ct":1,"ask_ct":0},{"bid_px":"170.000000000","ask_px":null,"bid_sz":3,"ask_sz":0,"bid_ct":1,"ask_ct":0},{"bid_px":null,"ask_px":null,"bid_sz":0,"ask_sz":0,"bid_ct":0,"ask_ct":0},{"bid_px":null,"ask_px":null,"bid_sz":0,"ask_sz":0,"bid_ct":0,"ask_ct":0}],"symbol":"TSLA"}
{"ts_recv":"2024-11-01T08:00:02.819310866Z","hd":{"ts_event":"2024-11-01T08:00:02.819145368Z","rtype":10,"publisher_id":2,"instrument_id":16244},"action":"C","side":"B","depth":0,"price":"249.870000000","size":50,"flags":130,"ts_in_delta":165498,"sequence":292610,"levels":[{"bid_px":"249.800000000","ask_px":"250.830000000","bid_sz":1000,"ask_sz":100,"bid_ct":1,"ask_ct":1},{"bid_px":"249.600000000","ask_px":"252.300000000","bid_sz":1000,"ask_sz":1000,"bid_ct":1,"ask_ct":1},{"bid_px":"248.500000000","ask_px":"253.650000000","bid_sz":1000,"ask_sz":400,"bid_ct":1,"ask_ct":1},{"bid_px":"247.150000000","ask_px":"960.000000000","bid_sz":400,"ask_sz":25,"bid_ct":1,"ask_ct":1},{"bid_px":"235.000000000","ask_px":null,"bid_sz":100,"ask_sz":0,"bid_ct":1,"ask_ct":0},{"bid_px":"203.000000000","ask_px":null,"bid_sz":2,"ask_sz":0,"bid_ct":1,"ask_ct":0},{"bid_px":"170.000000000","ask_px":null,"bid_sz":3,"ask_sz":0,"bid_ct":1,"ask_ct":0},{"bid_px":null,"ask_px":null,"bid_sz":0,"ask_sz":0,"bid_ct":0,"ask_ct":0},{"bid_px":null,"ask_px":null,"bid_sz":0,"ask_sz":0,"bid_ct":0,"ask_ct":0},{"bid_px":null,"ask_px":null,"bid_sz":0,"ask_sz":0,"bid_ct":0,"ask_ct":0}],"symbol":"TSLA"}
{"ts_recv":"2024-11-01T08:00:02.819580129Z","hd":{"ts_event":"2024-11-01T08:00:02.819414326Z","rtype":10,"publisher_id":2,"instrument_id":16244},"action":"C","side":"B","depth":2,"price":"248.500000000","size":1000,"flags":130,"ts_in_delta":165803,"sequence":292611,"levels":[{"bid_px":"249.800000000","ask_px":"250.830000000","bid_sz":1000,"ask_sz":100,"bid_ct":1,"ask_ct":1},{"bid_px":"249.600000000","ask_px":"252.300000000","bid_sz":1000,"ask_sz":1000,"bid_ct":1,"ask_ct":1},{"bid_px":"247.150000000","ask_px":"253.650000000","bid_sz":400,"ask_sz":400,"bid_ct":1,"ask_ct":1},{"bid_px":"235.000000000","ask_px":"960.000000000","bid_sz":100,"ask_sz":25,"bid_ct":1,"ask_ct":1},{"bid_px":"203.000000000","ask_px":null,"bid_sz":2,"ask_sz":0,"bid_ct":1,"ask_ct":0},{"bid_px":"170.000000000","ask_px":null,"bid_sz":3,"ask_sz":0,"bid_ct":1,"ask_ct":0},{"bid_px":null,"ask_px":null,"bid_sz":0,"ask_sz":0,"bid_ct":0,"ask_ct":0},{"bid_px":null,"ask_px":null,"bid_sz":0,"ask_sz":0,"bid_ct":0,"ask_ct":0},{"bid_px":null,"ask_px":null,"bid_sz":0,"ask_sz":0,"bid_ct":0,"ask_ct":0},{"bid_px":null,"ask_px":null,"bid_sz":0,"ask_sz":0,"bid_ct":0,"ask_ct":0}],"symbol":"TSLA"}
{"ts_recv":"2024-11-01T08:00:02.819973569Z","hd":{"ts_event":"2024-11-01T08:00:02.819806929Z","rtype":10,"publisher_id":2,"instrument_id":16244},"action":"A","side":"A","depth":0,"price":"250.430000000","size":13,"flags":130,"ts_in_delta":166640,"sequence":292612,"levels":[{"bid_px":"249.800000000","ask_px":"250.430000000","bid_sz":1000,"ask_sz":13,"bid_ct":1,"ask_ct":1},{"bid_px":"249.600000000","ask_px":"250.830000000","bid_sz":1000,"ask_sz":100,"bid_ct":1,"ask_ct":1},{"bid_px":"247.150000000","ask_px":"252.300000000","bid_sz":400,"ask_sz":1000,"bid_ct":1,"ask_ct":1},{"bid_px":"235.000000000","ask_px":"253.650000000","bid_sz":100,"ask_sz":400,"bid_ct":1,"ask_ct":1},{"bid_px":"203.000000000","ask_px":"960.000000000","bid_sz":2,"ask_sz":25,"bid_ct":1,"ask_ct":1},{"bid_px":"170.000000000","ask_px":null,"bid_sz":3,"ask_sz":0,"bid_ct":1,"ask_ct":0},{"bid_px":null,"ask_px":null,"bid_sz":0,"ask_sz":0,"bid_ct":0,"ask_ct":0},{"bid_px":null,"ask_px":null,"bid_sz":0,"ask_sz":0,"bid_ct":0,"ask_ct":0},{"bid_px":null,"ask_px":null,"bid_sz":0,"ask_sz":0,"bid_ct":0,"ask_ct":0},{"bid_px":null,"ask_px":null,"bid_sz":0,"ask_sz":0,"bid_ct":0,"ask_ct":0}],"symbol":"TSLA"}
{"ts_recv":"2024-11-01T08:00:02.819984926Z","hd":{"ts_event":"2024-11-01T08:00:02.819819196Z","rtype":10,"publisher_id":2,"instrument_id":16244},"action":"C","side":"A","depth":0,"price":"250.430000000","size":13,"flags":130,"ts_in_delta":165730,"sequence":292613,"levels":[{"bid_px":"249.800000000","ask_px":"250.830000000","bid_sz":1000,"ask_sz":100,"bid_ct":1,"ask_ct":1},{"bid_px":"249.600000000","ask_px":"252.300000000","bid_sz":1000,"ask_sz":1000,"bid_ct":1,"ask_ct":1},{"bid_px":"247.150000000","ask_px":"253.650000000","bid_sz":400,"ask_sz":400,"bid_ct":1,"ask_ct":1},{"bid_px":"235.000000000","ask_px":"960.000000000","bid_sz":100,"ask_sz":25,"bid_ct":1,"ask_ct":1},{"bid_px":"203.000000000","ask_px":null,"bid_sz":2,"ask_sz":0,"bid_ct":1,"ask_ct":0},{"bid_px":"170.000000000","ask_px":null,"bid_sz":3,"ask_sz":0,"bid_ct":1,"ask_ct":0},{"bid_px":null,"ask_px":null,"bid_sz":0,"ask_sz":0,"bid_ct":0,"ask_ct":0},{"bid_px":null,"ask_px":null,"bid_sz":0,"ask_sz":0,"bid_ct":0,"ask_ct":0},{"bid_px":null,"ask_px":null,"bid_sz":0,"ask_sz":0,"bid_ct":0,"ask_ct":0},{"bid_px":null,"ask_px":null,"bid_sz":0,"ask_sz":0,"bid_ct":0,"ask_ct":0}],"symbol":"TSLA"}
{"ts_recv":"2024-11-01T08:00:02.821250331Z","hd":{"ts_event":"2024-11-01T08:00:02.821084428Z","rtype":10,"publisher_id":2,"instrument_id":16244},"action":"C","side":"B","depth":0,"price":"249.800000000","size":1000,"flags":130,"ts_in_delta":165903,"sequence":292616,"levels":[{"bid_px":"249.600000000","ask_px":"250.830000000","bid_sz":1000,"ask_sz":100,"bid_ct":1,"ask_ct":1},{"bid_px":"247.150000000","ask_px":"252.300000000","bid_sz":400,"ask_sz":1000,"bid_ct":1,"ask_ct":1},{"bid_px":"235.000000000","ask_px":"253.650000000","bid_sz":100,"ask_sz":400,"bid_ct":1,"ask_ct":1},{"bid_px":"203.000000000","ask_px":"960.000000000","bid_sz":2,"ask_sz":25,"bid_ct":1,"ask_ct":1},{"bid_px":"170.000000000","ask_px":null,"bid_sz":3,"ask_sz":0,"bid_ct":1,"ask_ct":0},{"bid_px":null,"ask_px":null,"bid_sz":0,"ask_sz":0,"bid_ct":0,"ask_ct":0},{"bid_px":null,"ask_px":null,"bid_sz":0,"ask_sz":0,"bid_ct":0,"ask_ct":0},{"bid_px":null,"ask_px":null,"bid_sz":0,"ask_sz":0,"bid_ct":0,"ask_ct":0},{"bid_px":null,"ask_px":null,"bid_sz":0,"ask_sz":0,"bid_ct":0,"ask_ct":0},{"bid_px":null,"ask_px":null,"bid_sz":0,"ask_sz":0,"bid_ct":0,"ask_ct":0}],"symbol":"TSLA"}
{"ts_recv":"2024-11-01T08:00:02.830665898Z","hd":{"ts_event":"2024-11-01T08:00:02.830499730Z","rtype":10,"publisher_id":2,"instrument_id":16244},"action":"A","side":"A","depth":0,"price":"250.830000000","size":100,"flags":130,"ts_in_delta":166168,"sequence":292626,"levels":[{"bid_px":"249.600000000","ask_px":"250.830000000","bid_sz":1000,"ask_sz":200,"bid_ct":1,"ask_ct":2},{"bid_px":"247.150000000","ask_px":"252.300000000","bid_sz":400,"ask_sz":1000,"bid_ct":1,"ask_ct":1},{"bid_px":"235.000000000","ask_px":"253.650000000","bid_sz":100,"ask_sz":400,"bid_ct":1,"ask_ct":1},{"bid_px":"203.000000000","ask_px":"960.000000000","bid_sz":2,"ask_sz":25,"bid_ct":1,"ask_ct":1},{"bid_px":"170.000000000","ask_px":null,"bid_sz":3,"ask_sz":0,"bid_ct":1,"ask_ct":0},{"bid_px":null,"ask_px":null,"bid_sz":0,"ask_sz":0,"bid_ct":0,"ask_ct":0},{"bid_px":null,"ask_px":null,"bid_sz":0,"ask_sz":0,"bid_ct":0,"ask_ct":0},{"bid_px":null,"ask_px":null,"bid_sz":0,"ask_sz":0,"bid_ct":0,"ask_ct":0},{"bid_px":null,"ask_px":null,"bid_sz":0,"ask_sz":0,"bid_ct":0,"ask_ct":0},{"bid_px":null,"ask_px":null,"bid_sz":0,"ask_sz":0,"bid_ct":0,"ask_ct":0}],"symbol":"TSLA"}
{"ts_recv":"2024-11-01T08:00:02.844290141Z","hd":{"ts_event":"2024-11-01T08:00:02.844123787Z","rtype":10,"publisher_id":2,"instrument_id":16244},"action":"A","side":"A","depth":1,"price":"252.200000000","size":1000,"flags":130,"ts_in_delta":166354,"sequence":292637,"levels":[{"bid_px":"249.600000000","ask_px":"250.830000000","bid_sz":1000,"ask_sz":200,"bid_ct":1,"ask_ct":2},{"bid_px":"247.150000000","ask_px":"252.200000000","bid_sz":400,"ask_sz":1000,"bid_ct":1,"ask_ct":1},{"bid_px":"235.000000000","ask_px":"252.300000000","bid_sz":100,"ask_sz":1000,"bid_ct":1,"ask_ct":1},{"bid_px":"203.000000000","ask_px":"253.650000000","bid_sz":2,"ask_sz":400,"bid_ct":1,"ask_ct":1},{"bid_px":"170.000000000","ask_px":"960.000000000","bid_sz":3,"ask_sz":25,"bid_ct":1,"ask_ct":1},{"bid_px":null,"ask_px":null,"bid_sz":0,"ask_sz":0,"bid_ct":0,"ask_ct":0},{"bid_px":null,"ask_px":null,"bid_sz":0,"ask_sz":0,"bid_ct":0,"ask_ct":0},{"bid_px":null,"ask_px":null,"bid_sz":0,"ask_sz":0,"bid_ct":0,"ask_ct":0},{"bid_px":null,"ask_px":null,"bid_sz":0,"ask_sz":0,"bid_ct":0,"ask_ct":0},{"bid_px":null,"ask_px":null,"bid_sz":0,"ask_sz":0,"bid_ct":0,"ask_ct":0}],"symbol":"TSLA"}
{"ts_recv":"2024-11-01T08:00:02.844344811Z","hd":{"ts_event":"2024-11-01T08:00:02.844178721Z","rtype":10,"publisher_id":2,"instrument_id":16244},"action":"C","side":"A","depth":2,"price":"252.300000000","size":1000,"flags":130,"ts_in_delta":166090,"sequence":292638,"levels":[{"bid_px":"249.600000000","ask_px":"250.830000000","bid_sz":1000,"ask_sz":200,"bid_ct":1,"ask_ct":2},{"bid_px":"247.150000000","ask_px":"252.200000000","bid_sz":400,"ask_sz":1000,"bid_ct":1,"ask_ct":1},{"bid_px":"235.000000000","ask_px":"253.650000000","bid_sz":100,"ask_sz":400,"bid_ct":1,"ask_ct":1},{"bid_px":"203.000000000","ask_px":"960.000000000","bid_sz":2,"ask_sz":25,"bid_ct":1,"ask_ct":1},{"bid_px":"170.000000000","ask_px":null,"bid_sz":3,"ask_sz":0,"bid_ct":1,"ask_ct":0},{"bid_px":null,"ask_px":null,"bid_sz":0,"ask_sz":0,"bid_ct":0,"ask_ct":0},{"bid_px":null,"ask_px":null,"bid_sz":0,"ask_sz":0,"bid_ct":0,"ask_ct":0},{"bid_px":null,"ask_px":null,"bid_sz":0,"ask_sz":0,"bid_ct":0,"ask_ct":0},{"bid_px":null,"ask_px":null,"bid_sz":0,"ask_sz":0,"bid_ct":0,"ask_ct":0},{"bid_px":null,"ask_px":null,"bid_sz":0,"ask_sz":0,"bid_ct":0,"ask_ct":0}],"symbol":"TSLA"}
{"ts_recv":"2024-11-01T08:00:02.858272469Z","hd":{"ts_event":"2024-11-01T08:00:02.858106249Z","rtype":10,"publisher_id":2,"instrument_id":16244},"action":"A","side":"B","depth":1,"price":"249.100000000","size":1000,"flags":130,"ts_in_delta":166220,"sequence":292648,"levels":[{"bid_px":"249.600000000","ask_px":"250.830000000","bid_sz":1000,"ask_sz":200,"bid_ct":1,"ask_ct":2},{"bid_px":"249.100000000","ask_px":"252.200000000","bid_sz":1000,"ask_sz":1000,"bid_ct":1,"ask_ct":1},{"bid_px":"247.150000000","ask_px":"253.650000000","bid_sz":400,"ask_sz":400,"bid_ct":1,"ask_ct":1},{"bid_px":"235.000000000","ask_px":"960.000000000","bid_sz":100,"ask_sz":25,"bid_ct":1,"ask_ct":1},{"bid_px":"203.000000000","ask_px":null,"bid_sz":2,"ask_sz":0,"bid_ct":1,"ask_ct":0},{"bid_px":"170.000000000","ask_px":null,"bid_sz":3,"ask_sz":0,"bid_ct":1,"ask_ct":0},{"bid_px":null,"ask_px":null,"bid_sz":0,"ask_sz":0,"bid_ct":0,"ask_ct":0},{"bid_px":null,"ask_px":null,"bid_sz":0,"ask_sz":0,"bid_ct":0,"ask_ct":0},{"bid_px":null,"ask_px":null,"bid_sz":0,"ask_sz":0,"bid_ct":0,"ask_ct":0},{"bid_px":null,"ask_px":null,"bid_sz":0,"ask_sz":0,"bid_ct":0,"ask_ct":0}],"symbol":"TSLA"}
{"ts_recv":"2024-11-01T08:00:02.895656804Z","hd":{"ts_event":"2024-11-01T08:00:02.895491059Z","rtype":10,"publisher_id":2,"instrument_id":16244},"action":"C","side":"A","depth":0,"price":"250.830000000","size":100,"flags":130,"ts_in_delta":165745,"sequence":292819,"levels":[{"bid_px":"249.600000000","ask_px":"250.830000000","bid_sz":1000,"ask_sz":100,"bid_ct":1,"ask_ct":1},{"bid_px":"249.100000000","ask_px":"252.200000000","bid_sz":1000,"ask_sz":1000,"bid_ct":1,"ask_ct":1},{"bid_px":"247.150000000","ask_px":"253.650000000","bid_sz":400,"ask_sz":400,"bid_ct":1,"ask_ct":1},{"bid_px":"235.000000000","ask_px":"960.000000000","bid_sz":100,"ask_sz":25,"bid_ct":1,"ask_ct":1},{"bid_px":"203.000000000","ask_px":null,"bid_sz":2,"ask_sz":0,"bid_ct":1,"ask_ct":0},{"bid_px":"170.000000000","ask_px":null,"bid_sz":3,"ask_sz":0,"bid_ct":1,"ask_ct":0},{"bid_px":null,"ask_px":null,"bid_sz":0,"ask_sz":0,"bid_ct":0,"ask_ct":0},{"bid_px":null,"ask_px":null,"bid_sz":0,"ask_sz":0,"bid_ct":0,"ask_ct":0},{"bid_px":null,"ask_px":null,"bid_sz":0,"ask_sz":0,"bid_ct":0,"ask_ct":0},{"bid_px":null,"ask_px":null,"bid_sz":0,"ask_sz":0,"bid_ct":0,"ask_ct":0}],"symbol":"TSLA"}
{"ts_recv":"2024-11-01T08:00:02.895686744Z","hd":{"ts_event":"2024-11-01T08:00:02.895520294Z","rtype":10,"publisher_id":2,"instrument_id":16244},"action":"A","side":"A","depth":0,"price":"250.730000000","size":100,"flags":130,"ts_in_delta":166450,"sequence":292820,"levels":[{"bid_px":"249.600000000","ask_px":"250.730000000","bid_sz":1000,"ask_sz":100,"bid_ct":1,"ask_ct":1},{"bid_px":"249.100000000","ask_px":"252.200000000","bid_sz":1000,"ask_sz":1000,"bid_ct":1,"ask_ct":1},{"bid_px":"247.150000000","ask_px":"253.650000000","bid_sz":400,"ask_sz":400,"bid_ct":1,"ask_ct":1},{"bid_px":"235.000000000","ask_px":"960.000000000","bid_sz":100,"ask_sz":25,"bid_ct":1,"ask_ct":1},{"bid_px":"203.000000000","ask_px":null,"bid_sz":2,"ask_sz":0,"bid_ct":1,"ask_ct":0},{"bid_px":"170.000000000","ask_px":null,"bid_sz":3,"ask_sz":0,"bid_ct":1,"ask_ct":0},{"bid_px":null,"ask_px":null,"bid_sz":0,"ask_sz":0,"bid_ct":0,"ask_ct":0},{"bid_px":null,"ask_px":null,"bid_sz":0,"ask_sz":0,"bid_ct":0,"ask_ct":0},{"bid_px":null,"ask_px":null,"bid_sz":0,"ask_sz":0,"bid_ct":0,"ask_ct":0},{"bid_px":null,"ask_px":null,"bid_sz":0,"ask_sz":0,"bid_ct":0,"ask_ct":0}],"symbol":"TSLA"}
{"ts_recv":"2024-11-01T08:00:02.923206986Z","hd":{"ts_event":"2024-11-01T08:00:02.923040840Z","rtype":10,"publisher_id":2,"instrument_id":16244},"action":"A","side":"B","depth":0,"price":"249.870000000","size":50,"flags":130,"ts_in_delta":166146,"sequence":292854,"levels":[{"bid_px":"249.870000000","ask_px":"250.730000000","bid_sz":50,"ask_sz":100,"bid_ct":1,"ask_ct":1},{"bid_px":"249.600000000","ask_px":"252.200000000","bid_sz":1000,"ask_sz":1000,"bid_ct":1,"ask_ct":1},{"bid_px":"249.100000000","ask_px":"253.650000000","bid_sz":1000,"ask_sz":400,"bid_ct":1,"ask_ct":1},{"bid_px":"247.150000000","ask_px":"960.000000000","bid_sz":400,"ask_sz":25,"bid_ct":1,"ask_ct":1},{"bid_px":"235.000000000","ask_px":null,"bid_sz":100,"ask_sz":0,"bid_ct":1,"ask_ct":0},{"bid_px":"203.000000000","ask_px":null,"bid_sz":2,"ask_sz":0,"bid_ct":1,"ask_ct":0},{"bid_px":"170.000000000","ask_px":null,"bid_sz":3,"ask_sz":0,"bid_ct":1,"ask_ct":0},{"bid_px":null,"ask_px":null,"bid_sz":0,"ask_sz":0,"bid_ct":0,"ask_ct":0},{"bid_px":null,"ask_px":null,"bid_sz":0,"ask_sz":0,"bid_ct":0,"ask_ct":0},{"bid_px":null,"ask_px":null,"bid_sz":0,"ask_sz":0,"bid_ct":0,"ask_ct":0}],"symbol":"TSLA"}
{"ts_recv":"2024-11-01T08:00:02.941910475Z","hd":{"ts_event":"2024-11-01T08:00:02.941743559Z","rtype":10,"publisher_id":2,"instrument_id":16244},"action":"A","side":"B","depth":0,"price":"249.900000000","size":50,"flags":130,"ts_in_delta":166916,"sequence":292875,"levels":[{"bid_px":"249.900000000","ask_px":"250.730000000","bid_sz":50,"ask_sz":100,"bid_ct":1,"ask_ct":1},{"bid_px":"249.600000000","ask_px":"252.200000000","bid_sz":1000,"ask_sz":1000,"bid_ct":1,"ask_ct":1},{"bid_px":"249.100000000","ask_px":"253.650000000","bid_sz":1000,"ask_sz":400,"bid_ct":1,"ask_ct":1},{"bid_px":"247.150000000","ask_px":"960.000000000","bid_sz":400,"ask_sz":25,"bid_ct":1,"ask_ct":1},{"bid_px":"235.000000000","ask_px":null,"bid_sz":100,"ask_sz":0,"bid_ct":1,"ask_ct":0},{"bid_px":"203.000000000","ask_px":null,"bid_sz":2,"ask_sz":0,"bid_ct":1,"ask_ct":0},{"bid_px":"170.000000000","ask_px":null,"bid_sz":3,"ask_sz":0,"bid_ct":1,"ask_ct":0},{"bid_px":null,"ask_px":null,"bid_sz":0,"ask_sz":0,"bid_ct":0,"ask_ct":0},{"bid_px":null,"ask_px":null,"bid_sz":0,"ask_sz":0,"bid_ct":0,"ask_ct":0},{"bid_px":null,"ask_px":null,"bid_sz":0,"ask_sz":0,"bid_ct":0,"ask_ct":0}],"symbol":"TSLA"}
{"ts_recv":"2024-11-01T08:00:02.952347233Z","hd":{"ts_event":"2024-11-01T08:00:02.952181020Z","rtype":10,"publisher_id":2,"instrument_id":16244},"action":"A","side":"B","depth":2,"price":"249.500000000","size":1000,"flags":130,"ts_in_delta":166213,"sequence":292889,"levels":[{"bid_px":"249.900000000","ask_px":"250.730000000","bid_sz":50,"ask_sz":100,"bid_ct":1,"ask_ct":1},{"bid_px":"249.600000000","ask_px":"252.200000000","bid_sz":1000,"ask_sz":1000,"bid_ct":1,"ask_ct":1},{"bid_px":"249.500000000","ask_px":"253.650000000","bid_sz":1000,"ask_sz":400,"bid_ct":1,"ask_ct":1},{"bid_px":"249.100000000","ask_px":"960.000000000","bid_sz":1000,"ask_sz":25,"bid_ct":1,"ask_ct":1},{"bid_px":"247.150000000","ask_px":null,"bid_sz":400,"ask_sz":0,"bid_ct":1,"ask_ct":0},{"bid_px":"235.000000000","ask_px":null,"bid_sz":100,"ask_sz":0,"bid_ct":1,"ask_ct":0},{"bid_px":"203.000000000","ask_px":null,"bid_sz":2,"ask_sz":0,"bid_ct":1,"ask_ct":0},{"bid_px":"170.000000000","ask_px":null,"bid_sz":3,"ask_sz":0,"bid_ct":1,"ask_ct":0},{"bid_px":null,"ask_px":null,"bid_sz":0,"ask_sz":0,"bid_ct":0,"ask_ct":0},{"bid_px":null,"ask_px":null,"bid_sz":0,"ask_sz":0,"bid_ct":0,"ask_ct":0}],"symbol":"TSLA"}
{"ts_recv":"2024-11-01T08:00:02.952388850Z","hd":{"ts_event":"2024-11-01T08:00:02.952222880Z","rtype":10,"publisher_id":2,"instrument_id":16244},"action":"C","side":"B","depth":3,"price":"249.100000000","size":1000,"flags":130,"ts_in_delta":165970,"sequence":292890,"levels":[{"bid_px":"249.900000000","ask_px":"250.730000000","bid_sz":50,"ask_sz":100,"bid_ct":1,"ask_ct":1},{"bid_px":"249.600000000","ask_px":"252.200000000","bid_sz":1000,"ask_sz":1000,"bid_ct":1,"ask_ct":1},{"bid_px":"249.500000000","ask_px":"253.650000000","bid_sz":1000,"ask_sz":400,"bid_ct":1,"ask_ct":1},{"bid_px":"247.150000000","ask_px":"960.000000000","bid_sz":400,"ask_sz":25,"bid_ct":1,"ask_ct":1},{"bid_px":"235.000000000","ask_px":null,"bid_sz":100,"ask_sz":0,"bid_ct":1,"ask_ct":0},{"bid_px":"203.000000000","ask_px":null,"bid_sz":2,"ask_sz":0,"bid_ct":1,"ask_ct":0},{"bid_px":"170.000000000","ask_px":null,"bid_sz":3,"ask_sz":0,"bid_ct":1,"ask_ct":0},{"bid_px":null,"ask_px":null,"bid_sz":0,"ask_sz":0,"bid_ct":0,"ask_ct":0},{"bid_px":null,"ask_px":null,"bid_sz":0,"ask_sz":0,"bid_ct":0,"ask_ct":0},{"bid_px":null,"ask_px":null,"bid_sz":0,"ask_sz":0,"bid_ct":0,"ask_ct":0}],"symbol":"TSLA"}
{"ts_recv":"2024-11-01T08:00:02.963417496Z","hd":{"ts_event":"2024-11-01T08:00:02.963251228Z","rtype":10,"publisher_id":2,"instrument_id":16244},"action":"A","side":"B","depth":3,"price":"248.700000000","size":1000,"flags":130,"ts_in_delta":166268,"sequence":292897,"levels":[{"bid_px":"249.900000000","ask_px":"250.730000000","bid_sz":50,"ask_sz":100,"bid_ct":1,"ask_ct":1},{"bid_px":"249.600000000","ask_px":"252.200000000","bid_sz":1000,"ask_sz":1000,"bid_ct":1,"ask_ct":1},{"bid_px":"249.500000000","ask_px":"253.650000000","bid_sz":1000,"ask_sz":400,"bid_ct":1,"ask_ct":1},{"bid_px":"248.700000000","ask_px":"960.000000000","bid_sz":1000,"ask_sz":25,"bid_ct":1,"ask_ct":1},{"bid_px":"247.150000000","ask_px":null,"bid_sz":400,"ask_sz":0,"bid_ct":1,"ask_ct":0},{"bid_px":"235.000000000","ask_px":null,"bid_sz":100,"ask_sz":0,"bid_ct":1,"ask_ct":0},{"bid_px":"203.000000000","ask_px":null,"bid_sz":2,"ask_sz":0,"bid_ct":1,"ask_ct":0},{"bid_px":"170.000000000","ask_px":null,"bid_sz":3,"ask_sz":0,"bid_ct":1,"ask_ct":0},{"bid_px":null,"ask_px":null,"bid_sz":0,"ask_sz":0,"bid_ct":0,"ask_ct":0},{"bid_px":null,"ask_px":null,"bid_sz":0,"ask_sz":0,"bid_ct":0,"ask_ct":0}],"symbol":"TSLA"}
{"ts_recv":"2024-11-01T08:00:03.032059829Z","hd":{"ts_event":"2024-11-01T08:00:03.031893056Z","rtype":10,"publisher_id":2,"instrument_id":16244},"action":"A","side":"B","depth":0,"price":"249.930000000","size":50,"flags":130,"ts_in_delta":166773,"sequence":293097,"levels":[{"bid_px":"249.930000000","ask_px":"250.730000000","bid_sz":50,"ask_sz":100,"bid_ct":1,"ask_ct":1},{"bid_px":"249.600000000","ask_px":"252.200000000","bid_sz":1000,"ask_sz":1000,"bid_ct":1,"ask_ct":1},{"bid_px":"249.500000000","ask_px":"253.650000000","bid_sz":1000,"ask_sz":400,"bid_ct":1,"ask_ct":1},{"bid_px":"248.700000000","ask_px":"960.000000000","bid_sz":1000,"ask_sz":25,"bid_ct":1,"ask_ct":1},{"bid_px":"247.150000000","ask_px":null,"bid_sz":400,"ask_sz":0,"bid_ct":1,"ask_ct":0},{"bid_px":"235.000000000","ask_px":null,"bid_sz":100,"ask_sz":0,"bid_ct":1,"ask_ct":0},{"bid_px":"203.000000000","ask_px":null,"bid_sz":2,"ask_sz":0,"bid_ct":1,"ask_ct":0},{"bid_px":"170.000000000","ask_px":null,"bid_sz":3,"ask_sz":0,"bid_ct":1,"ask_ct":0},{"bid_px":null,"ask_px":null,"bid_sz":0,"ask_sz":0,"bid_ct":0,"ask_ct":0},{"bid_px":null,"ask_px":null,"bid_sz":0,"ask_sz":0,"bid_ct":0,"ask_ct":0}],"symbol":"TSLA"}
{"ts_recv":"2024-11-01T08:00:03.032778841Z","hd":{"ts_event":"2024-11-01T08:00:03.032613046Z","rtype":10,"publisher_id":2,"instrument_id":16244},"action":"C","side":"B","depth":0,"price":"249.930000000","size":50,"flags":130,"ts_in_delta":165795,"sequence":293101,"levels":[{"bid_px":"249.600000000","ask_px":"250.730000000","bid_sz":1000,"ask_sz":100,"bid_ct":1,"ask_ct":1},{"bid_px":"249.500000000","ask_px":"252.200000000","bid_sz":1000,"ask_sz":1000,"bid_ct":1,"ask_ct":1},{"bid_px":"248.700000000","ask_px":"253.650000000","bid_sz":1000,"ask_sz":400,"bid_ct":1,"ask_ct":1},{"bid_px":"247.150000000","ask_px":"960.000000000","bid_sz":400,"ask_sz":25,"bid_ct":1,"ask_ct":1},{"bid_px":"235.000000000","ask_px":null,"bid_sz":100,"ask_sz":0,"bid_ct":1,"ask_ct":0},{"bid_px":"203.000000000","ask_px":null,"bid_sz":2,"ask_sz":0,"bid_ct":1,"ask_ct":0},{"bid_px":"170.000000000","ask_px":null,"bid_sz":3,"ask_sz":0,"bid_ct":1,"ask_ct":0},{"bid_px":null,"ask_px":null,"bid_sz":0,"ask_sz":0,"bid_ct":0,"ask_ct":0},{"bid_px":null,"ask_px":null,"bid_sz":0,"ask_sz":0,"bid_ct":0,"ask_ct":0},{"bid_px":null,"ask_px":null,"bid_sz":0,"ask_sz":0,"bid_ct":0,"ask_ct":0}],"symbol":"TSLA"}
{"ts_recv":"2024-11-01T08:00:03.032790852Z","hd":{"ts_event":"2024-11-01T08:00:03.032624801Z","rtype":10,"publisher_id":2,"instrument_id":16244},"action":"A","side":"B","depth":0,"price":"249.900000000","size":50,"flags":130,"ts_in_delta":166051,"sequence":293102,"levels":[{"bid_px":"249.900000000","ask_px":"250.730000000","bid_sz":50,"ask_sz":100,"bid_ct":1,"ask_ct":1},{"bid_px":"249.600000000","ask_px":"252.200000000","bid_sz":1000,"ask_sz":1000,"bid_ct":1,"ask_ct":1},{"bid_px":"249.500000000","ask_px":"253.650000000","bid_sz":1000,"ask_sz":400,"bid_ct":1,"ask_ct":1},{"bid_px":"248.700000000","ask_px":"960.000000000","bid_sz":1000,"ask_sz":25,"bid_ct":1,"ask_ct":1},{"bid_px":"247.150000000","ask_px":null,"bid_sz":400,"ask_sz":0,"bid_ct":1,"ask_ct":0},{"bid_px":"235.000000000","ask_px":null,"bid_sz":100,"ask_sz":0,"bid_ct":1,"ask_ct":0},{"bid_px":"203.000000000","ask_px":null,"bid_sz":2,"ask_sz":0,"bid_ct":1,"ask_ct":0},{"bid_px":"170.000000000","ask_px":null,"bid_sz":3,"ask_sz":0,"bid_ct":1,"ask_ct":0},{"bid_px":null,"ask_px":null,"bid_sz":0,"ask_sz":0,"bid_ct":0,"ask_ct":0},{"bid_px":null,"ask_px":null,"bid_sz":0,"ask_sz":0,"bid_ct":0,"ask_ct":0}],"symbol":"TSLA"}
{"ts_recv":"2024-11-01T08:00:03.078595680Z","hd":{"ts_event":"2024-11-01T08:00:03.078428790Z","rtype":10,"publisher_id":2,"instrument_id":16244},"action":"C","side":"B","depth":0,"price":"249.900000000","size":50,"flags":130,"ts_in_delta":166890,"sequence":293176,"levels":[{"bid_px":"249.600000000","ask_px":"250.730000000","bid_sz":1000,"ask_sz":100,"bid_ct":1,"ask_ct":1},{"bid_px":"249.500000000","ask_px":"252.200000000","bid_sz":1000,"ask_sz":1000,"bid_ct":1,"ask_ct":1},{"bid_px":"248.700000000","ask_px":"253.650000000","bid_sz":1000,"ask_sz":400,"bid_ct":1,"ask_ct":1},{"bid_px":"247.150000000","ask_px":"960.000000000","bid_sz":400,"ask_sz":25,"bid_ct":1,"ask_ct":1},{"bid_px":"235.000000000","ask_px":null,"bid_sz":100,"ask_sz":0,"bid_ct":1,"ask_ct":0},{"bid_px":"203.000000000","ask_px":null,"bid_sz":2,"ask_sz":0,"bid_ct":1,"ask_ct":0},{"bid_px":"170.000000000","ask_px":null,"bid_sz":3,"ask_sz":0,"bid_ct":1,"ask_ct":0},{"bid_px":null,"ask_px":null,"bid_sz":0,"ask_sz":0,"bid_ct":0,"ask_ct":0},{"bid_px":null,"ask_px":null,"bid_sz":0,"ask_sz":0,"bid_ct":0,"ask_ct":0},{"bid_px":null,"ask_px":null,"bid_sz":0,"ask_sz":0,"bid_ct":0,"ask_ct":0}],"symbol":"TSLA"}
{"ts_recv":"2024-11-01T08:00:03.078608523Z","hd":{"ts_event":"2024-11-01T08:00:03.078442368Z","rtype":10,"publisher_id":2,"instrument_id":16244},"action":"A","side":"B","depth":0,"price":"249.870000000","size":50,"flags":130,"ts_in_delta":166155,"sequence":293177,"levels":[{"bid_px":"249.870000000","ask_px":"250.730000000","bid_sz":50,"ask_sz":100,"bid_ct":1,"ask_ct":1},{"bid_px":"249.600000000","ask_px":"252.200000000","bid_sz":1000,"ask_sz":1000,"bid_ct":1,"ask_ct":1},{"bid_px":"249.500000000","ask_px":"253.650000000","bid_sz":1000,"ask_sz":400,"bid_ct":1,"ask_ct":1},{"bid_px":"248.700000000","ask_px":"960.000000000","bid_sz":1000,"ask_sz":25,"bid_ct":1,"ask_ct":1},{"bid_px":"247.150000000","ask_px":null,"bid_sz":400,"ask_sz":0,"bid_ct":1,"ask_ct":0},{"bid_px":"235.000000000","ask_px":null,"bid_sz":100,"ask_sz":0,"bid_ct":1,"ask_ct":0},{"bid_px":"203.000000000","ask_px":null,"bid_sz":2,"ask_sz":0,"bid_ct":1,"ask_ct":0},{"bid_px":"170.000000000","ask_px":null,"bid_sz":3,"ask_sz":0,"bid_ct":1,"ask_ct":0},{"bid_px":null,"ask_px":null,"bid_sz":0,"ask_sz":0,"bid_ct":0,"ask_ct":0},{"bid_px":null,"ask_px":null,"bid_sz":0,"ask_sz":0,"bid_ct":0,"ask_ct":0}],"symbol":"TSLA"}
{"ts_recv":"2024-11-01T08:00:03.078689152Z","hd":{"ts_event":"2024-11-01T08:00:03.078523259Z","rtype":10,"publisher_id":2,"instrument_id":16244},"action":"C","side":"B","depth":0,"price":"249.870000000","size":50,"flags":130,"ts_in_delta":165893,"sequence":293178,"levels":[{"bid_px":"249.600000000","ask_px":"250.730000000","bid_sz":1000,"ask_sz":100,"bid_ct":1,"ask_ct":1},{"bid_px":"249.500000000","ask_px":"252.200000000","bid_sz":1000,"ask_sz":1000,"bid_ct":1,"ask_ct":1},{"bid_px":"248.700000000","ask_px":"253.650000000","bid_sz":1000,"ask_sz":400,"bid_ct":1,"ask_ct":1},{"bid_px":"247.150000000","ask_px":"960.000000000","bid_sz":400,"ask_sz":25,"bid_ct":1,"ask_ct":1},{"bid_px":"235.000000000","ask_px":null,"bid_sz":100,"ask_sz":0,"bid_ct":1,"ask_ct":0},{"bid_px":"203.000000000","ask_px":null,"bid_sz":2,"ask_sz":0,"bid_ct":1,"ask_ct":0},{"bid_px":"170.000000000","ask_px":null,"bid_sz":3,"ask_sz":0,"bid_ct":1,"ask_ct":0},{"bid_px":null,"ask_px":null,"bid_sz":0,"ask_sz":0,"bid_ct":0,"ask_ct":0},{"bid_px":null,"ask_px":null,"bid_sz":0,"ask_sz":0,"bid_ct":0,"ask_ct":0},{"bid_px":null,"ask_px":null,"bid_sz":0,"ask_sz":0,"bid_ct":0,"ask_ct":0}],"symbol":"TSLA"}
{"ts_recv":"2024-11-01T08:00:03.078712855Z","hd":{"ts_event":"2024-11-01T08:00:03.078546687Z","rtype":10,"publisher_id":2,"instrument_id":16244},"action":"A","side":"B","depth":0,"price":"249.850000000","size":50,"flags":130,"ts_in_delta":166168,"sequence":293179,"levels":[{"bid_px":"249.850000000","ask_px":"250.730000000","bid_sz":50,"ask_sz":100,"bid_ct":1,"ask_ct":1},{"bid_px":"249.600000000","ask_px":"252.200000000","bid_sz":1000,"ask_sz":1000,"bid_ct":1,"ask_ct":1},{"bid_px":"249.500000000","ask_px":"253.650000000","bid_sz":1000,"ask_sz":400,"bid_ct":1,"ask_ct":1},{"bid_px":"248.700000000","ask_px":"960.000000000","bid_sz":1000,"ask_sz":25,"bid_ct":1,"ask_ct":1},{"bid_px":"247.150000000","ask_px":null,"bid_sz":400,"ask_sz":0,"bid_ct":1,"ask_ct":0},{"bid_px":"235.000000000","ask_px":null,"bid_sz":100,"ask_sz":0,"bid_ct":1,"ask_ct":0},{"bid_px":"203.000000000","ask_px":null,"bid_sz":2,"ask_sz":0,"bid_ct":1,"ask_ct":0},{"bid_px":"170.000000000","ask_px":null,"bid_sz":3,"ask_sz":0,"bid_ct":1,"ask_ct":0},{"bid_px":null,"ask_px":null,"bid_sz":0,"ask_sz":0,"bid_ct":0,"ask_ct":0},{"bid_px":null,"ask_px":null,"bid_sz":0,"ask_sz":0,"bid_ct":0,"ask_ct":0}],"symbol":"TSLA"}
{"ts_recv":"2024-11-01T08:00:03.146238622Z","hd":{"ts_event":"2024-11-01T08:00:03.146072343Z","rtype":10,"publisher_id":2,"instrument_id":16244},"action":"A","side":"A","depth":1,"price":"250.960000000","size":50,"flags":130,"ts_in_delta":166279,"sequence":293289,"levels":[{"bid_px":"249.850000000","ask_px":"250.730000000","bid_sz":50,"ask_sz":100,"bid_ct":1,"ask_ct":1},{"bid_px":"249.600000000","ask_px":"250.960000000","bid_sz":1000,"ask_sz":50,"bid_ct":1,"ask_ct":1},{"bid_px":"249.500000000","ask_px":"252.200000000","bid_sz":1000,"ask_sz":1000,"bid_ct":1,"ask_ct":1},{"bid_px":"248.700000000","ask_px":"253.650000000","bid_sz":1000,"ask_sz":400,"bid_ct":1,"ask_ct":1},{"bid_px":"247.150000000","ask_px":"960.000000000","bid_sz":400,"ask_sz":25,"bid_ct":1,"ask_ct":1},{"bid_px":"235.000000000","ask_px":null,"bid_sz":100,"ask_sz":0,"bid_ct":1,"ask_ct":0},{"bid_px":"203.000000000","ask_px":null,"bid_sz":2,"ask_sz":0,"bid_ct":1,"ask_ct":0},{"bid_px":"170.000000000","ask_px":null,"bid_sz":3,"ask_sz":0,"bid_ct":1,"ask_ct":0},{"bid_px":null,"ask_px":null,"bid_sz":0,"ask_sz":0,"bid_ct":0,"ask_ct":0},{"bid_px":null,"ask_px":null,"bid_sz":0,"ask_sz":0,"bid_ct":0,"ask_ct":0}],"symbol":"TSLA"}
{"ts_recv":"2024-11-01T08:00:03.194370387Z","hd":{"ts_event":"2024-11-01T08:00:03.194203980Z","rtype":10,"publisher_id":2,"instrument_id":16244},"action":"A","side":"B","depth":2,"price":"249.500000000","size":1000,"flags":130,"ts_in_delta":166407,"sequence":293354,"levels":[{"bid_px":"249.850000000","ask_px":"250.730000000","bid_sz":50,"ask_sz":100,"bid_ct":1,"ask_ct":1},{"bid_px":"249.600000000","ask_px":"250.960000000","bid_sz":1000,"ask_sz":50,"bid_ct":1,"ask_ct":1},{"bid_px":"249.500000000","ask_px":"252.200000000","bid_sz":2000,"ask_sz":1000,"bid_ct":2,"ask_ct":1},{"bid_px":"248.700000000","ask_px":"253.650000000","bid_sz":1000,"ask_sz":400,"bid_ct":1,"ask_ct":1},{"bid_px":"247.150000000","ask_px":"960.000000000","bid_sz":400,"ask_sz":25,"bid_ct":1,"ask_ct":1},{"bid_px":"235.000000000","ask_px":null,"bid_sz":100,"ask_sz":0,"bid_ct":1,"ask_ct":0},{"bid_px":"203.000000000","ask_px":null,"bid_sz":2,"ask_sz":0,"bid_ct":1,"ask_ct":0},{"bid_px":"170.000000000","ask_px":null,"bid_sz":3,"ask_sz":0,"bid_ct":1,"ask_ct":0},{"bid_px":null,"ask_px":null,"bid_sz":0,"ask_sz":0,"bid_ct":0,"ask_ct":0},{"bid_px":null,"ask_px":null,"bid_sz":0,"ask_sz":0,"bid_ct":0,"ask_ct":0}],"symbol":"TSLA"}
{"ts_recv":"2024-11-01T08:00:03.194570308Z","hd":{"ts_event":"2024-11-01T08:00:03.194404399Z","rtype":10,"publisher_id":2,"instrument_id":16244},"action":"C","side":"B","depth":3,"price":"248.700000000","size":1000,"flags":130,"ts_in_delta":165909,"sequence":293355,"levels":[{"bid_px":"249.850000000","ask_px":"250.730000000","bid_sz":50,"ask_sz":100,"bid_ct":1,"ask_ct":1},{"bid_px":"249.600000000","ask_px":"250.960000000","bid_sz":1000,"ask_sz":50,"bid_ct":1,"ask_ct":1},{"bid_px":"249.500000000","ask_px":"252.200000000","bid_sz":2000,"ask_sz":1000,"bid_ct":2,"ask_ct":1},{"bid_px":"247.150000000","ask_px":"253.650000000","bid_sz":400,"ask_sz":400,"bid_ct":1,"ask_ct":1},{"bid_px":"235.000000000","ask_px":"960.000000000","bid_sz":100,"ask_sz":25,"bid_ct":1,"ask_ct":1},{"bid_px":"203.000000000","ask_px":null,"bid_sz":2,"ask_sz":0,"bid_ct":1,"ask_ct":0},{"bid_px":"170.000000000","ask_px":null,"bid_sz":3,"ask_sz":0,"bid_ct":1,"ask_ct":0},{"bid_px":null,"ask_px":null,"bid_sz":0,"ask_sz":0,"bid_ct":0,"ask_ct":0},{"bid_px":null,"ask_px":null,"bid_sz":0,"ask_sz":0,"bid_ct":0,"ask_ct":0},{"bid_px":null,"ask_px":null,"bid_sz":0,"ask_sz":0,"bid_ct":0,"ask_ct":0}],"symbol":"TSLA"}
{"ts_recv":"2024-11-01T08:00:03.205151206Z","hd":{"ts_event":"2024-11-01T08:00:03.204984748Z","rtype":10,"publisher_id":2,"instrument_id":16244},"action":"A","side":"B","depth":3,"price":"248.200000000","size":1000,"flags":130,"ts_in_delta":166458,"sequence":293360,"levels":[{"bid_px":"249.850000000","ask_px":"250.730000000","bid_sz":50,"ask_sz":100,"bid_ct":1,"ask_ct":1},{"bid_px":"249.600000000","ask_px":"250.960000000","bid_sz":1000,"ask_sz":50,"bid_ct":1,"ask_ct":1},{"bid_px":"249.500000000","ask_px":"252.200000000","bid_sz":2000,"ask_sz":1000,"bid_ct":2,"ask_ct":1},{"bid_px":"248.200000000","ask_px":"253.650000000","bid_sz":1000,"ask_sz":400,"bid_ct":1,"ask_ct":1},{"bid_px":"247.150000000","ask_px":"960.000000000","bid_sz":400,"ask_sz":25,"bid_ct":1,"ask_ct":1},{"bid_px":"235.000000000","ask_px":null,"bid_sz":100,"ask_sz":0,"bid_ct":1,"ask_ct":0},{"bid_px":"203.000000000","ask_px":null,"bid_sz":2,"ask_sz":0,"bid_ct":1,"ask_ct":0},{"bid_px":"170.000000000","ask_px":null,"bid_sz":3,"ask_sz":0,"bid_ct":1,"ask_ct":0},{"bid_px":null,"ask_px":null,"bid_sz":0,"ask_sz":0,"bid_ct":0,"ask_ct":0},{"bid_px":null,"ask_px":null,"bid_sz":0,"ask_sz":0,"bid_ct":0,"ask_ct":0}],"symbol":"TSLA"}
{"ts_recv":"2024-11-01T08:00:03.214331004Z","hd":{"ts_event":"2024-11-01T08:00:03.214163798Z","rtype":10,"publisher_id":2,"instrument_id":16244},"action":"A","side":"B","depth":0,"price":"249.870000000","size":50,"flags":130,"ts_in_delta":167206,"sequence":293369,"levels":[{"bid_px":"249.870000000","ask_px":"250.730000000","bid_sz":50,"ask_sz":100,"bid_ct":1,"ask_ct":1},{"bid_px":"249.600000000","ask_px":"250.960000000","bid_sz":1000,"ask_sz":50,"bid_ct":1,"ask_ct":1},{"bid_px":"249.500000000","ask_px":"252.200000000","bid_sz":2000,"ask_sz":1000,"bid_ct":2,"ask_ct":1},{"bid_px":"248.200000000","ask_px":"253.650000000","bid_sz":1000,"ask_sz":400,"bid_ct":1,"ask_ct":1},{"bid_px":"247.150000000","ask_px":"960.000000000","bid_sz":400,"ask_sz":25,"bid_ct":1,"ask_ct":1},{"bid_px":"235.000000000","ask_px":null,"bid_sz":100,"ask_sz":0,"bid_ct":1,"ask_ct":0},{"bid_px":"203.000000000","ask_px":null,"bid_sz":2,"ask_sz":0,"bid_ct":1,"ask_ct":0},{"bid_px":"170.000000000","ask_px":null,"bid_sz":3,"ask_sz":0,"bid_ct":1,"ask_ct":0},{"bid_px":null,"ask_px":null,"bid_sz":0,"ask_sz":0,"bid_ct":0,"ask_ct":0},{"bid_px":null,"ask_px":null,"bid_sz":0,"ask_sz":0,"bid_ct":0,"ask_ct":0}],"symbol":"TSLA"}
{"ts_recv":"2024-11-01T08:00:03.215083394Z","hd":{"ts_event":"2024-11-01T08:00:03.214917607Z","rtype":10,"publisher_id":2,"instrument_id":16244},"action":"C","side":"B","depth":2,"price":"249.500000000","size":1000,"flags":130,"ts_in_delta":165787,"sequence":293371,"levels":[{"bid_px":"249.870000000","ask_px":"250.730000000","bid_sz":50,"ask_sz":100,"bid_ct":1,"ask_ct":1},{"bid_px":"249.600000000","ask_px":"250.960000000","bid_sz":1000,"ask_sz":50,"bid_ct":1,"ask_ct":1},{"bid_px":"249.500000000","ask_px":"252.200000000","bid_sz":1000,"ask_sz":1000,"bid_ct":1,"ask_ct":1},{"bid_px":"248.200000000","ask_px":"253.650000000","bid_sz":1000,"ask_sz":400,"bid_ct":1,"ask_ct":1},{"bid_px":"247.150000000","ask_px":"960.000000000","bid_sz":400,"ask_sz":25,"bid_ct":1,"ask_ct":1},{"bid_px":"235.000000000","ask_px":null,"bid_sz":100,"ask_sz":0,"bid_ct":1,"ask_ct":0},{"bid_px":"203.000000000","ask_px":null,"bid_sz":2,"ask_sz":0,"bid_ct":1,"ask_ct":0},{"bid_px":"170.000000000","ask_px":null,"bid_sz":3,"ask_sz":0,"bid_ct":1,"ask_ct":0},{"bid_px":null,"ask_px":null,"bid_sz":0,"ask_sz":0,"bid_ct":0,"ask_ct":0},{"bid_px":null,"ask_px":null,"bid_sz":0,"ask_sz":0,"bid_ct":0,"ask_ct":0}],"symbol":"TSLA"}
{"ts_recv":"2024-11-01T08:00:03.225393824Z","hd":{"ts_event":"2024-11-01T08:00:03.225227516Z","rtype":10,"publisher_id":2,"instrument_id":16244},"action":"A","side":"B","depth":3,"price":"248.700000000","size":1000,"flags":130,"ts_in_delta":166308,"sequence":293382,"levels":[{"bid_px":"249.870000000","ask_px":"250.730000000","bid_sz":50,"ask_sz":100,"bid_ct":1,"ask_ct":1},{"bid_px":"249.600000000","ask_px":"250.960000000","bid_sz":1000,"ask_sz":50,"bid_ct":1,"ask_ct":1},{"bid_px":"249.500000000","ask_px":"252.200000000","bid_sz":1000,"ask_sz":1000,"bid_ct":1,"ask_ct":1},{"bid_px":"248.700000000","ask_px":"253.650000000","bid_sz":1000,"ask_sz":400,"bid_ct":1,"ask_ct":1},{"bid_px":"248.200000000","ask_px":"960.000000000","bid_sz":1000,"ask_sz":25,"bid_ct":1,"ask_ct":1},{"bid_px":"247.150000000","ask_px":null,"bid_sz":400,"ask_sz":0,"bid_ct":1,"ask_ct":0},{"bid_px":"235.000000000","ask_px":null,"bid_sz":100,"ask_sz":0,"bid_ct":1,"ask_ct":0},{"bid_px":"203.000000000","ask_px":null,"bid_sz":2,"ask_sz":0,"bid_ct":1,"ask_ct":0},{"bid_px":"170.000000000","ask_px":null,"bid_sz":3,"ask_sz":0,"bid_ct":1,"ask_ct":0},{"bid_px":null,"ask_px":null,"bid_sz":0,"ask_sz":0,"bid_ct":0,"ask_ct":0}],"symbol":"TSLA"}
{"ts_recv":"2024-11-01T08:00:03.225512312Z","hd":{"ts_event":"2024-11-01T08:00:03.225345068Z","rtype":10,"publisher_id":2,"instrument_id":16244},"action":"C","side":"B","depth":4,"price":"248.200000000","size":1000,"flags":130,"ts_in_delta":167244,"sequence":293383,"levels":[{"bid_px":"249.870000000","ask_px":"250.730000000","bid_sz":50,"ask_sz":100,"bid_ct":1,"ask_ct":1},{"bid_px":"249.600000000","ask_px":"250.960000000","bid_sz":1000,"ask_sz":50,"bid_ct":1,"ask_ct":1},{"bid_px":"249.500000000","ask_px":"252.200000000","bid_sz":1000,"ask_sz":1000,"bid_ct":1,"ask_ct":1},{"bid_px":"248.700000000","ask_px":"253.650000000","bid_sz":1000,"ask_sz":400,"bid_ct":1,"ask_ct":1},{"bid_px":"247.150000000","ask_px":"960.000000000","bid_sz":400,"ask_sz":25,"bid_ct":1,"ask_ct":1},{"bid_px":"235.000000000","ask_px":null,"bid_sz":100,"ask_sz":0,"bid_ct":1,"ask_ct":0},{"bid_px":"203.000000000","ask_px":null,"bid_sz":2,"ask_sz":0,"bid_ct":1,"ask_ct":0},{"bid_px":"170.000000000","ask_px":null,"bid_sz":3,"ask_sz":0,"bid_ct":1,"ask_ct":0},{"bid_px":null,"ask_px":null,"bid_sz":0,"ask_sz":0,"bid_ct":0,"ask_ct":0},{"bid_px":null,"ask_px":null,"bid_sz":0,"ask_sz":0,"bid_ct":0,"ask_ct":0}],"symbol":"TSLA"}
{"ts_recv":"2024-11-01T08:00:03.290794949Z","hd":{"ts_event":"2024-11-01T08:00:03.290628629Z","rtype":10,"publisher_id":2,"instrument_id":16244},"action":"C","side":"A","depth":2,"price":"252.200000000","size":1000,"flags":130,"ts_in_delta":166320,"sequence":293466,"levels":[{"bid_px":"249.870000000","ask_px":"250.730000000","bid_sz":50,"ask_sz":100,"bid_ct":1,"ask_ct":1},{"bid_px":"249.600000000","ask_px":"250.960000000","bid_sz":1000,"ask_sz":50,"bid_ct":1,"ask_ct":1},{"bid_px":"249.500000000","ask_px":"253.650000000","bid_sz":1000,"ask_sz":400,"bid_ct":1,"ask_ct":1},{"bid_px":"248.700000000","ask_px":"960.000000000","bid_sz":1000,"ask_sz":25,"bid_ct":1,"ask_ct":1},{"bid_px":"247.150000000","ask_px":null,"bid_sz":400,"ask_sz":0,"bid_ct":1,"ask_ct":0},{"bid_px":"235.000000000","ask_px":null,"bid_sz":100,"ask_sz":0,"bid_ct":1,"ask_ct":0},{"bid_px":"203.000000000","ask_px":null,"bid_sz":2,"ask_sz":0,"bid_ct":1,"ask_ct":0},{"bid_px":"170.000000000","ask_px":null,"bid_sz":3,"ask_sz":0,"bid_ct":1,"ask_ct":0},{"bid_px":null,"ask_px":null,"bid_sz":0,"ask_sz":0,"bid_ct":0,"ask_ct":0},{"bid_px":null,"ask_px":null,"bid_sz":0,"ask_sz":0,"bid_ct":0,"ask_ct":0}],"symbol":"TSLA"}
{"ts_recv":"2024-11-01T08:00:03.301371617Z","hd":{"ts_event":"2024-11-01T08:00:03.301205171Z","rtype":10,"publisher_id":2,"instrument_id":16244},"action":"A","side":"A","depth":2,"price":"252.300000000","size":1000,"flags":130,"ts_in_delta":166446,"sequence":293477,"levels":[{"bid_px":"249.870000000","ask_px":"250.730000000","bid_sz":50,"ask_sz":100,"bid_ct":1,"ask_ct":1},{"bid_px":"249.600000000","ask_px":"250.960000000","bid_sz":1000,"ask_sz":50,"bid_ct":1,"ask_ct":1},{"bid_px":"249.500000000","ask_px":"252.300000000","bid_sz":1000,"ask_sz":1000,"bid_ct":1,"ask_ct":1},{"bid_px":"248.700000000","ask_px":"253.650000000","bid_sz":1000,"ask_sz":400,"bid_ct":1,"ask_ct":1},{"bid_px":"247.150000000","ask_px":"960.000000000","bid_sz":400,"ask_sz":25,"bid_ct":1,"ask_ct":1},{"bid_px":"235.000000000","ask_px":null,"bid_sz":100,"ask_sz":0,"bid_ct":1,"ask_ct":0},{"bid_px":"203.000000000","ask_px":null,"bid_sz":2,"ask_sz":0,"bid_ct":1,"ask_ct":0},{"bid_px":"170.000000000","ask_px":null,"bid_sz":3,"ask_sz":0,"bid_ct":1,"ask_ct":0},{"bid_px":null,"ask_px":null,"bid_sz":0,"ask_sz":0,"bid_ct":0,"ask_ct":0},{"bid_px":null,"ask_px":null,"bid_sz":0,"ask_sz":0,"bid_ct":0,"ask_ct":0}],"symbol":"TSLA"}
{"ts_recv":"2024-11-01T08:00:03.864687567Z","hd":{"ts_event":"2024-11-01T08:00:03.864521543Z","rtype":10,"publisher_id":2,"instrument_id":16244},"action":"A","side":"B","depth":6,"price":"214.000000000","size":5,"flags":130,"ts_in_delta":166024,"sequence":294590,"levels":[{"bid_px":"249.870000000","ask_px":"250.730000000","bid_sz":50,"ask_sz":100,"bid_ct":1,"ask_ct":1},{"bid_px":"249.600000000","ask_px":"250.960000000","bid_sz":1000,"ask_sz":50,"bid_ct":1,"ask_ct":1},{"bid_px":"249.500000000","ask_px":"252.300000000","bid_sz":1000,"ask_sz":1000,"bid_ct":1,"ask_ct":1},{"bid_px":"248.700000000","ask_px":"253.650000000","bid_sz":1000,"ask_sz":400,"bid_ct":1,"ask_ct":1},{"bid_px":"247.150000000","ask_px":"960.000000000","bid_sz":400,"ask_sz":25,"bid_ct":1,"ask_ct":1},{"bid_px":"235.000000000","ask_px":null,"bid_sz":100,"ask_sz":0,"bid_ct":1,"ask_ct":0},{"bid_px":"214.000000000","ask_px":null,"bid_sz":5,"ask_sz":0,"bid_ct":1,"ask_ct":0},{"bid_px":"203.000000000","ask_px":null,"bid_sz":2,"ask_sz":0,"bid_ct":1,"ask_ct":0},{"bid_px":"170.000000000","ask_px":null,"bid_sz":3,"ask_sz":0,"bid_ct":1,"ask_ct":0},{"bid_px":null,"ask_px":null,"bid_sz":0,"ask_sz":0,"bid_ct":0,"ask_ct":0}],"symbol":"TSLA"}
{"ts_recv":"2024-11-01T08:00:03.990343678Z","hd":{"ts_event":"2024-11-01T08:00:03.990176949Z","rtype":10,"publisher_id":2,"instrument_id":16244},"action":"A","side":"A","depth":4,"price":"275.000000000","size":4,"flags":130,"ts_in_delta":166729,"sequence":294920,"levels":[{"bid_px":"249.870000000","ask_px":"250.730000000","bid_sz":50,"ask_sz":100,"bid_ct":1,"ask_ct":1},{"bid_px":"249.600000000","ask_px":"250.960000000","bid_sz":1000,"ask_sz":50,"bid_ct":1,"ask_ct":1},{"bid_px":"249.500000000","ask_px":"252.300000000","bid_sz":1000,"ask_sz":1000,"bid_ct":1,"ask_ct":1},{"bid_px":"248.700000000","ask_px":"253.650000000","bid_sz":1000,"ask_sz":400,"bid_ct":1,"ask_ct":1},{"bid_px":"247.150000000","ask_px":"275.000000000","bid_sz":400,"ask_sz":4,"bid_ct":1,"ask_ct":1},{"bid_px":"235.000000000","ask_px":"960.000000000","bid_sz":100,"ask_sz":25,"bid_ct":1,"ask_ct":1},{"bid_px":"214.000000000","ask_px":null,"bid_sz":5,"ask_sz":0,"bid_ct":1,"ask_ct":0},{"bid_px":"203.000000000","ask_px":null,"bid_sz":2,"ask_sz":0,"bid_ct":1,"ask_ct":0},{"bid_px":"170.000000000","ask_px":null,"bid_sz":3,"ask_sz":0,"bid_ct":1,"ask_ct":0},{"bid_px":null,"ask_px":null,"bid_sz":0,"ask_sz":0,"bid_ct":0,"ask_ct":0}],"symbol":"TSLA"}
{"ts_recv":"2024-11-01T08:00:04.119754546Z","hd":{"ts_event":"2024-11-01T08:00:04.119588707Z","rtype":10,"publisher_id":2,"instrument_id":16244},"action":"A","side":"A","depth":0,"price":"250.730000000","size":100,"flags":130,"ts_in_delta":165839,"sequence":295080,"levels":[{"bid_px":"249.870000000","ask_px":"250.730000000","bid_sz":50,"ask_sz":200,"bid_ct":1,"ask_ct":2},{"bid_px":"249.600000000","ask_px":"250.960000000","bid_sz":1000,"ask_sz":50,"bid_ct":1,"ask_ct":1},{"bid_px":"249.500000000","ask_px":"252.300000000","bid_sz":1000,"ask_sz":1000,"bid_ct":1,"ask_ct":1},{"bid_px":"248.700000000","ask_px":"253.650000000","bid_sz":1000,"ask_sz":400,"bid_ct":1,"ask_ct":1},{"bid_px":"247.150000000","ask_px":"275.000000000","bid_sz":400,"ask_sz":4,"bid_ct":1,"ask_ct":1},{"bid_px":"235.000000000","ask_px":"960.000000000","bid_sz":100,"ask_sz":25,"bid_ct":1,"ask_ct":1},{"bid_px":"214.000000000","ask_px":null,"bid_sz":5,"ask_sz":0,"bid_ct":1,"ask_ct":0},{"bid_px":"203.000000000","ask_px":null,"bid_sz":2,"ask_sz":0,"bid_ct":1,"ask_ct":0},{"bid_px":"170.000000000","ask_px":null,"bid_sz":3,"ask_sz":0,"bid_ct":1,"ask_ct":0},{"bid_px":null,"ask_px":null,"bid_sz":0,"ask_sz":0,"bid_ct":0,"ask_ct":0}],"symbol":"TSLA"}
{"ts_recv":"2024-11-01T08:00:04.119835321Z","hd":{"ts_event":"2024-11-01T08:00:04.119669642Z","rtype":10,"publisher_id":2,"instrument_id":16244},"action":"C","side":"B","depth":0,"price":"249.870000000","size":50,"flags":130,"ts_in_delta":165679,"sequence":295081,"levels":[{"bid_px":"249.600000000","ask_px":"250.730000000","bid_sz":1000,"ask_sz":200,"bid_ct":1,"ask_ct":2},{"bid_px":"249.500000000","ask_px":"250.960000000","bid_sz":1000,"ask_sz":50,"bid_ct":1,"ask_ct":1},{"bid_px":"248.700000000","ask_px":"252.300000000","bid_sz":1000,"ask_sz":1000,"bid_ct":1,"ask_ct":1},{"bid_px":"247.150000000","ask_px":"253.650000000","bid_sz":400,"ask_sz":400,"bid_ct":1,"ask_ct":1},{"bid_px":"235.000000000","ask_px":"275.000000000","bid_sz":100,"ask_sz":4,"bid_ct":1,"ask_ct":1},{"bid_px":"214.000000000","ask_px":"960.000000000","bid_sz":5,"ask_sz":25,"bid_ct":1,"ask_ct":1},{"bid_px":"203.000000000","ask_px":null,"bid_sz":2,"ask_sz":0,"bid_ct":1,"ask_ct":0},{"bid_px":"170.000000000","ask_px":null,"bid_sz":3,"ask_sz":0,"bid_ct":1,"ask_ct":0},{"bid_px":null,"ask_px":null,"bid_sz":0,"ask_sz":0,"bid_ct":0,"ask_ct":0},{"bid_px":null,"ask_px":null,"bid_sz":0,"ask_sz":0,"bid_ct":0,"ask_ct":0}],"symbol":"TSLA"}
{"ts_recv":"2024-11-01T08:00:04.119911891Z","hd":{"ts_event":"2024-11-01T08:00:04.119746189Z","rtype":10,"publisher_id":2,"instrument_id":16244},"action":"C","side":"B","depth":2,"price":"248.700000000","size":1000,"flags":130,"ts_in_delta":165702,"sequence":295082,"levels":[{"bid_px":"249.600000000","ask_px":"250.730000000","bid_sz":1000,"ask_sz":200,"bid_ct":1,"ask_ct":2},{"bid_px":"249.500000000","ask_px":"250.960000000","bid_sz":1000,"ask_sz":50,"bid_ct":1,"ask_ct":1},{"bid_px":"247.150000000","ask_px":"252.300000000","bid_sz":400,"ask_sz":1000,"bid_ct":1,"ask_ct":1},{"bid_px":"235.000000000","ask_px":"253.650000000","bid_sz":100,"ask_sz":400,"bid_ct":1,"ask_ct":1},{"bid_px":"214.000000000","ask_px":"275.000000000","bid_sz":5,"ask_sz":4,"bid_ct":1,"ask_ct":1},{"bid_px":"203.000000000","ask_px":"960.000000000","bid_sz":2,"ask_sz":25,"bid_ct":1,"ask_ct":1},{"bid_px":"170.000000000","ask_px":null,"bid_sz":3,"ask_sz":0,"bid_ct":1,"ask_ct":0},{"bid_px":null,"ask_px":null,"bid_sz":0,"ask_sz":0,"bid_ct":0,"ask_ct":0},{"bid_px":null,"ask_px":null,"bid_sz":0,"ask_sz":0,"bid_ct":0,"ask_ct":0},{"bid_px":null,"ask_px":null,"bid_sz":0,"ask_sz":0,"bid_ct":0,"ask_ct":0}],"symbol":"TSLA"}
{"ts_recv":"2024-11-01T08:00:04.120156195Z","hd":{"ts_event":"2024-11-01T08:00:04.119989815Z","rtype":10,"publisher_id":2,"instrument_id":16244},"action":"C","side":"B","depth":1,"price":"249.500000000","size":1000,"flags":130,"ts_in_delta":166380,"sequence":295083,"levels":[{"bid_px":"249.600000000","ask_px":"250.730000000","bid_sz":1000,"ask_sz":200,"bid_ct":1,"ask_ct":2},{"bid_px":"247.150000000","ask_px":"250.960000000","bid_sz":400,"ask_sz":50,"bid_ct":1,"ask_ct":1},{"bid_px":"235.000000000","ask_px":"252.300000000","bid_sz":100,"ask_sz":1000,"bid_ct":1,"ask_ct":1},{"bid_px":"214.000000000","ask_px":"253.650000000","bid_sz":5,"ask_sz":400,"bid_ct":1,"ask_ct":1},{"bid_px":"203.000000000","ask_px":"275.000000000","bid_sz":2,"ask_sz":4,"bid_ct":1,"ask_ct":1},{"bid_px":"170.000000000","ask_px":"960.000000000","bid_sz":3,"ask_sz":25,"bid_ct":1,"ask_ct":1},{"bid_px":null,"ask_px":null,"bid_sz":0,"ask_sz":0,"bid_ct":0,"ask_ct":0},{"bid_px":null,"ask_px":null,"bid_sz":0,"ask_sz":0,"bid_ct":0,"ask_ct":0},{"bid_px":null,"ask_px":null,"bid_sz":0,"ask_sz":0,"bid_ct":0,"ask_ct":0},{"bid_px":null,"ask_px":null,"bid_sz":0,"ask_sz":0,"bid_ct":0,"ask_ct":0}],"symbol":"TSLA"}
{"ts_recv":"2024-11-01T08:00:04.134985360Z","hd":{"ts_event":"2024-11-01T08:00:04.134815895Z","rtype":10,"publisher_id":2,"instrument_id":16244},"action":"A","side":"A","depth":2,"price":"251.300000000","size":1000,"flags":130,"ts_in_delta":169465,"sequence":295095,"levels":[{"bid_px":"249.600000000","ask_px":"250.730000000","bid_sz":1000,"ask_sz":200,"bid_ct":1,"ask_ct":2},{"bid_px":"247.150000000","ask_px":"250.960000000","bid_sz":400,"ask_sz":50,"bid_ct":1,"ask_ct":1},{"bid_px":"235.000000000","ask_px":"251.300000000","bid_sz":100,"ask_sz":1000,"bid_ct":1,"ask_ct":1},{"bid_px":"214.000000000","ask_px":"252.300000000","bid_sz":5,"ask_sz":1000,"bid_ct":1,"ask_ct":1},{"bid_px":"203.000000000","ask_px":"253.650000000","bid_sz":2,"ask_sz":400,"bid_ct":1,"ask_ct":1},{"bid_px":"170.000000000","ask_px":"275.000000000","bid_sz":3,"ask_sz":4,"bid_ct":1,"ask_ct":1},{"bid_px":null,"ask_px":"960.000000000","bid_sz":0,"ask_sz":25,"bid_ct":0,"ask_ct":1},{"bid_px":null,"ask_px":null,"bid_sz":0,"ask_sz":0,"bid_ct":0,"ask_ct":0},{"bid_px":null,"ask_px":null,"bid_sz":0,"ask_sz":0,"bid_ct":0,"ask_ct":0},{"bid_px":null,"ask_px":null,"bid_sz":0,"ask_sz":0,"bid_ct":0,"ask_ct":0}],"symbol":"TSLA"}
{"ts_recv":"2024-11-01T08:00:04.135044430Z","hd":{"ts_event":"2024-11-01T08:00:04.134878033Z","rtype":10,"publisher_id":2,"instrument_id":16244},"action":"C","side":"A","depth":3,"price":"252.300000000","size":1000,"flags":130,"ts_in_delta":166397,"sequence":295096,"levels":[{"bid_px":"249.600000000","ask_px":"250.730000000","bid_sz":1000,"ask_sz":200,"bid_ct":1,"ask_ct":2},{"bid_px":"247.150000000","ask_px":"250.960000000","bid_sz":400,"ask_sz":50,"bid_ct":1,"ask_ct":1},{"bid_px":"235.000000000","ask_px":"251.300000000","bid_sz":100,"ask_sz":1000,"bid_ct":1,"ask_ct":1},{"bid_px":"214.000000000","ask_px":"253.650000000","bid_sz":5,"ask_sz":400,"bid_ct":1,"ask_ct":1},{"bid_px":"203.000000000","ask_px":"275.000000000","bid_sz":2,"ask_sz":4,"bid_ct":1,"ask_ct":1},{"bid_px":"170.000000000","ask_px":"960.000000000","bid_sz":3,"ask_sz":25,"bid_ct":1,"ask_ct":1},{"bid_px":null,"ask_px":null,"bid_sz":0,"ask_sz":0,"bid_ct":0,"ask_ct":0},{"bid_px":null,"ask_px":null,"bid_sz":0,"ask_sz":0,"bid_ct":0,"ask_ct":0},{"bid_px":null,"ask_px":null,"bid_sz":0,"ask_sz":0,"bid_ct":0,"ask_ct":0},{"bid_px":null,"ask_px":null,"bid_sz":0,"ask_sz":0,"bid_ct":0,"ask_ct":0}],"symbol":"TSLA"}
{"ts_recv":"2024-11-01T08:00:04.153954286Z","hd":{"ts_event":"2024-11-01T08:00:04.153788131Z","rtype":10,"publisher_id":2,"instrument_id":16244},"action":"C","side":"A","depth":2,"price":"251.300000000","size":1000,"flags":130,"ts_in_delta":166155,"sequence":295110,"levels":[{"bid_px":"249.600000000","ask_px":"250.730000000","bid_sz":1000,"ask_sz":200,"bid_ct":1,"ask_ct":2},{"bid_px":"247.150000000","ask_px":"250.960000000","bid_sz":400,"ask_sz":50,"bid_ct":1,"ask_ct":1},{"bid_px":"235.000000000","ask_px":"253.650000000","bid_sz":100,"ask_sz":400,"bid_ct":1,"ask_ct":1},{"bid_px":"214.000000000","ask_px":"275.000000000","bid_sz":5,"ask_sz":4,"bid_ct":1,"ask_ct":1},{"bid_px":"203.000000000","ask_px":"960.000000000","bid_sz":2,"ask_sz":25,"bid_ct":1,"ask_ct":1},{"bid_px":"170.000000000","ask_px":null,"bid_sz":3,"ask_sz":0,"bid_ct":1,"ask_ct":0},{"bid_px":null,"ask_px":null,"bid_sz":0,"ask_sz":0,"bid_ct":0,"ask_ct":0},{"bid_px":null,"ask_px":null,"bid_sz":0,"ask_sz":0,"bid_ct":0,"ask_ct":0},{"bid_px":null,"ask_px":null,"bid_sz":0,"ask_sz":0,"bid_ct":0,"ask_ct":0},{"bid_px":null,"ask_px":null,"bid_sz":0,"ask_sz":0,"bid_ct":0,"ask_ct":0}],"symbol":"TSLA"}
{"ts_recv":"2024-11-01T08:00:04.162073569Z","hd":{"ts_event":"2024-11-01T08:00:04.161907144Z","rtype":10,"publisher_id":2,"instrument_id":16244},"action":"A","side":"B","depth":1,"price":"249.300000000","size":1000,"flags":130,"ts_in_delta":166425,"sequence":295120,"levels":[{"bid_px":"249.600000000","ask_px":"250.730000000","bid_sz":1000,"ask_sz":200,"bid_ct":1,"ask_ct":2},{"bid_px":"249.300000000","ask_px":"250.960000000","bid_sz":1000,"ask_sz":50,"bid_ct":1,"ask_ct":1},{"bid_px":"247.150000000","ask_px":"253.650000000","bid_sz":400,"ask_sz":400,"bid_ct":1,"ask_ct":1},{"bid_px":"235.000000000","ask_px":"275.000000000","bid_sz":100,"ask_sz":4,"bid_ct":1,"ask_ct":1},{"bid_px":"214.000000000","ask_px":"960.000000000","bid_sz":5,"ask_sz":25,"bid_ct":1,"ask_ct":1},{"bid_px":"203.000000000","ask_px":null,"bid_sz":2,"ask_sz":0,"bid_ct":1,"ask_ct":0},{"bid_px":"170.000000000","ask_px":null,"bid_sz":3,"ask_sz":0,"bid_ct":1,"ask_ct":0},{"bid_px":null,"ask_px":null,"bid_sz":0,"ask_sz":0,"bid_ct":0,"ask_ct":0},{"bid_px":null,"ask_px":null,"bid_sz":0,"ask_sz":0,"bid_ct":0,"ask_ct":0},{"bid_px":null,"ask_px":null,"bid_sz":0,"ask_sz":0,"bid_ct":0,"ask_ct":0}],"symbol":"TSLA"}
{"ts_recv":"2024-11-01T08:00:04.164271209Z","hd":{"ts_event":"2024-11-01T08:00:04.164104182Z","rtype":10,"publisher_id":2,"instrument_id":16244},"action":"A","side":"A","depth":2,"price":"251.700000000","size":1000,"flags":130,"ts_in_delta":167027,"sequence":295121,"levels":[{"bid_px":"249.600000000","ask_px":"250.730000000","bid_sz":1000,"ask_sz":200,"bid_ct":1,"ask_ct":2},{"bid_px":"249.300000000","ask_px":"250.960000000","bid_sz":1000,"ask_sz":50,"bid_ct":1,"ask_ct":1},{"bid_px":"247.150000000","ask_px":"251.700000000","bid_sz":400,"ask_sz":1000,"bid_ct":1,"ask_ct":1},{"bid_px":"235.000000000","ask_px":"253.650000000","bid_sz":100,"ask_sz":400,"bid_ct":1,"ask_ct":1},{"bid_px":"214.000000000","ask_px":"275.000000000","bid_sz":5,"ask_sz":4,"bid_ct":1,"ask_ct":1},{"bid_px":"203.000000000","ask_px":"960.000000000","bid_sz":2,"ask_sz":25,"bid_ct":1,"ask_ct":1},{"bid_px":"170.000000000","ask_px":null,"bid_sz":3,"ask_sz":0,"bid_ct":1,"ask_ct":0},{"bid_px":null,"ask_px":null,"bid_sz":0,"ask_sz":0,"bid_ct":0,"ask_ct":0},{"bid_px":null,"ask_px":null,"bid_sz":0,"ask_sz":0,"bid_ct":0,"ask_ct":0},{"bid_px":null,"ask_px":null,"bid_sz":0,"ask_sz":0,"bid_ct":0,"ask_ct":0}],"symbol":"TSLA"}
{"ts_recv":"2024-11-01T08:00:04.172136969Z","hd":{"ts_event":"2024-11-01T08:00:04.171971303Z","rtype":10,"publisher_id":2,"instrument_id":16244},"action":"C","side":"A","depth":2,"price":"251.700000000","size":1000,"flags":130,"ts_in_delta":165666,"sequence":295134,"levels":[{"bid_px":"249.600000000","ask_px":"250.730000000","bid_sz":1000,"ask_sz":200,"bid_ct":1,"ask_ct":2},{"bid_px":"249.300000000","ask_px":"250.960000000","bid_sz":1000,"ask_sz":50,"bid_ct":1,"ask_ct":1},{"bid_px":"247.150000000","ask_px":"253.650000000","bid_sz":400,"ask_sz":400,"bid_ct":1,"ask_ct":1},{"bid_px":"235.000000000","ask_px":"275.000000000","bid_sz":100,"ask_sz":4,"bid_ct":1,"ask_ct":1},{"bid_px":"214.000000000","ask_px":"960.000000000","bid_sz":5,"ask_sz":25,"bid_ct":1,"ask_ct":1},{"bid_px":"203.000000000","ask_px":null,"bid_sz":2,"ask_sz":0,"bid_ct":1,"ask_ct":0},{"bid_px":"170.000000000","ask_px":null,"bid_sz":3,"ask_sz":0,"bid_ct":1,"ask_ct":0},{"bid_px":null,"ask_px":null,"bid_sz":0,"ask_sz":0,"bid_ct":0,"ask_ct":0},{"bid_px":null,"ask_px":null,"bid_sz":0,"ask_sz":0,"bid_ct":0,"ask_ct":0},{"bid_px":null,"ask_px":null,"bid_sz":0,"ask_sz":0,"bid_ct":0,"ask_ct":0}],"symbol":"TSLA"}
{"ts_recv":"2024-11-01T08:00:04.185656271Z","hd":{"ts_event":"2024-11-01T08:00:04.185489815Z","rtype":10,"publisher_id":2,"instrument_id":16244},"action":"A","side":"A","depth":2,"price":"251.300000000","size":1000,"flags":130,"ts_in_delta":166456,"sequence":295160,"levels":[{"bid_px":"249.600000000","ask_px":"250.730000000","bid_sz":1000,"ask_sz":200,"bid_ct":1,"ask_ct":2},{"bid_px":"249.300000000","ask_px":"250.960000000","bid_sz":1000,"ask_sz":50,"bid_ct":1,"ask_ct":1},{"bid_px":"247.150000000","ask_px":"251.300000000","bid_sz":400,"ask_sz":1000,"bid_ct":1,"ask_ct":1},{"bid_px":"235.000000000","ask_px":"253.650000000","bid_sz":100,"ask_sz":400,"bid_ct":1,"ask_ct":1},{"bid_px":"214.000000000","ask_px":"275.000000000","bid_sz":5,"ask_sz":4,"bid_ct":1,"ask_ct":1},{"bid_px":"203.000000000","ask_px":"960.000000000","bid_sz":2,"ask_sz":25,"bid_ct":1,"ask_ct":1},{"bid_px":"170.000000000","ask_px":null,"bid_sz":3,"ask_sz":0,"bid_ct":1,"ask_ct":0},{"bid_px":null,"ask_px":null,"bid_sz":0,"ask_sz":0,"bid_ct":0,"ask_ct":0},{"bid_px":null,"ask_px":null,"bid_sz":0,"ask_sz":0,"bid_ct":0,"ask_ct":0},{"bid_px":null,"ask_px":null,"bid_sz":0,"ask_sz":0,"bid_ct":0,"ask_ct":0}],"symbol":"TSLA"}
{"ts_recv":"2024-11-01T08:00:04.185708515Z","hd":{"ts_event":"2024-11-01T08:00:04.185542577Z","rtype":10,"publisher_id":2,"instrument_id":16244},"action":"C","side":"A","depth":0,"price":"250.730000000","size":100,"flags":130,"ts_in_delta":165938,"sequence":295161,"levels":[{"bid_px":"249.600000000","ask_px":"250.730000000","bid_sz":1000,"ask_sz":100,"bid_ct":1,"ask_ct":1},{"bid_px":"249.300000000","ask_px":"250.960000000","bid_sz":1000,"ask_sz":50,"bid_ct":1,"ask_ct":1},{"bid_px":"247.150000000","ask_px":"251.300000000","bid_sz":400,"ask_sz":1000,"bid_ct":1,"ask_ct":1},{"bid_px":"235.000000000","ask_px":"253.650000000","bid_sz":100,"ask_sz":400,"bid_ct":1,"ask_ct":1},{"bid_px":"214.000000000","ask_px":"275.000000000","bid_sz":5,"ask_sz":4,"bid_ct":1,"ask_ct":1},{"bid_px":"203.000000000","ask_px":"960.000000000","bid_sz":2,"ask_sz":25,"bid_ct":1,"ask_ct":1},{"bid_px":"170.000000000","ask_px":null,"bid_sz":3,"ask_sz":0,"bid_ct":1,"ask_ct":0},{"bid_px":null,"ask_px":null,"bid_sz":0,"ask_sz":0,"bid_ct":0,"ask_ct":0},{"bid_px":null,"ask_px":null,"bid_sz":0,"ask_sz":0,"bid_ct":0,"ask_ct":0},{"bid_px":null,"ask_px":null,"bid_sz":0,"ask_sz":0,"bid_ct":0,"ask_ct":0}],"symbol":"TSLA"}
{"ts_recv":"2024-11-01T08:00:04.185728699Z","hd":{"ts_event":"2024-11-01T08:00:04.185562559Z","rtype":10,"publisher_id":2,"instrument_id":16244},"action":"A","side":"A","depth":0,"price":"250.680000000","size":100,"flags":130,"ts_in_delta":166140,"sequence":295162,"levels":[{"bid_px":"249.600000000","ask_px":"250.680000000","bid_sz":1000,"ask_sz":100,"bid_ct":1,"ask_ct":1},{"bid_px":"249.300000000","ask_px":"250.960000000","bid_sz":1000,"ask_sz":50,"bid_ct":1,"ask_ct":1},{"bid_px":"247.150000000","ask_px":"251.300000000","bid_sz":400,"ask_sz":1000,"bid_ct":1,"ask_ct":1},{"bid_px":"235.000000000","ask_px":"253.650000000","bid_sz":100,"ask_sz":400,"bid_ct":1,"ask_ct":1},{"bid_px":"214.000000000","ask_px":"275.000000000","bid_sz":5,"ask_sz":4,"bid_ct":1,"ask_ct":1},{"bid_px":"203.000000000","ask_px":"960.000000000","bid_sz":2,"ask_sz":25,"bid_ct":1,"ask_ct":1},{"bid_px":"170.000000000","ask_px":null,"bid_sz":3,"ask_sz":0,"bid_ct":1,"ask_ct":0},{"bid_px":null,"ask_px":null,"bid_sz":0,"ask_sz":0,"bid_ct":0,"ask_ct":0},{"bid_px":null,"ask_px":null,"bid_sz":0,"ask_sz":0,"bid_ct":0,"ask_ct":0},{"bid_px":null,"ask_px":null,"bid_sz":0,"ask_sz":0,"bid_ct":0,"ask_ct":0}],"symbol":"TSLA"}
{"ts_recv":"2024-11-01T08:00:04.209954772Z","hd":{"ts_event":"2024-11-01T08:00:04.209789063Z","rtype":10,"publisher_id":2,"instrument_id":16244},"action":"C","side":"A","depth":2,"price":"251.300000000","size":1000,"flags":130,"ts_in_delta":165709,"sequence":295186,"levels":[{"bid_px":"249.600000000","ask_px":"250.680000000","bid_sz":1000,"ask_sz":100,"bid_ct":1,"ask_ct":1},{"bid_px":"249.300000000","ask_px":"250.960000000","bid_sz":1000,"ask_sz":50,"bid_ct":1,"ask_ct":1},{"bid_px":"247.150000000","ask_px":"253.650000000","bid_sz":400,"ask_sz":400,"bid_ct":1,"ask_ct":1},{"bid_px":"235.000000000","ask_px":"275.000000000","bid_sz":100,"ask_sz":4,"bid_ct":1,"ask_ct":1},{"bid_px":"214.000000000","ask_px":"960.000000000","bid_sz":5,"ask_sz":25,"bid_ct":1,"ask_ct":1},{"bid_px":"203.000000000","ask_px":null,"bid_sz":2,"ask_sz":0,"bid_ct":1,"ask_ct":0},{"bid_px":"170.000000000","ask_px":null,"bid_sz":3,"ask_sz":0,"bid_ct":1,"ask_ct":0},{"bid_px":null,"ask_px":null,"bid_sz":0,"ask_sz":0,"bid_ct":0,"ask_ct":0},{"bid_px":null,"ask_px":null,"bid_sz":0,"ask_sz":0,"bid_ct":0,"ask_ct":0},{"bid_px":null,"ask_px":null,"bid_sz":0,"ask_sz":0,"bid_ct":0,"ask_ct":0}],"symbol":"TSLA"}
{"ts_recv":"2024-11-01T08:00:04.210810479Z","hd":{"ts_event":"2024-11-01T08:00:04.210644343Z","rtype":10,"publisher_id":2,"instrument_id":16244},"action":"A","side":"B","depth":5,"price":"213.000000000","size":1,"flags":130,"ts_in_delta":166136,"sequence":295187,"levels":[{"bid_px":"249.600000000","ask_px":"250.680000000","bid_sz":1000,"ask_sz":100,"bid_ct":1,"ask_ct":1},{"bid_px":"249.300000000","ask_px":"250.960000000","bid_sz":1000,"ask_sz":50,"bid_ct":1,"ask_ct":1},{"bid_px":"247.150000000","ask_px":"253.650000000","bid_sz":400,"ask_sz":400,"bid_ct":1,"ask_ct":1},{"bid_px":"235.000000000","ask_px":"275.000000000","bid_sz":100,"ask_sz":4,"bid_ct":1,"ask_ct":1},{"bid_px":"214.000000000","ask_px":"960.000000000","bid_sz":5,"ask_sz":25,"bid_ct":1,"ask_ct":1},{"bid_px":"213.000000000","ask_px":null,"bid_sz":1,"ask_sz":0,"bid_ct":1,"ask_ct":0},{"bid_px":"203.000000000","ask_px":null,"bid_sz":2,"ask_sz":0,"bid_ct":1,"ask_ct":0},{"bid_px":"170.000000000","ask_px":null,"bid_sz":3,"ask_sz":0,"bid_ct":1,"ask_ct":0},{"bid_px":null,"ask_px":null,"bid_sz":0,"ask_sz":0,"bid_ct":0,"ask_ct":0},{"bid_px":null,"ask_px":null,"bid_sz":0,"ask_sz":0,"bid_ct":0,"ask_ct":0}],"symbol":"TSLA"}
{"ts_recv":"2024-11-01T08:00:04.220490319Z","hd":{"ts_event":"2024-11-01T08:00:04.220324092Z","rtype":10,"publisher_id":2,"instrument_id":16244},"action":"A","side":"A","depth":2,"price":"251.700000000","size":1000,"flags":130,"ts_in_delta":166227,"sequence":295214,"levels":[{"bid_px":"249.600000000","ask_px":"250.680000000","bid_sz":1000,"ask_sz":100,"bid_ct":1,"ask_ct":1},{"bid_px":"249.300000000","ask_px":"250.960000000","bid_sz":1000,"ask_sz":50,"bid_ct":1,"ask_ct":1},{"bid_px":"247.150000000","ask_px":"251.700000000","bid_sz":400,"ask_sz":1000,"bid_ct":1,"ask_ct":1},{"bid_px":"235.000000000","ask_px":"253.650000000","bid_sz":100,"ask_sz":400,"bid_ct":1,"ask_ct":1},{"bid_px":"214.000000000","ask_px":"275.000000000","bid_sz":5,"ask_sz":4,"bid_ct":1,"ask_ct":1},{"bid_px":"213.000000000","ask_px":"960.000000000","bid_sz":1,"ask_sz":25,"bid_ct":1,"ask_ct":1},{"bid_px":"203.000000000","ask_px":null,"bid_sz":2,"ask_sz":0,"bid_ct":1,"ask_ct":0},{"bid_px":"170.000000000","ask_px":null,"bid_sz":3,"ask_sz":0,"bid_ct":1,"ask_ct":0},{"bid_px":null,"ask_px":null,"bid_sz":0,"ask_sz":0,"bid_ct":0,"ask_ct":0},{"bid_px":null,"ask_px":null,"bid_sz":0,"ask_sz":0,"bid_ct":0,"ask_ct":0}],"symbol":"TSLA"}
{"ts_recv":"2024-11-01T08:00:04.238566791Z","hd":{"ts_event":"2024-11-01T08:00:04.238400706Z","rtype":10,"publisher_id":2,"instrument_id":16244},"action":"A","side":"B","depth":0,"price":"249.870000000","size":50,"flags":130,"ts_in_delta":166085,"sequence":295290,"levels":[{"bid_px":"249.870000000","ask_px":"250.680000000","bid_sz":50,"ask_sz":100,"bid_ct":1,"ask_ct":1},{"bid_px":"249.600000000","ask_px":"250.960000000","bid_sz":1000,"ask_sz":50,"bid_ct":1,"ask_ct":1},{"bid_px":"249.300000000","ask_px":"251.700000000","bid_sz":1000,"ask_sz":1000,"bid_ct":1,"ask_ct":1},{"bid_px":"247.150000000","ask_px":"253.650000000","bid_sz":400,"ask_sz":400,"bid_ct":1,"ask_ct":1},{"bid_px":"235.000000000","ask_px":"275.000000000","bid_sz":100,"ask_sz":4,"bid_ct":1,"ask_ct":1},{"bid_px":"214.000000000","ask_px":"960.000000000","bid_sz":5,"ask_sz":25,"bid_ct":1,"ask_ct":1},{"bid_px":"213.000000000","ask_px":null,"bid_sz":1,"ask_sz":0,"bid_ct":1,"ask_ct":0},{"bid_px":"203.000000000","ask_px":null,"bid_sz":2,"ask_sz":0,"bid_ct":1,"ask_ct":0},{"bid_px":"170.000000000","ask_px":null,"bid_sz":3,"ask_sz":0,"bid_ct":1,"ask_ct":0},{"bid_px":null,"ask_px":null,"bid_sz":0,"ask_sz":0,"bid_ct":0,"ask_ct":0}],"symbol":"TSLA"}
{"ts_recv":"2024-11-01T08:00:04.238923737Z","hd":{"ts_event":"2024-11-01T08:00:04.238758087Z","rtype":10,"publisher_id":2,"instrument_id":16244},"action":"C","side":"A","depth":2,"price":"251.700000000","size":1000,"flags":130,"ts_in_delta":165650,"sequence":295293,"levels":[{"bid_px":"249.870000000","ask_px":"250.680000000","bid_sz":50,"ask_sz":100,"bid_ct":1,"ask_ct":1},{"bid_px":"249.600000000","ask_px":"250.960000000","bid_sz":1000,"ask_sz":50,"bid_ct":1,"ask_ct":1},{"bid_px":"249.300000000","ask_px":"253.650000000","bid_sz":1000,"ask_sz":400,"bid_ct":1,"ask_ct":1},{"bid_px":"247.150000000","ask_px":"275.000000000","bid_sz":400,"ask_sz":4,"bid_ct":1,"ask_ct":1},{"bid_px":"235.000000000","ask_px":"960.000000000","bid_sz":100,"ask_sz":25,"bid_ct":1,"ask_ct":1},{"bid_px":"214.000000000","ask_px":null,"bid_sz":5,"ask_sz":0,"bid_ct":1,"ask_ct":0},{"bid_px":"213.000000000","ask_px":null,"bid_sz":1,"ask_sz":0,"bid_ct":1,"ask_ct":0},{"bid_px":"203.000000000","ask_px":null,"bid_sz":2,"ask_sz":0,"bid_ct":1,"ask_ct":0},{"bid_px":"170.000000000","ask_px":null,"bid_sz":3,"ask_sz":0,"bid_ct":1,"ask_ct":0},{"bid_px":null,"ask_px":null,"bid_sz":0,"ask_sz":0,"bid_ct":0,"ask_ct":0}],"symbol":"TSLA"}
{"ts_recv":"2024-11-01T08:00:04.249251005Z","hd":{"ts_event":"2024-11-01T08:00:04.249084553Z","rtype":10,"publisher_id":2,"instrument_id":16244},"action":"A","side":"A","depth":2,"price":"251.900000000","size":1000,"flags":130,"ts_in_delta":166452,"sequence":295330,"levels":[{"bid_px":"249.870000000","ask_px":"250.680000000","bid_sz":50,"ask_sz":100,"bid_ct":1,"ask_ct":1},{"bid_px":"249.600000000","ask_px":"250.960000000","bid_sz":1000,"ask_sz":50,"bid_ct":1,"ask_ct":1},{"bid_px":"249.300000000","ask_px":"251.900000000","bid_sz":1000,"ask_sz":1000,"bid_ct":1,"ask_ct":1},{"bid_px":"247.150000000","ask_px":"253.650000000","bid_sz":400,"ask_sz":400,"bid_ct":1,"ask_ct":1},{"bid_px":"235.000000000","ask_px":"275.000000000","bid_sz":100,"ask_sz":4,"bid_ct":1,"ask_ct":1},{"bid_px":"214.000000000","ask_px":"960.000000000","bid_sz":5,"ask_sz":25,"bid_ct":1,"ask_ct":1},{"bid_px":"213.000000000","ask_px":null,"bid_sz":1,"ask_sz":0,"bid_ct":1,"ask_ct":0},{"bid_px":"203.000000000","ask_px":null,"bid_sz":2,"ask_sz":0,"bid_ct":1,"ask_ct":0},{"bid_px":"170.000000000","ask_px":null,"bid_sz":3,"ask_sz":0,"bid_ct":1,"ask_ct":0},{"bid_px":null,"ask_px":null,"bid_sz":0,"ask_sz":0,"bid_ct":0,"ask_ct":0}],"symbol":"TSLA"}
{"ts_recv":"2024-11-01T08:00:04.366083888Z","hd":{"ts_event":"2024-11-01T08:00:04.365918109Z","rtype":10,"publisher_id":2,"instrument_id":16244},"action":"C","side":"B","depth":0,"price":"249.870000000","size":50,"flags":130,"ts_in_delta":165779,"sequence":295485,"levels":[{"bid_px":"249.600000000","ask_px":"250.680000000","bid_sz":1000,"ask_sz":100,"bid_ct":1,"ask_ct":1},{"bid_px":"249.300000000","ask_px":"250.960000000","bid_sz":1000,"ask_sz":50,"bid_ct":1,"ask_ct":1},{"bid_px":"247.150000000","ask_px":"251.900000000","bid_sz":400,"ask_sz":1000,"bid_ct":1,"ask_ct":1},{"bid_px":"235.000000000","ask_px":"253.650000000","bid_sz":100,"ask_sz":400,"bid_ct":1,"ask_ct":1},{"bid_px":"214.000000000","ask_px":"275.000000000","bid_sz":5,"ask_sz":4,"bid_ct":1,"ask_ct":1},{"bid_px":"213.000000000","ask_px":"960.000000000","bid_sz":1,"ask_sz":25,"bid_ct":1,"ask_ct":1},{"bid_px":"203.000000000","ask_px":null,"bid_sz":2,"ask_sz":0,"bid_ct":1,"ask_ct":0},{"bid_px":"170.000000000","ask_px":null,"bid_sz":3,"ask_sz":0,"bid_ct":1,"ask_ct":0},{"bid_px":null,"ask_px":null,"bid_sz":0,"ask_sz":0,"bid_ct":0,"ask_ct":0},{"bid_px":null,"ask_px":null,"bid_sz":0,"ask_sz":0,"bid_ct":0,"ask_ct":0}],"symbol":"TSLA"}
{"ts_recv":"2024-11-01T08:00:04.366098645Z","hd":{"ts_event":"2024-11-01T08:00:04.365931595Z","rtype":10,"publisher_id":2,"instrument_id":16244},"action":"A","side":"B","depth":0,"price":"249.850000000","size":50,"flags":128,"ts_in_delta":167050,"sequence":295487,"levels":[{"bid_px":"249.850000000","ask_px":"250.680000000","bid_sz":50,"ask_sz":100,"bid_ct":1,"ask_ct":1},{"bid_px":"249.600000000","ask_px":"250.960000000","bid_sz":1000,"ask_sz":50,"bid_ct":1,"ask_ct":1},{"bid_px":"249.300000000","ask_px":"251.900000000","bid_sz":1000,"ask_sz":1000,"bid_ct":1,"ask_ct":1},{"bid_px":"247.150000000","ask_px":"253.650000000","bid_sz":400,"ask_sz":400,"bid_ct":1,"ask_ct":1},{"bid_px":"235.000000000","ask_px":"275.000000000","bid_sz":100,"ask_sz":4,"bid_ct":1,"ask_ct":1},{"bid_px":"214.000000000","ask_px":"960.000000000","bid_sz":5,"ask_sz":25,"bid_ct":1,"ask_ct":1},{"bid_px":"213.000000000","ask_px":null,"bid_sz":1,"ask_sz":0,"bid_ct":1,"ask_ct":0},{"bid_px":"203.000000000","ask_px":null,"bid_sz":2,"ask_sz":0,"bid_ct":1,"ask_ct":0},{"bid_px":"170.000000000","ask_px":null,"bid_sz":3,"ask_sz":0,"bid_ct":1,"ask_ct":0},{"bid_px":null,"ask_px":null,"bid_sz":0,"ask_sz":0,"bid_ct":0,"ask_ct":0}],"symbol":"TSLA"}
{"ts_recv":"2024-11-01T08:00:04.367087628Z","hd":{"ts_event":"2024-11-01T08:00:04.366921961Z","rtype":10,"publisher_id":2,"instrument_id":16244},"action":"C","side":"B","depth":0,"price":"249.850000000","size":50,"flags":130,"ts_in_delta":165667,"sequence":295494,"levels":[{"bid_px":"249.600000000","ask_px":"250.680000000","bid_sz":1000,"ask_sz":100,"bid_ct":1,"ask_ct":1},{"bid_px":"249.300000000","ask_px":"250.960000000","bid_sz":1000,"ask_sz":50,"bid_ct":1,"ask_ct":1},{"bid_px":"247.150000000","ask_px":"251.900000000","bid_sz":400,"ask_sz":1000,"bid_ct":1,"ask_ct":1},{"bid_px":"235.000000000","ask_px":"253.650000000","bid_sz":100,"ask_sz":400,"bid_ct":1,"ask_ct":1},{"bid_px":"214.000000000","ask_px":"275.000000000","bid_sz":5,"ask_sz":4,"bid_ct":1,"ask_ct":1},{"bid_px":"213.000000000","ask_px":"960.000000000","bid_sz":1,"ask_sz":25,"bid_ct":1,"ask_ct":1},{"bid_px":"203.000000000","ask_px":null,"bid_sz":2,"ask_sz":0,"bid_ct":1,"ask_ct":0},{"bid_px":"170.000000000","ask_px":null,"bid_sz":3,"ask_sz":0,"bid_ct":1,"ask_ct":0},{"bid_px":null,"ask_px":null,"bid_sz":0,"ask_sz":0,"bid_ct":0,"ask_ct":0},{"bid_px":null,"ask_px":null,"bid_sz":0,"ask_sz":0,"bid_ct":0,"ask_ct":0}],"symbol":"TSLA"}
{"ts_recv":"2024-11-01T08:00:04.367100716Z","hd":{"ts_event":"2024-11-01T08:00:04.366934766Z","rtype":10,"publisher_id":2,"instrument_id":16244},"action":"A","side":"B","depth":0,"price":"249.820000000","size":100,"flags":130,"ts_in_delta":165950,"sequence":295495,"levels":[{"bid_px":"249.820000000","ask_px":"250.680000000","bid_sz":100,"ask_sz":100,"bid_ct":1,"ask_ct":1},{"bid_px":"249.600000000","ask_px":"250.960000000","bid_sz":1000,"ask_sz":50,"bid_ct":1,"ask_ct":1},{"bid_px":"249.300000000","ask_px":"251.900000000","bid_sz":1000,"ask_sz":1000,"bid_ct":1,"ask_ct":1},{"bid_px":"247.150000000","ask_px":"253.650000000","bid_sz":400,"ask_sz":400,"bid_ct":1,"ask_ct":1},{"bid_px":"235.000000000","ask_px":"275.000000000","bid_sz":100,"ask_sz":4,"bid_ct":1,"ask_ct":1},{"bid_px":"214.000000000","ask_px":"960.000000000","bid_sz":5,"ask_sz":25,"bid_ct":1,"ask_ct":1},{"bid_px":"213.000000000","ask_px":null,"bid_sz":1,"ask_sz":0,"bid_ct":1,"ask_ct":0},{"bid_px":"203.000000000","ask_px":null,"bid_sz":2,"ask_sz":0,"bid_ct":1,"ask_ct":0},{"bid_px":"170.000000000","ask_px":null,"bid_sz":3,"ask_sz":0,"bid_ct":1,"ask_ct":0},{"bid_px":null,"ask_px":null,"bid_sz":0,"ask_sz":0,"bid_ct":0,"ask_ct":0}],"symbol":"TSLA"}
{"ts_recv":"2024-11-01T08:00:04.390459448Z","hd":{"ts_event":"2024-11-01T08:00:04.390293393Z","rtype":10,"publisher_id":2,"instrument_id":16244},"action":"A","side":"A","depth":4,"price":"265.000000000","size":1,"flags":130,"ts_in_delta":166055,"sequence":295522,"levels":[{"bid_px":"249.820000000","ask_px":"250.680000000","bid_sz":100,"ask_sz":100,"bid_ct":1,"ask_ct":1},{"bid_px":"249.600000000","ask_px":"250.960000000","bid_sz":1000,"ask_sz":50,"bid_ct":1,"ask_ct":1},{"bid_px":"249.300000000","ask_px":"251.900000000","bid_sz":1000,"ask_sz":1000,"bid_ct":1,"ask_ct":1},{"bid_px":"247.150000000","ask_px":"253.650000000","bid_sz":400,"ask_sz":400,"bid_ct":1,"ask_ct":1},{"bid_px":"235.000000000","ask_px":"265.000000000","bid_sz":100,"ask_sz":1,"bid_ct":1,"ask_ct":1},{"bid_px":"214.000000000","ask_px":"275.000000000","bid_sz":5,"ask_sz":4,"bid_ct":1,"ask_ct":1},{"bid_px":"213.000000000","ask_px":"960.000000000","bid_sz":1,"ask_sz":25,"bid_ct":1,"ask_ct":1},{"bid_px":"203.000000000","ask_px":null,"bid_sz":2,"ask_sz":0,"bid_ct":1,"ask_ct":0},{"bid_px":"170.000000000","ask_px":null,"bid_sz":3,"ask_sz":0,"bid_ct":1,"ask_ct":0},{"bid_px":null,"ask_px":null,"bid_sz":0,"ask_sz":0,"bid_ct":0,"ask_ct":0}],"symbol":"TSLA"}
{"ts_recv":"2024-11-01T08:00:04.404980797Z","hd":{"ts_event":"2024-11-01T08:00:04.404814202Z","rtype":10,"publisher_id":2,"instrument_id":16244},"action":"A","side":"B","depth":5,"price":"220.000000000","size":1,"flags":130,"ts_in_delta":166595,"sequence":295529,"levels":[{"bid_px":"249.820000000","ask_px":"250.680000000","bid_sz":100,"ask_sz":100,"bid_ct":1,"ask_ct":1},{"bid_px":"249.600000000","ask_px":"250.960000000","bid_sz":1000,"ask_sz":50,"bid_ct":1,"ask_ct":1},{"bid_px":"249.300000000","ask_px":"251.900000000","bid_sz":1000,"ask_sz":1000,"bid_ct":1,"ask_ct":1},{"bid_px":"247.150000000","ask_px":"253.650000000","bid_sz":400,"ask_sz":400,"bid_ct":1,"ask_ct":1},{"bid_px":"235.000000000","ask_px":"265.000000000","bid_sz":100,"ask_sz":1,"bid_ct":1,"ask_ct":1},{"bid_px":"220.000000000","ask_px":"275.000000000","bid_sz":1,"ask_sz":4,"bid_ct":1,"ask_ct":1},{"bid_px":"214.000000000","ask_px":"960.000000000","bid_sz":5,"ask_sz":25,"bid_ct":1,"ask_ct":1},{"bid_px":"213.000000000","ask_px":null,"bid_sz":1,"ask_sz":0,"bid_ct":1,"ask_ct":0},{"bid_px":"203.000000000","ask_px":null,"bid_sz":2,"ask_sz":0,"bid_ct":1,"ask_ct":0},{"bid_px":"170.000000000","ask_px":null,"bid_sz":3,"ask_sz":0,"bid_ct":1,"ask_ct":0}],"symbol":"TSLA"}
{"ts_recv":"2024-11-01T08:00:04.443604460Z","hd":{"ts_event":"2024-11-01T08:00:04.443438209Z","rtype":10,"publisher_id":2,"instrument_id":16244},"action":"A","side":"A","depth":1,"price":"250.960000000","size":50,"flags":130,"ts_in_delta":166251,"sequence":295569,"levels":[{"bid_px":"249.820000000","ask_px":"250.680000000","bid_sz":100,"ask_sz":100,"bid_ct":1,"ask_ct":1},{"bid_px":"249.600000000","ask_px":"250.960000000","bid_sz":1000,"ask_sz":100,"bid_ct":1,"ask_ct":2},{"bid_px":"249.300000000","ask_px":"251.900000000","bid_sz":1000,"ask_sz":1000,"bid_ct":1,"ask_ct":1},{"bid_px":"247.150000000","ask_px":"253.650000000","bid_sz":400,"ask_sz":400,"bid_ct":1,"ask_ct":1},{"bid_px":"235.000000000","ask_px":"265.000000000","bid_sz":100,"ask_sz":1,"bid_ct":1,"ask_ct":1},{"bid_px":"220.000000000","ask_px":"275.000000000","bid_sz":1,"ask_sz":4,"bid_ct":1,"ask_ct":1},{"bid_px":"214.000000000","ask_px":"960.000000000","bid_sz":5,"ask_sz":25,"bid_ct":1,"ask_ct":1},{"bid_px":"213.000000000","ask_px":null,"bid_sz":1,"ask_sz":0,"bid_ct":1,"ask_ct":0},{"bid_px":"203.000000000","ask_px":null,"bid_sz":2,"ask_sz":0,"bid_ct":1,"ask_ct":0},{"bid_px":"170.000000000","ask_px":null,"bid_sz":3,"ask_sz":0,"bid_ct":1,"ask_ct":0}],"symbol":"TSLA"}
{"ts_recv":"2024-11-01T08:00:04.470413664Z","hd":{"ts_event":"2024-11-01T08:00:04.470247417Z","rtype":10,"publisher_id":2,"instrument_id":16244},"action":"A","side":"A","depth":4,"price":"260.000000000","size":48,"flags":130,"ts_in_delta":166247,"sequence":295623,"levels":[{"bid_px":"249.820000000","ask_px":"250.680000000","bid_sz":100,"ask_sz":100,"bid_ct":1,"ask_ct":1},{"bid_px":"249.600000000","ask_px":"250.960000000","bid_sz":1000,"ask_sz":100,"bid_ct":1,"ask_ct":2},{"bid_px":"249.300000000","ask_px":"251.900000000","bid_sz":1000,"ask_sz":1000,"bid_ct":1,"ask_ct":1},{"bid_px":"247.150000000","ask_px":"253.650000000","bid_sz":400,"ask_sz":400,"bid_ct":1,"ask_ct":1},{"bid_px":"235.000000000","ask_px":"260.000000000","bid_sz":100,"ask_sz":48,"bid_ct":1,"ask_ct":1},{"bid_px":"220.000000000","ask_px":"265.000000000","bid_sz":1,"ask_sz":1,"bid_ct":1,"ask_ct":1},{"bid_px":"214.000000000","ask_px":"275.000000000","bid_sz":5,"ask_sz":4,"bid_ct":1,"ask_ct":1},{"bid_px":"213.000000000","ask_px":"960.000000000","bid_sz":1,"ask_sz":25,"bid_ct":1,"ask_ct":1},{"bid_px":"203.000000000","ask_px":null,"bid_sz":2,"ask_sz":0,"bid_ct":1,"ask_ct":0},{"bid_px":"170.000000000","ask_px":null,"bid_sz":3,"ask_sz":0,"bid_ct":1,"ask_ct":0}],"symbol":"TSLA"}
{"ts_recv":"2024-11-01T08:00:04.497617147Z","hd":{"ts_event":"2024-11-01T08:00:04.497451271Z","rtype":10,"publisher_id":2,"instrument_id":16244},"action":"C","side":"A","depth":1,"price":"250.960000000","size":50,"flags":130,"ts_in_delta":165876,"sequence":295704,"levels":[{"bid_px":"249.820000000","ask_px":"250.680000000","bid_sz":100,"ask_sz":100,"bid_ct":1,"ask_ct":1},{"bid_px":"249.600000000","ask_px":"250.960000000","bid_sz":1000,"ask_sz":50,"bid_ct":1,"ask_ct":1},{"bid_px":"249.300000000","ask_px":"251.900000000","bid_sz":1000,"ask_sz":1000,"bid_ct":1,"ask_ct":1},{"bid_px":"247.150000000","ask_px":"253.650000000","bid_sz":400,"ask_sz":400,"bid_ct":1,"ask_ct":1},{"bid_px":"235.000000000","ask_px":"260.000000000","bid_sz":100,"ask_sz":48,"bid_ct":1,"ask_ct":1},{"bid_px":"220.000000000","ask_px":"265.000000000","bid_sz":1,"ask_sz":1,"bid_ct":1,"ask_ct":1},{"bid_px":"214.000000000","ask_px":"275.000000000","bid_sz":5,"ask_sz":4,"bid_ct":1,"ask_ct":1},{"bid_px":"213.000000000","ask_px":"960.000000000","bid_sz":1,"ask_sz":25,"bid_ct":1,"ask_ct":1},{"bid_px":"203.000000000","ask_px":null,"bid_sz":2,"ask_sz":0,"bid_ct":1,"ask_ct":0},{"bid_px":"170.000000000","ask_px":null,"bid_sz":3,"ask_sz":0,"bid_ct":1,"ask_ct":0}],"symbol":"TSLA"}
{"ts_recv":"2024-11-01T08:00:04.497637192Z","hd":{"ts_event":"2024-11-01T08:00:04.497470818Z","rtype":10,"publisher_id":2,"instrument_id":16244},"action":"A","side":"A","depth":1,"price":"250.750000000","size":50,"flags":130,"ts_in_delta":166374,"sequence":295705,"levels":[{"bid_px":"249.820000000","ask_px":"250.680000000","bid_sz":100,"ask_sz":100,"bid_ct":1,"ask_ct":1},{"bid_px":"249.600000000","ask_px":"250.750000000","bid_sz":1000,"ask_sz":50,"bid_ct":1,"ask_ct":1},{"bid_px":"249.300000000","ask_px":"251.900000000","bid_sz":1000,"ask_sz":1000,"bid_ct":1,"ask_ct":1},{"bid_px":"247.150000000","ask_px":"253.650000000","bid_sz":400,"ask_sz":400,"bid_ct":1,"ask_ct":1},{"bid_px":"235.000000000","ask_px":"260.000000000","bid_sz":100,"ask_sz":48,"bid_ct":1,"ask_ct":1},{"bid_px":"220.000000000","ask_px":"265.000000000","bid_sz":1,"ask_sz":1,"bid_ct":1,"ask_ct":1},{"bid_px":"214.000000000","ask_px":"275.000000000","bid_sz":5,"ask_sz":4,"bid_ct":1,"ask_ct":1},{"bid_px":"213.000000000","ask_px":"960.000000000","bid_sz":1,"ask_sz":25,"bid_ct":1,"ask_ct":1},{"bid_px":"203.000000000","ask_px":null,"bid_sz":2,"ask_sz":0,"bid_ct":1,"ask_ct":0},{"bid_px":"170.000000000","ask_px":null,"bid_sz":3,"ask_sz":0,"bid_ct":1,"ask_ct":0}],"symbol":"TSLA"}
{"ts_recv":"2024-11-01T08:00:04.501706334Z","hd":{"ts_event":"2024-11-01T08:00:04.501540214Z","rtype":10,"publisher_id":2,"instrument_id":16244},"action":"C","side":"B","depth":0,"price":"249.820000000","size":50,"flags":130,"ts_in_delta":166120,"sequence":295725,"levels":[{"bid_px":"249.820000000","ask_px":"250.680000000","bid_sz":50,"ask_sz":100,"bid_ct":1,"ask_ct":1},{"bid_px":"249.600000000","ask_px":"250.750000000","bid_sz":1000,"ask_sz":50,"bid_ct":1,"ask_ct":1},{"bid_px":"249.300000000","ask_px":"251.900000000","bid_sz":1000,"ask_sz":1000,"bid_ct":1,"ask_ct":1},{"bid_px":"247.150000000","ask_px":"253.650000000","bid_sz":400,"ask_sz":400,"bid_ct":1,"ask_ct":1},{"bid_px":"235.000000000","ask_px":"260.000000000","bid_sz":100,"ask_sz":48,"bid_ct":1,"ask_ct":1},{"bid_px":"220.000000000","ask_px":"265.000000000","bid_sz":1,"ask_sz":1,"bid_ct":1,"ask_ct":1},{"bid_px":"214.000000000","ask_px":"275.000000000","bid_sz":5,"ask_sz":4,"bid_ct":1,"ask_ct":1},{"bid_px":"213.000000000","ask_px":"960.000000000","bid_sz":1,"ask_sz":25,"bid_ct":1,"ask_ct":1},{"bid_px":"203.000000000","ask_px":null,"bid_sz":2,"ask_sz":0,"bid_ct":1,"ask_ct":0},{"bid_px":"170.000000000","ask_px":null,"bid_sz":3,"ask_sz":0,"bid_ct":1,"ask_ct":0}],"symbol":"TSLA"}
{"ts_recv":"2024-11-01T08:00:04.514934233Z","hd":{"ts_event":"2024-11-01T08:00:04.514768318Z","rtype":10,"publisher_id":2,"instrument_id":16244},"action":"A","side":"B","depth":8,"price":"211.000000000","size":2,"flags":130,"ts_in_delta":165915,"sequence":295781,"levels":[{"bid_px":"249.820000000","ask_px":"250.680000000","bid_sz":50,"ask_sz":100,"bid_ct":1,"ask_ct":1},{"bid_px":"249.600000000","ask_px":"250.750000000","bid_sz":1000,"ask_sz":50,"bid_ct":1,"ask_ct":1},{"bid_px":"249.300000000","ask_px":"251.900000000","bid_sz":1000,"ask_sz":1000,"bid_ct":1,"ask_ct":1},{"bid_px":"247.150000000","ask_px":"253.650000000","bid_sz":400,"ask_sz":400,"bid_ct":1,"ask_ct":1},{"bid_px":"235.000000000","ask_px":"260.000000000","bid_sz":100,"ask_sz":48,"bid_ct":1,"ask_ct":1},{"bid_px":"220.000000000","ask_px":"265.000000000","bid_sz":1,"ask_sz":1,"bid_ct":1,"ask_ct":1},{"bid_px":"214.000000000","ask_px":"275.000000000","bid_sz":5,"ask_sz":4,"bid_ct":1,"ask_ct":1},{"bid_px":"213.000000000","ask_px":"960.000000000","bid_sz":1,"ask_sz":25,"bid_ct":1,"ask_ct":1},{"bid_px":"211.000000000","ask_px":null,"bid_sz":2,"ask_sz":0,"bid_ct":1,"ask_ct":0},{"bid_px":"203.000000000","ask_px":null,"bid_sz":2,"ask_sz":0,"bid_ct":1,"ask_ct":0}],"symbol":"TSLA"}
{"ts_recv":"2024-11-01T08:00:04.724128638Z","hd":{"ts_event":"2024-11-01T08:00:04.723962496Z","rtype":10,"publisher_id":2,"instrument_id":16244},"action":"A","side":"B","depth":7,"price":"213.650000000","size":3,"flags":130,"ts_in_delta":166142,"sequence":296410,"levels":[{"bid_px":"249.820000000","ask_px":"250.680000000","bid_sz":50,"ask_sz":100,"bid_ct":1,"ask_ct":1},{"bid_px":"249.600000000","ask_px":"250.750000000","bid_sz":1000,"ask_sz":50,"bid_ct":1,"ask_ct":1},{"bid_px":"249.300000000","ask_px":"251.900000000","bid_sz":1000,"ask_sz":1000,"bid_ct":1,"ask_ct":1},{"bid_px":"247.150000000","ask_px":"253.650000000","bid_sz":400,"ask_sz":400,"bid_ct":1,"ask_ct":1},{"bid_px":"235.000000000","ask_px":"260.000000000","bid_sz":100,"ask_sz":48,"bid_ct":1,"ask_ct":1},{"bid_px":"220.000000000","ask_px":"265.000000000","bid_sz":1,"ask_sz":1,"bid_ct":1,"ask_ct":1},{"bid_px":"214.000000000","ask_px":"275.000000000","bid_sz":5,"ask_sz":4,"bid_ct":1,"ask_ct":1},{"bid_px":"213.650000000","ask_px":"960.000000000","bid_sz":3,"ask_sz":25,"bid_ct":1,"ask_ct":1},{"bid_px":"213.000000000","ask_px":null,"bid_sz":1,"ask_sz":0,"bid_ct":1,"ask_ct":0},{"bid_px":"211.000000000","ask_px":null,"bid_sz":2,"ask_sz":0,"bid_ct":1,"ask_ct":0}],"symbol":"TSLA"}
{"ts_recv":"2024-11-01T08:00:04.836981943Z","hd":{"ts_event":"2024-11-01T08:00:04.836815700Z","rtype":10,"publisher_id":2,"instrument_id":16244},"action":"A","side":"A","depth":5,"price":"264.940000000","size":7,"flags":130,"ts_in_delta":166243,"sequence":296857,"levels":[{"bid_px":"249.820000000","ask_px":"250.680000000","bid_sz":50,"ask_sz":100,"bid_ct":1,"ask_ct":1},{"bid_px":"249.600000000","ask_px":"250.750000000","bid_sz":1000,"ask_sz":50,"bid_ct":1,"ask_ct":1},{"bid_px":"249.300000000","ask_px":"251.900000000","bid_sz":1000,"ask_sz":1000,"bid_ct":1,"ask_ct":1},{"bid_px":"247.150000000","ask_px":"253.650000000","bid_sz":400,"ask_sz":400,"bid_ct":1,"ask_ct":1},{"bid_px":"235.000000000","ask_px":"260.000000000","bid_sz":100,"ask_sz":48,"bid_ct":1,"ask_ct":1},{"bid_px":"220.000000000","ask_px":"264.940000000","bid_sz":1,"ask_sz":7,"bid_ct":1,"ask_ct":1},{"bid_px":"214.000000000","ask_px":"265.000000000","bid_sz":5,"ask_sz":1,"bid_ct":1,"ask_ct":1},{"bid_px":"213.650000000","ask_px":"275.000000000","bid_sz":3,"ask_sz":4,"bid_ct":1,"ask_ct":1},{"bid_px":"213.000000000","ask_px":"960.000000000","bid_sz":1,"ask_sz":25,"bid_ct":1,"ask_ct":1},{"bid_px":"211.000000000","ask_px":null,"bid_sz":2,"ask_sz":0,"bid_ct":1,"ask_ct":0}],"symbol":"TSLA"}
{"ts_recv":"2024-11-01T08:00:05.220725689Z","hd":{"ts_event":"2024-11-01T08:00:05.220559245Z","rtype":10,"publisher_id":2,"instrument_id":16244},"action":"A","side":"B","depth":5,"price":"220.000000000","size":5,"flags":130,"ts_in_delta":166444,"sequence":297655,"levels":[{"bid_px":"249.820000000","ask_px":"250.680000000","bid_sz":50,"ask_sz":100,"bid_ct":1,"ask_ct":1},{"bid_px":"249.600000000","ask_px":"250.750000000","bid_sz":1000,"ask_sz":50,"bid_ct":1,"ask_ct":1},{"bid_px":"249.300000000","ask_px":"251.900000000","bid_sz":1000,"ask_sz":1000,"bid_ct":1,"ask_ct":1},{"bid_px":"247.150000000","ask_px":"253.650000000","bid_sz":400,"ask_sz":400,"bid_ct":1,"ask_ct":1},{"bid_px":"235.000000000","ask_px":"260.000000000","bid_sz":100,"ask_sz":48,"bid_ct":1,"ask_ct":1},{"bid_px":"220.000000000","ask_px":"264.940000000","bid_sz":6,"ask_sz":7,"bid_ct":2,"ask_ct":1},{"bid_px":"214.000000000","ask_px":"265.000000000","bid_sz":5,"ask_sz":1,"bid_ct":1,"ask_ct":1},{"bid_px":"213.650000000","ask_px":"275.000000000","bid_sz":3,"ask_sz":4,"bid_ct":1,"ask_ct":1},{"bid_px":"213.000000000","ask_px":"960.000000000","bid_sz":1,"ask_sz":25,"bid_ct":1,"ask_ct":1},{"bid_px":"211.000000000","ask_px":null,"bid_sz":2,"ask_sz":0,"bid_ct":1,"ask_ct":0}],"symbol":"TSLA"}
{"ts_recv":"2024-11-01T08:00:05.292081938Z","hd":{"ts_event":"2024-11-01T08:00:05.291915839Z","rtype":10,"publisher_id":2,"instrument_id":16244},"action":"A","side":"B","depth":5,"price":"220.000000000","size":20,"flags":130,"ts_in_delta":166099,"sequence":297759,"levels":[{"bid_px":"249.820000000","ask_px":"250.680000000","bid_sz":50,"ask_sz":100,"bid_ct":1,"ask_ct":1},{"bid_px":"249.600000000","ask_px":"250.750000000","bid_sz":1000,"ask_sz":50,"bid_ct":1,"ask_ct":1},{"bid_px":"249.300000000","ask_px":"251.900000000","bid_sz":1000,"ask_sz":1000,"bid_ct":1,"ask_ct":1},{"bid_px":"247.150000000","ask_px":"253.650000000","bid_sz":400,"ask_sz":400,"bid_ct":1,"ask_ct":1},{"bid_px":"235.000000000","ask_px":"260.000000000","bid_sz":100,"ask_sz":48,"bid_ct":1,"ask_ct":1},{"bid_px":"220.000000000","ask_px":"264.940000000","bid_sz":26,"ask_sz":7,"bid_ct":3,"ask_ct":1},{"bid_px":"214.000000000","ask_px":"265.000000000","bid_sz":5,"ask_sz":1,"bid_ct":1,"ask_ct":1},{"bid_px":"213.650000000","ask_px":"275.000000000","bid_sz":3,"ask_sz":4,"bid_ct":1,"ask_ct":1},{"bid_px":"213.000000000","ask_px":"960.000000000","bid_sz":1,"ask_sz":25,"bid_ct":1,"ask_ct":1},{"bid_px":"211.000000000","ask_px":null,"bid_sz":2,"ask_sz":0,"bid_ct":1,"ask_ct":0}],"symbol":"TSLA"}
{"ts_recv":"2024-11-01T08:00:05.324142391Z","hd":{"ts_event":"2024-11-01T08:00:05.323976037Z","rtype":10,"publisher_id":2,"instrument_id":16244},"action":"A","side":"B","depth":5,"price":"230.000000000","size":12,"flags":130,"ts_in_delta":166354,"sequence":297807,"levels":[{"bid_px":"249.820000000","ask_px":"250.680000000","bid_sz":50,"ask_sz":100,"bid_ct":1,"ask_ct":1},{"bid_px":"249.600000000","ask_px":"250.750000000","bid_sz":1000,"ask_sz":50,"bid_ct":1,"ask_ct":1},{"bid_px":"249.300000000","ask_px":"251.900000000","bid_sz":1000,"ask_sz":1000,"bid_ct":1,"ask_ct":1},{"bid_px":"247.150000000","ask_px":"253.650000000","bid_sz":400,"ask_sz":400,"bid_ct":1,"ask_ct":1},{"bid_px":"235.000000000","ask_px":"260.000000000","bid_sz":100,"ask_sz":48,"bid_ct":1,"ask_ct":1},{"bid_px":"230.000000000","ask_px":"264.940000000","bid_sz":12,"ask_sz":7,"bid_ct":1,"ask_ct":1},{"bid_px":"220.000000000","ask_px":"265.000000000","bid_sz":26,"ask_sz":1,"bid_ct":3,"ask_ct":1},{"bid_px":"214.000000000","ask_px":"275.000000000","bid_sz":5,"ask_sz":4,"bid_ct":1,"ask_ct":1},{"bid_px":"213.650000000","ask_px":"960.000000000","bid_sz":3,"ask_sz":25,"bid_ct":1,"ask_ct":1},{"bid_px":"213.000000000","ask_px":null,"bid_sz":1,"ask_sz":0,"bid_ct":1,"ask_ct":0}],"symbol":"TSLA"}
{"ts_recv":"2024-11-01T08:00:05.354302759Z","hd":{"ts_event":"2024-11-01T08:00:05.354136410Z","rtype":10,"publisher_id":2,"instrument_id":16244},"action":"A","side":"B","depth":1,"price":"249.770000000","size":50,"flags":130,"ts_in_delta":166349,"sequence":297865,"levels":[{"bid_px":"249.820000000","ask_px":"250.680000000","bid_sz":50,"ask_sz":100,"bid_ct":1,"ask_ct":1},{"bid_px":"249.770000000","ask_px":"250.750000000","bid_sz":50,"ask_sz":50,"bid_ct":1,"ask_ct":1},{"bid_px":"249.600000000","ask_px":"251.900000000","bid_sz":1000,"ask_sz":1000,"bid_ct":1,"ask_ct":1},{"bid_px":"249.300000000","ask_px":"253.650000000","bid_sz":1000,"ask_sz":400,"bid_ct":1,"ask_ct":1},{"bid_px":"247.150000000","ask_px":"260.000000000","bid_sz":400,"ask_sz":48,"bid_ct":1,"ask_ct":1},{"bid_px":"235.000000000","ask_px":"264.940000000","bid_sz":100,"ask_sz":7,"bid_ct":1,"ask_ct":1},{"bid_px":"230.000000000","ask_px":"265.000000000","bid_sz":12,"ask_sz":1,"bid_ct":1,"ask_ct":1},{"bid_px":"220.000000000","ask_px":"275.000000000","bid_sz":26,"ask_sz":4,"bid_ct":3,"ask_ct":1},{"bid_px":"214.000000000","ask_px":"960.000000000","bid_sz":5,"ask_sz":25,"bid_ct":1,"ask_ct":1},{"bid_px":"213.650000000","ask_px":null,"bid_sz":3,"ask_sz":0,"bid_ct":1,"ask_ct":0}],"symbol":"TSLA"}
{"ts_recv":"2024-11-01T08:00:05.663155685Z","hd":{"ts_event":"2024-11-01T08:00:05.662989510Z","rtype":10,"publisher_id":2,"instrument_id":16244},"action":"A","side":"A","depth":8,"price":"300.000000000","size":7,"flags":130,"ts_in_delta":166175,"sequence":298692,"levels":[{"bid_px":"249.820000000","ask_px":"250.680000000","bid_sz":50,"ask_sz":100,"bid_ct":1,"ask_ct":1},{"bid_px":"249.770000000","ask_px":"250.750000000","bid_sz":50,"ask_sz":50,"bid_ct":1,"ask_ct":1},{"bid_px":"249.600000000","ask_px":"251.900000000","bid_sz":1000,"ask_sz":1000,"bid_ct":1,"ask_ct":1},{"bid_px":"249.300000000","ask_px":"253.650000000","bid_sz":1000,"ask_sz":400,"bid_ct":1,"ask_ct":1},{"bid_px":"247.150000000","ask_px":"260.000000000","bid_sz":400,"ask_sz":48,"bid_ct":1,"ask_ct":1},{"bid_px":"235.000000000","ask_px":"264.940000000","bid_sz":100,"ask_sz":7,"bid_ct":1,"ask_ct":1},{"bid_px":"230.000000000","ask_px":"265.000000000","bid_sz":12,"ask_sz":1,"bid_ct":1,"ask_ct":1},{"bid_px":"220.000000000","ask_px":"275.000000000","bid_sz":26,"ask_sz":4,"bid_ct":3,"ask_ct":1},{"bid_px":"214.000000000","ask_px":"300.000000000","bid_sz":5,"ask_sz":7,"bid_ct":1,"ask_ct":1},{"bid_px":"213.650000000","ask_px":"960.000000000","bid_sz":3,"ask_sz":25,"bid_ct":1,"ask_ct":1}],"symbol":"TSLA"}
{"ts_recv":"2024-11-01T08:00:05.777338971Z","hd":{"ts_event":"2024-11-01T08:00:05.777172581Z","rtype":10,"publisher_id":2,"instrument_id":16244},"action":"A","side":"B","depth":1,"price":"249.800000000","size":199,"flags":130,"ts_in_delta":166390,"sequence":298816,"levels":[{"bid_px":"249.820000000","ask_px":"250.680000000","bid_sz":50,"ask_sz":100,"bid_ct":1,"ask_ct":1},{"bid_px":"249.800000000","ask_px":"250.750000000","bid_sz":199,"ask_sz":50,"bid_ct":1,"ask_ct":1},{"bid_px":"249.770000000","ask_px":"251.900000000","bid_sz":50,"ask_sz":1000,"bid_ct":1,"ask_ct":1},{"bid_px":"249.600000000","ask_px":"253.650000000","bid_sz":1000,"ask_sz":400,"bid_ct":1,"ask_ct":1},{"bid_px":"249.300000000","ask_px":"260.000000000","bid_sz":1000,"ask_sz":48,"bid_ct":1,"ask_ct":1},{"bid_px":"247.150000000","ask_px":"264.940000000","bid_sz":400,"ask_sz":7,"bid_ct":1,"ask_ct":1},{"bid_px":"235.000000000","ask_px":"265.000000000","bid_sz":100,"ask_sz":1,"bid_ct":1,"ask_ct":1},{"bid_px":"230.000000000","ask_px":"275.000000000","bid_sz":12,"ask_sz":4,"bid_ct":1,"ask_ct":1},{"bid_px":"220.000000000","ask_px":"300.000000000","bid_sz":26,"ask_sz":7,"bid_ct":3,"ask_ct":1},{"bid_px":"214.000000000","ask_px":"960.000000000","bid_sz":5,"ask_sz":25,"bid_ct":1,"ask_ct":1}],"symbol":"TSLA"}
{"ts_recv":"2024-11-01T08:00:05.826373382Z","hd":{"ts_event":"2024-11-01T08:00:05.826207790Z","rtype":10,"publisher_id":2,"instrument_id":16244},"action":"C","side":"A","depth":2,"price":"251.900000000","size":1000,"flags":130,"ts_in_delta":165592,"sequence":298867,"levels":[{"bid_px":"249.820000000","ask_px":"250.680000000","bid_sz":50,"ask_sz":100,"bid_ct":1,"ask_ct":1},{"bid_px":"249.800000000","ask_px":"250.750000000","bid_sz":199,"ask_sz":50,"bid_ct":1,"ask_ct":1},{"bid_px":"249.770000000","ask_px":"253.650000000","bid_sz":50,"ask_sz":400,"bid_ct":1,"ask_ct":1},{"bid_px":"249.600000000","ask_px":"260.000000000","bid_sz":1000,"ask_sz":48,"bid_ct":1,"ask_ct":1},{"bid_px":"249.300000000","ask_px":"264.940000000","bid_sz":1000,"ask_sz":7,"bid_ct":1,"ask_ct":1},{"bid_px":"247.150000000","ask_px":"265.000000000","bid_sz":400,"ask_sz":1,"bid_ct":1,"ask_ct":1},{"bid_px":"235.000000000","ask_px":"275.000000000","bid_sz":100,"ask_sz":4,"bid_ct":1,"ask_ct":1},{"bid_px":"230.000000000","ask_px":"300.000000000","bid_sz":12,"ask_sz":7,"bid_ct":1,"ask_ct":1},{"bid_px":"220.000000000","ask_px":"960.000000000","bid_sz":26,"ask_sz":25,"bid_ct":3,"ask_ct":1},{"bid_px":"214.000000000","ask_px":null,"bid_sz":5,"ask_sz":0,"bid_ct":1,"ask_ct":0}],"symbol":"TSLA"}
{"ts_recv":"2024-11-01T08:00:05.842040154Z","hd":{"ts_event":"2024-11-01T08:00:05.841874018Z","rtype":10,"publisher_id":2,"instrument_id":16244},"action":"A","side":"A","depth":2,"price":"252.100000000","size":1000,"flags":130,"ts_in_delta":166136,"sequence":298880,"levels":[{"bid_px":"249.820000000","ask_px":"250.680000000","bid_sz":50,"ask_sz":100,"bid_ct":1,"ask_ct":1},{"bid_px":"249.800000000","ask_px":"250.750000000","bid_sz":199,"ask_sz":50,"bid_ct":1,"ask_ct":1},{"bid_px":"249.770000000","ask_px":"252.100000000","bid_sz":50,"ask_sz":1000,"bid_ct":1,"ask_ct":1},{"bid_px":"249.600000000","ask_px":"253.650000000","bid_sz":1000,"ask_sz":400,"bid_ct":1,"ask_ct":1},{"bid_px":"249.300000000","ask_px":"260.000000000","bid_sz":1000,"ask_sz":48,"bid_ct":1,"ask_ct":1},{"bid_px":"247.150000000","ask_px":"264.940000000","bid_sz":400,"ask_sz":7,"bid_ct":1,"ask_ct":1},{"bid_px":"235.000000000","ask_px":"265.000000000","bid_sz":100,"ask_sz":1,"bid_ct":1,"ask_ct":1},{"bid_px":"230.000000000","ask_px":"275.000000000","bid_sz":12,"ask_sz":4,"bid_ct":1,"ask_ct":1},{"bid_px":"220.000000000","ask_px":"300.000000000","bid_sz":26,"ask_sz":7,"bid_ct":3,"ask_ct":1},{"bid_px":"214.000000000","ask_px":"960.000000000","bid_sz":5,"ask_sz":25,"bid_ct":1,"ask_ct":1}],"symbol":"TSLA"}
{"ts_recv":"2024-11-01T08:00:05.961984958Z","hd":{"ts_event":"2024-11-01T08:00:05.961818767Z","rtype":10,"publisher_id":2,"instrument_id":16244},"action":"A","side":"B","depth":0,"price":"249.830000000","size":50,"flags":130,"ts_in_delta":166191,"sequence":299030,"levels":[{"bid_px":"249.830000000","ask_px":"250.680000000","bid_sz":50,"ask_sz":100,"bid_ct":1,"ask_ct":1},{"bid_px":"249.800000000","ask_px":"250.750000000","bid_sz":199,"ask_sz":50,"bid_ct":1,"ask_ct":1},{"bid_px":"249.770000000","ask_px":"252.100000000","bid_sz":50,"ask_sz":1000,"bid_ct":1,"ask_ct":1},{"bid_px":"249.600000000","ask_px":"253.650000000","bid_sz":1000,"ask_sz":400,"bid_ct":1,"ask_ct":1},{"bid_px":"249.300000000","ask_px":"260.000000000","bid_sz":1000,"ask_sz":48,"bid_ct":1,"ask_ct":1},{"bid_px":"247.150000000","ask_px":"264.940000000","bid_sz":400,"ask_sz":7,"bid_ct":1,"ask_ct":1},{"bid_px":"235.000000000","ask_px":"265.000000000","bid_sz":100,"ask_sz":1,"bid_ct":1,"ask_ct":1},{"bid_px":"230.000000000","ask_px":"275.000000000","bid_sz":12,"ask_sz":4,"bid_ct":1,"ask_ct":1},{"bid_px":"220.000000000","ask_px":"300.000000000","bid_sz":26,"ask_sz":7,"bid_ct":3,"ask_ct":1},{"bid_px":"214.000000000","ask_px":"960.000000000","bid_sz":5,"ask_sz":25,"bid_ct":1,"ask_ct":1}],"symbol":"TSLA"}
{"ts_recv":"2024-11-01T08:00:05.992007973Z","hd":{"ts_event":"2024-11-01T08:00:05.991841871Z","rtype":10,"publisher_id":2,"instrument_id":16244},"action":"A","side":"B","depth":8,"price":"220.000000000","size":34,"flags":130,"ts_in_delta":166102,"sequence":299054,"levels":[{"bid_px":"249.830000000","ask_px":"250.680000000","bid_sz":50,"ask_sz":100,"bid_ct":1,"ask_ct":1},{"bid_px":"249.800000000","ask_px":"250.750000000","bid_sz":199,"ask_sz":50,"bid_ct":1,"ask_ct":1},{"bid_px":"249.770000000","ask_px":"252.100000000","bid_sz":50,"ask_sz":1000,"bid_ct":1,"ask_ct":1},{"bid_px":"249.600000000","ask_px":"253.650000000","bid_sz":1000,"ask_sz":400,"bid_ct":1,"ask_ct":1},{"bid_px":"249.300000000","ask_px":"260.000000000","bid_sz":1000,"ask_sz":48,"bid_ct":1,"ask_ct":1},{"bid_px":"247.150000000","ask_px":"264.940000000","bid_sz":400,"ask_sz":7,"bid_ct":1,"ask_ct":1},{"bid_px":"235.000000000","ask_px":"265.000000000","bid_sz":100,"ask_sz":1,"bid_ct":1,"ask_ct":1},{"bid_px":"230.000000000","ask_px":"275.000000000","bid_sz":12,"ask_sz":4,"bid_ct":1,"ask_ct":1},{"bid_px":"220.000000000","ask_px":"300.000000000","bid_sz":60,"ask_sz":7,"bid_ct":4,"ask_ct":1},{"bid_px":"214.000000000","ask_px":"960.000000000","bid_sz":5,"ask_sz":25,"bid_ct":1,"ask_ct":1}],"symbol":"TSLA"}
{"ts_recv":"2024-11-01T08:00:06.008333344Z","hd":{"ts_event":"2024-11-01T08:00:06.008167175Z","rtype":10,"publisher_id":2,"instrument_id":16244},"action":"A","side":"B","depth":8,"price":"225.000000000","size":8,"flags":130,"ts_in_delta":166169,"sequence":299075,"levels":[{"bid_px":"249.830000000","ask_px":"250.680000000","bid_sz":50,"ask_sz":100,"bid_ct":1,"ask_ct":1},{"bid_px":"249.800000000","ask_px":"250.750000000","bid_sz":199,"ask_sz":50,"bid_ct":1,"ask_ct":1},{"bid_px":"249.770000000","ask_px":"252.100000000","bid_sz":50,"ask_sz":1000,"bid_ct":1,"ask_ct":1},{"bid_px":"249.600000000","ask_px":"253.650000000","bid_sz":1000,"ask_sz":400,"bid_ct":1,"ask_ct":1},{"bid_px":"249.300000000","ask_px":"260.000000000","bid_sz":1000,"ask_sz":48,"bid_ct":1,"ask_ct":1},{"bid_px":"247.150000000","ask_px":"264.940000000","bid_sz":400,"ask_sz":7,"bid_ct":1,"ask_ct":1},{"bid_px":"235.000000000","ask_px":"265.000000000","bid_sz":100,"ask_sz":1,"bid_ct":1,"ask_ct":1},{"bid_px":"230.000000000","ask_px":"275.000000000","bid_sz":12,"ask_sz":4,"bid_ct":1,"ask_ct":1},{"bid_px":"225.000000000","ask_px":"300.000000000","bid_sz":8,"ask_sz":7,"bid_ct":1,"ask_ct":1},{"bid_px":"220.000000000","ask_px":"960.000000000","bid_sz":60,"ask_sz":25,"bid_ct":4,"ask_ct":1}],"symbol":"TSLA"}
{"ts_recv":"2024-11-01T08:00:06.031861392Z","hd":{"ts_event":"2024-11-01T08:00:06.031695298Z","rtype":10,"publisher_id":2,"instrument_id":16244},"action":"A","side":"B","depth":6,"price":"235.000000000","size":30,"flags":130,"ts_in_delta":166094,"sequence":299119,"levels":[{"bid_px":"249.830000000","ask_px":"250.680000000","bid_sz":50,"ask_sz":100,"bid_ct":1,"ask_ct":1},{"bid_px":"249.800000000","ask_px":"250.750000000","bid_sz":199,"ask_sz":50,"bid_ct":1,"ask_ct":1},{"bid_px":"249.770000000","ask_px":"252.100000000","bid_sz":50,"ask_sz":1000,"bid_ct":1,"ask_ct":1},{"bid_px":"249.600000000","ask_px":"253.650000000","bid_sz":1000,"ask_sz":400,"bid_ct":1,"ask_ct":1},{"bid_px":"249.300000000","ask_px":"260.000000000","bid_sz":1000,"ask_sz":48,"bid_ct":1,"ask_ct":1},{"bid_px":"247.150000000","ask_px":"264.940000000","bid_sz":400,"ask_sz":7,"bid_ct":1,"ask_ct":1},{"bid_px":"235.000000000","ask_px":"265.000000000","bid_sz":130,"ask_sz":1,"bid_ct":2,"ask_ct":1},{"bid_px":"230.000000000","ask_px":"275.000000000","bid_sz":12,"ask_sz":4,"bid_ct":1,"ask_ct":1},{"bid_px":"225.000000000","ask_px":"300.000000000","bid_sz":8,"ask_sz":7,"bid_ct":1,"ask_ct":1},{"bid_px":"220.000000000","ask_px":"960.000000000","bid_sz":60,"ask_sz":25,"bid_ct":4,"ask_ct":1}],"symbol":"TSLA"}
{"ts_recv":"2024-11-01T08:00:06.052861614Z","hd":{"ts_event":"2024-11-01T08:00:06.052695502Z","rtype":10,"publisher_id":2,"instrument_id":16244},"action":"A","side":"A","depth":7,"price":"267.800000000","size":30,"flags":130,"ts_in_delta":166112,"sequence":299209,"levels":[{"bid_px":"249.830000000","ask_px":"250.680000000","bid_sz":50,"ask_sz":100,"bid_ct":1,"ask_ct":1},{"bid_px":"249.800000000","ask_px":"250.750000000","bid_sz":199,"ask_sz":50,"bid_ct":1,"ask_ct":1},{"bid_px":"249.770000000","ask_px":"252.100000000","bid_sz":50,"ask_sz":1000,"bid_ct":1,"ask_ct":1},{"bid_px":"249.600000000","ask_px":"253.650000000","bid_sz":1000,"ask_sz":400,"bid_ct":1,"ask_ct":1},{"bid_px":"249.300000000","ask_px":"260.000000000","bid_sz":1000,"ask_sz":48,"bid_ct":1,"ask_ct":1},{"bid_px":"247.150000000","ask_px":"264.940000000","bid_sz":400,"ask_sz":7,"bid_ct":1,"ask_ct":1},{"bid_px":"235.000000000","ask_px":"265.000000000","bid_sz":130,"ask_sz":1,"bid_ct":2,"ask_ct":1},{"bid_px":"230.000000000","ask_px":"267.800000000","bid_sz":12,"ask_sz":30,"bid_ct":1,"ask_ct":1},{"bid_px":"225.000000000","ask_px":"275.000000000","bid_sz":8,"ask_sz":4,"bid_ct":1,"ask_ct":1},{"bid_px":"220.000000000","ask_px":"300.000000000","bid_sz":60,"ask_sz":7,"bid_ct":4,"ask_ct":1}],"symbol":"TSLA"}
{"ts_recv":"2024-11-01T08:00:06.062906169Z","hd":{"ts_event":"2024-11-01T08:00:06.062739623Z","rtype":10,"publisher_id":2,"instrument_id":16244},"action":"A","side":"A","depth":8,"price":"275.000000000","size":12,"flags":130,"ts_in_delta":166546,"sequence":299266,"levels":[{"bid_px":"249.830000000","ask_px":"250.680000000","bid_sz":50,"ask_sz":100,"bid_ct":1,"ask_ct":1},{"bid_px":"249.800000000","ask_px":"250.750000000","bid_sz":199,"ask_sz":50,"bid_ct":1,"ask_ct":1},{"bid_px":"249.770000000","ask_px":"252.100000000","bid_sz":50,"ask_sz":1000,"bid_ct":1,"ask_ct":1},{"bid_px":"249.600000000","ask_px":"253.650000000","bid_sz":1000,"ask_sz":400,"bid_ct":1,"ask_ct":1},{"bid_px":"249.300000000","ask_px":"260.000000000","bid_sz":1000,"ask_sz":48,"bid_ct":1,"ask_ct":1},{"bid_px":"247.150000000","ask_px":"264.940000000","bid_sz":400,"ask_sz":7,"bid_ct":1,"ask_ct":1},{"bid_px":"235.000000000","ask_px":"265.000000000","bid_sz":130,"ask_sz":1,"bid_ct":2,"ask_ct":1},{"bid_px":"230.000000000","ask_px":"267.800000000","bid_sz":12,"ask_sz":30,"bid_ct":1,"ask_ct":1},{"bid_px":"225.000000000","ask_px":"275.000000000","bid_sz":8,"ask_sz":16,"bid_ct":1,"ask_ct":2},{"bid_px":"220.000000000","ask_px":"300.000000000","bid_sz":60,"ask_sz":7,"bid_ct":4,"ask_ct":1}],"symbol":"TSLA"}
{"ts_recv":"2024-11-01T08:00:06.066367690Z","hd":{"ts_event":"2024-11-01T08:00:06.066201594Z","rtype":10,"publisher_id":2,"instrument_id":16244},"action":"A","side":"A","depth":9,"price":"300.000000000","size":1,"flags":130,"ts_in_delta":166096,"sequence":299273,"levels":[{"bid_px":"249.830000000","ask_px":"250.680000000","bid_sz":50,"ask_sz":100,"bid_ct":1,"ask_ct":1},{"bid_px":"249.800000000","ask_px":"250.750000000","bid_sz":199,"ask_sz":50,"bid_ct":1,"ask_ct":1},{"bid_px":"249.770000000","ask_px":"252.100000000","bid_sz":50,"ask_sz":1000,"bid_ct":1,"ask_ct":1},{"bid_px":"249.600000000","ask_px":"253.650000000","bid_sz":1000,"ask_sz":400,"bid_ct":1,"ask_ct":1},{"bid_px":"249.300000000","ask_px":"260.000000000","bid_sz":1000,"ask_sz":48,"bid_ct":1,"ask_ct":1},{"bid_px":"247.150000000","ask_px":"264.940000000","bid_sz":400,"ask_sz":7,"bid_ct":1,"ask_ct":1},{"bid_px":"235.000000000","ask_px":"265.000000000","bid_sz":130,"ask_sz":1,"bid_ct":2,"ask_ct":1},{"bid_px":"230.000000000","ask_px":"267.800000000","bid_sz":12,"ask_sz":30,"bid_ct":1,"ask_ct":1},{"bid_px":"225.000000000","ask_px":"275.000000000","bid_sz":8,"ask_sz":16,"bid_ct":1,"ask_ct":2},{"bid_px":"220.000000000","ask_px":"300.000000000","bid_sz":60,"ask_sz":8,"bid_ct":4,"ask_ct":2}],"symbol":"TSLA"}
{"ts_recv":"2024-11-01T08:00:06.093022196Z","hd":{"ts_event":"2024-11-01T08:00:06.092855744Z","rtype":10,"publisher_id":2,"instrument_id":16244},"action":"A","side":"A","depth":8,"price":"273.000000000","size":1,"flags":130,"ts_in_delta":166452,"sequence":299399,"levels":[{"bid_px":"249.830000000","ask_px":"250.680000000","bid_sz":50,"ask_sz":100,"bid_ct":1,"ask_ct":1},{"bid_px":"249.800000000","ask_px":"250.750000000","bid_sz":199,"ask_sz":50,"bid_ct":1,"ask_ct":1},{"bid_px":"249.770000000","ask_px":"252.100000000","bid_sz":50,"ask_sz":1000,"bid_ct":1,"ask_ct":1},{"bid_px":"249.600000000","ask_px":"253.650000000","bid_sz":1000,"ask_sz":400,"bid_ct":1,"ask_ct":1},{"bid_px":"249.300000000","ask_px":"260.000000000","bid_sz":1000,"ask_sz":48,"bid_ct":1,"ask_ct":1},{"bid_px":"247.150000000","ask_px":"264.940000000","bid_sz":400,"ask_sz":7,"bid_ct":1,"ask_ct":1},{"bid_px":"235.000000000","ask_px":"265.000000000","bid_sz":130,"ask_sz":1,"bid_ct":2,"ask_ct":1},{"bid_px":"230.000000000","ask_px":"267.800000000","bid_sz":12,"ask_sz":30,"bid_ct":1,"ask_ct":1},{"bid_px":"225.000000000","ask_px":"273.000000000","bid_sz":8,"ask_sz":1,"bid_ct":1,"ask_ct":1},{"bid_px":"220.000000000","ask_px":"275.000000000","bid_sz":60,"ask_sz":16,"bid_ct":4,"ask_ct":2}],"symbol":"TSLA"}
{"ts_recv":"2024-11-01T08:00:06.174485927Z","hd":{"ts_event":"2024-11-01T08:00:06.174319610Z","rtype":10,"publisher_id":2,"instrument_id":16244},"action":"A","side":"B","depth":0,"price":"249.830000000","size":50,"flags":130,"ts_in_delta":166317,"sequence":299662,"levels":[{"bid_px":"249.830000000","ask_px":"250.680000000","bid_sz":100,"ask_sz":100,"bid_ct":2,"ask_ct":1},{"bid_px":"249.800000000","ask_px":"250.750000000","bid_sz":199,"ask_sz":50,"bid_ct":1,"ask_ct":1},{"bid_px":"249.770000000","ask_px":"252.100000000","bid_sz":50,"ask_sz":1000,"bid_ct":1,"ask_ct":1},{"bid_px":"249.600000000","ask_px":"253.650000000","bid_sz":1000,"ask_sz":400,"bid_ct":1,"ask_ct":1},{"bid_px":"249.300000000","ask_px":"260.000000000","bid_sz":1000,"ask_sz":48,"bid_ct":1,"ask_ct":1},{"bid_px":"247.150000000","ask_px":"264.940000000","bid_sz":400,"ask_sz":7,"bid_ct":1,"ask_ct":1},{"bid_px":"235.000000000","ask_px":"265.000000000","bid_sz":130,"ask_sz":1,"bid_ct":2,"ask_ct":1},{"bid_px":"230.000000000","ask_px":"267.800000000","bid_sz":12,"ask_sz":30,"bid_ct":1,"ask_ct":1},{"bid_px":"225.000000000","ask_px":"273.000000000","bid_sz":8,"ask_sz":1,"bid_ct":1,"ask_ct":1},{"bid_px":"220.000000000","ask_px":"275.000000000","bid_sz":60,"ask_sz":16,"bid_ct":4,"ask_ct":2}],"symbol":"TSLA"}
{"ts_recv":"2024-11-01T08:00:06.178289374Z","hd":{"ts_event":"2024-11-01T08:00:06.178123098Z","rtype":10,"publisher_id":2,"instrument_id":16244},"action":"A","side":"B","depth":4,"price":"249.400000000","size":1000,"flags":130,"ts_in_delta":166276,"sequence":299670,"levels":[{"bid_px":"249.830000000","ask_px":"250.680000000","bid_sz":100,"ask_sz":100,"bid_ct":2,"ask_ct":1},{"bid_px":"249.800000000","ask_px":"250.750000000","bid_sz":199,"ask_sz":50,"bid_ct":1,"ask_ct":1},{"bid_px":"249.770000000","ask_px":"252.100000000","bid_sz":50,"ask_sz":1000,"bid_ct":1,"ask_ct":1},{"bid_px":"249.600000000","ask_px":"253.650000000","bid_sz":1000,"ask_sz":400,"bid_ct":1,"ask_ct":1},{"bid_px":"249.400000000","ask_px":"260.000000000","bid_sz":1000,"ask_sz":48,"bid_ct":1,"ask_ct":1},{"bid_px":"249.300000000","ask_px":"264.940000000","bid_sz":1000,"ask_sz":7,"bid_ct":1,"ask_ct":1},{"bid_px":"247.150000000","ask_px":"265.000000000","bid_sz":400,"ask_sz":1,"bid_ct":1,"ask_ct":1},{"bid_px":"235.000000000","ask_px":"267.800000000","bid_sz":130,"ask_sz":30,"bid_ct":2,"ask_ct":1},{"bid_px":"230.000000000","ask_px":"273.000000000","bid_sz":12,"ask_sz":1,"bid_ct":1,"ask_ct":1},{"bid_px":"225.000000000","ask_px":"275.000000000","bid_sz":8,"ask_sz":16,"bid_ct":1,"ask_ct":2}],"symbol":"TSLA"}
{"ts_recv":"2024-11-01T08:00:06.178316655Z","hd":{"ts_event":"2024-11-01T08:00:06.178150776Z","rtype":10,"publisher_id":2,"instrument_id":16244},"action":"C","side":"B","depth":5,"price":"249.300000000","size":1000,"flags":130,"ts_in_delta":165879,"sequence":299671,"levels":[{"bid_px":"249.830000000","ask_px":"250.680000000","bid_sz":100,"ask_sz":100,"bid_ct":2,"ask_ct":1},{"bid_px":"249.800000000","ask_px":"250.750000000","bid_sz":199,"ask_sz":50,"bid_ct":1,"ask_ct":1},{"bid_px":"249.770000000","ask_px":"252.100000000","bid_sz":50,"ask_sz":1000,"bid_ct":1,"ask_ct":1},{"bid_px":"249.600000000","ask_px":"253.650000000","bid_sz":1000,"ask_sz":400,"bid_ct":1,"ask_ct":1},{"bid_px":"249.400000000","ask_px":"260.000000000","bid_sz":1000,"ask_sz":48,"bid_ct":1,"ask_ct":1},{"bid_px":"247.150000000","ask_px":"264.940000000","bid_sz":400,"ask_sz":7,"bid_ct":1,"ask_ct":1},{"bid_px":"235.000000000","ask_px":"265.000000000","bid_sz":130,"ask_sz":1,"bid_ct":2,"ask_ct":1},{"bid_px":"230.000000000","ask_px":"267.800000000","bid_sz":12,"ask_sz":30,"bid_ct":1,"ask_ct":1},{"bid_px":"225.000000000","ask_px":"273.000000000","bid_sz":8,"ask_sz":1,"bid_ct":1,"ask_ct":1},{"bid_px":"220.000000000","ask_px":"275.000000000","bid_sz":60,"ask_sz":16,"bid_ct":4,"ask_ct":2}],"symbol":"TSLA"}
{"ts_recv":"2024-11-01T08:00:06.187941659Z","hd":{"ts_event":"2024-11-01T08:00:06.187775355Z","rtype":10,"publisher_id":2,"instrument_id":16244},"action":"A","side":"B","depth":6,"price":"245.000000000","size":50,"flags":130,"ts_in_delta":166304,"sequence":299694,"levels":[{"bid_px":"249.830000000","ask_px":"250.680000000","bid_sz":100,"ask_sz":100,"bid_ct":2,"ask_ct":1},{"bid_px":"249.800000000","ask_px":"250.750000000","bid_sz":199,"ask_sz":50,"bid_ct":1,"ask_ct":1},{"bid_px":"249.770000000","ask_px":"252.100000000","bid_sz":50,"ask_sz":1000,"bid_ct":1,"ask_ct":1},{"bid_px":"249.600000000","ask_px":"253.650000000","bid_sz":1000,"ask_sz":400,"bid_ct":1,"ask_ct":1},{"bid_px":"249.400000000","ask_px":"260.000000000","bid_sz":1000,"ask_sz":48,"bid_ct":1,"ask_ct":1},{"bid_px":"247.150000000","ask_px":"264.940000000","bid_sz":400,"ask_sz":7,"bid_ct":1,"ask_ct":1},{"bid_px":"245.000000000","ask_px":"265.000000000","bid_sz":50,"ask_sz":1,"bid_ct":1,"ask_ct":1},{"bid_px":"235.000000000","ask_px":"267.800000000","bid_sz":130,"ask_sz":30,"bid_ct":2,"ask_ct":1},{"bid_px":"230.000000000","ask_px":"273.000000000","bid_sz":12,"ask_sz":1,"bid_ct":1,"ask_ct":1},{"bid_px":"225.000000000","ask_px":"275.000000000","bid_sz":8,"ask_sz":16,"bid_ct":1,"ask_ct":2}],"symbol":"TSLA"}
{"ts_recv":"2024-11-01T08:00:06.188451206Z","hd":{"ts_event":"2024-11-01T08:00:06.188285188Z","rtype":10,"publisher_id":2,"instrument_id":16244},"action":"A","side":"B","depth":5,"price":"247.700000000","size":1000,"flags":130,"ts_in_delta":166018,"sequence":299697,"levels":[{"bid_px":"249.830000000","ask_px":"250.680000000","bid_sz":100,"ask_sz":100,"bid_ct":2,"ask_ct":1},{"bid_px":"249.800000000","ask_px":"250.750000000","bid_sz":199,"ask_sz":50,"bid_ct":1,"ask_ct":1},{"bid_px":"249.770000000","ask_px":"252.100000000","bid_sz":50,"ask_sz":1000,"bid_ct":1,"ask_ct":1},{"bid_px":"249.600000000","ask_px":"253.650000000","bid_sz":1000,"ask_sz":400,"bid_ct":1,"ask_ct":1},{"bid_px":"249.400000000","ask_px":"260.000000000","bid_sz":1000,"ask_sz":48,"bid_ct":1,"ask_ct":1},{"bid_px":"247.700000000","ask_px":"264.940000000","bid_sz":1000,"ask_sz":7,"bid_ct":1,"ask_ct":1},{"bid_px":"247.150000000","ask_px":"265.000000000","bid_sz":400,"ask_sz":1,"bid_ct":1,"ask_ct":1},{"bid_px":"245.000000000","ask_px":"267.800000000","bid_sz":50,"ask_sz":30,"bid_ct":1,"ask_ct":1},{"bid_px":"235.000000000","ask_px":"273.000000000","bid_sz":130,"ask_sz":1,"bid_ct":2,"ask_ct":1},{"bid_px":"230.000000000","ask_px":"275.000000000","bid_sz":12,"ask_sz":16,"bid_ct":1,"ask_ct":2}],"symbol":"TSLA"}
{"ts_recv":"2024-11-01T08:00:06.200506093Z","hd":{"ts_event":"2024-11-01T08:00:06.200339057Z","rtype":10,"publisher_id":2,"instrument_id":16244},"action":"A","side":"A","depth":9,"price":"274.000000000","size":86,"flags":130,"ts_in_delta":167036,"sequence":299723,"levels":[{"bid_px":"249.830000000","ask_px":"250.680000000","bid_sz":100,"ask_sz":100,"bid_ct":2,"ask_ct":1},{"bid_px":"249.800000000","ask_px":"250.750000000","bid_sz":199,"ask_sz":50,"bid_ct":1,"ask_ct":1},{"bid_px":"249.770000000","ask_px":"252.100000000","bid_sz":50,"ask_sz":1000,"bid_ct":1,"ask_ct":1},{"bid_px":"249.600000000","ask_px":"253.650000000","bid_sz":1000,"ask_sz":400,"bid_ct":1,"ask_ct":1},{"bid_px":"249.400000000","ask_px":"260.000000000","bid_sz":1000,"ask_sz":48,"bid_ct":1,"ask_ct":1},{"bid_px":"247.700000000","ask_px":"264.940000000","bid_sz":1000,"ask_sz":7,"bid_ct":1,"ask_ct":1},{"bid_px":"247.150000000","ask_px":"265.000000000","bid_sz":400,"ask_sz":1,"bid_ct":1,"ask_ct":1},{"bid_px":"245.000000000","ask_px":"267.800000000","bid_sz":50,"ask_sz":30,"bid_ct":1,"ask_ct":1},{"bid_px":"235.000000000","ask_px":"273.000000000","bid_sz":130,"ask_sz":1,"bid_ct":2,"ask_ct":1},{"bid_px":"230.000000000","ask_px":"274.000000000","bid_sz":12,"ask_sz":86,"bid_ct":1,"ask_ct":1}],"symbol":"TSLA"}
{"ts_recv":"2024-11-01T08:00:06.225043027Z","hd":{"ts_event":"2024-11-01T08:00:06.224877387Z","rtype":10,"publisher_id":2,"instrument_id":16244},"action":"C","side":"B","depth":0,"price":"249.830000000","size":50,"flags":130,"ts_in_delta":165640,"sequence":299780,"levels":[{"bid_px":"249.830000000","ask_px":"250.680000000","bid_sz":50,"ask_sz":100,"bid_ct":1,"ask_ct":1},{"bid_px":"249.800000000","ask_px":"250.750000000","bid_sz":199,"ask_sz":50,"bid_ct":1,"ask_ct":1},{"bid_px":"249.770000000","ask_px":"252.100000000","bid_sz":50,"ask_sz":1000,"bid_ct":1,"ask_ct":1},{"bid_px":"249.600000000","ask_px":"253.650000000","bid_sz":1000,"ask_sz":400,"bid_ct":1,"ask_ct":1},{"bid_px":"249.400000000","ask_px":"260.000000000","bid_sz":1000,"ask_sz":48,"bid_ct":1,"ask_ct":1},{"bid_px":"247.700000000","ask_px":"264.940000000","bid_sz":1000,"ask_sz":7,"bid_ct":1,"ask_ct":1},{"bid_px":"247.150000000","ask_px":"265.000000000","bid_sz":400,"ask_sz":1,"bid_ct":1,"ask_ct":1},{"bid_px":"245.000000000","ask_px":"267.800000000","bid_sz":50,"ask_sz":30,"bid_ct":1,"ask_ct":1},{"bid_px":"235.000000000","ask_px":"273.000000000","bid_sz":130,"ask_sz":1,"bid_ct":2,"ask_ct":1},{"bid_px":"230.000000000","ask_px":"274.000000000","bid_sz":12,"ask_sz":86,"bid_ct":1,"ask_ct":1}],"symbol":"TSLA"}
{"ts_recv":"2024-11-01T08:00:06.225057101Z","hd":{"ts_event":"2024-11-01T08:00:06.224890172Z","rtype":10,"publisher_id":2,"instrument_id":16244},"action":"A","side":"B","depth":0,"price":"249.860000000","size":50,"flags":130,"ts_in_delta":166929,"sequence":299781,"levels":[{"bid_px":"249.860000000","ask_px":"250.680000000","bid_sz":50,"ask_sz":100,"bid_ct":1,"ask_ct":1},{"bid_px":"249.800000000","ask_px":"250.750000000","bid_sz":199,"ask_sz":50,"bid_ct":1,"ask_ct":1},{"bid_px":"249.770000000","ask_px":"252.100000000","bid_sz":50,"ask_sz":1000,"bid_ct":1,"ask_ct":1},{"bid_px":"249.600000000","ask_px":"253.650000000","bid_sz":1000,"ask_sz":400,"bid_ct":1,"ask_ct":1},{"bid_px":"249.400000000","ask_px":"260.000000000","bid_sz":1000,"ask_sz":48,"bid_ct":1,"ask_ct":1},{"bid_px":"247.700000000","ask_px":"264.940000000","bid_sz":1000,"ask_sz":7,"bid_ct":1,"ask_ct":1},{"bid_px":"247.150000000","ask_px":"265.000000000","bid_sz":400,"ask_sz":1,"bid_ct":1,"ask_ct":1},{"bid_px":"245.000000000","ask_px":"267.800000000","bid_sz":50,"ask_sz":30,"bid_ct":1,"ask_ct":1},{"bid_px":"235.000000000","ask_px":"273.000000000","bid_sz":130,"ask_sz":1,"bid_ct":2,"ask_ct":1},{"bid_px":"230.000000000","ask_px":"274.000000000","bid_sz":12,"ask_sz":86,"bid_ct":1,"ask_ct":1}],"symbol":"TSLA"}
{"ts_recv":"2024-11-01T08:00:06.226385793Z","hd":{"ts_event":"2024-11-01T08:00:06.226219652Z","rtype":10,"publisher_id":2,"instrument_id":16244},"action":"A","side":"B","depth":4,"price":"249.500000000","size":1000,"flags":130,"ts_in_delta":166141,"sequence":299788,"levels":[{"bid_px":"249.860000000","ask_px":"250.680000000","bid_sz":50,"ask_sz":100,"bid_ct":1,"ask_ct":1},{"bid_px":"249.800000000","ask_px":"250.750000000","bid_sz":199,"ask_sz":50,"bid_ct":1,"ask_ct":1},{"bid_px":"249.770000000","ask_px":"252.100000000","bid_sz":50,"ask_sz":1000,"bid_ct":1,"ask_ct":1},{"bid_px":"249.600000000","ask_px":"253.650000000","bid_sz":1000,"ask_sz":400,"bid_ct":1,"ask_ct":1},{"bid_px":"249.500000000","ask_px":"260.000000000","bid_sz":1000,"ask_sz":48,"bid_ct":1,"ask_ct":1},{"bid_px":"249.400000000","ask_px":"264.940000000","bid_sz":1000,"ask_sz":7,"bid_ct":1,"ask_ct":1},{"bid_px":"247.700000000","ask_px":"265.000000000","bid_sz":1000,"ask_sz":1,"bid_ct":1,"ask_ct":1},{"bid_px":"247.150000000","ask_px":"267.800000000","bid_sz":400,"ask_sz":30,"bid_ct":1,"ask_ct":1},{"bid_px":"245.000000000","ask_px":"273.000000000","bid_sz":50,"ask_sz":1,"bid_ct":1,"ask_ct":1},{"bid_px":"235.000000000","ask_px":"274.000000000","bid_sz":130,"ask_sz":86,"bid_ct":2,"ask_ct":1}],"symbol":"TSLA"}
{"ts_recv":"2024-11-01T08:00:06.284148577Z","hd":{"ts_event":"2024-11-01T08:00:06.283982285Z","rtype":10,"publisher_id":2,"instrument_id":16244},"action":"A","side":"B","depth":0,"price":"249.880000000","size":50,"flags":130,"ts_in_delta":166292,"sequence":299988,"levels":[{"bid_px":"249.880000000","ask_px":"250.680000000","bid_sz":50,"ask_sz":100,"bid_ct":1,"ask_ct":1},{"bid_px":"249.800000000","ask_px":"250.750000000","bid_sz":199,"ask_sz":50,"bid_ct":1,"ask_ct":1},{"bid_px":"249.770000000","ask_px":"252.100000000","bid_sz":50,"ask_sz":1000,"bid_ct":1,"ask_ct":1},{"bid_px":"249.600000000","ask_px":"253.650000000","bid_sz":1000,"ask_sz":400,"bid_ct":1,"ask_ct":1},{"bid_px":"249.500000000","ask_px":"260.000000000","bid_sz":1000,"ask_sz":48,"bid_ct":1,"ask_ct":1},{"bid_px":"249.400000000","ask_px":"264.940000000","bid_sz":1000,"ask_sz":7,"bid_ct":1,"ask_ct":1},{"bid_px":"247.700000000","ask_px":"265.000000000","bid_sz":1000,"ask_sz":1,"bid_ct":1,"ask_ct":1},{"bid_px":"247.150000000","ask_px":"267.800000000","bid_sz":400,"ask_sz":30,"bid_ct":1,"ask_ct":1},{"bid_px":"245.000000000","ask_px":"273.000000000","bid_sz":50,"ask_sz":1,"bid_ct":1,"ask_ct":1},{"bid_px":"235.000000000","ask_px":"274.000000000","bid_sz":130,"ask_sz":86,"bid_ct":2,"ask_ct":1}],"symbol":"TSLA"}
{"ts_recv":"2024-11-01T08:00:06.356470084Z","hd":{"ts_event":"2024-11-01T08:00:06.356303814Z","rtype":10,"publisher_id":2,"instrument_id":16244},"action":"A","side":"A","depth":8,"price":"270.000000000","size":3,"flags":130,"ts_in_delta":166270,"sequence":300060,"levels":[{"bid_px":"249.880000000","ask_px":"250.680000000","bid_sz":50,"ask_sz":100,"bid_ct":1,"ask_ct":1},{"bid_px":"249.800000000","ask_px":"250.750000000","bid_sz":199,"ask_sz":50,"bid_ct":1,"ask_ct":1},{"bid_px":"249.770000000","ask_px":"252.100000000","bid_sz":50,"ask_sz":1000,"bid_ct":1,"ask_ct":1},{"bid_px":"249.600000000","ask_px":"253.650000000","bid_sz":1000,"ask_sz":400,"bid_ct":1,"ask_ct":1},{"bid_px":"249.500000000","ask_px":"260.000000000","bid_sz":1000,"ask_sz":48,"bid_ct":1,"ask_ct":1},{"bid_px":"249.400000000","ask_px":"264.940000000","bid_sz":1000,"ask_sz":7,"bid_ct":1,"ask_ct":1},{"bid_px":"247.700000000","ask_px":"265.000000000","bid_sz":1000,"ask_sz":1,"bid_ct":1,"ask_ct":1},{"bid_px":"247.150000000","ask_px":"267.800000000","bid_sz":400,"ask_sz":30,"bid_ct":1,"ask_ct":1},{"bid_px":"245.000000000","ask_px":"270.000000000","bid_sz":50,"ask_sz":3,"bid_ct":1,"ask_ct":1},{"bid_px":"235.000000000","ask_px":"273.000000000","bid_sz":130,"ask_sz":1,"bid_ct":2,"ask_ct":1}],"symbol":"TSLA"}
{"ts_recv":"2024-11-01T08:00:06.359584924Z","hd":{"ts_event":"2024-11-01T08:00:06.359418598Z","rtype":10,"publisher_id":2,"instrument_id":16244},"action":"A","side":"B","depth":0,"price":"249.880000000","size":50,"flags":130,"ts_in_delta":166326,"sequence":300069,"levels":[{"bid_px":"249.880000000","ask_px":"250.680000000","bid_sz":100,"ask_sz":100,"bid_ct":2,"ask_ct":1},{"bid_px":"249.800000000","ask_px":"250.750000000","bid_sz":199,"ask_sz":50,"bid_ct":1,"ask_ct":1},{"bid_px":"249.770000000","ask_px":"252.100000000","bid_sz":50,"ask_sz":1000,"bid_ct":1,"ask_ct":1},{"bid_px":"249.600000000","ask_px":"253.650000000","bid_sz":1000,"ask_sz":400,"bid_ct":1,"ask_ct":1},{"bid_px":"249.500000000","ask_px":"260.000000000","bid_sz":1000,"ask_sz":48,"bid_ct":1,"ask_ct":1},{"bid_px":"249.400000000","ask_px":"264.940000000","bid_sz":1000,"ask_sz":7,"bid_ct":1,"ask_ct":1},{"bid_px":"247.700000000","ask_px":"265.000000000","bid_sz":1000,"ask_sz":1,"bid_ct":1,"ask_ct":1},{"bid_px":"247.150000000","ask_px":"267.800000000","bid_sz":400,"ask_sz":30,"bid_ct":1,"ask_ct":1},{"bid_px":"245.000000000","ask_px":"270.000000000","bid_sz":50,"ask_sz":3,"bid_ct":1,"ask_ct":1},{"bid_px":"235.000000000","ask_px":"273.000000000","bid_sz":130,"ask_sz":1,"bid_ct":2,"ask_ct":1}],"symbol":"TSLA"}
{"ts_recv":"2024-11-01T08:00:06.622143213Z","hd":{"ts_event":"2024-11-01T08:00:06.621976999Z","rtype":10,"publisher_id":2,"instrument_id":16244},"action":"A","side":"B","depth":9,"price":"243.200000000","size":15,"flags":130,"ts_in_delta":166214,"sequence":300581,"levels":[{"bid_px":"249.880000000","ask_px":"250.680000000","bid_sz":100,"ask_sz":100,"bid_ct":2,"ask_ct":1},{"bid_px":"249.800000000","ask_px":"250.750000000","bid_sz":199,"ask_sz":50,"bid_ct":1,"ask_ct":1},{"bid_px":"249.770000000","ask_px":"252.100000000","bid_sz":50,"ask_sz":1000,"bid_ct":1,"ask_ct":1},{"bid_px":"249.600000000","ask_px":"253.650000000","bid_sz":1000,"ask_sz":400,"bid_ct":1,"ask_ct":1},{"bid_px":"249.500000000","ask_px":"260.000000000","bid_sz":1000,"ask_sz":48,"bid_ct":1,"ask_ct":1},{"bid_px":"249.400000000","ask_px":"264.940000000","bid_sz":1000,"ask_sz":7,"bid_ct":1,"ask_ct":1},{"bid_px":"247.700000000","ask_px":"265.000000000","bid_sz":1000,"ask_sz":1,"bid_ct":1,"ask_ct":1},{"bid_px":"247.150000000","ask_px":"267.800000000","bid_sz":400,"ask_sz":30,"bid_ct":1,"ask_ct":1},{"bid_px":"245.000000000","ask_px":"270.000000000","bid_sz":50,"ask_sz":3,"bid_ct":1,"ask_ct":1},{"bid_px":"243.200000000","ask_px":"273.000000000","bid_sz":15,"ask_sz":1,"bid_ct":1,"ask_ct":1}],"symbol":"TSLA"}
{"ts_recv":"2024-11-01T08:00:06.880701595Z","hd":{"ts_event":"2024-11-01T08:00:06.880535282Z","rtype":10,"publisher_id":2,"instrument_id":16244},"action":"A","side":"B","depth":8,"price":"245.000000000","size":5,"flags":130,"ts_in_delta":166313,"sequence":300879,"levels":[{"bid_px":"249.880000000","ask_px":"250.680000000","bid_sz":100,"ask_sz":100,"bid_ct":2,"ask_ct":1},{"bid_px":"249.800000000","ask_px":"250.750000000","bid_sz":199,"ask_sz":50,"bid_ct":1,"ask_ct":1},{"bid_px":"249.770000000","ask_px":"252.100000000","bid_sz":50,"ask_sz":1000,"bid_ct":1,"ask_ct":1},{"bid_px":"249.600000000","ask_px":"253.650000000","bid_sz":1000,"ask_sz":400,"bid_ct":1,"ask_ct":1},{"bid_px":"249.500000000","ask_px":"260.000000000","bid_sz":1000,"ask_sz":48,"bid_ct":1,"ask_ct":1},{"bid_px":"249.400000000","ask_px":"264.940000000","bid_sz":1000,"ask_sz":7,"bid_ct":1,"ask_ct":1},{"bid_px":"247.700000000","ask_px":"265.000000000","bid_sz":1000,"ask_sz":1,"bid_ct":1,"ask_ct":1},{"bid_px":"247.150000000","ask_px":"267.800000000","bid_sz":400,"ask_sz":30,"bid_ct":1,"ask_ct":1},{"bid_px":"245.000000000","ask_px":"270.000000000","bid_sz":55,"ask_sz":3,"bid_ct":2,"ask_ct":1},{"bid_px":"243.200000000","ask_px":"273.000000000","bid_sz":15,"ask_sz":1,"bid_ct":1,"ask_ct":1}],"symbol":"TSLA"}
{"ts_recv":"2024-11-01T08:00:07.079894788Z","hd":{"ts_event":"2024-11-01T08:00:07.079728933Z","rtype":10,"publisher_id":2,"instrument_id":16244},"action":"C","side":"A","depth":1,"price":"250.750000000","size":50,"flags":130,"ts_in_delta":165855,"sequence":301044,"levels":[{"bid_px":"249.880000000","ask_px":"250.680000000","bid_sz":100,"ask_sz":100,"bid_ct":2,"ask_ct":1},{"bid_px":"249.800000000","ask_px":"252.100000000","bid_sz":199,"ask_sz":1000,"bid_ct":1,"ask_ct":1},{"bid_px":"249.770000000","ask_px":"253.650000000","bid_sz":50,"ask_sz":400,"bid_ct":1,"ask_ct":1},{"bid_px":"249.600000000","ask_px":"260.000000000","bid_sz":1000,"ask_sz":48,"bid_ct":1,"ask_ct":1},{"bid_px":"249.500000000","ask_px":"264.940000000","bid_sz":1000,"ask_sz":7,"bid_ct":1,"ask_ct":1},{"bid_px":"249.400000000","ask_px":"265.000000000","bid_sz":1000,"ask_sz":1,"bid_ct":1,"ask_ct":1},{"bid_px":"247.700000000","ask_px":"267.800000000","bid_sz":1000,"ask_sz":30,"bid_ct":1,"ask_ct":1},{"bid_px":"247.150000000","ask_px":"270.000000000","bid_sz":400,"ask_sz":3,"bid_ct":1,"ask_ct":1},{"bid_px":"245.000000000","ask_px":"273.000000000","bid_sz":55,"ask_sz":1,"bid_ct":2,"ask_ct":1},{"bid_px":"243.200000000","ask_px":"274.000000000","bid_sz":15,"ask_sz":86,"bid_ct":1,"ask_ct":1}],"symbol":"TSLA"}
{"ts_recv":"2024-11-01T08:00:07.089199825Z","hd":{"ts_event":"2024-11-01T08:00:07.089033596Z","rtype":10,"publisher_id":2,"instrument_id":16244},"action":"A","side":"A","depth":1,"price":"250.760000000","size":50,"flags":130,"ts_in_delta":166229,"sequence":301047,"levels":[{"bid_px":"249.880000000","ask_px":"250.680000000","bid_sz":100,"ask_sz":100,"bid_ct":2,"ask_ct":1},{"bid_px":"249.800000000","ask_px":"250.760000000","bid_sz":199,"ask_sz":50,"bid_ct":1,"ask_ct":1},{"bid_px":"249.770000000","ask_px":"252.100000000","bid_sz":50,"ask_sz":1000,"bid_ct":1,"ask_ct":1},{"bid_px":"249.600000000","ask_px":"253.650000000","bid_sz":1000,"ask_sz":400,"bid_ct":1,"ask_ct":1},{"bid_px":"249.500000000","ask_px":"260.000000000","bid_sz":1000,"ask_sz":48,"bid_ct":1,"ask_ct":1},{"bid_px":"249.400000000","ask_px":"264.940000000","bid_sz":1000,"ask_sz":7,"bid_ct":1,"ask_ct":1},{"bid_px":"247.700000000","ask_px":"265.000000000","bid_sz":1000,"ask_sz":1,"bid_ct":1,"ask_ct":1},{"bid_px":"247.150000000","ask_px":"267.800000000","bid_sz":400,"ask_sz":30,"bid_ct":1,"ask_ct":1},{"bid_px":"245.000000000","ask_px":"270.000000000","bid_sz":55,"ask_sz":3,"bid_ct":2,"ask_ct":1},{"bid_px":"243.200000000","ask_px":"273.000000000","bid_sz":15,"ask_sz":1,"bid_ct":1,"ask_ct":1}],"symbol":"TSLA"}
{"ts_recv":"2024-11-01T08:00:07.104804757Z","hd":{"ts_event":"2024-11-01T08:00:07.104638780Z","rtype":10,"publisher_id":2,"instrument_id":16244},"action":"C","side":"B","depth":0,"price":"249.880000000","size":50,"flags":130,"ts_in_delta":165977,"sequence":301056,"levels":[{"bid_px":"249.880000000","ask_px":"250.680000000","bid_sz":50,"ask_sz":100,"bid_ct":1,"ask_ct":1},{"bid_px":"249.800000000","ask_px":"250.760000000","bid_sz":199,"ask_sz":50,"bid_ct":1,"ask_ct":1},{"bid_px":"249.770000000","ask_px":"252.100000000","bid_sz":50,"ask_sz":1000,"bid_ct":1,"ask_ct":1},{"bid_px":"249.600000000","ask_px":"253.650000000","bid_sz":1000,"ask_sz":400,"bid_ct":1,"ask_ct":1},{"bid_px":"249.500000000","ask_px":"260.000000000","bid_sz":1000,"ask_sz":48,"bid_ct":1,"ask_ct":1},{"bid_px":"249.400000000","ask_px":"264.940000000","bid_sz":1000,"ask_sz":7,"bid_ct":1,"ask_ct":1},{"bid_px":"247.700000000","ask_px":"265.000000000","bid_sz":1000,"ask_sz":1,"bid_ct":1,"ask_ct":1},{"bid_px":"247.150000000","ask_px":"267.800000000","bid_sz":400,"ask_sz":30,"bid_ct":1,"ask_ct":1},{"bid_px":"245.000000000","ask_px":"270.000000000","bid_sz":55,"ask_sz":3,"bid_ct":2,"ask_ct":1},{"bid_px":"243.200000000","ask_px":"273.000000000","bid_sz":15,"ask_sz":1,"bid_ct":1,"ask_ct":1}],"symbol":"TSLA"}
{"ts_recv":"2024-11-01T08:00:07.104820824Z","hd":{"ts_event":"2024-11-01T08:00:07.104654217Z","rtype":10,"publisher_id":2,"instrument_id":16244},"action":"A","side":"B","depth":0,"price":"249.890000000","size":50,"flags":130,"ts_in_delta":166607,"sequence":301057,"levels":[{"bid_px":"249.890000000","ask_px":"250.680000000","bid_sz":50,"ask_sz":100,"bid_ct":1,"ask_ct":1},{"bid_px":"249.800000000","ask_px":"250.760000000","bid_sz":199,"ask_sz":50,"bid_ct":1,"ask_ct":1},{"bid_px":"249.770000000","ask_px":"252.100000000","bid_sz":50,"ask_sz":1000,"bid_ct":1,"ask_ct":1},{"bid_px":"249.600000000","ask_px":"253.650000000","bid_sz":1000,"ask_sz":400,"bid_ct":1,"ask_ct":1},{"bid_px":"249.500000000","ask_px":"260.000000000","bid_sz":1000,"ask_sz":48,"bid_ct":1,"ask_ct":1},{"bid_px":"249.400000000","ask_px":"264.940000000","bid_sz":1000,"ask_sz":7,"bid_ct":1,"ask_ct":1},{"bid_px":"247.700000000","ask_px":"265.000000000","bid_sz":1000,"ask_sz":1,"bid_ct":1,"ask_ct":1},{"bid_px":"247.150000000","ask_px":"267.800000000","bid_sz":400,"ask_sz":30,"bid_ct":1,"ask_ct":1},{"bid_px":"245.000000000","ask_px":"270.000000000","bid_sz":55,"ask_sz":3,"bid_ct":2,"ask_ct":1},{"bid_px":"243.200000000","ask_px":"273.000000000","bid_sz":15,"ask_sz":1,"bid_ct":1,"ask_ct":1}],"symbol":"TSLA"}
{"ts_recv":"2024-11-01T08:00:07.120093736Z","hd":{"ts_event":"2024-11-01T08:00:07.119927482Z","rtype":10,"publisher_id":2,"instrument_id":16244},"action":"C","side":"A","depth":0,"price":"250.680000000","size":100,"flags":130,"ts_in_delta":166254,"sequence":301103,"levels":[{"bid_px":"249.890000000","ask_px":"250.760000000","bid_sz":50,"ask_sz":50,"bid_ct":1,"ask_ct":1},{"bid_px":"249.800000000","ask_px":"252.100000000","bid_sz":199,"ask_sz":1000,"bid_ct":1,"ask_ct":1},{"bid_px":"249.770000000","ask_px":"253.650000000","bid_sz":50,"ask_sz":400,"bid_ct":1,"ask_ct":1},{"bid_px":"249.600000000","ask_px":"260.000000000","bid_sz":1000,"ask_sz":48,"bid_ct":1,"ask_ct":1},{"bid_px":"249.500000000","ask_px":"264.940000000","bid_sz":1000,"ask_sz":7,"bid_ct":1,"ask_ct":1},{"bid_px":"249.400000000","ask_px":"265.000000000","bid_sz":1000,"ask_sz":1,"bid_ct":1,"ask_ct":1},{"bid_px":"247.700000000","ask_px":"267.800000000","bid_sz":1000,"ask_sz":30,"bid_ct":1,"ask_ct":1},{"bid_px":"247.150000000","ask_px":"270.000000000","bid_sz":400,"ask_sz":3,"bid_ct":1,"ask_ct":1},{"bid_px":"245.000000000","ask_px":"273.000000000","bid_sz":55,"ask_sz":1,"bid_ct":2,"ask_ct":1},{"bid_px":"243.200000000","ask_px":"274.000000000","bid_sz":15,"ask_sz":86,"bid_ct":1,"ask_ct":1}],"symbol":"TSLA"}
{"ts_recv":"2024-11-01T08:00:07.120106510Z","hd":{"ts_event":"2024-11-01T08:00:07.119940373Z","rtype":10,"publisher_id":2,"instrument_id":16244},"action":"A","side":"A","depth":0,"price":"250.700000000","size":100,"flags":130,"ts_in_delta":166137,"sequence":301104,"levels":[{"bid_px":"249.890000000","ask_px":"250.700000000","bid_sz":50,"ask_sz":100,"bid_ct":1,"ask_ct":1},{"bid_px":"249.800000000","ask_px":"250.760000000","bid_sz":199,"ask_sz":50,"bid_ct":1,"ask_ct":1},{"bid_px":"249.770000000","ask_px":"252.100000000","bid_sz":50,"ask_sz":1000,"bid_ct":1,"ask_ct":1},{"bid_px":"249.600000000","ask_px":"253.650000000","bid_sz":1000,"ask_sz":400,"bid_ct":1,"ask_ct":1},{"bid_px":"249.500000000","ask_px":"260.000000000","bid_sz":1000,"ask_sz":48,"bid_ct":1,"ask_ct":1},{"bid_px":"249.400000000","ask_px":"264.940000000","bid_sz":1000,"ask_sz":7,"bid_ct":1,"ask_ct":1},{"bid_px":"247.700000000","ask_px":"265.000000000","bid_sz":1000,"ask_sz":1,"bid_ct":1,"ask_ct":1},{"bid_px":"247.150000000","ask_px":"267.800000000","bid_sz":400,"ask_sz":30,"bid_ct":1,"ask_ct":1},{"bid_px":"245.000000000","ask_px":"270.000000000","bid_sz":55,"ask_sz":3,"bid_ct":2,"ask_ct":1},{"bid_px":"243.200000000","ask_px":"273.000000000","bid_sz":15,"ask_sz":1,"bid_ct":1,"ask_ct":1}],"symbol":"TSLA"}
{"ts_recv":"2024-11-01T08:00:07.120191155Z","hd":{"ts_event":"2024-11-01T08:00:07.120025391Z","rtype":10,"publisher_id":2,"instrument_id":16244},"action":"C","side":"A","depth":2,"price":"252.100000000","size":1000,"flags":130,"ts_in_delta":165764,"sequence":301105,"levels":[{"bid_px":"249.890000000","ask_px":"250.700000000","bid_sz":50,"ask_sz":100,"bid_ct":1,"ask_ct":1},{"bid_px":"249.800000000","ask_px":"250.760000000","bid_sz":199,"ask_sz":50,"bid_ct":1,"ask_ct":1},{"bid_px":"249.770000000","ask_px":"253.650000000","bid_sz":50,"ask_sz":400,"bid_ct":1,"ask_ct":1},{"bid_px":"249.600000000","ask_px":"260.000000000","bid_sz":1000,"ask_sz":48,"bid_ct":1,"ask_ct":1},{"bid_px":"249.500000000","ask_px":"264.940000000","bid_sz":1000,"ask_sz":7,"bid_ct":1,"ask_ct":1},{"bid_px":"249.400000000","ask_px":"265.000000000","bid_sz":1000,"ask_sz":1,"bid_ct":1,"ask_ct":1},{"bid_px":"247.700000000","ask_px":"267.800000000","bid_sz":1000,"ask_sz":30,"bid_ct":1,"ask_ct":1},{"bid_px":"247.150000000","ask_px":"270.000000000","bid_sz":400,"ask_sz":3,"bid_ct":1,"ask_ct":1},{"bid_px":"245.000000000","ask_px":"273.000000000","bid_sz":55,"ask_sz":1,"bid_ct":2,"ask_ct":1},{"bid_px":"243.200000000","ask_px":"274.000000000","bid_sz":15,"ask_sz":86,"bid_ct":1,"ask_ct":1}],"symbol":"TSLA"}
{"ts_recv":"2024-11-01T08:00:07.120386110Z","hd":{"ts_event":"2024-11-01T08:00:07.120220561Z","rtype":10,"publisher_id":2,"instrument_id":16244},"action":"C","side":"A","depth":0,"price":"250.700000000","size":100,"flags":130,"ts_in_delta":165549,"sequence":301108,"levels":[{"bid_px":"249.890000000","ask_px":"250.760000000","bid_sz":50,"ask_sz":50,"bid_ct":1,"ask_ct":1},{"bid_px":"249.800000000","ask_px":"253.650000000","bid_sz":199,"ask_sz":400,"bid_ct":1,"ask_ct":1},{"bid_px":"249.770000000","ask_px":"260.000000000","bid_sz":50,"ask_sz":48,"bid_ct":1,"ask_ct":1},{"bid_px":"249.600000000","ask_px":"264.940000000","bid_sz":1000,"ask_sz":7,"bid_ct":1,"ask_ct":1},{"bid_px":"249.500000000","ask_px":"265.000000000","bid_sz":1000,"ask_sz":1,"bid_ct":1,"ask_ct":1},{"bid_px":"249.400000000","ask_px":"267.800000000","bid_sz":1000,"ask_sz":30,"bid_ct":1,"ask_ct":1},{"bid_px":"247.700000000","ask_px":"270.000000000","bid_sz":1000,"ask_sz":3,"bid_ct":1,"ask_ct":1},{"bid_px":"247.150000000","ask_px":"273.000000000","bid_sz":400,"ask_sz":1,"bid_ct":1,"ask_ct":1},{"bid_px":"245.000000000","ask_px":"274.000000000","bid_sz":55,"ask_sz":86,"bid_ct":2,"ask_ct":1},{"bid_px":"243.200000000","ask_px":"275.000000000","bid_sz":15,"ask_sz":16,"bid_ct":1,"ask_ct":2}],"symbol":"TSLA"}
{"ts_recv":"2024-11-01T08:00:07.120398047Z","hd":{"ts_event":"2024-11-01T08:00:07.120232340Z","rtype":10,"publisher_id":2,"instrument_id":16244},"action":"A","side":"A","depth":0,"price":"250.720000000","size":100,"flags":130,"ts_in_delta":165707,"sequence":301109,"levels":[{"bid_px":"249.890000000","ask_px":"250.720000000","bid_sz":50,"ask_sz":100,"bid_ct":1,"ask_ct":1},{"bid_px":"249.800000000","ask_px":"250.760000000","bid_sz":199,"ask_sz":50,"bid_ct":1,"ask_ct":1},{"bid_px":"249.770000000","ask_px":"253.650000000","bid_sz":50,"ask_sz":400,"bid_ct":1,"ask_ct":1},{"bid_px":"249.600000000","ask_px":"260.000000000","bid_sz":1000,"ask_sz":48,"bid_ct":1,"ask_ct":1},{"bid_px":"249.500000000","ask_px":"264.940000000","bid_sz":1000,"ask_sz":7,"bid_ct":1,"ask_ct":1},{"bid_px":"249.400000000","ask_px":"265.000000000","bid_sz":1000,"ask_sz":1,"bid_ct":1,"ask_ct":1},{"bid_px":"247.700000000","ask_px":"267.800000000","bid_sz":1000,"ask_sz":30,"bid_ct":1,"ask_ct":1},{"bid_px":"247.150000000","ask_px":"270.000000000","bid_sz":400,"ask_sz":3,"bid_ct":1,"ask_ct":1},{"bid_px":"245.000000000","ask_px":"273.000000000","bid_sz":55,"ask_sz":1,"bid_ct":2,"ask_ct":1},{"bid_px":"243.200000000","ask_px":"274.000000000","bid_sz":15,"ask_sz":86,"bid_ct":1,"ask_ct":1}],"symbol":"TSLA"}
{"ts_recv":"2024-11-01T08:00:07.132106037Z","hd":{"ts_event":"2024-11-01T08:00:07.131939916Z","rtype":10,"publisher_id":2,"instrument_id":16244},"action":"A","side":"A","depth":2,"price":"252.400000000","size":1000,"flags":130,"ts_in_delta":166121,"sequence":301116,"levels":[{"bid_px":"249.890000000","ask_px":"250.720000000","bid_sz":50,"ask_sz":100,"bid_ct":1,"ask_ct":1},{"bid_px":"249.800000000","ask_px":"250.760000000","bid_sz":199,"ask_sz":50,"bid_ct":1,"ask_ct":1},{"bid_px":"249.770000000","ask_px":"252.400000000","bid_sz":50,"ask_sz":1000,"bid_ct":1,"ask_ct":1},{"bid_px":"249.600000000","ask_px":"253.650000000","bid_sz":1000,"ask_sz":400,"bid_ct":1,"ask_ct":1},{"bid_px":"249.500000000","ask_px":"260.000000000","bid_sz":1000,"ask_sz":48,"bid_ct":1,"ask_ct":1},{"bid_px":"249.400000000","ask_px":"264.940000000","bid_sz":1000,"ask_sz":7,"bid_ct":1,"ask_ct":1},{"bid_px":"247.700000000","ask_px":"265.000000000","bid_sz":1000,"ask_sz":1,"bid_ct":1,"ask_ct":1},{"bid_px":"247.150000000","ask_px":"267.800000000","bid_sz":400,"ask_sz":30,"bid_ct":1,"ask_ct":1},{"bid_px":"245.000000000","ask_px":"270.000000000","bid_sz":55,"ask_sz":3,"bid_ct":2,"ask_ct":1},{"bid_px":"243.200000000","ask_px":"273.000000000","bid_sz":15,"ask_sz":1,"bid_ct":1,"ask_ct":1}],"symbol":"TSLA"}
{"ts_recv":"2024-11-01T08:00:07.151742419Z","hd":{"ts_event":"2024-11-01T08:00:07.151575801Z","rtype":10,"publisher_id":2,"instrument_id":16244},"action":"A","side":"B","depth":0,"price":"249.890000000","size":50,"flags":130,"ts_in_delta":166618,"sequence":301134,"levels":[{"bid_px":"249.890000000","ask_px":"250.720000000","bid_sz":100,"ask_sz":100,"bid_ct":2,"ask_ct":1},{"bid_px":"249.800000000","ask_px":"250.760000000","bid_sz":199,"ask_sz":50,"bid_ct":1,"ask_ct":1},{"bid_px":"249.770000000","ask_px":"252.400000000","bid_sz":50,"ask_sz":1000,"bid_ct":1,"ask_ct":1},{"bid_px":"249.600000000","ask_px":"253.650000000","bid_sz":1000,"ask_sz":400,"bid_ct":1,"ask_ct":1},{"bid_px":"249.500000000","ask_px":"260.000000000","bid_sz":1000,"ask_sz":48,"bid_ct":1,"ask_ct":1},{"bid_px":"249.400000000","ask_px":"264.940000000","bid_sz":1000,"ask_sz":7,"bid_ct":1,"ask_ct":1},{"bid_px":"247.700000000","ask_px":"265.000000000","bid_sz":1000,"ask_sz":1,"bid_ct":1,"ask_ct":1},{"bid_px":"247.150000000","ask_px":"267.800000000","bid_sz":400,"ask_sz":30,"bid_ct":1,"ask_ct":1},{"bid_px":"245.000000000","ask_px":"270.000000000","bid_sz":55,"ask_sz":3,"bid_ct":2,"ask_ct":1},{"bid_px":"243.200000000","ask_px":"273.000000000","bid_sz":15,"ask_sz":1,"bid_ct":1,"ask_ct":1}],"symbol":"TSLA"}
{"ts_recv":"2024-11-01T08:00:07.161215134Z","hd":{"ts_event":"2024-11-01T08:00:07.161049386Z","rtype":10,"publisher_id":2,"instrument_id":16244},"action":"C","side":"B","depth":0,"price":"249.890000000","size":50,"flags":130,"ts_in_delta":165748,"sequence":301158,"levels":[{"bid_px":"249.890000000","ask_px":"250.720000000","bid_sz":50,"ask_sz":100,"bid_ct":1,"ask_ct":1},{"bid_px":"249.800000000","ask_px":"250.760000000","bid_sz":199,"ask_sz":50,"bid_ct":1,"ask_ct":1},{"bid_px":"249.770000000","ask_px":"252.400000000","bid_sz":50,"ask_sz":1000,"bid_ct":1,"ask_ct":1},{"bid_px":"249.600000000","ask_px":"253.650000000","bid_sz":1000,"ask_sz":400,"bid_ct":1,"ask_ct":1},{"bid_px":"249.500000000","ask_px":"260.000000000","bid_sz":1000,"ask_sz":48,"bid_ct":1,"ask_ct":1},{"bid_px":"249.400000000","ask_px":"264.940000000","bid_sz":1000,"ask_sz":7,"bid_ct":1,"ask_ct":1},{"bid_px":"247.700000000","ask_px":"265.000000000","bid_sz":1000,"ask_sz":1,"bid_ct":1,"ask_ct":1},{"bid_px":"247.150000000","ask_px":"267.800000000","bid_sz":400,"ask_sz":30,"bid_ct":1,"ask_ct":1},{"bid_px":"245.000000000","ask_px":"270.000000000","bid_sz":55,"ask_sz":3,"bid_ct":2,"ask_ct":1},{"bid_px":"243.200000000","ask_px":"273.000000000","bid_sz":15,"ask_sz":1,"bid_ct":1,"ask_ct":1}],"symbol":"TSLA"}
{"ts_recv":"2024-11-01T08:00:07.161233935Z","hd":{"ts_event":"2024-11-01T08:00:07.161067733Z","rtype":10,"publisher_id":2,"instrument_id":16244},"action":"A","side":"B","depth":0,"price":"249.900000000","size":100,"flags":130,"ts_in_delta":166202,"sequence":301159,"levels":[{"bid_px":"249.900000000","ask_px":"250.720000000","bid_sz":100,"ask_sz":100,"bid_ct":1,"ask_ct":1},{"bid_px":"249.800000000","ask_px":"250.760000000","bid_sz":199,"ask_sz":50,"bid_ct":1,"ask_ct":1},{"bid_px":"249.770000000","ask_px":"252.400000000","bid_sz":50,"ask_sz":1000,"bid_ct":1,"ask_ct":1},{"bid_px":"249.600000000","ask_px":"253.650000000","bid_sz":1000,"ask_sz":400,"bid_ct":1,"ask_ct":1},{"bid_px":"249.500000000","ask_px":"260.000000000","bid_sz":1000,"ask_sz":48,"bid_ct":1,"ask_ct":1},{"bid_px":"249.400000000","ask_px":"264.940000000","bid_sz":1000,"ask_sz":7,"bid_ct":1,"ask_ct":1},{"bid_px":"247.700000000","ask_px":"265.000000000","bid_sz":1000,"ask_sz":1,"bid_ct":1,"ask_ct":1},{"bid_px":"247.150000000","ask_px":"267.800000000","bid_sz":400,"ask_sz":30,"bid_ct":1,"ask_ct":1},{"bid_px":"245.000000000","ask_px":"270.000000000","bid_sz":55,"ask_sz":3,"bid_ct":2,"ask_ct":1},{"bid_px":"243.200000000","ask_px":"273.000000000","bid_sz":15,"ask_sz":1,"bid_ct":1,"ask_ct":1}],"symbol":"TSLA"}
{"ts_recv":"2024-11-01T08:00:07.217938771Z","hd":{"ts_event":"2024-11-01T08:00:07.217772345Z","rtype":10,"publisher_id":2,"instrument_id":16244},"action":"A","side":"B","depth":0,"price":"249.910000000","size":100,"flags":130,"ts_in_delta":166426,"sequence":301395,"levels":[{"bid_px":"249.910000000","ask_px":"250.720000000","bid_sz":100,"ask_sz":100,"bid_ct":1,"ask_ct":1},{"bid_px":"249.800000000","ask_px":"250.760000000","bid_sz":199,"ask_sz":50,"bid_ct":1,"ask_ct":1},{"bid_px":"249.770000000","ask_px":"252.400000000","bid_sz":50,"ask_sz":1000,"bid_ct":1,"ask_ct":1},{"bid_px":"249.600000000","ask_px":"253.650000000","bid_sz":1000,"ask_sz":400,"bid_ct":1,"ask_ct":1},{"bid_px":"249.500000000","ask_px":"260.000000000","bid_sz":1000,"ask_sz":48,"bid_ct":1,"ask_ct":1},{"bid_px":"249.400000000","ask_px":"264.940000000","bid_sz":1000,"ask_sz":7,"bid_ct":1,"ask_ct":1},{"bid_px":"247.700000000","ask_px":"265.000000000","bid_sz":1000,"ask_sz":1,"bid_ct":1,"ask_ct":1},{"bid_px":"247.150000000","ask_px":"267.800000000","bid_sz":400,"ask_sz":30,"bid_ct":1,"ask_ct":1},{"bid_px":"245.000000000","ask_px":"270.000000000","bid_sz":55,"ask_sz":3,"bid_ct":2,"ask_ct":1},{"bid_px":"243.200000000","ask_px":"273.000000000","bid_sz":15,"ask_sz":1,"bid_ct":1,"ask_ct":1}],"symbol":"TSLA"}
{"ts_recv":"2024-11-01T08:00:07.236243107Z","hd":{"ts_event":"2024-11-01T08:00:07.236076869Z","rtype":10,"publisher_id":2,"instrument_id":16244},"action":"A","side":"B","depth":0,"price":"250.050000000","size":50,"flags":130,"ts_in_delta":166238,"sequence":301456,"levels":[{"bid_px":"250.050000000","ask_px":"250.720000000","bid_sz":50,"ask_sz":100,"bid_ct":1,"ask_ct":1},{"bid_px":"249.800000000","ask_px":"250.760000000","bid_sz":199,"ask_sz":50,"bid_ct":1,"ask_ct":1},{"bid_px":"249.770000000","ask_px":"252.400000000","bid_sz":50,"ask_sz":1000,"bid_ct":1,"ask_ct":1},{"bid_px":"249.600000000","ask_px":"253.650000000","bid_sz":1000,"ask_sz":400,"bid_ct":1,"ask_ct":1},{"bid_px":"249.500000000","ask_px":"260.000000000","bid_sz":1000,"ask_sz":48,"bid_ct":1,"ask_ct":1},{"bid_px":"249.400000000","ask_px":"264.940000000","bid_sz":1000,"ask_sz":7,"bid_ct":1,"ask_ct":1},{"bid_px":"247.700000000","ask_px":"265.000000000","bid_sz":1000,"ask_sz":1,"bid_ct":1,"ask_ct":1},{"bid_px":"247.150000000","ask_px":"267.800000000","bid_sz":400,"ask_sz":30,"bid_ct":1,"ask_ct":1},{"bid_px":"245.000000000","ask_px":"270.000000000","bid_sz":55,"ask_sz":3,"bid_ct":2,"ask_ct":1},{"bid_px":"243.200000000","ask_px":"273.000000000","bid_sz":15,"ask_sz":1,"bid_ct":1,"ask_ct":1}],"symbol":"TSLA"}
{"ts_recv":"2024-11-01T08:00:08.066264961Z","hd":{"ts_event":"2024-11-01T08:00:08.066098641Z","rtype":10,"publisher_id":2,"instrument_id":16244},"action":"C","side":"B","depth":0,"price":"250.050000000","size":50,"flags":130,"ts_in_delta":166320,"sequence":304212,"levels":[{"bid_px":"249.800000000","ask_px":"250.720000000","bid_sz":199,"ask_sz":100,"bid_ct":1,"ask_ct":1},{"bid_px":"249.770000000","ask_px":"250.760000000","bid_sz":50,"ask_sz":50,"bid_ct":1,"ask_ct":1},{"bid_px":"249.600000000","ask_px":"252.400000000","bid_sz":1000,"ask_sz":1000,"bid_ct":1,"ask_ct":1},{"bid_px":"249.500000000","ask_px":"253.650000000","bid_sz":1000,"ask_sz":400,"bid_ct":1,"ask_ct":1},{"bid_px":"249.400000000","ask_px":"260.000000000","bid_sz":1000,"ask_sz":48,"bid_ct":1,"ask_ct":1},{"bid_px":"247.700000000","ask_px":"264.940000000","bid_sz":1000,"ask_sz":7,"bid_ct":1,"ask_ct":1},{"bid_px":"247.150000000","ask_px":"265.000000000","bid_sz":400,"ask_sz":1,"bid_ct":1,"ask_ct":1},{"bid_px":"245.000000000","ask_px":"267.800000000","bid_sz":55,"ask_sz":30,"bid_ct":2,"ask_ct":1},{"bid_px":"243.200000000","ask_px":"270.000000000","bid_sz":15,"ask_sz":3,"bid_ct":1,"ask_ct":1},{"bid_px":"235.000000000","ask_px":"273.000000000","bid_sz":130,"ask_sz":1,"bid_ct":2,"ask_ct":1}],"symbol":"TSLA"}
{"ts_recv":"2024-11-01T08:00:08.066277251Z","hd":{"ts_event":"2024-11-01T08:00:08.066111120Z","rtype":10,"publisher_id":2,"instrument_id":16244},"action":"A","side":"B","depth":0,"price":"250.030000000","size":50,"flags":130,"ts_in_delta":166131,"sequence":304213,"levels":[{"bid_px":"250.030000000","ask_px":"250.720000000","bid_sz":50,"ask_sz":100,"bid_ct":1,"ask_ct":1},{"bid_px":"249.800000000","ask_px":"250.760000000","bid_sz":199,"ask_sz":50,"bid_ct":1,"ask_ct":1},{"bid_px":"249.770000000","ask_px":"252.400000000","bid_sz":50,"ask_sz":1000,"bid_ct":1,"ask_ct":1},{"bid_px":"249.600000000","ask_px":"253.650000000","bid_sz":1000,"ask_sz":400,"bid_ct":1,"ask_ct":1},{"bid_px":"249.500000000","ask_px":"260.000000000","bid_sz":1000,"ask_sz":48,"bid_ct":1,"ask_ct":1},{"bid_px":"249.400000000","ask_px":"264.940000000","bid_sz":1000,"ask_sz":7,"bid_ct":1,"ask_ct":1},{"bid_px":"247.700000000","ask_px":"265.000000000","bid_sz":1000,"ask_sz":1,"bid_ct":1,"ask_ct":1},{"bid_px":"247.150000000","ask_px":"267.800000000","bid_sz":400,"ask_sz":30,"bid_ct":1,"ask_ct":1},{"bid_px":"245.000000000","ask_px":"270.000000000","bid_sz":55,"ask_sz":3,"bid_ct":2,"ask_ct":1},{"bid_px":"243.200000000","ask_px":"273.000000000","bid_sz":15,"ask_sz":1,"bid_ct":1,"ask_ct":1}],"symbol":"TSLA"}
{"ts_recv":"2024-11-01T08:00:08.257587355Z","hd":{"ts_event":"2024-11-01T08:00:08.257420922Z","rtype":10,"publisher_id":2,"instrument_id":16244},"action":"A","side":"A","depth":4,"price":"255.000000000","size":10,"flags":130,"ts_in_delta":166433,"sequence":304768,"levels":[{"bid_px":"250.030000000","ask_px":"250.720000000","bid_sz":50,"ask_sz":100,"bid_ct":1,"ask_ct":1},{"bid_px":"249.800000000","ask_px":"250.760000000","bid_sz":199,"ask_sz":50,"bid_ct":1,"ask_ct":1},{"bid_px":"249.770000000","ask_px":"252.400000000","bid_sz":50,"ask_sz":1000,"bid_ct":1,"ask_ct":1},{"bid_px":"249.600000000","ask_px":"253.650000000","bid_sz":1000,"ask_sz":400,"bid_ct":1,"ask_ct":1},{"bid_px":"249.500000000","ask_px":"255.000000000","bid_sz":1000,"ask_sz":10,"bid_ct":1,"ask_ct":1},{"bid_px":"249.400000000","ask_px":"260.000000000","bid_sz":1000,"ask_sz":48,"bid_ct":1,"ask_ct":1},{"bid_px":"247.700000000","ask_px":"264.940000000","bid_sz":1000,"ask_sz":7,"bid_ct":1,"ask_ct":1},{"bid_px":"247.150000000","ask_px":"265.000000000","bid_sz":400,"ask_sz":1,"bid_ct":1,"ask_ct":1},{"bid_px":"245.000000000","ask_px":"267.800000000","bid_sz":55,"ask_sz":30,"bid_ct":2,"ask_ct":1},{"bid_px":"243.200000000","ask_px":"270.000000000","bid_sz":15,"ask_sz":3,"bid_ct":1,"ask_ct":1}],"symbol":"TSLA"}
{"ts_recv":"2024-11-01T08:00:08.320809942Z","hd":{"ts_event":"2024-11-01T08:00:08.320643637Z","rtype":10,"publisher_id":2,"instrument_id":16244},"action":"A","side":"A","depth":9,"price":"269.580000000","size":100,"flags":130,"ts_in_delta":166305,"sequence":305132,"levels":[{"bid_px":"250.030000000","ask_px":"250.720000000","bid_sz":50,"ask_sz":100,"bid_ct":1,"ask_ct":1},{"bid_px":"249.800000000","ask_px":"250.760000000","bid_sz":199,"ask_sz":50,"bid_ct":1,"ask_ct":1},{"bid_px":"249.770000000","ask_px":"252.400000000","bid_sz":50,"ask_sz":1000,"bid_ct":1,"ask_ct":1},{"bid_px":"249.600000000","ask_px":"253.650000000","bid_sz":1000,"ask_sz":400,"bid_ct":1,"ask_ct":1},{"bid_px":"249.500000000","ask_px":"255.000000000","bid_sz":1000,"ask_sz":10,"bid_ct":1,"ask_ct":1},{"bid_px":"249.400000000","ask_px":"260.000000000","bid_sz":1000,"ask_sz":48,"bid_ct":1,"ask_ct":1},{"bid_px":"247.700000000","ask_px":"264.940000000","bid_sz":1000,"ask_sz":7,"bid_ct":1,"ask_ct":1},{"bid_px":"247.150000000","ask_px":"265.000000000","bid_sz":400,"ask_sz":1,"bid_ct":1,"ask_ct":1},{"bid_px":"245.000000000","ask_px":"267.800000000","bid_sz":55,"ask_sz":30,"bid_ct":2,"ask_ct":1},{"bid_px":"243.200000000","ask_px":"269.580000000","bid_sz":15,"ask_sz":100,"bid_ct":1,"ask_ct":1}],"symbol":"TSLA"}
{"ts_recv":"2024-11-01T08:00:08.398037236Z","hd":{"ts_event":"2024-11-01T08:00:08.397871271Z","rtype":10,"publisher_id":2,"instrument_id":16244},"action":"A","side":"B","depth":1,"price":"249.930000000","size":10,"flags":130,"ts_in_delta":165965,"sequence":305707,"levels":[{"bid_px":"250.030000000","ask_px":"250.720000000","bid_sz":50,"ask_sz":100,"bid_ct":1,"ask_ct":1},{"bid_px":"249.930000000","ask_px":"250.760000000","bid_sz":10,"ask_sz":50,"bid_ct":1,"ask_ct":1},{"bid_px":"249.800000000","ask_px":"252.400000000","bid_sz":199,"ask_sz":1000,"bid_ct":1,"ask_ct":1},{"bid_px":"249.770000000","ask_px":"253.650000000","bid_sz":50,"ask_sz":400,"bid_ct":1,"ask_ct":1},{"bid_px":"249.600000000","ask_px":"255.000000000","bid_sz":1000,"ask_sz":10,"bid_ct":1,"ask_ct":1},{"bid_px":"249.500000000","ask_px":"260.000000000","bid_sz":1000,"ask_sz":48,"bid_ct":1,"ask_ct":1},{"bid_px":"249.400000000","ask_px":"264.940000000","bid_sz":1000,"ask_sz":7,"bid_ct":1,"ask_ct":1},{"bid_px":"247.700000000","ask_px":"265.000000000","bid_sz":1000,"ask_sz":1,"bid_ct":1,"ask_ct":1},{"bid_px":"247.150000000","ask_px":"267.800000000","bid_sz":400,"ask_sz":30,"bid_ct":1,"ask_ct":1},{"bid_px":"245.000000000","ask_px":"269.580000000","bid_sz":55,"ask_sz":100,"bid_ct":2,"ask_ct":1}],"symbol":"TSLA"}
{"ts_recv":"2024-11-01T08:00:08.496635521Z","hd":{"ts_event":"2024-11-01T08:00:08.496469300Z","rtype":10,"publisher_id":2,"instrument_id":16244},"action":"A","side":"A","depth":9,"price":"268.670000000","size":100,"flags":130,"ts_in_delta":166221,"sequence":306180,"levels":[{"bid_px":"250.030000000","ask_px":"250.720000000","bid_sz":50,"ask_sz":100,"bid_ct":1,"ask_ct":1},{"bid_px":"249.930000000","ask_px":"250.760000000","bid_sz":10,"ask_sz":50,"bid_ct":1,"ask_ct":1},{"bid_px":"249.800000000","ask_px":"252.400000000","bid_sz":199,"ask_sz":1000,"bid_ct":1,"ask_ct":1},{"bid_px":"249.770000000","ask_px":"253.650000000","bid_sz":50,"ask_sz":400,"bid_ct":1,"ask_ct":1},{"bid_px":"249.600000000","ask_px":"255.000000000","bid_sz":1000,"ask_sz":10,"bid_ct":1,"ask_ct":1},{"bid_px":"249.500000000","ask_px":"260.000000000","bid_sz":1000,"ask_sz":48,"bid_ct":1,"ask_ct":1},{"bid_px":"249.400000000","ask_px":"264.940000000","bid_sz":1000,"ask_sz":7,"bid_ct":1,"ask_ct":1},{"bid_px":"247.700000000","ask_px":"265.000000000","bid_sz":1000,"ask_sz":1,"bid_ct":1,"ask_ct":1},{"bid_px":"247.150000000","ask_px":"267.800000000","bid_sz":400,"ask_sz":30,"bid_ct":1,"ask_ct":1},{"bid_px":"245.000000000","ask_px":"268.670000000","bid_sz":55,"ask_sz":100,"bid_ct":2,"ask_ct":1}],"symbol":"TSLA"}
{"ts_recv":"2024-11-01T08:00:08.962661271Z","hd":{"ts_event":"2024-11-01T08:00:08.962495026Z","rtype":10,"publisher_id":2,"instrument_id":16244},"action":"A","side":"A","depth":6,"price":"262.660000000","size":56,"flags":130,"ts_in_delta":166245,"sequence":307561,"levels":[{"bid_px":"250.030000000","ask_px":"250.720000000","bid_sz":50,"ask_sz":100,"bid_ct":1,"ask_ct":1},{"bid_px":"249.930000000","ask_px":"250.760000000","bid_sz":10,"ask_sz":50,"bid_ct":1,"ask_ct":1},{"bid_px":"249.800000000","ask_px":"252.400000000","bid_sz":199,"ask_sz":1000,"bid_ct":1,"ask_ct":1},{"bid_px":"249.770000000","ask_px":"253.650000000","bid_sz":50,"ask_sz":400,"bid_ct":1,"ask_ct":1},{"bid_px":"249.600000000","ask_px":"255.000000000","bid_sz":1000,"ask_sz":10,"bid_ct":1,"ask_ct":1},{"bid_px":"249.500000000","ask_px":"260.000000000","bid_sz":1000,"ask_sz":48,"bid_ct":1,"ask_ct":1},{"bid_px":"249.400000000","ask_px":"262.660000000","bid_sz":1000,"ask_sz":56,"bid_ct":1,"ask_ct":1},{"bid_px":"247.700000000","ask_px":"264.940000000","bid_sz":1000,"ask_sz":7,"bid_ct":1,"ask_ct":1},{"bid_px":"247.150000000","ask_px":"265.000000000","bid_sz":400,"ask_sz":1,"bid_ct":1,"ask_ct":1},{"bid_px":"245.000000000","ask_px":"267.800000000","bid_sz":55,"ask_sz":30,"bid_ct":2,"ask_ct":1}],"symbol":"TSLA"}
{"ts_recv":"2024-11-01T08:00:09.070231821Z","hd":{"ts_event":"2024-11-01T08:00:09.070065678Z","rtype":10,"publisher_id":2,"instrument_id":16244},"action":"A","side":"B","depth":9,"price":"246.000000000","size":4,"flags":130,"ts_in_delta":166143,"sequence":307784,"levels":[{"bid_px":"250.030000000","ask_px":"250.720000000","bid_sz":50,"ask_sz":100,"bid_ct":1,"ask_ct":1},{"bid_px":"249.930000000","ask_px":"250.760000000","bid_sz":10,"ask_sz":50,"bid_ct":1,"ask_ct":1},{"bid_px":"249.800000000","ask_px":"252.400000000","bid_sz":199,"ask_sz":1000,"bid_ct":1,"ask_ct":1},{"bid_px":"249.770000000","ask_px":"253.650000000","bid_sz":50,"ask_sz":400,"bid_ct":1,"ask_ct":1},{"bid_px":"249.600000000","ask_px":"255.000000000","bid_sz":1000,"ask_sz":10,"bid_ct":1,"ask_ct":1},{"bid_px":"249.500000000","ask_px":"260.000000000","bid_sz":1000,"ask_sz":48,"bid_ct":1,"ask_ct":1},{"bid_px":"249.400000000","ask_px":"262.660000000","bid_sz":1000,"ask_sz":56,"bid_ct":1,"ask_ct":1},{"bid_px":"247.700000000","ask_px":"264.940000000","bid_sz":1000,"ask_sz":7,"bid_ct":1,"ask_ct":1},{"bid_px":"247.150000000","ask_px":"265.000000000","bid_sz":400,"ask_sz":1,"bid_ct":1,"ask_ct":1},{"bid_px":"246.000000000","ask_px":"267.800000000","bid_sz":4,"ask_sz":30,"bid_ct":1,"ask_ct":1}],"symbol":"TSLA"}
{"ts_recv":"2024-11-01T08:00:09.184621728Z","hd":{"ts_event":"2024-11-01T08:00:09.184455471Z","rtype":10,"publisher_id":2,"instrument_id":16244},"action":"A","side":"B","depth":9,"price":"247.000000000","size":12,"flags":130,"ts_in_delta":166257,"sequence":307945,"levels":[{"bid_px":"250.030000000","ask_px":"250.720000000","bid_sz":50,"ask_sz":100,"bid_ct":1,"ask_ct":1},{"bid_px":"249.930000000","ask_px":"250.760000000","bid_sz":10,"ask_sz":50,"bid_ct":1,"ask_ct":1},{"bid_px":"249.800000000","ask_px":"252.400000000","bid_sz":199,"ask_sz":1000,"bid_ct":1,"ask_ct":1},{"bid_px":"249.770000000","ask_px":"253.650000000","bid_sz":50,"ask_sz":400,"bid_ct":1,"ask_ct":1},{"bid_px":"249.600000000","ask_px":"255.000000000","bid_sz":1000,"ask_sz":10,"bid_ct":1,"ask_ct":1},{"bid_px":"249.500000000","ask_px":"260.000000000","bid_sz":1000,"ask_sz":48,"bid_ct":1,"ask_ct":1},{"bid_px":"249.400000000","ask_px":"262.660000000","bid_sz":1000,"ask_sz":56,"bid_ct":1,"ask_ct":1},{"bid_px":"247.700000000","ask_px":"264.940000000","bid_sz":1000,"ask_sz":7,"bid_ct":1,"ask_ct":1},{"bid_px":"247.150000000","ask_px":"265.000000000","bid_sz":400,"ask_sz":1,"bid_ct":1,"ask_ct":1},{"bid_px":"247.000000000","ask_px":"267.800000000","bid_sz":12,"ask_sz":30,"bid_ct":1,"ask_ct":1}],"symbol":"TSLA"}
{"ts_recv":"2024-11-01T08:00:09.237350461Z","hd":{"ts_event":"2024-11-01T08:00:09.237184087Z","rtype":10,"publisher_id":2,"instrument_id":16244},"action":"A","side":"B","depth":1,"price":"250.000000000","size":1,"flags":130,"ts_in_delta":166374,"sequence":308002,"levels":[{"bid_px":"250.030000000","ask_px":"250.720000000","bid_sz":50,"ask_sz":100,"bid_ct":1,"ask_ct":1},{"bid_px":"250.000000000","ask_px":"250.760000000","bid_sz":1,"ask_sz":50,"bid_ct":1,"ask_ct":1},{"bid_px":"249.930000000","ask_px":"252.400000000","bid_sz":10,"ask_sz":1000,"bid_ct":1,"ask_ct":1},{"bid_px":"249.800000000","ask_px":"253.650000000","bid_sz":199,"ask_sz":400,"bid_ct":1,"ask_ct":1},{"bid_px":"249.770000000","ask_px":"255.000000000","bid_sz":50,"ask_sz":10,"bid_ct":1,"ask_ct":1},{"bid_px":"249.600000000","ask_px":"260.000000000","bid_sz":1000,"ask_sz":48,"bid_ct":1,"ask_ct":1},{"bid_px":"249.500000000","ask_px":"262.660000000","bid_sz":1000,"ask_sz":56,"bid_ct":1,"ask_ct":1},{"bid_px":"249.400000000","ask_px":"264.940000000","bid_sz":1000,"ask_sz":7,"bid_ct":1,"ask_ct":1},{"bid_px":"247.700000000","ask_px":"265.000000000","bid_sz":1000,"ask_sz":1,"bid_ct":1,"ask_ct":1},{"bid_px":"247.150000000","ask_px":"267.800000000","bid_sz":400,"ask_sz":30,"bid_ct":1,"ask_ct":1}],"symbol":"TSLA"}
{"ts_recv":"2024-11-01T08:00:09.238148826Z","hd":{"ts_event":"2024-11-01T08:00:09.237982939Z","rtype":10,"publisher_id":2,"instrument_id":16244},"action":"C","side":"B","depth":7,"price":"249.400000000","size":1000,"flags":130,"ts_in_delta":165887,"sequence":308003,"levels":[{"bid_px":"250.030000000","ask_px":"250.720000000","bid_sz":50,"ask_sz":100,"bid_ct":1,"ask_ct":1},{"bid_px":"250.000000000","ask_px":"250.760000000","bid_sz":1,"ask_sz":50,"bid_ct":1,"ask_ct":1},{"bid_px":"249.930000000","ask_px":"252.400000000","bid_sz":10,"ask_sz":1000,"bid_ct":1,"ask_ct":1},{"bid_px":"249.800000000","ask_px":"253.650000000","bid_sz":199,"ask_sz":400,"bid_ct":1,"ask_ct":1},{"bid_px":"249.770000000","ask_px":"255.000000000","bid_sz":50,"ask_sz":10,"bid_ct":1,"ask_ct":1},{"bid_px":"249.600000000","ask_px":"260.000000000","bid_sz":1000,"ask_sz":48,"bid_ct":1,"ask_ct":1},{"bid_px":"249.500000000","ask_px":"262.660000000","bid_sz":1000,"ask_sz":56,"bid_ct":1,"ask_ct":1},{"bid_px":"247.700000000","ask_px":"264.940000000","bid_sz":1000,"ask_sz":7,"bid_ct":1,"ask_ct":1},{"bid_px":"247.150000000","ask_px":"265.000000000","bid_sz":400,"ask_sz":1,"bid_ct":1,"ask_ct":1},{"bid_px":"247.000000000","ask_px":"267.800000000","bid_sz":12,"ask_sz":30,"bid_ct":1,"ask_ct":1}],"symbol":"TSLA"}
{"ts_recv":"2024-11-01T08:00:09.248919398Z","hd":{"ts_event":"2024-11-01T08:00:09.248753431Z","rtype":10,"publisher_id":2,"instrument_id":16244},"action":"A","side":"B","depth":7,"price":"248.600000000","size":1000,"flags":130,"ts_in_delta":165967,"sequence":308020,"levels":[{"bid_px":"250.030000000","ask_px":"250.720000000","bid_sz":50,"ask_sz":100,"bid_ct":1,"ask_ct":1},{"bid_px":"250.000000000","ask_px":"250.760000000","bid_sz":1,"ask_sz":50,"bid_ct":1,"ask_ct":1},{"bid_px":"249.930000000","ask_px":"252.400000000","bid_sz":10,"ask_sz":1000,"bid_ct":1,"ask_ct":1},{"bid_px":"249.800000000","ask_px":"253.650000000","bid_sz":199,"ask_sz":400,"bid_ct":1,"ask_ct":1},{"bid_px":"249.770000000","ask_px":"255.000000000","bid_sz":50,"ask_sz":10,"bid_ct":1,"ask_ct":1},{"bid_px":"249.600000000","ask_px":"260.000000000","bid_sz":1000,"ask_sz":48,"bid_ct":1,"ask_ct":1},{"bid_px":"249.500000000","ask_px":"262.660000000","bid_sz":1000,"ask_sz":56,"bid_ct":1,"ask_ct":1},{"bid_px":"248.600000000","ask_px":"264.940000000","bid_sz":1000,"ask_sz":7,"bid_ct":1,"ask_ct":1},{"bid_px":"247.700000000","ask_px":"265.000000000","bid_sz":1000,"ask_sz":1,"bid_ct":1,"ask_ct":1},{"bid_px":"247.150000000","ask_px":"267.800000000","bid_sz":400,"ask_sz":30,"bid_ct":1,"ask_ct":1}],"symbol":"TSLA"}
{"ts_recv":"2024-11-01T08:00:09.248957175Z","hd":{"ts_event":"2024-11-01T08:00:09.248791239Z","rtype":10,"publisher_id":2,"instrument_id":16244},"action":"C","side":"B","depth":8,"price":"247.700000000","size":1000,"flags":130,"ts_in_delta":165936,"sequence":308021,"levels":[{"bid_px":"250.030000000","ask_px":"250.720000000","bid_sz":50,"ask_sz":100,"bid_ct":1,"ask_ct":1},{"bid_px":"250.000000000","ask_px":"250.760000000","bid_sz":1,"ask_sz":50,"bid_ct":1,"ask_ct":1},{"bid_px":"249.930000000","ask_px":"252.400000000","bid_sz":10,"ask_sz":1000,"bid_ct":1,"ask_ct":1},{"bid_px":"249.800000000","ask_px":"253.650000000","bid_sz":199,"ask_sz":400,"bid_ct":1,"ask_ct":1},{"bid_px":"249.770000000","ask_px":"255.000000000","bid_sz":50,"ask_sz":10,"bid_ct":1,"ask_ct":1},{"bid_px":"249.600000000","ask_px":"260.000000000","bid_sz":1000,"ask_sz":48,"bid_ct":1,"ask_ct":1},{"bid_px":"249.500000000","ask_px":"262.660000000","bid_sz":1000,"ask_sz":56,"bid_ct":1,"ask_ct":1},{"bid_px":"248.600000000","ask_px":"264.940000000","bid_sz":1000,"ask_sz":7,"bid_ct":1,"ask_ct":1},{"bid_px":"247.150000000","ask_px":"265.000000000","bid_sz":400,"ask_sz":1,"bid_ct":1,"ask_ct":1},{"bid_px":"247.000000000","ask_px":"267.800000000","bid_sz":12,"ask_sz":30,"bid_ct":1,"ask_ct":1}],"symbol":"TSLA"}
{"ts_recv":"2024-11-01T08:00:09.310782807Z","hd":{"ts_event":"2024-11-01T08:00:09.310616621Z","rtype":10,"publisher_id":2,"instrument_id":16244},"action":"A","side":"A","depth":4,"price":"255.000000000","size":75,"flags":130,"ts_in_delta":166186,"sequence":308109,"levels":[{"bid_px":"250.030000000","ask_px":"250.720000000","bid_sz":50,"ask_sz":100,"bid_ct":1,"ask_ct":1},{"bid_px":"250.000000000","ask_px":"250.760000000","bid_sz":1,"ask_sz":50,"bid_ct":1,"ask_ct":1},{"bid_px":"249.930000000","ask_px":"252.400000000","bid_sz":10,"ask_sz":1000,"bid_ct":1,"ask_ct":1},{"bid_px":"249.800000000","ask_px":"253.650000000","bid_sz":199,"ask_sz":400,"bid_ct":1,"ask_ct":1},{"bid_px":"249.770000000","ask_px":"255.000000000","bid_sz":50,"ask_sz":85,"bid_ct":1,"ask_ct":2},{"bid_px":"249.600000000","ask_px":"260.000000000","bid_sz":1000,"ask_sz":48,"bid_ct":1,"ask_ct":1},{"bid_px":"249.500000000","ask_px":"262.660000000","bid_sz":1000,"ask_sz":56,"bid_ct":1,"ask_ct":1},{"bid_px":"248.600000000","ask_px":"264.940000000","bid_sz":1000,"ask_sz":7,"bid_ct":1,"ask_ct":1},{"bid_px":"247.150000000","ask_px":"265.000000000","bid_sz":400,"ask_sz":1,"bid_ct":1,"ask_ct":1},{"bid_px":"247.000000000","ask_px":"267.800000000","bid_sz":12,"ask_sz":30,"bid_ct":1,"ask_ct":1}],"symbol":"TSLA"}
{"ts_recv":"2024-11-01T08:00:09.418377932Z","hd":{"ts_event":"2024-11-01T08:00:09.418212103Z","rtype":10,"publisher_id":2,"instrument_id":16244},"action":"C","side":"A","depth":1,"price":"250.760000000","size":50,"flags":130,"ts_in_delta":165829,"sequence":308333,"levels":[{"bid_px":"250.030000000","ask_px":"250.720000000","bid_sz":50,"ask_sz":100,"bid_ct":1,"ask_ct":1},{"bid_px":"250.000000000","ask_px":"252.400000000","bid_sz":1,"ask_sz":1000,"bid_ct":1,"ask_ct":1},{"bid_px":"249.930000000","ask_px":"253.650000000","bid_sz":10,"ask_sz":400,"bid_ct":1,"ask_ct":1},{"bid_px":"249.800000000","ask_px":"255.000000000","bid_sz":199,"ask_sz":85,"bid_ct":1,"ask_ct":2},{"bid_px":"249.770000000","ask_px":"260.000000000","bid_sz":50,"ask_sz":48,"bid_ct":1,"ask_ct":1},{"bid_px":"249.600000000","ask_px":"262.660000000","bid_sz":1000,"ask_sz":56,"bid_ct":1,"ask_ct":1},{"bid_px":"249.500000000","ask_px":"264.940000000","bid_sz":1000,"ask_sz":7,"bid_ct":1,"ask_ct":1},{"bid_px":"248.600000000","ask_px":"265.000000000","bid_sz":1000,"ask_sz":1,"bid_ct":1,"ask_ct":1},{"bid_px":"247.150000000","ask_px":"267.800000000","bid_sz":400,"ask_sz":30,"bid_ct":1,"ask_ct":1},{"bid_px":"247.000000000","ask_px":"268.670000000","bid_sz":12,"ask_sz":100,"bid_ct":1,"ask_ct":1}],"symbol":"TSLA"}
{"ts_recv":"2024-11-01T08:00:09.418389580Z","hd":{"ts_event":"2024-11-01T08:00:09.418223858Z","rtype":10,"publisher_id":2,"instrument_id":16244},"action":"A","side":"A","depth":1,"price":"250.850000000","size":50,"flags":130,"ts_in_delta":165722,"sequence":308334,"levels":[{"bid_px":"250.030000000","ask_px":"250.720000000","bid_sz":50,"ask_sz":100,"bid_ct":1,"ask_ct":1},{"bid_px":"250.000000000","ask_px":"250.850000000","bid_sz":1,"ask_sz":50,"bid_ct":1,"ask_ct":1},{"bid_px":"249.930000000","ask_px":"252.400000000","bid_sz":10,"ask_sz":1000,"bid_ct":1,"ask_ct":1},{"bid_px":"249.800000000","ask_px":"253.650000000","bid_sz":199,"ask_sz":400,"bid_ct":1,"ask_ct":1},{"bid_px":"249.770000000","ask_px":"255.000000000","bid_sz":50,"ask_sz":85,"bid_ct":1,"ask_ct":2},{"bid_px":"249.600000000","ask_px":"260.000000000","bid_sz":1000,"ask_sz":48,"bid_ct":1,"ask_ct":1},{"bid_px":"249.500000000","ask_px":"262.660000000","bid_sz":1000,"ask_sz":56,"bid_ct":1,"ask_ct":1},{"bid_px":"248.600000000","ask_px":"264.940000000","bid_sz":1000,"ask_sz":7,"bid_ct":1,"ask_ct":1},{"bid_px":"247.150000000","ask_px":"265.000000000","bid_sz":400,"ask_sz":1,"bid_ct":1,"ask_ct":1},{"bid_px":"247.000000000","ask_px":"267.800000000","bid_sz":12,"ask_sz":30,"bid_ct":1,"ask_ct":1}],"symbol":"TSLA"}
{"ts_recv":"2024-11-01T08:00:09.418425546Z","hd":{"ts_event":"2024-11-01T08:00:09.418259940Z","rtype":10,"publisher_id":2,"instrument_id":16244},"action":"C","side":"A","depth":1,"price":"250.850000000","size":50,"flags":130,"ts_in_delta":165606,"sequence":308335,"levels":[{"bid_px":"250.030000000","ask_px":"250.720000000","bid_sz":50,"ask_sz":100,"bid_ct":1,"ask_ct":1},{"bid_px":"250.000000000","ask_px":"252.400000000","bid_sz":1,"ask_sz":1000,"bid_ct":1,"ask_ct":1},{"bid_px":"249.930000000","ask_px":"253.650000000","bid_sz":10,"ask_sz":400,"bid_ct":1,"ask_ct":1},{"bid_px":"249.800000000","ask_px":"255.000000000","bid_sz":199,"ask_sz":85,"bid_ct":1,"ask_ct":2},{"bid_px":"249.770000000","ask_px":"260.000000000","bid_sz":50,"ask_sz":48,"bid_ct":1,"ask_ct":1},{"bid_px":"249.600000000","ask_px":"262.660000000","bid_sz":1000,"ask_sz":56,"bid_ct":1,"ask_ct":1},{"bid_px":"249.500000000","ask_px":"264.940000000","bid_sz":1000,"ask_sz":7,"bid_ct":1,"ask_ct":1},{"bid_px":"248.600000000","ask_px":"265.000000000","bid_sz":1000,"ask_sz":1,"bid_ct":1,"ask_ct":1},{"bid_px":"247.150000000","ask_px":"267.800000000","bid_sz":400,"ask_sz":30,"bid_ct":1,"ask_ct":1},{"bid_px":"247.000000000","ask_px":"268.670000000","bid_sz":12,"ask_sz":100,"bid_ct":1,"ask_ct":1}],"symbol":"TSLA"}
{"ts_recv":"2024-11-01T08:00:09.418520594Z","hd":{"ts_event":"2024-11-01T08:00:09.418354592Z","rtype":10,"publisher_id":2,"instrument_id":16244},"action":"A","side":"A","depth":1,"price":"251.090000000","size":50,"flags":130,"ts_in_delta":166002,"sequence":308336,"levels":[{"bid_px":"250.030000000","ask_px":"250.720000000","bid_sz":50,"ask_sz":100,"bid_ct":1,"ask_ct":1},{"bid_px":"250.000000000","ask_px":"251.090000000","bid_sz":1,"ask_sz":50,"bid_ct":1,"ask_ct":1},{"bid_px":"249.930000000","ask_px":"252.400000000","bid_sz":10,"ask_sz":1000,"bid_ct":1,"ask_ct":1},{"bid_px":"249.800000000","ask_px":"253.650000000","bid_sz":199,"ask_sz":400,"bid_ct":1,"ask_ct":1},{"bid_px":"249.770000000","ask_px":"255.000000000","bid_sz":50,"ask_sz":85,"bid_ct":1,"ask_ct":2},{"bid_px":"249.600000000","ask_px":"260.000000000","bid_sz":1000,"ask_sz":48,"bid_ct":1,"ask_ct":1},{"bid_px":"249.500000000","ask_px":"262.660000000","bid_sz":1000,"ask_sz":56,"bid_ct":1,"ask_ct":1},{"bid_px":"248.600000000","ask_px":"264.940000000","bid_sz":1000,"ask_sz":7,"bid_ct":1,"ask_ct":1},{"bid_px":"247.150000000","ask_px":"265.000000000","bid_sz":400,"ask_sz":1,"bid_ct":1,"ask_ct":1},{"bid_px":"247.000000000","ask_px":"267.800000000","bid_sz":12,"ask_sz":30,"bid_ct":1,"ask_ct":1}],"symbol":"TSLA"}
{"ts_recv":"2024-11-01T08:00:09.418532243Z","hd":{"ts_event":"2024-11-01T08:00:09.418366536Z","rtype":10,"publisher_id":2,"instrument_id":16244},"action":"C","side":"B","depth":0,"price":"250.030000000","size":50,"flags":130,"ts_in_delta":165707,"sequence":308337,"levels":[{"bid_px":"250.000000000","ask_px":"250.720000000","bid_sz":1,"ask_sz":100,"bid_ct":1,"ask_ct":1},{"bid_px":"249.930000000","ask_px":"251.090000000","bid_sz":10,"ask_sz":50,"bid_ct":1,"ask_ct":1},{"bid_px":"249.800000000","ask_px":"252.400000000","bid_sz":199,"ask_sz":1000,"bid_ct":1,"ask_ct":1},{"bid_px":"249.770000000","ask_px":"253.650000000","bid_sz":50,"ask_sz":400,"bid_ct":1,"ask_ct":1},{"bid_px":"249.600000000","ask_px":"255.000000000","bid_sz":1000,"ask_sz":85,"bid_ct":1,"ask_ct":2},{"bid_px":"249.500000000","ask_px":"260.000000000","bid_sz":1000,"ask_sz":48,"bid_ct":1,"ask_ct":1},{"bid_px":"248.600000000","ask_px":"262.660000000","bid_sz":1000,"ask_sz":56,"bid_ct":1,"ask_ct":1},{"bid_px":"247.150000000","ask_px":"264.940000000","bid_sz":400,"ask_sz":7,"bid_ct":1,"ask_ct":1},{"bid_px":"247.000000000","ask_px":"265.000000000","bid_sz":12,"ask_sz":1,"bid_ct":1,"ask_ct":1},{"bid_px":"246.000000000","ask_px":"267.800000000","bid_sz":4,"ask_sz":30,"bid_ct":1,"ask_ct":1}],"symbol":"TSLA"}
{"ts_recv":"2024-11-01T08:00:09.418543180Z","hd":{"ts_event":"2024-11-01T08:00:09.418377438Z","rtype":10,"publisher_id":2,"instrument_id":16244},"action":"A","side":"B","depth":1,"price":"249.980000000","size":50,"flags":130,"ts_in_delta":165742,"sequence":308338,"levels":[{"bid_px":"250.000000000","ask_px":"250.720000000","bid_sz":1,"ask_sz":100,"bid_ct":1,"ask_ct":1},{"bid_px":"249.980000000","ask_px":"251.090000000","bid_sz":50,"ask_sz":50,"bid_ct":1,"ask_ct":1},{"bid_px":"249.930000000","ask_px":"252.400000000","bid_sz":10,"ask_sz":1000,"bid_ct":1,"ask_ct":1},{"bid_px":"249.800000000","ask_px":"253.650000000","bid_sz":199,"ask_sz":400,"bid_ct":1,"ask_ct":1},{"bid_px":"249.770000000","ask_px":"255.000000000","bid_sz":50,"ask_sz":85,"bid_ct":1,"ask_ct":2},{"bid_px":"249.600000000","ask_px":"260.000000000","bid_sz":1000,"ask_sz":48,"bid_ct":1,"ask_ct":1},{"bid_px":"249.500000000","ask_px":"262.660000000","bid_sz":1000,"ask_sz":56,"bid_ct":1,"ask_ct":1},{"bid_px":"248.600000000","ask_px":"264.940000000","bid_sz":1000,"ask_sz":7,"bid_ct":1,"ask_ct":1},{"bid_px":"247.150000000","ask_px":"265.000000000","bid_sz":400,"ask_sz":1,"bid_ct":1,"ask_ct":1},{"bid_px":"247.000000000","ask_px":"267.800000000","bid_sz":12,"ask_sz":30,"bid_ct":1,"ask_ct":1}],"symbol":"TSLA"}
{"ts_recv":"2024-11-01T08:00:09.418593088Z","hd":{"ts_event":"2024-11-01T08:00:09.418426750Z","rtype":10,"publisher_id":2,"instrument_id":16244},"action":"C","side":"B","depth":1,"price":"249.980000000","size":50,"flags":130,"ts_in_delta":166338,"sequence":308339,"levels":[{"bid_px":"250.000000000","ask_px":"250.720000000","bid_sz":1,"ask_sz":100,"bid_ct":1,"ask_ct":1},{"bid_px":"249.930000000","ask_px":"251.090000000","bid_sz":10,"ask_sz":50,"bid_ct":1,"ask_ct":1},{"bid_px":"249.800000000","ask_px":"252.400000000","bid_sz":199,"ask_sz":1000,"bid_ct":1,"ask_ct":1},{"bid_px":"249.770000000","ask_px":"253.650000000","bid_sz":50,"ask_sz":400,"bid_ct":1,"ask_ct":1},{"bid_px":"249.600000000","ask_px":"255.000000000","bid_sz":1000,"ask_sz":85,"bid_ct":1,"ask_ct":2},{"bid_px":"249.500000000","ask_px":"260.000000000","bid_sz":1000,"ask_sz":48,"bid_ct":1,"ask_ct":1},{"bid_px":"248.600000000","ask_px":"262.660000000","bid_sz":1000,"ask_sz":56,"bid_ct":1,"ask_ct":1},{"bid_px":"247.150000000","ask_px":"264.940000000","bid_sz":400,"ask_sz":7,"bid_ct":1,"ask_ct":1},{"bid_px":"247.000000000","ask_px":"265.000000000","bid_sz":12,"ask_sz":1,"bid_ct":1,"ask_ct":1},{"bid_px":"246.000000000","ask_px":"267.800000000","bid_sz":4,"ask_sz":30,"bid_ct":1,"ask_ct":1}],"symbol":"TSLA"}
{"ts_recv":"2024-11-01T08:00:09.418640702Z","hd":{"ts_event":"2024-11-01T08:00:09.418474852Z","rtype":10,"publisher_id":2,"instrument_id":16244},"action":"A","side":"B","depth":2,"price":"249.920000000","size":50,"flags":130,"ts_in_delta":165850,"sequence":308340,"levels":[{"bid_px":"250.000000000","ask_px":"250.720000000","bid_sz":1,"ask_sz":100,"bid_ct":1,"ask_ct":1},{"bid_px":"249.930000000","ask_px":"251.090000000","bid_sz":10,"ask_sz":50,"bid_ct":1,"ask_ct":1},{"bid_px":"249.920000000","ask_px":"252.400000000","bid_sz":50,"ask_sz":1000,"bid_ct":1,"ask_ct":1},{"bid_px":"249.800000000","ask_px":"253.650000000","bid_sz":199,"ask_sz":400,"bid_ct":1,"ask_ct":1},{"bid_px":"249.770000000","ask_px":"255.000000000","bid_sz":50,"ask_sz":85,"bid_ct":1,"ask_ct":2},{"bid_px":"249.600000000","ask_px":"260.000000000","bid_sz":1000,"ask_sz":48,"bid_ct":1,"ask_ct":1},{"bid_px":"249.500000000","ask_px":"262.660000000","bid_sz":1000,"ask_sz":56,"bid_ct":1,"ask_ct":1},{"bid_px":"248.600000000","ask_px":"264.940000000","bid_sz":1000,"ask_sz":7,"bid_ct":1,"ask_ct":1},{"bid_px":"247.150000000","ask_px":"265.000000000","bid_sz":400,"ask_sz":1,"bid_ct":1,"ask_ct":1},{"bid_px":"247.000000000","ask_px":"267.800000000","bid_sz":12,"ask_sz":30,"bid_ct":1,"ask_ct":1}],"symbol":"TSLA"}
{"ts_recv":"2024-11-01T08:00:09.696356146Z","hd":{"ts_event":"2024-11-01T08:00:09.696189765Z","rtype":10,"publisher_id":2,"instrument_id":16244},"action":"A","side":"B","depth":1,"price":"249.970000000","size":50,"flags":130,"ts_in_delta":166381,"sequence":309221,"levels":[{"bid_px":"250.000000000","ask_px":"250.720000000","bid_sz":1,"ask_sz":100,"bid_ct":1,"ask_ct":1},{"bid_px":"249.970000000","ask_px":"251.090000000","bid_sz":50,"ask_sz":50,"bid_ct":1,"ask_ct":1},{"bid_px":"249.930000000","ask_px":"252.400000000","bid_sz":10,"ask_sz":1000,"bid_ct":1,"ask_ct":1},{"bid_px":"249.800000000","ask_px":"253.650000000","bid_sz":199,"ask_sz":400,"bid_ct":1,"ask_ct":1},{"bid_px":"249.770000000","ask_px":"255.000000000","bid_sz":50,"ask_sz":85,"bid_ct":1,"ask_ct":2},{"bid_px":"249.600000000","ask_px":"260.000000000","bid_sz":1000,"ask_sz":48,"bid_ct":1,"ask_ct":1},{"bid_px":"249.500000000","ask_px":"262.660000000","bid_sz":1000,"ask_sz":56,"bid_ct":1,"ask_ct":1},{"bid_px":"248.600000000","ask_px":"264.940000000","bid_sz":1000,"ask_sz":7,"bid_ct":1,"ask_ct":1},{"bid_px":"247.150000000","ask_px":"265.000000000","bid_sz":400,"ask_sz":1,"bid_ct":1,"ask_ct":1},{"bid_px":"247.000000000","ask_px":"267.800000000","bid_sz":12,"ask_sz":30,"bid_ct":1,"ask_ct":1}],"symbol":"TSLA"}
{"ts_recv":"2024-11-01T08:00:09.784828619Z","hd":{"ts_event":"2024-11-01T08:00:09.784663053Z","rtype":10,"publisher_id":2,"instrument_id":16244},"action":"C","side":"A","depth":0,"price":"250.720000000","size":100,"flags":130,"ts_in_delta":165566,"sequence":309442,"levels":[{"bid_px":"250.000000000","ask_px":"251.090000000","bid_sz":1,"ask_sz":50,"bid_ct":1,"ask_ct":1},{"bid_px":"249.970000000","ask_px":"252.400000000","bid_sz":50,"ask_sz":1000,"bid_ct":1,"ask_ct":1},{"bid_px":"249.930000000","ask_px":"253.650000000","bid_sz":10,"ask_sz":400,"bid_ct":1,"ask_ct":1},{"bid_px":"249.800000000","ask_px":"255.000000000","bid_sz":199,"ask_sz":85,"bid_ct":1,"ask_ct":2},{"bid_px":"249.770000000","ask_px":"260.000000000","bid_sz":50,"ask_sz":48,"bid_ct":1,"ask_ct":1},{"bid_px":"249.600000000","ask_px":"262.660000000","bid_sz":1000,"ask_sz":56,"bid_ct":1,"ask_ct":1},{"bid_px":"249.500000000","ask_px":"264.940000000","bid_sz":1000,"ask_sz":7,"bid_ct":1,"ask_ct":1},{"bid_px":"248.600000000","ask_px":"265.000000000","bid_sz":1000,"ask_sz":1,"bid_ct":1,"ask_ct":1},{"bid_px":"247.150000000","ask_px":"267.800000000","bid_sz":400,"ask_sz":30,"bid_ct":1,"ask_ct":1},{"bid_px":"247.000000000","ask_px":"268.670000000","bid_sz":12,"ask_sz":100,"bid_ct":1,"ask_ct":1}],"symbol":"TSLA"}
{"ts_recv":"2024-11-01T08:00:09.784842070Z","hd":{"ts_event":"2024-11-01T08:00:09.784676131Z","rtype":10,"publisher_id":2,"instrument_id":16244},"action":"A","side":"A","depth":0,"price":"250.740000000","size":100,"flags":130,"ts_in_delta":165939,"sequence":309443,"levels":[{"bid_px":"250.000000000","ask_px":"250.740000000","bid_sz":1,"ask_sz":100,"bid_ct":1,"ask_ct":1},{"bid_px":"249.970000000","ask_px":"251.090000000","bid_sz":50,"ask_sz":50,"bid_ct":1,"ask_ct":1},{"bid_px":"249.930000000","ask_px":"252.400000000","bid_sz":10,"ask_sz":1000,"bid_ct":1,"ask_ct":1},{"bid_px":"249.800000000","ask_px":"253.650000000","bid_sz":199,"ask_sz":400,"bid_ct":1,"ask_ct":1},{"bid_px":"249.770000000","ask_px":"255.000000000","bid_sz":50,"ask_sz":85,"bid_ct":1,"ask_ct":2},{"bid_px":"249.600000000","ask_px":"260.000000000","bid_sz":1000,"ask_sz":48,"bid_ct":1,"ask_ct":1},{"bid_px":"249.500000000","ask_px":"262.660000000","bid_sz":1000,"ask_sz":56,"bid_ct":1,"ask_ct":1},{"bid_px":"248.600000000","ask_px":"264.940000000","bid_sz":1000,"ask_sz":7,"bid_ct":1,"ask_ct":1},{"bid_px":"247.150000000","ask_px":"265.000000000","bid_sz":400,"ask_sz":1,"bid_ct":1,"ask_ct":1},{"bid_px":"247.000000000","ask_px":"267.800000000","bid_sz":12,"ask_sz":30,"bid_ct":1,"ask_ct":1}],"symbol":"TSLA"}
{"ts_recv":"2024-11-01T08:00:09.784885483Z","hd":{"ts_event":"2024-11-01T08:00:09.784719694Z","rtype":10,"publisher_id":2,"instrument_id":16244},"action":"C","side":"A","depth":0,"price":"250.740000000","size":100,"flags":130,"ts_in_delta":165789,"sequence":309444,"levels":[{"bid_px":"250.000000000","ask_px":"251.090000000","bid_sz":1,"ask_sz":50,"bid_ct":1,"ask_ct":1},{"bid_px":"249.970000000","ask_px":"252.400000000","bid_sz":50,"ask_sz":1000,"bid_ct":1,"ask_ct":1},{"bid_px":"249.930000000","ask_px":"253.650000000","bid_sz":10,"ask_sz":400,"bid_ct":1,"ask_ct":1},{"bid_px":"249.800000000","ask_px":"255.000000000","bid_sz":199,"ask_sz":85,"bid_ct":1,"ask_ct":2},{"bid_px":"249.770000000","ask_px":"260.000000000","bid_sz":50,"ask_sz":48,"bid_ct":1,"ask_ct":1},{"bid_px":"249.600000000","ask_px":"262.660000000","bid_sz":1000,"ask_sz":56,"bid_ct":1,"ask_ct":1},{"bid_px":"249.500000000","ask_px":"264.940000000","bid_sz":1000,"ask_sz":7,"bid_ct":1,"ask_ct":1},{"bid_px":"248.600000000","ask_px":"265.000000000","bid_sz":1000,"ask_sz":1,"bid_ct":1,"ask_ct":1},{"bid_px":"247.150000000","ask_px":"267.800000000","bid_sz":400,"ask_sz":30,"bid_ct":1,"ask_ct":1},{"bid_px":"247.000000000","ask_px":"268.670000000","bid_sz":12,"ask_sz":100,"bid_ct":1,"ask_ct":1}],"symbol":"TSLA"}
{"ts_recv":"2024-11-01T08:00:09.784946250Z","hd":{"ts_event":"2024-11-01T08:00:09.784779245Z","rtype":10,"publisher_id":2,"instrument_id":16244},"action":"A","side":"A","depth":0,"price":"250.800000000","size":100,"flags":130,"ts_in_delta":167005,"sequence":309445,"levels":[{"bid_px":"250.000000000","ask_px":"250.800000000","bid_sz":1,"ask_sz":100,"bid_ct":1,"ask_ct":1},{"bid_px":"249.970000000","ask_px":"251.090000000","bid_sz":50,"ask_sz":50,"bid_ct":1,"ask_ct":1},{"bid_px":"249.930000000","ask_px":"252.400000000","bid_sz":10,"ask_sz":1000,"bid_ct":1,"ask_ct":1},{"bid_px":"249.800000000","ask_px":"253.650000000","bid_sz":199,"ask_sz":400,"bid_ct":1,"ask_ct":1},{"bid_px":"249.770000000","ask_px":"255.000000000","bid_sz":50,"ask_sz":85,"bid_ct":1,"ask_ct":2},{"bid_px":"249.600000000","ask_px":"260.000000000","bid_sz":1000,"ask_sz":48,"bid_ct":1,"ask_ct":1},{"bid_px":"249.500000000","ask_px":"262.660000000","bid_sz":1000,"ask_sz":56,"bid_ct":1,"ask_ct":1},{"bid_px":"248.600000000","ask_px":"264.940000000","bid_sz":1000,"ask_sz":7,"bid_ct":1,"ask_ct":1},{"bid_px":"247.150000000","ask_px":"265.000000000","bid_sz":400,"ask_sz":1,"bid_ct":1,"ask_ct":1},{"bid_px":"247.000000000","ask_px":"267.800000000","bid_sz":12,"ask_sz":30,"bid_ct":1,"ask_ct":1}],"symbol":"TSLA"}
{"ts_recv":"2024-11-01T08:00:09.785109969Z","hd":{"ts_event":"2024-11-01T08:00:09.784944294Z","rtype":10,"publisher_id":2,"instrument_id":16244},"action":"C","side":"A","depth":0,"price":"250.800000000","size":100,"flags":130,"ts_in_delta":165675,"sequence":309446,"levels":[{"bid_px":"250.000000000","ask_px":"251.090000000","bid_sz":1,"ask_sz":50,"bid_ct":1,"ask_ct":1},{"bid_px":"249.970000000","ask_px":"252.400000000","bid_sz":50,"ask_sz":1000,"bid_ct":1,"ask_ct":1},{"bid_px":"249.930000000","ask_px":"253.650000000","bid_sz":10,"ask_sz":400,"bid_ct":1,"ask_ct":1},{"bid_px":"249.800000000","ask_px":"255.000000000","bid_sz":199,"ask_sz":85,"bid_ct":1,"ask_ct":2},{"bid_px":"249.770000000","ask_px":"260.000000000","bid_sz":50,"ask_sz":48,"bid_ct":1,"ask_ct":1},{"bid_px":"249.600000000","ask_px":"262.660000000","bid_sz":1000,"ask_sz":56,"bid_ct":1,"ask_ct":1},{"bid_px":"249.500000000","ask_px":"264.940000000","bid_sz":1000,"ask_sz":7,"bid_ct":1,"ask_ct":1},{"bid_px":"248.600000000","ask_px":"265.000000000","bid_sz":1000,"ask_sz":1,"bid_ct":1,"ask_ct":1},{"bid_px":"247.150000000","ask_px":"267.800000000","bid_sz":400,"ask_sz":30,"bid_ct":1,"ask_ct":1},{"bid_px":"247.000000000","ask_px":"268.670000000","bid_sz":12,"ask_sz":100,"bid_ct":1,"ask_ct":1}],"symbol":"TSLA"}
{"ts_recv":"2024-11-01T08:00:09.785121862Z","hd":{"ts_event":"2024-11-01T08:00:09.784955737Z","rtype":10,"publisher_id":2,"instrument_id":16244},"action":"A","side":"A","depth":0,"price":"251.010000000","size":100,"flags":130,"ts_in_delta":166125,"sequence":309447,"levels":[{"bid_px":"250.000000000","ask_px":"251.010000000","bid_sz":1,"ask_sz":100,"bid_ct":1,"ask_ct":1},{"bid_px":"249.970000000","ask_px":"251.090000000","bid_sz":50,"ask_sz":50,"bid_ct":1,"ask_ct":1},{"bid_px":"249.930000000","ask_px":"252.400000000","bid_sz":10,"ask_sz":1000,"bid_ct":1,"ask_ct":1},{"bid_px":"249.800000000","ask_px":"253.650000000","bid_sz":199,"ask_sz":400,"bid_ct":1,"ask_ct":1},{"bid_px":"249.770000000","ask_px":"255.000000000","bid_sz":50,"ask_sz":85,"bid_ct":1,"ask_ct":2},{"bid_px":"249.600000000","ask_px":"260.000000000","bid_sz":1000,"ask_sz":48,"bid_ct":1,"ask_ct":1},{"bid_px":"249.500000000","ask_px":"262.660000000","bid_sz":1000,"ask_sz":56,"bid_ct":1,"ask_ct":1},{"bid_px":"248.600000000","ask_px":"264.940000000","bid_sz":1000,"ask_sz":7,"bid_ct":1,"ask_ct":1},{"bid_px":"247.150000000","ask_px":"265.000000000","bid_sz":400,"ask_sz":1,"bid_ct":1,"ask_ct":1},{"bid_px":"247.000000000","ask_px":"267.800000000","bid_sz":12,"ask_sz":30,"bid_ct":1,"ask_ct":1}],"symbol":"TSLA"}
{"ts_recv":"2024-11-01T08:00:09.786503869Z","hd":{"ts_event":"2024-11-01T08:00:09.786337768Z","rtype":10,"publisher_id":2,"instrument_id":16244},"action":"C","side":"A","depth":0,"price":"251.010000000","size":100,"flags":130,"ts_in_delta":166101,"sequence":309452,"levels":[{"bid_px":"250.000000000","ask_px":"251.090000000","bid_sz":1,"ask_sz":50,"bid_ct":1,"ask_ct":1},{"bid_px":"249.970000000","ask_px":"252.400000000","bid_sz":50,"ask_sz":1000,"bid_ct":1,"ask_ct":1},{"bid_px":"249.930000000","ask_px":"253.650000000","bid_sz":10,"ask_sz":400,"bid_ct":1,"ask_ct":1},{"bid_px":"249.800000000","ask_px":"255.000000000","bid_sz":199,"ask_sz":85,"bid_ct":1,"ask_ct":2},{"bid_px":"249.770000000","ask_px":"260.000000000","bid_sz":50,"ask_sz":48,"bid_ct":1,"ask_ct":1},{"bid_px":"249.600000000","ask_px":"262.660000000","bid_sz":1000,"ask_sz":56,"bid_ct":1,"ask_ct":1},{"bid_px":"249.500000000","ask_px":"264.940000000","bid_sz":1000,"ask_sz":7,"bid_ct":1,"ask_ct":1},{"bid_px":"248.600000000","ask_px":"265.000000000","bid_sz":1000,"ask_sz":1,"bid_ct":1,"ask_ct":1},{"bid_px":"247.150000000","ask_px":"267.800000000","bid_sz":400,"ask_sz":30,"bid_ct":1,"ask_ct":1},{"bid_px":"247.000000000","ask_px":"268.670000000","bid_sz":12,"ask_sz":100,"bid_ct":1,"ask_ct":1}],"symbol":"TSLA"}
{"ts_recv":"2024-11-01T08:00:09.786515173Z","hd":{"ts_event":"2024-11-01T08:00:09.786349334Z","rtype":10,"publisher_id":2,"instrument_id":16244},"action":"A","side":"A","depth":0,"price":"251.030000000","size":100,"flags":130,"ts_in_delta":165839,"sequence":309453,"levels":[{"bid_px":"250.000000000","ask_px":"251.030000000","bid_sz":1,"ask_sz":100,"bid_ct":1,"ask_ct":1},{"bid_px":"249.970000000","ask_px":"251.090000000","bid_sz":50,"ask_sz":50,"bid_ct":1,"ask_ct":1},{"bid_px":"249.930000000","ask_px":"252.400000000","bid_sz":10,"ask_sz":1000,"bid_ct":1,"ask_ct":1},{"bid_px":"249.800000000","ask_px":"253.650000000","bid_sz":199,"ask_sz":400,"bid_ct":1,"ask_ct":1},{"bid_px":"249.770000000","ask_px":"255.000000000","bid_sz":50,"ask_sz":85,"bid_ct":1,"ask_ct":2},{"bid_px":"249.600000000","ask_px":"260.000000000","bid_sz":1000,"ask_sz":48,"bid_ct":1,"ask_ct":1},{"bid_px":"249.500000000","ask_px":"262.660000000","bid_sz":1000,"ask_sz":56,"bid_ct":1,"ask_ct":1},{"bid_px":"248.600000000","ask_px":"264.940000000","bid_sz":1000,"ask_sz":7,"bid_ct":1,"ask_ct":1},{"bid_px":"247.150000000","ask_px":"265.000000000","bid_sz":400,"ask_sz":1,"bid_ct":1,"ask_ct":1},{"bid_px":"247.000000000","ask_px":"267.800000000","bid_sz":12,"ask_sz":30,"bid_ct":1,"ask_ct":1}],"symbol":"TSLA"}
{"ts_recv":"2024-11-01T08:00:09.786563838Z","hd":{"ts_event":"2024-11-01T08:00:09.786398263Z","rtype":10,"publisher_id":2,"instrument_id":16244},"action":"C","side":"A","depth":0,"price":"251.030000000","size":100,"flags":130,"ts_in_delta":165575,"sequence":309455,"levels":[{"bid_px":"250.000000000","ask_px":"251.090000000","bid_sz":1,"ask_sz":50,"bid_ct":1,"ask_ct":1},{"bid_px":"249.970000000","ask_px":"252.400000000","bid_sz":50,"ask_sz":1000,"bid_ct":1,"ask_ct":1},{"bid_px":"249.930000000","ask_px":"253.650000000","bid_sz":10,"ask_sz":400,"bid_ct":1,"ask_ct":1},{"bid_px":"249.800000000","ask_px":"255.000000000","bid_sz":199,"ask_sz":85,"bid_ct":1,"ask_ct":2},{"bid_px":"249.770000000","ask_px":"260.000000000","bid_sz":50,"ask_sz":48,"bid_ct":1,"ask_ct":1},{"bid_px":"249.600000000","ask_px":"262.660000000","bid_sz":1000,"ask_sz":56,"bid_ct":1,"ask_ct":1},{"bid_px":"249.500000000","ask_px":"264.940000000","bid_sz":1000,"ask_sz":7,"bid_ct":1,"ask_ct":1},{"bid_px":"248.600000000","ask_px":"265.000000000","bid_sz":1000,"ask_sz":1,"bid_ct":1,"ask_ct":1},{"bid_px":"247.150000000","ask_px":"267.800000000","bid_sz":400,"ask_sz":30,"bid_ct":1,"ask_ct":1},{"bid_px":"247.000000000","ask_px":"268.670000000","bid_sz":12,"ask_sz":100,"bid_ct":1,"ask_ct":1}],"symbol":"TSLA"}
{"ts_recv":"2024-11-01T08:00:09.786625105Z","hd":{"ts_event":"2024-11-01T08:00:09.786459035Z","rtype":10,"publisher_id":2,"instrument_id":16244},"action":"A","side":"A","depth":0,"price":"251.050000000","size":100,"flags":130,"ts_in_delta":166070,"sequence":309456,"levels":[{"bid_px":"250.000000000","ask_px":"251.050000000","bid_sz":1,"ask_sz":100,"bid_ct":1,"ask_ct":1},{"bid_px":"249.970000000","ask_px":"251.090000000","bid_sz":50,"ask_sz":50,"bid_ct":1,"ask_ct":1},{"bid_px":"249.930000000","ask_px":"252.400000000","bid_sz":10,"ask_sz":1000,"bid_ct":1,"ask_ct":1},{"bid_px":"249.800000000","ask_px":"253.650000000","bid_sz":199,"ask_sz":400,"bid_ct":1,"ask_ct":1},{"bid_px":"249.770000000","ask_px":"255.000000000","bid_sz":50,"ask_sz":85,"bid_ct":1,"ask_ct":2},{"bid_px":"249.600000000","ask_px":"260.000000000","bid_sz":1000,"ask_sz":48,"bid_ct":1,"ask_ct":1},{"bid_px":"249.500000000","ask_px":"262.660000000","bid_sz":1000,"ask_sz":56,"bid_ct":1,"ask_ct":1},{"bid_px":"248.600000000","ask_px":"264.940000000","bid_sz":1000,"ask_sz":7,"bid_ct":1,"ask_ct":1},{"bid_px":"247.150000000","ask_px":"265.000000000","bid_sz":400,"ask_sz":1,"bid_ct":1,"ask_ct":1},{"bid_px":"247.000000000","ask_px":"267.800000000","bid_sz":12,"ask_sz":30,"bid_ct":1,"ask_ct":1}],"symbol":"TSLA"}
{"ts_recv":"2024-11-01T08:00:09.786809862Z","hd":{"ts_event":"2024-11-01T08:00:09.786643807Z","rtype":10,"publisher_id":2,"instrument_id":16244},"action":"C","side":"A","depth":0,"price":"251.050000000","size":100,"flags":130,"ts_in_delta":166055,"sequence":309457,"levels":[{"bid_px":"250.000000000","ask_px":"251.090000000","bid_sz":1,"ask_sz":50,"bid_ct":1,"ask_ct":1},{"bid_px":"249.970000000","ask_px":"252.400000000","bid_sz":50,"ask_sz":1000,"bid_ct":1,"ask_ct":1},{"bid_px":"249.930000000","ask_px":"253.650000000","bid_sz":10,"ask_sz":400,"bid_ct":1,"ask_ct":1},{"bid_px":"249.800000000","ask_px":"255.000000000","bid_sz":199,"ask_sz":85,"bid_ct":1,"ask_ct":2},{"bid_px":"249.770000000","ask_px":"260.000000000","bid_sz":50,"ask_sz":48,"bid_ct":1,"ask_ct":1},{"bid_px":"249.600000000","ask_px":"262.660000000","bid_sz":1000,"ask_sz":56,"bid_ct":1,"ask_ct":1},{"bid_px":"249.500000000","ask_px":"264.940000000","bid_sz":1000,"ask_sz":7,"bid_ct":1,"ask_ct":1},{"bid_px":"248.600000000","ask_px":"265.000000000","bid_sz":1000,"ask_sz":1,"bid_ct":1,"ask_ct":1},{"bid_px":"247.150000000","ask_px":"267.800000000","bid_sz":400,"ask_sz":30,"bid_ct":1,"ask_ct":1},{"bid_px":"247.000000000","ask_px":"268.670000000","bid_sz":12,"ask_sz":100,"bid_ct":1,"ask_ct":1}],"symbol":"TSLA"}
