{"ts_recv":"2024-11-01T08:00:09.786821100Z","hd":{"ts_event":"2024-11-01T08:00:09.786654970Z","rtype":10,"publisher_id":2,"instrument_id":16244},"action":"A","side":"A","depth":0,"price":"251.070000000","size":100,"flags":130,"ts_in_delta":166130,"sequence":309458,"levels":[{"bid_px":"250.000000000","ask_px":"251.070000000","bid_sz":1,"ask_sz":100,"bid_ct":1,"ask_ct":1},{"bid_px":"249.970000000","ask_px":"251.090000000","bid_sz":50,"ask_sz":50,"bid_ct":1,"ask_ct":1},{"bid_px":"249.930000000","ask_px":"252.400000000","bid_sz":10,"ask_sz":1000,"bid_ct":1,"ask_ct":1},{"bid_px":"249.800000000","ask_px":"253.650000000","bid_sz":199,"ask_sz":400,"bid_ct":1,"ask_ct":1},{"bid_px":"249.770000000","ask_px":"255.000000000","bid_sz":50,"ask_sz":85,"bid_ct":1,"ask_ct":2},{"bid_px":"249.600000000","ask_px":"260.000000000","bid_sz":1000,"ask_sz":48,"bid_ct":1,"ask_ct":1},{"bid_px":"249.500000000","ask_px":"262.660000000","bid_sz":1000,"ask_sz":56,"bid_ct":1,"ask_ct":1},{"bid_px":"248.600000000","ask_px":"264.940000000","bid_sz":1000,"ask_sz":7,"bid_ct":1,"ask_ct":1},{"bid_px":"247.150000000","ask_px":"265.000000000","bid_sz":400,"ask_sz":1,"bid_ct":1,"ask_ct":1},{"bid_px":"247.000000000","ask_px":"267.800000000","bid_sz":12,"ask_sz":30,"bid_ct":1,"ask_ct":1}],"symbol":"TSLA"}
{"ts_recv":"2024-11-01T08:00:09.788788085Z","hd":{"ts_event":"2024-11-01T08:00:09.788621861Z","rtype":10,"publisher_id":2,"instrument_id":16244},"action":"C","side":"B","depth":1,"price":"249.970000000","size":50,"flags":130,"ts_in_delta":166224,"sequence":309459,"levels":[{"bid_px":"250.000000000","ask_px":"251.070000000","bid_sz":1,"ask_sz":100,"bid_ct":1,"ask_ct":1},{"bid_px":"249.930000000","ask_px":"251.090000000","bid_sz":10,"ask_sz":50,"bid_ct":1,"ask_ct":1},{"bid_px":"249.800000000","ask_px":"252.400000000","bid_sz":199,"ask_sz":1000,"bid_ct":1,"ask_ct":1},{"bid_px":"249.770000000","ask_px":"253.650000000","bid_sz":50,"ask_sz":400,"bid_ct":1,"ask_ct":1},{"bid_px":"249.600000000","ask_px":"255.000000000","bid_sz":1000,"ask_sz":85,"bid_ct":1,"ask_ct":2},{"bid_px":"249.500000000","ask_px":"260.000000000","bid_sz":1000,"ask_sz":48,"bid_ct":1,"ask_ct":1},{"bid_px":"248.600000000","ask_px":"262.660000000","bid_sz":1000,"ask_sz":56,"bid_ct":1,"ask_ct":1},{"bid_px":"247.150000000","ask_px":"264.940000000","bid_sz":400,"ask_sz":7,"bid_ct":1,"ask_ct":1},{"bid_px":"247.000000000","ask_px":"265.000000000","bid_sz":12,"ask_sz":1,"bid_ct":1,"ask_ct":1},{"bid_px":"246.000000000","ask_px":"267.800000000","bid_sz":4,"ask_sz":30,"bid_ct":1,"ask_ct":1}],"symbol":"TSLA"}
{"ts_recv":"2024-11-01T08:00:09.789806388Z","hd":{"ts_event":"2024-11-01T08:00:09.789640391Z","rtype":10,"publisher_id":2,"instrument_id":16244},"action":"A","side":"A","depth":0,"price":"251.070000000","size":100,"flags":130,"ts_in_delta":165997,"sequence":309463,"levels":[{"bid_px":"250.000000000","ask_px":"251.070000000","bid_sz":1,"ask_sz":200,"bid_ct":1,"ask_ct":2},{"bid_px":"249.930000000","ask_px":"251.090000000","bid_sz":10,"ask_sz":50,"bid_ct":1,"ask_ct":1},{"bid_px":"249.800000000","ask_px":"252.400000000","bid_sz":199,"ask_sz":1000,"bid_ct":1,"ask_ct":1},{"bid_px":"249.770000000","ask_px":"253.650000000","bid_sz":50,"ask_sz":400,"bid_ct":1,"ask_ct":1},{"bid_px":"249.600000000","ask_px":"255.000000000","bid_sz":1000,"ask_sz":85,"bid_ct":1,"ask_ct":2},{"bid_px":"249.500000000","ask_px":"260.000000000","bid_sz":1000,"ask_sz":48,"bid_ct":1,"ask_ct":1},{"bid_px":"248.600000000","ask_px":"262.660000000","bid_sz":1000,"ask_sz":56,"bid_ct":1,"ask_ct":1},{"bid_px":"247.150000000","ask_px":"264.940000000","bid_sz":400,"ask_sz":7,"bid_ct":1,"ask_ct":1},{"bid_px":"247.000000000","ask_px":"265.000000000","bid_sz":12,"ask_sz":1,"bid_ct":1,"ask_ct":1},{"bid_px":"246.000000000","ask_px":"267.800000000","bid_sz":4,"ask_sz":30,"bid_ct":1,"ask_ct":1}],"symbol":"TSLA"}
{"ts_recv":"2024-11-01T08:00:09.801041263Z","hd":{"ts_event":"2024-11-01T08:00:09.800874905Z","rtype":10,"publisher_id":2,"instrument_id":16244},"action":"A","side":"B","depth":0,"price":"250.000000000","size":1,"flags":130,"ts_in_delta":166358,"sequence":309488,"levels":[{"bid_px":"250.000000000","ask_px":"251.070000000","bid_sz":2,"ask_sz":200,"bid_ct":2,"ask_ct":2},{"bid_px":"249.930000000","ask_px":"251.090000000","bid_sz":10,"ask_sz":50,"bid_ct":1,"ask_ct":1},{"bid_px":"249.800000000","ask_px":"252.400000000","bid_sz":199,"ask_sz":1000,"bid_ct":1,"ask_ct":1},{"bid_px":"249.770000000","ask_px":"253.650000000","bid_sz":50,"ask_sz":400,"bid_ct":1,"ask_ct":1},{"bid_px":"249.600000000","ask_px":"255.000000000","bid_sz":1000,"ask_sz":85,"bid_ct":1,"ask_ct":2},{"bid_px":"249.500000000","ask_px":"260.000000000","bid_sz":1000,"ask_sz":48,"bid_ct":1,"ask_ct":1},{"bid_px":"248.600000000","ask_px":"262.660000000","bid_sz":1000,"ask_sz":56,"bid_ct":1,"ask_ct":1},{"bid_px":"247.150000000","ask_px":"264.940000000","bid_sz":400,"ask_sz":7,"bid_ct":1,"ask_ct":1},{"bid_px":"247.000000000","ask_px":"265.000000000","bid_sz":12,"ask_sz":1,"bid_ct":1,"ask_ct":1},{"bid_px":"246.000000000","ask_px":"267.800000000","bid_sz":4,"ask_sz":30,"bid_ct":1,"ask_ct":1}],"symbol":"TSLA"}
{"ts_recv":"2024-11-01T08:00:09.844640477Z","hd":{"ts_event":"2024-11-01T08:00:09.844474368Z","rtype":10,"publisher_id":2,"instrument_id":16244},"action":"C","side":"A","depth":1,"price":"251.090000000","size":50,"flags":130,"ts_in_delta":166109,"sequence":309590,"levels":[{"bid_px":"250.000000000","ask_px":"251.070000000","bid_sz":2,"ask_sz":200,"bid_ct":2,"ask_ct":2},{"bid_px":"249.930000000","ask_px":"252.400000000","bid_sz":10,"ask_sz":1000,"bid_ct":1,"ask_ct":1},{"bid_px":"249.800000000","ask_px":"253.650000000","bid_sz":199,"ask_sz":400,"bid_ct":1,"ask_ct":1},{"bid_px":"249.770000000","ask_px":"255.000000000","bid_sz":50,"ask_sz":85,"bid_ct":1,"ask_ct":2},{"bid_px":"249.600000000","ask_px":"260.000000000","bid_sz":1000,"ask_sz":48,"bid_ct":1,"ask_ct":1},{"bid_px":"249.500000000","ask_px":"262.660000000","bid_sz":1000,"ask_sz":56,"bid_ct":1,"ask_ct":1},{"bid_px":"248.600000000","ask_px":"264.940000000","bid_sz":1000,"ask_sz":7,"bid_ct":1,"ask_ct":1},{"bid_px":"247.150000000","ask_px":"265.000000000","bid_sz":400,"ask_sz":1,"bid_ct":1,"ask_ct":1},{"bid_px":"247.000000000","ask_px":"267.800000000","bid_sz":12,"ask_sz":30,"bid_ct":1,"ask_ct":1},{"bid_px":"246.000000000","ask_px":"268.670000000","bid_sz":4,"ask_sz":100,"bid_ct":1,"ask_ct":1}],"symbol":"TSLA"}
{"ts_recv":"2024-11-01T08:00:09.844701754Z","hd":{"ts_event":"2024-11-01T08:00:09.844532194Z","rtype":10,"publisher_id":2,"instrument_id":16244},"action":"A","side":"B","depth":1,"price":"249.970000000","size":50,"flags":130,"ts_in_delta":169560,"sequence":309591,"levels":[{"bid_px":"250.000000000","ask_px":"251.070000000","bid_sz":2,"ask_sz":200,"bid_ct":2,"ask_ct":2},{"bid_px":"249.970000000","ask_px":"252.400000000","bid_sz":50,"ask_sz":1000,"bid_ct":1,"ask_ct":1},{"bid_px":"249.930000000","ask_px":"253.650000000","bid_sz":10,"ask_sz":400,"bid_ct":1,"ask_ct":1},{"bid_px":"249.800000000","ask_px":"255.000000000","bid_sz":199,"ask_sz":85,"bid_ct":1,"ask_ct":2},{"bid_px":"249.770000000","ask_px":"260.000000000","bid_sz":50,"ask_sz":48,"bid_ct":1,"ask_ct":1},{"bid_px":"249.600000000","ask_px":"262.660000000","bid_sz":1000,"ask_sz":56,"bid_ct":1,"ask_ct":1},{"bid_px":"249.500000000","ask_px":"264.940000000","bid_sz":1000,"ask_sz":7,"bid_ct":1,"ask_ct":1},{"bid_px":"248.600000000","ask_px":"265.000000000","bid_sz":1000,"ask_sz":1,"bid_ct":1,"ask_ct":1},{"bid_px":"247.150000000","ask_px":"267.800000000","bid_sz":400,"ask_sz":30,"bid_ct":1,"ask_ct":1},{"bid_px":"247.000000000","ask_px":"268.670000000","bid_sz":12,"ask_sz":100,"bid_ct":1,"ask_ct":1}],"symbol":"TSLA"}
{"ts_recv":"2024-11-01T08:00:09.844728634Z","hd":{"ts_event":"2024-11-01T08:00:09.844562361Z","rtype":10,"publisher_id":2,"instrument_id":16244},"action":"A","side":"A","depth":1,"price":"251.150000000","size":50,"flags":130,"ts_in_delta":166273,"sequence":309592,"levels":[{"bid_px":"250.000000000","ask_px":"251.070000000","bid_sz":2,"ask_sz":200,"bid_ct":2,"ask_ct":2},{"bid_px":"249.970000000","ask_px":"251.150000000","bid_sz":50,"ask_sz":50,"bid_ct":1,"ask_ct":1},{"bid_px":"249.930000000","ask_px":"252.400000000","bid_sz":10,"ask_sz":1000,"bid_ct":1,"ask_ct":1},{"bid_px":"249.800000000","ask_px":"253.650000000","bid_sz":199,"ask_sz":400,"bid_ct":1,"ask_ct":1},{"bid_px":"249.770000000","ask_px":"255.000000000","bid_sz":50,"ask_sz":85,"bid_ct":1,"ask_ct":2},{"bid_px":"249.600000000","ask_px":"260.000000000","bid_sz":1000,"ask_sz":48,"bid_ct":1,"ask_ct":1},{"bid_px":"249.500000000","ask_px":"262.660000000","bid_sz":1000,"ask_sz":56,"bid_ct":1,"ask_ct":1},{"bid_px":"248.600000000","ask_px":"264.940000000","bid_sz":1000,"ask_sz":7,"bid_ct":1,"ask_ct":1},{"bid_px":"247.150000000","ask_px":"265.000000000","bid_sz":400,"ask_sz":1,"bid_ct":1,"ask_ct":1},{"bid_px":"247.000000000","ask_px":"267.800000000","bid_sz":12,"ask_sz":30,"bid_ct":1,"ask_ct":1}],"symbol":"TSLA"}
{"ts_recv":"2024-11-01T08:00:09.848533907Z","hd":{"ts_event":"2024-11-01T08:00:09.848366265Z","rtype":10,"publisher_id":2,"instrument_id":16244},"action":"A","side":"A","depth":1,"price":"251.150000000","size":50,"flags":130,"ts_in_delta":167642,"sequence":309595,"levels":[{"bid_px":"250.000000000","ask_px":"251.070000000","bid_sz":2,"ask_sz":200,"bid_ct":2,"ask_ct":2},{"bid_px":"249.970000000","ask_px":"251.150000000","bid_sz":50,"ask_sz":100,"bid_ct":1,"ask_ct":2},{"bid_px":"249.930000000","ask_px":"252.400000000","bid_sz":10,"ask_sz":1000,"bid_ct":1,"ask_ct":1},{"bid_px":"249.800000000","ask_px":"253.650000000","bid_sz":199,"ask_sz":400,"bid_ct":1,"ask_ct":1},{"bid_px":"249.770000000","ask_px":"255.000000000","bid_sz":50,"ask_sz":85,"bid_ct":1,"ask_ct":2},{"bid_px":"249.600000000","ask_px":"260.000000000","bid_sz":1000,"ask_sz":48,"bid_ct":1,"ask_ct":1},{"bid_px":"249.500000000","ask_px":"262.660000000","bid_sz":1000,"ask_sz":56,"bid_ct":1,"ask_ct":1},{"bid_px":"248.600000000","ask_px":"264.940000000","bid_sz":1000,"ask_sz":7,"bid_ct":1,"ask_ct":1},{"bid_px":"247.150000000","ask_px":"265.000000000","bid_sz":400,"ask_sz":1,"bid_ct":1,"ask_ct":1},{"bid_px":"247.000000000","ask_px":"267.800000000","bid_sz":12,"ask_sz":30,"bid_ct":1,"ask_ct":1}],"symbol":"TSLA"}
{"ts_recv":"2024-11-01T08:00:09.848579974Z","hd":{"ts_event":"2024-11-01T08:00:09.848414050Z","rtype":10,"publisher_id":2,"instrument_id":16244},"action":"C","side":"B","depth":1,"price":"249.970000000","size":50,"flags":130,"ts_in_delta":165924,"sequence":309596,"levels":[{"bid_px":"250.000000000","ask_px":"251.070000000","bid_sz":2,"ask_sz":200,"bid_ct":2,"ask_ct":2},{"bid_px":"249.930000000","ask_px":"251.150000000","bid_sz":10,"ask_sz":100,"bid_ct":1,"ask_ct":2},{"bid_px":"249.800000000","ask_px":"252.400000000","bid_sz":199,"ask_sz":1000,"bid_ct":1,"ask_ct":1},{"bid_px":"249.770000000","ask_px":"253.650000000","bid_sz":50,"ask_sz":400,"bid_ct":1,"ask_ct":1},{"bid_px":"249.600000000","ask_px":"255.000000000","bid_sz":1000,"ask_sz":85,"bid_ct":1,"ask_ct":2},{"bid_px":"249.500000000","ask_px":"260.000000000","bid_sz":1000,"ask_sz":48,"bid_ct":1,"ask_ct":1},{"bid_px":"248.600000000","ask_px":"262.660000000","bid_sz":1000,"ask_sz":56,"bid_ct":1,"ask_ct":1},{"bid_px":"247.150000000","ask_px":"264.940000000","bid_sz":400,"ask_sz":7,"bid_ct":1,"ask_ct":1},{"bid_px":"247.000000000","ask_px":"265.000000000","bid_sz":12,"ask_sz":1,"bid_ct":1,"ask_ct":1},{"bid_px":"246.000000000","ask_px":"267.800000000","bid_sz":4,"ask_sz":30,"bid_ct":1,"ask_ct":1}],"symbol":"TSLA"}
{"ts_recv":"2024-11-01T08:00:09.855243663Z","hd":{"ts_event":"2024-11-01T08:00:09.855077638Z","rtype":10,"publisher_id":2,"instrument_id":16244},"action":"C","side":"A","depth":0,"price":"251.070000000","size":100,"flags":130,"ts_in_delta":166025,"sequence":309599,"levels":[{"bid_px":"250.000000000","ask_px":"251.070000000","bid_sz":2,"ask_sz":100,"bid_ct":2,"ask_ct":1},{"bid_px":"249.930000000","ask_px":"251.150000000","bid_sz":10,"ask_sz":100,"bid_ct":1,"ask_ct":2},{"bid_px":"249.800000000","ask_px":"252.400000000","bid_sz":199,"ask_sz":1000,"bid_ct":1,"ask_ct":1},{"bid_px":"249.770000000","ask_px":"253.650000000","bid_sz":50,"ask_sz":400,"bid_ct":1,"ask_ct":1},{"bid_px":"249.600000000","ask_px":"255.000000000","bid_sz":1000,"ask_sz":85,"bid_ct":1,"ask_ct":2},{"bid_px":"249.500000000","ask_px":"260.000000000","bid_sz":1000,"ask_sz":48,"bid_ct":1,"ask_ct":1},{"bid_px":"248.600000000","ask_px":"262.660000000","bid_sz":1000,"ask_sz":56,"bid_ct":1,"ask_ct":1},{"bid_px":"247.150000000","ask_px":"264.940000000","bid_sz":400,"ask_sz":7,"bid_ct":1,"ask_ct":1},{"bid_px":"247.000000000","ask_px":"265.000000000","bid_sz":12,"ask_sz":1,"bid_ct":1,"ask_ct":1},{"bid_px":"246.000000000","ask_px":"267.800000000","bid_sz":4,"ask_sz":30,"bid_ct":1,"ask_ct":1}],"symbol":"TSLA"}
{"ts_recv":"2024-11-01T08:00:09.855256729Z","hd":{"ts_event":"2024-11-01T08:00:09.855090665Z","rtype":10,"publisher_id":2,"instrument_id":16244},"action":"A","side":"A","depth":0,"price":"250.940000000","size":100,"flags":130,"ts_in_delta":166064,"sequence":309600,"levels":[{"bid_px":"250.000000000","ask_px":"250.940000000","bid_sz":2,"ask_sz":100,"bid_ct":2,"ask_ct":1},{"bid_px":"249.930000000","ask_px":"251.150000000","bid_sz":10,"ask_sz":100,"bid_ct":1,"ask_ct":2},{"bid_px":"249.800000000","ask_px":"252.400000000","bid_sz":199,"ask_sz":1000,"bid_ct":1,"ask_ct":1},{"bid_px":"249.770000000","ask_px":"253.650000000","bid_sz":50,"ask_sz":400,"bid_ct":1,"ask_ct":1},{"bid_px":"249.600000000","ask_px":"255.000000000","bid_sz":1000,"ask_sz":85,"bid_ct":1,"ask_ct":2},{"bid_px":"249.500000000","ask_px":"260.000000000","bid_sz":1000,"ask_sz":48,"bid_ct":1,"ask_ct":1},{"bid_px":"248.600000000","ask_px":"262.660000000","bid_sz":1000,"ask_sz":56,"bid_ct":1,"ask_ct":1},{"bid_px":"247.150000000","ask_px":"264.940000000","bid_sz":400,"ask_sz":7,"bid_ct":1,"ask_ct":1},{"bid_px":"247.000000000","ask_px":"265.000000000","bid_sz":12,"ask_sz":1,"bid_ct":1,"ask_ct":1},{"bid_px":"246.000000000","ask_px":"267.800000000","bid_sz":4,"ask_sz":30,"bid_ct":1,"ask_ct":1}],"symbol":"TSLA"}
{"ts_recv":"2024-11-01T08:00:09.891408749Z","hd":{"ts_event":"2024-11-01T08:00:09.891242517Z","rtype":10,"publisher_id":2,"instrument_id":16244},"action":"A","side":"B","depth":2,"price":"249.920000000","size":50,"flags":130,"ts_in_delta":166232,"sequence":309785,"levels":[{"bid_px":"250.000000000","ask_px":"250.940000000","bid_sz":2,"ask_sz":100,"bid_ct":2,"ask_ct":1},{"bid_px":"249.930000000","ask_px":"251.150000000","bid_sz":10,"ask_sz":100,"bid_ct":1,"ask_ct":2},{"bid_px":"249.920000000","ask_px":"252.400000000","bid_sz":50,"ask_sz":1000,"bid_ct":1,"ask_ct":1},{"bid_px":"249.800000000","ask_px":"253.650000000","bid_sz":199,"ask_sz":400,"bid_ct":1,"ask_ct":1},{"bid_px":"249.770000000","ask_px":"255.000000000","bid_sz":50,"ask_sz":85,"bid_ct":1,"ask_ct":2},{"bid_px":"249.600000000","ask_px":"260.000000000","bid_sz":1000,"ask_sz":48,"bid_ct":1,"ask_ct":1},{"bid_px":"249.500000000","ask_px":"262.660000000","bid_sz":1000,"ask_sz":56,"bid_ct":1,"ask_ct":1},{"bid_px":"248.600000000","ask_px":"264.940000000","bid_sz":1000,"ask_sz":7,"bid_ct":1,"ask_ct":1},{"bid_px":"247.150000000","ask_px":"265.000000000","bid_sz":400,"ask_sz":1,"bid_ct":1,"ask_ct":1},{"bid_px":"247.000000000","ask_px":"267.800000000","bid_sz":12,"ask_sz":30,"bid_ct":1,"ask_ct":1}],"symbol":"TSLA"}
{"ts_recv":"2024-11-01T08:00:09.900875098Z","hd":{"ts_event":"2024-11-01T08:00:09.900709507Z","rtype":10,"publisher_id":2,"instrument_id":16244},"action":"C","side":"A","depth":1,"price":"251.150000000","size":50,"flags":130,"ts_in_delta":165591,"sequence":309911,"levels":[{"bid_px":"250.000000000","ask_px":"250.940000000","bid_sz":2,"ask_sz":100,"bid_ct":2,"ask_ct":1},{"bid_px":"249.930000000","ask_px":"251.150000000","bid_sz":10,"ask_sz":50,"bid_ct":1,"ask_ct":1},{"bid_px":"249.920000000","ask_px":"252.400000000","bid_sz":50,"ask_sz":1000,"bid_ct":1,"ask_ct":1},{"bid_px":"249.800000000","ask_px":"253.650000000","bid_sz":199,"ask_sz":400,"bid_ct":1,"ask_ct":1},{"bid_px":"249.770000000","ask_px":"255.000000000","bid_sz":50,"ask_sz":85,"bid_ct":1,"ask_ct":2},{"bid_px":"249.600000000","ask_px":"260.000000000","bid_sz":1000,"ask_sz":48,"bid_ct":1,"ask_ct":1},{"bid_px":"249.500000000","ask_px":"262.660000000","bid_sz":1000,"ask_sz":56,"bid_ct":1,"ask_ct":1},{"bid_px":"248.600000000","ask_px":"264.940000000","bid_sz":1000,"ask_sz":7,"bid_ct":1,"ask_ct":1},{"bid_px":"247.150000000","ask_px":"265.000000000","bid_sz":400,"ask_sz":1,"bid_ct":1,"ask_ct":1},{"bid_px":"247.000000000","ask_px":"267.800000000","bid_sz":12,"ask_sz":30,"bid_ct":1,"ask_ct":1}],"symbol":"TSLA"}
{"ts_recv":"2024-11-01T08:00:09.900889623Z","hd":{"ts_event":"2024-11-01T08:00:09.900723380Z","rtype":10,"publisher_id":2,"instrument_id":16244},"action":"A","side":"A","depth":1,"price":"251.090000000","size":50,"flags":130,"ts_in_delta":166243,"sequence":309912,"levels":[{"bid_px":"250.000000000","ask_px":"250.940000000","bid_sz":2,"ask_sz":100,"bid_ct":2,"ask_ct":1},{"bid_px":"249.930000000","ask_px":"251.090000000","bid_sz":10,"ask_sz":50,"bid_ct":1,"ask_ct":1},{"bid_px":"249.920000000","ask_px":"252.400000000","bid_sz":50,"ask_sz":1000,"bid_ct":1,"ask_ct":1},{"bid_px":"249.800000000","ask_px":"253.650000000","bid_sz":199,"ask_sz":400,"bid_ct":1,"ask_ct":1},{"bid_px":"249.770000000","ask_px":"255.000000000","bid_sz":50,"ask_sz":85,"bid_ct":1,"ask_ct":2},{"bid_px":"249.600000000","ask_px":"260.000000000","bid_sz":1000,"ask_sz":48,"bid_ct":1,"ask_ct":1},{"bid_px":"249.500000000","ask_px":"262.660000000","bid_sz":1000,"ask_sz":56,"bid_ct":1,"ask_ct":1},{"bid_px":"248.600000000","ask_px":"264.940000000","bid_sz":1000,"ask_sz":7,"bid_ct":1,"ask_ct":1},{"bid_px":"247.150000000","ask_px":"265.000000000","bid_sz":400,"ask_sz":1,"bid_ct":1,"ask_ct":1},{"bid_px":"247.000000000","ask_px":"267.800000000","bid_sz":12,"ask_sz":30,"bid_ct":1,"ask_ct":1}],"symbol":"TSLA"}
{"ts_recv":"2024-11-01T08:00:09.932269707Z","hd":{"ts_event":"2024-11-01T08:00:09.932103494Z","rtype":10,"publisher_id":2,"instrument_id":16244},"action":"A","side":"B","depth":8,"price":"248.500000000","size":40,"flags":130,"ts_in_delta":166213,"sequence":310073,"levels":[{"bid_px":"250.000000000","ask_px":"250.940000000","bid_sz":2,"ask_sz":100,"bid_ct":2,"ask_ct":1},{"bid_px":"249.930000000","ask_px":"251.090000000","bid_sz":10,"ask_sz":50,"bid_ct":1,"ask_ct":1},{"bid_px":"249.920000000","ask_px":"252.400000000","bid_sz":50,"ask_sz":1000,"bid_ct":1,"ask_ct":1},{"bid_px":"249.800000000","ask_px":"253.650000000","bid_sz":199,"ask_sz":400,"bid_ct":1,"ask_ct":1},{"bid_px":"249.770000000","ask_px":"255.000000000","bid_sz":50,"ask_sz":85,"bid_ct":1,"ask_ct":2},{"bid_px":"249.600000000","ask_px":"260.000000000","bid_sz":1000,"ask_sz":48,"bid_ct":1,"ask_ct":1},{"bid_px":"249.500000000","ask_px":"262.660000000","bid_sz":1000,"ask_sz":56,"bid_ct":1,"ask_ct":1},{"bid_px":"248.600000000","ask_px":"264.940000000","bid_sz":1000,"ask_sz":7,"bid_ct":1,"ask_ct":1},{"bid_px":"248.500000000","ask_px":"265.000000000","bid_sz":40,"ask_sz":1,"bid_ct":1,"ask_ct":1},{"bid_px":"247.150000000","ask_px":"267.800000000","bid_sz":400,"ask_sz":30,"bid_ct":1,"ask_ct":1}],"symbol":"TSLA"}
{"ts_recv":"2024-11-01T08:00:10.097591952Z","hd":{"ts_event":"2024-11-01T08:00:10.097425474Z","rtype":10,"publisher_id":2,"instrument_id":16244},"action":"A","side":"A","depth":1,"price":"251.090000000","size":50,"flags":130,"ts_in_delta":166478,"sequence":310304,"levels":[{"bid_px":"250.000000000","ask_px":"250.940000000","bid_sz":2,"ask_sz":100,"bid_ct":2,"ask_ct":1},{"bid_px":"249.930000000","ask_px":"251.090000000","bid_sz":10,"ask_sz":100,"bid_ct":1,"ask_ct":2},{"bid_px":"249.920000000","ask_px":"252.400000000","bid_sz":50,"ask_sz":1000,"bid_ct":1,"ask_ct":1},{"bid_px":"249.800000000","ask_px":"253.650000000","bid_sz":199,"ask_sz":400,"bid_ct":1,"ask_ct":1},{"bid_px":"249.770000000","ask_px":"255.000000000","bid_sz":50,"ask_sz":85,"bid_ct":1,"ask_ct":2},{"bid_px":"249.600000000","ask_px":"260.000000000","bid_sz":1000,"ask_sz":48,"bid_ct":1,"ask_ct":1},{"bid_px":"249.500000000","ask_px":"262.660000000","bid_sz":1000,"ask_sz":56,"bid_ct":1,"ask_ct":1},{"bid_px":"248.600000000","ask_px":"264.940000000","bid_sz":1000,"ask_sz":7,"bid_ct":1,"ask_ct":1},{"bid_px":"248.500000000","ask_px":"265.000000000","bid_sz":40,"ask_sz":1,"bid_ct":1,"ask_ct":1},{"bid_px":"247.150000000","ask_px":"267.800000000","bid_sz":400,"ask_sz":30,"bid_ct":1,"ask_ct":1}],"symbol":"TSLA"}
{"ts_recv":"2024-11-01T08:00:10.097635281Z","hd":{"ts_event":"2024-11-01T08:00:10.097469401Z","rtype":10,"publisher_id":2,"instrument_id":16244},"action":"C","side":"B","depth":2,"price":"249.920000000","size":50,"flags":130,"ts_in_delta":165880,"sequence":310305,"levels":[{"bid_px":"250.000000000","ask_px":"250.940000000","bid_sz":2,"ask_sz":100,"bid_ct":2,"ask_ct":1},{"bid_px":"249.930000000","ask_px":"251.090000000","bid_sz":10,"ask_sz":100,"bid_ct":1,"ask_ct":2},{"bid_px":"249.800000000","ask_px":"252.400000000","bid_sz":199,"ask_sz":1000,"bid_ct":1,"ask_ct":1},{"bid_px":"249.770000000","ask_px":"253.650000000","bid_sz":50,"ask_sz":400,"bid_ct":1,"ask_ct":1},{"bid_px":"249.600000000","ask_px":"255.000000000","bid_sz":1000,"ask_sz":85,"bid_ct":1,"ask_ct":2},{"bid_px":"249.500000000","ask_px":"260.000000000","bid_sz":1000,"ask_sz":48,"bid_ct":1,"ask_ct":1},{"bid_px":"248.600000000","ask_px":"262.660000000","bid_sz":1000,"ask_sz":56,"bid_ct":1,"ask_ct":1},{"bid_px":"248.500000000","ask_px":"264.940000000","bid_sz":40,"ask_sz":7,"bid_ct":1,"ask_ct":1},{"bid_px":"247.150000000","ask_px":"265.000000000","bid_sz":400,"ask_sz":1,"bid_ct":1,"ask_ct":1},{"bid_px":"247.000000000","ask_px":"267.800000000","bid_sz":12,"ask_sz":30,"bid_ct":1,"ask_ct":1}],"symbol":"TSLA"}
{"ts_recv":"2024-11-01T08:00:10.097648012Z","hd":{"ts_event":"2024-11-01T08:00:10.097481745Z","rtype":10,"publisher_id":2,"instrument_id":16244},"action":"A","side":"B","depth":2,"price":"249.890000000","size":50,"flags":130,"ts_in_delta":166267,"sequence":310306,"levels":[{"bid_px":"250.000000000","ask_px":"250.940000000","bid_sz":2,"ask_sz":100,"bid_ct":2,"ask_ct":1},{"bid_px":"249.930000000","ask_px":"251.090000000","bid_sz":10,"ask_sz":100,"bid_ct":1,"ask_ct":2},{"bid_px":"249.890000000","ask_px":"252.400000000","bid_sz":50,"ask_sz":1000,"bid_ct":1,"ask_ct":1},{"bid_px":"249.800000000","ask_px":"253.650000000","bid_sz":199,"ask_sz":400,"bid_ct":1,"ask_ct":1},{"bid_px":"249.770000000","ask_px":"255.000000000","bid_sz":50,"ask_sz":85,"bid_ct":1,"ask_ct":2},{"bid_px":"249.600000000","ask_px":"260.000000000","bid_sz":1000,"ask_sz":48,"bid_ct":1,"ask_ct":1},{"bid_px":"249.500000000","ask_px":"262.660000000","bid_sz":1000,"ask_sz":56,"bid_ct":1,"ask_ct":1},{"bid_px":"248.600000000","ask_px":"264.940000000","bid_sz":1000,"ask_sz":7,"bid_ct":1,"ask_ct":1},{"bid_px":"248.500000000","ask_px":"265.000000000","bid_sz":40,"ask_sz":1,"bid_ct":1,"ask_ct":1},{"bid_px":"247.150000000","ask_px":"267.800000000","bid_sz":400,"ask_sz":30,"bid_ct":1,"ask_ct":1}],"symbol":"TSLA"}
{"ts_recv":"2024-11-01T08:00:10.148750553Z","hd":{"ts_event":"2024-11-01T08:00:10.148584206Z","rtype":10,"publisher_id":2,"instrument_id":16244},"action":"C","side":"A","depth":1,"price":"251.090000000","size":50,"flags":130,"ts_in_delta":166347,"sequence":310376,"levels":[{"bid_px":"250.000000000","ask_px":"250.940000000","bid_sz":2,"ask_sz":100,"bid_ct":2,"ask_ct":1},{"bid_px":"249.930000000","ask_px":"251.090000000","bid_sz":10,"ask_sz":50,"bid_ct":1,"ask_ct":1},{"bid_px":"249.890000000","ask_px":"252.400000000","bid_sz":50,"ask_sz":1000,"bid_ct":1,"ask_ct":1},{"bid_px":"249.800000000","ask_px":"253.650000000","bid_sz":199,"ask_sz":400,"bid_ct":1,"ask_ct":1},{"bid_px":"249.770000000","ask_px":"255.000000000","bid_sz":50,"ask_sz":85,"bid_ct":1,"ask_ct":2},{"bid_px":"249.600000000","ask_px":"260.000000000","bid_sz":1000,"ask_sz":48,"bid_ct":1,"ask_ct":1},{"bid_px":"249.500000000","ask_px":"262.660000000","bid_sz":1000,"ask_sz":56,"bid_ct":1,"ask_ct":1},{"bid_px":"248.600000000","ask_px":"264.940000000","bid_sz":1000,"ask_sz":7,"bid_ct":1,"ask_ct":1},{"bid_px":"248.500000000","ask_px":"265.000000000","bid_sz":40,"ask_sz":1,"bid_ct":1,"ask_ct":1},{"bid_px":"247.150000000","ask_px":"267.800000000","bid_sz":400,"ask_sz":30,"bid_ct":1,"ask_ct":1}],"symbol":"TSLA"}
{"ts_recv":"2024-11-01T08:00:10.148764513Z","hd":{"ts_event":"2024-11-01T08:00:10.148598171Z","rtype":10,"publisher_id":2,"instrument_id":16244},"action":"A","side":"A","depth":1,"price":"250.990000000","size":50,"flags":130,"ts_in_delta":166342,"sequence":310377,"levels":[{"bid_px":"250.000000000","ask_px":"250.940000000","bid_sz":2,"ask_sz":100,"bid_ct":2,"ask_ct":1},{"bid_px":"249.930000000","ask_px":"250.990000000","bid_sz":10,"ask_sz":50,"bid_ct":1,"ask_ct":1},{"bid_px":"249.890000000","ask_px":"252.400000000","bid_sz":50,"ask_sz":1000,"bid_ct":1,"ask_ct":1},{"bid_px":"249.800000000","ask_px":"253.650000000","bid_sz":199,"ask_sz":400,"bid_ct":1,"ask_ct":1},{"bid_px":"249.770000000","ask_px":"255.000000000","bid_sz":50,"ask_sz":85,"bid_ct":1,"ask_ct":2},{"bid_px":"249.600000000","ask_px":"260.000000000","bid_sz":1000,"ask_sz":48,"bid_ct":1,"ask_ct":1},{"bid_px":"249.500000000","ask_px":"262.660000000","bid_sz":1000,"ask_sz":56,"bid_ct":1,"ask_ct":1},{"bid_px":"248.600000000","ask_px":"264.940000000","bid_sz":1000,"ask_sz":7,"bid_ct":1,"ask_ct":1},{"bid_px":"248.500000000","ask_px":"265.000000000","bid_sz":40,"ask_sz":1,"bid_ct":1,"ask_ct":1},{"bid_px":"247.150000000","ask_px":"267.800000000","bid_sz":400,"ask_sz":30,"bid_ct":1,"ask_ct":1}],"symbol":"TSLA"}
{"ts_recv":"2024-11-01T08:00:10.168606294Z","hd":{"ts_event":"2024-11-01T08:00:10.168439956Z","rtype":10,"publisher_id":2,"instrument_id":16244},"action":"A","side":"B","depth":2,"price":"249.910000000","size":50,"flags":130,"ts_in_delta":166338,"sequence":310404,"levels":[{"bid_px":"250.000000000","ask_px":"250.940000000","bid_sz":2,"ask_sz":100,"bid_ct":2,"ask_ct":1},{"bid_px":"249.930000000","ask_px":"250.990000000","bid_sz":10,"ask_sz":50,"bid_ct":1,"ask_ct":1},{"bid_px":"249.910000000","ask_px":"252.400000000","bid_sz":50,"ask_sz":1000,"bid_ct":1,"ask_ct":1},{"bid_px":"249.800000000","ask_px":"253.650000000","bid_sz":199,"ask_sz":400,"bid_ct":1,"ask_ct":1},{"bid_px":"249.770000000","ask_px":"255.000000000","bid_sz":50,"ask_sz":85,"bid_ct":1,"ask_ct":2},{"bid_px":"249.600000000","ask_px":"260.000000000","bid_sz":1000,"ask_sz":48,"bid_ct":1,"ask_ct":1},{"bid_px":"249.500000000","ask_px":"262.660000000","bid_sz":1000,"ask_sz":56,"bid_ct":1,"ask_ct":1},{"bid_px":"248.600000000","ask_px":"264.940000000","bid_sz":1000,"ask_sz":7,"bid_ct":1,"ask_ct":1},{"bid_px":"248.500000000","ask_px":"265.000000000","bid_sz":40,"ask_sz":1,"bid_ct":1,"ask_ct":1},{"bid_px":"247.150000000","ask_px":"267.800000000","bid_sz":400,"ask_sz":30,"bid_ct":1,"ask_ct":1}],"symbol":"TSLA"}
{"ts_recv":"2024-11-01T08:00:10.178995283Z","hd":{"ts_event":"2024-11-01T08:00:10.178829435Z","rtype":10,"publisher_id":2,"instrument_id":16244},"action":"C","side":"B","depth":7,"price":"248.600000000","size":1000,"flags":130,"ts_in_delta":165848,"sequence":310428,"levels":[{"bid_px":"250.000000000","ask_px":"250.940000000","bid_sz":2,"ask_sz":100,"bid_ct":2,"ask_ct":1},{"bid_px":"249.930000000","ask_px":"250.990000000","bid_sz":10,"ask_sz":50,"bid_ct":1,"ask_ct":1},{"bid_px":"249.910000000","ask_px":"252.400000000","bid_sz":50,"ask_sz":1000,"bid_ct":1,"ask_ct":1},{"bid_px":"249.800000000","ask_px":"253.650000000","bid_sz":199,"ask_sz":400,"bid_ct":1,"ask_ct":1},{"bid_px":"249.770000000","ask_px":"255.000000000","bid_sz":50,"ask_sz":85,"bid_ct":1,"ask_ct":2},{"bid_px":"249.600000000","ask_px":"260.000000000","bid_sz":1000,"ask_sz":48,"bid_ct":1,"ask_ct":1},{"bid_px":"249.500000000","ask_px":"262.660000000","bid_sz":1000,"ask_sz":56,"bid_ct":1,"ask_ct":1},{"bid_px":"248.500000000","ask_px":"264.940000000","bid_sz":40,"ask_sz":7,"bid_ct":1,"ask_ct":1},{"bid_px":"247.150000000","ask_px":"265.000000000","bid_sz":400,"ask_sz":1,"bid_ct":1,"ask_ct":1},{"bid_px":"247.000000000","ask_px":"267.800000000","bid_sz":12,"ask_sz":30,"bid_ct":1,"ask_ct":1}],"symbol":"TSLA"}
{"ts_recv":"2024-11-01T08:00:10.189419686Z","hd":{"ts_event":"2024-11-01T08:00:10.189253300Z","rtype":10,"publisher_id":2,"instrument_id":16244},"action":"A","side":"B","depth":5,"price":"249.700000000","size":1000,"flags":130,"ts_in_delta":166386,"sequence":310444,"levels":[{"bid_px":"250.000000000","ask_px":"250.940000000","bid_sz":2,"ask_sz":100,"bid_ct":2,"ask_ct":1},{"bid_px":"249.930000000","ask_px":"250.990000000","bid_sz":10,"ask_sz":50,"bid_ct":1,"ask_ct":1},{"bid_px":"249.910000000","ask_px":"252.400000000","bid_sz":50,"ask_sz":1000,"bid_ct":1,"ask_ct":1},{"bid_px":"249.800000000","ask_px":"253.650000000","bid_sz":199,"ask_sz":400,"bid_ct":1,"ask_ct":1},{"bid_px":"249.770000000","ask_px":"255.000000000","bid_sz":50,"ask_sz":85,"bid_ct":1,"ask_ct":2},{"bid_px":"249.700000000","ask_px":"260.000000000","bid_sz":1000,"ask_sz":48,"bid_ct":1,"ask_ct":1},{"bid_px":"249.600000000","ask_px":"262.660000000","bid_sz":1000,"ask_sz":56,"bid_ct":1,"ask_ct":1},{"bid_px":"249.500000000","ask_px":"264.940000000","bid_sz":1000,"ask_sz":7,"bid_ct":1,"ask_ct":1},{"bid_px":"248.500000000","ask_px":"265.000000000","bid_sz":40,"ask_sz":1,"bid_ct":1,"ask_ct":1},{"bid_px":"247.150000000","ask_px":"267.800000000","bid_sz":400,"ask_sz":30,"bid_ct":1,"ask_ct":1}],"symbol":"TSLA"}
{"ts_recv":"2024-11-01T08:00:10.189446830Z","hd":{"ts_event":"2024-11-01T08:00:10.189280846Z","rtype":10,"publisher_id":2,"instrument_id":16244},"action":"C","side":"B","depth":7,"price":"249.500000000","size":1000,"flags":130,"ts_in_delta":165984,"sequence":310445,"levels":[{"bid_px":"250.000000000","ask_px":"250.940000000","bid_sz":2,"ask_sz":100,"bid_ct":2,"ask_ct":1},{"bid_px":"249.930000000","ask_px":"250.990000000","bid_sz":10,"ask_sz":50,"bid_ct":1,"ask_ct":1},{"bid_px":"249.910000000","ask_px":"252.400000000","bid_sz":50,"ask_sz":1000,"bid_ct":1,"ask_ct":1},{"bid_px":"249.800000000","ask_px":"253.650000000","bid_sz":199,"ask_sz":400,"bid_ct":1,"ask_ct":1},{"bid_px":"249.770000000","ask_px":"255.000000000","bid_sz":50,"ask_sz":85,"bid_ct":1,"ask_ct":2},{"bid_px":"249.700000000","ask_px":"260.000000000","bid_sz":1000,"ask_sz":48,"bid_ct":1,"ask_ct":1},{"bid_px":"249.600000000","ask_px":"262.660000000","bid_sz":1000,"ask_sz":56,"bid_ct":1,"ask_ct":1},{"bid_px":"248.500000000","ask_px":"264.940000000","bid_sz":40,"ask_sz":7,"bid_ct":1,"ask_ct":1},{"bid_px":"247.150000000","ask_px":"265.000000000","bid_sz":400,"ask_sz":1,"bid_ct":1,"ask_ct":1},{"bid_px":"247.000000000","ask_px":"267.800000000","bid_sz":12,"ask_sz":30,"bid_ct":1,"ask_ct":1}],"symbol":"TSLA"}
{"ts_recv":"2024-11-01T08:00:10.200968842Z","hd":{"ts_event":"2024-11-01T08:00:10.200802660Z","rtype":10,"publisher_id":2,"instrument_id":16244},"action":"A","side":"B","depth":8,"price":"248.200000000","size":1000,"flags":130,"ts_in_delta":166182,"sequence":310455,"levels":[{"bid_px":"250.000000000","ask_px":"250.940000000","bid_sz":2,"ask_sz":100,"bid_ct":2,"ask_ct":1},{"bid_px":"249.930000000","ask_px":"250.990000000","bid_sz":10,"ask_sz":50,"bid_ct":1,"ask_ct":1},{"bid_px":"249.910000000","ask_px":"252.400000000","bid_sz":50,"ask_sz":1000,"bid_ct":1,"ask_ct":1},{"bid_px":"249.800000000","ask_px":"253.650000000","bid_sz":199,"ask_sz":400,"bid_ct":1,"ask_ct":1},{"bid_px":"249.770000000","ask_px":"255.000000000","bid_sz":50,"ask_sz":85,"bid_ct":1,"ask_ct":2},{"bid_px":"249.700000000","ask_px":"260.000000000","bid_sz":1000,"ask_sz":48,"bid_ct":1,"ask_ct":1},{"bid_px":"249.600000000","ask_px":"262.660000000","bid_sz":1000,"ask_sz":56,"bid_ct":1,"ask_ct":1},{"bid_px":"248.500000000","ask_px":"264.940000000","bid_sz":40,"ask_sz":7,"bid_ct":1,"ask_ct":1},{"bid_px":"248.200000000","ask_px":"265.000000000","bid_sz":1000,"ask_sz":1,"bid_ct":1,"ask_ct":1},{"bid_px":"247.150000000","ask_px":"267.800000000","bid_sz":400,"ask_sz":30,"bid_ct":1,"ask_ct":1}],"symbol":"TSLA"}
{"ts_recv":"2024-11-01T08:00:10.264778366Z","hd":{"ts_event":"2024-11-01T08:00:10.264611611Z","rtype":10,"publisher_id":2,"instrument_id":16244},"action":"C","side":"B","depth":2,"price":"249.910000000","size":50,"flags":130,"ts_in_delta":166755,"sequence":310554,"levels":[{"bid_px":"250.000000000","ask_px":"250.940000000","bid_sz":2,"ask_sz":100,"bid_ct":2,"ask_ct":1},{"bid_px":"249.930000000","ask_px":"250.990000000","bid_sz":10,"ask_sz":50,"bid_ct":1,"ask_ct":1},{"bid_px":"249.800000000","ask_px":"252.400000000","bid_sz":199,"ask_sz":1000,"bid_ct":1,"ask_ct":1},{"bid_px":"249.770000000","ask_px":"253.650000000","bid_sz":50,"ask_sz":400,"bid_ct":1,"ask_ct":1},{"bid_px":"249.700000000","ask_px":"255.000000000","bid_sz":1000,"ask_sz":85,"bid_ct":1,"ask_ct":2},{"bid_px":"249.600000000","ask_px":"260.000000000","bid_sz":1000,"ask_sz":48,"bid_ct":1,"ask_ct":1},{"bid_px":"248.500000000","ask_px":"262.660000000","bid_sz":40,"ask_sz":56,"bid_ct":1,"ask_ct":1},{"bid_px":"248.200000000","ask_px":"264.940000000","bid_sz":1000,"ask_sz":7,"bid_ct":1,"ask_ct":1},{"bid_px":"247.150000000","ask_px":"265.000000000","bid_sz":400,"ask_sz":1,"bid_ct":1,"ask_ct":1},{"bid_px":"247.000000000","ask_px":"267.800000000","bid_sz":12,"ask_sz":30,"bid_ct":1,"ask_ct":1}],"symbol":"TSLA"}
{"ts_recv":"2024-11-01T08:00:10.445872888Z","hd":{"ts_event":"2024-11-01T08:00:10.445705898Z","rtype":10,"publisher_id":2,"instrument_id":16244},"action":"A","side":"B","depth":0,"price":"250.150000000","size":50,"flags":130,"ts_in_delta":166990,"sequence":310826,"levels":[{"bid_px":"250.150000000","ask_px":"250.940000000","bid_sz":50,"ask_sz":100,"bid_ct":1,"ask_ct":1},{"bid_px":"250.000000000","ask_px":"250.990000000","bid_sz":2,"ask_sz":50,"bid_ct":2,"ask_ct":1},{"bid_px":"249.930000000","ask_px":"252.400000000","bid_sz":10,"ask_sz":1000,"bid_ct":1,"ask_ct":1},{"bid_px":"249.800000000","ask_px":"253.650000000","bid_sz":199,"ask_sz":400,"bid_ct":1,"ask_ct":1},{"bid_px":"249.770000000","ask_px":"255.000000000","bid_sz":50,"ask_sz":85,"bid_ct":1,"ask_ct":2},{"bid_px":"249.700000000","ask_px":"260.000000000","bid_sz":1000,"ask_sz":48,"bid_ct":1,"ask_ct":1},{"bid_px":"249.600000000","ask_px":"262.660000000","bid_sz":1000,"ask_sz":56,"bid_ct":1,"ask_ct":1},{"bid_px":"248.500000000","ask_px":"264.940000000","bid_sz":40,"ask_sz":7,"bid_ct":1,"ask_ct":1},{"bid_px":"248.200000000","ask_px":"265.000000000","bid_sz":1000,"ask_sz":1,"bid_ct":1,"ask_ct":1},{"bid_px":"247.150000000","ask_px":"267.800000000","bid_sz":400,"ask_sz":30,"bid_ct":1,"ask_ct":1}],"symbol":"TSLA"}
{"ts_recv":"2024-11-01T08:00:10.622856667Z","hd":{"ts_event":"2024-11-01T08:00:10.622690498Z","rtype":10,"publisher_id":2,"instrument_id":16244},"action":"A","side":"A","depth":8,"price":"265.000000000","size":1,"flags":130,"ts_in_delta":166169,"sequence":311375,"levels":[{"bid_px":"250.150000000","ask_px":"250.940000000","bid_sz":50,"ask_sz":100,"bid_ct":1,"ask_ct":1},{"bid_px":"250.000000000","ask_px":"250.990000000","bid_sz":2,"ask_sz":50,"bid_ct":2,"ask_ct":1},{"bid_px":"249.930000000","ask_px":"252.400000000","bid_sz":10,"ask_sz":1000,"bid_ct":1,"ask_ct":1},{"bid_px":"249.800000000","ask_px":"253.650000000","bid_sz":199,"ask_sz":400,"bid_ct":1,"ask_ct":1},{"bid_px":"249.770000000","ask_px":"255.000000000","bid_sz":50,"ask_sz":85,"bid_ct":1,"ask_ct":2},{"bid_px":"249.700000000","ask_px":"260.000000000","bid_sz":1000,"ask_sz":48,"bid_ct":1,"ask_ct":1},{"bid_px":"249.600000000","ask_px":"262.660000000","bid_sz":1000,"ask_sz":56,"bid_ct":1,"ask_ct":1},{"bid_px":"248.500000000","ask_px":"264.940000000","bid_sz":40,"ask_sz":7,"bid_ct":1,"ask_ct":1},{"bid_px":"248.200000000","ask_px":"265.000000000","bid_sz":1000,"ask_sz":2,"bid_ct":1,"ask_ct":2},{"bid_px":"247.150000000","ask_px":"267.800000000","bid_sz":400,"ask_sz":30,"bid_ct":1,"ask_ct":1}],"symbol":"TSLA"}
{"ts_recv":"2024-11-01T08:00:10.625500963Z","hd":{"ts_event":"2024-11-01T08:00:10.625335069Z","rtype":10,"publisher_id":2,"instrument_id":16244},"action":"A","side":"A","depth":1,"price":"250.980000000","size":50,"flags":130,"ts_in_delta":165894,"sequence":311383,"levels":[{"bid_px":"250.150000000","ask_px":"250.940000000","bid_sz":50,"ask_sz":100,"bid_ct":1,"ask_ct":1},{"bid_px":"250.000000000","ask_px":"250.980000000","bid_sz":2,"ask_sz":50,"bid_ct":2,"ask_ct":1},{"bid_px":"249.930000000","ask_px":"252.400000000","bid_sz":10,"ask_sz":1000,"bid_ct":1,"ask_ct":1},{"bid_px":"249.800000000","ask_px":"253.650000000","bid_sz":199,"ask_sz":400,"bid_ct":1,"ask_ct":1},{"bid_px":"249.770000000","ask_px":"255.000000000","bid_sz":50,"ask_sz":85,"bid_ct":1,"ask_ct":2},{"bid_px":"249.700000000","ask_px":"260.000000000","bid_sz":1000,"ask_sz":48,"bid_ct":1,"ask_ct":1},{"bid_px":"249.600000000","ask_px":"262.660000000","bid_sz":1000,"ask_sz":56,"bid_ct":1,"ask_ct":1},{"bid_px":"248.500000000","ask_px":"264.940000000","bid_sz":40,"ask_sz":7,"bid_ct":1,"ask_ct":1},{"bid_px":"248.200000000","ask_px":"265.000000000","bid_sz":1000,"ask_sz":2,"bid_ct":1,"ask_ct":2},{"bid_px":"247.150000000","ask_px":"267.800000000","bid_sz":400,"ask_sz":30,"bid_ct":1,"ask_ct":1}],"symbol":"TSLA"}
{"ts_recv":"2024-11-01T08:00:10.852043842Z","hd":{"ts_event":"2024-11-01T08:00:10.851877543Z","rtype":10,"publisher_id":2,"instrument_id":16244},"action":"A","side":"A","depth":8,"price":"265.000000000","size":100,"flags":130,"ts_in_delta":166299,"sequence":311997,"levels":[{"bid_px":"250.150000000","ask_px":"250.940000000","bid_sz":50,"ask_sz":100,"bid_ct":1,"ask_ct":1},{"bid_px":"250.000000000","ask_px":"250.980000000","bid_sz":2,"ask_sz":50,"bid_ct":2,"ask_ct":1},{"bid_px":"249.930000000","ask_px":"252.400000000","bid_sz":10,"ask_sz":1000,"bid_ct":1,"ask_ct":1},{"bid_px":"249.800000000","ask_px":"253.650000000","bid_sz":199,"ask_sz":400,"bid_ct":1,"ask_ct":1},{"bid_px":"249.770000000","ask_px":"255.000000000","bid_sz":50,"ask_sz":85,"bid_ct":1,"ask_ct":2},{"bid_px":"249.700000000","ask_px":"260.000000000","bid_sz":1000,"ask_sz":48,"bid_ct":1,"ask_ct":1},{"bid_px":"249.600000000","ask_px":"262.660000000","bid_sz":1000,"ask_sz":56,"bid_ct":1,"ask_ct":1},{"bid_px":"248.500000000","ask_px":"264.940000000","bid_sz":40,"ask_sz":7,"bid_ct":1,"ask_ct":1},{"bid_px":"248.200000000","ask_px":"265.000000000","bid_sz":1000,"ask_sz":102,"bid_ct":1,"ask_ct":3},{"bid_px":"247.150000000","ask_px":"267.800000000","bid_sz":400,"ask_sz":30,"bid_ct":1,"ask_ct":1}],"symbol":"TSLA"}
{"ts_recv":"2024-11-01T08:00:10.963661271Z","hd":{"ts_event":"2024-11-01T08:00:10.963495230Z","rtype":10,"publisher_id":2,"instrument_id":16244},"action":"C","side":"A","depth":1,"price":"250.980000000","size":50,"flags":130,"ts_in_delta":166041,"sequence":312130,"levels":[{"bid_px":"250.150000000","ask_px":"250.940000000","bid_sz":50,"ask_sz":100,"bid_ct":1,"ask_ct":1},{"bid_px":"250.000000000","ask_px":"252.400000000","bid_sz":2,"ask_sz":1000,"bid_ct":2,"ask_ct":1},{"bid_px":"249.930000000","ask_px":"253.650000000","bid_sz":10,"ask_sz":400,"bid_ct":1,"ask_ct":1},{"bid_px":"249.800000000","ask_px":"255.000000000","bid_sz":199,"ask_sz":85,"bid_ct":1,"ask_ct":2},{"bid_px":"249.770000000","ask_px":"260.000000000","bid_sz":50,"ask_sz":48,"bid_ct":1,"ask_ct":1},{"bid_px":"249.700000000","ask_px":"262.660000000","bid_sz":1000,"ask_sz":56,"bid_ct":1,"ask_ct":1},{"bid_px":"249.600000000","ask_px":"264.940000000","bid_sz":1000,"ask_sz":7,"bid_ct":1,"ask_ct":1},{"bid_px":"248.500000000","ask_px":"265.000000000","bid_sz":40,"ask_sz":102,"bid_ct":1,"ask_ct":3},{"bid_px":"248.200000000","ask_px":"267.800000000","bid_sz":1000,"ask_sz":30,"bid_ct":1,"ask_ct":1},{"bid_px":"247.150000000","ask_px":"268.670000000","bid_sz":400,"ask_sz":100,"bid_ct":1,"ask_ct":1}],"symbol":"TSLA"}
{"ts_recv":"2024-11-01T08:00:11.035334462Z","hd":{"ts_event":"2024-11-01T08:00:11.035168252Z","rtype":10,"publisher_id":2,"instrument_id":16244},"action":"A","side":"A","depth":1,"price":"250.990000000","size":50,"flags":130,"ts_in_delta":166210,"sequence":312363,"levels":[{"bid_px":"250.150000000","ask_px":"250.940000000","bid_sz":50,"ask_sz":100,"bid_ct":1,"ask_ct":1},{"bid_px":"250.000000000","ask_px":"250.990000000","bid_sz":2,"ask_sz":50,"bid_ct":2,"ask_ct":1},{"bid_px":"249.930000000","ask_px":"252.400000000","bid_sz":10,"ask_sz":1000,"bid_ct":1,"ask_ct":1},{"bid_px":"249.800000000","ask_px":"253.650000000","bid_sz":199,"ask_sz":400,"bid_ct":1,"ask_ct":1},{"bid_px":"249.770000000","ask_px":"255.000000000","bid_sz":50,"ask_sz":85,"bid_ct":1,"ask_ct":2},{"bid_px":"249.700000000","ask_px":"260.000000000","bid_sz":1000,"ask_sz":48,"bid_ct":1,"ask_ct":1},{"bid_px":"249.600000000","ask_px":"262.660000000","bid_sz":1000,"ask_sz":56,"bid_ct":1,"ask_ct":1},{"bid_px":"248.500000000","ask_px":"264.940000000","bid_sz":40,"ask_sz":7,"bid_ct":1,"ask_ct":1},{"bid_px":"248.200000000","ask_px":"265.000000000","bid_sz":1000,"ask_sz":102,"bid_ct":1,"ask_ct":3},{"bid_px":"247.150000000","ask_px":"267.800000000","bid_sz":400,"ask_sz":30,"bid_ct":1,"ask_ct":1}],"symbol":"TSLA"}
{"ts_recv":"2024-11-01T08:00:11.128548275Z","hd":{"ts_event":"2024-11-01T08:00:11.128382259Z","rtype":10,"publisher_id":2,"instrument_id":16244},"action":"C","side":"B","depth":0,"price":"250.150000000","size":50,"flags":130,"ts_in_delta":166016,"sequence":312644,"levels":[{"bid_px":"250.000000000","ask_px":"250.940000000","bid_sz":2,"ask_sz":100,"bid_ct":2,"ask_ct":1},{"bid_px":"249.930000000","ask_px":"250.990000000","bid_sz":10,"ask_sz":50,"bid_ct":1,"ask_ct":1},{"bid_px":"249.800000000","ask_px":"252.400000000","bid_sz":199,"ask_sz":1000,"bid_ct":1,"ask_ct":1},{"bid_px":"249.770000000","ask_px":"253.650000000","bid_sz":50,"ask_sz":400,"bid_ct":1,"ask_ct":1},{"bid_px":"249.700000000","ask_px":"255.000000000","bid_sz":1000,"ask_sz":85,"bid_ct":1,"ask_ct":2},{"bid_px":"249.600000000","ask_px":"260.000000000","bid_sz":1000,"ask_sz":48,"bid_ct":1,"ask_ct":1},{"bid_px":"248.500000000","ask_px":"262.660000000","bid_sz":40,"ask_sz":56,"bid_ct":1,"ask_ct":1},{"bid_px":"248.200000000","ask_px":"264.940000000","bid_sz":1000,"ask_sz":7,"bid_ct":1,"ask_ct":1},{"bid_px":"247.150000000","ask_px":"265.000000000","bid_sz":400,"ask_sz":102,"bid_ct":1,"ask_ct":3},{"bid_px":"247.000000000","ask_px":"267.800000000","bid_sz":12,"ask_sz":30,"bid_ct":1,"ask_ct":1}],"symbol":"TSLA"}
{"ts_recv":"2024-11-01T08:00:11.128560599Z","hd":{"ts_event":"2024-11-01T08:00:11.128394620Z","rtype":10,"publisher_id":2,"instrument_id":16244},"action":"A","side":"B","depth":0,"price":"250.110000000","size":50,"flags":130,"ts_in_delta":165979,"sequence":312645,"levels":[{"bid_px":"250.110000000","ask_px":"250.940000000","bid_sz":50,"ask_sz":100,"bid_ct":1,"ask_ct":1},{"bid_px":"250.000000000","ask_px":"250.990000000","bid_sz":2,"ask_sz":50,"bid_ct":2,"ask_ct":1},{"bid_px":"249.930000000","ask_px":"252.400000000","bid_sz":10,"ask_sz":1000,"bid_ct":1,"ask_ct":1},{"bid_px":"249.800000000","ask_px":"253.650000000","bid_sz":199,"ask_sz":400,"bid_ct":1,"ask_ct":1},{"bid_px":"249.770000000","ask_px":"255.000000000","bid_sz":50,"ask_sz":85,"bid_ct":1,"ask_ct":2},{"bid_px":"249.700000000","ask_px":"260.000000000","bid_sz":1000,"ask_sz":48,"bid_ct":1,"ask_ct":1},{"bid_px":"249.600000000","ask_px":"262.660000000","bid_sz":1000,"ask_sz":56,"bid_ct":1,"ask_ct":1},{"bid_px":"248.500000000","ask_px":"264.940000000","bid_sz":40,"ask_sz":7,"bid_ct":1,"ask_ct":1},{"bid_px":"248.200000000","ask_px":"265.000000000","bid_sz":1000,"ask_sz":102,"bid_ct":1,"ask_ct":3},{"bid_px":"247.150000000","ask_px":"267.800000000","bid_sz":400,"ask_sz":30,"bid_ct":1,"ask_ct":1}],"symbol":"TSLA"}
{"ts_recv":"2024-11-01T08:00:11.410487817Z","hd":{"ts_event":"2024-11-01T08:00:11.410321560Z","rtype":10,"publisher_id":2,"instrument_id":16244},"action":"A","side":"A","depth":2,"price":"252.300000000","size":1000,"flags":130,"ts_in_delta":166257,"sequence":313780,"levels":[{"bid_px":"250.110000000","ask_px":"250.940000000","bid_sz":50,"ask_sz":100,"bid_ct":1,"ask_ct":1},{"bid_px":"250.000000000","ask_px":"250.990000000","bid_sz":2,"ask_sz":50,"bid_ct":2,"ask_ct":1},{"bid_px":"249.930000000","ask_px":"252.300000000","bid_sz":10,"ask_sz":1000,"bid_ct":1,"ask_ct":1},{"bid_px":"249.800000000","ask_px":"252.400000000","bid_sz":199,"ask_sz":1000,"bid_ct":1,"ask_ct":1},{"bid_px":"249.770000000","ask_px":"253.650000000","bid_sz":50,"ask_sz":400,"bid_ct":1,"ask_ct":1},{"bid_px":"249.700000000","ask_px":"255.000000000","bid_sz":1000,"ask_sz":85,"bid_ct":1,"ask_ct":2},{"bid_px":"249.600000000","ask_px":"260.000000000","bid_sz":1000,"ask_sz":48,"bid_ct":1,"ask_ct":1},{"bid_px":"248.500000000","ask_px":"262.660000000","bid_sz":40,"ask_sz":56,"bid_ct":1,"ask_ct":1},{"bid_px":"248.200000000","ask_px":"264.940000000","bid_sz":1000,"ask_sz":7,"bid_ct":1,"ask_ct":1},{"bid_px":"247.150000000","ask_px":"265.000000000","bid_sz":400,"ask_sz":102,"bid_ct":1,"ask_ct":3}],"symbol":"TSLA"}
{"ts_recv":"2024-11-01T08:00:11.410540052Z","hd":{"ts_event":"2024-11-01T08:00:11.410374270Z","rtype":10,"publisher_id":2,"instrument_id":16244},"action":"C","side":"A","depth":3,"price":"252.400000000","size":1000,"flags":130,"ts_in_delta":165782,"sequence":313781,"levels":[{"bid_px":"250.110000000","ask_px":"250.940000000","bid_sz":50,"ask_sz":100,"bid_ct":1,"ask_ct":1},{"bid_px":"250.000000000","ask_px":"250.990000000","bid_sz":2,"ask_sz":50,"bid_ct":2,"ask_ct":1},{"bid_px":"249.930000000","ask_px":"252.300000000","bid_sz":10,"ask_sz":1000,"bid_ct":1,"ask_ct":1},{"bid_px":"249.800000000","ask_px":"253.650000000","bid_sz":199,"ask_sz":400,"bid_ct":1,"ask_ct":1},{"bid_px":"249.770000000","ask_px":"255.000000000","bid_sz":50,"ask_sz":85,"bid_ct":1,"ask_ct":2},{"bid_px":"249.700000000","ask_px":"260.000000000","bid_sz":1000,"ask_sz":48,"bid_ct":1,"ask_ct":1},{"bid_px":"249.600000000","ask_px":"262.660000000","bid_sz":1000,"ask_sz":56,"bid_ct":1,"ask_ct":1},{"bid_px":"248.500000000","ask_px":"264.940000000","bid_sz":40,"ask_sz":7,"bid_ct":1,"ask_ct":1},{"bid_px":"248.200000000","ask_px":"265.000000000","bid_sz":1000,"ask_sz":102,"bid_ct":1,"ask_ct":3},{"bid_px":"247.150000000","ask_px":"267.800000000","bid_sz":400,"ask_sz":30,"bid_ct":1,"ask_ct":1}],"symbol":"TSLA"}
{"ts_recv":"2024-11-01T08:00:11.588640971Z","hd":{"ts_event":"2024-11-01T08:00:11.588474530Z","rtype":10,"publisher_id":2,"instrument_id":16244},"action":"A","side":"A","depth":5,"price":"260.000000000","size":100,"flags":130,"ts_in_delta":166441,"sequence":314051,"levels":[{"bid_px":"250.110000000","ask_px":"250.940000000","bid_sz":50,"ask_sz":100,"bid_ct":1,"ask_ct":1},{"bid_px":"250.000000000","ask_px":"250.990000000","bid_sz":2,"ask_sz":50,"bid_ct":2,"ask_ct":1},{"bid_px":"249.930000000","ask_px":"252.300000000","bid_sz":10,"ask_sz":1000,"bid_ct":1,"ask_ct":1},{"bid_px":"249.800000000","ask_px":"253.650000000","bid_sz":199,"ask_sz":400,"bid_ct":1,"ask_ct":1},{"bid_px":"249.770000000","ask_px":"255.000000000","bid_sz":50,"ask_sz":85,"bid_ct":1,"ask_ct":2},{"bid_px":"249.700000000","ask_px":"260.000000000","bid_sz":1000,"ask_sz":148,"bid_ct":1,"ask_ct":2},{"bid_px":"249.600000000","ask_px":"262.660000000","bid_sz":1000,"ask_sz":56,"bid_ct":1,"ask_ct":1},{"bid_px":"248.500000000","ask_px":"264.940000000","bid_sz":40,"ask_sz":7,"bid_ct":1,"ask_ct":1},{"bid_px":"248.200000000","ask_px":"265.000000000","bid_sz":1000,"ask_sz":102,"bid_ct":1,"ask_ct":3},{"bid_px":"247.150000000","ask_px":"267.800000000","bid_sz":400,"ask_sz":30,"bid_ct":1,"ask_ct":1}],"symbol":"TSLA"}
{"ts_recv":"2024-11-01T08:00:11.716180528Z","hd":{"ts_event":"2024-11-01T08:00:11.716014319Z","rtype":10,"publisher_id":2,"instrument_id":16244},"action":"A","side":"A","depth":5,"price":"260.000000000","size":20,"flags":130,"ts_in_delta":166209,"sequence":314250,"levels":[{"bid_px":"250.110000000","ask_px":"250.940000000","bid_sz":50,"ask_sz":100,"bid_ct":1,"ask_ct":1},{"bid_px":"250.000000000","ask_px":"250.990000000","bid_sz":2,"ask_sz":50,"bid_ct":2,"ask_ct":1},{"bid_px":"249.930000000","ask_px":"252.300000000","bid_sz":10,"ask_sz":1000,"bid_ct":1,"ask_ct":1},{"bid_px":"249.800000000","ask_px":"253.650000000","bid_sz":199,"ask_sz":400,"bid_ct":1,"ask_ct":1},{"bid_px":"249.770000000","ask_px":"255.000000000","bid_sz":50,"ask_sz":85,"bid_ct":1,"ask_ct":2},{"bid_px":"249.700000000","ask_px":"260.000000000","bid_sz":1000,"ask_sz":168,"bid_ct":1,"ask_ct":3},{"bid_px":"249.600000000","ask_px":"262.660000000","bid_sz":1000,"ask_sz":56,"bid_ct":1,"ask_ct":1},{"bid_px":"248.500000000","ask_px":"264.940000000","bid_sz":40,"ask_sz":7,"bid_ct":1,"ask_ct":1},{"bid_px":"248.200000000","ask_px":"265.000000000","bid_sz":1000,"ask_sz":102,"bid_ct":1,"ask_ct":3},{"bid_px":"247.150000000","ask_px":"267.800000000","bid_sz":400,"ask_sz":30,"bid_ct":1,"ask_ct":1}],"symbol":"TSLA"}
{"ts_recv":"2024-11-01T08:00:11.744818545Z","hd":{"ts_event":"2024-11-01T08:00:11.744652546Z","rtype":10,"publisher_id":2,"instrument_id":16244},"action":"C","side":"B","depth":0,"price":"250.110000000","size":50,"flags":130,"ts_in_delta":165999,"sequence":314271,"levels":[{"bid_px":"250.000000000","ask_px":"250.940000000","bid_sz":2,"ask_sz":100,"bid_ct":2,"ask_ct":1},{"bid_px":"249.930000000","ask_px":"250.990000000","bid_sz":10,"ask_sz":50,"bid_ct":1,"ask_ct":1},{"bid_px":"249.800000000","ask_px":"252.300000000","bid_sz":199,"ask_sz":1000,"bid_ct":1,"ask_ct":1},{"bid_px":"249.770000000","ask_px":"253.650000000","bid_sz":50,"ask_sz":400,"bid_ct":1,"ask_ct":1},{"bid_px":"249.700000000","ask_px":"255.000000000","bid_sz":1000,"ask_sz":85,"bid_ct":1,"ask_ct":2},{"bid_px":"249.600000000","ask_px":"260.000000000","bid_sz":1000,"ask_sz":168,"bid_ct":1,"ask_ct":3},{"bid_px":"248.500000000","ask_px":"262.660000000","bid_sz":40,"ask_sz":56,"bid_ct":1,"ask_ct":1},{"bid_px":"248.200000000","ask_px":"264.940000000","bid_sz":1000,"ask_sz":7,"bid_ct":1,"ask_ct":1},{"bid_px":"247.150000000","ask_px":"265.000000000","bid_sz":400,"ask_sz":102,"bid_ct":1,"ask_ct":3},{"bid_px":"247.000000000","ask_px":"267.800000000","bid_sz":12,"ask_sz":30,"bid_ct":1,"ask_ct":1}],"symbol":"TSLA"}
{"ts_recv":"2024-11-01T08:00:11.744831009Z","hd":{"ts_event":"2024-11-01T08:00:11.744664963Z","rtype":10,"publisher_id":2,"instrument_id":16244},"action":"A","side":"B","depth":0,"price":"250.060000000","size":50,"flags":130,"ts_in_delta":166046,"sequence":314272,"levels":[{"bid_px":"250.060000000","ask_px":"250.940000000","bid_sz":50,"ask_sz":100,"bid_ct":1,"ask_ct":1},{"bid_px":"250.000000000","ask_px":"250.990000000","bid_sz":2,"ask_sz":50,"bid_ct":2,"ask_ct":1},{"bid_px":"249.930000000","ask_px":"252.300000000","bid_sz":10,"ask_sz":1000,"bid_ct":1,"ask_ct":1},{"bid_px":"249.800000000","ask_px":"253.650000000","bid_sz":199,"ask_sz":400,"bid_ct":1,"ask_ct":1},{"bid_px":"249.770000000","ask_px":"255.000000000","bid_sz":50,"ask_sz":85,"bid_ct":1,"ask_ct":2},{"bid_px":"249.700000000","ask_px":"260.000000000","bid_sz":1000,"ask_sz":168,"bid_ct":1,"ask_ct":3},{"bid_px":"249.600000000","ask_px":"262.660000000","bid_sz":1000,"ask_sz":56,"bid_ct":1,"ask_ct":1},{"bid_px":"248.500000000","ask_px":"264.940000000","bid_sz":40,"ask_sz":7,"bid_ct":1,"ask_ct":1},{"bid_px":"248.200000000","ask_px":"265.000000000","bid_sz":1000,"ask_sz":102,"bid_ct":1,"ask_ct":3},{"bid_px":"247.150000000","ask_px":"267.800000000","bid_sz":400,"ask_sz":30,"bid_ct":1,"ask_ct":1}],"symbol":"TSLA"}
{"ts_recv":"2024-11-01T08:00:11.744846096Z","hd":{"ts_event":"2024-11-01T08:00:11.744679696Z","rtype":10,"publisher_id":2,"instrument_id":16244},"action":"C","side":"B","depth":0,"price":"250.060000000","size":50,"flags":130,"ts_in_delta":166400,"sequence":314273,"levels":[{"bid_px":"250.000000000","ask_px":"250.940000000","bid_sz":2,"ask_sz":100,"bid_ct":2,"ask_ct":1},{"bid_px":"249.930000000","ask_px":"250.990000000","bid_sz":10,"ask_sz":50,"bid_ct":1,"ask_ct":1},{"bid_px":"249.800000000","ask_px":"252.300000000","bid_sz":199,"ask_sz":1000,"bid_ct":1,"ask_ct":1},{"bid_px":"249.770000000","ask_px":"253.650000000","bid_sz":50,"ask_sz":400,"bid_ct":1,"ask_ct":1},{"bid_px":"249.700000000","ask_px":"255.000000000","bid_sz":1000,"ask_sz":85,"bid_ct":1,"ask_ct":2},{"bid_px":"249.600000000","ask_px":"260.000000000","bid_sz":1000,"ask_sz":168,"bid_ct":1,"ask_ct":3},{"bid_px":"248.500000000","ask_px":"262.660000000","bid_sz":40,"ask_sz":56,"bid_ct":1,"ask_ct":1},{"bid_px":"248.200000000","ask_px":"264.940000000","bid_sz":1000,"ask_sz":7,"bid_ct":1,"ask_ct":1},{"bid_px":"247.150000000","ask_px":"265.000000000","bid_sz":400,"ask_sz":102,"bid_ct":1,"ask_ct":3},{"bid_px":"247.000000000","ask_px":"267.800000000","bid_sz":12,"ask_sz":30,"bid_ct":1,"ask_ct":1}],"symbol":"TSLA"}
{"ts_recv":"2024-11-01T08:00:11.798934057Z","hd":{"ts_event":"2024-11-01T08:00:11.798767560Z","rtype":10,"publisher_id":2,"instrument_id":16244},"action":"A","side":"B","depth":0,"price":"250.020000000","size":50,"flags":130,"ts_in_delta":166497,"sequence":314386,"levels":[{"bid_px":"250.020000000","ask_px":"250.940000000","bid_sz":50,"ask_sz":100,"bid_ct":1,"ask_ct":1},{"bid_px":"250.000000000","ask_px":"250.990000000","bid_sz":2,"ask_sz":50,"bid_ct":2,"ask_ct":1},{"bid_px":"249.930000000","ask_px":"252.300000000","bid_sz":10,"ask_sz":1000,"bid_ct":1,"ask_ct":1},{"bid_px":"249.800000000","ask_px":"253.650000000","bid_sz":199,"ask_sz":400,"bid_ct":1,"ask_ct":1},{"bid_px":"249.770000000","ask_px":"255.000000000","bid_sz":50,"ask_sz":85,"bid_ct":1,"ask_ct":2},{"bid_px":"249.700000000","ask_px":"260.000000000","bid_sz":1000,"ask_sz":168,"bid_ct":1,"ask_ct":3},{"bid_px":"249.600000000","ask_px":"262.660000000","bid_sz":1000,"ask_sz":56,"bid_ct":1,"ask_ct":1},{"bid_px":"248.500000000","ask_px":"264.940000000","bid_sz":40,"ask_sz":7,"bid_ct":1,"ask_ct":1},{"bid_px":"248.200000000","ask_px":"265.000000000","bid_sz":1000,"ask_sz":102,"bid_ct":1,"ask_ct":3},{"bid_px":"247.150000000","ask_px":"267.800000000","bid_sz":400,"ask_sz":30,"bid_ct":1,"ask_ct":1}],"symbol":"TSLA"}
{"ts_recv":"2024-11-01T08:00:11.838828055Z","hd":{"ts_event":"2024-11-01T08:00:11.838662245Z","rtype":10,"publisher_id":2,"instrument_id":16244},"action":"C","side":"A","depth":1,"price":"250.990000000","size":50,"flags":130,"ts_in_delta":165810,"sequence":314431,"levels":[{"bid_px":"250.020000000","ask_px":"250.940000000","bid_sz":50,"ask_sz":100,"bid_ct":1,"ask_ct":1},{"bid_px":"250.000000000","ask_px":"252.300000000","bid_sz":2,"ask_sz":1000,"bid_ct":2,"ask_ct":1},{"bid_px":"249.930000000","ask_px":"253.650000000","bid_sz":10,"ask_sz":400,"bid_ct":1,"ask_ct":1},{"bid_px":"249.800000000","ask_px":"255.000000000","bid_sz":199,"ask_sz":85,"bid_ct":1,"ask_ct":2},{"bid_px":"249.770000000","ask_px":"260.000000000","bid_sz":50,"ask_sz":168,"bid_ct":1,"ask_ct":3},{"bid_px":"249.700000000","ask_px":"262.660000000","bid_sz":1000,"ask_sz":56,"bid_ct":1,"ask_ct":1},{"bid_px":"249.600000000","ask_px":"264.940000000","bid_sz":1000,"ask_sz":7,"bid_ct":1,"ask_ct":1},{"bid_px":"248.500000000","ask_px":"265.000000000","bid_sz":40,"ask_sz":102,"bid_ct":1,"ask_ct":3},{"bid_px":"248.200000000","ask_px":"267.800000000","bid_sz":1000,"ask_sz":30,"bid_ct":1,"ask_ct":1},{"bid_px":"247.150000000","ask_px":"268.670000000","bid_sz":400,"ask_sz":100,"bid_ct":1,"ask_ct":1}],"symbol":"TSLA"}
{"ts_recv":"2024-11-01T08:00:11.839112275Z","hd":{"ts_event":"2024-11-01T08:00:11.838946435Z","rtype":10,"publisher_id":2,"instrument_id":16244},"action":"C","side":"A","depth":1,"price":"252.300000000","size":1000,"flags":130,"ts_in_delta":165840,"sequence":314437,"levels":[{"bid_px":"250.020000000","ask_px":"250.940000000","bid_sz":50,"ask_sz":100,"bid_ct":1,"ask_ct":1},{"bid_px":"250.000000000","ask_px":"253.650000000","bid_sz":2,"ask_sz":400,"bid_ct":2,"ask_ct":1},{"bid_px":"249.930000000","ask_px":"255.000000000","bid_sz":10,"ask_sz":85,"bid_ct":1,"ask_ct":2},{"bid_px":"249.800000000","ask_px":"260.000000000","bid_sz":199,"ask_sz":168,"bid_ct":1,"ask_ct":3},{"bid_px":"249.770000000","ask_px":"262.660000000","bid_sz":50,"ask_sz":56,"bid_ct":1,"ask_ct":1},{"bid_px":"249.700000000","ask_px":"264.940000000","bid_sz":1000,"ask_sz":7,"bid_ct":1,"ask_ct":1},{"bid_px":"249.600000000","ask_px":"265.000000000","bid_sz":1000,"ask_sz":102,"bid_ct":1,"ask_ct":3},{"bid_px":"248.500000000","ask_px":"267.800000000","bid_sz":40,"ask_sz":30,"bid_ct":1,"ask_ct":1},{"bid_px":"248.200000000","ask_px":"268.670000000","bid_sz":1000,"ask_sz":100,"bid_ct":1,"ask_ct":1},{"bid_px":"247.150000000","ask_px":"269.580000000","bid_sz":400,"ask_sz":100,"bid_ct":1,"ask_ct":1}],"symbol":"TSLA"}
{"ts_recv":"2024-11-01T08:00:11.839138765Z","hd":{"ts_event":"2024-11-01T08:00:11.838973149Z","rtype":10,"publisher_id":2,"instrument_id":16244},"action":"C","side":"B","depth":0,"price":"250.020000000","size":50,"flags":130,"ts_in_delta":165616,"sequence":314438,"levels":[{"bid_px":"250.000000000","ask_px":"250.940000000","bid_sz":2,"ask_sz":100,"bid_ct":2,"ask_ct":1},{"bid_px":"249.930000000","ask_px":"253.650000000","bid_sz":10,"ask_sz":400,"bid_ct":1,"ask_ct":1},{"bid_px":"249.800000000","ask_px":"255.000000000","bid_sz":199,"ask_sz":85,"bid_ct":1,"ask_ct":2},{"bid_px":"249.770000000","ask_px":"260.000000000","bid_sz":50,"ask_sz":168,"bid_ct":1,"ask_ct":3},{"bid_px":"249.700000000","ask_px":"262.660000000","bid_sz":1000,"ask_sz":56,"bid_ct":1,"ask_ct":1},{"bid_px":"249.600000000","ask_px":"264.940000000","bid_sz":1000,"ask_sz":7,"bid_ct":1,"ask_ct":1},{"bid_px":"248.500000000","ask_px":"265.000000000","bid_sz":40,"ask_sz":102,"bid_ct":1,"ask_ct":3},{"bid_px":"248.200000000","ask_px":"267.800000000","bid_sz":1000,"ask_sz":30,"bid_ct":1,"ask_ct":1},{"bid_px":"247.150000000","ask_px":"268.670000000","bid_sz":400,"ask_sz":100,"bid_ct":1,"ask_ct":1},{"bid_px":"247.000000000","ask_px":"269.580000000","bid_sz":12,"ask_sz":100,"bid_ct":1,"ask_ct":1}],"symbol":"TSLA"}
{"ts_recv":"2024-11-01T08:00:11.839607412Z","hd":{"ts_event":"2024-11-01T08:00:11.839441795Z","rtype":10,"publisher_id":2,"instrument_id":16244},"action":"C","side":"A","depth":0,"price":"250.940000000","size":100,"flags":130,"ts_in_delta":165617,"sequence":314441,"levels":[{"bid_px":"250.000000000","ask_px":"253.650000000","bid_sz":2,"ask_sz":400,"bid_ct":2,"ask_ct":1},{"bid_px":"249.930000000","ask_px":"255.000000000","bid_sz":10,"ask_sz":85,"bid_ct":1,"ask_ct":2},{"bid_px":"249.800000000","ask_px":"260.000000000","bid_sz":199,"ask_sz":168,"bid_ct":1,"ask_ct":3},{"bid_px":"249.770000000","ask_px":"262.660000000","bid_sz":50,"ask_sz":56,"bid_ct":1,"ask_ct":1},{"bid_px":"249.700000000","ask_px":"264.940000000","bid_sz":1000,"ask_sz":7,"bid_ct":1,"ask_ct":1},{"bid_px":"249.600000000","ask_px":"265.000000000","bid_sz":1000,"ask_sz":102,"bid_ct":1,"ask_ct":3},{"bid_px":"248.500000000","ask_px":"267.800000000","bid_sz":40,"ask_sz":30,"bid_ct":1,"ask_ct":1},{"bid_px":"248.200000000","ask_px":"268.670000000","bid_sz":1000,"ask_sz":100,"bid_ct":1,"ask_ct":1},{"bid_px":"247.150000000","ask_px":"269.580000000","bid_sz":400,"ask_sz":100,"bid_ct":1,"ask_ct":1},{"bid_px":"247.000000000","ask_px":"270.000000000","bid_sz":12,"ask_sz":118,"bid_ct":1,"ask_ct":3}],"symbol":"TSLA"}
{"ts_recv":"2024-11-01T08:00:11.839620531Z","hd":{"ts_event":"2024-11-01T08:00:11.839454020Z","rtype":10,"publisher_id":2,"instrument_id":16244},"action":"A","side":"A","depth":0,"price":"250.980000000","size":100,"flags":130,"ts_in_delta":166511,"sequence":314442,"levels":[{"bid_px":"250.000000000","ask_px":"250.980000000","bid_sz":2,"ask_sz":100,"bid_ct":2,"ask_ct":1},{"bid_px":"249.930000000","ask_px":"253.650000000","bid_sz":10,"ask_sz":400,"bid_ct":1,"ask_ct":1},{"bid_px":"249.800000000","ask_px":"255.000000000","bid_sz":199,"ask_sz":85,"bid_ct":1,"ask_ct":2},{"bid_px":"249.770000000","ask_px":"260.000000000","bid_sz":50,"ask_sz":168,"bid_ct":1,"ask_ct":3},{"bid_px":"249.700000000","ask_px":"262.660000000","bid_sz":1000,"ask_sz":56,"bid_ct":1,"ask_ct":1},{"bid_px":"249.600000000","ask_px":"264.940000000","bid_sz":1000,"ask_sz":7,"bid_ct":1,"ask_ct":1},{"bid_px":"248.500000000","ask_px":"265.000000000","bid_sz":40,"ask_sz":102,"bid_ct":1,"ask_ct":3},{"bid_px":"248.200000000","ask_px":"267.800000000","bid_sz":1000,"ask_sz":30,"bid_ct":1,"ask_ct":1},{"bid_px":"247.150000000","ask_px":"268.670000000","bid_sz":400,"ask_sz":100,"bid_ct":1,"ask_ct":1},{"bid_px":"247.000000000","ask_px":"269.580000000","bid_sz":12,"ask_sz":100,"bid_ct":1,"ask_ct":1}],"symbol":"TSLA"}
{"ts_recv":"2024-11-01T08:00:11.839848675Z","hd":{"ts_event":"2024-11-01T08:00:11.839683089Z","rtype":10,"publisher_id":2,"instrument_id":16244},"action":"C","side":"A","depth":0,"price":"250.980000000","size":100,"flags":130,"ts_in_delta":165586,"sequence":314443,"levels":[{"bid_px":"250.000000000","ask_px":"253.650000000","bid_sz":2,"ask_sz":400,"bid_ct":2,"ask_ct":1},{"bid_px":"249.930000000","ask_px":"255.000000000","bid_sz":10,"ask_sz":85,"bid_ct":1,"ask_ct":2},{"bid_px":"249.800000000","ask_px":"260.000000000","bid_sz":199,"ask_sz":168,"bid_ct":1,"ask_ct":3},{"bid_px":"249.770000000","ask_px":"262.660000000","bid_sz":50,"ask_sz":56,"bid_ct":1,"ask_ct":1},{"bid_px":"249.700000000","ask_px":"264.940000000","bid_sz":1000,"ask_sz":7,"bid_ct":1,"ask_ct":1},{"bid_px":"249.600000000","ask_px":"265.000000000","bid_sz":1000,"ask_sz":102,"bid_ct":1,"ask_ct":3},{"bid_px":"248.500000000","ask_px":"267.800000000","bid_sz":40,"ask_sz":30,"bid_ct":1,"ask_ct":1},{"bid_px":"248.200000000","ask_px":"268.670000000","bid_sz":1000,"ask_sz":100,"bid_ct":1,"ask_ct":1},{"bid_px":"247.150000000","ask_px":"269.580000000","bid_sz":400,"ask_sz":100,"bid_ct":1,"ask_ct":1},{"bid_px":"247.000000000","ask_px":"270.000000000","bid_sz":12,"ask_sz":118,"bid_ct":1,"ask_ct":3}],"symbol":"TSLA"}
{"ts_recv":"2024-11-01T08:00:11.839861372Z","hd":{"ts_event":"2024-11-01T08:00:11.839695448Z","rtype":10,"publisher_id":2,"instrument_id":16244},"action":"A","side":"A","depth":0,"price":"251.010000000","size":100,"flags":130,"ts_in_delta":165924,"sequence":314444,"levels":[{"bid_px":"250.000000000","ask_px":"251.010000000","bid_sz":2,"ask_sz":100,"bid_ct":2,"ask_ct":1},{"bid_px":"249.930000000","ask_px":"253.650000000","bid_sz":10,"ask_sz":400,"bid_ct":1,"ask_ct":1},{"bid_px":"249.800000000","ask_px":"255.000000000","bid_sz":199,"ask_sz":85,"bid_ct":1,"ask_ct":2},{"bid_px":"249.770000000","ask_px":"260.000000000","bid_sz":50,"ask_sz":168,"bid_ct":1,"ask_ct":3},{"bid_px":"249.700000000","ask_px":"262.660000000","bid_sz":1000,"ask_sz":56,"bid_ct":1,"ask_ct":1},{"bid_px":"249.600000000","ask_px":"264.940000000","bid_sz":1000,"ask_sz":7,"bid_ct":1,"ask_ct":1},{"bid_px":"248.500000000","ask_px":"265.000000000","bid_sz":40,"ask_sz":102,"bid_ct":1,"ask_ct":3},{"bid_px":"248.200000000","ask_px":"267.800000000","bid_sz":1000,"ask_sz":30,"bid_ct":1,"ask_ct":1},{"bid_px":"247.150000000","ask_px":"268.670000000","bid_sz":400,"ask_sz":100,"bid_ct":1,"ask_ct":1},{"bid_px":"247.000000000","ask_px":"269.580000000","bid_sz":12,"ask_sz":100,"bid_ct":1,"ask_ct":1}],"symbol":"TSLA"}
{"ts_recv":"2024-11-01T08:00:11.840870983Z","hd":{"ts_event":"2024-11-01T08:00:11.840705256Z","rtype":10,"publisher_id":2,"instrument_id":16244},"action":"C","side":"A","depth":0,"price":"251.010000000","size":100,"flags":130,"ts_in_delta":165727,"sequence":314447,"levels":[{"bid_px":"250.000000000","ask_px":"253.650000000","bid_sz":2,"ask_sz":400,"bid_ct":2,"ask_ct":1},{"bid_px":"249.930000000","ask_px":"255.000000000","bid_sz":10,"ask_sz":85,"bid_ct":1,"ask_ct":2},{"bid_px":"249.800000000","ask_px":"260.000000000","bid_sz":199,"ask_sz":168,"bid_ct":1,"ask_ct":3},{"bid_px":"249.770000000","ask_px":"262.660000000","bid_sz":50,"ask_sz":56,"bid_ct":1,"ask_ct":1},{"bid_px":"249.700000000","ask_px":"264.940000000","bid_sz":1000,"ask_sz":7,"bid_ct":1,"ask_ct":1},{"bid_px":"249.600000000","ask_px":"265.000000000","bid_sz":1000,"ask_sz":102,"bid_ct":1,"ask_ct":3},{"bid_px":"248.500000000","ask_px":"267.800000000","bid_sz":40,"ask_sz":30,"bid_ct":1,"ask_ct":1},{"bid_px":"248.200000000","ask_px":"268.670000000","bid_sz":1000,"ask_sz":100,"bid_ct":1,"ask_ct":1},{"bid_px":"247.150000000","ask_px":"269.580000000","bid_sz":400,"ask_sz":100,"bid_ct":1,"ask_ct":1},{"bid_px":"247.000000000","ask_px":"270.000000000","bid_sz":12,"ask_sz":118,"bid_ct":1,"ask_ct":3}],"symbol":"TSLA"}
{"ts_recv":"2024-11-01T08:00:11.840884133Z","hd":{"ts_event":"2024-11-01T08:00:11.840718163Z","rtype":10,"publisher_id":2,"instrument_id":16244},"action":"A","side":"A","depth":0,"price":"251.040000000","size":100,"flags":130,"ts_in_delta":165970,"sequence":314448,"levels":[{"bid_px":"250.000000000","ask_px":"251.040000000","bid_sz":2,"ask_sz":100,"bid_ct":2,"ask_ct":1},{"bid_px":"249.930000000","ask_px":"253.650000000","bid_sz":10,"ask_sz":400,"bid_ct":1,"ask_ct":1},{"bid_px":"249.800000000","ask_px":"255.000000000","bid_sz":199,"ask_sz":85,"bid_ct":1,"ask_ct":2},{"bid_px":"249.770000000","ask_px":"260.000000000","bid_sz":50,"ask_sz":168,"bid_ct":1,"ask_ct":3},{"bid_px":"249.700000000","ask_px":"262.660000000","bid_sz":1000,"ask_sz":56,"bid_ct":1,"ask_ct":1},{"bid_px":"249.600000000","ask_px":"264.940000000","bid_sz":1000,"ask_sz":7,"bid_ct":1,"ask_ct":1},{"bid_px":"248.500000000","ask_px":"265.000000000","bid_sz":40,"ask_sz":102,"bid_ct":1,"ask_ct":3},{"bid_px":"248.200000000","ask_px":"267.800000000","bid_sz":1000,"ask_sz":30,"bid_ct":1,"ask_ct":1},{"bid_px":"247.150000000","ask_px":"268.670000000","bid_sz":400,"ask_sz":100,"bid_ct":1,"ask_ct":1},{"bid_px":"247.000000000","ask_px":"269.580000000","bid_sz":12,"ask_sz":100,"bid_ct":1,"ask_ct":1}],"symbol":"TSLA"}
{"ts_recv":"2024-11-01T08:00:11.841111394Z","hd":{"ts_event":"2024-11-01T08:00:11.840944632Z","rtype":10,"publisher_id":2,"instrument_id":16244},"action":"C","side":"A","depth":0,"price":"251.040000000","size":100,"flags":130,"ts_in_delta":166762,"sequence":314451,"levels":[{"bid_px":"250.000000000","ask_px":"253.650000000","bid_sz":2,"ask_sz":400,"bid_ct":2,"ask_ct":1},{"bid_px":"249.930000000","ask_px":"255.000000000","bid_sz":10,"ask_sz":85,"bid_ct":1,"ask_ct":2},{"bid_px":"249.800000000","ask_px":"260.000000000","bid_sz":199,"ask_sz":168,"bid_ct":1,"ask_ct":3},{"bid_px":"249.770000000","ask_px":"262.660000000","bid_sz":50,"ask_sz":56,"bid_ct":1,"ask_ct":1},{"bid_px":"249.700000000","ask_px":"264.940000000","bid_sz":1000,"ask_sz":7,"bid_ct":1,"ask_ct":1},{"bid_px":"249.600000000","ask_px":"265.000000000","bid_sz":1000,"ask_sz":102,"bid_ct":1,"ask_ct":3},{"bid_px":"248.500000000","ask_px":"267.800000000","bid_sz":40,"ask_sz":30,"bid_ct":1,"ask_ct":1},{"bid_px":"248.200000000","ask_px":"268.670000000","bid_sz":1000,"ask_sz":100,"bid_ct":1,"ask_ct":1},{"bid_px":"247.150000000","ask_px":"269.580000000","bid_sz":400,"ask_sz":100,"bid_ct":1,"ask_ct":1},{"bid_px":"247.000000000","ask_px":"270.000000000","bid_sz":12,"ask_sz":118,"bid_ct":1,"ask_ct":3}],"symbol":"TSLA"}
{"ts_recv":"2024-11-01T08:00:11.841122521Z","hd":{"ts_event":"2024-11-01T08:00:11.840956689Z","rtype":10,"publisher_id":2,"instrument_id":16244},"action":"A","side":"A","depth":0,"price":"251.070000000","size":100,"flags":130,"ts_in_delta":165832,"sequence":314452,"levels":[{"bid_px":"250.000000000","ask_px":"251.070000000","bid_sz":2,"ask_sz":100,"bid_ct":2,"ask_ct":1},{"bid_px":"249.930000000","ask_px":"253.650000000","bid_sz":10,"ask_sz":400,"bid_ct":1,"ask_ct":1},{"bid_px":"249.800000000","ask_px":"255.000000000","bid_sz":199,"ask_sz":85,"bid_ct":1,"ask_ct":2},{"bid_px":"249.770000000","ask_px":"260.000000000","bid_sz":50,"ask_sz":168,"bid_ct":1,"ask_ct":3},{"bid_px":"249.700000000","ask_px":"262.660000000","bid_sz":1000,"ask_sz":56,"bid_ct":1,"ask_ct":1},{"bid_px":"249.600000000","ask_px":"264.940000000","bid_sz":1000,"ask_sz":7,"bid_ct":1,"ask_ct":1},{"bid_px":"248.500000000","ask_px":"265.000000000","bid_sz":40,"ask_sz":102,"bid_ct":1,"ask_ct":3},{"bid_px":"248.200000000","ask_px":"267.800000000","bid_sz":1000,"ask_sz":30,"bid_ct":1,"ask_ct":1},{"bid_px":"247.150000000","ask_px":"268.670000000","bid_sz":400,"ask_sz":100,"bid_ct":1,"ask_ct":1},{"bid_px":"247.000000000","ask_px":"269.580000000","bid_sz":12,"ask_sz":100,"bid_ct":1,"ask_ct":1}],"symbol":"TSLA"}
{"ts_recv":"2024-11-01T08:00:11.841196323Z","hd":{"ts_event":"2024-11-01T08:00:11.841030767Z","rtype":10,"publisher_id":2,"instrument_id":16244},"action":"C","side":"A","depth":0,"price":"251.070000000","size":100,"flags":130,"ts_in_delta":165556,"sequence":314455,"levels":[{"bid_px":"250.000000000","ask_px":"253.650000000","bid_sz":2,"ask_sz":400,"bid_ct":2,"ask_ct":1},{"bid_px":"249.930000000","ask_px":"255.000000000","bid_sz":10,"ask_sz":85,"bid_ct":1,"ask_ct":2},{"bid_px":"249.800000000","ask_px":"260.000000000","bid_sz":199,"ask_sz":168,"bid_ct":1,"ask_ct":3},{"bid_px":"249.770000000","ask_px":"262.660000000","bid_sz":50,"ask_sz":56,"bid_ct":1,"ask_ct":1},{"bid_px":"249.700000000","ask_px":"264.940000000","bid_sz":1000,"ask_sz":7,"bid_ct":1,"ask_ct":1},{"bid_px":"249.600000000","ask_px":"265.000000000","bid_sz":1000,"ask_sz":102,"bid_ct":1,"ask_ct":3},{"bid_px":"248.500000000","ask_px":"267.800000000","bid_sz":40,"ask_sz":30,"bid_ct":1,"ask_ct":1},{"bid_px":"248.200000000","ask_px":"268.670000000","bid_sz":1000,"ask_sz":100,"bid_ct":1,"ask_ct":1},{"bid_px":"247.150000000","ask_px":"269.580000000","bid_sz":400,"ask_sz":100,"bid_ct":1,"ask_ct":1},{"bid_px":"247.000000000","ask_px":"270.000000000","bid_sz":12,"ask_sz":118,"bid_ct":1,"ask_ct":3}],"symbol":"TSLA"}
{"ts_recv":"2024-11-01T08:00:11.841209194Z","hd":{"ts_event":"2024-11-01T08:00:11.841043022Z","rtype":10,"publisher_id":2,"instrument_id":16244},"action":"A","side":"A","depth":0,"price":"251.100000000","size":100,"flags":130,"ts_in_delta":166172,"sequence":314456,"levels":[{"bid_px":"250.000000000","ask_px":"251.100000000","bid_sz":2,"ask_sz":100,"bid_ct":2,"ask_ct":1},{"bid_px":"249.930000000","ask_px":"253.650000000","bid_sz":10,"ask_sz":400,"bid_ct":1,"ask_ct":1},{"bid_px":"249.800000000","ask_px":"255.000000000","bid_sz":199,"ask_sz":85,"bid_ct":1,"ask_ct":2},{"bid_px":"249.770000000","ask_px":"260.000000000","bid_sz":50,"ask_sz":168,"bid_ct":1,"ask_ct":3},{"bid_px":"249.700000000","ask_px":"262.660000000","bid_sz":1000,"ask_sz":56,"bid_ct":1,"ask_ct":1},{"bid_px":"249.600000000","ask_px":"264.940000000","bid_sz":1000,"ask_sz":7,"bid_ct":1,"ask_ct":1},{"bid_px":"248.500000000","ask_px":"265.000000000","bid_sz":40,"ask_sz":102,"bid_ct":1,"ask_ct":3},{"bid_px":"248.200000000","ask_px":"267.800000000","bid_sz":1000,"ask_sz":30,"bid_ct":1,"ask_ct":1},{"bid_px":"247.150000000","ask_px":"268.670000000","bid_sz":400,"ask_sz":100,"bid_ct":1,"ask_ct":1},{"bid_px":"247.000000000","ask_px":"269.580000000","bid_sz":12,"ask_sz":100,"bid_ct":1,"ask_ct":1}],"symbol":"TSLA"}
{"ts_recv":"2024-11-01T08:00:11.841459071Z","hd":{"ts_event":"2024-11-01T08:00:11.841293294Z","rtype":10,"publisher_id":2,"instrument_id":16244},"action":"C","side":"A","depth":0,"price":"251.100000000","size":100,"flags":130,"ts_in_delta":165777,"sequence":314457,"levels":[{"bid_px":"250.000000000","ask_px":"253.650000000","bid_sz":2,"ask_sz":400,"bid_ct":2,"ask_ct":1},{"bid_px":"249.930000000","ask_px":"255.000000000","bid_sz":10,"ask_sz":85,"bid_ct":1,"ask_ct":2},{"bid_px":"249.800000000","ask_px":"260.000000000","bid_sz":199,"ask_sz":168,"bid_ct":1,"ask_ct":3},{"bid_px":"249.770000000","ask_px":"262.660000000","bid_sz":50,"ask_sz":56,"bid_ct":1,"ask_ct":1},{"bid_px":"249.700000000","ask_px":"264.940000000","bid_sz":1000,"ask_sz":7,"bid_ct":1,"ask_ct":1},{"bid_px":"249.600000000","ask_px":"265.000000000","bid_sz":1000,"ask_sz":102,"bid_ct":1,"ask_ct":3},{"bid_px":"248.500000000","ask_px":"267.800000000","bid_sz":40,"ask_sz":30,"bid_ct":1,"ask_ct":1},{"bid_px":"248.200000000","ask_px":"268.670000000","bid_sz":1000,"ask_sz":100,"bid_ct":1,"ask_ct":1},{"bid_px":"247.150000000","ask_px":"269.580000000","bid_sz":400,"ask_sz":100,"bid_ct":1,"ask_ct":1},{"bid_px":"247.000000000","ask_px":"270.000000000","bid_sz":12,"ask_sz":118,"bid_ct":1,"ask_ct":3}],"symbol":"TSLA"}
{"ts_recv":"2024-11-01T08:00:11.841471325Z","hd":{"ts_event":"2024-11-01T08:00:11.841304887Z","rtype":10,"publisher_id":2,"instrument_id":16244},"action":"A","side":"A","depth":0,"price":"251.120000000","size":100,"flags":130,"ts_in_delta":166438,"sequence":314458,"levels":[{"bid_px":"250.000000000","ask_px":"251.120000000","bid_sz":2,"ask_sz":100,"bid_ct":2,"ask_ct":1},{"bid_px":"249.930000000","ask_px":"253.650000000","bid_sz":10,"ask_sz":400,"bid_ct":1,"ask_ct":1},{"bid_px":"249.800000000","ask_px":"255.000000000","bid_sz":199,"ask_sz":85,"bid_ct":1,"ask_ct":2},{"bid_px":"249.770000000","ask_px":"260.000000000","bid_sz":50,"ask_sz":168,"bid_ct":1,"ask_ct":3},{"bid_px":"249.700000000","ask_px":"262.660000000","bid_sz":1000,"ask_sz":56,"bid_ct":1,"ask_ct":1},{"bid_px":"249.600000000","ask_px":"264.940000000","bid_sz":1000,"ask_sz":7,"bid_ct":1,"ask_ct":1},{"bid_px":"248.500000000","ask_px":"265.000000000","bid_sz":40,"ask_sz":102,"bid_ct":1,"ask_ct":3},{"bid_px":"248.200000000","ask_px":"267.800000000","bid_sz":1000,"ask_sz":30,"bid_ct":1,"ask_ct":1},{"bid_px":"247.150000000","ask_px":"268.670000000","bid_sz":400,"ask_sz":100,"bid_ct":1,"ask_ct":1},{"bid_px":"247.000000000","ask_px":"269.580000000","bid_sz":12,"ask_sz":100,"bid_ct":1,"ask_ct":1}],"symbol":"TSLA"}
{"ts_recv":"2024-11-01T08:00:11.849201522Z","hd":{"ts_event":"2024-11-01T08:00:11.849035558Z","rtype":10,"publisher_id":2,"instrument_id":16244},"action":"A","side":"B","depth":6,"price":"248.800000000","size":1000,"flags":130,"ts_in_delta":165964,"sequence":314473,"levels":[{"bid_px":"250.000000000","ask_px":"251.120000000","bid_sz":2,"ask_sz":100,"bid_ct":2,"ask_ct":1},{"bid_px":"249.930000000","ask_px":"253.650000000","bid_sz":10,"ask_sz":400,"bid_ct":1,"ask_ct":1},{"bid_px":"249.800000000","ask_px":"255.000000000","bid_sz":199,"ask_sz":85,"bid_ct":1,"ask_ct":2},{"bid_px":"249.770000000","ask_px":"260.000000000","bid_sz":50,"ask_sz":168,"bid_ct":1,"ask_ct":3},{"bid_px":"249.700000000","ask_px":"262.660000000","bid_sz":1000,"ask_sz":56,"bid_ct":1,"ask_ct":1},{"bid_px":"249.600000000","ask_px":"264.940000000","bid_sz":1000,"ask_sz":7,"bid_ct":1,"ask_ct":1},{"bid_px":"248.800000000","ask_px":"265.000000000","bid_sz":1000,"ask_sz":102,"bid_ct":1,"ask_ct":3},{"bid_px":"248.500000000","ask_px":"267.800000000","bid_sz":40,"ask_sz":30,"bid_ct":1,"ask_ct":1},{"bid_px":"248.200000000","ask_px":"268.670000000","bid_sz":1000,"ask_sz":100,"bid_ct":1,"ask_ct":1},{"bid_px":"247.150000000","ask_px":"269.580000000","bid_sz":400,"ask_sz":100,"bid_ct":1,"ask_ct":1}],"symbol":"TSLA"}
{"ts_recv":"2024-11-01T08:00:11.849228369Z","hd":{"ts_event":"2024-11-01T08:00:11.849062607Z","rtype":10,"publisher_id":2,"instrument_id":16244},"action":"C","side":"B","depth":8,"price":"248.200000000","size":1000,"flags":130,"ts_in_delta":165762,"sequence":314474,"levels":[{"bid_px":"250.000000000","ask_px":"251.120000000","bid_sz":2,"ask_sz":100,"bid_ct":2,"ask_ct":1},{"bid_px":"249.930000000","ask_px":"253.650000000","bid_sz":10,"ask_sz":400,"bid_ct":1,"ask_ct":1},{"bid_px":"249.800000000","ask_px":"255.000000000","bid_sz":199,"ask_sz":85,"bid_ct":1,"ask_ct":2},{"bid_px":"249.770000000","ask_px":"260.000000000","bid_sz":50,"ask_sz":168,"bid_ct":1,"ask_ct":3},{"bid_px":"249.700000000","ask_px":"262.660000000","bid_sz":1000,"ask_sz":56,"bid_ct":1,"ask_ct":1},{"bid_px":"249.600000000","ask_px":"264.940000000","bid_sz":1000,"ask_sz":7,"bid_ct":1,"ask_ct":1},{"bid_px":"248.800000000","ask_px":"265.000000000","bid_sz":1000,"ask_sz":102,"bid_ct":1,"ask_ct":3},{"bid_px":"248.500000000","ask_px":"267.800000000","bid_sz":40,"ask_sz":30,"bid_ct":1,"ask_ct":1},{"bid_px":"247.150000000","ask_px":"268.670000000","bid_sz":400,"ask_sz":100,"bid_ct":1,"ask_ct":1},{"bid_px":"247.000000000","ask_px":"269.580000000","bid_sz":12,"ask_sz":100,"bid_ct":1,"ask_ct":1}],"symbol":"TSLA"}
{"ts_recv":"2024-11-01T08:00:11.849293502Z","hd":{"ts_event":"2024-11-01T08:00:11.849127303Z","rtype":10,"publisher_id":2,"instrument_id":16244},"action":"A","side":"A","depth":1,"price":"252.400000000","size":1000,"flags":130,"ts_in_delta":166199,"sequence":314475,"levels":[{"bid_px":"250.000000000","ask_px":"251.120000000","bid_sz":2,"ask_sz":100,"bid_ct":2,"ask_ct":1},{"bid_px":"249.930000000","ask_px":"252.400000000","bid_sz":10,"ask_sz":1000,"bid_ct":1,"ask_ct":1},{"bid_px":"249.800000000","ask_px":"253.650000000","bid_sz":199,"ask_sz":400,"bid_ct":1,"ask_ct":1},{"bid_px":"249.770000000","ask_px":"255.000000000","bid_sz":50,"ask_sz":85,"bid_ct":1,"ask_ct":2},{"bid_px":"249.700000000","ask_px":"260.000000000","bid_sz":1000,"ask_sz":168,"bid_ct":1,"ask_ct":3},{"bid_px":"249.600000000","ask_px":"262.660000000","bid_sz":1000,"ask_sz":56,"bid_ct":1,"ask_ct":1},{"bid_px":"248.800000000","ask_px":"264.940000000","bid_sz":1000,"ask_sz":7,"bid_ct":1,"ask_ct":1},{"bid_px":"248.500000000","ask_px":"265.000000000","bid_sz":40,"ask_sz":102,"bid_ct":1,"ask_ct":3},{"bid_px":"247.150000000","ask_px":"267.800000000","bid_sz":400,"ask_sz":30,"bid_ct":1,"ask_ct":1},{"bid_px":"247.000000000","ask_px":"268.670000000","bid_sz":12,"ask_sz":100,"bid_ct":1,"ask_ct":1}],"symbol":"TSLA"}
{"ts_recv":"2024-11-01T08:00:11.876397328Z","hd":{"ts_event":"2024-11-01T08:00:11.876231653Z","rtype":10,"publisher_id":2,"instrument_id":16244},"action":"C","side":"B","depth":6,"price":"248.800000000","size":1000,"flags":130,"ts_in_delta":165675,"sequence":314499,"levels":[{"bid_px":"250.000000000","ask_px":"251.120000000","bid_sz":2,"ask_sz":100,"bid_ct":2,"ask_ct":1},{"bid_px":"249.930000000","ask_px":"252.400000000","bid_sz":10,"ask_sz":1000,"bid_ct":1,"ask_ct":1},{"bid_px":"249.800000000","ask_px":"253.650000000","bid_sz":199,"ask_sz":400,"bid_ct":1,"ask_ct":1},{"bid_px":"249.770000000","ask_px":"255.000000000","bid_sz":50,"ask_sz":85,"bid_ct":1,"ask_ct":2},{"bid_px":"249.700000000","ask_px":"260.000000000","bid_sz":1000,"ask_sz":168,"bid_ct":1,"ask_ct":3},{"bid_px":"249.600000000","ask_px":"262.660000000","bid_sz":1000,"ask_sz":56,"bid_ct":1,"ask_ct":1},{"bid_px":"248.500000000","ask_px":"264.940000000","bid_sz":40,"ask_sz":7,"bid_ct":1,"ask_ct":1},{"bid_px":"247.150000000","ask_px":"265.000000000","bid_sz":400,"ask_sz":102,"bid_ct":1,"ask_ct":3},{"bid_px":"247.000000000","ask_px":"267.800000000","bid_sz":12,"ask_sz":30,"bid_ct":1,"ask_ct":1},{"bid_px":"246.000000000","ask_px":"268.670000000","bid_sz":4,"ask_sz":100,"bid_ct":1,"ask_ct":1}],"symbol":"TSLA"}
{"ts_recv":"2024-11-01T08:00:11.876545666Z","hd":{"ts_event":"2024-11-01T08:00:11.876379447Z","rtype":10,"publisher_id":2,"instrument_id":16244},"action":"C","side":"B","depth":4,"price":"249.600000000","size":1000,"flags":130,"ts_in_delta":166219,"sequence":314501,"levels":[{"bid_px":"250.000000000","ask_px":"251.120000000","bid_sz":2,"ask_sz":100,"bid_ct":2,"ask_ct":1},{"bid_px":"249.930000000","ask_px":"252.400000000","bid_sz":10,"ask_sz":1000,"bid_ct":1,"ask_ct":1},{"bid_px":"249.800000000","ask_px":"253.650000000","bid_sz":199,"ask_sz":400,"bid_ct":1,"ask_ct":1},{"bid_px":"249.770000000","ask_px":"255.000000000","bid_sz":50,"ask_sz":85,"bid_ct":1,"ask_ct":2},{"bid_px":"248.500000000","ask_px":"260.000000000","bid_sz":40,"ask_sz":168,"bid_ct":1,"ask_ct":3},{"bid_px":"247.150000000","ask_px":"262.660000000","bid_sz":400,"ask_sz":56,"bid_ct":1,"ask_ct":1},{"bid_px":"247.000000000","ask_px":"264.940000000","bid_sz":12,"ask_sz":7,"bid_ct":1,"ask_ct":1},{"bid_px":"246.000000000","ask_px":"265.000000000","bid_sz":4,"ask_sz":102,"bid_ct":1,"ask_ct":3},{"bid_px":"245.000000000","ask_px":"267.800000000","bid_sz":115,"ask_sz":30,"bid_ct":3,"ask_ct":1},{"bid_px":"243.200000000","ask_px":"268.670000000","bid_sz":15,"ask_sz":100,"bid_ct":1,"ask_ct":1}],"symbol":"TSLA"}
{"ts_recv":"2024-11-01T08:00:11.887224459Z","hd":{"ts_event":"2024-11-01T08:00:11.887058146Z","rtype":10,"publisher_id":2,"instrument_id":16244},"action":"A","side":"B","depth":4,"price":"249.700000000","size":1000,"flags":130,"ts_in_delta":166313,"sequence":314532,"levels":[{"bid_px":"250.000000000","ask_px":"251.120000000","bid_sz":2,"ask_sz":100,"bid_ct":2,"ask_ct":1},{"bid_px":"249.930000000","ask_px":"252.400000000","bid_sz":10,"ask_sz":1000,"bid_ct":1,"ask_ct":1},{"bid_px":"249.800000000","ask_px":"253.650000000","bid_sz":199,"ask_sz":400,"bid_ct":1,"ask_ct":1},{"bid_px":"249.770000000","ask_px":"255.000000000","bid_sz":50,"ask_sz":85,"bid_ct":1,"ask_ct":2},{"bid_px":"249.700000000","ask_px":"260.000000000","bid_sz":1000,"ask_sz":168,"bid_ct":1,"ask_ct":3},{"bid_px":"248.500000000","ask_px":"262.660000000","bid_sz":40,"ask_sz":56,"bid_ct":1,"ask_ct":1},{"bid_px":"247.150000000","ask_px":"264.940000000","bid_sz":400,"ask_sz":7,"bid_ct":1,"ask_ct":1},{"bid_px":"247.000000000","ask_px":"265.000000000","bid_sz":12,"ask_sz":102,"bid_ct":1,"ask_ct":3},{"bid_px":"246.000000000","ask_px":"267.800000000","bid_sz":4,"ask_sz":30,"bid_ct":1,"ask_ct":1},{"bid_px":"245.000000000","ask_px":"268.670000000","bid_sz":115,"ask_sz":100,"bid_ct":3,"ask_ct":1}],"symbol":"TSLA"}
{"ts_recv":"2024-11-01T08:00:11.900500040Z","hd":{"ts_event":"2024-11-01T08:00:11.900334458Z","rtype":10,"publisher_id":2,"instrument_id":16244},"action":"C","side":"B","depth":4,"price":"249.700000000","size":1000,"flags":130,"ts_in_delta":165582,"sequence":314541,"levels":[{"bid_px":"250.000000000","ask_px":"251.120000000","bid_sz":2,"ask_sz":100,"bid_ct":2,"ask_ct":1},{"bid_px":"249.930000000","ask_px":"252.400000000","bid_sz":10,"ask_sz":1000,"bid_ct":1,"ask_ct":1},{"bid_px":"249.800000000","ask_px":"253.650000000","bid_sz":199,"ask_sz":400,"bid_ct":1,"ask_ct":1},{"bid_px":"249.770000000","ask_px":"255.000000000","bid_sz":50,"ask_sz":85,"bid_ct":1,"ask_ct":2},{"bid_px":"248.500000000","ask_px":"260.000000000","bid_sz":40,"ask_sz":168,"bid_ct":1,"ask_ct":3},{"bid_px":"247.150000000","ask_px":"262.660000000","bid_sz":400,"ask_sz":56,"bid_ct":1,"ask_ct":1},{"bid_px":"247.000000000","ask_px":"264.940000000","bid_sz":12,"ask_sz":7,"bid_ct":1,"ask_ct":1},{"bid_px":"246.000000000","ask_px":"265.000000000","bid_sz":4,"ask_sz":102,"bid_ct":1,"ask_ct":3},{"bid_px":"245.000000000","ask_px":"267.800000000","bid_sz":115,"ask_sz":30,"bid_ct":3,"ask_ct":1},{"bid_px":"243.200000000","ask_px":"268.670000000","bid_sz":15,"ask_sz":100,"bid_ct":1,"ask_ct":1}],"symbol":"TSLA"}
{"ts_recv":"2024-11-01T08:00:11.909754193Z","hd":{"ts_event":"2024-11-01T08:00:11.909587907Z","rtype":10,"publisher_id":2,"instrument_id":16244},"action":"A","side":"A","depth":0,"price":"251.100000000","size":100,"flags":130,"ts_in_delta":166286,"sequence":314557,"levels":[{"bid_px":"250.000000000","ask_px":"251.100000000","bid_sz":2,"ask_sz":100,"bid_ct":2,"ask_ct":1},{"bid_px":"249.930000000","ask_px":"252.400000000","bid_sz":10,"ask_sz":1000,"bid_ct":1,"ask_ct":1},{"bid_px":"249.800000000","ask_px":"253.650000000","bid_sz":199,"ask_sz":400,"bid_ct":1,"ask_ct":1},{"bid_px":"249.770000000","ask_px":"255.000000000","bid_sz":50,"ask_sz":85,"bid_ct":1,"ask_ct":2},{"bid_px":"248.500000000","ask_px":"260.000000000","bid_sz":40,"ask_sz":168,"bid_ct":1,"ask_ct":3},{"bid_px":"247.150000000","ask_px":"262.660000000","bid_sz":400,"ask_sz":56,"bid_ct":1,"ask_ct":1},{"bid_px":"247.000000000","ask_px":"264.940000000","bid_sz":12,"ask_sz":7,"bid_ct":1,"ask_ct":1},{"bid_px":"246.000000000","ask_px":"265.000000000","bid_sz":4,"ask_sz":102,"bid_ct":1,"ask_ct":3},{"bid_px":"245.000000000","ask_px":"267.800000000","bid_sz":115,"ask_sz":30,"bid_ct":3,"ask_ct":1},{"bid_px":"243.200000000","ask_px":"268.670000000","bid_sz":15,"ask_sz":100,"bid_ct":1,"ask_ct":1}],"symbol":"TSLA"}
{"ts_recv":"2024-11-01T08:00:11.911317254Z","hd":{"ts_event":"2024-11-01T08:00:11.911151222Z","rtype":10,"publisher_id":2,"instrument_id":16244},"action":"A","side":"B","depth":4,"price":"249.400000000","size":1000,"flags":130,"ts_in_delta":166032,"sequence":314559,"levels":[{"bid_px":"250.000000000","ask_px":"251.100000000","bid_sz":2,"ask_sz":100,"bid_ct":2,"ask_ct":1},{"bid_px":"249.930000000","ask_px":"252.400000000","bid_sz":10,"ask_sz":1000,"bid_ct":1,"ask_ct":1},{"bid_px":"249.800000000","ask_px":"253.650000000","bid_sz":199,"ask_sz":400,"bid_ct":1,"ask_ct":1},{"bid_px":"249.770000000","ask_px":"255.000000000","bid_sz":50,"ask_sz":85,"bid_ct":1,"ask_ct":2},{"bid_px":"249.400000000","ask_px":"260.000000000","bid_sz":1000,"ask_sz":168,"bid_ct":1,"ask_ct":3},{"bid_px":"248.500000000","ask_px":"262.660000000","bid_sz":40,"ask_sz":56,"bid_ct":1,"ask_ct":1},{"bid_px":"247.150000000","ask_px":"264.940000000","bid_sz":400,"ask_sz":7,"bid_ct":1,"ask_ct":1},{"bid_px":"247.000000000","ask_px":"265.000000000","bid_sz":12,"ask_sz":102,"bid_ct":1,"ask_ct":3},{"bid_px":"246.000000000","ask_px":"267.800000000","bid_sz":4,"ask_sz":30,"bid_ct":1,"ask_ct":1},{"bid_px":"245.000000000","ask_px":"268.670000000","bid_sz":115,"ask_sz":100,"bid_ct":3,"ask_ct":1}],"symbol":"TSLA"}
{"ts_recv":"2024-11-01T08:00:11.940234616Z","hd":{"ts_event":"2024-11-01T08:00:11.940068402Z","rtype":10,"publisher_id":2,"instrument_id":16244},"action":"A","side":"A","depth":0,"price":"251.100000000","size":50,"flags":130,"ts_in_delta":166214,"sequence":314579,"levels":[{"bid_px":"250.000000000","ask_px":"251.100000000","bid_sz":2,"ask_sz":150,"bid_ct":2,"ask_ct":2},{"bid_px":"249.930000000","ask_px":"252.400000000","bid_sz":10,"ask_sz":1000,"bid_ct":1,"ask_ct":1},{"bid_px":"249.800000000","ask_px":"253.650000000","bid_sz":199,"ask_sz":400,"bid_ct":1,"ask_ct":1},{"bid_px":"249.770000000","ask_px":"255.000000000","bid_sz":50,"ask_sz":85,"bid_ct":1,"ask_ct":2},{"bid_px":"249.400000000","ask_px":"260.000000000","bid_sz":1000,"ask_sz":168,"bid_ct":1,"ask_ct":3},{"bid_px":"248.500000000","ask_px":"262.660000000","bid_sz":40,"ask_sz":56,"bid_ct":1,"ask_ct":1},{"bid_px":"247.150000000","ask_px":"264.940000000","bid_sz":400,"ask_sz":7,"bid_ct":1,"ask_ct":1},{"bid_px":"247.000000000","ask_px":"265.000000000","bid_sz":12,"ask_sz":102,"bid_ct":1,"ask_ct":3},{"bid_px":"246.000000000","ask_px":"267.800000000","bid_sz":4,"ask_sz":30,"bid_ct":1,"ask_ct":1},{"bid_px":"245.000000000","ask_px":"268.670000000","bid_sz":115,"ask_sz":100,"bid_ct":3,"ask_ct":1}],"symbol":"TSLA"}
{"ts_recv":"2024-11-01T08:00:11.980261074Z","hd":{"ts_event":"2024-11-01T08:00:11.980094588Z","rtype":10,"publisher_id":2,"instrument_id":16244},"action":"A","side":"B","depth":0,"price":"250.020000000","size":50,"flags":130,"ts_in_delta":166486,"sequence":314604,"levels":[{"bid_px":"250.020000000","ask_px":"251.100000000","bid_sz":50,"ask_sz":150,"bid_ct":1,"ask_ct":2},{"bid_px":"250.000000000","ask_px":"252.400000000","bid_sz":2,"ask_sz":1000,"bid_ct":2,"ask_ct":1},{"bid_px":"249.930000000","ask_px":"253.650000000","bid_sz":10,"ask_sz":400,"bid_ct":1,"ask_ct":1},{"bid_px":"249.800000000","ask_px":"255.000000000","bid_sz":199,"ask_sz":85,"bid_ct":1,"ask_ct":2},{"bid_px":"249.770000000","ask_px":"260.000000000","bid_sz":50,"ask_sz":168,"bid_ct":1,"ask_ct":3},{"bid_px":"249.400000000","ask_px":"262.660000000","bid_sz":1000,"ask_sz":56,"bid_ct":1,"ask_ct":1},{"bid_px":"248.500000000","ask_px":"264.940000000","bid_sz":40,"ask_sz":7,"bid_ct":1,"ask_ct":1},{"bid_px":"247.150000000","ask_px":"265.000000000","bid_sz":400,"ask_sz":102,"bid_ct":1,"ask_ct":3},{"bid_px":"247.000000000","ask_px":"267.800000000","bid_sz":12,"ask_sz":30,"bid_ct":1,"ask_ct":1},{"bid_px":"246.000000000","ask_px":"268.670000000","bid_sz":4,"ask_sz":100,"bid_ct":1,"ask_ct":1}],"symbol":"TSLA"}
{"ts_recv":"2024-11-01T08:00:12.010298851Z","hd":{"ts_event":"2024-11-01T08:00:12.010132491Z","rtype":10,"publisher_id":2,"instrument_id":16244},"action":"A","side":"B","depth":0,"price":"250.110000000","size":50,"flags":130,"ts_in_delta":166360,"sequence":314644,"levels":[{"bid_px":"250.110000000","ask_px":"251.100000000","bid_sz":50,"ask_sz":150,"bid_ct":1,"ask_ct":2},{"bid_px":"250.000000000","ask_px":"252.400000000","bid_sz":2,"ask_sz":1000,"bid_ct":2,"ask_ct":1},{"bid_px":"249.930000000","ask_px":"253.650000000","bid_sz":10,"ask_sz":400,"bid_ct":1,"ask_ct":1},{"bid_px":"249.800000000","ask_px":"255.000000000","bid_sz":199,"ask_sz":85,"bid_ct":1,"ask_ct":2},{"bid_px":"249.770000000","ask_px":"260.000000000","bid_sz":50,"ask_sz":168,"bid_ct":1,"ask_ct":3},{"bid_px":"249.400000000","ask_px":"262.660000000","bid_sz":1000,"ask_sz":56,"bid_ct":1,"ask_ct":1},{"bid_px":"248.500000000","ask_px":"264.940000000","bid_sz":40,"ask_sz":7,"bid_ct":1,"ask_ct":1},{"bid_px":"247.150000000","ask_px":"265.000000000","bid_sz":400,"ask_sz":102,"bid_ct":1,"ask_ct":3},{"bid_px":"247.000000000","ask_px":"267.800000000","bid_sz":12,"ask_sz":30,"bid_ct":1,"ask_ct":1},{"bid_px":"246.000000000","ask_px":"268.670000000","bid_sz":4,"ask_sz":100,"bid_ct":1,"ask_ct":1}],"symbol":"TSLA"}
{"ts_recv":"2024-11-01T08:00:12.051837828Z","hd":{"ts_event":"2024-11-01T08:00:12.051671871Z","rtype":10,"publisher_id":2,"instrument_id":16244},"action":"C","side":"A","depth":0,"price":"251.100000000","size":50,"flags":130,"ts_in_delta":165957,"sequence":314734,"levels":[{"bid_px":"250.110000000","ask_px":"251.100000000","bid_sz":50,"ask_sz":100,"bid_ct":1,"ask_ct":1},{"bid_px":"250.000000000","ask_px":"252.400000000","bid_sz":2,"ask_sz":1000,"bid_ct":2,"ask_ct":1},{"bid_px":"249.930000000","ask_px":"253.650000000","bid_sz":10,"ask_sz":400,"bid_ct":1,"ask_ct":1},{"bid_px":"249.800000000","ask_px":"255.000000000","bid_sz":199,"ask_sz":85,"bid_ct":1,"ask_ct":2},{"bid_px":"249.770000000","ask_px":"260.000000000","bid_sz":50,"ask_sz":168,"bid_ct":1,"ask_ct":3},{"bid_px":"249.400000000","ask_px":"262.660000000","bid_sz":1000,"ask_sz":56,"bid_ct":1,"ask_ct":1},{"bid_px":"248.500000000","ask_px":"264.940000000","bid_sz":40,"ask_sz":7,"bid_ct":1,"ask_ct":1},{"bid_px":"247.150000000","ask_px":"265.000000000","bid_sz":400,"ask_sz":102,"bid_ct":1,"ask_ct":3},{"bid_px":"247.000000000","ask_px":"267.800000000","bid_sz":12,"ask_sz":30,"bid_ct":1,"ask_ct":1},{"bid_px":"246.000000000","ask_px":"268.670000000","bid_sz":4,"ask_sz":100,"bid_ct":1,"ask_ct":1}],"symbol":"TSLA"}
{"ts_recv":"2024-11-01T08:00:12.052652034Z","hd":{"ts_event":"2024-11-01T08:00:12.052486477Z","rtype":10,"publisher_id":2,"instrument_id":16244},"action":"C","side":"A","depth":0,"price":"251.100000000","size":100,"flags":130,"ts_in_delta":165557,"sequence":314740,"levels":[{"bid_px":"250.110000000","ask_px":"252.400000000","bid_sz":50,"ask_sz":1000,"bid_ct":1,"ask_ct":1},{"bid_px":"250.000000000","ask_px":"253.650000000","bid_sz":2,"ask_sz":400,"bid_ct":2,"ask_ct":1},{"bid_px":"249.930000000","ask_px":"255.000000000","bid_sz":10,"ask_sz":85,"bid_ct":1,"ask_ct":2},{"bid_px":"249.800000000","ask_px":"260.000000000","bid_sz":199,"ask_sz":168,"bid_ct":1,"ask_ct":3},{"bid_px":"249.770000000","ask_px":"262.660000000","bid_sz":50,"ask_sz":56,"bid_ct":1,"ask_ct":1},{"bid_px":"249.400000000","ask_px":"264.940000000","bid_sz":1000,"ask_sz":7,"bid_ct":1,"ask_ct":1},{"bid_px":"248.500000000","ask_px":"265.000000000","bid_sz":40,"ask_sz":102,"bid_ct":1,"ask_ct":3},{"bid_px":"247.150000000","ask_px":"267.800000000","bid_sz":400,"ask_sz":30,"bid_ct":1,"ask_ct":1},{"bid_px":"247.000000000","ask_px":"268.670000000","bid_sz":12,"ask_sz":100,"bid_ct":1,"ask_ct":1},{"bid_px":"246.000000000","ask_px":"269.580000000","bid_sz":4,"ask_sz":100,"bid_ct":1,"ask_ct":1}],"symbol":"TSLA"}
{"ts_recv":"2024-11-01T08:00:12.052664746Z","hd":{"ts_event":"2024-11-01T08:00:12.052498638Z","rtype":10,"publisher_id":2,"instrument_id":16244},"action":"A","side":"A","depth":0,"price":"251.120000000","size":100,"flags":130,"ts_in_delta":166108,"sequence":314741,"levels":[{"bid_px":"250.110000000","ask_px":"251.120000000","bid_sz":50,"ask_sz":100,"bid_ct":1,"ask_ct":1},{"bid_px":"250.000000000","ask_px":"252.400000000","bid_sz":2,"ask_sz":1000,"bid_ct":2,"ask_ct":1},{"bid_px":"249.930000000","ask_px":"253.650000000","bid_sz":10,"ask_sz":400,"bid_ct":1,"ask_ct":1},{"bid_px":"249.800000000","ask_px":"255.000000000","bid_sz":199,"ask_sz":85,"bid_ct":1,"ask_ct":2},{"bid_px":"249.770000000","ask_px":"260.000000000","bid_sz":50,"ask_sz":168,"bid_ct":1,"ask_ct":3},{"bid_px":"249.400000000","ask_px":"262.660000000","bid_sz":1000,"ask_sz":56,"bid_ct":1,"ask_ct":1},{"bid_px":"248.500000000","ask_px":"264.940000000","bid_sz":40,"ask_sz":7,"bid_ct":1,"ask_ct":1},{"bid_px":"247.150000000","ask_px":"265.000000000","bid_sz":400,"ask_sz":102,"bid_ct":1,"ask_ct":3},{"bid_px":"247.000000000","ask_px":"267.800000000","bid_sz":12,"ask_sz":30,"bid_ct":1,"ask_ct":1},{"bid_px":"246.000000000","ask_px":"268.670000000","bid_sz":4,"ask_sz":100,"bid_ct":1,"ask_ct":1}],"symbol":"TSLA"}
{"ts_recv":"2024-11-01T08:00:12.052943030Z","hd":{"ts_event":"2024-11-01T08:00:12.052777371Z","rtype":10,"publisher_id":2,"instrument_id":16244},"action":"C","side":"A","depth":0,"price":"251.120000000","size":100,"flags":130,"ts_in_delta":165659,"sequence":314742,"levels":[{"bid_px":"250.110000000","ask_px":"252.400000000","bid_sz":50,"ask_sz":1000,"bid_ct":1,"ask_ct":1},{"bid_px":"250.000000000","ask_px":"253.650000000","bid_sz":2,"ask_sz":400,"bid_ct":2,"ask_ct":1},{"bid_px":"249.930000000","ask_px":"255.000000000","bid_sz":10,"ask_sz":85,"bid_ct":1,"ask_ct":2},{"bid_px":"249.800000000","ask_px":"260.000000000","bid_sz":199,"ask_sz":168,"bid_ct":1,"ask_ct":3},{"bid_px":"249.770000000","ask_px":"262.660000000","bid_sz":50,"ask_sz":56,"bid_ct":1,"ask_ct":1},{"bid_px":"249.400000000","ask_px":"264.940000000","bid_sz":1000,"ask_sz":7,"bid_ct":1,"ask_ct":1},{"bid_px":"248.500000000","ask_px":"265.000000000","bid_sz":40,"ask_sz":102,"bid_ct":1,"ask_ct":3},{"bid_px":"247.150000000","ask_px":"267.800000000","bid_sz":400,"ask_sz":30,"bid_ct":1,"ask_ct":1},{"bid_px":"247.000000000","ask_px":"268.670000000","bid_sz":12,"ask_sz":100,"bid_ct":1,"ask_ct":1},{"bid_px":"246.000000000","ask_px":"269.580000000","bid_sz":4,"ask_sz":100,"bid_ct":1,"ask_ct":1}],"symbol":"TSLA"}
{"ts_recv":"2024-11-01T08:00:12.052955594Z","hd":{"ts_event":"2024-11-01T08:00:12.052789609Z","rtype":10,"publisher_id":2,"instrument_id":16244},"action":"A","side":"A","depth":0,"price":"251.150000000","size":100,"flags":130,"ts_in_delta":165985,"sequence":314743,"levels":[{"bid_px":"250.110000000","ask_px":"251.150000000","bid_sz":50,"ask_sz":100,"bid_ct":1,"ask_ct":1},{"bid_px":"250.000000000","ask_px":"252.400000000","bid_sz":2,"ask_sz":1000,"bid_ct":2,"ask_ct":1},{"bid_px":"249.930000000","ask_px":"253.650000000","bid_sz":10,"ask_sz":400,"bid_ct":1,"ask_ct":1},{"bid_px":"249.800000000","ask_px":"255.000000000","bid_sz":199,"ask_sz":85,"bid_ct":1,"ask_ct":2},{"bid_px":"249.770000000","ask_px":"260.000000000","bid_sz":50,"ask_sz":168,"bid_ct":1,"ask_ct":3},{"bid_px":"249.400000000","ask_px":"262.660000000","bid_sz":1000,"ask_sz":56,"bid_ct":1,"ask_ct":1},{"bid_px":"248.500000000","ask_px":"264.940000000","bid_sz":40,"ask_sz":7,"bid_ct":1,"ask_ct":1},{"bid_px":"247.150000000","ask_px":"265.000000000","bid_sz":400,"ask_sz":102,"bid_ct":1,"ask_ct":3},{"bid_px":"247.000000000","ask_px":"267.800000000","bid_sz":12,"ask_sz":30,"bid_ct":1,"ask_ct":1},{"bid_px":"246.000000000","ask_px":"268.670000000","bid_sz":4,"ask_sz":100,"bid_ct":1,"ask_ct":1}],"symbol":"TSLA"}
{"ts_recv":"2024-11-01T08:00:12.072038689Z","hd":{"ts_event":"2024-11-01T08:00:12.071872261Z","rtype":10,"publisher_id":2,"instrument_id":16244},"action":"A","side":"B","depth":0,"price":"250.150000000","size":50,"flags":130,"ts_in_delta":166428,"sequence":314755,"levels":[{"bid_px":"250.150000000","ask_px":"251.150000000","bid_sz":50,"ask_sz":100,"bid_ct":1,"ask_ct":1},{"bid_px":"250.000000000","ask_px":"252.400000000","bid_sz":2,"ask_sz":1000,"bid_ct":2,"ask_ct":1},{"bid_px":"249.930000000","ask_px":"253.650000000","bid_sz":10,"ask_sz":400,"bid_ct":1,"ask_ct":1},{"bid_px":"249.800000000","ask_px":"255.000000000","bid_sz":199,"ask_sz":85,"bid_ct":1,"ask_ct":2},{"bid_px":"249.770000000","ask_px":"260.000000000","bid_sz":50,"ask_sz":168,"bid_ct":1,"ask_ct":3},{"bid_px":"249.400000000","ask_px":"262.660000000","bid_sz":1000,"ask_sz":56,"bid_ct":1,"ask_ct":1},{"bid_px":"248.500000000","ask_px":"264.940000000","bid_sz":40,"ask_sz":7,"bid_ct":1,"ask_ct":1},{"bid_px":"247.150000000","ask_px":"265.000000000","bid_sz":400,"ask_sz":102,"bid_ct":1,"ask_ct":3},{"bid_px":"247.000000000","ask_px":"267.800000000","bid_sz":12,"ask_sz":30,"bid_ct":1,"ask_ct":1},{"bid_px":"246.000000000","ask_px":"268.670000000","bid_sz":4,"ask_sz":100,"bid_ct":1,"ask_ct":1}],"symbol":"TSLA"}
{"ts_recv":"2024-11-01T08:00:12.072262589Z","hd":{"ts_event":"2024-11-01T08:00:12.072096208Z","rtype":10,"publisher_id":2,"instrument_id":16244},"action":"A","side":"B","depth":3,"price":"249.880000000","size":4,"flags":130,"ts_in_delta":166381,"sequence":314756,"levels":[{"bid_px":"250.150000000","ask_px":"251.150000000","bid_sz":50,"ask_sz":100,"bid_ct":1,"ask_ct":1},{"bid_px":"250.000000000","ask_px":"252.400000000","bid_sz":2,"ask_sz":1000,"bid_ct":2,"ask_ct":1},{"bid_px":"249.930000000","ask_px":"253.650000000","bid_sz":10,"ask_sz":400,"bid_ct":1,"ask_ct":1},{"bid_px":"249.880000000","ask_px":"255.000000000","bid_sz":4,"ask_sz":85,"bid_ct":1,"ask_ct":2},{"bid_px":"249.800000000","ask_px":"260.000000000","bid_sz":199,"ask_sz":168,"bid_ct":1,"ask_ct":3},{"bid_px":"249.770000000","ask_px":"262.660000000","bid_sz":50,"ask_sz":56,"bid_ct":1,"ask_ct":1},{"bid_px":"249.400000000","ask_px":"264.940000000","bid_sz":1000,"ask_sz":7,"bid_ct":1,"ask_ct":1},{"bid_px":"248.500000000","ask_px":"265.000000000","bid_sz":40,"ask_sz":102,"bid_ct":1,"ask_ct":3},{"bid_px":"247.150000000","ask_px":"267.800000000","bid_sz":400,"ask_sz":30,"bid_ct":1,"ask_ct":1},{"bid_px":"247.000000000","ask_px":"268.670000000","bid_sz":12,"ask_sz":100,"bid_ct":1,"ask_ct":1}],"symbol":"TSLA"}
{"ts_recv":"2024-11-01T08:00:12.083344521Z","hd":{"ts_event":"2024-11-01T08:00:12.083178480Z","rtype":10,"publisher_id":2,"instrument_id":16244},"action":"A","side":"B","depth":0,"price":"250.150000000","size":50,"flags":130,"ts_in_delta":166041,"sequence":314776,"levels":[{"bid_px":"250.150000000","ask_px":"251.150000000","bid_sz":100,"ask_sz":100,"bid_ct":2,"ask_ct":1},{"bid_px":"250.000000000","ask_px":"252.400000000","bid_sz":2,"ask_sz":1000,"bid_ct":2,"ask_ct":1},{"bid_px":"249.930000000","ask_px":"253.650000000","bid_sz":10,"ask_sz":400,"bid_ct":1,"ask_ct":1},{"bid_px":"249.880000000","ask_px":"255.000000000","bid_sz":4,"ask_sz":85,"bid_ct":1,"ask_ct":2},{"bid_px":"249.800000000","ask_px":"260.000000000","bid_sz":199,"ask_sz":168,"bid_ct":1,"ask_ct":3},{"bid_px":"249.770000000","ask_px":"262.660000000","bid_sz":50,"ask_sz":56,"bid_ct":1,"ask_ct":1},{"bid_px":"249.400000000","ask_px":"264.940000000","bid_sz":1000,"ask_sz":7,"bid_ct":1,"ask_ct":1},{"bid_px":"248.500000000","ask_px":"265.000000000","bid_sz":40,"ask_sz":102,"bid_ct":1,"ask_ct":3},{"bid_px":"247.150000000","ask_px":"267.800000000","bid_sz":400,"ask_sz":30,"bid_ct":1,"ask_ct":1},{"bid_px":"247.000000000","ask_px":"268.670000000","bid_sz":12,"ask_sz":100,"bid_ct":1,"ask_ct":1}],"symbol":"TSLA"}
{"ts_recv":"2024-11-01T08:00:12.137337594Z","hd":{"ts_event":"2024-11-01T08:00:12.137171993Z","rtype":10,"publisher_id":2,"instrument_id":16244},"action":"C","side":"B","depth":0,"price":"250.150000000","size":50,"flags":130,"ts_in_delta":165601,"sequence":314909,"levels":[{"bid_px":"250.150000000","ask_px":"251.150000000","bid_sz":50,"ask_sz":100,"bid_ct":1,"ask_ct":1},{"bid_px":"250.000000000","ask_px":"252.400000000","bid_sz":2,"ask_sz":1000,"bid_ct":2,"ask_ct":1},{"bid_px":"249.930000000","ask_px":"253.650000000","bid_sz":10,"ask_sz":400,"bid_ct":1,"ask_ct":1},{"bid_px":"249.880000000","ask_px":"255.000000000","bid_sz":4,"ask_sz":85,"bid_ct":1,"ask_ct":2},{"bid_px":"249.800000000","ask_px":"260.000000000","bid_sz":199,"ask_sz":168,"bid_ct":1,"ask_ct":3},{"bid_px":"249.770000000","ask_px":"262.660000000","bid_sz":50,"ask_sz":56,"bid_ct":1,"ask_ct":1},{"bid_px":"249.400000000","ask_px":"264.940000000","bid_sz":1000,"ask_sz":7,"bid_ct":1,"ask_ct":1},{"bid_px":"248.500000000","ask_px":"265.000000000","bid_sz":40,"ask_sz":102,"bid_ct":1,"ask_ct":3},{"bid_px":"247.150000000","ask_px":"267.800000000","bid_sz":400,"ask_sz":30,"bid_ct":1,"ask_ct":1},{"bid_px":"247.000000000","ask_px":"268.670000000","bid_sz":12,"ask_sz":100,"bid_ct":1,"ask_ct":1}],"symbol":"TSLA"}
{"ts_recv":"2024-11-01T08:00:12.137351725Z","hd":{"ts_event":"2024-11-01T08:00:12.137185661Z","rtype":10,"publisher_id":2,"instrument_id":16244},"action":"A","side":"B","depth":0,"price":"250.170000000","size":100,"flags":130,"ts_in_delta":166064,"sequence":314910,"levels":[{"bid_px":"250.170000000","ask_px":"251.150000000","bid_sz":100,"ask_sz":100,"bid_ct":1,"ask_ct":1},{"bid_px":"250.000000000","ask_px":"252.400000000","bid_sz":2,"ask_sz":1000,"bid_ct":2,"ask_ct":1},{"bid_px":"249.930000000","ask_px":"253.650000000","bid_sz":10,"ask_sz":400,"bid_ct":1,"ask_ct":1},{"bid_px":"249.880000000","ask_px":"255.000000000","bid_sz":4,"ask_sz":85,"bid_ct":1,"ask_ct":2},{"bid_px":"249.800000000","ask_px":"260.000000000","bid_sz":199,"ask_sz":168,"bid_ct":1,"ask_ct":3},{"bid_px":"249.770000000","ask_px":"262.660000000","bid_sz":50,"ask_sz":56,"bid_ct":1,"ask_ct":1},{"bid_px":"249.400000000","ask_px":"264.940000000","bid_sz":1000,"ask_sz":7,"bid_ct":1,"ask_ct":1},{"bid_px":"248.500000000","ask_px":"265.000000000","bid_sz":40,"ask_sz":102,"bid_ct":1,"ask_ct":3},{"bid_px":"247.150000000","ask_px":"267.800000000","bid_sz":400,"ask_sz":30,"bid_ct":1,"ask_ct":1},{"bid_px":"247.000000000","ask_px":"268.670000000","bid_sz":12,"ask_sz":100,"bid_ct":1,"ask_ct":1}],"symbol":"TSLA"}
{"ts_recv":"2024-11-01T08:00:12.259106789Z","hd":{"ts_event":"2024-11-01T08:00:12.258940574Z","rtype":10,"publisher_id":2,"instrument_id":16244},"action":"A","side":"A","depth":1,"price":"251.500000000","size":50,"flags":130,"ts_in_delta":166215,"sequence":315240,"levels":[{"bid_px":"250.170000000","ask_px":"251.150000000","bid_sz":100,"ask_sz":100,"bid_ct":1,"ask_ct":1},{"bid_px":"250.000000000","ask_px":"251.500000000","bid_sz":2,"ask_sz":50,"bid_ct":2,"ask_ct":1},{"bid_px":"249.930000000","ask_px":"252.400000000","bid_sz":10,"ask_sz":1000,"bid_ct":1,"ask_ct":1},{"bid_px":"249.880000000","ask_px":"253.650000000","bid_sz":4,"ask_sz":400,"bid_ct":1,"ask_ct":1},{"bid_px":"249.800000000","ask_px":"255.000000000","bid_sz":199,"ask_sz":85,"bid_ct":1,"ask_ct":2},{"bid_px":"249.770000000","ask_px":"260.000000000","bid_sz":50,"ask_sz":168,"bid_ct":1,"ask_ct":3},{"bid_px":"249.400000000","ask_px":"262.660000000","bid_sz":1000,"ask_sz":56,"bid_ct":1,"ask_ct":1},{"bid_px":"248.500000000","ask_px":"264.940000000","bid_sz":40,"ask_sz":7,"bid_ct":1,"ask_ct":1},{"bid_px":"247.150000000","ask_px":"265.000000000","bid_sz":400,"ask_sz":102,"bid_ct":1,"ask_ct":3},{"bid_px":"247.000000000","ask_px":"267.800000000","bid_sz":12,"ask_sz":30,"bid_ct":1,"ask_ct":1}],"symbol":"TSLA"}
{"ts_recv":"2024-11-01T08:00:12.278103756Z","hd":{"ts_event":"2024-11-01T08:00:12.277937537Z","rtype":10,"publisher_id":2,"instrument_id":16244},"action":"A","side":"A","depth":1,"price":"251.500000000","size":50,"flags":130,"ts_in_delta":166219,"sequence":315276,"levels":[{"bid_px":"250.170000000","ask_px":"251.150000000","bid_sz":100,"ask_sz":100,"bid_ct":1,"ask_ct":1},{"bid_px":"250.000000000","ask_px":"251.500000000","bid_sz":2,"ask_sz":100,"bid_ct":2,"ask_ct":2},{"bid_px":"249.930000000","ask_px":"252.400000000","bid_sz":10,"ask_sz":1000,"bid_ct":1,"ask_ct":1},{"bid_px":"249.880000000","ask_px":"253.650000000","bid_sz":4,"ask_sz":400,"bid_ct":1,"ask_ct":1},{"bid_px":"249.800000000","ask_px":"255.000000000","bid_sz":199,"ask_sz":85,"bid_ct":1,"ask_ct":2},{"bid_px":"249.770000000","ask_px":"260.000000000","bid_sz":50,"ask_sz":168,"bid_ct":1,"ask_ct":3},{"bid_px":"249.400000000","ask_px":"262.660000000","bid_sz":1000,"ask_sz":56,"bid_ct":1,"ask_ct":1},{"bid_px":"248.500000000","ask_px":"264.940000000","bid_sz":40,"ask_sz":7,"bid_ct":1,"ask_ct":1},{"bid_px":"247.150000000","ask_px":"265.000000000","bid_sz":400,"ask_sz":102,"bid_ct":1,"ask_ct":3},{"bid_px":"247.000000000","ask_px":"267.800000000","bid_sz":12,"ask_sz":30,"bid_ct":1,"ask_ct":1}],"symbol":"TSLA"}
{"ts_recv":"2024-11-01T08:00:12.311466890Z","hd":{"ts_event":"2024-11-01T08:00:12.311300895Z","rtype":10,"publisher_id":2,"instrument_id":16244},"action":"C","side":"A","depth":1,"price":"251.500000000","size":50,"flags":130,"ts_in_delta":165995,"sequence":315376,"levels":[{"bid_px":"250.170000000","ask_px":"251.150000000","bid_sz":100,"ask_sz":100,"bid_ct":1,"ask_ct":1},{"bid_px":"250.000000000","ask_px":"251.500000000","bid_sz":2,"ask_sz":50,"bid_ct":2,"ask_ct":1},{"bid_px":"249.930000000","ask_px":"252.400000000","bid_sz":10,"ask_sz":1000,"bid_ct":1,"ask_ct":1},{"bid_px":"249.880000000","ask_px":"253.650000000","bid_sz":4,"ask_sz":400,"bid_ct":1,"ask_ct":1},{"bid_px":"249.800000000","ask_px":"255.000000000","bid_sz":199,"ask_sz":85,"bid_ct":1,"ask_ct":2},{"bid_px":"249.770000000","ask_px":"260.000000000","bid_sz":50,"ask_sz":168,"bid_ct":1,"ask_ct":3},{"bid_px":"249.400000000","ask_px":"262.660000000","bid_sz":1000,"ask_sz":56,"bid_ct":1,"ask_ct":1},{"bid_px":"248.500000000","ask_px":"264.940000000","bid_sz":40,"ask_sz":7,"bid_ct":1,"ask_ct":1},{"bid_px":"247.150000000","ask_px":"265.000000000","bid_sz":400,"ask_sz":102,"bid_ct":1,"ask_ct":3},{"bid_px":"247.000000000","ask_px":"267.800000000","bid_sz":12,"ask_sz":30,"bid_ct":1,"ask_ct":1}],"symbol":"TSLA"}
{"ts_recv":"2024-11-01T08:00:12.311481300Z","hd":{"ts_event":"2024-11-01T08:00:12.311314874Z","rtype":10,"publisher_id":2,"instrument_id":16244},"action":"A","side":"A","depth":1,"price":"251.490000000","size":100,"flags":130,"ts_in_delta":166426,"sequence":315377,"levels":[{"bid_px":"250.170000000","ask_px":"251.150000000","bid_sz":100,"ask_sz":100,"bid_ct":1,"ask_ct":1},{"bid_px":"250.000000000","ask_px":"251.490000000","bid_sz":2,"ask_sz":100,"bid_ct":2,"ask_ct":1},{"bid_px":"249.930000000","ask_px":"252.400000000","bid_sz":10,"ask_sz":1000,"bid_ct":1,"ask_ct":1},{"bid_px":"249.880000000","ask_px":"253.650000000","bid_sz":4,"ask_sz":400,"bid_ct":1,"ask_ct":1},{"bid_px":"249.800000000","ask_px":"255.000000000","bid_sz":199,"ask_sz":85,"bid_ct":1,"ask_ct":2},{"bid_px":"249.770000000","ask_px":"260.000000000","bid_sz":50,"ask_sz":168,"bid_ct":1,"ask_ct":3},{"bid_px":"249.400000000","ask_px":"262.660000000","bid_sz":1000,"ask_sz":56,"bid_ct":1,"ask_ct":1},{"bid_px":"248.500000000","ask_px":"264.940000000","bid_sz":40,"ask_sz":7,"bid_ct":1,"ask_ct":1},{"bid_px":"247.150000000","ask_px":"265.000000000","bid_sz":400,"ask_sz":102,"bid_ct":1,"ask_ct":3},{"bid_px":"247.000000000","ask_px":"267.800000000","bid_sz":12,"ask_sz":30,"bid_ct":1,"ask_ct":1}],"symbol":"TSLA"}
{"ts_recv":"2024-11-01T08:00:12.330113236Z","hd":{"ts_event":"2024-11-01T08:00:12.329946593Z","rtype":10,"publisher_id":2,"instrument_id":16244},"action":"A","side":"A","depth":0,"price":"251.150000000","size":50,"flags":130,"ts_in_delta":166643,"sequence":315397,"levels":[{"bid_px":"250.170000000","ask_px":"251.150000000","bid_sz":100,"ask_sz":150,"bid_ct":1,"ask_ct":2},{"bid_px":"250.000000000","ask_px":"252.400000000","bid_sz":2,"ask_sz":1000,"bid_ct":2,"ask_ct":1},{"bid_px":"249.930000000","ask_px":"253.650000000","bid_sz":10,"ask_sz":400,"bid_ct":1,"ask_ct":1},{"bid_px":"249.880000000","ask_px":"255.000000000","bid_sz":4,"ask_sz":85,"bid_ct":1,"ask_ct":2},{"bid_px":"249.800000000","ask_px":"260.000000000","bid_sz":199,"ask_sz":168,"bid_ct":1,"ask_ct":3},{"bid_px":"249.770000000","ask_px":"262.660000000","bid_sz":50,"ask_sz":56,"bid_ct":1,"ask_ct":1},{"bid_px":"249.400000000","ask_px":"264.940000000","bid_sz":1000,"ask_sz":7,"bid_ct":1,"ask_ct":1},{"bid_px":"248.500000000","ask_px":"265.000000000","bid_sz":40,"ask_sz":102,"bid_ct":1,"ask_ct":3},{"bid_px":"247.150000000","ask_px":"267.800000000","bid_sz":400,"ask_sz":30,"bid_ct":1,"ask_ct":1},{"bid_px":"247.000000000","ask_px":"268.670000000","bid_sz":12,"ask_sz":100,"bid_ct":1,"ask_ct":1}],"symbol":"TSLA"}
{"ts_recv":"2024-11-01T08:00:12.521061332Z","hd":{"ts_event":"2024-11-01T08:00:12.520894841Z","rtype":10,"publisher_id":2,"instrument_id":16244},"action":"A","side":"A","depth":0,"price":"251.150000000","size":50,"flags":130,"ts_in_delta":166491,"sequence":315732,"levels":[{"bid_px":"250.170000000","ask_px":"251.150000000","bid_sz":100,"ask_sz":200,"bid_ct":1,"ask_ct":3},{"bid_px":"250.000000000","ask_px":"252.400000000","bid_sz":2,"ask_sz":1000,"bid_ct":2,"ask_ct":1},{"bid_px":"249.930000000","ask_px":"253.650000000","bid_sz":10,"ask_sz":400,"bid_ct":1,"ask_ct":1},{"bid_px":"249.880000000","ask_px":"255.000000000","bid_sz":4,"ask_sz":85,"bid_ct":1,"ask_ct":2},{"bid_px":"249.800000000","ask_px":"260.000000000","bid_sz":199,"ask_sz":168,"bid_ct":1,"ask_ct":3},{"bid_px":"249.770000000","ask_px":"262.660000000","bid_sz":50,"ask_sz":56,"bid_ct":1,"ask_ct":1},{"bid_px":"249.400000000","ask_px":"264.940000000","bid_sz":1000,"ask_sz":7,"bid_ct":1,"ask_ct":1},{"bid_px":"248.500000000","ask_px":"265.000000000","bid_sz":40,"ask_sz":102,"bid_ct":1,"ask_ct":3},{"bid_px":"247.150000000","ask_px":"267.800000000","bid_sz":400,"ask_sz":30,"bid_ct":1,"ask_ct":1},{"bid_px":"247.000000000","ask_px":"268.670000000","bid_sz":12,"ask_sz":100,"bid_ct":1,"ask_ct":1}],"symbol":"TSLA"}
{"ts_recv":"2024-11-01T08:00:12.689662015Z","hd":{"ts_event":"2024-11-01T08:00:12.689495698Z","rtype":10,"publisher_id":2,"instrument_id":16244},"action":"A","side":"A","depth":0,"price":"250.770000000","size":6,"flags":130,"ts_in_delta":166317,"sequence":315982,"levels":[{"bid_px":"250.170000000","ask_px":"250.770000000","bid_sz":100,"ask_sz":6,"bid_ct":1,"ask_ct":1},{"bid_px":"250.000000000","ask_px":"251.150000000","bid_sz":2,"ask_sz":200,"bid_ct":2,"ask_ct":3},{"bid_px":"249.930000000","ask_px":"252.400000000","bid_sz":10,"ask_sz":1000,"bid_ct":1,"ask_ct":1},{"bid_px":"249.880000000","ask_px":"253.650000000","bid_sz":4,"ask_sz":400,"bid_ct":1,"ask_ct":1},{"bid_px":"249.800000000","ask_px":"255.000000000","bid_sz":199,"ask_sz":85,"bid_ct":1,"ask_ct":2},{"bid_px":"249.770000000","ask_px":"260.000000000","bid_sz":50,"ask_sz":168,"bid_ct":1,"ask_ct":3},{"bid_px":"249.400000000","ask_px":"262.660000000","bid_sz":1000,"ask_sz":56,"bid_ct":1,"ask_ct":1},{"bid_px":"248.500000000","ask_px":"264.940000000","bid_sz":40,"ask_sz":7,"bid_ct":1,"ask_ct":1},{"bid_px":"247.150000000","ask_px":"265.000000000","bid_sz":400,"ask_sz":102,"bid_ct":1,"ask_ct":3},{"bid_px":"247.000000000","ask_px":"267.800000000","bid_sz":12,"ask_sz":30,"bid_ct":1,"ask_ct":1}],"symbol":"TSLA"}
{"ts_recv":"2024-11-01T08:00:12.722939114Z","hd":{"ts_event":"2024-11-01T08:00:12.722773182Z","rtype":10,"publisher_id":2,"instrument_id":16244},"action":"C","side":"A","depth":1,"price":"251.150000000","size":50,"flags":130,"ts_in_delta":165932,"sequence":316000,"levels":[{"bid_px":"250.170000000","ask_px":"250.770000000","bid_sz":100,"ask_sz":6,"bid_ct":1,"ask_ct":1},{"bid_px":"250.000000000","ask_px":"251.150000000","bid_sz":2,"ask_sz":150,"bid_ct":2,"ask_ct":2},{"bid_px":"249.930000000","ask_px":"252.400000000","bid_sz":10,"ask_sz":1000,"bid_ct":1,"ask_ct":1},{"bid_px":"249.880000000","ask_px":"253.650000000","bid_sz":4,"ask_sz":400,"bid_ct":1,"ask_ct":1},{"bid_px":"249.800000000","ask_px":"255.000000000","bid_sz":199,"ask_sz":85,"bid_ct":1,"ask_ct":2},{"bid_px":"249.770000000","ask_px":"260.000000000","bid_sz":50,"ask_sz":168,"bid_ct":1,"ask_ct":3},{"bid_px":"249.400000000","ask_px":"262.660000000","bid_sz":1000,"ask_sz":56,"bid_ct":1,"ask_ct":1},{"bid_px":"248.500000000","ask_px":"264.940000000","bid_sz":40,"ask_sz":7,"bid_ct":1,"ask_ct":1},{"bid_px":"247.150000000","ask_px":"265.000000000","bid_sz":400,"ask_sz":102,"bid_ct":1,"ask_ct":3},{"bid_px":"247.000000000","ask_px":"267.800000000","bid_sz":12,"ask_sz":30,"bid_ct":1,"ask_ct":1}],"symbol":"TSLA"}
{"ts_recv":"2024-11-01T08:00:12.722953136Z","hd":{"ts_event":"2024-11-01T08:00:12.722786957Z","rtype":10,"publisher_id":2,"instrument_id":16244},"action":"A","side":"A","depth":1,"price":"251.140000000","size":50,"flags":130,"ts_in_delta":166179,"sequence":316001,"levels":[{"bid_px":"250.170000000","ask_px":"250.770000000","bid_sz":100,"ask_sz":6,"bid_ct":1,"ask_ct":1},{"bid_px":"250.000000000","ask_px":"251.140000000","bid_sz":2,"ask_sz":50,"bid_ct":2,"ask_ct":1},{"bid_px":"249.930000000","ask_px":"251.150000000","bid_sz":10,"ask_sz":100,"bid_ct":1,"ask_ct":1},{"bid_px":"249.880000000","ask_px":"252.400000000","bid_sz":4,"ask_sz":1000,"bid_ct":1,"ask_ct":1},{"bid_px":"249.800000000","ask_px":"253.650000000","bid_sz":199,"ask_sz":400,"bid_ct":1,"ask_ct":1},{"bid_px":"249.770000000","ask_px":"255.000000000","bid_sz":50,"ask_sz":85,"bid_ct":1,"ask_ct":2},{"bid_px":"249.400000000","ask_px":"260.000000000","bid_sz":1000,"ask_sz":168,"bid_ct":1,"ask_ct":3},{"bid_px":"248.500000000","ask_px":"262.660000000","bid_sz":40,"ask_sz":56,"bid_ct":1,"ask_ct":1},{"bid_px":"247.150000000","ask_px":"264.940000000","bid_sz":400,"ask_sz":7,"bid_ct":1,"ask_ct":1},{"bid_px":"247.000000000","ask_px":"265.000000000","bid_sz":12,"ask_sz":102,"bid_ct":1,"ask_ct":3}],"symbol":"TSLA"}
{"ts_recv":"2024-11-01T08:00:12.723026482Z","hd":{"ts_event":"2024-11-01T08:00:12.722860394Z","rtype":10,"publisher_id":2,"instrument_id":16244},"action":"C","side":"B","depth":0,"price":"250.170000000","size":50,"flags":130,"ts_in_delta":166088,"sequence":316002,"levels":[{"bid_px":"250.170000000","ask_px":"250.770000000","bid_sz":50,"ask_sz":6,"bid_ct":1,"ask_ct":1},{"bid_px":"250.000000000","ask_px":"251.140000000","bid_sz":2,"ask_sz":50,"bid_ct":2,"ask_ct":1},{"bid_px":"249.930000000","ask_px":"251.150000000","bid_sz":10,"ask_sz":100,"bid_ct":1,"ask_ct":1},{"bid_px":"249.880000000","ask_px":"252.400000000","bid_sz":4,"ask_sz":1000,"bid_ct":1,"ask_ct":1},{"bid_px":"249.800000000","ask_px":"253.650000000","bid_sz":199,"ask_sz":400,"bid_ct":1,"ask_ct":1},{"bid_px":"249.770000000","ask_px":"255.000000000","bid_sz":50,"ask_sz":85,"bid_ct":1,"ask_ct":2},{"bid_px":"249.400000000","ask_px":"260.000000000","bid_sz":1000,"ask_sz":168,"bid_ct":1,"ask_ct":3},{"bid_px":"248.500000000","ask_px":"262.660000000","bid_sz":40,"ask_sz":56,"bid_ct":1,"ask_ct":1},{"bid_px":"247.150000000","ask_px":"264.940000000","bid_sz":400,"ask_sz":7,"bid_ct":1,"ask_ct":1},{"bid_px":"247.000000000","ask_px":"265.000000000","bid_sz":12,"ask_sz":102,"bid_ct":1,"ask_ct":3}],"symbol":"TSLA"}
{"ts_recv":"2024-11-01T08:00:12.923864319Z","hd":{"ts_event":"2024-11-01T08:00:12.923698300Z","rtype":10,"publisher_id":2,"instrument_id":16244},"action":"A","side":"A","depth":4,"price":"253.350000000","size":23,"flags":130,"ts_in_delta":166019,"sequence":316503,"levels":[{"bid_px":"250.170000000","ask_px":"250.770000000","bid_sz":50,"ask_sz":6,"bid_ct":1,"ask_ct":1},{"bid_px":"250.000000000","ask_px":"251.140000000","bid_sz":2,"ask_sz":50,"bid_ct":2,"ask_ct":1},{"bid_px":"249.930000000","ask_px":"251.150000000","bid_sz":10,"ask_sz":100,"bid_ct":1,"ask_ct":1},{"bid_px":"249.880000000","ask_px":"252.400000000","bid_sz":4,"ask_sz":1000,"bid_ct":1,"ask_ct":1},{"bid_px":"249.800000000","ask_px":"253.350000000","bid_sz":199,"ask_sz":23,"bid_ct":1,"ask_ct":1},{"bid_px":"249.770000000","ask_px":"253.650000000","bid_sz":50,"ask_sz":400,"bid_ct":1,"ask_ct":1},{"bid_px":"249.400000000","ask_px":"255.000000000","bid_sz":1000,"ask_sz":85,"bid_ct":1,"ask_ct":2},{"bid_px":"248.500000000","ask_px":"260.000000000","bid_sz":40,"ask_sz":168,"bid_ct":1,"ask_ct":3},{"bid_px":"247.150000000","ask_px":"262.660000000","bid_sz":400,"ask_sz":56,"bid_ct":1,"ask_ct":1},{"bid_px":"247.000000000","ask_px":"264.940000000","bid_sz":12,"ask_sz":7,"bid_ct":1,"ask_ct":1}],"symbol":"TSLA"}
{"ts_recv":"2024-11-01T08:00:12.928285652Z","hd":{"ts_event":"2024-11-01T08:00:12.928119453Z","rtype":10,"publisher_id":2,"instrument_id":16244},"action":"A","side":"A","depth":7,"price":"258.000000000","size":200,"flags":130,"ts_in_delta":166199,"sequence":316520,"levels":[{"bid_px":"250.170000000","ask_px":"250.770000000","bid_sz":50,"ask_sz":6,"bid_ct":1,"ask_ct":1},{"bid_px":"250.000000000","ask_px":"251.140000000","bid_sz":2,"ask_sz":50,"bid_ct":2,"ask_ct":1},{"bid_px":"249.930000000","ask_px":"251.150000000","bid_sz":10,"ask_sz":100,"bid_ct":1,"ask_ct":1},{"bid_px":"249.880000000","ask_px":"252.400000000","bid_sz":4,"ask_sz":1000,"bid_ct":1,"ask_ct":1},{"bid_px":"249.800000000","ask_px":"253.350000000","bid_sz":199,"ask_sz":23,"bid_ct":1,"ask_ct":1},{"bid_px":"249.770000000","ask_px":"253.650000000","bid_sz":50,"ask_sz":400,"bid_ct":1,"ask_ct":1},{"bid_px":"249.400000000","ask_px":"255.000000000","bid_sz":1000,"ask_sz":85,"bid_ct":1,"ask_ct":2},{"bid_px":"248.500000000","ask_px":"258.000000000","bid_sz":40,"ask_sz":200,"bid_ct":1,"ask_ct":1},{"bid_px":"247.150000000","ask_px":"260.000000000","bid_sz":400,"ask_sz":168,"bid_ct":1,"ask_ct":3},{"bid_px":"247.000000000","ask_px":"262.660000000","bid_sz":12,"ask_sz":56,"bid_ct":1,"ask_ct":1}],"symbol":"TSLA"}
{"ts_recv":"2024-11-01T08:00:13.013111583Z","hd":{"ts_event":"2024-11-01T08:00:13.012945480Z","rtype":10,"publisher_id":2,"instrument_id":16244},"action":"A","side":"A","depth":1,"price":"251.140000000","size":50,"flags":130,"ts_in_delta":166103,"sequence":316811,"levels":[{"bid_px":"250.170000000","ask_px":"250.770000000","bid_sz":50,"ask_sz":6,"bid_ct":1,"ask_ct":1},{"bid_px":"250.000000000","ask_px":"251.140000000","bid_sz":2,"ask_sz":100,"bid_ct":2,"ask_ct":2},{"bid_px":"249.930000000","ask_px":"251.150000000","bid_sz":10,"ask_sz":100,"bid_ct":1,"ask_ct":1},{"bid_px":"249.880000000","ask_px":"252.400000000","bid_sz":4,"ask_sz":1000,"bid_ct":1,"ask_ct":1},{"bid_px":"249.800000000","ask_px":"253.350000000","bid_sz":199,"ask_sz":23,"bid_ct":1,"ask_ct":1},{"bid_px":"249.770000000","ask_px":"253.650000000","bid_sz":50,"ask_sz":400,"bid_ct":1,"ask_ct":1},{"bid_px":"249.400000000","ask_px":"255.000000000","bid_sz":1000,"ask_sz":85,"bid_ct":1,"ask_ct":2},{"bid_px":"248.500000000","ask_px":"258.000000000","bid_sz":40,"ask_sz":200,"bid_ct":1,"ask_ct":1},{"bid_px":"247.150000000","ask_px":"260.000000000","bid_sz":400,"ask_sz":168,"bid_ct":1,"ask_ct":3},{"bid_px":"247.000000000","ask_px":"262.660000000","bid_sz":12,"ask_sz":56,"bid_ct":1,"ask_ct":1}],"symbol":"TSLA"}
{"ts_recv":"2024-11-01T08:00:13.067295659Z","hd":{"ts_event":"2024-11-01T08:00:13.067129626Z","rtype":10,"publisher_id":2,"instrument_id":16244},"action":"C","side":"A","depth":1,"price":"251.140000000","size":50,"flags":130,"ts_in_delta":166033,"sequence":317010,"levels":[{"bid_px":"250.170000000","ask_px":"250.770000000","bid_sz":50,"ask_sz":6,"bid_ct":1,"ask_ct":1},{"bid_px":"250.000000000","ask_px":"251.140000000","bid_sz":2,"ask_sz":50,"bid_ct":2,"ask_ct":1},{"bid_px":"249.930000000","ask_px":"251.150000000","bid_sz":10,"ask_sz":100,"bid_ct":1,"ask_ct":1},{"bid_px":"249.880000000","ask_px":"252.400000000","bid_sz":4,"ask_sz":1000,"bid_ct":1,"ask_ct":1},{"bid_px":"249.800000000","ask_px":"253.350000000","bid_sz":199,"ask_sz":23,"bid_ct":1,"ask_ct":1},{"bid_px":"249.770000000","ask_px":"253.650000000","bid_sz":50,"ask_sz":400,"bid_ct":1,"ask_ct":1},{"bid_px":"249.400000000","ask_px":"255.000000000","bid_sz":1000,"ask_sz":85,"bid_ct":1,"ask_ct":2},{"bid_px":"248.500000000","ask_px":"258.000000000","bid_sz":40,"ask_sz":200,"bid_ct":1,"ask_ct":1},{"bid_px":"247.150000000","ask_px":"260.000000000","bid_sz":400,"ask_sz":168,"bid_ct":1,"ask_ct":3},{"bid_px":"247.000000000","ask_px":"262.660000000","bid_sz":12,"ask_sz":56,"bid_ct":1,"ask_ct":1}],"symbol":"TSLA"}
{"ts_recv":"2024-11-01T08:00:13.067309448Z","hd":{"ts_event":"2024-11-01T08:00:13.067143347Z","rtype":10,"publisher_id":2,"instrument_id":16244},"action":"A","side":"A","depth":1,"price":"251.130000000","size":50,"flags":130,"ts_in_delta":166101,"sequence":317011,"levels":[{"bid_px":"250.170000000","ask_px":"250.770000000","bid_sz":50,"ask_sz":6,"bid_ct":1,"ask_ct":1},{"bid_px":"250.000000000","ask_px":"251.130000000","bid_sz":2,"ask_sz":50,"bid_ct":2,"ask_ct":1},{"bid_px":"249.930000000","ask_px":"251.150000000","bid_sz":10,"ask_sz":100,"bid_ct":1,"ask_ct":1},{"bid_px":"249.880000000","ask_px":"252.400000000","bid_sz":4,"ask_sz":1000,"bid_ct":1,"ask_ct":1},{"bid_px":"249.800000000","ask_px":"253.350000000","bid_sz":199,"ask_sz":23,"bid_ct":1,"ask_ct":1},{"bid_px":"249.770000000","ask_px":"253.650000000","bid_sz":50,"ask_sz":400,"bid_ct":1,"ask_ct":1},{"bid_px":"249.400000000","ask_px":"255.000000000","bid_sz":1000,"ask_sz":85,"bid_ct":1,"ask_ct":2},{"bid_px":"248.500000000","ask_px":"258.000000000","bid_sz":40,"ask_sz":200,"bid_ct":1,"ask_ct":1},{"bid_px":"247.150000000","ask_px":"260.000000000","bid_sz":400,"ask_sz":168,"bid_ct":1,"ask_ct":3},{"bid_px":"247.000000000","ask_px":"262.660000000","bid_sz":12,"ask_sz":56,"bid_ct":1,"ask_ct":1}],"symbol":"TSLA"}
{"ts_recv":"2024-11-01T08:00:13.132843278Z","hd":{"ts_event":"2024-11-01T08:00:13.132677034Z","rtype":10,"publisher_id":2,"instrument_id":16244},"action":"A","side":"B","depth":7,"price":"249.000000000","size":100,"flags":130,"ts_in_delta":166244,"sequence":317239,"levels":[{"bid_px":"250.170000000","ask_px":"250.770000000","bid_sz":50,"ask_sz":6,"bid_ct":1,"ask_ct":1},{"bid_px":"250.000000000","ask_px":"251.130000000","bid_sz":2,"ask_sz":50,"bid_ct":2,"ask_ct":1},{"bid_px":"249.930000000","ask_px":"251.150000000","bid_sz":10,"ask_sz":100,"bid_ct":1,"ask_ct":1},{"bid_px":"249.880000000","ask_px":"252.400000000","bid_sz":4,"ask_sz":1000,"bid_ct":1,"ask_ct":1},{"bid_px":"249.800000000","ask_px":"253.350000000","bid_sz":199,"ask_sz":23,"bid_ct":1,"ask_ct":1},{"bid_px":"249.770000000","ask_px":"253.650000000","bid_sz":50,"ask_sz":400,"bid_ct":1,"ask_ct":1},{"bid_px":"249.400000000","ask_px":"255.000000000","bid_sz":1000,"ask_sz":85,"bid_ct":1,"ask_ct":2},{"bid_px":"249.000000000","ask_px":"258.000000000","bid_sz":100,"ask_sz":200,"bid_ct":1,"ask_ct":1},{"bid_px":"248.500000000","ask_px":"260.000000000","bid_sz":40,"ask_sz":168,"bid_ct":1,"ask_ct":3},{"bid_px":"247.150000000","ask_px":"262.660000000","bid_sz":400,"ask_sz":56,"bid_ct":1,"ask_ct":1}],"symbol":"TSLA"}
{"ts_recv":"2024-11-01T08:00:13.134571071Z","hd":{"ts_event":"2024-11-01T08:00:13.134404595Z","rtype":10,"publisher_id":2,"instrument_id":16244},"action":"A","side":"A","depth":8,"price":"260.000000000","size":1,"flags":130,"ts_in_delta":166476,"sequence":317253,"levels":[{"bid_px":"250.170000000","ask_px":"250.770000000","bid_sz":50,"ask_sz":6,"bid_ct":1,"ask_ct":1},{"bid_px":"250.000000000","ask_px":"251.130000000","bid_sz":2,"ask_sz":50,"bid_ct":2,"ask_ct":1},{"bid_px":"249.930000000","ask_px":"251.150000000","bid_sz":10,"ask_sz":100,"bid_ct":1,"ask_ct":1},{"bid_px":"249.880000000","ask_px":"252.400000000","bid_sz":4,"ask_sz":1000,"bid_ct":1,"ask_ct":1},{"bid_px":"249.800000000","ask_px":"253.350000000","bid_sz":199,"ask_sz":23,"bid_ct":1,"ask_ct":1},{"bid_px":"249.770000000","ask_px":"253.650000000","bid_sz":50,"ask_sz":400,"bid_ct":1,"ask_ct":1},{"bid_px":"249.400000000","ask_px":"255.000000000","bid_sz":1000,"ask_sz":85,"bid_ct":1,"ask_ct":2},{"bid_px":"249.000000000","ask_px":"258.000000000","bid_sz":100,"ask_sz":200,"bid_ct":1,"ask_ct":1},{"bid_px":"248.500000000","ask_px":"260.000000000","bid_sz":40,"ask_sz":169,"bid_ct":1,"ask_ct":4},{"bid_px":"247.150000000","ask_px":"262.660000000","bid_sz":400,"ask_sz":56,"bid_ct":1,"ask_ct":1}],"symbol":"TSLA"}
{"ts_recv":"2024-11-01T08:00:13.137893281Z","hd":{"ts_event":"2024-11-01T08:00:13.137727086Z","rtype":10,"publisher_id":2,"instrument_id":16244},"action":"C","side":"B","depth":0,"price":"250.170000000","size":50,"flags":130,"ts_in_delta":166195,"sequence":317269,"levels":[{"bid_px":"250.000000000","ask_px":"250.770000000","bid_sz":2,"ask_sz":6,"bid_ct":2,"ask_ct":1},{"bid_px":"249.930000000","ask_px":"251.130000000","bid_sz":10,"ask_sz":50,"bid_ct":1,"ask_ct":1},{"bid_px":"249.880000000","ask_px":"251.150000000","bid_sz":4,"ask_sz":100,"bid_ct":1,"ask_ct":1},{"bid_px":"249.800000000","ask_px":"252.400000000","bid_sz":199,"ask_sz":1000,"bid_ct":1,"ask_ct":1},{"bid_px":"249.770000000","ask_px":"253.350000000","bid_sz":50,"ask_sz":23,"bid_ct":1,"ask_ct":1},{"bid_px":"249.400000000","ask_px":"253.650000000","bid_sz":1000,"ask_sz":400,"bid_ct":1,"ask_ct":1},{"bid_px":"249.000000000","ask_px":"255.000000000","bid_sz":100,"ask_sz":85,"bid_ct":1,"ask_ct":2},{"bid_px":"248.500000000","ask_px":"258.000000000","bid_sz":40,"ask_sz":200,"bid_ct":1,"ask_ct":1},{"bid_px":"247.150000000","ask_px":"260.000000000","bid_sz":400,"ask_sz":169,"bid_ct":1,"ask_ct":4},{"bid_px":"247.000000000","ask_px":"262.660000000","bid_sz":12,"ask_sz":56,"bid_ct":1,"ask_ct":1}],"symbol":"TSLA"}
{"ts_recv":"2024-11-01T08:00:13.137906177Z","hd":{"ts_event":"2024-11-01T08:00:13.137739685Z","rtype":10,"publisher_id":2,"instrument_id":16244},"action":"A","side":"B","depth":0,"price":"250.150000000","size":50,"flags":130,"ts_in_delta":166492,"sequence":317270,"levels":[{"bid_px":"250.150000000","ask_px":"250.770000000","bid_sz":50,"ask_sz":6,"bid_ct":1,"ask_ct":1},{"bid_px":"250.000000000","ask_px":"251.130000000","bid_sz":2,"ask_sz":50,"bid_ct":2,"ask_ct":1},{"bid_px":"249.930000000","ask_px":"251.150000000","bid_sz":10,"ask_sz":100,"bid_ct":1,"ask_ct":1},{"bid_px":"249.880000000","ask_px":"252.400000000","bid_sz":4,"ask_sz":1000,"bid_ct":1,"ask_ct":1},{"bid_px":"249.800000000","ask_px":"253.350000000","bid_sz":199,"ask_sz":23,"bid_ct":1,"ask_ct":1},{"bid_px":"249.770000000","ask_px":"253.650000000","bid_sz":50,"ask_sz":400,"bid_ct":1,"ask_ct":1},{"bid_px":"249.400000000","ask_px":"255.000000000","bid_sz":1000,"ask_sz":85,"bid_ct":1,"ask_ct":2},{"bid_px":"249.000000000","ask_px":"258.000000000","bid_sz":100,"ask_sz":200,"bid_ct":1,"ask_ct":1},{"bid_px":"248.500000000","ask_px":"260.000000000","bid_sz":40,"ask_sz":169,"bid_ct":1,"ask_ct":4},{"bid_px":"247.150000000","ask_px":"262.660000000","bid_sz":400,"ask_sz":56,"bid_ct":1,"ask_ct":1}],"symbol":"TSLA"}
{"ts_recv":"2024-11-01T08:00:13.234563518Z","hd":{"ts_event":"2024-11-01T08:00:13.234395636Z","rtype":10,"publisher_id":2,"instrument_id":16244},"action":"A","side":"A","depth":9,"price":"262.560000000","size":50,"flags":130,"ts_in_delta":167882,"sequence":317926,"levels":[{"bid_px":"250.150000000","ask_px":"250.770000000","bid_sz":50,"ask_sz":6,"bid_ct":1,"ask_ct":1},{"bid_px":"250.000000000","ask_px":"251.130000000","bid_sz":2,"ask_sz":50,"bid_ct":2,"ask_ct":1},{"bid_px":"249.930000000","ask_px":"251.150000000","bid_sz":10,"ask_sz":100,"bid_ct":1,"ask_ct":1},{"bid_px":"249.880000000","ask_px":"252.400000000","bid_sz":4,"ask_sz":1000,"bid_ct":1,"ask_ct":1},{"bid_px":"249.800000000","ask_px":"253.350000000","bid_sz":199,"ask_sz":23,"bid_ct":1,"ask_ct":1},{"bid_px":"249.770000000","ask_px":"253.650000000","bid_sz":50,"ask_sz":400,"bid_ct":1,"ask_ct":1},{"bid_px":"249.400000000","ask_px":"255.000000000","bid_sz":1000,"ask_sz":85,"bid_ct":1,"ask_ct":2},{"bid_px":"249.000000000","ask_px":"258.000000000","bid_sz":100,"ask_sz":200,"bid_ct":1,"ask_ct":1},{"bid_px":"248.500000000","ask_px":"260.000000000","bid_sz":40,"ask_sz":169,"bid_ct":1,"ask_ct":4},{"bid_px":"247.150000000","ask_px":"262.560000000","bid_sz":400,"ask_sz":50,"bid_ct":1,"ask_ct":1}],"symbol":"TSLA"}
{"ts_recv":"2024-11-01T08:00:13.247459338Z","hd":{"ts_event":"2024-11-01T08:00:13.247293005Z","rtype":10,"publisher_id":2,"instrument_id":16244},"action":"A","side":"B","depth":8,"price":"248.500000000","size":5,"flags":130,"ts_in_delta":166333,"sequence":317958,"levels":[{"bid_px":"250.150000000","ask_px":"250.770000000","bid_sz":50,"ask_sz":6,"bid_ct":1,"ask_ct":1},{"bid_px":"250.000000000","ask_px":"251.130000000","bid_sz":2,"ask_sz":50,"bid_ct":2,"ask_ct":1},{"bid_px":"249.930000000","ask_px":"251.150000000","bid_sz":10,"ask_sz":100,"bid_ct":1,"ask_ct":1},{"bid_px":"249.880000000","ask_px":"252.400000000","bid_sz":4,"ask_sz":1000,"bid_ct":1,"ask_ct":1},{"bid_px":"249.800000000","ask_px":"253.350000000","bid_sz":199,"ask_sz":23,"bid_ct":1,"ask_ct":1},{"bid_px":"249.770000000","ask_px":"253.650000000","bid_sz":50,"ask_sz":400,"bid_ct":1,"ask_ct":1},{"bid_px":"249.400000000","ask_px":"255.000000000","bid_sz":1000,"ask_sz":85,"bid_ct":1,"ask_ct":2},{"bid_px":"249.000000000","ask_px":"258.000000000","bid_sz":100,"ask_sz":200,"bid_ct":1,"ask_ct":1},{"bid_px":"248.500000000","ask_px":"260.000000000","bid_sz":45,"ask_sz":169,"bid_ct":2,"ask_ct":4},{"bid_px":"247.150000000","ask_px":"262.560000000","bid_sz":400,"ask_sz":50,"bid_ct":1,"ask_ct":1}],"symbol":"TSLA"}
{"ts_recv":"2024-11-01T08:00:13.310387215Z","hd":{"ts_event":"2024-11-01T08:00:13.310221021Z","rtype":10,"publisher_id":2,"instrument_id":16244},"action":"A","side":"A","depth":3,"price":"251.500000000","size":10,"flags":130,"ts_in_delta":166194,"sequence":318064,"levels":[{"bid_px":"250.150000000","ask_px":"250.770000000","bid_sz":50,"ask_sz":6,"bid_ct":1,"ask_ct":1},{"bid_px":"250.000000000","ask_px":"251.130000000","bid_sz":2,"ask_sz":50,"bid_ct":2,"ask_ct":1},{"bid_px":"249.930000000","ask_px":"251.150000000","bid_sz":10,"ask_sz":100,"bid_ct":1,"ask_ct":1},{"bid_px":"249.880000000","ask_px":"251.500000000","bid_sz":4,"ask_sz":10,"bid_ct":1,"ask_ct":1},{"bid_px":"249.800000000","ask_px":"252.400000000","bid_sz":199,"ask_sz":1000,"bid_ct":1,"ask_ct":1},{"bid_px":"249.770000000","ask_px":"253.350000000","bid_sz":50,"ask_sz":23,"bid_ct":1,"ask_ct":1},{"bid_px":"249.400000000","ask_px":"253.650000000","bid_sz":1000,"ask_sz":400,"bid_ct":1,"ask_ct":1},{"bid_px":"249.000000000","ask_px":"255.000000000","bid_sz":100,"ask_sz":85,"bid_ct":1,"ask_ct":2},{"bid_px":"248.500000000","ask_px":"258.000000000","bid_sz":45,"ask_sz":200,"bid_ct":2,"ask_ct":1},{"bid_px":"247.150000000","ask_px":"260.000000000","bid_sz":400,"ask_sz":169,"bid_ct":1,"ask_ct":4}],"symbol":"TSLA"}
{"ts_recv":"2024-11-01T08:00:13.310747707Z","hd":{"ts_event":"2024-11-01T08:00:13.310581079Z","rtype":10,"publisher_id":2,"instrument_id":16244},"action":"A","side":"B","depth":8,"price":"248.500000000","size":66,"flags":130,"ts_in_delta":166628,"sequence":318065,"levels":[{"bid_px":"250.150000000","ask_px":"250.770000000","bid_sz":50,"ask_sz":6,"bid_ct":1,"ask_ct":1},{"bid_px":"250.000000000","ask_px":"251.130000000","bid_sz":2,"ask_sz":50,"bid_ct":2,"ask_ct":1},{"bid_px":"249.930000000","ask_px":"251.150000000","bid_sz":10,"ask_sz":100,"bid_ct":1,"ask_ct":1},{"bid_px":"249.880000000","ask_px":"251.500000000","bid_sz":4,"ask_sz":10,"bid_ct":1,"ask_ct":1},{"bid_px":"249.800000000","ask_px":"252.400000000","bid_sz":199,"ask_sz":1000,"bid_ct":1,"ask_ct":1},{"bid_px":"249.770000000","ask_px":"253.350000000","bid_sz":50,"ask_sz":23,"bid_ct":1,"ask_ct":1},{"bid_px":"249.400000000","ask_px":"253.650000000","bid_sz":1000,"ask_sz":400,"bid_ct":1,"ask_ct":1},{"bid_px":"249.000000000","ask_px":"255.000000000","bid_sz":100,"ask_sz":85,"bid_ct":1,"ask_ct":2},{"bid_px":"248.500000000","ask_px":"258.000000000","bid_sz":111,"ask_sz":200,"bid_ct":3,"ask_ct":1},{"bid_px":"247.150000000","ask_px":"260.000000000","bid_sz":400,"ask_sz":169,"bid_ct":1,"ask_ct":4}],"symbol":"TSLA"}
{"ts_recv":"2024-11-01T08:00:13.339369155Z","hd":{"ts_event":"2024-11-01T08:00:13.339203039Z","rtype":10,"publisher_id":2,"instrument_id":16244},"action":"A","side":"B","depth":6,"price":"249.500000000","size":1000,"flags":130,"ts_in_delta":166116,"sequence":318138,"levels":[{"bid_px":"250.150000000","ask_px":"250.770000000","bid_sz":50,"ask_sz":6,"bid_ct":1,"ask_ct":1},{"bid_px":"250.000000000","ask_px":"251.130000000","bid_sz":2,"ask_sz":50,"bid_ct":2,"ask_ct":1},{"bid_px":"249.930000000","ask_px":"251.150000000","bid_sz":10,"ask_sz":100,"bid_ct":1,"ask_ct":1},{"bid_px":"249.880000000","ask_px":"251.500000000","bid_sz":4,"ask_sz":10,"bid_ct":1,"ask_ct":1},{"bid_px":"249.800000000","ask_px":"252.400000000","bid_sz":199,"ask_sz":1000,"bid_ct":1,"ask_ct":1},{"bid_px":"249.770000000","ask_px":"253.350000000","bid_sz":50,"ask_sz":23,"bid_ct":1,"ask_ct":1},{"bid_px":"249.500000000","ask_px":"253.650000000","bid_sz":1000,"ask_sz":400,"bid_ct":1,"ask_ct":1},{"bid_px":"249.400000000","ask_px":"255.000000000","bid_sz":1000,"ask_sz":85,"bid_ct":1,"ask_ct":2},{"bid_px":"249.000000000","ask_px":"258.000000000","bid_sz":100,"ask_sz":200,"bid_ct":1,"ask_ct":1},{"bid_px":"248.500000000","ask_px":"260.000000000","bid_sz":111,"ask_sz":169,"bid_ct":3,"ask_ct":4}],"symbol":"TSLA"}
{"ts_recv":"2024-11-01T08:00:13.339409856Z","hd":{"ts_event":"2024-11-01T08:00:13.339243947Z","rtype":10,"publisher_id":2,"instrument_id":16244},"action":"C","side":"B","depth":7,"price":"249.400000000","size":1000,"flags":130,"ts_in_delta":165909,"sequence":318139,"levels":[{"bid_px":"250.150000000","ask_px":"250.770000000","bid_sz":50,"ask_sz":6,"bid_ct":1,"ask_ct":1},{"bid_px":"250.000000000","ask_px":"251.130000000","bid_sz":2,"ask_sz":50,"bid_ct":2,"ask_ct":1},{"bid_px":"249.930000000","ask_px":"251.150000000","bid_sz":10,"ask_sz":100,"bid_ct":1,"ask_ct":1},{"bid_px":"249.880000000","ask_px":"251.500000000","bid_sz":4,"ask_sz":10,"bid_ct":1,"ask_ct":1},{"bid_px":"249.800000000","ask_px":"252.400000000","bid_sz":199,"ask_sz":1000,"bid_ct":1,"ask_ct":1},{"bid_px":"249.770000000","ask_px":"253.350000000","bid_sz":50,"ask_sz":23,"bid_ct":1,"ask_ct":1},{"bid_px":"249.500000000","ask_px":"253.650000000","bid_sz":1000,"ask_sz":400,"bid_ct":1,"ask_ct":1},{"bid_px":"249.000000000","ask_px":"255.000000000","bid_sz":100,"ask_sz":85,"bid_ct":1,"ask_ct":2},{"bid_px":"248.500000000","ask_px":"258.000000000","bid_sz":111,"ask_sz":200,"bid_ct":3,"ask_ct":1},{"bid_px":"247.150000000","ask_px":"260.000000000","bid_sz":400,"ask_sz":169,"bid_ct":1,"ask_ct":4}],"symbol":"TSLA"}
{"ts_recv":"2024-11-01T08:00:13.442108136Z","hd":{"ts_event":"2024-11-01T08:00:13.441942088Z","rtype":10,"publisher_id":2,"instrument_id":16244},"action":"A","side":"A","depth":7,"price":"254.990000000","size":5,"flags":130,"ts_in_delta":166048,"sequence":318427,"levels":[{"bid_px":"250.150000000","ask_px":"250.770000000","bid_sz":50,"ask_sz":6,"bid_ct":1,"ask_ct":1},{"bid_px":"250.000000000","ask_px":"251.130000000","bid_sz":2,"ask_sz":50,"bid_ct":2,"ask_ct":1},{"bid_px":"249.930000000","ask_px":"251.150000000","bid_sz":10,"ask_sz":100,"bid_ct":1,"ask_ct":1},{"bid_px":"249.880000000","ask_px":"251.500000000","bid_sz":4,"ask_sz":10,"bid_ct":1,"ask_ct":1},{"bid_px":"249.800000000","ask_px":"252.400000000","bid_sz":199,"ask_sz":1000,"bid_ct":1,"ask_ct":1},{"bid_px":"249.770000000","ask_px":"253.350000000","bid_sz":50,"ask_sz":23,"bid_ct":1,"ask_ct":1},{"bid_px":"249.500000000","ask_px":"253.650000000","bid_sz":1000,"ask_sz":400,"bid_ct":1,"ask_ct":1},{"bid_px":"249.000000000","ask_px":"254.990000000","bid_sz":100,"ask_sz":5,"bid_ct":1,"ask_ct":1},{"bid_px":"248.500000000","ask_px":"255.000000000","bid_sz":111,"ask_sz":85,"bid_ct":3,"ask_ct":2},{"bid_px":"247.150000000","ask_px":"258.000000000","bid_sz":400,"ask_sz":200,"bid_ct":1,"ask_ct":1}],"symbol":"TSLA"}
{"ts_recv":"2024-11-01T08:00:13.452403627Z","hd":{"ts_event":"2024-11-01T08:00:13.452236643Z","rtype":10,"publisher_id":2,"instrument_id":16244},"action":"T","side":"N","depth":0,"price":"250.760000000","size":6,"flags":130,"ts_in_delta":166984,"sequence":318449,"levels":[{"bid_px":"250.150000000","ask_px":"250.770000000","bid_sz":50,"ask_sz":6,"bid_ct":1,"ask_ct":1},{"bid_px":"250.000000000","ask_px":"251.130000000","bid_sz":2,"ask_sz":50,"bid_ct":2,"ask_ct":1},{"bid_px":"249.930000000","ask_px":"251.150000000","bid_sz":10,"ask_sz":100,"bid_ct":1,"ask_ct":1},{"bid_px":"249.880000000","ask_px":"251.500000000","bid_sz":4,"ask_sz":10,"bid_ct":1,"ask_ct":1},{"bid_px":"249.800000000","ask_px":"252.400000000","bid_sz":199,"ask_sz":1000,"bid_ct":1,"ask_ct":1},{"bid_px":"249.770000000","ask_px":"253.350000000","bid_sz":50,"ask_sz":23,"bid_ct":1,"ask_ct":1},{"bid_px":"249.500000000","ask_px":"253.650000000","bid_sz":1000,"ask_sz":400,"bid_ct":1,"ask_ct":1},{"bid_px":"249.000000000","ask_px":"254.990000000","bid_sz":100,"ask_sz":5,"bid_ct":1,"ask_ct":1},{"bid_px":"248.500000000","ask_px":"255.000000000","bid_sz":111,"ask_sz":85,"bid_ct":3,"ask_ct":2},{"bid_px":"247.150000000","ask_px":"258.000000000","bid_sz":400,"ask_sz":200,"bid_ct":1,"ask_ct":1}],"symbol":"TSLA"}
{"ts_recv":"2024-11-01T08:00:13.452455678Z","hd":{"ts_event":"2024-11-01T08:00:13.452289609Z","rtype":10,"publisher_id":2,"instrument_id":16244},"action":"A","side":"B","depth":0,"price":"250.450000000","size":1,"flags":130,"ts_in_delta":166069,"sequence":318450,"levels":[{"bid_px":"250.450000000","ask_px":"250.770000000","bid_sz":1,"ask_sz":6,"bid_ct":1,"ask_ct":1},{"bid_px":"250.150000000","ask_px":"251.130000000","bid_sz":50,"ask_sz":50,"bid_ct":1,"ask_ct":1},{"bid_px":"250.000000000","ask_px":"251.150000000","bid_sz":2,"ask_sz":100,"bid_ct":2,"ask_ct":1},{"bid_px":"249.930000000","ask_px":"251.500000000","bid_sz":10,"ask_sz":10,"bid_ct":1,"ask_ct":1},{"bid_px":"249.880000000","ask_px":"252.400000000","bid_sz":4,"ask_sz":1000,"bid_ct":1,"ask_ct":1},{"bid_px":"249.800000000","ask_px":"253.350000000","bid_sz":199,"ask_sz":23,"bid_ct":1,"ask_ct":1},{"bid_px":"249.770000000","ask_px":"253.650000000","bid_sz":50,"ask_sz":400,"bid_ct":1,"ask_ct":1},{"bid_px":"249.500000000","ask_px":"254.990000000","bid_sz":1000,"ask_sz":5,"bid_ct":1,"ask_ct":1},{"bid_px":"249.000000000","ask_px":"255.000000000","bid_sz":100,"ask_sz":85,"bid_ct":1,"ask_ct":2},{"bid_px":"248.500000000","ask_px":"258.000000000","bid_sz":111,"ask_sz":200,"bid_ct":3,"ask_ct":1}],"symbol":"TSLA"}
{"ts_recv":"2024-11-01T08:00:13.452480070Z","hd":{"ts_event":"2024-11-01T08:00:13.452313759Z","rtype":10,"publisher_id":2,"instrument_id":16244},"action":"A","side":"B","depth":1,"price":"250.270000000","size":1,"flags":130,"ts_in_delta":166311,"sequence":318451,"levels":[{"bid_px":"250.450000000","ask_px":"250.770000000","bid_sz":1,"ask_sz":6,"bid_ct":1,"ask_ct":1},{"bid_px":"250.270000000","ask_px":"251.130000000","bid_sz":1,"ask_sz":50,"bid_ct":1,"ask_ct":1},{"bid_px":"250.150000000","ask_px":"251.150000000","bid_sz":50,"ask_sz":100,"bid_ct":1,"ask_ct":1},{"bid_px":"250.000000000","ask_px":"251.500000000","bid_sz":2,"ask_sz":10,"bid_ct":2,"ask_ct":1},{"bid_px":"249.930000000","ask_px":"252.400000000","bid_sz":10,"ask_sz":1000,"bid_ct":1,"ask_ct":1},{"bid_px":"249.880000000","ask_px":"253.350000000","bid_sz":4,"ask_sz":23,"bid_ct":1,"ask_ct":1},{"bid_px":"249.800000000","ask_px":"253.650000000","bid_sz":199,"ask_sz":400,"bid_ct":1,"ask_ct":1},{"bid_px":"249.770000000","ask_px":"254.990000000","bid_sz":50,"ask_sz":5,"bid_ct":1,"ask_ct":1},{"bid_px":"249.500000000","ask_px":"255.000000000","bid_sz":1000,"ask_sz":85,"bid_ct":1,"ask_ct":2},{"bid_px":"249.000000000","ask_px":"258.000000000","bid_sz":100,"ask_sz":200,"bid_ct":1,"ask_ct":1}],"symbol":"TSLA"}
{"ts_recv":"2024-11-01T08:00:13.452978654Z","hd":{"ts_event":"2024-11-01T08:00:13.452811833Z","rtype":10,"publisher_id":2,"instrument_id":16244},"action":"T","side":"B","depth":0,"price":"250.770000000","size":6,"flags":130,"ts_in_delta":166821,"sequence":318455,"levels":[{"bid_px":"250.450000000","ask_px":"250.770000000","bid_sz":1,"ask_sz":6,"bid_ct":1,"ask_ct":1},{"bid_px":"250.270000000","ask_px":"251.130000000","bid_sz":1,"ask_sz":50,"bid_ct":1,"ask_ct":1},{"bid_px":"250.150000000","ask_px":"251.150000000","bid_sz":50,"ask_sz":100,"bid_ct":1,"ask_ct":1},{"bid_px":"250.000000000","ask_px":"251.500000000","bid_sz":2,"ask_sz":10,"bid_ct":2,"ask_ct":1},{"bid_px":"249.930000000","ask_px":"252.400000000","bid_sz":10,"ask_sz":1000,"bid_ct":1,"ask_ct":1},{"bid_px":"249.880000000","ask_px":"253.350000000","bid_sz":4,"ask_sz":23,"bid_ct":1,"ask_ct":1},{"bid_px":"249.800000000","ask_px":"253.650000000","bid_sz":199,"ask_sz":400,"bid_ct":1,"ask_ct":1},{"bid_px":"249.770000000","ask_px":"254.990000000","bid_sz":50,"ask_sz":5,"bid_ct":1,"ask_ct":1},{"bid_px":"249.500000000","ask_px":"255.000000000","bid_sz":1000,"ask_sz":85,"bid_ct":1,"ask_ct":2},{"bid_px":"249.000000000","ask_px":"258.000000000","bid_sz":100,"ask_sz":200,"bid_ct":1,"ask_ct":1}],"symbol":"TSLA"}
{"ts_recv":"2024-11-01T08:00:13.452978654Z","hd":{"ts_event":"2024-11-01T08:00:13.452811833Z","rtype":10,"publisher_id":2,"instrument_id":16244},"action":"C","side":"A","depth":0,"price":"250.770000000","size":6,"flags":130,"ts_in_delta":166821,"sequence":318455,"levels":[{"bid_px":"250.450000000","ask_px":"251.130000000","bid_sz":1,"ask_sz":50,"bid_ct":1,"ask_ct":1},{"bid_px":"250.270000000","ask_px":"251.150000000","bid_sz":1,"ask_sz":100,"bid_ct":1,"ask_ct":1},{"bid_px":"250.150000000","ask_px":"251.500000000","bid_sz":50,"ask_sz":10,"bid_ct":1,"ask_ct":1},{"bid_px":"250.000000000","ask_px":"252.400000000","bid_sz":2,"ask_sz":1000,"bid_ct":2,"ask_ct":1},{"bid_px":"249.930000000","ask_px":"253.350000000","bid_sz":10,"ask_sz":23,"bid_ct":1,"ask_ct":1},{"bid_px":"249.880000000","ask_px":"253.650000000","bid_sz":4,"ask_sz":400,"bid_ct":1,"ask_ct":1},{"bid_px":"249.800000000","ask_px":"254.990000000","bid_sz":199,"ask_sz":5,"bid_ct":1,"ask_ct":1},{"bid_px":"249.770000000","ask_px":"255.000000000","bid_sz":50,"ask_sz":85,"bid_ct":1,"ask_ct":2},{"bid_px":"249.500000000","ask_px":"258.000000000","bid_sz":1000,"ask_sz":200,"bid_ct":1,"ask_ct":1},{"bid_px":"249.000000000","ask_px":"260.000000000","bid_sz":100,"ask_sz":169,"bid_ct":1,"ask_ct":4}],"symbol":"TSLA"}
{"ts_recv":"2024-11-01T08:00:13.453000958Z","hd":{"ts_event":"2024-11-01T08:00:13.452833319Z","rtype":10,"publisher_id":2,"instrument_id":16244},"action":"A","side":"B","depth":0,"price":"250.520000000","size":100,"flags":130,"ts_in_delta":167639,"sequence":318456,"levels":[{"bid_px":"250.520000000","ask_px":"251.130000000","bid_sz":100,"ask_sz":50,"bid_ct":1,"ask_ct":1},{"bid_px":"250.450000000","ask_px":"251.150000000","bid_sz":1,"ask_sz":100,"bid_ct":1,"ask_ct":1},{"bid_px":"250.270000000","ask_px":"251.500000000","bid_sz":1,"ask_sz":10,"bid_ct":1,"ask_ct":1},{"bid_px":"250.150000000","ask_px":"252.400000000","bid_sz":50,"ask_sz":1000,"bid_ct":1,"ask_ct":1},{"bid_px":"250.000000000","ask_px":"253.350000000","bid_sz":2,"ask_sz":23,"bid_ct":2,"ask_ct":1},{"bid_px":"249.930000000","ask_px":"253.650000000","bid_sz":10,"ask_sz":400,"bid_ct":1,"ask_ct":1},{"bid_px":"249.880000000","ask_px":"254.990000000","bid_sz":4,"ask_sz":5,"bid_ct":1,"ask_ct":1},{"bid_px":"249.800000000","ask_px":"255.000000000","bid_sz":199,"ask_sz":85,"bid_ct":1,"ask_ct":2},{"bid_px":"249.770000000","ask_px":"258.000000000","bid_sz":50,"ask_sz":200,"bid_ct":1,"ask_ct":1},{"bid_px":"249.500000000","ask_px":"260.000000000","bid_sz":1000,"ask_sz":169,"bid_ct":1,"ask_ct":4}],"symbol":"TSLA"}
{"ts_recv":"2024-11-01T08:00:13.453012249Z","hd":{"ts_event":"2024-11-01T08:00:13.452846044Z","rtype":10,"publisher_id":2,"instrument_id":16244},"action":"A","side":"B","depth":0,"price":"250.610000000","size":26,"flags":130,"ts_in_delta":166205,"sequence":318458,"levels":[{"bid_px":"250.610000000","ask_px":"251.130000000","bid_sz":26,"ask_sz":50,"bid_ct":1,"ask_ct":1},{"bid_px":"250.520000000","ask_px":"251.150000000","bid_sz":100,"ask_sz":100,"bid_ct":1,"ask_ct":1},{"bid_px":"250.450000000","ask_px":"251.500000000","bid_sz":1,"ask_sz":10,"bid_ct":1,"ask_ct":1},{"bid_px":"250.270000000","ask_px":"252.400000000","bid_sz":1,"ask_sz":1000,"bid_ct":1,"ask_ct":1},{"bid_px":"250.150000000","ask_px":"253.350000000","bid_sz":50,"ask_sz":23,"bid_ct":1,"ask_ct":1},{"bid_px":"250.000000000","ask_px":"253.650000000","bid_sz":2,"ask_sz":400,"bid_ct":2,"ask_ct":1},{"bid_px":"249.930000000","ask_px":"254.990000000","bid_sz":10,"ask_sz":5,"bid_ct":1,"ask_ct":1},{"bid_px":"249.880000000","ask_px":"255.000000000","bid_sz":4,"ask_sz":85,"bid_ct":1,"ask_ct":2},{"bid_px":"249.800000000","ask_px":"258.000000000","bid_sz":199,"ask_sz":200,"bid_ct":1,"ask_ct":1},{"bid_px":"249.770000000","ask_px":"260.000000000","bid_sz":50,"ask_sz":169,"bid_ct":1,"ask_ct":4}],"symbol":"TSLA"}
{"ts_recv":"2024-11-01T08:00:13.453014645Z","hd":{"ts_event":"2024-11-01T08:00:13.452849113Z","rtype":10,"publisher_id":2,"instrument_id":16244},"action":"C","side":"B","depth":1,"price":"250.520000000","size":100,"flags":130,"ts_in_delta":165532,"sequence":318459,"levels":[{"bid_px":"250.610000000","ask_px":"251.130000000","bid_sz":26,"ask_sz":50,"bid_ct":1,"ask_ct":1},{"bid_px":"250.450000000","ask_px":"251.150000000","bid_sz":1,"ask_sz":100,"bid_ct":1,"ask_ct":1},{"bid_px":"250.270000000","ask_px":"251.500000000","bid_sz":1,"ask_sz":10,"bid_ct":1,"ask_ct":1},{"bid_px":"250.150000000","ask_px":"252.400000000","bid_sz":50,"ask_sz":1000,"bid_ct":1,"ask_ct":1},{"bid_px":"250.000000000","ask_px":"253.350000000","bid_sz":2,"ask_sz":23,"bid_ct":2,"ask_ct":1},{"bid_px":"249.930000000","ask_px":"253.650000000","bid_sz":10,"ask_sz":400,"bid_ct":1,"ask_ct":1},{"bid_px":"249.880000000","ask_px":"254.990000000","bid_sz":4,"ask_sz":5,"bid_ct":1,"ask_ct":1},{"bid_px":"249.800000000","ask_px":"255.000000000","bid_sz":199,"ask_sz":85,"bid_ct":1,"ask_ct":2},{"bid_px":"249.770000000","ask_px":"258.000000000","bid_sz":50,"ask_sz":200,"bid_ct":1,"ask_ct":1},{"bid_px":"249.500000000","ask_px":"260.000000000","bid_sz":1000,"ask_sz":169,"bid_ct":1,"ask_ct":4}],"symbol":"TSLA"}
{"ts_recv":"2024-11-01T08:00:13.453042680Z","hd":{"ts_event":"2024-11-01T08:00:13.452876693Z","rtype":10,"publisher_id":2,"instrument_id":16244},"action":"A","side":"B","depth":1,"price":"250.510000000","size":26,"flags":130,"ts_in_delta":165987,"sequence":318460,"levels":[{"bid_px":"250.610000000","ask_px":"251.130000000","bid_sz":26,"ask_sz":50,"bid_ct":1,"ask_ct":1},{"bid_px":"250.510000000","ask_px":"251.150000000","bid_sz":26,"ask_sz":100,"bid_ct":1,"ask_ct":1},{"bid_px":"250.450000000","ask_px":"251.500000000","bid_sz":1,"ask_sz":10,"bid_ct":1,"ask_ct":1},{"bid_px":"250.270000000","ask_px":"252.400000000","bid_sz":1,"ask_sz":1000,"bid_ct":1,"ask_ct":1},{"bid_px":"250.150000000","ask_px":"253.350000000","bid_sz":50,"ask_sz":23,"bid_ct":1,"ask_ct":1},{"bid_px":"250.000000000","ask_px":"253.650000000","bid_sz":2,"ask_sz":400,"bid_ct":2,"ask_ct":1},{"bid_px":"249.930000000","ask_px":"254.990000000","bid_sz":10,"ask_sz":5,"bid_ct":1,"ask_ct":1},{"bid_px":"249.880000000","ask_px":"255.000000000","bid_sz":4,"ask_sz":85,"bid_ct":1,"ask_ct":2},{"bid_px":"249.800000000","ask_px":"258.000000000","bid_sz":199,"ask_sz":200,"bid_ct":1,"ask_ct":1},{"bid_px":"249.770000000","ask_px":"260.000000000","bid_sz":50,"ask_sz":169,"bid_ct":1,"ask_ct":4}],"symbol":"TSLA"}
{"ts_recv":"2024-11-01T08:00:13.453082155Z","hd":{"ts_event":"2024-11-01T08:00:13.452915842Z","rtype":10,"publisher_id":2,"instrument_id":16244},"action":"A","side":"B","depth":1,"price":"250.510000000","size":67,"flags":130,"ts_in_delta":166313,"sequence":318461,"levels":[{"bid_px":"250.610000000","ask_px":"251.130000000","bid_sz":26,"ask_sz":50,"bid_ct":1,"ask_ct":1},{"bid_px":"250.510000000","ask_px":"251.150000000","bid_sz":93,"ask_sz":100,"bid_ct":2,"ask_ct":1},{"bid_px":"250.450000000","ask_px":"251.500000000","bid_sz":1,"ask_sz":10,"bid_ct":1,"ask_ct":1},{"bid_px":"250.270000000","ask_px":"252.400000000","bid_sz":1,"ask_sz":1000,"bid_ct":1,"ask_ct":1},{"bid_px":"250.150000000","ask_px":"253.350000000","bid_sz":50,"ask_sz":23,"bid_ct":1,"ask_ct":1},{"bid_px":"250.000000000","ask_px":"253.650000000","bid_sz":2,"ask_sz":400,"bid_ct":2,"ask_ct":1},{"bid_px":"249.930000000","ask_px":"254.990000000","bid_sz":10,"ask_sz":5,"bid_ct":1,"ask_ct":1},{"bid_px":"249.880000000","ask_px":"255.000000000","bid_sz":4,"ask_sz":85,"bid_ct":1,"ask_ct":2},{"bid_px":"249.800000000","ask_px":"258.000000000","bid_sz":199,"ask_sz":200,"bid_ct":1,"ask_ct":1},{"bid_px":"249.770000000","ask_px":"260.000000000","bid_sz":50,"ask_sz":169,"bid_ct":1,"ask_ct":4}],"symbol":"TSLA"}
{"ts_recv":"2024-11-01T08:00:13.453093819Z","hd":{"ts_event":"2024-11-01T08:00:13.452928000Z","rtype":10,"publisher_id":2,"instrument_id":16244},"action":"C","side":"B","depth":0,"price":"250.610000000","size":26,"flags":130,"ts_in_delta":165819,"sequence":318462,"levels":[{"bid_px":"250.510000000","ask_px":"251.130000000","bid_sz":93,"ask_sz":50,"bid_ct":2,"ask_ct":1},{"bid_px":"250.450000000","ask_px":"251.150000000","bid_sz":1,"ask_sz":100,"bid_ct":1,"ask_ct":1},{"bid_px":"250.270000000","ask_px":"251.500000000","bid_sz":1,"ask_sz":10,"bid_ct":1,"ask_ct":1},{"bid_px":"250.150000000","ask_px":"252.400000000","bid_sz":50,"ask_sz":1000,"bid_ct":1,"ask_ct":1},{"bid_px":"250.000000000","ask_px":"253.350000000","bid_sz":2,"ask_sz":23,"bid_ct":2,"ask_ct":1},{"bid_px":"249.930000000","ask_px":"253.650000000","bid_sz":10,"ask_sz":400,"bid_ct":1,"ask_ct":1},{"bid_px":"249.880000000","ask_px":"254.990000000","bid_sz":4,"ask_sz":5,"bid_ct":1,"ask_ct":1},{"bid_px":"249.800000000","ask_px":"255.000000000","bid_sz":199,"ask_sz":85,"bid_ct":1,"ask_ct":2},{"bid_px":"249.770000000","ask_px":"258.000000000","bid_sz":50,"ask_sz":200,"bid_ct":1,"ask_ct":1},{"bid_px":"249.500000000","ask_px":"260.000000000","bid_sz":1000,"ask_sz":169,"bid_ct":1,"ask_ct":4}],"symbol":"TSLA"}
{"ts_recv":"2024-11-01T08:00:13.453106450Z","hd":{"ts_event":"2024-11-01T08:00:13.452940931Z","rtype":10,"publisher_id":2,"instrument_id":16244},"action":"C","side":"B","depth":0,"price":"250.510000000","size":26,"flags":130,"ts_in_delta":165519,"sequence":318463,"levels":[{"bid_px":"250.510000000","ask_px":"251.130000000","bid_sz":67,"ask_sz":50,"bid_ct":1,"ask_ct":1},{"bid_px":"250.450000000","ask_px":"251.150000000","bid_sz":1,"ask_sz":100,"bid_ct":1,"ask_ct":1},{"bid_px":"250.270000000","ask_px":"251.500000000","bid_sz":1,"ask_sz":10,"bid_ct":1,"ask_ct":1},{"bid_px":"250.150000000","ask_px":"252.400000000","bid_sz":50,"ask_sz":1000,"bid_ct":1,"ask_ct":1},{"bid_px":"250.000000000","ask_px":"253.350000000","bid_sz":2,"ask_sz":23,"bid_ct":2,"ask_ct":1},{"bid_px":"249.930000000","ask_px":"253.650000000","bid_sz":10,"ask_sz":400,"bid_ct":1,"ask_ct":1},{"bid_px":"249.880000000","ask_px":"254.990000000","bid_sz":4,"ask_sz":5,"bid_ct":1,"ask_ct":1},{"bid_px":"249.800000000","ask_px":"255.000000000","bid_sz":199,"ask_sz":85,"bid_ct":1,"ask_ct":2},{"bid_px":"249.770000000","ask_px":"258.000000000","bid_sz":50,"ask_sz":200,"bid_ct":1,"ask_ct":1},{"bid_px":"249.500000000","ask_px":"260.000000000","bid_sz":1000,"ask_sz":169,"bid_ct":1,"ask_ct":4}],"symbol":"TSLA"}
{"ts_recv":"2024-11-01T08:00:13.453121984Z","hd":{"ts_event":"2024-11-01T08:00:13.452951117Z","rtype":10,"publisher_id":2,"instrument_id":16244},"action":"C","side":"B","depth":0,"price":"250.510000000","size":67,"flags":130,"ts_in_delta":170867,"sequence":318464,"levels":[{"bid_px":"250.450000000","ask_px":"251.130000000","bid_sz":1,"ask_sz":50,"bid_ct":1,"ask_ct":1},{"bid_px":"250.270000000","ask_px":"251.150000000","bid_sz":1,"ask_sz":100,"bid_ct":1,"ask_ct":1},{"bid_px":"250.150000000","ask_px":"251.500000000","bid_sz":50,"ask_sz":10,"bid_ct":1,"ask_ct":1},{"bid_px":"250.000000000","ask_px":"252.400000000","bid_sz":2,"ask_sz":1000,"bid_ct":2,"ask_ct":1},{"bid_px":"249.930000000","ask_px":"253.350000000","bid_sz":10,"ask_sz":23,"bid_ct":1,"ask_ct":1},{"bid_px":"249.880000000","ask_px":"253.650000000","bid_sz":4,"ask_sz":400,"bid_ct":1,"ask_ct":1},{"bid_px":"249.800000000","ask_px":"254.990000000","bid_sz":199,"ask_sz":5,"bid_ct":1,"ask_ct":1},{"bid_px":"249.770000000","ask_px":"255.000000000","bid_sz":50,"ask_sz":85,"bid_ct":1,"ask_ct":2},{"bid_px":"249.500000000","ask_px":"258.000000000","bid_sz":1000,"ask_sz":200,"bid_ct":1,"ask_ct":1},{"bid_px":"249.000000000","ask_px":"260.000000000","bid_sz":100,"ask_sz":169,"bid_ct":1,"ask_ct":4}],"symbol":"TSLA"}
{"ts_recv":"2024-11-01T08:00:13.453847021Z","hd":{"ts_event":"2024-11-01T08:00:13.453681294Z","rtype":10,"publisher_id":2,"instrument_id":16244},"action":"C","side":"B","depth":0,"price":"250.450000000","size":1,"flags":130,"ts_in_delta":165727,"sequence":318468,"levels":[{"bid_px":"250.270000000","ask_px":"251.130000000","bid_sz":1,"ask_sz":50,"bid_ct":1,"ask_ct":1},{"bid_px":"250.150000000","ask_px":"251.150000000","bid_sz":50,"ask_sz":100,"bid_ct":1,"ask_ct":1},{"bid_px":"250.000000000","ask_px":"251.500000000","bid_sz":2,"ask_sz":10,"bid_ct":2,"ask_ct":1},{"bid_px":"249.930000000","ask_px":"252.400000000","bid_sz":10,"ask_sz":1000,"bid_ct":1,"ask_ct":1},{"bid_px":"249.880000000","ask_px":"253.350000000","bid_sz":4,"ask_sz":23,"bid_ct":1,"ask_ct":1},{"bid_px":"249.800000000","ask_px":"253.650000000","bid_sz":199,"ask_sz":400,"bid_ct":1,"ask_ct":1},{"bid_px":"249.770000000","ask_px":"254.990000000","bid_sz":50,"ask_sz":5,"bid_ct":1,"ask_ct":1},{"bid_px":"249.500000000","ask_px":"255.000000000","bid_sz":1000,"ask_sz":85,"bid_ct":1,"ask_ct":2},{"bid_px":"249.000000000","ask_px":"258.000000000","bid_sz":100,"ask_sz":200,"bid_ct":1,"ask_ct":1},{"bid_px":"248.500000000","ask_px":"260.000000000","bid_sz":111,"ask_sz":169,"bid_ct":3,"ask_ct":4}],"symbol":"TSLA"}
{"ts_recv":"2024-11-01T08:00:13.464929853Z","hd":{"ts_event":"2024-11-01T08:00:13.464763555Z","rtype":10,"publisher_id":2,"instrument_id":16244},"action":"A","side":"B","depth":5,"price":"249.850000000","size":4,"flags":130,"ts_in_delta":166298,"sequence":318477,"levels":[{"bid_px":"250.270000000","ask_px":"251.130000000","bid_sz":1,"ask_sz":50,"bid_ct":1,"ask_ct":1},{"bid_px":"250.150000000","ask_px":"251.150000000","bid_sz":50,"ask_sz":100,"bid_ct":1,"ask_ct":1},{"bid_px":"250.000000000","ask_px":"251.500000000","bid_sz":2,"ask_sz":10,"bid_ct":2,"ask_ct":1},{"bid_px":"249.930000000","ask_px":"252.400000000","bid_sz":10,"ask_sz":1000,"bid_ct":1,"ask_ct":1},{"bid_px":"249.880000000","ask_px":"253.350000000","bid_sz":4,"ask_sz":23,"bid_ct":1,"ask_ct":1},{"bid_px":"249.850000000","ask_px":"253.650000000","bid_sz":4,"ask_sz":400,"bid_ct":1,"ask_ct":1},{"bid_px":"249.800000000","ask_px":"254.990000000","bid_sz":199,"ask_sz":5,"bid_ct":1,"ask_ct":1},{"bid_px":"249.770000000","ask_px":"255.000000000","bid_sz":50,"ask_sz":85,"bid_ct":1,"ask_ct":2},{"bid_px":"249.500000000","ask_px":"258.000000000","bid_sz":1000,"ask_sz":200,"bid_ct":1,"ask_ct":1},{"bid_px":"249.000000000","ask_px":"260.000000000","bid_sz":100,"ask_sz":169,"bid_ct":1,"ask_ct":4}],"symbol":"TSLA"}
{"ts_recv":"2024-11-01T08:00:13.960272379Z","hd":{"ts_event":"2024-11-01T08:00:13.960106672Z","rtype":10,"publisher_id":2,"instrument_id":16244},"action":"C","side":"B","depth":0,"price":"250.270000000","size":1,"flags":130,"ts_in_delta":165707,"sequence":319530,"levels":[{"bid_px":"250.150000000","ask_px":"251.130000000","bid_sz":50,"ask_sz":50,"bid_ct":1,"ask_ct":1},{"bid_px":"250.000000000","ask_px":"251.150000000","bid_sz":2,"ask_sz":100,"bid_ct":2,"ask_ct":1},{"bid_px":"249.930000000","ask_px":"251.500000000","bid_sz":10,"ask_sz":10,"bid_ct":1,"ask_ct":1},{"bid_px":"249.880000000","ask_px":"252.400000000","bid_sz":4,"ask_sz":1000,"bid_ct":1,"ask_ct":1},{"bid_px":"249.850000000","ask_px":"253.350000000","bid_sz":4,"ask_sz":23,"bid_ct":1,"ask_ct":1},{"bid_px":"249.800000000","ask_px":"253.650000000","bid_sz":199,"ask_sz":400,"bid_ct":1,"ask_ct":1},{"bid_px":"249.770000000","ask_px":"254.990000000","bid_sz":50,"ask_sz":5,"bid_ct":1,"ask_ct":1},{"bid_px":"249.500000000","ask_px":"255.000000000","bid_sz":1000,"ask_sz":85,"bid_ct":1,"ask_ct":2},{"bid_px":"249.000000000","ask_px":"258.000000000","bid_sz":100,"ask_sz":200,"bid_ct":1,"ask_ct":1},{"bid_px":"248.500000000","ask_px":"260.000000000","bid_sz":111,"ask_sz":169,"bid_ct":3,"ask_ct":4}],"symbol":"TSLA"}
{"ts_recv":"2024-11-01T08:00:14.059816709Z","hd":{"ts_event":"2024-11-01T08:00:14.059650349Z","rtype":10,"publisher_id":2,"instrument_id":16244},"action":"A","side":"A","depth":0,"price":"250.880000000","size":23,"flags":130,"ts_in_delta":166360,"sequence":319767,"levels":[{"bid_px":"250.150000000","ask_px":"250.880000000","bid_sz":50,"ask_sz":23,"bid_ct":1,"ask_ct":1},{"bid_px":"250.000000000","ask_px":"251.130000000","bid_sz":2,"ask_sz":50,"bid_ct":2,"ask_ct":1},{"bid_px":"249.930000000","ask_px":"251.150000000","bid_sz":10,"ask_sz":100,"bid_ct":1,"ask_ct":1},{"bid_px":"249.880000000","ask_px":"251.500000000","bid_sz":4,"ask_sz":10,"bid_ct":1,"ask_ct":1},{"bid_px":"249.850000000","ask_px":"252.400000000","bid_sz":4,"ask_sz":1000,"bid_ct":1,"ask_ct":1},{"bid_px":"249.800000000","ask_px":"253.350000000","bid_sz":199,"ask_sz":23,"bid_ct":1,"ask_ct":1},{"bid_px":"249.770000000","ask_px":"253.650000000","bid_sz":50,"ask_sz":400,"bid_ct":1,"ask_ct":1},{"bid_px":"249.500000000","ask_px":"254.990000000","bid_sz":1000,"ask_sz":5,"bid_ct":1,"ask_ct":1},{"bid_px":"249.000000000","ask_px":"255.000000000","bid_sz":100,"ask_sz":85,"bid_ct":1,"ask_ct":2},{"bid_px":"248.500000000","ask_px":"258.000000000","bid_sz":111,"ask_sz":200,"bid_ct":3,"ask_ct":1}],"symbol":"TSLA"}
{"ts_recv":"2024-11-01T08:00:14.061115915Z","hd":{"ts_event":"2024-11-01T08:00:14.060949344Z","rtype":10,"publisher_id":2,"instrument_id":16244},"action":"A","side":"A","depth":8,"price":"255.000000000","size":20,"flags":130,"ts_in_delta":166571,"sequence":319780,"levels":[{"bid_px":"250.150000000","ask_px":"250.880000000","bid_sz":50,"ask_sz":23,"bid_ct":1,"ask_ct":1},{"bid_px":"250.000000000","ask_px":"251.130000000","bid_sz":2,"ask_sz":50,"bid_ct":2,"ask_ct":1},{"bid_px":"249.930000000","ask_px":"251.150000000","bid_sz":10,"ask_sz":100,"bid_ct":1,"ask_ct":1},{"bid_px":"249.880000000","ask_px":"251.500000000","bid_sz":4,"ask_sz":10,"bid_ct":1,"ask_ct":1},{"bid_px":"249.850000000","ask_px":"252.400000000","bid_sz":4,"ask_sz":1000,"bid_ct":1,"ask_ct":1},{"bid_px":"249.800000000","ask_px":"253.350000000","bid_sz":199,"ask_sz":23,"bid_ct":1,"ask_ct":1},{"bid_px":"249.770000000","ask_px":"253.650000000","bid_sz":50,"ask_sz":400,"bid_ct":1,"ask_ct":1},{"bid_px":"249.500000000","ask_px":"254.990000000","bid_sz":1000,"ask_sz":5,"bid_ct":1,"ask_ct":1},{"bid_px":"249.000000000","ask_px":"255.000000000","bid_sz":100,"ask_sz":105,"bid_ct":1,"ask_ct":3},{"bid_px":"248.500000000","ask_px":"258.000000000","bid_sz":111,"ask_sz":200,"bid_ct":3,"ask_ct":1}],"symbol":"TSLA"}
{"ts_recv":"2024-11-01T08:00:14.103942544Z","hd":{"ts_event":"2024-11-01T08:00:14.103774190Z","rtype":10,"publisher_id":2,"instrument_id":16244},"action":"T","side":"N","depth":0,"price":"250.870000000","size":12,"flags":0,"ts_in_delta":168354,"sequence":319875,"levels":[{"bid_px":"250.150000000","ask_px":"250.880000000","bid_sz":50,"ask_sz":23,"bid_ct":1,"ask_ct":1},{"bid_px":"250.000000000","ask_px":"251.130000000","bid_sz":2,"ask_sz":50,"bid_ct":2,"ask_ct":1},{"bid_px":"249.930000000","ask_px":"251.150000000","bid_sz":10,"ask_sz":100,"bid_ct":1,"ask_ct":1},{"bid_px":"249.880000000","ask_px":"251.500000000","bid_sz":4,"ask_sz":10,"bid_ct":1,"ask_ct":1},{"bid_px":"249.850000000","ask_px":"252.400000000","bid_sz":4,"ask_sz":1000,"bid_ct":1,"ask_ct":1},{"bid_px":"249.800000000","ask_px":"253.350000000","bid_sz":199,"ask_sz":23,"bid_ct":1,"ask_ct":1},{"bid_px":"249.770000000","ask_px":"253.650000000","bid_sz":50,"ask_sz":400,"bid_ct":1,"ask_ct":1},{"bid_px":"249.500000000","ask_px":"254.990000000","bid_sz":1000,"ask_sz":5,"bid_ct":1,"ask_ct":1},{"bid_px":"249.000000000","ask_px":"255.000000000","bid_sz":100,"ask_sz":105,"bid_ct":1,"ask_ct":3},{"bid_px":"248.500000000","ask_px":"258.000000000","bid_sz":111,"ask_sz":200,"bid_ct":3,"ask_ct":1}],"symbol":"TSLA"}
{"ts_recv":"2024-11-01T08:00:14.103942544Z","hd":{"ts_event":"2024-11-01T08:00:14.103774190Z","rtype":10,"publisher_id":2,"instrument_id":16244},"action":"T","side":"B","depth":0,"price":"250.880000000","size":9,"flags":130,"ts_in_delta":168354,"sequence":319876,"levels":[{"bid_px":"250.150000000","ask_px":"250.880000000","bid_sz":50,"ask_sz":23,"bid_ct":1,"ask_ct":1},{"bid_px":"250.000000000","ask_px":"251.130000000","bid_sz":2,"ask_sz":50,"bid_ct":2,"ask_ct":1},{"bid_px":"249.930000000","ask_px":"251.150000000","bid_sz":10,"ask_sz":100,"bid_ct":1,"ask_ct":1},{"bid_px":"249.880000000","ask_px":"251.500000000","bid_sz":4,"ask_sz":10,"bid_ct":1,"ask_ct":1},{"bid_px":"249.850000000","ask_px":"252.400000000","bid_sz":4,"ask_sz":1000,"bid_ct":1,"ask_ct":1},{"bid_px":"249.800000000","ask_px":"253.350000000","bid_sz":199,"ask_sz":23,"bid_ct":1,"ask_ct":1},{"bid_px":"249.770000000","ask_px":"253.650000000","bid_sz":50,"ask_sz":400,"bid_ct":1,"ask_ct":1},{"bid_px":"249.500000000","ask_px":"254.990000000","bid_sz":1000,"ask_sz":5,"bid_ct":1,"ask_ct":1},{"bid_px":"249.000000000","ask_px":"255.000000000","bid_sz":100,"ask_sz":105,"bid_ct":1,"ask_ct":3},{"bid_px":"248.500000000","ask_px":"258.000000000","bid_sz":111,"ask_sz":200,"bid_ct":3,"ask_ct":1}],"symbol":"TSLA"}
{"ts_recv":"2024-11-01T08:00:14.103942544Z","hd":{"ts_event":"2024-11-01T08:00:14.103774190Z","rtype":10,"publisher_id":2,"instrument_id":16244},"action":"C","side":"A","depth":0,"price":"250.880000000","size":9,"flags":130,"ts_in_delta":168354,"sequence":319876,"levels":[{"bid_px":"250.150000000","ask_px":"250.880000000","bid_sz":50,"ask_sz":14,"bid_ct":1,"ask_ct":1},{"bid_px":"250.000000000","ask_px":"251.130000000","bid_sz":2,"ask_sz":50,"bid_ct":2,"ask_ct":1},{"bid_px":"249.930000000","ask_px":"251.150000000","bid_sz":10,"ask_sz":100,"bid_ct":1,"ask_ct":1},{"bid_px":"249.880000000","ask_px":"251.500000000","bid_sz":4,"ask_sz":10,"bid_ct":1,"ask_ct":1},{"bid_px":"249.850000000","ask_px":"252.400000000","bid_sz":4,"ask_sz":1000,"bid_ct":1,"ask_ct":1},{"bid_px":"249.800000000","ask_px":"253.350000000","bid_sz":199,"ask_sz":23,"bid_ct":1,"ask_ct":1},{"bid_px":"249.770000000","ask_px":"253.650000000","bid_sz":50,"ask_sz":400,"bid_ct":1,"ask_ct":1},{"bid_px":"249.500000000","ask_px":"254.990000000","bid_sz":1000,"ask_sz":5,"bid_ct":1,"ask_ct":1},{"bid_px":"249.000000000","ask_px":"255.000000000","bid_sz":100,"ask_sz":105,"bid_ct":1,"ask_ct":3},{"bid_px":"248.500000000","ask_px":"258.000000000","bid_sz":111,"ask_sz":200,"bid_ct":3,"ask_ct":1}],"symbol":"TSLA"}
{"ts_recv":"2024-11-01T08:00:14.103983462Z","hd":{"ts_event":"2024-11-01T08:00:14.103817271Z","rtype":10,"publisher_id":2,"instrument_id":16244},"action":"A","side":"B","depth":0,"price":"250.510000000","size":1,"flags":130,"ts_in_delta":166191,"sequence":319878,"levels":[{"bid_px":"250.510000000","ask_px":"250.880000000","bid_sz":1,"ask_sz":14,"bid_ct":1,"ask_ct":1},{"bid_px":"250.150000000","ask_px":"251.130000000","bid_sz":50,"ask_sz":50,"bid_ct":1,"ask_ct":1},{"bid_px":"250.000000000","ask_px":"251.150000000","bid_sz":2,"ask_sz":100,"bid_ct":2,"ask_ct":1},{"bid_px":"249.930000000","ask_px":"251.500000000","bid_sz":10,"ask_sz":10,"bid_ct":1,"ask_ct":1},{"bid_px":"249.880000000","ask_px":"252.400000000","bid_sz":4,"ask_sz":1000,"bid_ct":1,"ask_ct":1},{"bid_px":"249.850000000","ask_px":"253.350000000","bid_sz":4,"ask_sz":23,"bid_ct":1,"ask_ct":1},{"bid_px":"249.800000000","ask_px":"253.650000000","bid_sz":199,"ask_sz":400,"bid_ct":1,"ask_ct":1},{"bid_px":"249.770000000","ask_px":"254.990000000","bid_sz":50,"ask_sz":5,"bid_ct":1,"ask_ct":1},{"bid_px":"249.500000000","ask_px":"255.000000000","bid_sz":1000,"ask_sz":105,"bid_ct":1,"ask_ct":3},{"bid_px":"249.000000000","ask_px":"258.000000000","bid_sz":100,"ask_sz":200,"bid_ct":1,"ask_ct":1}],"symbol":"TSLA"}
{"ts_recv":"2024-11-01T08:00:14.104001263Z","hd":{"ts_event":"2024-11-01T08:00:14.103834859Z","rtype":10,"publisher_id":2,"instrument_id":16244},"action":"A","side":"B","depth":1,"price":"250.290000000","size":1,"flags":130,"ts_in_delta":166404,"sequence":319879,"levels":[{"bid_px":"250.510000000","ask_px":"250.880000000","bid_sz":1,"ask_sz":14,"bid_ct":1,"ask_ct":1},{"bid_px":"250.290000000","ask_px":"251.130000000","bid_sz":1,"ask_sz":50,"bid_ct":1,"ask_ct":1},{"bid_px":"250.150000000","ask_px":"251.150000000","bid_sz":50,"ask_sz":100,"bid_ct":1,"ask_ct":1},{"bid_px":"250.000000000","ask_px":"251.500000000","bid_sz":2,"ask_sz":10,"bid_ct":2,"ask_ct":1},{"bid_px":"249.930000000","ask_px":"252.400000000","bid_sz":10,"ask_sz":1000,"bid_ct":1,"ask_ct":1},{"bid_px":"249.880000000","ask_px":"253.350000000","bid_sz":4,"ask_sz":23,"bid_ct":1,"ask_ct":1},{"bid_px":"249.850000000","ask_px":"253.650000000","bid_sz":4,"ask_sz":400,"bid_ct":1,"ask_ct":1},{"bid_px":"249.800000000","ask_px":"254.990000000","bid_sz":199,"ask_sz":5,"bid_ct":1,"ask_ct":1},{"bid_px":"249.770000000","ask_px":"255.000000000","bid_sz":50,"ask_sz":105,"bid_ct":1,"ask_ct":3},{"bid_px":"249.500000000","ask_px":"258.000000000","bid_sz":1000,"ask_sz":200,"bid_ct":1,"ask_ct":1}],"symbol":"TSLA"}
{"ts_recv":"2024-11-01T08:00:14.110389232Z","hd":{"ts_event":"2024-11-01T08:00:14.110223085Z","rtype":10,"publisher_id":2,"instrument_id":16244},"action":"C","side":"B","depth":0,"price":"250.510000000","size":1,"flags":130,"ts_in_delta":166147,"sequence":319882,"levels":[{"bid_px":"250.290000000","ask_px":"250.880000000","bid_sz":1,"ask_sz":14,"bid_ct":1,"ask_ct":1},{"bid_px":"250.150000000","ask_px":"251.130000000","bid_sz":50,"ask_sz":50,"bid_ct":1,"ask_ct":1},{"bid_px":"250.000000000","ask_px":"251.150000000","bid_sz":2,"ask_sz":100,"bid_ct":2,"ask_ct":1},{"bid_px":"249.930000000","ask_px":"251.500000000","bid_sz":10,"ask_sz":10,"bid_ct":1,"ask_ct":1},{"bid_px":"249.880000000","ask_px":"252.400000000","bid_sz":4,"ask_sz":1000,"bid_ct":1,"ask_ct":1},{"bid_px":"249.850000000","ask_px":"253.350000000","bid_sz":4,"ask_sz":23,"bid_ct":1,"ask_ct":1},{"bid_px":"249.800000000","ask_px":"253.650000000","bid_sz":199,"ask_sz":400,"bid_ct":1,"ask_ct":1},{"bid_px":"249.770000000","ask_px":"254.990000000","bid_sz":50,"ask_sz":5,"bid_ct":1,"ask_ct":1},{"bid_px":"249.500000000","ask_px":"255.000000000","bid_sz":1000,"ask_sz":105,"bid_ct":1,"ask_ct":3},{"bid_px":"249.000000000","ask_px":"258.000000000","bid_sz":100,"ask_sz":200,"bid_ct":1,"ask_ct":1}],"symbol":"TSLA"}
{"ts_recv":"2024-11-01T08:00:14.372789135Z","hd":{"ts_event":"2024-11-01T08:00:14.372622693Z","rtype":10,"publisher_id":2,"instrument_id":16244},"action":"A","side":"B","depth":0,"price":"250.590000000","size":2,"flags":130,"ts_in_delta":166442,"sequence":321093,"levels":[{"bid_px":"250.590000000","ask_px":"250.880000000","bid_sz":2,"ask_sz":14,"bid_ct":1,"ask_ct":1},{"bid_px":"250.290000000","ask_px":"251.130000000","bid_sz":1,"ask_sz":50,"bid_ct":1,"ask_ct":1},{"bid_px":"250.150000000","ask_px":"251.150000000","bid_sz":50,"ask_sz":100,"bid_ct":1,"ask_ct":1},{"bid_px":"250.000000000","ask_px":"251.500000000","bid_sz":2,"ask_sz":10,"bid_ct":2,"ask_ct":1},{"bid_px":"249.930000000","ask_px":"252.400000000","bid_sz":10,"ask_sz":1000,"bid_ct":1,"ask_ct":1},{"bid_px":"249.880000000","ask_px":"253.350000000","bid_sz":4,"ask_sz":23,"bid_ct":1,"ask_ct":1},{"bid_px":"249.850000000","ask_px":"253.650000000","bid_sz":4,"ask_sz":400,"bid_ct":1,"ask_ct":1},{"bid_px":"249.800000000","ask_px":"254.990000000","bid_sz":199,"ask_sz":5,"bid_ct":1,"ask_ct":1},{"bid_px":"249.770000000","ask_px":"255.000000000","bid_sz":50,"ask_sz":105,"bid_ct":1,"ask_ct":3},{"bid_px":"249.500000000","ask_px":"258.000000000","bid_sz":1000,"ask_sz":200,"bid_ct":1,"ask_ct":1}],"symbol":"TSLA"}
{"ts_recv":"2024-11-01T08:00:14.372951976Z","hd":{"ts_event":"2024-11-01T08:00:14.372785914Z","rtype":10,"publisher_id":2,"instrument_id":16244},"action":"A","side":"B","depth":0,"price":"250.590000000","size":1,"flags":130,"ts_in_delta":166062,"sequence":321096,"levels":[{"bid_px":"250.590000000","ask_px":"250.880000000","bid_sz":3,"ask_sz":14,"bid_ct":2,"ask_ct":1},{"bid_px":"250.290000000","ask_px":"251.130000000","bid_sz":1,"ask_sz":50,"bid_ct":1,"ask_ct":1},{"bid_px":"250.150000000","ask_px":"251.150000000","bid_sz":50,"ask_sz":100,"bid_ct":1,"ask_ct":1},{"bid_px":"250.000000000","ask_px":"251.500000000","bid_sz":2,"ask_sz":10,"bid_ct":2,"ask_ct":1},{"bid_px":"249.930000000","ask_px":"252.400000000","bid_sz":10,"ask_sz":1000,"bid_ct":1,"ask_ct":1},{"bid_px":"249.880000000","ask_px":"253.350000000","bid_sz":4,"ask_sz":23,"bid_ct":1,"ask_ct":1},{"bid_px":"249.850000000","ask_px":"253.650000000","bid_sz":4,"ask_sz":400,"bid_ct":1,"ask_ct":1},{"bid_px":"249.800000000","ask_px":"254.990000000","bid_sz":199,"ask_sz":5,"bid_ct":1,"ask_ct":1},{"bid_px":"249.770000000","ask_px":"255.000000000","bid_sz":50,"ask_sz":105,"bid_ct":1,"ask_ct":3},{"bid_px":"249.500000000","ask_px":"258.000000000","bid_sz":1000,"ask_sz":200,"bid_ct":1,"ask_ct":1}],"symbol":"TSLA"}
{"ts_recv":"2024-11-01T08:00:14.373237946Z","hd":{"ts_event":"2024-11-01T08:00:14.373071835Z","rtype":10,"publisher_id":2,"instrument_id":16244},"action":"A","side":"A","depth":3,"price":"251.450000000","size":157,"flags":130,"ts_in_delta":166111,"sequence":321101,"levels":[{"bid_px":"250.590000000","ask_px":"250.880000000","bid_sz":3,"ask_sz":14,"bid_ct":2,"ask_ct":1},{"bid_px":"250.290000000","ask_px":"251.130000000","bid_sz":1,"ask_sz":50,"bid_ct":1,"ask_ct":1},{"bid_px":"250.150000000","ask_px":"251.150000000","bid_sz":50,"ask_sz":100,"bid_ct":1,"ask_ct":1},{"bid_px":"250.000000000","ask_px":"251.450000000","bid_sz":2,"ask_sz":157,"bid_ct":2,"ask_ct":1},{"bid_px":"249.930000000","ask_px":"251.500000000","bid_sz":10,"ask_sz":10,"bid_ct":1,"ask_ct":1},{"bid_px":"249.880000000","ask_px":"252.400000000","bid_sz":4,"ask_sz":1000,"bid_ct":1,"ask_ct":1},{"bid_px":"249.850000000","ask_px":"253.350000000","bid_sz":4,"ask_sz":23,"bid_ct":1,"ask_ct":1},{"bid_px":"249.800000000","ask_px":"253.650000000","bid_sz":199,"ask_sz":400,"bid_ct":1,"ask_ct":1},{"bid_px":"249.770000000","ask_px":"254.990000000","bid_sz":50,"ask_sz":5,"bid_ct":1,"ask_ct":1},{"bid_px":"249.500000000","ask_px":"255.000000000","bid_sz":1000,"ask_sz":105,"bid_ct":1,"ask_ct":3}],"symbol":"TSLA"}
{"ts_recv":"2024-11-01T08:00:14.373786027Z","hd":{"ts_event":"2024-11-01T08:00:14.373619762Z","rtype":10,"publisher_id":2,"instrument_id":16244},"action":"A","side":"A","depth":9,"price":"255.000000000","size":50,"flags":130,"ts_in_delta":166265,"sequence":321109,"levels":[{"bid_px":"250.590000000","ask_px":"250.880000000","bid_sz":3,"ask_sz":14,"bid_ct":2,"ask_ct":1},{"bid_px":"250.290000000","ask_px":"251.130000000","bid_sz":1,"ask_sz":50,"bid_ct":1,"ask_ct":1},{"bid_px":"250.150000000","ask_px":"251.150000000","bid_sz":50,"ask_sz":100,"bid_ct":1,"ask_ct":1},{"bid_px":"250.000000000","ask_px":"251.450000000","bid_sz":2,"ask_sz":157,"bid_ct":2,"ask_ct":1},{"bid_px":"249.930000000","ask_px":"251.500000000","bid_sz":10,"ask_sz":10,"bid_ct":1,"ask_ct":1},{"bid_px":"249.880000000","ask_px":"252.400000000","bid_sz":4,"ask_sz":1000,"bid_ct":1,"ask_ct":1},{"bid_px":"249.850000000","ask_px":"253.350000000","bid_sz":4,"ask_sz":23,"bid_ct":1,"ask_ct":1},{"bid_px":"249.800000000","ask_px":"253.650000000","bid_sz":199,"ask_sz":400,"bid_ct":1,"ask_ct":1},{"bid_px":"249.770000000","ask_px":"254.990000000","bid_sz":50,"ask_sz":5,"bid_ct":1,"ask_ct":1},{"bid_px":"249.500000000","ask_px":"255.000000000","bid_sz":1000,"ask_sz":155,"bid_ct":1,"ask_ct":4}],"symbol":"TSLA"}
{"ts_recv":"2024-11-01T08:00:14.421150070Z","hd":{"ts_event":"2024-11-01T08:00:14.420983738Z","rtype":10,"publisher_id":2,"instrument_id":16244},"action":"A","side":"A","depth":9,"price":"255.000000000","size":5,"flags":130,"ts_in_delta":166332,"sequence":321243,"levels":[{"bid_px":"250.590000000","ask_px":"250.880000000","bid_sz":3,"ask_sz":14,"bid_ct":2,"ask_ct":1},{"bid_px":"250.290000000","ask_px":"251.130000000","bid_sz":1,"ask_sz":50,"bid_ct":1,"ask_ct":1},{"bid_px":"250.150000000","ask_px":"251.150000000","bid_sz":50,"ask_sz":100,"bid_ct":1,"ask_ct":1},{"bid_px":"250.000000000","ask_px":"251.450000000","bid_sz":2,"ask_sz":157,"bid_ct":2,"ask_ct":1},{"bid_px":"249.930000000","ask_px":"251.500000000","bid_sz":10,"ask_sz":10,"bid_ct":1,"ask_ct":1},{"bid_px":"249.880000000","ask_px":"252.400000000","bid_sz":4,"ask_sz":1000,"bid_ct":1,"ask_ct":1},{"bid_px":"249.850000000","ask_px":"253.350000000","bid_sz":4,"ask_sz":23,"bid_ct":1,"ask_ct":1},{"bid_px":"249.800000000","ask_px":"253.650000000","bid_sz":199,"ask_sz":400,"bid_ct":1,"ask_ct":1},{"bid_px":"249.770000000","ask_px":"254.990000000","bid_sz":50,"ask_sz":5,"bid_ct":1,"ask_ct":1},{"bid_px":"249.500000000","ask_px":"255.000000000","bid_sz":1000,"ask_sz":160,"bid_ct":1,"ask_ct":5}],"symbol":"TSLA"}
{"ts_recv":"2024-11-01T08:00:14.422030836Z","hd":{"ts_event":"2024-11-01T08:00:14.421864617Z","rtype":10,"publisher_id":2,"instrument_id":16244},"action":"A","side":"A","depth":3,"price":"251.450000000","size":217,"flags":130,"ts_in_delta":166219,"sequence":321257,"levels":[{"bid_px":"250.590000000","ask_px":"250.880000000","bid_sz":3,"ask_sz":14,"bid_ct":2,"ask_ct":1},{"bid_px":"250.290000000","ask_px":"251.130000000","bid_sz":1,"ask_sz":50,"bid_ct":1,"ask_ct":1},{"bid_px":"250.150000000","ask_px":"251.150000000","bid_sz":50,"ask_sz":100,"bid_ct":1,"ask_ct":1},{"bid_px":"250.000000000","ask_px":"251.450000000","bid_sz":2,"ask_sz":374,"bid_ct":2,"ask_ct":2},{"bid_px":"249.930000000","ask_px":"251.500000000","bid_sz":10,"ask_sz":10,"bid_ct":1,"ask_ct":1},{"bid_px":"249.880000000","ask_px":"252.400000000","bid_sz":4,"ask_sz":1000,"bid_ct":1,"ask_ct":1},{"bid_px":"249.850000000","ask_px":"253.350000000","bid_sz":4,"ask_sz":23,"bid_ct":1,"ask_ct":1},{"bid_px":"249.800000000","ask_px":"253.650000000","bid_sz":199,"ask_sz":400,"bid_ct":1,"ask_ct":1},{"bid_px":"249.770000000","ask_px":"254.990000000","bid_sz":50,"ask_sz":5,"bid_ct":1,"ask_ct":1},{"bid_px":"249.500000000","ask_px":"255.000000000","bid_sz":1000,"ask_sz":160,"bid_ct":1,"ask_ct":5}],"symbol":"TSLA"}
{"ts_recv":"2024-11-01T08:00:14.474154694Z","hd":{"ts_event":"2024-11-01T08:00:14.473988644Z","rtype":10,"publisher_id":2,"instrument_id":16244},"action":"A","side":"B","depth":0,"price":"250.590000000","size":4,"flags":130,"ts_in_delta":166050,"sequence":321323,"levels":[{"bid_px":"250.590000000","ask_px":"250.880000000","bid_sz":7,"ask_sz":14,"bid_ct":3,"ask_ct":1},{"bid_px":"250.290000000","ask_px":"251.130000000","bid_sz":1,"ask_sz":50,"bid_ct":1,"ask_ct":1},{"bid_px":"250.150000000","ask_px":"251.150000000","bid_sz":50,"ask_sz":100,"bid_ct":1,"ask_ct":1},{"bid_px":"250.000000000","ask_px":"251.450000000","bid_sz":2,"ask_sz":374,"bid_ct":2,"ask_ct":2},{"bid_px":"249.930000000","ask_px":"251.500000000","bid_sz":10,"ask_sz":10,"bid_ct":1,"ask_ct":1},{"bid_px":"249.880000000","ask_px":"252.400000000","bid_sz":4,"ask_sz":1000,"bid_ct":1,"ask_ct":1},{"bid_px":"249.850000000","ask_px":"253.350000000","bid_sz":4,"ask_sz":23,"bid_ct":1,"ask_ct":1},{"bid_px":"249.800000000","ask_px":"253.650000000","bid_sz":199,"ask_sz":400,"bid_ct":1,"ask_ct":1},{"bid_px":"249.770000000","ask_px":"254.990000000","bid_sz":50,"ask_sz":5,"bid_ct":1,"ask_ct":1},{"bid_px":"249.500000000","ask_px":"255.000000000","bid_sz":1000,"ask_sz":160,"bid_ct":1,"ask_ct":5}],"symbol":"TSLA"}
{"ts_recv":"2024-11-01T08:00:14.475259273Z","hd":{"ts_event":"2024-11-01T08:00:14.475093049Z","rtype":10,"publisher_id":2,"instrument_id":16244},"action":"A","side":"A","depth":8,"price":"253.880000000","size":8,"flags":130,"ts_in_delta":166224,"sequence":321336,"levels":[{"bid_px":"250.590000000","ask_px":"250.880000000","bid_sz":7,"ask_sz":14,"bid_ct":3,"ask_ct":1},{"bid_px":"250.290000000","ask_px":"251.130000000","bid_sz":1,"ask_sz":50,"bid_ct":1,"ask_ct":1},{"bid_px":"250.150000000","ask_px":"251.150000000","bid_sz":50,"ask_sz":100,"bid_ct":1,"ask_ct":1},{"bid_px":"250.000000000","ask_px":"251.450000000","bid_sz":2,"ask_sz":374,"bid_ct":2,"ask_ct":2},{"bid_px":"249.930000000","ask_px":"251.500000000","bid_sz":10,"ask_sz":10,"bid_ct":1,"ask_ct":1},{"bid_px":"249.880000000","ask_px":"252.400000000","bid_sz":4,"ask_sz":1000,"bid_ct":1,"ask_ct":1},{"bid_px":"249.850000000","ask_px":"253.350000000","bid_sz":4,"ask_sz":23,"bid_ct":1,"ask_ct":1},{"bid_px":"249.800000000","ask_px":"253.650000000","bid_sz":199,"ask_sz":400,"bid_ct":1,"ask_ct":1},{"bid_px":"249.770000000","ask_px":"253.880000000","bid_sz":50,"ask_sz":8,"bid_ct":1,"ask_ct":1},{"bid_px":"249.500000000","ask_px":"254.990000000","bid_sz":1000,"ask_sz":5,"bid_ct":1,"ask_ct":1}],"symbol":"TSLA"}
{"ts_recv":"2024-11-01T08:00:14.561172921Z","hd":{"ts_event":"2024-11-01T08:00:14.561006642Z","rtype":10,"publisher_id":2,"instrument_id":16244},"action":"A","side":"B","depth":2,"price":"250.150000000","size":50,"flags":130,"ts_in_delta":166279,"sequence":321582,"levels":[{"bid_px":"250.590000000","ask_px":"250.880000000","bid_sz":7,"ask_sz":14,"bid_ct":3,"ask_ct":1},{"bid_px":"250.290000000","ask_px":"251.130000000","bid_sz":1,"ask_sz":50,"bid_ct":1,"ask_ct":1},{"bid_px":"250.150000000","ask_px":"251.150000000","bid_sz":100,"ask_sz":100,"bid_ct":2,"ask_ct":1},{"bid_px":"250.000000000","ask_px":"251.450000000","bid_sz":2,"ask_sz":374,"bid_ct":2,"ask_ct":2},{"bid_px":"249.930000000","ask_px":"251.500000000","bid_sz":10,"ask_sz":10,"bid_ct":1,"ask_ct":1},{"bid_px":"249.880000000","ask_px":"252.400000000","bid_sz":4,"ask_sz":1000,"bid_ct":1,"ask_ct":1},{"bid_px":"249.850000000","ask_px":"253.350000000","bid_sz":4,"ask_sz":23,"bid_ct":1,"ask_ct":1},{"bid_px":"249.800000000","ask_px":"253.650000000","bid_sz":199,"ask_sz":400,"bid_ct":1,"ask_ct":1},{"bid_px":"249.770000000","ask_px":"253.880000000","bid_sz":50,"ask_sz":8,"bid_ct":1,"ask_ct":1},{"bid_px":"249.500000000","ask_px":"254.990000000","bid_sz":1000,"ask_sz":5,"bid_ct":1,"ask_ct":1}],"symbol":"TSLA"}
{"ts_recv":"2024-11-01T08:00:14.609094522Z","hd":{"ts_event":"2024-11-01T08:00:14.608928632Z","rtype":10,"publisher_id":2,"instrument_id":16244},"action":"C","side":"B","depth":1,"price":"250.290000000","size":1,"flags":130,"ts_in_delta":165890,"sequence":321698,"levels":[{"bid_px":"250.590000000","ask_px":"250.880000000","bid_sz":7,"ask_sz":14,"bid_ct":3,"ask_ct":1},{"bid_px":"250.150000000","ask_px":"251.130000000","bid_sz":100,"ask_sz":50,"bid_ct":2,"ask_ct":1},{"bid_px":"250.000000000","ask_px":"251.150000000","bid_sz":2,"ask_sz":100,"bid_ct":2,"ask_ct":1},{"bid_px":"249.930000000","ask_px":"251.450000000","bid_sz":10,"ask_sz":374,"bid_ct":1,"ask_ct":2},{"bid_px":"249.880000000","ask_px":"251.500000000","bid_sz":4,"ask_sz":10,"bid_ct":1,"ask_ct":1},{"bid_px":"249.850000000","ask_px":"252.400000000","bid_sz":4,"ask_sz":1000,"bid_ct":1,"ask_ct":1},{"bid_px":"249.800000000","ask_px":"253.350000000","bid_sz":199,"ask_sz":23,"bid_ct":1,"ask_ct":1},{"bid_px":"249.770000000","ask_px":"253.650000000","bid_sz":50,"ask_sz":400,"bid_ct":1,"ask_ct":1},{"bid_px":"249.500000000","ask_px":"253.880000000","bid_sz":1000,"ask_sz":8,"bid_ct":1,"ask_ct":1},{"bid_px":"249.010000000","ask_px":"254.990000000","bid_sz":3,"ask_sz":5,"bid_ct":1,"ask_ct":1}],"symbol":"TSLA"}
{"ts_recv":"2024-11-01T08:00:14.737892197Z","hd":{"ts_event":"2024-11-01T08:00:14.737725942Z","rtype":10,"publisher_id":2,"instrument_id":16244},"action":"A","side":"A","depth":0,"price":"250.790000000","size":200,"flags":130,"ts_in_delta":166255,"sequence":322141,"levels":[{"bid_px":"250.590000000","ask_px":"250.790000000","bid_sz":7,"ask_sz":200,"bid_ct":3,"ask_ct":1},{"bid_px":"250.150000000","ask_px":"250.880000000","bid_sz":100,"ask_sz":14,"bid_ct":2,"ask_ct":1},{"bid_px":"250.000000000","ask_px":"251.130000000","bid_sz":2,"ask_sz":50,"bid_ct":2,"ask_ct":1},{"bid_px":"249.930000000","ask_px":"251.150000000","bid_sz":10,"ask_sz":100,"bid_ct":1,"ask_ct":1},{"bid_px":"249.880000000","ask_px":"251.450000000","bid_sz":4,"ask_sz":374,"bid_ct":1,"ask_ct":2},{"bid_px":"249.850000000","ask_px":"251.500000000","bid_sz":4,"ask_sz":10,"bid_ct":1,"ask_ct":1},{"bid_px":"249.800000000","ask_px":"252.400000000","bid_sz":199,"ask_sz":1000,"bid_ct":1,"ask_ct":1},{"bid_px":"249.770000000","ask_px":"253.350000000","bid_sz":50,"ask_sz":23,"bid_ct":1,"ask_ct":1},{"bid_px":"249.500000000","ask_px":"253.650000000","bid_sz":1000,"ask_sz":400,"bid_ct":1,"ask_ct":1},{"bid_px":"249.010000000","ask_px":"253.880000000","bid_sz":3,"ask_sz":8,"bid_ct":1,"ask_ct":1}],"symbol":"TSLA"}
{"ts_recv":"2024-11-01T08:00:14.749487202Z","hd":{"ts_event":"2024-11-01T08:00:14.749320310Z","rtype":10,"publisher_id":2,"instrument_id":16244},"action":"A","side":"A","depth":4,"price":"251.400000000","size":1000,"flags":130,"ts_in_delta":166892,"sequence":322153,"levels":[{"bid_px":"250.590000000","ask_px":"250.790000000","bid_sz":7,"ask_sz":200,"bid_ct":3,"ask_ct":1},{"bid_px":"250.150000000","ask_px":"250.880000000","bid_sz":100,"ask_sz":14,"bid_ct":2,"ask_ct":1},{"bid_px":"250.000000000","ask_px":"251.130000000","bid_sz":2,"ask_sz":50,"bid_ct":2,"ask_ct":1},{"bid_px":"249.930000000","ask_px":"251.150000000","bid_sz":10,"ask_sz":100,"bid_ct":1,"ask_ct":1},{"bid_px":"249.880000000","ask_px":"251.400000000","bid_sz":4,"ask_sz":1000,"bid_ct":1,"ask_ct":1},{"bid_px":"249.850000000","ask_px":"251.450000000","bid_sz":4,"ask_sz":374,"bid_ct":1,"ask_ct":2},{"bid_px":"249.800000000","ask_px":"251.500000000","bid_sz":199,"ask_sz":10,"bid_ct":1,"ask_ct":1},{"bid_px":"249.770000000","ask_px":"252.400000000","bid_sz":50,"ask_sz":1000,"bid_ct":1,"ask_ct":1},{"bid_px":"249.500000000","ask_px":"253.350000000","bid_sz":1000,"ask_sz":23,"bid_ct":1,"ask_ct":1},{"bid_px":"249.010000000","ask_px":"253.650000000","bid_sz":3,"ask_sz":400,"bid_ct":1,"ask_ct":1}],"symbol":"TSLA"}
{"ts_recv":"2024-11-01T08:00:14.749537643Z","hd":{"ts_event":"2024-11-01T08:00:14.749371488Z","rtype":10,"publisher_id":2,"instrument_id":16244},"action":"C","side":"A","depth":7,"price":"252.400000000","size":1000,"flags":130,"ts_in_delta":166155,"sequence":322154,"levels":[{"bid_px":"250.590000000","ask_px":"250.790000000","bid_sz":7,"ask_sz":200,"bid_ct":3,"ask_ct":1},{"bid_px":"250.150000000","ask_px":"250.880000000","bid_sz":100,"ask_sz":14,"bid_ct":2,"ask_ct":1},{"bid_px":"250.000000000","ask_px":"251.130000000","bid_sz":2,"ask_sz":50,"bid_ct":2,"ask_ct":1},{"bid_px":"249.930000000","ask_px":"251.150000000","bid_sz":10,"ask_sz":100,"bid_ct":1,"ask_ct":1},{"bid_px":"249.880000000","ask_px":"251.400000000","bid_sz":4,"ask_sz":1000,"bid_ct":1,"ask_ct":1},{"bid_px":"249.850000000","ask_px":"251.450000000","bid_sz":4,"ask_sz":374,"bid_ct":1,"ask_ct":2},{"bid_px":"249.800000000","ask_px":"251.500000000","bid_sz":199,"ask_sz":10,"bid_ct":1,"ask_ct":1},{"bid_px":"249.770000000","ask_px":"253.350000000","bid_sz":50,"ask_sz":23,"bid_ct":1,"ask_ct":1},{"bid_px":"249.500000000","ask_px":"253.650000000","bid_sz":1000,"ask_sz":400,"bid_ct":1,"ask_ct":1},{"bid_px":"249.010000000","ask_px":"253.880000000","bid_sz":3,"ask_sz":8,"bid_ct":1,"ask_ct":1}],"symbol":"TSLA"}
{"ts_recv":"2024-11-01T08:00:14.768424321Z","hd":{"ts_event":"2024-11-01T08:00:14.768258475Z","rtype":10,"publisher_id":2,"instrument_id":16244},"action":"C","side":"A","depth":4,"price":"251.400000000","size":1000,"flags":130,"ts_in_delta":165846,"sequence":322175,"levels":[{"bid_px":"250.590000000","ask_px":"250.790000000","bid_sz":7,"ask_sz":200,"bid_ct":3,"ask_ct":1},{"bid_px":"250.150000000","ask_px":"250.880000000","bid_sz":100,"ask_sz":14,"bid_ct":2,"ask_ct":1},{"bid_px":"250.000000000","ask_px":"251.130000000","bid_sz":2,"ask_sz":50,"bid_ct":2,"ask_ct":1},{"bid_px":"249.930000000","ask_px":"251.150000000","bid_sz":10,"ask_sz":100,"bid_ct":1,"ask_ct":1},{"bid_px":"249.880000000","ask_px":"251.450000000","bid_sz":4,"ask_sz":374,"bid_ct":1,"ask_ct":2},{"bid_px":"249.850000000","ask_px":"251.500000000","bid_sz":4,"ask_sz":10,"bid_ct":1,"ask_ct":1},{"bid_px":"249.800000000","ask_px":"253.350000000","bid_sz":199,"ask_sz":23,"bid_ct":1,"ask_ct":1},{"bid_px":"249.770000000","ask_px":"253.650000000","bid_sz":50,"ask_sz":400,"bid_ct":1,"ask_ct":1},{"bid_px":"249.500000000","ask_px":"253.880000000","bid_sz":1000,"ask_sz":8,"bid_ct":1,"ask_ct":1},{"bid_px":"249.010000000","ask_px":"254.990000000","bid_sz":3,"ask_sz":5,"bid_ct":1,"ask_ct":1}],"symbol":"TSLA"}
{"ts_recv":"2024-11-01T08:00:14.779854583Z","hd":{"ts_event":"2024-11-01T08:00:14.779688487Z","rtype":10,"publisher_id":2,"instrument_id":16244},"action":"A","side":"A","depth":6,"price":"252.100000000","size":1000,"flags":130,"ts_in_delta":166096,"sequence":322200,"levels":[{"bid_px":"250.590000000","ask_px":"250.790000000","bid_sz":7,"ask_sz":200,"bid_ct":3,"ask_ct":1},{"bid_px":"250.150000000","ask_px":"250.880000000","bid_sz":100,"ask_sz":14,"bid_ct":2,"ask_ct":1},{"bid_px":"250.000000000","ask_px":"251.130000000","bid_sz":2,"ask_sz":50,"bid_ct":2,"ask_ct":1},{"bid_px":"249.930000000","ask_px":"251.150000000","bid_sz":10,"ask_sz":100,"bid_ct":1,"ask_ct":1},{"bid_px":"249.880000000","ask_px":"251.450000000","bid_sz":4,"ask_sz":374,"bid_ct":1,"ask_ct":2},{"bid_px":"249.850000000","ask_px":"251.500000000","bid_sz":4,"ask_sz":10,"bid_ct":1,"ask_ct":1},{"bid_px":"249.800000000","ask_px":"252.100000000","bid_sz":199,"ask_sz":1000,"bid_ct":1,"ask_ct":1},{"bid_px":"249.770000000","ask_px":"253.350000000","bid_sz":50,"ask_sz":23,"bid_ct":1,"ask_ct":1},{"bid_px":"249.500000000","ask_px":"253.650000000","bid_sz":1000,"ask_sz":400,"bid_ct":1,"ask_ct":1},{"bid_px":"249.010000000","ask_px":"253.880000000","bid_sz":3,"ask_sz":8,"bid_ct":1,"ask_ct":1}],"symbol":"TSLA"}
{"ts_recv":"2024-11-01T08:00:14.780606166Z","hd":{"ts_event":"2024-11-01T08:00:14.780439656Z","rtype":10,"publisher_id":2,"instrument_id":16244},"action":"A","side":"A","depth":3,"price":"251.150000000","size":100,"flags":130,"ts_in_delta":166510,"sequence":322202,"levels":[{"bid_px":"250.590000000","ask_px":"250.790000000","bid_sz":7,"ask_sz":200,"bid_ct":3,"ask_ct":1},{"bid_px":"250.150000000","ask_px":"250.880000000","bid_sz":100,"ask_sz":14,"bid_ct":2,"ask_ct":1},{"bid_px":"250.000000000","ask_px":"251.130000000","bid_sz":2,"ask_sz":50,"bid_ct":2,"ask_ct":1},{"bid_px":"249.930000000","ask_px":"251.150000000","bid_sz":10,"ask_sz":200,"bid_ct":1,"ask_ct":2},{"bid_px":"249.880000000","ask_px":"251.450000000","bid_sz":4,"ask_sz":374,"bid_ct":1,"ask_ct":2},{"bid_px":"249.850000000","ask_px":"251.500000000","bid_sz":4,"ask_sz":10,"bid_ct":1,"ask_ct":1},{"bid_px":"249.800000000","ask_px":"252.100000000","bid_sz":199,"ask_sz":1000,"bid_ct":1,"ask_ct":1},{"bid_px":"249.770000000","ask_px":"253.350000000","bid_sz":50,"ask_sz":23,"bid_ct":1,"ask_ct":1},{"bid_px":"249.500000000","ask_px":"253.650000000","bid_sz":1000,"ask_sz":400,"bid_ct":1,"ask_ct":1},{"bid_px":"249.010000000","ask_px":"253.880000000","bid_sz":3,"ask_sz":8,"bid_ct":1,"ask_ct":1}],"symbol":"TSLA"}
{"ts_recv":"2024-11-01T08:00:14.800331271Z","hd":{"ts_event":"2024-11-01T08:00:14.800165481Z","rtype":10,"publisher_id":2,"instrument_id":16244},"action":"C","side":"A","depth":6,"price":"252.100000000","size":1000,"flags":130,"ts_in_delta":165790,"sequence":322237,"levels":[{"bid_px":"250.590000000","ask_px":"250.790000000","bid_sz":7,"ask_sz":200,"bid_ct":3,"ask_ct":1},{"bid_px":"250.150000000","ask_px":"250.880000000","bid_sz":100,"ask_sz":14,"bid_ct":2,"ask_ct":1},{"bid_px":"250.000000000","ask_px":"251.130000000","bid_sz":2,"ask_sz":50,"bid_ct":2,"ask_ct":1},{"bid_px":"249.930000000","ask_px":"251.150000000","bid_sz":10,"ask_sz":200,"bid_ct":1,"ask_ct":2},{"bid_px":"249.880000000","ask_px":"251.450000000","bid_sz":4,"ask_sz":374,"bid_ct":1,"ask_ct":2},{"bid_px":"249.850000000","ask_px":"251.500000000","bid_sz":4,"ask_sz":10,"bid_ct":1,"ask_ct":1},{"bid_px":"249.800000000","ask_px":"253.350000000","bid_sz":199,"ask_sz":23,"bid_ct":1,"ask_ct":1},{"bid_px":"249.770000000","ask_px":"253.650000000","bid_sz":50,"ask_sz":400,"bid_ct":1,"ask_ct":1},{"bid_px":"249.500000000","ask_px":"253.880000000","bid_sz":1000,"ask_sz":8,"bid_ct":1,"ask_ct":1},{"bid_px":"249.010000000","ask_px":"254.990000000","bid_sz":3,"ask_sz":5,"bid_ct":1,"ask_ct":1}],"symbol":"TSLA"}
{"ts_recv":"2024-11-01T08:00:14.811830976Z","hd":{"ts_event":"2024-11-01T08:00:14.811664676Z","rtype":10,"publisher_id":2,"instrument_id":16244},"action":"A","side":"A","depth":6,"price":"252.300000000","size":1000,"flags":130,"ts_in_delta":166300,"sequence":322246,"levels":[{"bid_px":"250.590000000","ask_px":"250.790000000","bid_sz":7,"ask_sz":200,"bid_ct":3,"ask_ct":1},{"bid_px":"250.150000000","ask_px":"250.880000000","bid_sz":100,"ask_sz":14,"bid_ct":2,"ask_ct":1},{"bid_px":"250.000000000","ask_px":"251.130000000","bid_sz":2,"ask_sz":50,"bid_ct":2,"ask_ct":1},{"bid_px":"249.930000000","ask_px":"251.150000000","bid_sz":10,"ask_sz":200,"bid_ct":1,"ask_ct":2},{"bid_px":"249.880000000","ask_px":"251.450000000","bid_sz":4,"ask_sz":374,"bid_ct":1,"ask_ct":2},{"bid_px":"249.850000000","ask_px":"251.500000000","bid_sz":4,"ask_sz":10,"bid_ct":1,"ask_ct":1},{"bid_px":"249.800000000","ask_px":"252.300000000","bid_sz":199,"ask_sz":1000,"bid_ct":1,"ask_ct":1},{"bid_px":"249.770000000","ask_px":"253.350000000","bid_sz":50,"ask_sz":23,"bid_ct":1,"ask_ct":1},{"bid_px":"249.500000000","ask_px":"253.650000000","bid_sz":1000,"ask_sz":400,"bid_ct":1,"ask_ct":1},{"bid_px":"249.010000000","ask_px":"253.880000000","bid_sz":3,"ask_sz":8,"bid_ct":1,"ask_ct":1}],"symbol":"TSLA"}
{"ts_recv":"2024-11-01T08:00:14.845725995Z","hd":{"ts_event":"2024-11-01T08:00:14.845560224Z","rtype":10,"publisher_id":2,"instrument_id":16244},"action":"C","side":"A","depth":3,"price":"251.150000000","size":100,"flags":130,"ts_in_delta":165771,"sequence":322335,"levels":[{"bid_px":"250.590000000","ask_px":"250.790000000","bid_sz":7,"ask_sz":200,"bid_ct":3,"ask_ct":1},{"bid_px":"250.150000000","ask_px":"250.880000000","bid_sz":100,"ask_sz":14,"bid_ct":2,"ask_ct":1},{"bid_px":"250.000000000","ask_px":"251.130000000","bid_sz":2,"ask_sz":50,"bid_ct":2,"ask_ct":1},{"bid_px":"249.930000000","ask_px":"251.150000000","bid_sz":10,"ask_sz":100,"bid_ct":1,"ask_ct":1},{"bid_px":"249.880000000","ask_px":"251.450000000","bid_sz":4,"ask_sz":374,"bid_ct":1,"ask_ct":2},{"bid_px":"249.850000000","ask_px":"251.500000000","bid_sz":4,"ask_sz":10,"bid_ct":1,"ask_ct":1},{"bid_px":"249.800000000","ask_px":"252.300000000","bid_sz":199,"ask_sz":1000,"bid_ct":1,"ask_ct":1},{"bid_px":"249.770000000","ask_px":"253.350000000","bid_sz":50,"ask_sz":23,"bid_ct":1,"ask_ct":1},{"bid_px":"249.500000000","ask_px":"253.650000000","bid_sz":1000,"ask_sz":400,"bid_ct":1,"ask_ct":1},{"bid_px":"249.010000000","ask_px":"253.880000000","bid_sz":3,"ask_sz":8,"bid_ct":1,"ask_ct":1}],"symbol":"TSLA"}
{"ts_recv":"2024-11-01T08:00:14.845743247Z","hd":{"ts_event":"2024-11-01T08:00:14.845576901Z","rtype":10,"publisher_id":2,"instrument_id":16244},"action":"A","side":"A","depth":2,"price":"250.940000000","size":100,"flags":130,"ts_in_delta":166346,"sequence":322336,"levels":[{"bid_px":"250.590000000","ask_px":"250.790000000","bid_sz":7,"ask_sz":200,"bid_ct":3,"ask_ct":1},{"bid_px":"250.150000000","ask_px":"250.880000000","bid_sz":100,"ask_sz":14,"bid_ct":2,"ask_ct":1},{"bid_px":"250.000000000","ask_px":"250.940000000","bid_sz":2,"ask_sz":100,"bid_ct":2,"ask_ct":1},{"bid_px":"249.930000000","ask_px":"251.130000000","bid_sz":10,"ask_sz":50,"bid_ct":1,"ask_ct":1},{"bid_px":"249.880000000","ask_px":"251.450000000","bid_sz":4,"ask_sz":374,"bid_ct":1,"ask_ct":2},{"bid_px":"249.850000000","ask_px":"251.500000000","bid_sz":4,"ask_sz":10,"bid_ct":1,"ask_ct":1},{"bid_px":"249.800000000","ask_px":"252.300000000","bid_sz":199,"ask_sz":1000,"bid_ct":1,"ask_ct":1},{"bid_px":"249.770000000","ask_px":"253.350000000","bid_sz":50,"ask_sz":23,"bid_ct":1,"ask_ct":1},{"bid_px":"249.500000000","ask_px":"253.650000000","bid_sz":1000,"ask_sz":400,"bid_ct":1,"ask_ct":1},{"bid_px":"249.010000000","ask_px":"253.880000000","bid_sz":3,"ask_sz":8,"bid_ct":1,"ask_ct":1}],"symbol":"TSLA"}
{"ts_recv":"2024-11-01T08:00:14.982454469Z","hd":{"ts_event":"2024-11-01T08:00:14.982288003Z","rtype":10,"publisher_id":2,"instrument_id":16244},"action":"A","side":"A","depth":3,"price":"251.130000000","size":50,"flags":130,"ts_in_delta":166466,"sequence":322620,"levels":[{"bid_px":"250.590000000","ask_px":"250.790000000","bid_sz":7,"ask_sz":200,"bid_ct":3,"ask_ct":1},{"bid_px":"250.150000000","ask_px":"250.880000000","bid_sz":100,"ask_sz":14,"bid_ct":2,"ask_ct":1},{"bid_px":"250.000000000","ask_px":"250.940000000","bid_sz":2,"ask_sz":100,"bid_ct":2,"ask_ct":1},{"bid_px":"249.930000000","ask_px":"251.130000000","bid_sz":10,"ask_sz":100,"bid_ct":1,"ask_ct":2},{"bid_px":"249.880000000","ask_px":"251.450000000","bid_sz":4,"ask_sz":374,"bid_ct":1,"ask_ct":2},{"bid_px":"249.850000000","ask_px":"251.500000000","bid_sz":4,"ask_sz":10,"bid_ct":1,"ask_ct":1},{"bid_px":"249.800000000","ask_px":"252.300000000","bid_sz":199,"ask_sz":1000,"bid_ct":1,"ask_ct":1},{"bid_px":"249.770000000","ask_px":"253.350000000","bid_sz":50,"ask_sz":23,"bid_ct":1,"ask_ct":1},{"bid_px":"249.500000000","ask_px":"253.650000000","bid_sz":1000,"ask_sz":400,"bid_ct":1,"ask_ct":1},{"bid_px":"249.010000000","ask_px":"253.880000000","bid_sz":3,"ask_sz":8,"bid_ct":1,"ask_ct":1}],"symbol":"TSLA"}
{"ts_recv":"2024-11-01T08:00:14.982571709Z","hd":{"ts_event":"2024-11-01T08:00:14.982405684Z","rtype":10,"publisher_id":2,"instrument_id":16244},"action":"C","side":"B","depth":1,"price":"250.150000000","size":50,"flags":130,"ts_in_delta":166025,"sequence":322621,"levels":[{"bid_px":"250.590000000","ask_px":"250.790000000","bid_sz":7,"ask_sz":200,"bid_ct":3,"ask_ct":1},{"bid_px":"250.150000000","ask_px":"250.880000000","bid_sz":50,"ask_sz":14,"bid_ct":1,"ask_ct":1},{"bid_px":"250.000000000","ask_px":"250.940000000","bid_sz":2,"ask_sz":100,"bid_ct":2,"ask_ct":1},{"bid_px":"249.930000000","ask_px":"251.130000000","bid_sz":10,"ask_sz":100,"bid_ct":1,"ask_ct":2},{"bid_px":"249.880000000","ask_px":"251.450000000","bid_sz":4,"ask_sz":374,"bid_ct":1,"ask_ct":2},{"bid_px":"249.850000000","ask_px":"251.500000000","bid_sz":4,"ask_sz":10,"bid_ct":1,"ask_ct":1},{"bid_px":"249.800000000","ask_px":"252.300000000","bid_sz":199,"ask_sz":1000,"bid_ct":1,"ask_ct":1},{"bid_px":"249.770000000","ask_px":"253.350000000","bid_sz":50,"ask_sz":23,"bid_ct":1,"ask_ct":1},{"bid_px":"249.500000000","ask_px":"253.650000000","bid_sz":1000,"ask_sz":400,"bid_ct":1,"ask_ct":1},{"bid_px":"249.010000000","ask_px":"253.880000000","bid_sz":3,"ask_sz":8,"bid_ct":1,"ask_ct":1}],"symbol":"TSLA"}
{"ts_recv":"2024-11-01T08:00:15.037297016Z","hd":{"ts_event":"2024-11-01T08:00:15.037131293Z","rtype":10,"publisher_id":2,"instrument_id":16244},"action":"C","side":"A","depth":3,"price":"251.130000000","size":50,"flags":130,"ts_in_delta":165723,"sequence":322673,"levels":[{"bid_px":"250.590000000","ask_px":"250.790000000","bid_sz":7,"ask_sz":200,"bid_ct":3,"ask_ct":1},{"bid_px":"250.150000000","ask_px":"250.880000000","bid_sz":50,"ask_sz":14,"bid_ct":1,"ask_ct":1},{"bid_px":"250.000000000","ask_px":"250.940000000","bid_sz":2,"ask_sz":100,"bid_ct":2,"ask_ct":1},{"bid_px":"249.930000000","ask_px":"251.130000000","bid_sz":10,"ask_sz":50,"bid_ct":1,"ask_ct":1},{"bid_px":"249.880000000","ask_px":"251.450000000","bid_sz":4,"ask_sz":374,"bid_ct":1,"ask_ct":2},{"bid_px":"249.850000000","ask_px":"251.500000000","bid_sz":4,"ask_sz":10,"bid_ct":1,"ask_ct":1},{"bid_px":"249.800000000","ask_px":"252.300000000","bid_sz":199,"ask_sz":1000,"bid_ct":1,"ask_ct":1},{"bid_px":"249.770000000","ask_px":"253.350000000","bid_sz":50,"ask_sz":23,"bid_ct":1,"ask_ct":1},{"bid_px":"249.500000000","ask_px":"253.650000000","bid_sz":1000,"ask_sz":400,"bid_ct":1,"ask_ct":1},{"bid_px":"249.010000000","ask_px":"253.880000000","bid_sz":3,"ask_sz":8,"bid_ct":1,"ask_ct":1}],"symbol":"TSLA"}
{"ts_recv":"2024-11-01T08:00:15.037311818Z","hd":{"ts_event":"2024-11-01T08:00:15.037145518Z","rtype":10,"publisher_id":2,"instrument_id":16244},"action":"A","side":"A","depth":3,"price":"251.080000000","size":100,"flags":130,"ts_in_delta":166300,"sequence":322674,"levels":[{"bid_px":"250.590000000","ask_px":"250.790000000","bid_sz":7,"ask_sz":200,"bid_ct":3,"ask_ct":1},{"bid_px":"250.150000000","ask_px":"250.880000000","bid_sz":50,"ask_sz":14,"bid_ct":1,"ask_ct":1},{"bid_px":"250.000000000","ask_px":"250.940000000","bid_sz":2,"ask_sz":100,"bid_ct":2,"ask_ct":1},{"bid_px":"249.930000000","ask_px":"251.080000000","bid_sz":10,"ask_sz":100,"bid_ct":1,"ask_ct":1},{"bid_px":"249.880000000","ask_px":"251.450000000","bid_sz":4,"ask_sz":374,"bid_ct":1,"ask_ct":2},{"bid_px":"249.850000000","ask_px":"251.500000000","bid_sz":4,"ask_sz":10,"bid_ct":1,"ask_ct":1},{"bid_px":"249.800000000","ask_px":"252.300000000","bid_sz":199,"ask_sz":1000,"bid_ct":1,"ask_ct":1},{"bid_px":"249.770000000","ask_px":"253.350000000","bid_sz":50,"ask_sz":23,"bid_ct":1,"ask_ct":1},{"bid_px":"249.500000000","ask_px":"253.650000000","bid_sz":1000,"ask_sz":400,"bid_ct":1,"ask_ct":1},{"bid_px":"249.010000000","ask_px":"253.880000000","bid_sz":3,"ask_sz":8,"bid_ct":1,"ask_ct":1}],"symbol":"TSLA"}
{"ts_recv":"2024-11-01T08:00:15.050462920Z","hd":{"ts_event":"2024-11-01T08:00:15.050297076Z","rtype":10,"publisher_id":2,"instrument_id":16244},"action":"C","side":"A","depth":3,"price":"251.080000000","size":100,"flags":130,"ts_in_delta":165844,"sequence":322689,"levels":[{"bid_px":"250.590000000","ask_px":"250.790000000","bid_sz":7,"ask_sz":200,"bid_ct":3,"ask_ct":1},{"bid_px":"250.150000000","ask_px":"250.880000000","bid_sz":50,"ask_sz":14,"bid_ct":1,"ask_ct":1},{"bid_px":"250.000000000","ask_px":"250.940000000","bid_sz":2,"ask_sz":100,"bid_ct":2,"ask_ct":1},{"bid_px":"249.930000000","ask_px":"251.450000000","bid_sz":10,"ask_sz":374,"bid_ct":1,"ask_ct":2},{"bid_px":"249.880000000","ask_px":"251.500000000","bid_sz":4,"ask_sz":10,"bid_ct":1,"ask_ct":1},{"bid_px":"249.850000000","ask_px":"252.300000000","bid_sz":4,"ask_sz":1000,"bid_ct":1,"ask_ct":1},{"bid_px":"249.800000000","ask_px":"253.350000000","bid_sz":199,"ask_sz":23,"bid_ct":1,"ask_ct":1},{"bid_px":"249.770000000","ask_px":"253.650000000","bid_sz":50,"ask_sz":400,"bid_ct":1,"ask_ct":1},{"bid_px":"249.500000000","ask_px":"253.880000000","bid_sz":1000,"ask_sz":8,"bid_ct":1,"ask_ct":1},{"bid_px":"249.010000000","ask_px":"254.990000000","bid_sz":3,"ask_sz":5,"bid_ct":1,"ask_ct":1}],"symbol":"TSLA"}
{"ts_recv":"2024-11-01T08:00:15.050476834Z","hd":{"ts_event":"2024-11-01T08:00:15.050310498Z","rtype":10,"publisher_id":2,"instrument_id":16244},"action":"A","side":"A","depth":3,"price":"251.100000000","size":100,"flags":130,"ts_in_delta":166336,"sequence":322690,"levels":[{"bid_px":"250.590000000","ask_px":"250.790000000","bid_sz":7,"ask_sz":200,"bid_ct":3,"ask_ct":1},{"bid_px":"250.150000000","ask_px":"250.880000000","bid_sz":50,"ask_sz":14,"bid_ct":1,"ask_ct":1},{"bid_px":"250.000000000","ask_px":"250.940000000","bid_sz":2,"ask_sz":100,"bid_ct":2,"ask_ct":1},{"bid_px":"249.930000000","ask_px":"251.100000000","bid_sz":10,"ask_sz":100,"bid_ct":1,"ask_ct":1},{"bid_px":"249.880000000","ask_px":"251.450000000","bid_sz":4,"ask_sz":374,"bid_ct":1,"ask_ct":2},{"bid_px":"249.850000000","ask_px":"251.500000000","bid_sz":4,"ask_sz":10,"bid_ct":1,"ask_ct":1},{"bid_px":"249.800000000","ask_px":"252.300000000","bid_sz":199,"ask_sz":1000,"bid_ct":1,"ask_ct":1},{"bid_px":"249.770000000","ask_px":"253.350000000","bid_sz":50,"ask_sz":23,"bid_ct":1,"ask_ct":1},{"bid_px":"249.500000000","ask_px":"253.650000000","bid_sz":1000,"ask_sz":400,"bid_ct":1,"ask_ct":1},{"bid_px":"249.010000000","ask_px":"253.880000000","bid_sz":3,"ask_sz":8,"bid_ct":1,"ask_ct":1}],"symbol":"TSLA"}
{"ts_recv":"2024-11-01T08:00:15.103636017Z","hd":{"ts_event":"2024-11-01T08:00:15.103468390Z","rtype":10,"publisher_id":2,"instrument_id":16244},"action":"A","side":"A","depth":3,"price":"251.090000000","size":100,"flags":130,"ts_in_delta":167627,"sequence":322741,"levels":[{"bid_px":"250.590000000","ask_px":"250.790000000","bid_sz":7,"ask_sz":200,"bid_ct":3,"ask_ct":1},{"bid_px":"250.150000000","ask_px":"250.880000000","bid_sz":50,"ask_sz":14,"bid_ct":1,"ask_ct":1},{"bid_px":"250.000000000","ask_px":"250.940000000","bid_sz":2,"ask_sz":100,"bid_ct":2,"ask_ct":1},{"bid_px":"249.930000000","ask_px":"251.090000000","bid_sz":10,"ask_sz":100,"bid_ct":1,"ask_ct":1},{"bid_px":"249.880000000","ask_px":"251.450000000","bid_sz":4,"ask_sz":374,"bid_ct":1,"ask_ct":2},{"bid_px":"249.850000000","ask_px":"251.500000000","bid_sz":4,"ask_sz":10,"bid_ct":1,"ask_ct":1},{"bid_px":"249.800000000","ask_px":"252.300000000","bid_sz":199,"ask_sz":1000,"bid_ct":1,"ask_ct":1},{"bid_px":"249.770000000","ask_px":"253.350000000","bid_sz":50,"ask_sz":23,"bid_ct":1,"ask_ct":1},{"bid_px":"249.500000000","ask_px":"253.650000000","bid_sz":1000,"ask_sz":400,"bid_ct":1,"ask_ct":1},{"bid_px":"249.010000000","ask_px":"253.880000000","bid_sz":3,"ask_sz":8,"bid_ct":1,"ask_ct":1}],"symbol":"TSLA"}
