{"ts_recv":"2024-11-01T08:00:00.013053287Z","hd":{"ts_event":"2024-11-01T08:00:00.012886460Z","rtype":10,"publisher_id":2,"instrument_id":16244},"action":"A","side":"N","depth":0,"price":"235.000000000","size":20000,"flags":130,"ts_in_delta":166827,"sequence":284484,"levels":[{"bid_px":"235.000000000","ask_px":null,"bid_sz":20000,"ask_sz":0,"bid_ct":1,"ask_ct":0},{"bid_px":null,"ask_px":null,"bid_sz":0,"ask_sz":0,"bid_ct":0,"ask_ct":0},{"bid_px":null,"ask_px":null,"bid_sz":0,"ask_sz":0,"bid_ct":0,"ask_ct":0},{"bid_px":null,"ask_px":null,"bid_sz":0,"ask_sz":0,"bid_ct":0,"ask_ct":0},{"bid_px":null,"ask_px":null,"bid_sz":0,"ask_sz":0,"bid_ct":0,"ask_ct":0},{"bid_px":null,"ask_px":null,"bid_sz":0,"ask_sz":0,"bid_ct":0,"ask_ct":0},{"bid_px":null,"ask_px":null,"bid_sz":0,"ask_sz":0,"bid_ct":0,"ask_ct":0},{"bid_px":null,"ask_px":null,"bid_sz":0,"ask_sz":0,"bid_ct":0,"ask_ct":0},{"bid_px":null,"ask_px":null,"bid_sz":0,"ask_sz":0,"bid_ct":0,"ask_ct":0},{"bid_px":null,"ask_px":null,"bid_sz":0,"ask_sz":0,"bid_ct":0,"ask_ct":0}],"symbol":"TSLA"}
{"ts_recv":"2024-11-01T08:00:00.031886181Z","hd":{"ts_event":"2024-11-01T08:00:00.031701605Z","rtype":10,"publisher_id":2,"instrument_id":16244},"action":"A","side":"A","depth":0,"price":"960.000000000","size":25,"flags":130,"ts_in_delta":184576,"sequence":284655,"levels":[{"bid_px":"235.000000000","ask_px":"960.000000000","bid_sz":20000,"ask_sz":25,"bid_ct":1,"ask_ct":1},{"bid_px":null,"ask_px":null,"bid_sz":0,"ask_sz":0,"bid_ct":0,"ask_ct":0},{"bid_px":null,"ask_px":null,"bid_sz":0,"ask_sz":0,"bid_ct":0,"ask_ct":0},{"bid_px":null,"ask_px":null,"bid_sz":0,"ask_sz":0,"bid_ct":0,"ask_ct":0},{"bid_px":null,"ask_px":null,"bid_sz":0,"ask_sz":0,"bid_ct":0,"ask_ct":0},{"bid_px":null,"ask_px":null,"bid_sz":0,"ask_sz":0,"bid_ct":0,"ask_ct":0},{"bid_px":null,"ask_px":null,"bid_sz":0,"ask_sz":0,"bid_ct":0,"ask_ct":0},{"bid_px":null,"ask_px":null,"bid_sz":0,"ask_sz":0,"bid_ct":0,"ask_ct":0},{"bid_px":null,"ask_px":null,"bid_sz":0,"ask_sz":0,"bid_ct":0,"ask_ct":0},{"bid_px":null,"ask_px":null,"bid_sz":0,"ask_sz":0,"bid_ct":0,"ask_ct":0}],"symbol":"TSLA"}
{"ts_recv":"2024-11-01T08:00:00.136377397Z","hd":{"ts_event":"2024-11-01T08:00:00.136210914Z","rtype":10,"publisher_id":2,"instrument_id":16244},"action":"A","side":"A","depth":0,"price":"251.050000000","size":100,"flags":130,"ts_in_delta":166483,"sequence":286141,"levels":[{"bid_px":"235.000000000","ask_px":"251.050000000","bid_sz":20000,"ask_sz":100,"bid_ct":1,"ask_ct":1},{"bid_px":null,"ask_px":"960.000000000","bid_sz":0,"ask_sz":25,"bid_ct":0,"ask_ct":1},{"bid_px":null,"ask_px":null,"bid_sz":0,"ask_sz":0,"bid_ct":0,"ask_ct":0},{"bid_px":null,"ask_px":null,"bid_sz":0,"ask_sz":0,"bid_ct":0,"ask_ct":0},{"bid_px":null,"ask_px":null,"bid_sz":0,"ask_sz":0,"bid_ct":0,"ask_ct":0},{"bid_px":null,"ask_px":null,"bid_sz":0,"ask_sz":0,"bid_ct":0,"ask_ct":0},{"bid_px":null,"ask_px":null,"bid_sz":0,"ask_sz":0,"bid_ct":0,"ask_ct":0},{"bid_px":null,"ask_px":null,"bid_sz":0,"ask_sz":0,"bid_ct":0,"ask_ct":0},{"bid_px":null,"ask_px":null,"bid_sz":0,"ask_sz":0,"bid_ct":0,"ask_ct":0},{"bid_px":null,"ask_px":null,"bid_sz":0,"ask_sz":0,"bid_ct":0,"ask_ct":0}],"symbol":"TSLA"}
{"ts_recv":"2024-11-01T08:00:00.176651949Z","hd":{"ts_event":"2024-11-01T08:00:00.176486081Z","rtype":10,"publisher_id":2,"instrument_id":16244},"action":"C","side":"B","depth":0,"price":"235.000000000","size":20000,"flags":130,"ts_in_delta":165868,"sequence":286384,"levels":[{"bid_px":null,"ask_px":"251.050000000","bid_sz":0,"ask_sz":100,"bid_ct":0,"ask_ct":1},{"bid_px":null,"ask_px":"960.000000000","bid_sz":0,"ask_sz":25,"bid_ct":0,"ask_ct":1},{"bid_px":null,"ask_px":null,"bid_sz":0,"ask_sz":0,"bid_ct":0,"ask_ct":0},{"bid_px":null,"ask_px":null,"bid_sz":0,"ask_sz":0,"bid_ct":0,"ask_ct":0},{"bid_px":null,"ask_px":null,"bid_sz":0,"ask_sz":0,"bid_ct":0,"ask_ct":0},{"bid_px":null,"ask_px":null,"bid_sz":0,"ask_sz":0,"bid_ct":0,"ask_ct":0},{"bid_px":null,"ask_px":null,"bid_sz":0,"ask_sz":0,"bid_ct":0,"ask_ct":0},{"bid_px":null,"ask_px":null,"bid_sz":0,"ask_sz":0,"bid_ct":0,"ask_ct":0},{"bid_px":null,"ask_px":null,"bid_sz":0,"ask_sz":0,"bid_ct":0,"ask_ct":0},{"bid_px":null,"ask_px":null,"bid_sz":0,"ask_sz":0,"bid_ct":0,"ask_ct":0}],"symbol":"TSLA"}
{"ts_recv":"2024-11-01T08:00:00.176756781Z","hd":{"ts_event":"2024-11-01T08:00:00.176590432Z","rtype":10,"publisher_id":2,"instrument_id":16244},"action":"A","side":"B","depth":0,"price":"235.000000000","size":100,"flags":130,"ts_in_delta":166349,"sequence":286385,"levels":[{"bid_px":"235.000000000","ask_px":"251.050000000","bid_sz":100,"ask_sz":100,"bid_ct":1,"ask_ct":1},{"bid_px":null,"ask_px":"960.000000000","bid_sz":0,"ask_sz":25,"bid_ct":0,"ask_ct":1},{"bid_px":null,"ask_px":null,"bid_sz":0,"ask_sz":0,"bid_ct":0,"ask_ct":0},{"bid_px":null,"ask_px":null,"bid_sz":0,"ask_sz":0,"bid_ct":0,"ask_ct":0},{"bid_px":null,"ask_px":null,"bid_sz":0,"ask_sz":0,"bid_ct":0,"ask_ct":0},{"bid_px":null,"ask_px":null,"bid_sz":0,"ask_sz":0,"bid_ct":0,"ask_ct":0},{"bid_px":null,"ask_px":null,"bid_sz":0,"ask_sz":0,"bid_ct":0,"ask_ct":0},{"bid_px":null,"ask_px":null,"bid_sz":0,"ask_sz":0,"bid_ct":0,"ask_ct":0},{"bid_px":null,"ask_px":null,"bid_sz":0,"ask_sz":0,"bid_ct":0,"ask_ct":0},{"bid_px":null,"ask_px":null,"bid_sz":0,"ask_sz":0,"bid_ct":0,"ask_ct":0}],"symbol":"TSLA"}
{"ts_recv":"2024-11-01T08:00:00.189970576Z","hd":{"ts_event":"2024-11-01T08:00:00.189802730Z","rtype":10,"publisher_id":2,"instrument_id":16244},"action":"A","side":"A","depth":0,"price":"249.520000000","size":27,"flags":130,"ts_in_delta":167846,"sequence":286452,"levels":[{"bid_px":"235.000000000","ask_px":"249.520000000","bid_sz":100,"ask_sz":27,"bid_ct":1,"ask_ct":1},{"bid_px":null,"ask_px":"251.050000000","bid_sz":0,"ask_sz":100,"bid_ct":0,"ask_ct":1},{"bid_px":null,"ask_px":"960.000000000","bid_sz":0,"ask_sz":25,"bid_ct":0,"ask_ct":1},{"bid_px":null,"ask_px":null,"bid_sz":0,"ask_sz":0,"bid_ct":0,"ask_ct":0},{"bid_px":null,"ask_px":null,"bid_sz":0,"ask_sz":0,"bid_ct":0,"ask_ct":0},{"bid_px":null,"ask_px":null,"bid_sz":0,"ask_sz":0,"bid_ct":0,"ask_ct":0},{"bid_px":null,"ask_px":null,"bid_sz":0,"ask_sz":0,"bid_ct":0,"ask_ct":0},{"bid_px":null,"ask_px":null,"bid_sz":0,"ask_sz":0,"bid_ct":0,"ask_ct":0},{"bid_px":null,"ask_px":null,"bid_sz":0,"ask_sz":0,"bid_ct":0,"ask_ct":0},{"bid_px":null,"ask_px":null,"bid_sz":0,"ask_sz":0,"bid_ct":0,"ask_ct":0}],"symbol":"TSLA"}
{"ts_recv":"2024-11-01T08:00:00.191482094Z","hd":{"ts_event":"2024-11-01T08:00:00.191316476Z","rtype":10,"publisher_id":2,"instrument_id":16244},"action":"C","side":"A","depth":0,"price":"249.520000000","size":27,"flags":130,"ts_in_delta":165618,"sequence":286454,"levels":[{"bid_px":"235.000000000","ask_px":"251.050000000","bid_sz":100,"ask_sz":100,"bid_ct":1,"ask_ct":1},{"bid_px":null,"ask_px":"960.000000000","bid_sz":0,"ask_sz":25,"bid_ct":0,"ask_ct":1},{"bid_px":null,"ask_px":null,"bid_sz":0,"ask_sz":0,"bid_ct":0,"ask_ct":0},{"bid_px":null,"ask_px":null,"bid_sz":0,"ask_sz":0,"bid_ct":0,"ask_ct":0},{"bid_px":null,"ask_px":null,"bid_sz":0,"ask_sz":0,"bid_ct":0,"ask_ct":0},{"bid_px":null,"ask_px":null,"bid_sz":0,"ask_sz":0,"bid_ct":0,"ask_ct":0},{"bid_px":null,"ask_px":null,"bid_sz":0,"ask_sz":0,"bid_ct":0,"ask_ct":0},{"bid_px":null,"ask_px":null,"bid_sz":0,"ask_sz":0,"bid_ct":0,"ask_ct":0},{"bid_px":null,"ask_px":null,"bid_sz":0,"ask_sz":0,"bid_ct":0,"ask_ct":0},{"bid_px":null,"ask_px":null,"bid_sz":0,"ask_sz":0,"bid_ct":0,"ask_ct":0}],"symbol":"TSLA"}
{"ts_recv":"2024-11-01T08:00:00.191557126Z","hd":{"ts_event":"2024-11-01T08:00:00.191390836Z","rtype":10,"publisher_id":2,"instrument_id":16244},"action":"A","side":"B","depth":0,"price":"250.590000000","size":100,"flags":130,"ts_in_delta":166290,"sequence":286455,"levels":[{"bid_px":"250.590000000","ask_px":"251.050000000","bid_sz":100,"ask_sz":100,"bid_ct":1,"ask_ct":1},{"bid_px":"235.000000000","ask_px":"960.000000000","bid_sz":100,"ask_sz":25,"bid_ct":1,"ask_ct":1},{"bid_px":null,"ask_px":null,"bid_sz":0,"ask_sz":0,"bid_ct":0,"ask_ct":0},{"bid_px":null,"ask_px":null,"bid_sz":0,"ask_sz":0,"bid_ct":0,"ask_ct":0},{"bid_px":null,"ask_px":null,"bid_sz":0,"ask_sz":0,"bid_ct":0,"ask_ct":0},{"bid_px":null,"ask_px":null,"bid_sz":0,"ask_sz":0,"bid_ct":0,"ask_ct":0},{"bid_px":null,"ask_px":null,"bid_sz":0,"ask_sz":0,"bid_ct":0,"ask_ct":0},{"bid_px":null,"ask_px":null,"bid_sz":0,"ask_sz":0,"bid_ct":0,"ask_ct":0},{"bid_px":null,"ask_px":null,"bid_sz":0,"ask_sz":0,"bid_ct":0,"ask_ct":0},{"bid_px":null,"ask_px":null,"bid_sz":0,"ask_sz":0,"bid_ct":0,"ask_ct":0}],"symbol":"TSLA"}
{"ts_recv":"2024-11-01T08:00:00.191885779Z","hd":{"ts_event":"2024-11-01T08:00:00.191719300Z","rtype":10,"publisher_id":2,"instrument_id":16244},"action":"A","side":"B","depth":1,"price":"249.240000000","size":27,"flags":130,"ts_in_delta":166479,"sequence":286457,"levels":[{"bid_px":"250.590000000","ask_px":"251.050000000","bid_sz":100,"ask_sz":100,"bid_ct":1,"ask_ct":1},{"bid_px":"249.240000000","ask_px":"960.000000000","bid_sz":27,"ask_sz":25,"bid_ct":1,"ask_ct":1},{"bid_px":"235.000000000","ask_px":null,"bid_sz":100,"ask_sz":0,"bid_ct":1,"ask_ct":0},{"bid_px":null,"ask_px":null,"bid_sz":0,"ask_sz":0,"bid_ct":0,"ask_ct":0},{"bid_px":null,"ask_px":null,"bid_sz":0,"ask_sz":0,"bid_ct":0,"ask_ct":0},{"bid_px":null,"ask_px":null,"bid_sz":0,"ask_sz":0,"bid_ct":0,"ask_ct":0},{"bid_px":null,"ask_px":null,"bid_sz":0,"ask_sz":0,"bid_ct":0,"ask_ct":0},{"bid_px":null,"ask_px":null,"bid_sz":0,"ask_sz":0,"bid_ct":0,"ask_ct":0},{"bid_px":null,"ask_px":null,"bid_sz":0,"ask_sz":0,"bid_ct":0,"ask_ct":0},{"bid_px":null,"ask_px":null,"bid_sz":0,"ask_sz":0,"bid_ct":0,"ask_ct":0}],"symbol":"TSLA"}
{"ts_recv":"2024-11-01T08:00:00.191900223Z","hd":{"ts_event":"2024-11-01T08:00:00.191734501Z","rtype":10,"publisher_id":2,"instrument_id":16244},"action":"C","side":"B","depth":1,"price":"249.240000000","size":27,"flags":130,"ts_in_delta":165722,"sequence":286458,"levels":[{"bid_px":"250.590000000","ask_px":"251.050000000","bid_sz":100,"ask_sz":100,"bid_ct":1,"ask_ct":1},{"bid_px":"235.000000000","ask_px":"960.000000000","bid_sz":100,"ask_sz":25,"bid_ct":1,"ask_ct":1},{"bid_px":null,"ask_px":null,"bid_sz":0,"ask_sz":0,"bid_ct":0,"ask_ct":0},{"bid_px":null,"ask_px":null,"bid_sz":0,"ask_sz":0,"bid_ct":0,"ask_ct":0},{"bid_px":null,"ask_px":null,"bid_sz":0,"ask_sz":0,"bid_ct":0,"ask_ct":0},{"bid_px":null,"ask_px":null,"bid_sz":0,"ask_sz":0,"bid_ct":0,"ask_ct":0},{"bid_px":null,"ask_px":null,"bid_sz":0,"ask_sz":0,"bid_ct":0,"ask_ct":0},{"bid_px":null,"ask_px":null,"bid_sz":0,"ask_sz":0,"bid_ct":0,"ask_ct":0},{"bid_px":null,"ask_px":null,"bid_sz":0,"ask_sz":0,"bid_ct":0,"ask_ct":0},{"bid_px":null,"ask_px":null,"bid_sz":0,"ask_sz":0,"bid_ct":0,"ask_ct":0}],"symbol":"TSLA"}
{"ts_recv":"2024-11-01T08:00:00.191986130Z","hd":{"ts_event":"2024-11-01T08:00:00.191819920Z","rtype":10,"publisher_id":2,"instrument_id":16244},"action":"A","side":"B","depth":1,"price":"249.890000000","size":27,"flags":130,"ts_in_delta":166210,"sequence":286459,"levels":[{"bid_px":"250.590000000","ask_px":"251.050000000","bid_sz":100,"ask_sz":100,"bid_ct":1,"ask_ct":1},{"bid_px":"249.890000000","ask_px":"960.000000000","bid_sz":27,"ask_sz":25,"bid_ct":1,"ask_ct":1},{"bid_px":"235.000000000","ask_px":null,"bid_sz":100,"ask_sz":0,"bid_ct":1,"ask_ct":0},{"bid_px":null,"ask_px":null,"bid_sz":0,"ask_sz":0,"bid_ct":0,"ask_ct":0},{"bid_px":null,"ask_px":null,"bid_sz":0,"ask_sz":0,"bid_ct":0,"ask_ct":0},{"bid_px":null,"ask_px":null,"bid_sz":0,"ask_sz":0,"bid_ct":0,"ask_ct":0},{"bid_px":null,"ask_px":null,"bid_sz":0,"ask_sz":0,"bid_ct":0,"ask_ct":0},{"bid_px":null,"ask_px":null,"bid_sz":0,"ask_sz":0,"bid_ct":0,"ask_ct":0},{"bid_px":null,"ask_px":null,"bid_sz":0,"ask_sz":0,"bid_ct":0,"ask_ct":0},{"bid_px":null,"ask_px":null,"bid_sz":0,"ask_sz":0,"bid_ct":0,"ask_ct":0}],"symbol":"TSLA"}
{"ts_recv":"2024-11-01T08:00:00.196977431Z","hd":{"ts_event":"2024-11-01T08:00:00.196811568Z","rtype":10,"publisher_id":2,"instrument_id":16244},"action":"C","side":"A","depth":0,"price":"251.050000000","size":100,"flags":130,"ts_in_delta":165863,"sequence":286485,"levels":[{"bid_px":"250.590000000","ask_px":"960.000000000","bid_sz":100,"ask_sz":25,"bid_ct":1,"ask_ct":1},{"bid_px":"249.890000000","ask_px":null,"bid_sz":27,"ask_sz":0,"bid_ct":1,"ask_ct":0},{"bid_px":"235.000000000","ask_px":null,"bid_sz":100,"ask_sz":0,"bid_ct":1,"ask_ct":0},{"bid_px":null,"ask_px":null,"bid_sz":0,"ask_sz":0,"bid_ct":0,"ask_ct":0},{"bid_px":null,"ask_px":null,"bid_sz":0,"ask_sz":0,"bid_ct":0,"ask_ct":0},{"bid_px":null,"ask_px":null,"bid_sz":0,"ask_sz":0,"bid_ct":0,"ask_ct":0},{"bid_px":null,"ask_px":null,"bid_sz":0,"ask_sz":0,"bid_ct":0,"ask_ct":0},{"bid_px":null,"ask_px":null,"bid_sz":0,"ask_sz":0,"bid_ct":0,"ask_ct":0},{"bid_px":null,"ask_px":null,"bid_sz":0,"ask_sz":0,"bid_ct":0,"ask_ct":0},{"bid_px":null,"ask_px":null,"bid_sz":0,"ask_sz":0,"bid_ct":0,"ask_ct":0}],"symbol":"TSLA"}
{"ts_recv":"2024-11-01T08:00:00.196992070Z","hd":{"ts_event":"2024-11-01T08:00:00.196825881Z","rtype":10,"publisher_id":2,"instrument_id":16244},"action":"A","side":"A","depth":0,"price":"251.100000000","size":100,"flags":130,"ts_in_delta":166189,"sequence":286486,"levels":[{"bid_px":"250.590000000","ask_px":"251.100000000","bid_sz":100,"ask_sz":100,"bid_ct":1,"ask_ct":1},{"bid_px":"249.890000000","ask_px":"960.000000000","bid_sz":27,"ask_sz":25,"bid_ct":1,"ask_ct":1},{"bid_px":"235.000000000","ask_px":null,"bid_sz":100,"ask_sz":0,"bid_ct":1,"ask_ct":0},{"bid_px":null,"ask_px":null,"bid_sz":0,"ask_sz":0,"bid_ct":0,"ask_ct":0},{"bid_px":null,"ask_px":null,"bid_sz":0,"ask_sz":0,"bid_ct":0,"ask_ct":0},{"bid_px":null,"ask_px":null,"bid_sz":0,"ask_sz":0,"bid_ct":0,"ask_ct":0},{"bid_px":null,"ask_px":null,"bid_sz":0,"ask_sz":0,"bid_ct":0,"ask_ct":0},{"bid_px":null,"ask_px":null,"bid_sz":0,"ask_sz":0,"bid_ct":0,"ask_ct":0},{"bid_px":null,"ask_px":null,"bid_sz":0,"ask_sz":0,"bid_ct":0,"ask_ct":0},{"bid_px":null,"ask_px":null,"bid_sz":0,"ask_sz":0,"bid_ct":0,"ask_ct":0}],"symbol":"TSLA"}
{"ts_recv":"2024-11-01T08:00:00.197233272Z","hd":{"ts_event":"2024-11-01T08:00:00.197067720Z","rtype":10,"publisher_id":2,"instrument_id":16244},"action":"C","side":"A","depth":0,"price":"251.100000000","size":100,"flags":130,"ts_in_delta":165552,"sequence":286487,"levels":[{"bid_px":"250.590000000","ask_px":"960.000000000","bid_sz":100,"ask_sz":25,"bid_ct":1,"ask_ct":1},{"bid_px":"249.890000000","ask_px":null,"bid_sz":27,"ask_sz":0,"bid_ct":1,"ask_ct":0},{"bid_px":"235.000000000","ask_px":null,"bid_sz":100,"ask_sz":0,"bid_ct":1,"ask_ct":0},{"bid_px":null,"ask_px":null,"bid_sz":0,"ask_sz":0,"bid_ct":0,"ask_ct":0},{"bid_px":null,"ask_px":null,"bid_sz":0,"ask_sz":0,"bid_ct":0,"ask_ct":0},{"bid_px":null,"ask_px":null,"bid_sz":0,"ask_sz":0,"bid_ct":0,"ask_ct":0},{"bid_px":null,"ask_px":null,"bid_sz":0,"ask_sz":0,"bid_ct":0,"ask_ct":0},{"bid_px":null,"ask_px":null,"bid_sz":0,"ask_sz":0,"bid_ct":0,"ask_ct":0},{"bid_px":null,"ask_px":null,"bid_sz":0,"ask_sz":0,"bid_ct":0,"ask_ct":0},{"bid_px":null,"ask_px":null,"bid_sz":0,"ask_sz":0,"bid_ct":0,"ask_ct":0}],"symbol":"TSLA"}
{"ts_recv":"2024-11-01T08:00:00.197246429Z","hd":{"ts_event":"2024-11-01T08:00:00.197080392Z","rtype":10,"publisher_id":2,"instrument_id":16244},"action":"A","side":"A","depth":0,"price":"251.540000000","size":100,"flags":130,"ts_in_delta":166037,"sequence":286488,"levels":[{"bid_px":"250.590000000","ask_px":"251.540000000","bid_sz":100,"ask_sz":100,"bid_ct":1,"ask_ct":1},{"bid_px":"249.890000000","ask_px":"960.000000000","bid_sz":27,"ask_sz":25,"bid_ct":1,"ask_ct":1},{"bid_px":"235.000000000","ask_px":null,"bid_sz":100,"ask_sz":0,"bid_ct":1,"ask_ct":0},{"bid_px":null,"ask_px":null,"bid_sz":0,"ask_sz":0,"bid_ct":0,"ask_ct":0},{"bid_px":null,"ask_px":null,"bid_sz":0,"ask_sz":0,"bid_ct":0,"ask_ct":0},{"bid_px":null,"ask_px":null,"bid_sz":0,"ask_sz":0,"bid_ct":0,"ask_ct":0},{"bid_px":null,"ask_px":null,"bid_sz":0,"ask_sz":0,"bid_ct":0,"ask_ct":0},{"bid_px":null,"ask_px":null,"bid_sz":0,"ask_sz":0,"bid_ct":0,"ask_ct":0},{"bid_px":null,"ask_px":null,"bid_sz":0,"ask_sz":0,"bid_ct":0,"ask_ct":0},{"bid_px":null,"ask_px":null,"bid_sz":0,"ask_sz":0,"bid_ct":0,"ask_ct":0}],"symbol":"TSLA"}
{"ts_recv":"2024-11-01T08:00:00.241387465Z","hd":{"ts_event":"2024-11-01T08:00:00.241220838Z","rtype":10,"publisher_id":2,"instrument_id":16244},"action":"A","side":"A","depth":0,"price":"251.540000000","size":100,"flags":130,"ts_in_delta":166627,"sequence":286694,"levels":[{"bid_px":"250.590000000","ask_px":"251.540000000","bid_sz":100,"ask_sz":200,"bid_ct":1,"ask_ct":2},{"bid_px":"249.890000000","ask_px":"960.000000000","bid_sz":27,"ask_sz":25,"bid_ct":1,"ask_ct":1},{"bid_px":"235.000000000","ask_px":null,"bid_sz":100,"ask_sz":0,"bid_ct":1,"ask_ct":0},{"bid_px":null,"ask_px":null,"bid_sz":0,"ask_sz":0,"bid_ct":0,"ask_ct":0},{"bid_px":null,"ask_px":null,"bid_sz":0,"ask_sz":0,"bid_ct":0,"ask_ct":0},{"bid_px":null,"ask_px":null,"bid_sz":0,"ask_sz":0,"bid_ct":0,"ask_ct":0},{"bid_px":null,"ask_px":null,"bid_sz":0,"ask_sz":0,"bid_ct":0,"ask_ct":0},{"bid_px":null,"ask_px":null,"bid_sz":0,"ask_sz":0,"bid_ct":0,"ask_ct":0},{"bid_px":null,"ask_px":null,"bid_sz":0,"ask_sz":0,"bid_ct":0,"ask_ct":0},{"bid_px":null,"ask_px":null,"bid_sz":0,"ask_sz":0,"bid_ct":0,"ask_ct":0}],"symbol":"TSLA"}
{"ts_recv":"2024-11-01T08:00:00.301168858Z","hd":{"ts_event":"2024-11-01T08:00:00.301003128Z","rtype":10,"publisher_id":2,"instrument_id":16244},"action":"C","side":"A","depth":0,"price":"251.540000000","size":100,"flags":130,"ts_in_delta":165730,"sequence":287040,"levels":[{"bid_px":"250.590000000","ask_px":"251.540000000","bid_sz":100,"ask_sz":100,"bid_ct":1,"ask_ct":1},{"bid_px":"249.890000000","ask_px":"960.000000000","bid_sz":27,"ask_sz":25,"bid_ct":1,"ask_ct":1},{"bid_px":"235.000000000","ask_px":null,"bid_sz":100,"ask_sz":0,"bid_ct":1,"ask_ct":0},{"bid_px":null,"ask_px":null,"bid_sz":0,"ask_sz":0,"bid_ct":0,"ask_ct":0},{"bid_px":null,"ask_px":null,"bid_sz":0,"ask_sz":0,"bid_ct":0,"ask_ct":0},{"bid_px":null,"ask_px":null,"bid_sz":0,"ask_sz":0,"bid_ct":0,"ask_ct":0},{"bid_px":null,"ask_px":null,"bid_sz":0,"ask_sz":0,"bid_ct":0,"ask_ct":0},{"bid_px":null,"ask_px":null,"bid_sz":0,"ask_sz":0,"bid_ct":0,"ask_ct":0},{"bid_px":null,"ask_px":null,"bid_sz":0,"ask_sz":0,"bid_ct":0,"ask_ct":0},{"bid_px":null,"ask_px":null,"bid_sz":0,"ask_sz":0,"bid_ct":0,"ask_ct":0}],"symbol":"TSLA"}
{"ts_recv":"2024-11-01T08:00:00.301192443Z","hd":{"ts_event":"2024-11-01T08:00:00.301026245Z","rtype":10,"publisher_id":2,"instrument_id":16244},"action":"A","side":"A","depth":0,"price":"251.530000000","size":200,"flags":130,"ts_in_delta":166198,"sequence":287041,"levels":[{"bid_px":"250.590000000","ask_px":"251.530000000","bid_sz":100,"ask_sz":200,"bid_ct":1,"ask_ct":1},{"bid_px":"249.890000000","ask_px":"960.000000000","bid_sz":27,"ask_sz":25,"bid_ct":1,"ask_ct":1},{"bid_px":"235.000000000","ask_px":null,"bid_sz":100,"ask_sz":0,"bid_ct":1,"ask_ct":0},{"bid_px":null,"ask_px":null,"bid_sz":0,"ask_sz":0,"bid_ct":0,"ask_ct":0},{"bid_px":null,"ask_px":null,"bid_sz":0,"ask_sz":0,"bid_ct":0,"ask_ct":0},{"bid_px":null,"ask_px":null,"bid_sz":0,"ask_sz":0,"bid_ct":0,"ask_ct":0},{"bid_px":null,"ask_px":null,"bid_sz":0,"ask_sz":0,"bid_ct":0,"ask_ct":0},{"bid_px":null,"ask_px":null,"bid_sz":0,"ask_sz":0,"bid_ct":0,"ask_ct":0},{"bid_px":null,"ask_px":null,"bid_sz":0,"ask_sz":0,"bid_ct":0,"ask_ct":0},{"bid_px":null,"ask_px":null,"bid_sz":0,"ask_sz":0,"bid_ct":0,"ask_ct":0}],"symbol":"TSLA"}
{"ts_recv":"2024-11-01T08:00:00.316129151Z","hd":{"ts_event":"2024-11-01T08:00:00.315961115Z","rtype":10,"publisher_id":2,"instrument_id":16244},"action":"T","side":"N","depth":0,"price":"250.610000000","size":60,"flags":0,"ts_in_delta":168036,"sequence":287214,"levels":[{"bid_px":"250.590000000","ask_px":"251.530000000","bid_sz":100,"ask_sz":200,"bid_ct":1,"ask_ct":1},{"bid_px":"249.890000000","ask_px":"960.000000000","bid_sz":27,"ask_sz":25,"bid_ct":1,"ask_ct":1},{"bid_px":"235.000000000","ask_px":null,"bid_sz":100,"ask_sz":0,"bid_ct":1,"ask_ct":0},{"bid_px":null,"ask_px":null,"bid_sz":0,"ask_sz":0,"bid_ct":0,"ask_ct":0},{"bid_px":null,"ask_px":null,"bid_sz":0,"ask_sz":0,"bid_ct":0,"ask_ct":0},{"bid_px":null,"ask_px":null,"bid_sz":0,"ask_sz":0,"bid_ct":0,"ask_ct":0},{"bid_px":null,"ask_px":null,"bid_sz":0,"ask_sz":0,"bid_ct":0,"ask_ct":0},{"bid_px":null,"ask_px":null,"bid_sz":0,"ask_sz":0,"bid_ct":0,"ask_ct":0},{"bid_px":null,"ask_px":null,"bid_sz":0,"ask_sz":0,"bid_ct":0,"ask_ct":0},{"bid_px":null,"ask_px":null,"bid_sz":0,"ask_sz":0,"bid_ct":0,"ask_ct":0}],"symbol":"TSLA"}
{"ts_recv":"2024-11-01T08:00:00.316129151Z","hd":{"ts_event":"2024-11-01T08:00:00.315961115Z","rtype":10,"publisher_id":2,"instrument_id":16244},"action":"T","side":"A","depth":0,"price":"250.590000000","size":40,"flags":130,"ts_in_delta":168036,"sequence":287215,"levels":[{"bid_px":"250.590000000","ask_px":"251.530000000","bid_sz":100,"ask_sz":200,"bid_ct":1,"ask_ct":1},{"bid_px":"249.890000000","ask_px":"960.000000000","bid_sz":27,"ask_sz":25,"bid_ct":1,"ask_ct":1},{"bid_px":"235.000000000","ask_px":null,"bid_sz":100,"ask_sz":0,"bid_ct":1,"ask_ct":0},{"bid_px":null,"ask_px":null,"bid_sz":0,"ask_sz":0,"bid_ct":0,"ask_ct":0},{"bid_px":null,"ask_px":null,"bid_sz":0,"ask_sz":0,"bid_ct":0,"ask_ct":0},{"bid_px":null,"ask_px":null,"bid_sz":0,"ask_sz":0,"bid_ct":0,"ask_ct":0},{"bid_px":null,"ask_px":null,"bid_sz":0,"ask_sz":0,"bid_ct":0,"ask_ct":0},{"bid_px":null,"ask_px":null,"bid_sz":0,"ask_sz":0,"bid_ct":0,"ask_ct":0},{"bid_px":null,"ask_px":null,"bid_sz":0,"ask_sz":0,"bid_ct":0,"ask_ct":0},{"bid_px":null,"ask_px":null,"bid_sz":0,"ask_sz":0,"bid_ct":0,"ask_ct":0}],"symbol":"TSLA"}
{"ts_recv":"2024-11-01T08:00:00.316129151Z","hd":{"ts_event":"2024-11-01T08:00:00.315961115Z","rtype":10,"publisher_id":2,"instrument_id":16244},"action":"C","side":"B","depth":0,"price":"250.590000000","size":40,"flags":130,"ts_in_delta":168036,"sequence":287215,"levels":[{"bid_px":"250.590000000","ask_px":"251.530000000","bid_sz":60,"ask_sz":200,"bid_ct":1,"ask_ct":1},{"bid_px":"249.890000000","ask_px":"960.000000000","bid_sz":27,"ask_sz":25,"bid_ct":1,"ask_ct":1},{"bid_px":"235.000000000","ask_px":null,"bid_sz":100,"ask_sz":0,"bid_ct":1,"ask_ct":0},{"bid_px":null,"ask_px":null,"bid_sz":0,"ask_sz":0,"bid_ct":0,"ask_ct":0},{"bid_px":null,"ask_px":null,"bid_sz":0,"ask_sz":0,"bid_ct":0,"ask_ct":0},{"bid_px":null,"ask_px":null,"bid_sz":0,"ask_sz":0,"bid_ct":0,"ask_ct":0},{"bid_px":null,"ask_px":null,"bid_sz":0,"ask_sz":0,"bid_ct":0,"ask_ct":0},{"bid_px":null,"ask_px":null,"bid_sz":0,"ask_sz":0,"bid_ct":0,"ask_ct":0},{"bid_px":null,"ask_px":null,"bid_sz":0,"ask_sz":0,"bid_ct":0,"ask_ct":0},{"bid_px":null,"ask_px":null,"bid_sz":0,"ask_sz":0,"bid_ct":0,"ask_ct":0}],"symbol":"TSLA"}
{"ts_recv":"2024-11-01T08:00:00.316199950Z","hd":{"ts_event":"2024-11-01T08:00:00.316033983Z","rtype":10,"publisher_id":2,"instrument_id":16244},"action":"A","side":"A","depth":0,"price":"251.070000000","size":5,"flags":130,"ts_in_delta":165967,"sequence":287216,"levels":[{"bid_px":"250.590000000","ask_px":"251.070000000","bid_sz":60,"ask_sz":5,"bid_ct":1,"ask_ct":1},{"bid_px":"249.890000000","ask_px":"251.530000000","bid_sz":27,"ask_sz":200,"bid_ct":1,"ask_ct":1},{"bid_px":"235.000000000","ask_px":"960.000000000","bid_sz":100,"ask_sz":25,"bid_ct":1,"ask_ct":1},{"bid_px":null,"ask_px":null,"bid_sz":0,"ask_sz":0,"bid_ct":0,"ask_ct":0},{"bid_px":null,"ask_px":null,"bid_sz":0,"ask_sz":0,"bid_ct":0,"ask_ct":0},{"bid_px":null,"ask_px":null,"bid_sz":0,"ask_sz":0,"bid_ct":0,"ask_ct":0},{"bid_px":null,"ask_px":null,"bid_sz":0,"ask_sz":0,"bid_ct":0,"ask_ct":0},{"bid_px":null,"ask_px":null,"bid_sz":0,"ask_sz":0,"bid_ct":0,"ask_ct":0},{"bid_px":null,"ask_px":null,"bid_sz":0,"ask_sz":0,"bid_ct":0,"ask_ct":0},{"bid_px":null,"ask_px":null,"bid_sz":0,"ask_sz":0,"bid_ct":0,"ask_ct":0}],"symbol":"TSLA"}
{"ts_recv":"2024-11-01T08:00:00.316243164Z","hd":{"ts_event":"2024-11-01T08:00:00.316076612Z","rtype":10,"publisher_id":2,"instrument_id":16244},"action":"A","side":"A","depth":1,"price":"251.350000000","size":1,"flags":130,"ts_in_delta":166552,"sequence":287217,"levels":[{"bid_px":"250.590000000","ask_px":"251.070000000","bid_sz":60,"ask_sz":5,"bid_ct":1,"ask_ct":1},{"bid_px":"249.890000000","ask_px":"251.350000000","bid_sz":27,"ask_sz":1,"bid_ct":1,"ask_ct":1},{"bid_px":"235.000000000","ask_px":"251.530000000","bid_sz":100,"ask_sz":200,"bid_ct":1,"ask_ct":1},{"bid_px":null,"ask_px":"960.000000000","bid_sz":0,"ask_sz":25,"bid_ct":0,"ask_ct":1},{"bid_px":null,"ask_px":null,"bid_sz":0,"ask_sz":0,"bid_ct":0,"ask_ct":0},{"bid_px":null,"ask_px":null,"bid_sz":0,"ask_sz":0,"bid_ct":0,"ask_ct":0},{"bid_px":null,"ask_px":null,"bid_sz":0,"ask_sz":0,"bid_ct":0,"ask_ct":0},{"bid_px":null,"ask_px":null,"bid_sz":0,"ask_sz":0,"bid_ct":0,"ask_ct":0},{"bid_px":null,"ask_px":null,"bid_sz":0,"ask_sz":0,"bid_ct":0,"ask_ct":0},{"bid_px":null,"ask_px":null,"bid_sz":0,"ask_sz":0,"bid_ct":0,"ask_ct":0}],"symbol":"TSLA"}
{"ts_recv":"2024-11-01T08:00:00.318804188Z","hd":{"ts_event":"2024-11-01T08:00:00.318637776Z","rtype":10,"publisher_id":2,"instrument_id":16244},"action":"C","side":"A","depth":0,"price":"251.070000000","size":5,"flags":130,"ts_in_delta":166412,"sequence":287233,"levels":[{"bid_px":"250.590000000","ask_px":"251.350000000","bid_sz":60,"ask_sz":1,"bid_ct":1,"ask_ct":1},{"bid_px":"249.890000000","ask_px":"251.530000000","bid_sz":27,"ask_sz":200,"bid_ct":1,"ask_ct":1},{"bid_px":"235.000000000","ask_px":"960.000000000","bid_sz":100,"ask_sz":25,"bid_ct":1,"ask_ct":1},{"bid_px":null,"ask_px":null,"bid_sz":0,"ask_sz":0,"bid_ct":0,"ask_ct":0},{"bid_px":null,"ask_px":null,"bid_sz":0,"ask_sz":0,"bid_ct":0,"ask_ct":0},{"bid_px":null,"ask_px":null,"bid_sz":0,"ask_sz":0,"bid_ct":0,"ask_ct":0},{"bid_px":null,"ask_px":null,"bid_sz":0,"ask_sz":0,"bid_ct":0,"ask_ct":0},{"bid_px":null,"ask_px":null,"bid_sz":0,"ask_sz":0,"bid_ct":0,"ask_ct":0},{"bid_px":null,"ask_px":null,"bid_sz":0,"ask_sz":0,"bid_ct":0,"ask_ct":0},{"bid_px":null,"ask_px":null,"bid_sz":0,"ask_sz":0,"bid_ct":0,"ask_ct":0}],"symbol":"TSLA"}
{"ts_recv":"2024-11-01T08:00:00.369440196Z","hd":{"ts_event":"2024-11-01T08:00:00.369273960Z","rtype":10,"publisher_id":2,"instrument_id":16244},"action":"A","side":"A","depth":1,"price":"251.520000000","size":200,"flags":130,"ts_in_delta":166236,"sequence":287383,"levels":[{"bid_px":"250.590000000","ask_px":"251.350000000","bid_sz":60,"ask_sz":1,"bid_ct":1,"ask_ct":1},{"bid_px":"249.890000000","ask_px":"251.520000000","bid_sz":27,"ask_sz":200,"bid_ct":1,"ask_ct":1},{"bid_px":"235.000000000","ask_px":"960.000000000","bid_sz":100,"ask_sz":25,"bid_ct":1,"ask_ct":1},{"bid_px":null,"ask_px":null,"bid_sz":0,"ask_sz":0,"bid_ct":0,"ask_ct":0},{"bid_px":null,"ask_px":null,"bid_sz":0,"ask_sz":0,"bid_ct":0,"ask_ct":0},{"bid_px":null,"ask_px":null,"bid_sz":0,"ask_sz":0,"bid_ct":0,"ask_ct":0},{"bid_px":null,"ask_px":null,"bid_sz":0,"ask_sz":0,"bid_ct":0,"ask_ct":0},{"bid_px":null,"ask_px":null,"bid_sz":0,"ask_sz":0,"bid_ct":0,"ask_ct":0},{"bid_px":null,"ask_px":null,"bid_sz":0,"ask_sz":0,"bid_ct":0,"ask_ct":0},{"bid_px":null,"ask_px":null,"bid_sz":0,"ask_sz":0,"bid_ct":0,"ask_ct":0}],"symbol":"TSLA"}
{"ts_recv":"2024-11-01T08:00:00.387442715Z","hd":{"ts_event":"2024-11-01T08:00:00.387276086Z","rtype":10,"publisher_id":2,"instrument_id":16244},"action":"A","side":"A","depth":0,"price":"251.120000000","size":100,"flags":130,"ts_in_delta":166629,"sequence":287422,"levels":[{"bid_px":"250.590000000","ask_px":"251.120000000","bid_sz":60,"ask_sz":100,"bid_ct":1,"ask_ct":1},{"bid_px":"249.890000000","ask_px":"251.350000000","bid_sz":27,"ask_sz":1,"bid_ct":1,"ask_ct":1},{"bid_px":"235.000000000","ask_px":"960.000000000","bid_sz":100,"ask_sz":25,"bid_ct":1,"ask_ct":1},{"bid_px":null,"ask_px":null,"bid_sz":0,"ask_sz":0,"bid_ct":0,"ask_ct":0},{"bid_px":null,"ask_px":null,"bid_sz":0,"ask_sz":0,"bid_ct":0,"ask_ct":0},{"bid_px":null,"ask_px":null,"bid_sz":0,"ask_sz":0,"bid_ct":0,"ask_ct":0},{"bid_px":null,"ask_px":null,"bid_sz":0,"ask_sz":0,"bid_ct":0,"ask_ct":0},{"bid_px":null,"ask_px":null,"bid_sz":0,"ask_sz":0,"bid_ct":0,"ask_ct":0},{"bid_px":null,"ask_px":null,"bid_sz":0,"ask_sz":0,"bid_ct":0,"ask_ct":0},{"bid_px":null,"ask_px":null,"bid_sz":0,"ask_sz":0,"bid_ct":0,"ask_ct":0}],"symbol":"TSLA"}
{"ts_recv":"2024-11-01T08:00:00.432197000Z","hd":{"ts_event":"2024-11-01T08:00:00.432030721Z","rtype":10,"publisher_id":2,"instrument_id":16244},"action":"C","side":"A","depth":0,"price":"251.120000000","size":100,"flags":128,"ts_in_delta":166279,"sequence":287589,"levels":[{"bid_px":"250.590000000","ask_px":"251.350000000","bid_sz":60,"ask_sz":1,"bid_ct":1,"ask_ct":1},{"bid_px":"249.890000000","ask_px":"960.000000000","bid_sz":27,"ask_sz":25,"bid_ct":1,"ask_ct":1},{"bid_px":"235.000000000","ask_px":null,"bid_sz":100,"ask_sz":0,"bid_ct":1,"ask_ct":0},{"bid_px":null,"ask_px":null,"bid_sz":0,"ask_sz":0,"bid_ct":0,"ask_ct":0},{"bid_px":null,"ask_px":null,"bid_sz":0,"ask_sz":0,"bid_ct":0,"ask_ct":0},{"bid_px":null,"ask_px":null,"bid_sz":0,"ask_sz":0,"bid_ct":0,"ask_ct":0},{"bid_px":null,"ask_px":null,"bid_sz":0,"ask_sz":0,"bid_ct":0,"ask_ct":0},{"bid_px":null,"ask_px":null,"bid_sz":0,"ask_sz":0,"bid_ct":0,"ask_ct":0},{"bid_px":null,"ask_px":null,"bid_sz":0,"ask_sz":0,"bid_ct":0,"ask_ct":0},{"bid_px":null,"ask_px":null,"bid_sz":0,"ask_sz":0,"bid_ct":0,"ask_ct":0}],"symbol":"TSLA"}
{"ts_recv":"2024-11-01T08:00:00.432210472Z","hd":{"ts_event":"2024-11-01T08:00:00.432044433Z","rtype":10,"publisher_id":2,"instrument_id":16244},"action":"A","side":"A","depth":0,"price":"251.140000000","size":100,"flags":130,"ts_in_delta":166039,"sequence":287591,"levels":[{"bid_px":"250.590000000","ask_px":"251.140000000","bid_sz":60,"ask_sz":100,"bid_ct":1,"ask_ct":1},{"bid_px":"249.890000000","ask_px":"251.350000000","bid_sz":27,"ask_sz":1,"bid_ct":1,"ask_ct":1},{"bid_px":"235.000000000","ask_px":"960.000000000","bid_sz":100,"ask_sz":25,"bid_ct":1,"ask_ct":1},{"bid_px":null,"ask_px":null,"bid_sz":0,"ask_sz":0,"bid_ct":0,"ask_ct":0},{"bid_px":null,"ask_px":null,"bid_sz":0,"ask_sz":0,"bid_ct":0,"ask_ct":0},{"bid_px":null,"ask_px":null,"bid_sz":0,"ask_sz":0,"bid_ct":0,"ask_ct":0},{"bid_px":null,"ask_px":null,"bid_sz":0,"ask_sz":0,"bid_ct":0,"ask_ct":0},{"bid_px":null,"ask_px":null,"bid_sz":0,"ask_sz":0,"bid_ct":0,"ask_ct":0},{"bid_px":null,"ask_px":null,"bid_sz":0,"ask_sz":0,"bid_ct":0,"ask_ct":0},{"bid_px":null,"ask_px":null,"bid_sz":0,"ask_sz":0,"bid_ct":0,"ask_ct":0}],"symbol":"TSLA"}
{"ts_recv":"2024-11-01T08:00:00.442560532Z","hd":{"ts_event":"2024-11-01T08:00:00.442394402Z","rtype":10,"publisher_id":2,"instrument_id":16244},"action":"C","side":"B","depth":1,"price":"249.890000000","size":27,"flags":130,"ts_in_delta":166130,"sequence":287605,"levels":[{"bid_px":"250.590000000","ask_px":"251.140000000","bid_sz":60,"ask_sz":100,"bid_ct":1,"ask_ct":1},{"bid_px":"235.000000000","ask_px":"251.350000000","bid_sz":100,"ask_sz":1,"bid_ct":1,"ask_ct":1},{"bid_px":null,"ask_px":"960.000000000","bid_sz":0,"ask_sz":25,"bid_ct":0,"ask_ct":1},{"bid_px":null,"ask_px":null,"bid_sz":0,"ask_sz":0,"bid_ct":0,"ask_ct":0},{"bid_px":null,"ask_px":null,"bid_sz":0,"ask_sz":0,"bid_ct":0,"ask_ct":0},{"bid_px":null,"ask_px":null,"bid_sz":0,"ask_sz":0,"bid_ct":0,"ask_ct":0},{"bid_px":null,"ask_px":null,"bid_sz":0,"ask_sz":0,"bid_ct":0,"ask_ct":0},{"bid_px":null,"ask_px":null,"bid_sz":0,"ask_sz":0,"bid_ct":0,"ask_ct":0},{"bid_px":null,"ask_px":null,"bid_sz":0,"ask_sz":0,"bid_ct":0,"ask_ct":0},{"bid_px":null,"ask_px":null,"bid_sz":0,"ask_sz":0,"bid_ct":0,"ask_ct":0}],"symbol":"TSLA"}
{"ts_recv":"2024-11-01T08:00:00.445664686Z","hd":{"ts_event":"2024-11-01T08:00:00.445498437Z","rtype":10,"publisher_id":2,"instrument_id":16244},"action":"A","side":"B","depth":0,"price":"250.590000000","size":60,"flags":130,"ts_in_delta":166249,"sequence":287612,"levels":[{"bid_px":"250.590000000","ask_px":"251.140000000","bid_sz":120,"ask_sz":100,"bid_ct":2,"ask_ct":1},{"bid_px":"235.000000000","ask_px":"251.350000000","bid_sz":100,"ask_sz":1,"bid_ct":1,"ask_ct":1},{"bid_px":null,"ask_px":"960.000000000","bid_sz":0,"ask_sz":25,"bid_ct":0,"ask_ct":1},{"bid_px":null,"ask_px":null,"bid_sz":0,"ask_sz":0,"bid_ct":0,"ask_ct":0},{"bid_px":null,"ask_px":null,"bid_sz":0,"ask_sz":0,"bid_ct":0,"ask_ct":0},{"bid_px":null,"ask_px":null,"bid_sz":0,"ask_sz":0,"bid_ct":0,"ask_ct":0},{"bid_px":null,"ask_px":null,"bid_sz":0,"ask_sz":0,"bid_ct":0,"ask_ct":0},{"bid_px":null,"ask_px":null,"bid_sz":0,"ask_sz":0,"bid_ct":0,"ask_ct":0},{"bid_px":null,"ask_px":null,"bid_sz":0,"ask_sz":0,"bid_ct":0,"ask_ct":0},{"bid_px":null,"ask_px":null,"bid_sz":0,"ask_sz":0,"bid_ct":0,"ask_ct":0}],"symbol":"TSLA"}
{"ts_recv":"2024-11-01T08:00:00.445690307Z","hd":{"ts_event":"2024-11-01T08:00:00.445524743Z","rtype":10,"publisher_id":2,"instrument_id":16244},"action":"C","side":"B","depth":0,"price":"250.590000000","size":60,"flags":130,"ts_in_delta":165564,"sequence":287613,"levels":[{"bid_px":"250.590000000","ask_px":"251.140000000","bid_sz":60,"ask_sz":100,"bid_ct":1,"ask_ct":1},{"bid_px":"235.000000000","ask_px":"251.350000000","bid_sz":100,"ask_sz":1,"bid_ct":1,"ask_ct":1},{"bid_px":null,"ask_px":"960.000000000","bid_sz":0,"ask_sz":25,"bid_ct":0,"ask_ct":1},{"bid_px":null,"ask_px":null,"bid_sz":0,"ask_sz":0,"bid_ct":0,"ask_ct":0},{"bid_px":null,"ask_px":null,"bid_sz":0,"ask_sz":0,"bid_ct":0,"ask_ct":0},{"bid_px":null,"ask_px":null,"bid_sz":0,"ask_sz":0,"bid_ct":0,"ask_ct":0},{"bid_px":null,"ask_px":null,"bid_sz":0,"ask_sz":0,"bid_ct":0,"ask_ct":0},{"bid_px":null,"ask_px":null,"bid_sz":0,"ask_sz":0,"bid_ct":0,"ask_ct":0},{"bid_px":null,"ask_px":null,"bid_sz":0,"ask_sz":0,"bid_ct":0,"ask_ct":0},{"bid_px":null,"ask_px":null,"bid_sz":0,"ask_sz":0,"bid_ct":0,"ask_ct":0}],"symbol":"TSLA"}
{"ts_recv":"2024-11-01T08:00:00.474545078Z","hd":{"ts_event":"2024-11-01T08:00:00.474378454Z","rtype":10,"publisher_id":2,"instrument_id":16244},"action":"T","side":"A","depth":0,"price":"250.590000000","size":1,"flags":130,"ts_in_delta":166624,"sequence":287659,"levels":[{"bid_px":"250.590000000","ask_px":"251.140000000","bid_sz":60,"ask_sz":100,"bid_ct":1,"ask_ct":1},{"bid_px":"235.000000000","ask_px":"251.350000000","bid_sz":100,"ask_sz":1,"bid_ct":1,"ask_ct":1},{"bid_px":null,"ask_px":"960.000000000","bid_sz":0,"ask_sz":25,"bid_ct":0,"ask_ct":1},{"bid_px":null,"ask_px":null,"bid_sz":0,"ask_sz":0,"bid_ct":0,"ask_ct":0},{"bid_px":null,"ask_px":null,"bid_sz":0,"ask_sz":0,"bid_ct":0,"ask_ct":0},{"bid_px":null,"ask_px":null,"bid_sz":0,"ask_sz":0,"bid_ct":0,"ask_ct":0},{"bid_px":null,"ask_px":null,"bid_sz":0,"ask_sz":0,"bid_ct":0,"ask_ct":0},{"bid_px":null,"ask_px":null,"bid_sz":0,"ask_sz":0,"bid_ct":0,"ask_ct":0},{"bid_px":null,"ask_px":null,"bid_sz":0,"ask_sz":0,"bid_ct":0,"ask_ct":0},{"bid_px":null,"ask_px":null,"bid_sz":0,"ask_sz":0,"bid_ct":0,"ask_ct":0}],"symbol":"TSLA"}
{"ts_recv":"2024-11-01T08:00:00.474545078Z","hd":{"ts_event":"2024-11-01T08:00:00.474378454Z","rtype":10,"publisher_id":2,"instrument_id":16244},"action":"C","side":"B","depth":0,"price":"250.590000000","size":1,"flags":130,"ts_in_delta":166624,"sequence":287659,"levels":[{"bid_px":"250.590000000","ask_px":"251.140000000","bid_sz":59,"ask_sz":100,"bid_ct":1,"ask_ct":1},{"bid_px":"235.000000000","ask_px":"251.350000000","bid_sz":100,"ask_sz":1,"bid_ct":1,"ask_ct":1},{"bid_px":null,"ask_px":"960.000000000","bid_sz":0,"ask_sz":25,"bid_ct":0,"ask_ct":1},{"bid_px":null,"ask_px":null,"bid_sz":0,"ask_sz":0,"bid_ct":0,"ask_ct":0},{"bid_px":null,"ask_px":null,"bid_sz":0,"ask_sz":0,"bid_ct":0,"ask_ct":0},{"bid_px":null,"ask_px":null,"bid_sz":0,"ask_sz":0,"bid_ct":0,"ask_ct":0},{"bid_px":null,"ask_px":null,"bid_sz":0,"ask_sz":0,"bid_ct":0,"ask_ct":0},{"bid_px":null,"ask_px":null,"bid_sz":0,"ask_sz":0,"bid_ct":0,"ask_ct":0},{"bid_px":null,"ask_px":null,"bid_sz":0,"ask_sz":0,"bid_ct":0,"ask_ct":0},{"bid_px":null,"ask_px":null,"bid_sz":0,"ask_sz":0,"bid_ct":0,"ask_ct":0}],"symbol":"TSLA"}
{"ts_recv":"2024-11-01T08:00:00.482523142Z","hd":{"ts_event":"2024-11-01T08:00:00.482356557Z","rtype":10,"publisher_id":2,"instrument_id":16244},"action":"T","side":"A","depth":0,"price":"250.590000000","size":2,"flags":130,"ts_in_delta":166585,"sequence":287680,"levels":[{"bid_px":"250.590000000","ask_px":"251.140000000","bid_sz":59,"ask_sz":100,"bid_ct":1,"ask_ct":1},{"bid_px":"235.000000000","ask_px":"251.350000000","bid_sz":100,"ask_sz":1,"bid_ct":1,"ask_ct":1},{"bid_px":null,"ask_px":"960.000000000","bid_sz":0,"ask_sz":25,"bid_ct":0,"ask_ct":1},{"bid_px":null,"ask_px":null,"bid_sz":0,"ask_sz":0,"bid_ct":0,"ask_ct":0},{"bid_px":null,"ask_px":null,"bid_sz":0,"ask_sz":0,"bid_ct":0,"ask_ct":0},{"bid_px":null,"ask_px":null,"bid_sz":0,"ask_sz":0,"bid_ct":0,"ask_ct":0},{"bid_px":null,"ask_px":null,"bid_sz":0,"ask_sz":0,"bid_ct":0,"ask_ct":0},{"bid_px":null,"ask_px":null,"bid_sz":0,"ask_sz":0,"bid_ct":0,"ask_ct":0},{"bid_px":null,"ask_px":null,"bid_sz":0,"ask_sz":0,"bid_ct":0,"ask_ct":0},{"bid_px":null,"ask_px":null,"bid_sz":0,"ask_sz":0,"bid_ct":0,"ask_ct":0}],"symbol":"TSLA"}
{"ts_recv":"2024-11-01T08:00:00.482523142Z","hd":{"ts_event":"2024-11-01T08:00:00.482356557Z","rtype":10,"publisher_id":2,"instrument_id":16244},"action":"C","side":"B","depth":0,"price":"250.590000000","size":2,"flags":130,"ts_in_delta":166585,"sequence":287680,"levels":[{"bid_px":"250.590000000","ask_px":"251.140000000","bid_sz":57,"ask_sz":100,"bid_ct":1,"ask_ct":1},{"bid_px":"235.000000000","ask_px":"251.350000000","bid_sz":100,"ask_sz":1,"bid_ct":1,"ask_ct":1},{"bid_px":null,"ask_px":"960.000000000","bid_sz":0,"ask_sz":25,"bid_ct":0,"ask_ct":1},{"bid_px":null,"ask_px":null,"bid_sz":0,"ask_sz":0,"bid_ct":0,"ask_ct":0},{"bid_px":null,"ask_px":null,"bid_sz":0,"ask_sz":0,"bid_ct":0,"ask_ct":0},{"bid_px":null,"ask_px":null,"bid_sz":0,"ask_sz":0,"bid_ct":0,"ask_ct":0},{"bid_px":null,"ask_px":null,"bid_sz":0,"ask_sz":0,"bid_ct":0,"ask_ct":0},{"bid_px":null,"ask_px":null,"bid_sz":0,"ask_sz":0,"bid_ct":0,"ask_ct":0},{"bid_px":null,"ask_px":null,"bid_sz":0,"ask_sz":0,"bid_ct":0,"ask_ct":0},{"bid_px":null,"ask_px":null,"bid_sz":0,"ask_sz":0,"bid_ct":0,"ask_ct":0}],"symbol":"TSLA"}
{"ts_recv":"2024-11-01T08:00:00.486672774Z","hd":{"ts_event":"2024-11-01T08:00:00.486506095Z","rtype":10,"publisher_id":2,"instrument_id":16244},"action":"A","side":"B","depth":0,"price":"250.590000000","size":57,"flags":130,"ts_in_delta":166679,"sequence":287685,"levels":[{"bid_px":"250.590000000","ask_px":"251.140000000","bid_sz":114,"ask_sz":100,"bid_ct":2,"ask_ct":1},{"bid_px":"235.000000000","ask_px":"251.350000000","bid_sz":100,"ask_sz":1,"bid_ct":1,"ask_ct":1},{"bid_px":null,"ask_px":"960.000000000","bid_sz":0,"ask_sz":25,"bid_ct":0,"ask_ct":1},{"bid_px":null,"ask_px":null,"bid_sz":0,"ask_sz":0,"bid_ct":0,"ask_ct":0},{"bid_px":null,"ask_px":null,"bid_sz":0,"ask_sz":0,"bid_ct":0,"ask_ct":0},{"bid_px":null,"ask_px":null,"bid_sz":0,"ask_sz":0,"bid_ct":0,"ask_ct":0},{"bid_px":null,"ask_px":null,"bid_sz":0,"ask_sz":0,"bid_ct":0,"ask_ct":0},{"bid_px":null,"ask_px":null,"bid_sz":0,"ask_sz":0,"bid_ct":0,"ask_ct":0},{"bid_px":null,"ask_px":null,"bid_sz":0,"ask_sz":0,"bid_ct":0,"ask_ct":0},{"bid_px":null,"ask_px":null,"bid_sz":0,"ask_sz":0,"bid_ct":0,"ask_ct":0}],"symbol":"TSLA"}
{"ts_recv":"2024-11-01T08:00:00.486706449Z","hd":{"ts_event":"2024-11-01T08:00:00.486540735Z","rtype":10,"publisher_id":2,"instrument_id":16244},"action":"C","side":"B","depth":0,"price":"250.590000000","size":57,"flags":130,"ts_in_delta":165714,"sequence":287686,"levels":[{"bid_px":"250.590000000","ask_px":"251.140000000","bid_sz":57,"ask_sz":100,"bid_ct":1,"ask_ct":1},{"bid_px":"235.000000000","ask_px":"251.350000000","bid_sz":100,"ask_sz":1,"bid_ct":1,"ask_ct":1},{"bid_px":null,"ask_px":"960.000000000","bid_sz":0,"ask_sz":25,"bid_ct":0,"ask_ct":1},{"bid_px":null,"ask_px":null,"bid_sz":0,"ask_sz":0,"bid_ct":0,"ask_ct":0},{"bid_px":null,"ask_px":null,"bid_sz":0,"ask_sz":0,"bid_ct":0,"ask_ct":0},{"bid_px":null,"ask_px":null,"bid_sz":0,"ask_sz":0,"bid_ct":0,"ask_ct":0},{"bid_px":null,"ask_px":null,"bid_sz":0,"ask_sz":0,"bid_ct":0,"ask_ct":0},{"bid_px":null,"ask_px":null,"bid_sz":0,"ask_sz":0,"bid_ct":0,"ask_ct":0},{"bid_px":null,"ask_px":null,"bid_sz":0,"ask_sz":0,"bid_ct":0,"ask_ct":0},{"bid_px":null,"ask_px":null,"bid_sz":0,"ask_sz":0,"bid_ct":0,"ask_ct":0}],"symbol":"TSLA"}
{"ts_recv":"2024-11-01T08:00:00.501417442Z","hd":{"ts_event":"2024-11-01T08:00:00.501249656Z","rtype":10,"publisher_id":2,"instrument_id":16244},"action":"T","side":"A","depth":0,"price":"250.590000000","size":8,"flags":130,"ts_in_delta":167786,"sequence":287707,"levels":[{"bid_px":"250.590000000","ask_px":"251.140000000","bid_sz":57,"ask_sz":100,"bid_ct":1,"ask_ct":1},{"bid_px":"235.000000000","ask_px":"251.350000000","bid_sz":100,"ask_sz":1,"bid_ct":1,"ask_ct":1},{"bid_px":null,"ask_px":"960.000000000","bid_sz":0,"ask_sz":25,"bid_ct":0,"ask_ct":1},{"bid_px":null,"ask_px":null,"bid_sz":0,"ask_sz":0,"bid_ct":0,"ask_ct":0},{"bid_px":null,"ask_px":null,"bid_sz":0,"ask_sz":0,"bid_ct":0,"ask_ct":0},{"bid_px":null,"ask_px":null,"bid_sz":0,"ask_sz":0,"bid_ct":0,"ask_ct":0},{"bid_px":null,"ask_px":null,"bid_sz":0,"ask_sz":0,"bid_ct":0,"ask_ct":0},{"bid_px":null,"ask_px":null,"bid_sz":0,"ask_sz":0,"bid_ct":0,"ask_ct":0},{"bid_px":null,"ask_px":null,"bid_sz":0,"ask_sz":0,"bid_ct":0,"ask_ct":0},{"bid_px":null,"ask_px":null,"bid_sz":0,"ask_sz":0,"bid_ct":0,"ask_ct":0}],"symbol":"TSLA"}
{"ts_recv":"2024-11-01T08:00:00.501417442Z","hd":{"ts_event":"2024-11-01T08:00:00.501249656Z","rtype":10,"publisher_id":2,"instrument_id":16244},"action":"C","side":"B","depth":0,"price":"250.590000000","size":8,"flags":130,"ts_in_delta":167786,"sequence":287707,"levels":[{"bid_px":"250.590000000","ask_px":"251.140000000","bid_sz":49,"ask_sz":100,"bid_ct":1,"ask_ct":1},{"bid_px":"235.000000000","ask_px":"251.350000000","bid_sz":100,"ask_sz":1,"bid_ct":1,"ask_ct":1},{"bid_px":null,"ask_px":"960.000000000","bid_sz":0,"ask_sz":25,"bid_ct":0,"ask_ct":1},{"bid_px":null,"ask_px":null,"bid_sz":0,"ask_sz":0,"bid_ct":0,"ask_ct":0},{"bid_px":null,"ask_px":null,"bid_sz":0,"ask_sz":0,"bid_ct":0,"ask_ct":0},{"bid_px":null,"ask_px":null,"bid_sz":0,"ask_sz":0,"bid_ct":0,"ask_ct":0},{"bid_px":null,"ask_px":null,"bid_sz":0,"ask_sz":0,"bid_ct":0,"ask_ct":0},{"bid_px":null,"ask_px":null,"bid_sz":0,"ask_sz":0,"bid_ct":0,"ask_ct":0},{"bid_px":null,"ask_px":null,"bid_sz":0,"ask_sz":0,"bid_ct":0,"ask_ct":0},{"bid_px":null,"ask_px":null,"bid_sz":0,"ask_sz":0,"bid_ct":0,"ask_ct":0}],"symbol":"TSLA"}
{"ts_recv":"2024-11-01T08:00:00.535855868Z","hd":{"ts_event":"2024-11-01T08:00:00.535688993Z","rtype":10,"publisher_id":2,"instrument_id":16244},"action":"T","side":"A","depth":0,"price":"250.590000000","size":5,"flags":130,"ts_in_delta":166875,"sequence":287853,"levels":[{"bid_px":"250.590000000","ask_px":"251.140000000","bid_sz":49,"ask_sz":100,"bid_ct":1,"ask_ct":1},{"bid_px":"235.000000000","ask_px":"251.350000000","bid_sz":100,"ask_sz":1,"bid_ct":1,"ask_ct":1},{"bid_px":null,"ask_px":"960.000000000","bid_sz":0,"ask_sz":25,"bid_ct":0,"ask_ct":1},{"bid_px":null,"ask_px":null,"bid_sz":0,"ask_sz":0,"bid_ct":0,"ask_ct":0},{"bid_px":null,"ask_px":null,"bid_sz":0,"ask_sz":0,"bid_ct":0,"ask_ct":0},{"bid_px":null,"ask_px":null,"bid_sz":0,"ask_sz":0,"bid_ct":0,"ask_ct":0},{"bid_px":null,"ask_px":null,"bid_sz":0,"ask_sz":0,"bid_ct":0,"ask_ct":0},{"bid_px":null,"ask_px":null,"bid_sz":0,"ask_sz":0,"bid_ct":0,"ask_ct":0},{"bid_px":null,"ask_px":null,"bid_sz":0,"ask_sz":0,"bid_ct":0,"ask_ct":0},{"bid_px":null,"ask_px":null,"bid_sz":0,"ask_sz":0,"bid_ct":0,"ask_ct":0}],"symbol":"TSLA"}
{"ts_recv":"2024-11-01T08:00:00.535855868Z","hd":{"ts_event":"2024-11-01T08:00:00.535688993Z","rtype":10,"publisher_id":2,"instrument_id":16244},"action":"C","side":"B","depth":0,"price":"250.590000000","size":5,"flags":130,"ts_in_delta":166875,"sequence":287853,"levels":[{"bid_px":"250.590000000","ask_px":"251.140000000","bid_sz":44,"ask_sz":100,"bid_ct":1,"ask_ct":1},{"bid_px":"235.000000000","ask_px":"251.350000000","bid_sz":100,"ask_sz":1,"bid_ct":1,"ask_ct":1},{"bid_px":null,"ask_px":"960.000000000","bid_sz":0,"ask_sz":25,"bid_ct":0,"ask_ct":1},{"bid_px":null,"ask_px":null,"bid_sz":0,"ask_sz":0,"bid_ct":0,"ask_ct":0},{"bid_px":null,"ask_px":null,"bid_sz":0,"ask_sz":0,"bid_ct":0,"ask_ct":0},{"bid_px":null,"ask_px":null,"bid_sz":0,"ask_sz":0,"bid_ct":0,"ask_ct":0},{"bid_px":null,"ask_px":null,"bid_sz":0,"ask_sz":0,"bid_ct":0,"ask_ct":0},{"bid_px":null,"ask_px":null,"bid_sz":0,"ask_sz":0,"bid_ct":0,"ask_ct":0},{"bid_px":null,"ask_px":null,"bid_sz":0,"ask_sz":0,"bid_ct":0,"ask_ct":0},{"bid_px":null,"ask_px":null,"bid_sz":0,"ask_sz":0,"bid_ct":0,"ask_ct":0}],"symbol":"TSLA"}
{"ts_recv":"2024-11-01T08:00:00.549680583Z","hd":{"ts_event":"2024-11-01T08:00:00.549514422Z","rtype":10,"publisher_id":2,"instrument_id":16244},"action":"A","side":"B","depth":0,"price":"250.640000000","size":44,"flags":130,"ts_in_delta":166161,"sequence":287892,"levels":[{"bid_px":"250.640000000","ask_px":"251.140000000","bid_sz":44,"ask_sz":100,"bid_ct":1,"ask_ct":1},{"bid_px":"250.590000000","ask_px":"251.350000000","bid_sz":44,"ask_sz":1,"bid_ct":1,"ask_ct":1},{"bid_px":"235.000000000","ask_px":"960.000000000","bid_sz":100,"ask_sz":25,"bid_ct":1,"ask_ct":1},{"bid_px":null,"ask_px":null,"bid_sz":0,"ask_sz":0,"bid_ct":0,"ask_ct":0},{"bid_px":null,"ask_px":null,"bid_sz":0,"ask_sz":0,"bid_ct":0,"ask_ct":0},{"bid_px":null,"ask_px":null,"bid_sz":0,"ask_sz":0,"bid_ct":0,"ask_ct":0},{"bid_px":null,"ask_px":null,"bid_sz":0,"ask_sz":0,"bid_ct":0,"ask_ct":0},{"bid_px":null,"ask_px":null,"bid_sz":0,"ask_sz":0,"bid_ct":0,"ask_ct":0},{"bid_px":null,"ask_px":null,"bid_sz":0,"ask_sz":0,"bid_ct":0,"ask_ct":0},{"bid_px":null,"ask_px":null,"bid_sz":0,"ask_sz":0,"bid_ct":0,"ask_ct":0}],"symbol":"TSLA"}
{"ts_recv":"2024-11-01T08:00:00.549718559Z","hd":{"ts_event":"2024-11-01T08:00:00.549552699Z","rtype":10,"publisher_id":2,"instrument_id":16244},"action":"C","side":"B","depth":1,"price":"250.590000000","size":44,"flags":130,"ts_in_delta":165860,"sequence":287893,"levels":[{"bid_px":"250.640000000","ask_px":"251.140000000","bid_sz":44,"ask_sz":100,"bid_ct":1,"ask_ct":1},{"bid_px":"235.000000000","ask_px":"251.350000000","bid_sz":100,"ask_sz":1,"bid_ct":1,"ask_ct":1},{"bid_px":null,"ask_px":"960.000000000","bid_sz":0,"ask_sz":25,"bid_ct":0,"ask_ct":1},{"bid_px":null,"ask_px":null,"bid_sz":0,"ask_sz":0,"bid_ct":0,"ask_ct":0},{"bid_px":null,"ask_px":null,"bid_sz":0,"ask_sz":0,"bid_ct":0,"ask_ct":0},{"bid_px":null,"ask_px":null,"bid_sz":0,"ask_sz":0,"bid_ct":0,"ask_ct":0},{"bid_px":null,"ask_px":null,"bid_sz":0,"ask_sz":0,"bid_ct":0,"ask_ct":0},{"bid_px":null,"ask_px":null,"bid_sz":0,"ask_sz":0,"bid_ct":0,"ask_ct":0},{"bid_px":null,"ask_px":null,"bid_sz":0,"ask_sz":0,"bid_ct":0,"ask_ct":0},{"bid_px":null,"ask_px":null,"bid_sz":0,"ask_sz":0,"bid_ct":0,"ask_ct":0}],"symbol":"TSLA"}
{"ts_recv":"2024-11-01T08:00:00.549765488Z","hd":{"ts_event":"2024-11-01T08:00:00.549599269Z","rtype":10,"publisher_id":2,"instrument_id":16244},"action":"A","side":"B","depth":0,"price":"250.650000000","size":44,"flags":130,"ts_in_delta":166219,"sequence":287894,"levels":[{"bid_px":"250.650000000","ask_px":"251.140000000","bid_sz":44,"ask_sz":100,"bid_ct":1,"ask_ct":1},{"bid_px":"250.640000000","ask_px":"251.350000000","bid_sz":44,"ask_sz":1,"bid_ct":1,"ask_ct":1},{"bid_px":"235.000000000","ask_px":"960.000000000","bid_sz":100,"ask_sz":25,"bid_ct":1,"ask_ct":1},{"bid_px":null,"ask_px":null,"bid_sz":0,"ask_sz":0,"bid_ct":0,"ask_ct":0},{"bid_px":null,"ask_px":null,"bid_sz":0,"ask_sz":0,"bid_ct":0,"ask_ct":0},{"bid_px":null,"ask_px":null,"bid_sz":0,"ask_sz":0,"bid_ct":0,"ask_ct":0},{"bid_px":null,"ask_px":null,"bid_sz":0,"ask_sz":0,"bid_ct":0,"ask_ct":0},{"bid_px":null,"ask_px":null,"bid_sz":0,"ask_sz":0,"bid_ct":0,"ask_ct":0},{"bid_px":null,"ask_px":null,"bid_sz":0,"ask_sz":0,"bid_ct":0,"ask_ct":0},{"bid_px":null,"ask_px":null,"bid_sz":0,"ask_sz":0,"bid_ct":0,"ask_ct":0}],"symbol":"TSLA"}
{"ts_recv":"2024-11-01T08:00:00.549787962Z","hd":{"ts_event":"2024-11-01T08:00:00.549622245Z","rtype":10,"publisher_id":2,"instrument_id":16244},"action":"C","side":"B","depth":1,"price":"250.640000000","size":44,"flags":130,"ts_in_delta":165717,"sequence":287895,"levels":[{"bid_px":"250.650000000","ask_px":"251.140000000","bid_sz":44,"ask_sz":100,"bid_ct":1,"ask_ct":1},{"bid_px":"235.000000000","ask_px":"251.350000000","bid_sz":100,"ask_sz":1,"bid_ct":1,"ask_ct":1},{"bid_px":null,"ask_px":"960.000000000","bid_sz":0,"ask_sz":25,"bid_ct":0,"ask_ct":1},{"bid_px":null,"ask_px":null,"bid_sz":0,"ask_sz":0,"bid_ct":0,"ask_ct":0},{"bid_px":null,"ask_px":null,"bid_sz":0,"ask_sz":0,"bid_ct":0,"ask_ct":0},{"bid_px":null,"ask_px":null,"bid_sz":0,"ask_sz":0,"bid_ct":0,"ask_ct":0},{"bid_px":null,"ask_px":null,"bid_sz":0,"ask_sz":0,"bid_ct":0,"ask_ct":0},{"bid_px":null,"ask_px":null,"bid_sz":0,"ask_sz":0,"bid_ct":0,"ask_ct":0},{"bid_px":null,"ask_px":null,"bid_sz":0,"ask_sz":0,"bid_ct":0,"ask_ct":0},{"bid_px":null,"ask_px":null,"bid_sz":0,"ask_sz":0,"bid_ct":0,"ask_ct":0}],"symbol":"TSLA"}
{"ts_recv":"2024-11-01T08:00:00.602698323Z","hd":{"ts_event":"2024-11-01T08:00:00.602531836Z","rtype":10,"publisher_id":2,"instrument_id":16244},"action":"A","side":"B","depth":1,"price":"249.700000000","size":1000,"flags":130,"ts_in_delta":166487,"sequence":288041,"levels":[{"bid_px":"250.650000000","ask_px":"251.140000000","bid_sz":44,"ask_sz":100,"bid_ct":1,"ask_ct":1},{"bid_px":"249.700000000","ask_px":"251.350000000","bid_sz":1000,"ask_sz":1,"bid_ct":1,"ask_ct":1},{"bid_px":"235.000000000","ask_px":"252.400000000","bid_sz":100,"ask_sz":1000,"bid_ct":1,"ask_ct":1},{"bid_px":null,"ask_px":"960.000000000","bid_sz":0,"ask_sz":25,"bid_ct":0,"ask_ct":1},{"bid_px":null,"ask_px":null,"bid_sz":0,"ask_sz":0,"bid_ct":0,"ask_ct":0},{"bid_px":null,"ask_px":null,"bid_sz":0,"ask_sz":0,"bid_ct":0,"ask_ct":0},{"bid_px":null,"ask_px":null,"bid_sz":0,"ask_sz":0,"bid_ct":0,"ask_ct":0},{"bid_px":null,"ask_px":null,"bid_sz":0,"ask_sz":0,"bid_ct":0,"ask_ct":0},{"bid_px":null,"ask_px":null,"bid_sz":0,"ask_sz":0,"bid_ct":0,"ask_ct":0},{"bid_px":null,"ask_px":null,"bid_sz":0,"ask_sz":0,"bid_ct":0,"ask_ct":0}],"symbol":"TSLA"}
{"ts_recv":"2024-11-01T08:00:00.646448551Z","hd":{"ts_event":"2024-11-01T08:00:00.646282292Z","rtype":10,"publisher_id":2,"instrument_id":16244},"action":"A","side":"A","depth":1,"price":"251.300000000","size":50,"flags":130,"ts_in_delta":166259,"sequence":288185,"levels":[{"bid_px":"250.650000000","ask_px":"251.140000000","bid_sz":44,"ask_sz":100,"bid_ct":1,"ask_ct":1},{"bid_px":"249.700000000","ask_px":"251.300000000","bid_sz":1000,"ask_sz":50,"bid_ct":1,"ask_ct":1},{"bid_px":"235.000000000","ask_px":"251.350000000","bid_sz":100,"ask_sz":1,"bid_ct":1,"ask_ct":1},{"bid_px":null,"ask_px":"252.400000000","bid_sz":0,"ask_sz":1000,"bid_ct":0,"ask_ct":1},{"bid_px":null,"ask_px":"960.000000000","bid_sz":0,"ask_sz":25,"bid_ct":0,"ask_ct":1},{"bid_px":null,"ask_px":null,"bid_sz":0,"ask_sz":0,"bid_ct":0,"ask_ct":0},{"bid_px":null,"ask_px":null,"bid_sz":0,"ask_sz":0,"bid_ct":0,"ask_ct":0},{"bid_px":null,"ask_px":null,"bid_sz":0,"ask_sz":0,"bid_ct":0,"ask_ct":0},{"bid_px":null,"ask_px":null,"bid_sz":0,"ask_sz":0,"bid_ct":0,"ask_ct":0},{"bid_px":null,"ask_px":null,"bid_sz":0,"ask_sz":0,"bid_ct":0,"ask_ct":0}],"symbol":"TSLA"}
{"ts_recv":"2024-11-01T08:00:00.685257122Z","hd":{"ts_event":"2024-11-01T08:00:00.685090840Z","rtype":10,"publisher_id":2,"instrument_id":16244},"action":"A","side":"B","depth":2,"price":"247.150000000","size":400,"flags":130,"ts_in_delta":166282,"sequence":288302,"levels":[{"bid_px":"250.650000000","ask_px":"251.140000000","bid_sz":44,"ask_sz":100,"bid_ct":1,"ask_ct":1},{"bid_px":"249.700000000","ask_px":"251.300000000","bid_sz":1000,"ask_sz":50,"bid_ct":1,"ask_ct":1},{"bid_px":"247.150000000","ask_px":"251.350000000","bid_sz":400,"ask_sz":1,"bid_ct":1,"ask_ct":1},{"bid_px":"235.000000000","ask_px":"252.400000000","bid_sz":100,"ask_sz":1000,"bid_ct":1,"ask_ct":1},{"bid_px":null,"ask_px":"960.000000000","bid_sz":0,"ask_sz":25,"bid_ct":0,"ask_ct":1},{"bid_px":null,"ask_px":null,"bid_sz":0,"ask_sz":0,"bid_ct":0,"ask_ct":0},{"bid_px":null,"ask_px":null,"bid_sz":0,"ask_sz":0,"bid_ct":0,"ask_ct":0},{"bid_px":null,"ask_px":null,"bid_sz":0,"ask_sz":0,"bid_ct":0,"ask_ct":0},{"bid_px":null,"ask_px":null,"bid_sz":0,"ask_sz":0,"bid_ct":0,"ask_ct":0},{"bid_px":null,"ask_px":null,"bid_sz":0,"ask_sz":0,"bid_ct":0,"ask_ct":0}],"symbol":"TSLA"}
{"ts_recv":"2024-11-01T08:00:00.685358404Z","hd":{"ts_event":"2024-11-01T08:00:00.685191982Z","rtype":10,"publisher_id":2,"instrument_id":16244},"action":"A","side":"A","depth":4,"price":"253.650000000","size":400,"flags":130,"ts_in_delta":166422,"sequence":288303,"levels":[{"bid_px":"250.650000000","ask_px":"251.140000000","bid_sz":44,"ask_sz":100,"bid_ct":1,"ask_ct":1},{"bid_px":"249.700000000","ask_px":"251.300000000","bid_sz":1000,"ask_sz":50,"bid_ct":1,"ask_ct":1},{"bid_px":"247.150000000","ask_px":"251.350000000","bid_sz":400,"ask_sz":1,"bid_ct":1,"ask_ct":1},{"bid_px":"235.000000000","ask_px":"252.400000000","bid_sz":100,"ask_sz":1000,"bid_ct":1,"ask_ct":1},{"bid_px":null,"ask_px":"253.650000000","bid_sz":0,"ask_sz":400,"bid_ct":0,"ask_ct":1},{"bid_px":null,"ask_px":"960.000000000","bid_sz":0,"ask_sz":25,"bid_ct":0,"ask_ct":1},{"bid_px":null,"ask_px":null,"bid_sz":0,"ask_sz":0,"bid_ct":0,"ask_ct":0},{"bid_px":null,"ask_px":null,"bid_sz":0,"ask_sz":0,"bid_ct":0,"ask_ct":0},{"bid_px":null,"ask_px":null,"bid_sz":0,"ask_sz":0,"bid_ct":0,"ask_ct":0},{"bid_px":null,"ask_px":null,"bid_sz":0,"ask_sz":0,"bid_ct":0,"ask_ct":0}],"symbol":"TSLA"}
{"ts_recv":"2024-11-01T08:00:00.728053346Z","hd":{"ts_event":"2024-11-01T08:00:00.727887097Z","rtype":10,"publisher_id":2,"instrument_id":16244},"action":"A","side":"A","depth":1,"price":"251.300000000","size":50,"flags":130,"ts_in_delta":166249,"sequence":288414,"levels":[{"bid_px":"250.650000000","ask_px":"251.140000000","bid_sz":44,"ask_sz":100,"bid_ct":1,"ask_ct":1},{"bid_px":"249.700000000","ask_px":"251.300000000","bid_sz":1000,"ask_sz":100,"bid_ct":1,"ask_ct":2},{"bid_px":"247.150000000","ask_px":"251.350000000","bid_sz":400,"ask_sz":1,"bid_ct":1,"ask_ct":1},{"bid_px":"235.000000000","ask_px":"252.400000000","bid_sz":100,"ask_sz":1000,"bid_ct":1,"ask_ct":1},{"bid_px":null,"ask_px":"253.650000000","bid_sz":0,"ask_sz":400,"bid_ct":0,"ask_ct":1},{"bid_px":null,"ask_px":"960.000000000","bid_sz":0,"ask_sz":25,"bid_ct":0,"ask_ct":1},{"bid_px":null,"ask_px":null,"bid_sz":0,"ask_sz":0,"bid_ct":0,"ask_ct":0},{"bid_px":null,"ask_px":null,"bid_sz":0,"ask_sz":0,"bid_ct":0,"ask_ct":0},{"bid_px":null,"ask_px":null,"bid_sz":0,"ask_sz":0,"bid_ct":0,"ask_ct":0},{"bid_px":null,"ask_px":null,"bid_sz":0,"ask_sz":0,"bid_ct":0,"ask_ct":0}],"symbol":"TSLA"}
{"ts_recv":"2024-11-01T08:00:00.737585014Z","hd":{"ts_event":"2024-11-01T08:00:00.737419091Z","rtype":10,"publisher_id":2,"instrument_id":16244},"action":"A","side":"B","depth":1,"price":"250.370000000","size":50,"flags":130,"ts_in_delta":165923,"sequence":288424,"levels":[{"bid_px":"250.650000000","ask_px":"251.140000000","bid_sz":44,"ask_sz":100,"bid_ct":1,"ask_ct":1},{"bid_px":"250.370000000","ask_px":"251.300000000","bid_sz":50,"ask_sz":100,"bid_ct":1,"ask_ct":2},{"bid_px":"249.700000000","ask_px":"251.350000000","bid_sz":1000,"ask_sz":1,"bid_ct":1,"ask_ct":1},{"bid_px":"247.150000000","ask_px":"252.400000000","bid_sz":400,"ask_sz":1000,"bid_ct":1,"ask_ct":1},{"bid_px":"235.000000000","ask_px":"253.650000000","bid_sz":100,"ask_sz":400,"bid_ct":1,"ask_ct":1},{"bid_px":null,"ask_px":"960.000000000","bid_sz":0,"ask_sz":25,"bid_ct":0,"ask_ct":1},{"bid_px":null,"ask_px":null,"bid_sz":0,"ask_sz":0,"bid_ct":0,"ask_ct":0},{"bid_px":null,"ask_px":null,"bid_sz":0,"ask_sz":0,"bid_ct":0,"ask_ct":0},{"bid_px":null,"ask_px":null,"bid_sz":0,"ask_sz":0,"bid_ct":0,"ask_ct":0},{"bid_px":null,"ask_px":null,"bid_sz":0,"ask_sz":0,"bid_ct":0,"ask_ct":0}],"symbol":"TSLA"}
{"ts_recv":"2024-11-01T08:00:00.737615718Z","hd":{"ts_event":"2024-11-01T08:00:00.737450175Z","rtype":10,"publisher_id":2,"instrument_id":16244},"action":"C","side":"A","depth":1,"price":"251.300000000","size":50,"flags":130,"ts_in_delta":165543,"sequence":288425,"levels":[{"bid_px":"250.650000000","ask_px":"251.140000000","bid_sz":44,"ask_sz":100,"bid_ct":1,"ask_ct":1},{"bid_px":"250.370000000","ask_px":"251.300000000","bid_sz":50,"ask_sz":50,"bid_ct":1,"ask_ct":1},{"bid_px":"249.700000000","ask_px":"251.350000000","bid_sz":1000,"ask_sz":1,"bid_ct":1,"ask_ct":1},{"bid_px":"247.150000000","ask_px":"252.400000000","bid_sz":400,"ask_sz":1000,"bid_ct":1,"ask_ct":1},{"bid_px":"235.000000000","ask_px":"253.650000000","bid_sz":100,"ask_sz":400,"bid_ct":1,"ask_ct":1},{"bid_px":null,"ask_px":"960.000000000","bid_sz":0,"ask_sz":25,"bid_ct":0,"ask_ct":1},{"bid_px":null,"ask_px":null,"bid_sz":0,"ask_sz":0,"bid_ct":0,"ask_ct":0},{"bid_px":null,"ask_px":null,"bid_sz":0,"ask_sz":0,"bid_ct":0,"ask_ct":0},{"bid_px":null,"ask_px":null,"bid_sz":0,"ask_sz":0,"bid_ct":0,"ask_ct":0},{"bid_px":null,"ask_px":null,"bid_sz":0,"ask_sz":0,"bid_ct":0,"ask_ct":0}],"symbol":"TSLA"}
{"ts_recv":"2024-11-01T08:00:00.737637686Z","hd":{"ts_event":"2024-11-01T08:00:00.737471510Z","rtype":10,"publisher_id":2,"instrument_id":16244},"action":"A","side":"A","depth":1,"price":"251.290000000","size":50,"flags":130,"ts_in_delta":166176,"sequence":288426,"levels":[{"bid_px":"250.650000000","ask_px":"251.140000000","bid_sz":44,"ask_sz":100,"bid_ct":1,"ask_ct":1},{"bid_px":"250.370000000","ask_px":"251.290000000","bid_sz":50,"ask_sz":50,"bid_ct":1,"ask_ct":1},{"bid_px":"249.700000000","ask_px":"251.350000000","bid_sz":1000,"ask_sz":1,"bid_ct":1,"ask_ct":1},{"bid_px":"247.150000000","ask_px":"252.400000000","bid_sz":400,"ask_sz":1000,"bid_ct":1,"ask_ct":1},{"bid_px":"235.000000000","ask_px":"253.650000000","bid_sz":100,"ask_sz":400,"bid_ct":1,"ask_ct":1},{"bid_px":null,"ask_px":"960.000000000","bid_sz":0,"ask_sz":25,"bid_ct":0,"ask_ct":1},{"bid_px":null,"ask_px":null,"bid_sz":0,"ask_sz":0,"bid_ct":0,"ask_ct":0},{"bid_px":null,"ask_px":null,"bid_sz":0,"ask_sz":0,"bid_ct":0,"ask_ct":0},{"bid_px":null,"ask_px":null,"bid_sz":0,"ask_sz":0,"bid_ct":0,"ask_ct":0},{"bid_px":null,"ask_px":null,"bid_sz":0,"ask_sz":0,"bid_ct":0,"ask_ct":0}],"symbol":"TSLA"}
{"ts_recv":"2024-11-01T08:00:00.783046930Z","hd":{"ts_event":"2024-11-01T08:00:00.782879583Z","rtype":10,"publisher_id":2,"instrument_id":16244},"action":"A","side":"A","depth":1,"price":"251.250000000","size":50,"flags":130,"ts_in_delta":167347,"sequence":288564,"levels":[{"bid_px":"250.650000000","ask_px":"251.140000000","bid_sz":44,"ask_sz":100,"bid_ct":1,"ask_ct":1},{"bid_px":"250.370000000","ask_px":"251.250000000","bid_sz":50,"ask_sz":50,"bid_ct":1,"ask_ct":1},{"bid_px":"249.700000000","ask_px":"251.350000000","bid_sz":1000,"ask_sz":1,"bid_ct":1,"ask_ct":1},{"bid_px":"247.150000000","ask_px":"252.400000000","bid_sz":400,"ask_sz":1000,"bid_ct":1,"ask_ct":1},{"bid_px":"235.000000000","ask_px":"253.650000000","bid_sz":100,"ask_sz":400,"bid_ct":1,"ask_ct":1},{"bid_px":null,"ask_px":"960.000000000","bid_sz":0,"ask_sz":25,"bid_ct":0,"ask_ct":1},{"bid_px":null,"ask_px":null,"bid_sz":0,"ask_sz":0,"bid_ct":0,"ask_ct":0},{"bid_px":null,"ask_px":null,"bid_sz":0,"ask_sz":0,"bid_ct":0,"ask_ct":0},{"bid_px":null,"ask_px":null,"bid_sz":0,"ask_sz":0,"bid_ct":0,"ask_ct":0},{"bid_px":null,"ask_px":null,"bid_sz":0,"ask_sz":0,"bid_ct":0,"ask_ct":0}],"symbol":"TSLA"}
{"ts_recv":"2024-11-01T08:00:00.816324059Z","hd":{"ts_event":"2024-11-01T08:00:00.816157932Z","rtype":10,"publisher_id":2,"instrument_id":16244},"action":"C","side":"A","depth":2,"price":"251.350000000","size":1,"flags":130,"ts_in_delta":166127,"sequence":288650,"levels":[{"bid_px":"250.650000000","ask_px":"251.140000000","bid_sz":44,"ask_sz":100,"bid_ct":1,"ask_ct":1},{"bid_px":"250.370000000","ask_px":"251.250000000","bid_sz":50,"ask_sz":50,"bid_ct":1,"ask_ct":1},{"bid_px":"249.700000000","ask_px":"252.400000000","bid_sz":1000,"ask_sz":1000,"bid_ct":1,"ask_ct":1},{"bid_px":"247.150000000","ask_px":"253.650000000","bid_sz":400,"ask_sz":400,"bid_ct":1,"ask_ct":1},{"bid_px":"235.000000000","ask_px":"960.000000000","bid_sz":100,"ask_sz":25,"bid_ct":1,"ask_ct":1},{"bid_px":null,"ask_px":null,"bid_sz":0,"ask_sz":0,"bid_ct":0,"ask_ct":0},{"bid_px":null,"ask_px":null,"bid_sz":0,"ask_sz":0,"bid_ct":0,"ask_ct":0},{"bid_px":null,"ask_px":null,"bid_sz":0,"ask_sz":0,"bid_ct":0,"ask_ct":0},{"bid_px":null,"ask_px":null,"bid_sz":0,"ask_sz":0,"bid_ct":0,"ask_ct":0},{"bid_px":null,"ask_px":null,"bid_sz":0,"ask_sz":0,"bid_ct":0,"ask_ct":0}],"symbol":"TSLA"}
{"ts_recv":"2024-11-01T08:00:00.870798645Z","hd":{"ts_event":"2024-11-01T08:00:00.870632992Z","rtype":10,"publisher_id":2,"instrument_id":16244},"action":"C","side":"B","depth":1,"price":"250.370000000","size":50,"flags":130,"ts_in_delta":165653,"sequence":288765,"levels":[{"bid_px":"250.650000000","ask_px":"251.140000000","bid_sz":44,"ask_sz":100,"bid_ct":1,"ask_ct":1},{"bid_px":"249.700000000","ask_px":"251.250000000","bid_sz":1000,"ask_sz":50,"bid_ct":1,"ask_ct":1},{"bid_px":"247.150000000","ask_px":"252.400000000","bid_sz":400,"ask_sz":1000,"bid_ct":1,"ask_ct":1},{"bid_px":"235.000000000","ask_px":"253.650000000","bid_sz":100,"ask_sz":400,"bid_ct":1,"ask_ct":1},{"bid_px":null,"ask_px":"960.000000000","bid_sz":0,"ask_sz":25,"bid_ct":0,"ask_ct":1},{"bid_px":null,"ask_px":null,"bid_sz":0,"ask_sz":0,"bid_ct":0,"ask_ct":0},{"bid_px":null,"ask_px":null,"bid_sz":0,"ask_sz":0,"bid_ct":0,"ask_ct":0},{"bid_px":null,"ask_px":null,"bid_sz":0,"ask_sz":0,"bid_ct":0,"ask_ct":0},{"bid_px":null,"ask_px":null,"bid_sz":0,"ask_sz":0,"bid_ct":0,"ask_ct":0},{"bid_px":null,"ask_px":null,"bid_sz":0,"ask_sz":0,"bid_ct":0,"ask_ct":0}],"symbol":"TSLA"}
{"ts_recv":"2024-11-01T08:00:00.870810579Z","hd":{"ts_event":"2024-11-01T08:00:00.870644760Z","rtype":10,"publisher_id":2,"instrument_id":16244},"action":"A","side":"B","depth":1,"price":"250.320000000","size":50,"flags":130,"ts_in_delta":165819,"sequence":288766,"levels":[{"bid_px":"250.650000000","ask_px":"251.140000000","bid_sz":44,"ask_sz":100,"bid_ct":1,"ask_ct":1},{"bid_px":"250.320000000","ask_px":"251.250000000","bid_sz":50,"ask_sz":50,"bid_ct":1,"ask_ct":1},{"bid_px":"249.700000000","ask_px":"252.400000000","bid_sz":1000,"ask_sz":1000,"bid_ct":1,"ask_ct":1},{"bid_px":"247.150000000","ask_px":"253.650000000","bid_sz":400,"ask_sz":400,"bid_ct":1,"ask_ct":1},{"bid_px":"235.000000000","ask_px":"960.000000000","bid_sz":100,"ask_sz":25,"bid_ct":1,"ask_ct":1},{"bid_px":null,"ask_px":null,"bid_sz":0,"ask_sz":0,"bid_ct":0,"ask_ct":0},{"bid_px":null,"ask_px":null,"bid_sz":0,"ask_sz":0,"bid_ct":0,"ask_ct":0},{"bid_px":null,"ask_px":null,"bid_sz":0,"ask_sz":0,"bid_ct":0,"ask_ct":0},{"bid_px":null,"ask_px":null,"bid_sz":0,"ask_sz":0,"bid_ct":0,"ask_ct":0},{"bid_px":null,"ask_px":null,"bid_sz":0,"ask_sz":0,"bid_ct":0,"ask_ct":0}],"symbol":"TSLA"}
{"ts_recv":"2024-11-01T08:00:00.923892379Z","hd":{"ts_event":"2024-11-01T08:00:00.923726506Z","rtype":10,"publisher_id":2,"instrument_id":16244},"action":"C","side":"B","depth":1,"price":"250.320000000","size":50,"flags":130,"ts_in_delta":165873,"sequence":289004,"levels":[{"bid_px":"250.650000000","ask_px":"251.140000000","bid_sz":44,"ask_sz":100,"bid_ct":1,"ask_ct":1},{"bid_px":"249.700000000","ask_px":"251.250000000","bid_sz":1000,"ask_sz":50,"bid_ct":1,"ask_ct":1},{"bid_px":"247.150000000","ask_px":"252.400000000","bid_sz":400,"ask_sz":1000,"bid_ct":1,"ask_ct":1},{"bid_px":"235.000000000","ask_px":"253.650000000","bid_sz":100,"ask_sz":400,"bid_ct":1,"ask_ct":1},{"bid_px":null,"ask_px":"960.000000000","bid_sz":0,"ask_sz":25,"bid_ct":0,"ask_ct":1},{"bid_px":null,"ask_px":null,"bid_sz":0,"ask_sz":0,"bid_ct":0,"ask_ct":0},{"bid_px":null,"ask_px":null,"bid_sz":0,"ask_sz":0,"bid_ct":0,"ask_ct":0},{"bid_px":null,"ask_px":null,"bid_sz":0,"ask_sz":0,"bid_ct":0,"ask_ct":0},{"bid_px":null,"ask_px":null,"bid_sz":0,"ask_sz":0,"bid_ct":0,"ask_ct":0},{"bid_px":null,"ask_px":null,"bid_sz":0,"ask_sz":0,"bid_ct":0,"ask_ct":0}],"symbol":"TSLA"}
{"ts_recv":"2024-11-01T08:00:00.924058952Z","hd":{"ts_event":"2024-11-01T08:00:00.923891312Z","rtype":10,"publisher_id":2,"instrument_id":16244},"action":"T","side":"A","depth":0,"price":"250.650000000","size":44,"flags":130,"ts_in_delta":167640,"sequence":289007,"levels":[{"bid_px":"250.650000000","ask_px":"251.140000000","bid_sz":44,"ask_sz":100,"bid_ct":1,"ask_ct":1},{"bid_px":"249.700000000","ask_px":"251.250000000","bid_sz":1000,"ask_sz":50,"bid_ct":1,"ask_ct":1},{"bid_px":"247.150000000","ask_px":"252.400000000","bid_sz":400,"ask_sz":1000,"bid_ct":1,"ask_ct":1},{"bid_px":"235.000000000","ask_px":"253.650000000","bid_sz":100,"ask_sz":400,"bid_ct":1,"ask_ct":1},{"bid_px":null,"ask_px":"960.000000000","bid_sz":0,"ask_sz":25,"bid_ct":0,"ask_ct":1},{"bid_px":null,"ask_px":null,"bid_sz":0,"ask_sz":0,"bid_ct":0,"ask_ct":0},{"bid_px":null,"ask_px":null,"bid_sz":0,"ask_sz":0,"bid_ct":0,"ask_ct":0},{"bid_px":null,"ask_px":null,"bid_sz":0,"ask_sz":0,"bid_ct":0,"ask_ct":0},{"bid_px":null,"ask_px":null,"bid_sz":0,"ask_sz":0,"bid_ct":0,"ask_ct":0},{"bid_px":null,"ask_px":null,"bid_sz":0,"ask_sz":0,"bid_ct":0,"ask_ct":0}],"symbol":"TSLA"}
{"ts_recv":"2024-11-01T08:00:00.924058952Z","hd":{"ts_event":"2024-11-01T08:00:00.923891312Z","rtype":10,"publisher_id":2,"instrument_id":16244},"action":"C","side":"B","depth":0,"price":"250.650000000","size":44,"flags":130,"ts_in_delta":167640,"sequence":289007,"levels":[{"bid_px":"249.700000000","ask_px":"251.140000000","bid_sz":1000,"ask_sz":100,"bid_ct":1,"ask_ct":1},{"bid_px":"247.150000000","ask_px":"251.250000000","bid_sz":400,"ask_sz":50,"bid_ct":1,"ask_ct":1},{"bid_px":"235.000000000","ask_px":"252.400000000","bid_sz":100,"ask_sz":1000,"bid_ct":1,"ask_ct":1},{"bid_px":null,"ask_px":"253.650000000","bid_sz":0,"ask_sz":400,"bid_ct":0,"ask_ct":1},{"bid_px":null,"ask_px":"960.000000000","bid_sz":0,"ask_sz":25,"bid_ct":0,"ask_ct":1},{"bid_px":null,"ask_px":null,"bid_sz":0,"ask_sz":0,"bid_ct":0,"ask_ct":0},{"bid_px":null,"ask_px":null,"bid_sz":0,"ask_sz":0,"bid_ct":0,"ask_ct":0},{"bid_px":null,"ask_px":null,"bid_sz":0,"ask_sz":0,"bid_ct":0,"ask_ct":0},{"bid_px":null,"ask_px":null,"bid_sz":0,"ask_sz":0,"bid_ct":0,"ask_ct":0},{"bid_px":null,"ask_px":null,"bid_sz":0,"ask_sz":0,"bid_ct":0,"ask_ct":0}],"symbol":"TSLA"}
{"ts_recv":"2024-11-01T08:00:00.924082550Z","hd":{"ts_event":"2024-11-01T08:00:00.923916634Z","rtype":10,"publisher_id":2,"instrument_id":16244},"action":"A","side":"A","depth":0,"price":"251.040000000","size":100,"flags":130,"ts_in_delta":165916,"sequence":289008,"levels":[{"bid_px":"249.700000000","ask_px":"251.040000000","bid_sz":1000,"ask_sz":100,"bid_ct":1,"ask_ct":1},{"bid_px":"247.150000000","ask_px":"251.140000000","bid_sz":400,"ask_sz":100,"bid_ct":1,"ask_ct":1},{"bid_px":"235.000000000","ask_px":"251.250000000","bid_sz":100,"ask_sz":50,"bid_ct":1,"ask_ct":1},{"bid_px":null,"ask_px":"252.400000000","bid_sz":0,"ask_sz":1000,"bid_ct":0,"ask_ct":1},{"bid_px":null,"ask_px":"253.650000000","bid_sz":0,"ask_sz":400,"bid_ct":0,"ask_ct":1},{"bid_px":null,"ask_px":"960.000000000","bid_sz":0,"ask_sz":25,"bid_ct":0,"ask_ct":1},{"bid_px":null,"ask_px":null,"bid_sz":0,"ask_sz":0,"bid_ct":0,"ask_ct":0},{"bid_px":null,"ask_px":null,"bid_sz":0,"ask_sz":0,"bid_ct":0,"ask_ct":0},{"bid_px":null,"ask_px":null,"bid_sz":0,"ask_sz":0,"bid_ct":0,"ask_ct":0},{"bid_px":null,"ask_px":null,"bid_sz":0,"ask_sz":0,"bid_ct":0,"ask_ct":0}],"symbol":"TSLA"}
{"ts_recv":"2024-11-01T08:00:00.924083719Z","hd":{"ts_event":"2024-11-01T08:00:00.923917728Z","rtype":10,"publisher_id":2,"instrument_id":16244},"action":"A","side":"A","depth":0,"price":"250.860000000","size":100,"flags":130,"ts_in_delta":165991,"sequence":289009,"levels":[{"bid_px":"249.700000000","ask_px":"250.860000000","bid_sz":1000,"ask_sz":100,"bid_ct":1,"ask_ct":1},{"bid_px":"247.150000000","ask_px":"251.040000000","bid_sz":400,"ask_sz":100,"bid_ct":1,"ask_ct":1},{"bid_px":"235.000000000","ask_px":"251.140000000","bid_sz":100,"ask_sz":100,"bid_ct":1,"ask_ct":1},{"bid_px":null,"ask_px":"251.250000000","bid_sz":0,"ask_sz":50,"bid_ct":0,"ask_ct":1},{"bid_px":null,"ask_px":"252.400000000","bid_sz":0,"ask_sz":1000,"bid_ct":0,"ask_ct":1},{"bid_px":null,"ask_px":"253.650000000","bid_sz":0,"ask_sz":400,"bid_ct":0,"ask_ct":1},{"bid_px":null,"ask_px":"960.000000000","bid_sz":0,"ask_sz":25,"bid_ct":0,"ask_ct":1},{"bid_px":null,"ask_px":null,"bid_sz":0,"ask_sz":0,"bid_ct":0,"ask_ct":0},{"bid_px":null,"ask_px":null,"bid_sz":0,"ask_sz":0,"bid_ct":0,"ask_ct":0},{"bid_px":null,"ask_px":null,"bid_sz":0,"ask_sz":0,"bid_ct":0,"ask_ct":0}],"symbol":"TSLA"}
{"ts_recv":"2024-11-01T08:00:00.924085460Z","hd":{"ts_event":"2024-11-01T08:00:00.923918768Z","rtype":10,"publisher_id":2,"instrument_id":16244},"action":"A","side":"A","depth":1,"price":"251.040000000","size":100,"flags":130,"ts_in_delta":166692,"sequence":289010,"levels":[{"bid_px":"249.700000000","ask_px":"250.860000000","bid_sz":1000,"ask_sz":100,"bid_ct":1,"ask_ct":1},{"bid_px":"247.150000000","ask_px":"251.040000000","bid_sz":400,"ask_sz":200,"bid_ct":1,"ask_ct":2},{"bid_px":"235.000000000","ask_px":"251.140000000","bid_sz":100,"ask_sz":100,"bid_ct":1,"ask_ct":1},{"bid_px":null,"ask_px":"251.250000000","bid_sz":0,"ask_sz":50,"bid_ct":0,"ask_ct":1},{"bid_px":null,"ask_px":"252.400000000","bid_sz":0,"ask_sz":1000,"bid_ct":0,"ask_ct":1},{"bid_px":null,"ask_px":"253.650000000","bid_sz":0,"ask_sz":400,"bid_ct":0,"ask_ct":1},{"bid_px":null,"ask_px":"960.000000000","bid_sz":0,"ask_sz":25,"bid_ct":0,"ask_ct":1},{"bid_px":null,"ask_px":null,"bid_sz":0,"ask_sz":0,"bid_ct":0,"ask_ct":0},{"bid_px":null,"ask_px":null,"bid_sz":0,"ask_sz":0,"bid_ct":0,"ask_ct":0},{"bid_px":null,"ask_px":null,"bid_sz":0,"ask_sz":0,"bid_ct":0,"ask_ct":0}],"symbol":"TSLA"}
{"ts_recv":"2024-11-01T08:00:00.924097499Z","hd":{"ts_event":"2024-11-01T08:00:00.923931446Z","rtype":10,"publisher_id":2,"instrument_id":16244},"action":"A","side":"A","depth":1,"price":"251.040000000","size":100,"flags":130,"ts_in_delta":166053,"sequence":289011,"levels":[{"bid_px":"249.700000000","ask_px":"250.860000000","bid_sz":1000,"ask_sz":100,"bid_ct":1,"ask_ct":1},{"bid_px":"247.150000000","ask_px":"251.040000000","bid_sz":400,"ask_sz":300,"bid_ct":1,"ask_ct":3},{"bid_px":"235.000000000","ask_px":"251.140000000","bid_sz":100,"ask_sz":100,"bid_ct":1,"ask_ct":1},{"bid_px":null,"ask_px":"251.250000000","bid_sz":0,"ask_sz":50,"bid_ct":0,"ask_ct":1},{"bid_px":null,"ask_px":"252.400000000","bid_sz":0,"ask_sz":1000,"bid_ct":0,"ask_ct":1},{"bid_px":null,"ask_px":"253.650000000","bid_sz":0,"ask_sz":400,"bid_ct":0,"ask_ct":1},{"bid_px":null,"ask_px":"960.000000000","bid_sz":0,"ask_sz":25,"bid_ct":0,"ask_ct":1},{"bid_px":null,"ask_px":null,"bid_sz":0,"ask_sz":0,"bid_ct":0,"ask_ct":0},{"bid_px":null,"ask_px":null,"bid_sz":0,"ask_sz":0,"bid_ct":0,"ask_ct":0},{"bid_px":null,"ask_px":null,"bid_sz":0,"ask_sz":0,"bid_ct":0,"ask_ct":0}],"symbol":"TSLA"}
{"ts_recv":"2024-11-01T08:00:00.924108518Z","hd":{"ts_event":"2024-11-01T08:00:00.923942922Z","rtype":10,"publisher_id":2,"instrument_id":16244},"action":"C","side":"A","depth":0,"price":"250.860000000","size":100,"flags":130,"ts_in_delta":165596,"sequence":289012,"levels":[{"bid_px":"249.700000000","ask_px":"251.040000000","bid_sz":1000,"ask_sz":300,"bid_ct":1,"ask_ct":3},{"bid_px":"247.150000000","ask_px":"251.140000000","bid_sz":400,"ask_sz":100,"bid_ct":1,"ask_ct":1},{"bid_px":"235.000000000","ask_px":"251.250000000","bid_sz":100,"ask_sz":50,"bid_ct":1,"ask_ct":1},{"bid_px":null,"ask_px":"252.400000000","bid_sz":0,"ask_sz":1000,"bid_ct":0,"ask_ct":1},{"bid_px":null,"ask_px":"253.650000000","bid_sz":0,"ask_sz":400,"bid_ct":0,"ask_ct":1},{"bid_px":null,"ask_px":"960.000000000","bid_sz":0,"ask_sz":25,"bid_ct":0,"ask_ct":1},{"bid_px":null,"ask_px":null,"bid_sz":0,"ask_sz":0,"bid_ct":0,"ask_ct":0},{"bid_px":null,"ask_px":null,"bid_sz":0,"ask_sz":0,"bid_ct":0,"ask_ct":0},{"bid_px":null,"ask_px":null,"bid_sz":0,"ask_sz":0,"bid_ct":0,"ask_ct":0},{"bid_px":null,"ask_px":null,"bid_sz":0,"ask_sz":0,"bid_ct":0,"ask_ct":0}],"symbol":"TSLA"}
{"ts_recv":"2024-11-01T08:00:00.924122177Z","hd":{"ts_event":"2024-11-01T08:00:00.923956325Z","rtype":10,"publisher_id":2,"instrument_id":16244},"action":"C","side":"A","depth":0,"price":"251.040000000","size":100,"flags":130,"ts_in_delta":165852,"sequence":289014,"levels":[{"bid_px":"249.700000000","ask_px":"250.900000000","bid_sz":1000,"ask_sz":27,"bid_ct":1,"ask_ct":1},{"bid_px":"247.150000000","ask_px":"251.040000000","bid_sz":400,"ask_sz":200,"bid_ct":1,"ask_ct":2},{"bid_px":"235.000000000","ask_px":"251.140000000","bid_sz":100,"ask_sz":100,"bid_ct":1,"ask_ct":1},{"bid_px":null,"ask_px":"251.250000000","bid_sz":0,"ask_sz":50,"bid_ct":0,"ask_ct":1},{"bid_px":null,"ask_px":"252.400000000","bid_sz":0,"ask_sz":1000,"bid_ct":0,"ask_ct":1},{"bid_px":null,"ask_px":"253.650000000","bid_sz":0,"ask_sz":400,"bid_ct":0,"ask_ct":1},{"bid_px":null,"ask_px":"960.000000000","bid_sz":0,"ask_sz":25,"bid_ct":0,"ask_ct":1},{"bid_px":null,"ask_px":null,"bid_sz":0,"ask_sz":0,"bid_ct":0,"ask_ct":0},{"bid_px":null,"ask_px":null,"bid_sz":0,"ask_sz":0,"bid_ct":0,"ask_ct":0},{"bid_px":null,"ask_px":null,"bid_sz":0,"ask_sz":0,"bid_ct":0,"ask_ct":0}],"symbol":"TSLA"}
{"ts_recv":"2024-11-01T08:00:00.924162055Z","hd":{"ts_event":"2024-11-01T08:00:00.923996173Z","rtype":10,"publisher_id":2,"instrument_id":16244},"action":"A","side":"A","depth":2,"price":"251.050000000","size":27,"flags":130,"ts_in_delta":165882,"sequence":289015,"levels":[{"bid_px":"249.700000000","ask_px":"250.900000000","bid_sz":1000,"ask_sz":27,"bid_ct":1,"ask_ct":1},{"bid_px":"247.150000000","ask_px":"251.040000000","bid_sz":400,"ask_sz":200,"bid_ct":1,"ask_ct":2},{"bid_px":"235.000000000","ask_px":"251.050000000","bid_sz":100,"ask_sz":27,"bid_ct":1,"ask_ct":1},{"bid_px":null,"ask_px":"251.140000000","bid_sz":0,"ask_sz":100,"bid_ct":0,"ask_ct":1},{"bid_px":null,"ask_px":"251.250000000","bid_sz":0,"ask_sz":50,"bid_ct":0,"ask_ct":1},{"bid_px":null,"ask_px":"252.400000000","bid_sz":0,"ask_sz":1000,"bid_ct":0,"ask_ct":1},{"bid_px":null,"ask_px":"253.650000000","bid_sz":0,"ask_sz":400,"bid_ct":0,"ask_ct":1},{"bid_px":null,"ask_px":"960.000000000","bid_sz":0,"ask_sz":25,"bid_ct":0,"ask_ct":1},{"bid_px":null,"ask_px":null,"bid_sz":0,"ask_sz":0,"bid_ct":0,"ask_ct":0},{"bid_px":null,"ask_px":null,"bid_sz":0,"ask_sz":0,"bid_ct":0,"ask_ct":0}],"symbol":"TSLA"}
{"ts_recv":"2024-11-01T08:00:00.924222494Z","hd":{"ts_event":"2024-11-01T08:00:00.924056793Z","rtype":10,"publisher_id":2,"instrument_id":16244},"action":"A","side":"A","depth":2,"price":"251.050000000","size":69,"flags":130,"ts_in_delta":165701,"sequence":289016,"levels":[{"bid_px":"249.700000000","ask_px":"250.900000000","bid_sz":1000,"ask_sz":27,"bid_ct":1,"ask_ct":1},{"bid_px":"247.150000000","ask_px":"251.040000000","bid_sz":400,"ask_sz":200,"bid_ct":1,"ask_ct":2},{"bid_px":"235.000000000","ask_px":"251.050000000","bid_sz":100,"ask_sz":96,"bid_ct":1,"ask_ct":2},{"bid_px":null,"ask_px":"251.140000000","bid_sz":0,"ask_sz":100,"bid_ct":0,"ask_ct":1},{"bid_px":null,"ask_px":"251.250000000","bid_sz":0,"ask_sz":50,"bid_ct":0,"ask_ct":1},{"bid_px":null,"ask_px":"252.400000000","bid_sz":0,"ask_sz":1000,"bid_ct":0,"ask_ct":1},{"bid_px":null,"ask_px":"253.650000000","bid_sz":0,"ask_sz":400,"bid_ct":0,"ask_ct":1},{"bid_px":null,"ask_px":"960.000000000","bid_sz":0,"ask_sz":25,"bid_ct":0,"ask_ct":1},{"bid_px":null,"ask_px":null,"bid_sz":0,"ask_sz":0,"bid_ct":0,"ask_ct":0},{"bid_px":null,"ask_px":null,"bid_sz":0,"ask_sz":0,"bid_ct":0,"ask_ct":0}],"symbol":"TSLA"}
{"ts_recv":"2024-11-01T08:00:00.924238256Z","hd":{"ts_event":"2024-11-01T08:00:00.924072526Z","rtype":10,"publisher_id":2,"instrument_id":16244},"action":"C","side":"A","depth":0,"price":"250.900000000","size":27,"flags":130,"ts_in_delta":165730,"sequence":289017,"levels":[{"bid_px":"249.700000000","ask_px":"251.040000000","bid_sz":1000,"ask_sz":200,"bid_ct":1,"ask_ct":2},{"bid_px":"247.150000000","ask_px":"251.050000000","bid_sz":400,"ask_sz":96,"bid_ct":1,"ask_ct":2},{"bid_px":"235.000000000","ask_px":"251.140000000","bid_sz":100,"ask_sz":100,"bid_ct":1,"ask_ct":1},{"bid_px":null,"ask_px":"251.250000000","bid_sz":0,"ask_sz":50,"bid_ct":0,"ask_ct":1},{"bid_px":null,"ask_px":"252.400000000","bid_sz":0,"ask_sz":1000,"bid_ct":0,"ask_ct":1},{"bid_px":null,"ask_px":"253.650000000","bid_sz":0,"ask_sz":400,"bid_ct":0,"ask_ct":1},{"bid_px":null,"ask_px":"960.000000000","bid_sz":0,"ask_sz":25,"bid_ct":0,"ask_ct":1},{"bid_px":null,"ask_px":null,"bid_sz":0,"ask_sz":0,"bid_ct":0,"ask_ct":0},{"bid_px":null,"ask_px":null,"bid_sz":0,"ask_sz":0,"bid_ct":0,"ask_ct":0},{"bid_px":null,"ask_px":null,"bid_sz":0,"ask_sz":0,"bid_ct":0,"ask_ct":0}],"symbol":"TSLA"}
{"ts_recv":"2024-11-01T08:00:00.924250448Z","hd":{"ts_event":"2024-11-01T08:00:00.924084776Z","rtype":10,"publisher_id":2,"instrument_id":16244},"action":"C","side":"A","depth":1,"price":"251.050000000","size":27,"flags":130,"ts_in_delta":165672,"sequence":289018,"levels":[{"bid_px":"249.700000000","ask_px":"251.040000000","bid_sz":1000,"ask_sz":200,"bid_ct":1,"ask_ct":2},{"bid_px":"247.150000000","ask_px":"251.050000000","bid_sz":400,"ask_sz":69,"bid_ct":1,"ask_ct":1},{"bid_px":"235.000000000","ask_px":"251.140000000","bid_sz":100,"ask_sz":100,"bid_ct":1,"ask_ct":1},{"bid_px":null,"ask_px":"251.250000000","bid_sz":0,"ask_sz":50,"bid_ct":0,"ask_ct":1},{"bid_px":null,"ask_px":"252.400000000","bid_sz":0,"ask_sz":1000,"bid_ct":0,"ask_ct":1},{"bid_px":null,"ask_px":"253.650000000","bid_sz":0,"ask_sz":400,"bid_ct":0,"ask_ct":1},{"bid_px":null,"ask_px":"960.000000000","bid_sz":0,"ask_sz":25,"bid_ct":0,"ask_ct":1},{"bid_px":null,"ask_px":null,"bid_sz":0,"ask_sz":0,"bid_ct":0,"ask_ct":0},{"bid_px":null,"ask_px":null,"bid_sz":0,"ask_sz":0,"bid_ct":0,"ask_ct":0},{"bid_px":null,"ask_px":null,"bid_sz":0,"ask_sz":0,"bid_ct":0,"ask_ct":0}],"symbol":"TSLA"}
{"ts_recv":"2024-11-01T08:00:00.924261497Z","hd":{"ts_event":"2024-11-01T08:00:00.924095782Z","rtype":10,"publisher_id":2,"instrument_id":16244},"action":"C","side":"A","depth":1,"price":"251.050000000","size":69,"flags":130,"ts_in_delta":165715,"sequence":289019,"levels":[{"bid_px":"249.700000000","ask_px":"251.040000000","bid_sz":1000,"ask_sz":200,"bid_ct":1,"ask_ct":2},{"bid_px":"247.150000000","ask_px":"251.140000000","bid_sz":400,"ask_sz":100,"bid_ct":1,"ask_ct":1},{"bid_px":"235.000000000","ask_px":"251.250000000","bid_sz":100,"ask_sz":50,"bid_ct":1,"ask_ct":1},{"bid_px":null,"ask_px":"252.400000000","bid_sz":0,"ask_sz":1000,"bid_ct":0,"ask_ct":1},{"bid_px":null,"ask_px":"253.650000000","bid_sz":0,"ask_sz":400,"bid_ct":0,"ask_ct":1},{"bid_px":null,"ask_px":"960.000000000","bid_sz":0,"ask_sz":25,"bid_ct":0,"ask_ct":1},{"bid_px":null,"ask_px":null,"bid_sz":0,"ask_sz":0,"bid_ct":0,"ask_ct":0},{"bid_px":null,"ask_px":null,"bid_sz":0,"ask_sz":0,"bid_ct":0,"ask_ct":0},{"bid_px":null,"ask_px":null,"bid_sz":0,"ask_sz":0,"bid_ct":0,"ask_ct":0},{"bid_px":null,"ask_px":null,"bid_sz":0,"ask_sz":0,"bid_ct":0,"ask_ct":0}],"symbol":"TSLA"}
{"ts_recv":"2024-11-01T08:00:00.924336479Z","hd":{"ts_event":"2024-11-01T08:00:00.924170863Z","rtype":10,"publisher_id":2,"instrument_id":16244},"action":"C","side":"A","depth":0,"price":"251.040000000","size":100,"flags":130,"ts_in_delta":165616,"sequence":289020,"levels":[{"bid_px":"249.700000000","ask_px":"251.040000000","bid_sz":1000,"ask_sz":100,"bid_ct":1,"ask_ct":1},{"bid_px":"247.150000000","ask_px":"251.140000000","bid_sz":400,"ask_sz":100,"bid_ct":1,"ask_ct":1},{"bid_px":"235.000000000","ask_px":"251.250000000","bid_sz":100,"ask_sz":50,"bid_ct":1,"ask_ct":1},{"bid_px":null,"ask_px":"252.400000000","bid_sz":0,"ask_sz":1000,"bid_ct":0,"ask_ct":1},{"bid_px":null,"ask_px":"253.650000000","bid_sz":0,"ask_sz":400,"bid_ct":0,"ask_ct":1},{"bid_px":null,"ask_px":"960.000000000","bid_sz":0,"ask_sz":25,"bid_ct":0,"ask_ct":1},{"bid_px":null,"ask_px":null,"bid_sz":0,"ask_sz":0,"bid_ct":0,"ask_ct":0},{"bid_px":null,"ask_px":null,"bid_sz":0,"ask_sz":0,"bid_ct":0,"ask_ct":0},{"bid_px":null,"ask_px":null,"bid_sz":0,"ask_sz":0,"bid_ct":0,"ask_ct":0},{"bid_px":null,"ask_px":null,"bid_sz":0,"ask_sz":0,"bid_ct":0,"ask_ct":0}],"symbol":"TSLA"}
{"ts_recv":"2024-11-01T08:00:00.926519472Z","hd":{"ts_event":"2024-11-01T08:00:00.926353755Z","rtype":10,"publisher_id":2,"instrument_id":16244},"action":"C","side":"B","depth":0,"price":"249.700000000","size":1000,"flags":130,"ts_in_delta":165717,"sequence":289028,"levels":[{"bid_px":"247.150000000","ask_px":"251.040000000","bid_sz":400,"ask_sz":100,"bid_ct":1,"ask_ct":1},{"bid_px":"235.000000000","ask_px":"251.140000000","bid_sz":100,"ask_sz":100,"bid_ct":1,"ask_ct":1},{"bid_px":null,"ask_px":"251.250000000","bid_sz":0,"ask_sz":50,"bid_ct":0,"ask_ct":1},{"bid_px":null,"ask_px":"252.400000000","bid_sz":0,"ask_sz":1000,"bid_ct":0,"ask_ct":1},{"bid_px":null,"ask_px":"253.650000000","bid_sz":0,"ask_sz":400,"bid_ct":0,"ask_ct":1},{"bid_px":null,"ask_px":"960.000000000","bid_sz":0,"ask_sz":25,"bid_ct":0,"ask_ct":1},{"bid_px":null,"ask_px":null,"bid_sz":0,"ask_sz":0,"bid_ct":0,"ask_ct":0},{"bid_px":null,"ask_px":null,"bid_sz":0,"ask_sz":0,"bid_ct":0,"ask_ct":0},{"bid_px":null,"ask_px":null,"bid_sz":0,"ask_sz":0,"bid_ct":0,"ask_ct":0},{"bid_px":null,"ask_px":null,"bid_sz":0,"ask_sz":0,"bid_ct":0,"ask_ct":0}],"symbol":"TSLA"}
{"ts_recv":"2024-11-01T08:00:00.929078256Z","hd":{"ts_event":"2024-11-01T08:00:00.928912137Z","rtype":10,"publisher_id":2,"instrument_id":16244},"action":"C","side":"A","depth":0,"price":"251.040000000","size":100,"flags":130,"ts_in_delta":166119,"sequence":289038,"levels":[{"bid_px":"247.150000000","ask_px":"251.140000000","bid_sz":400,"ask_sz":100,"bid_ct":1,"ask_ct":1},{"bid_px":"235.000000000","ask_px":"251.250000000","bid_sz":100,"ask_sz":50,"bid_ct":1,"ask_ct":1},{"bid_px":null,"ask_px":"252.400000000","bid_sz":0,"ask_sz":1000,"bid_ct":0,"ask_ct":1},{"bid_px":null,"ask_px":"253.650000000","bid_sz":0,"ask_sz":400,"bid_ct":0,"ask_ct":1},{"bid_px":null,"ask_px":"960.000000000","bid_sz":0,"ask_sz":25,"bid_ct":0,"ask_ct":1},{"bid_px":null,"ask_px":null,"bid_sz":0,"ask_sz":0,"bid_ct":0,"ask_ct":0},{"bid_px":null,"ask_px":null,"bid_sz":0,"ask_sz":0,"bid_ct":0,"ask_ct":0},{"bid_px":null,"ask_px":null,"bid_sz":0,"ask_sz":0,"bid_ct":0,"ask_ct":0},{"bid_px":null,"ask_px":null,"bid_sz":0,"ask_sz":0,"bid_ct":0,"ask_ct":0},{"bid_px":null,"ask_px":null,"bid_sz":0,"ask_sz":0,"bid_ct":0,"ask_ct":0}],"symbol":"TSLA"}
{"ts_recv":"2024-11-01T08:00:00.960394963Z","hd":{"ts_event":"2024-11-01T08:00:00.960228634Z","rtype":10,"publisher_id":2,"instrument_id":16244},"action":"A","side":"B","depth":0,"price":"249.600000000","size":1000,"flags":130,"ts_in_delta":166329,"sequence":289123,"levels":[{"bid_px":"249.600000000","ask_px":"251.140000000","bid_sz":1000,"ask_sz":100,"bid_ct":1,"ask_ct":1},{"bid_px":"247.150000000","ask_px":"251.250000000","bid_sz":400,"ask_sz":50,"bid_ct":1,"ask_ct":1},{"bid_px":"235.000000000","ask_px":"252.400000000","bid_sz":100,"ask_sz":1000,"bid_ct":1,"ask_ct":1},{"bid_px":null,"ask_px":"253.650000000","bid_sz":0,"ask_sz":400,"bid_ct":0,"ask_ct":1},{"bid_px":null,"ask_px":"960.000000000","bid_sz":0,"ask_sz":25,"bid_ct":0,"ask_ct":1},{"bid_px":null,"ask_px":null,"bid_sz":0,"ask_sz":0,"bid_ct":0,"ask_ct":0},{"bid_px":null,"ask_px":null,"bid_sz":0,"ask_sz":0,"bid_ct":0,"ask_ct":0},{"bid_px":null,"ask_px":null,"bid_sz":0,"ask_sz":0,"bid_ct":0,"ask_ct":0},{"bid_px":null,"ask_px":null,"bid_sz":0,"ask_sz":0,"bid_ct":0,"ask_ct":0},{"bid_px":null,"ask_px":null,"bid_sz":0,"ask_sz":0,"bid_ct":0,"ask_ct":0}],"symbol":"TSLA"}
{"ts_recv":"2024-11-01T08:00:00.983216400Z","hd":{"ts_event":"2024-11-01T08:00:00.983050792Z","rtype":10,"publisher_id":2,"instrument_id":16244},"action":"C","side":"A","depth":1,"price":"251.250000000","size":50,"flags":130,"ts_in_delta":165608,"sequence":289185,"levels":[{"bid_px":"249.600000000","ask_px":"251.140000000","bid_sz":1000,"ask_sz":100,"bid_ct":1,"ask_ct":1},{"bid_px":"247.150000000","ask_px":"252.400000000","bid_sz":400,"ask_sz":1000,"bid_ct":1,"ask_ct":1},{"bid_px":"235.000000000","ask_px":"253.650000000","bid_sz":100,"ask_sz":400,"bid_ct":1,"ask_ct":1},{"bid_px":null,"ask_px":"960.000000000","bid_sz":0,"ask_sz":25,"bid_ct":0,"ask_ct":1},{"bid_px":null,"ask_px":null,"bid_sz":0,"ask_sz":0,"bid_ct":0,"ask_ct":0},{"bid_px":null,"ask_px":null,"bid_sz":0,"ask_sz":0,"bid_ct":0,"ask_ct":0},{"bid_px":null,"ask_px":null,"bid_sz":0,"ask_sz":0,"bid_ct":0,"ask_ct":0},{"bid_px":null,"ask_px":null,"bid_sz":0,"ask_sz":0,"bid_ct":0,"ask_ct":0},{"bid_px":null,"ask_px":null,"bid_sz":0,"ask_sz":0,"bid_ct":0,"ask_ct":0},{"bid_px":null,"ask_px":null,"bid_sz":0,"ask_sz":0,"bid_ct":0,"ask_ct":0}],"symbol":"TSLA"}
{"ts_recv":"2024-11-01T08:00:00.983229752Z","hd":{"ts_event":"2024-11-01T08:00:00.983063706Z","rtype":10,"publisher_id":2,"instrument_id":16244},"action":"A","side":"A","depth":1,"price":"251.280000000","size":50,"flags":130,"ts_in_delta":166046,"sequence":289186,"levels":[{"bid_px":"249.600000000","ask_px":"251.140000000","bid_sz":1000,"ask_sz":100,"bid_ct":1,"ask_ct":1},{"bid_px":"247.150000000","ask_px":"251.280000000","bid_sz":400,"ask_sz":50,"bid_ct":1,"ask_ct":1},{"bid_px":"235.000000000","ask_px":"252.400000000","bid_sz":100,"ask_sz":1000,"bid_ct":1,"ask_ct":1},{"bid_px":null,"ask_px":"253.650000000","bid_sz":0,"ask_sz":400,"bid_ct":0,"ask_ct":1},{"bid_px":null,"ask_px":"960.000000000","bid_sz":0,"ask_sz":25,"bid_ct":0,"ask_ct":1},{"bid_px":null,"ask_px":null,"bid_sz":0,"ask_sz":0,"bid_ct":0,"ask_ct":0},{"bid_px":null,"ask_px":null,"bid_sz":0,"ask_sz":0,"bid_ct":0,"ask_ct":0},{"bid_px":null,"ask_px":null,"bid_sz":0,"ask_sz":0,"bid_ct":0,"ask_ct":0},{"bid_px":null,"ask_px":null,"bid_sz":0,"ask_sz":0,"bid_ct":0,"ask_ct":0},{"bid_px":null,"ask_px":null,"bid_sz":0,"ask_sz":0,"bid_ct":0,"ask_ct":0}],"symbol":"TSLA"}
{"ts_recv":"2024-11-01T08:00:00.983312891Z","hd":{"ts_event":"2024-11-01T08:00:00.983147307Z","rtype":10,"publisher_id":2,"instrument_id":16244},"action":"C","side":"A","depth":1,"price":"251.280000000","size":50,"flags":130,"ts_in_delta":165584,"sequence":289187,"levels":[{"bid_px":"249.600000000","ask_px":"251.140000000","bid_sz":1000,"ask_sz":100,"bid_ct":1,"ask_ct":1},{"bid_px":"247.150000000","ask_px":"252.400000000","bid_sz":400,"ask_sz":1000,"bid_ct":1,"ask_ct":1},{"bid_px":"235.000000000","ask_px":"253.650000000","bid_sz":100,"ask_sz":400,"bid_ct":1,"ask_ct":1},{"bid_px":null,"ask_px":"960.000000000","bid_sz":0,"ask_sz":25,"bid_ct":0,"ask_ct":1},{"bid_px":null,"ask_px":null,"bid_sz":0,"ask_sz":0,"bid_ct":0,"ask_ct":0},{"bid_px":null,"ask_px":null,"bid_sz":0,"ask_sz":0,"bid_ct":0,"ask_ct":0},{"bid_px":null,"ask_px":null,"bid_sz":0,"ask_sz":0,"bid_ct":0,"ask_ct":0},{"bid_px":null,"ask_px":null,"bid_sz":0,"ask_sz":0,"bid_ct":0,"ask_ct":0},{"bid_px":null,"ask_px":null,"bid_sz":0,"ask_sz":0,"bid_ct":0,"ask_ct":0},{"bid_px":null,"ask_px":null,"bid_sz":0,"ask_sz":0,"bid_ct":0,"ask_ct":0}],"symbol":"TSLA"}
{"ts_recv":"2024-11-01T08:00:00.983325098Z","hd":{"ts_event":"2024-11-01T08:00:00.983159237Z","rtype":10,"publisher_id":2,"instrument_id":16244},"action":"A","side":"A","depth":1,"price":"251.300000000","size":50,"flags":130,"ts_in_delta":165861,"sequence":289188,"levels":[{"bid_px":"249.600000000","ask_px":"251.140000000","bid_sz":1000,"ask_sz":100,"bid_ct":1,"ask_ct":1},{"bid_px":"247.150000000","ask_px":"251.300000000","bid_sz":400,"ask_sz":50,"bid_ct":1,"ask_ct":1},{"bid_px":"235.000000000","ask_px":"252.400000000","bid_sz":100,"ask_sz":1000,"bid_ct":1,"ask_ct":1},{"bid_px":null,"ask_px":"253.650000000","bid_sz":0,"ask_sz":400,"bid_ct":0,"ask_ct":1},{"bid_px":null,"ask_px":"960.000000000","bid_sz":0,"ask_sz":25,"bid_ct":0,"ask_ct":1},{"bid_px":null,"ask_px":null,"bid_sz":0,"ask_sz":0,"bid_ct":0,"ask_ct":0},{"bid_px":null,"ask_px":null,"bid_sz":0,"ask_sz":0,"bid_ct":0,"ask_ct":0},{"bid_px":null,"ask_px":null,"bid_sz":0,"ask_sz":0,"bid_ct":0,"ask_ct":0},{"bid_px":null,"ask_px":null,"bid_sz":0,"ask_sz":0,"bid_ct":0,"ask_ct":0},{"bid_px":null,"ask_px":null,"bid_sz":0,"ask_sz":0,"bid_ct":0,"ask_ct":0}],"symbol":"TSLA"}
{"ts_recv":"2024-11-01T08:00:00.983364607Z","hd":{"ts_event":"2024-11-01T08:00:00.983198689Z","rtype":10,"publisher_id":2,"instrument_id":16244},"action":"C","side":"A","depth":1,"price":"251.300000000","size":50,"flags":130,"ts_in_delta":165918,"sequence":289189,"levels":[{"bid_px":"249.600000000","ask_px":"251.140000000","bid_sz":1000,"ask_sz":100,"bid_ct":1,"ask_ct":1},{"bid_px":"247.150000000","ask_px":"252.400000000","bid_sz":400,"ask_sz":1000,"bid_ct":1,"ask_ct":1},{"bid_px":"235.000000000","ask_px":"253.650000000","bid_sz":100,"ask_sz":400,"bid_ct":1,"ask_ct":1},{"bid_px":null,"ask_px":"960.000000000","bid_sz":0,"ask_sz":25,"bid_ct":0,"ask_ct":1},{"bid_px":null,"ask_px":null,"bid_sz":0,"ask_sz":0,"bid_ct":0,"ask_ct":0},{"bid_px":null,"ask_px":null,"bid_sz":0,"ask_sz":0,"bid_ct":0,"ask_ct":0},{"bid_px":null,"ask_px":null,"bid_sz":0,"ask_sz":0,"bid_ct":0,"ask_ct":0},{"bid_px":null,"ask_px":null,"bid_sz":0,"ask_sz":0,"bid_ct":0,"ask_ct":0},{"bid_px":null,"ask_px":null,"bid_sz":0,"ask_sz":0,"bid_ct":0,"ask_ct":0},{"bid_px":null,"ask_px":null,"bid_sz":0,"ask_sz":0,"bid_ct":0,"ask_ct":0}],"symbol":"TSLA"}
{"ts_recv":"2024-11-01T08:00:00.983459000Z","hd":{"ts_event":"2024-11-01T08:00:00.983292932Z","rtype":10,"publisher_id":2,"instrument_id":16244},"action":"A","side":"A","depth":1,"price":"251.490000000","size":50,"flags":130,"ts_in_delta":166068,"sequence":289190,"levels":[{"bid_px":"249.600000000","ask_px":"251.140000000","bid_sz":1000,"ask_sz":100,"bid_ct":1,"ask_ct":1},{"bid_px":"247.150000000","ask_px":"251.490000000","bid_sz":400,"ask_sz":50,"bid_ct":1,"ask_ct":1},{"bid_px":"235.000000000","ask_px":"252.400000000","bid_sz":100,"ask_sz":1000,"bid_ct":1,"ask_ct":1},{"bid_px":null,"ask_px":"253.650000000","bid_sz":0,"ask_sz":400,"bid_ct":0,"ask_ct":1},{"bid_px":null,"ask_px":"960.000000000","bid_sz":0,"ask_sz":25,"bid_ct":0,"ask_ct":1},{"bid_px":null,"ask_px":null,"bid_sz":0,"ask_sz":0,"bid_ct":0,"ask_ct":0},{"bid_px":null,"ask_px":null,"bid_sz":0,"ask_sz":0,"bid_ct":0,"ask_ct":0},{"bid_px":null,"ask_px":null,"bid_sz":0,"ask_sz":0,"bid_ct":0,"ask_ct":0},{"bid_px":null,"ask_px":null,"bid_sz":0,"ask_sz":0,"bid_ct":0,"ask_ct":0},{"bid_px":null,"ask_px":null,"bid_sz":0,"ask_sz":0,"bid_ct":0,"ask_ct":0}],"symbol":"TSLA"}
{"ts_recv":"2024-11-01T08:00:01.004277713Z","hd":{"ts_event":"2024-11-01T08:00:01.004111311Z","rtype":10,"publisher_id":2,"instrument_id":16244},"action":"A","side":"B","depth":0,"price":"249.700000000","size":1000,"flags":130,"ts_in_delta":166402,"sequence":289243,"levels":[{"bid_px":"249.700000000","ask_px":"251.140000000","bid_sz":1000,"ask_sz":100,"bid_ct":1,"ask_ct":1},{"bid_px":"249.600000000","ask_px":"251.490000000","bid_sz":1000,"ask_sz":50,"bid_ct":1,"ask_ct":1},{"bid_px":"247.150000000","ask_px":"252.400000000","bid_sz":400,"ask_sz":1000,"bid_ct":1,"ask_ct":1},{"bid_px":"235.000000000","ask_px":"253.650000000","bid_sz":100,"ask_sz":400,"bid_ct":1,"ask_ct":1},{"bid_px":null,"ask_px":"960.000000000","bid_sz":0,"ask_sz":25,"bid_ct":0,"ask_ct":1},{"bid_px":null,"ask_px":null,"bid_sz":0,"ask_sz":0,"bid_ct":0,"ask_ct":0},{"bid_px":null,"ask_px":null,"bid_sz":0,"ask_sz":0,"bid_ct":0,"ask_ct":0},{"bid_px":null,"ask_px":null,"bid_sz":0,"ask_sz":0,"bid_ct":0,"ask_ct":0},{"bid_px":null,"ask_px":null,"bid_sz":0,"ask_sz":0,"bid_ct":0,"ask_ct":0},{"bid_px":null,"ask_px":null,"bid_sz":0,"ask_sz":0,"bid_ct":0,"ask_ct":0}],"symbol":"TSLA"}
{"ts_recv":"2024-11-01T08:00:01.004489943Z","hd":{"ts_event":"2024-11-01T08:00:01.004324198Z","rtype":10,"publisher_id":2,"instrument_id":16244},"action":"C","side":"B","depth":1,"price":"249.600000000","size":1000,"flags":130,"ts_in_delta":165745,"sequence":289245,"levels":[{"bid_px":"249.700000000","ask_px":"251.140000000","bid_sz":1000,"ask_sz":100,"bid_ct":1,"ask_ct":1},{"bid_px":"247.150000000","ask_px":"251.490000000","bid_sz":400,"ask_sz":50,"bid_ct":1,"ask_ct":1},{"bid_px":"235.000000000","ask_px":"252.400000000","bid_sz":100,"ask_sz":1000,"bid_ct":1,"ask_ct":1},{"bid_px":null,"ask_px":"253.650000000","bid_sz":0,"ask_sz":400,"bid_ct":0,"ask_ct":1},{"bid_px":null,"ask_px":"960.000000000","bid_sz":0,"ask_sz":25,"bid_ct":0,"ask_ct":1},{"bid_px":null,"ask_px":null,"bid_sz":0,"ask_sz":0,"bid_ct":0,"ask_ct":0},{"bid_px":null,"ask_px":null,"bid_sz":0,"ask_sz":0,"bid_ct":0,"ask_ct":0},{"bid_px":null,"ask_px":null,"bid_sz":0,"ask_sz":0,"bid_ct":0,"ask_ct":0},{"bid_px":null,"ask_px":null,"bid_sz":0,"ask_sz":0,"bid_ct":0,"ask_ct":0},{"bid_px":null,"ask_px":null,"bid_sz":0,"ask_sz":0,"bid_ct":0,"ask_ct":0}],"symbol":"TSLA"}
{"ts_recv":"2024-11-01T08:00:01.059109773Z","hd":{"ts_event":"2024-11-01T08:00:01.058943966Z","rtype":10,"publisher_id":2,"instrument_id":16244},"action":"C","side":"B","depth":0,"price":"249.700000000","size":1000,"flags":130,"ts_in_delta":165807,"sequence":289424,"levels":[{"bid_px":"247.150000000","ask_px":"251.140000000","bid_sz":400,"ask_sz":100,"bid_ct":1,"ask_ct":1},{"bid_px":"235.000000000","ask_px":"251.490000000","bid_sz":100,"ask_sz":50,"bid_ct":1,"ask_ct":1},{"bid_px":null,"ask_px":"252.400000000","bid_sz":0,"ask_sz":1000,"bid_ct":0,"ask_ct":1},{"bid_px":null,"ask_px":"253.650000000","bid_sz":0,"ask_sz":400,"bid_ct":0,"ask_ct":1},{"bid_px":null,"ask_px":"960.000000000","bid_sz":0,"ask_sz":25,"bid_ct":0,"ask_ct":1},{"bid_px":null,"ask_px":null,"bid_sz":0,"ask_sz":0,"bid_ct":0,"ask_ct":0},{"bid_px":null,"ask_px":null,"bid_sz":0,"ask_sz":0,"bid_ct":0,"ask_ct":0},{"bid_px":null,"ask_px":null,"bid_sz":0,"ask_sz":0,"bid_ct":0,"ask_ct":0},{"bid_px":null,"ask_px":null,"bid_sz":0,"ask_sz":0,"bid_ct":0,"ask_ct":0},{"bid_px":null,"ask_px":null,"bid_sz":0,"ask_sz":0,"bid_ct":0,"ask_ct":0}],"symbol":"TSLA"}
{"ts_recv":"2024-11-01T08:00:01.094440542Z","hd":{"ts_event":"2024-11-01T08:00:01.094274556Z","rtype":10,"publisher_id":2,"instrument_id":16244},"action":"A","side":"B","depth":0,"price":"249.500000000","size":1000,"flags":130,"ts_in_delta":165986,"sequence":289532,"levels":[{"bid_px":"249.500000000","ask_px":"251.140000000","bid_sz":1000,"ask_sz":100,"bid_ct":1,"ask_ct":1},{"bid_px":"247.150000000","ask_px":"251.490000000","bid_sz":400,"ask_sz":50,"bid_ct":1,"ask_ct":1},{"bid_px":"235.000000000","ask_px":"252.400000000","bid_sz":100,"ask_sz":1000,"bid_ct":1,"ask_ct":1},{"bid_px":null,"ask_px":"253.650000000","bid_sz":0,"ask_sz":400,"bid_ct":0,"ask_ct":1},{"bid_px":null,"ask_px":"960.000000000","bid_sz":0,"ask_sz":25,"bid_ct":0,"ask_ct":1},{"bid_px":null,"ask_px":null,"bid_sz":0,"ask_sz":0,"bid_ct":0,"ask_ct":0},{"bid_px":null,"ask_px":null,"bid_sz":0,"ask_sz":0,"bid_ct":0,"ask_ct":0},{"bid_px":null,"ask_px":null,"bid_sz":0,"ask_sz":0,"bid_ct":0,"ask_ct":0},{"bid_px":null,"ask_px":null,"bid_sz":0,"ask_sz":0,"bid_ct":0,"ask_ct":0},{"bid_px":null,"ask_px":null,"bid_sz":0,"ask_sz":0,"bid_ct":0,"ask_ct":0}],"symbol":"TSLA"}
{"ts_recv":"2024-11-01T08:00:01.110332272Z","hd":{"ts_event":"2024-11-01T08:00:01.110166175Z","rtype":10,"publisher_id":2,"instrument_id":16244},"action":"A","side":"A","depth":1,"price":"251.490000000","size":50,"flags":130,"ts_in_delta":166097,"sequence":289565,"levels":[{"bid_px":"249.500000000","ask_px":"251.140000000","bid_sz":1000,"ask_sz":100,"bid_ct":1,"ask_ct":1},{"bid_px":"247.150000000","ask_px":"251.490000000","bid_sz":400,"ask_sz":100,"bid_ct":1,"ask_ct":2},{"bid_px":"235.000000000","ask_px":"252.400000000","bid_sz":100,"ask_sz":1000,"bid_ct":1,"ask_ct":1},{"bid_px":null,"ask_px":"253.650000000","bid_sz":0,"ask_sz":400,"bid_ct":0,"ask_ct":1},{"bid_px":null,"ask_px":"960.000000000","bid_sz":0,"ask_sz":25,"bid_ct":0,"ask_ct":1},{"bid_px":null,"ask_px":null,"bid_sz":0,"ask_sz":0,"bid_ct":0,"ask_ct":0},{"bid_px":null,"ask_px":null,"bid_sz":0,"ask_sz":0,"bid_ct":0,"ask_ct":0},{"bid_px":null,"ask_px":null,"bid_sz":0,"ask_sz":0,"bid_ct":0,"ask_ct":0},{"bid_px":null,"ask_px":null,"bid_sz":0,"ask_sz":0,"bid_ct":0,"ask_ct":0},{"bid_px":null,"ask_px":null,"bid_sz":0,"ask_sz":0,"bid_ct":0,"ask_ct":0}],"symbol":"TSLA"}
{"ts_recv":"2024-11-01T08:00:01.116734144Z","hd":{"ts_event":"2024-11-01T08:00:01.116568271Z","rtype":10,"publisher_id":2,"instrument_id":16244},"action":"C","side":"A","depth":1,"price":"251.490000000","size":50,"flags":130,"ts_in_delta":165873,"sequence":289574,"levels":[{"bid_px":"249.500000000","ask_px":"251.140000000","bid_sz":1000,"ask_sz":100,"bid_ct":1,"ask_ct":1},{"bid_px":"247.150000000","ask_px":"251.490000000","bid_sz":400,"ask_sz":50,"bid_ct":1,"ask_ct":1},{"bid_px":"235.000000000","ask_px":"252.400000000","bid_sz":100,"ask_sz":1000,"bid_ct":1,"ask_ct":1},{"bid_px":null,"ask_px":"253.650000000","bid_sz":0,"ask_sz":400,"bid_ct":0,"ask_ct":1},{"bid_px":null,"ask_px":"960.000000000","bid_sz":0,"ask_sz":25,"bid_ct":0,"ask_ct":1},{"bid_px":null,"ask_px":null,"bid_sz":0,"ask_sz":0,"bid_ct":0,"ask_ct":0},{"bid_px":null,"ask_px":null,"bid_sz":0,"ask_sz":0,"bid_ct":0,"ask_ct":0},{"bid_px":null,"ask_px":null,"bid_sz":0,"ask_sz":0,"bid_ct":0,"ask_ct":0},{"bid_px":null,"ask_px":null,"bid_sz":0,"ask_sz":0,"bid_ct":0,"ask_ct":0},{"bid_px":null,"ask_px":null,"bid_sz":0,"ask_sz":0,"bid_ct":0,"ask_ct":0}],"symbol":"TSLA"}
{"ts_recv":"2024-11-01T08:00:01.116754577Z","hd":{"ts_event":"2024-11-01T08:00:01.116588527Z","rtype":10,"publisher_id":2,"instrument_id":16244},"action":"A","side":"A","depth":1,"price":"251.480000000","size":100,"flags":130,"ts_in_delta":166050,"sequence":289575,"levels":[{"bid_px":"249.500000000","ask_px":"251.140000000","bid_sz":1000,"ask_sz":100,"bid_ct":1,"ask_ct":1},{"bid_px":"247.150000000","ask_px":"251.480000000","bid_sz":400,"ask_sz":100,"bid_ct":1,"ask_ct":1},{"bid_px":"235.000000000","ask_px":"252.400000000","bid_sz":100,"ask_sz":1000,"bid_ct":1,"ask_ct":1},{"bid_px":null,"ask_px":"253.650000000","bid_sz":0,"ask_sz":400,"bid_ct":0,"ask_ct":1},{"bid_px":null,"ask_px":"960.000000000","bid_sz":0,"ask_sz":25,"bid_ct":0,"ask_ct":1},{"bid_px":null,"ask_px":null,"bid_sz":0,"ask_sz":0,"bid_ct":0,"ask_ct":0},{"bid_px":null,"ask_px":null,"bid_sz":0,"ask_sz":0,"bid_ct":0,"ask_ct":0},{"bid_px":null,"ask_px":null,"bid_sz":0,"ask_sz":0,"bid_ct":0,"ask_ct":0},{"bid_px":null,"ask_px":null,"bid_sz":0,"ask_sz":0,"bid_ct":0,"ask_ct":0},{"bid_px":null,"ask_px":null,"bid_sz":0,"ask_sz":0,"bid_ct":0,"ask_ct":0}],"symbol":"TSLA"}
{"ts_recv":"2024-11-01T08:00:01.137385846Z","hd":{"ts_event":"2024-11-01T08:00:01.137219880Z","rtype":10,"publisher_id":2,"instrument_id":16244},"action":"A","side":"B","depth":0,"price":"249.600000000","size":1000,"flags":130,"ts_in_delta":165966,"sequence":289595,"levels":[{"bid_px":"249.600000000","ask_px":"251.140000000","bid_sz":1000,"ask_sz":100,"bid_ct":1,"ask_ct":1},{"bid_px":"249.500000000","ask_px":"251.480000000","bid_sz":1000,"ask_sz":100,"bid_ct":1,"ask_ct":1},{"bid_px":"247.150000000","ask_px":"252.400000000","bid_sz":400,"ask_sz":1000,"bid_ct":1,"ask_ct":1},{"bid_px":"235.000000000","ask_px":"253.650000000","bid_sz":100,"ask_sz":400,"bid_ct":1,"ask_ct":1},{"bid_px":null,"ask_px":"960.000000000","bid_sz":0,"ask_sz":25,"bid_ct":0,"ask_ct":1},{"bid_px":null,"ask_px":null,"bid_sz":0,"ask_sz":0,"bid_ct":0,"ask_ct":0},{"bid_px":null,"ask_px":null,"bid_sz":0,"ask_sz":0,"bid_ct":0,"ask_ct":0},{"bid_px":null,"ask_px":null,"bid_sz":0,"ask_sz":0,"bid_ct":0,"ask_ct":0},{"bid_px":null,"ask_px":null,"bid_sz":0,"ask_sz":0,"bid_ct":0,"ask_ct":0},{"bid_px":null,"ask_px":null,"bid_sz":0,"ask_sz":0,"bid_ct":0,"ask_ct":0}],"symbol":"TSLA"}
{"ts_recv":"2024-11-01T08:00:01.137488602Z","hd":{"ts_event":"2024-11-01T08:00:01.137322871Z","rtype":10,"publisher_id":2,"instrument_id":16244},"action":"C","side":"B","depth":1,"price":"249.500000000","size":1000,"flags":130,"ts_in_delta":165731,"sequence":289596,"levels":[{"bid_px":"249.600000000","ask_px":"251.140000000","bid_sz":1000,"ask_sz":100,"bid_ct":1,"ask_ct":1},{"bid_px":"247.150000000","ask_px":"251.480000000","bid_sz":400,"ask_sz":100,"bid_ct":1,"ask_ct":1},{"bid_px":"235.000000000","ask_px":"252.400000000","bid_sz":100,"ask_sz":1000,"bid_ct":1,"ask_ct":1},{"bid_px":null,"ask_px":"253.650000000","bid_sz":0,"ask_sz":400,"bid_ct":0,"ask_ct":1},{"bid_px":null,"ask_px":"960.000000000","bid_sz":0,"ask_sz":25,"bid_ct":0,"ask_ct":1},{"bid_px":null,"ask_px":null,"bid_sz":0,"ask_sz":0,"bid_ct":0,"ask_ct":0},{"bid_px":null,"ask_px":null,"bid_sz":0,"ask_sz":0,"bid_ct":0,"ask_ct":0},{"bid_px":null,"ask_px":null,"bid_sz":0,"ask_sz":0,"bid_ct":0,"ask_ct":0},{"bid_px":null,"ask_px":null,"bid_sz":0,"ask_sz":0,"bid_ct":0,"ask_ct":0},{"bid_px":null,"ask_px":null,"bid_sz":0,"ask_sz":0,"bid_ct":0,"ask_ct":0}],"symbol":"TSLA"}
{"ts_recv":"2024-11-01T08:00:01.155279986Z","hd":{"ts_event":"2024-11-01T08:00:01.155114036Z","rtype":10,"publisher_id":2,"instrument_id":16244},"action":"C","side":"A","depth":1,"price":"251.480000000","size":50,"flags":130,"ts_in_delta":165950,"sequence":289634,"levels":[{"bid_px":"249.600000000","ask_px":"251.140000000","bid_sz":1000,"ask_sz":100,"bid_ct":1,"ask_ct":1},{"bid_px":"247.150000000","ask_px":"251.480000000","bid_sz":400,"ask_sz":50,"bid_ct":1,"ask_ct":1},{"bid_px":"235.000000000","ask_px":"252.400000000","bid_sz":100,"ask_sz":1000,"bid_ct":1,"ask_ct":1},{"bid_px":null,"ask_px":"253.650000000","bid_sz":0,"ask_sz":400,"bid_ct":0,"ask_ct":1},{"bid_px":null,"ask_px":"960.000000000","bid_sz":0,"ask_sz":25,"bid_ct":0,"ask_ct":1},{"bid_px":null,"ask_px":null,"bid_sz":0,"ask_sz":0,"bid_ct":0,"ask_ct":0},{"bid_px":null,"ask_px":null,"bid_sz":0,"ask_sz":0,"bid_ct":0,"ask_ct":0},{"bid_px":null,"ask_px":null,"bid_sz":0,"ask_sz":0,"bid_ct":0,"ask_ct":0},{"bid_px":null,"ask_px":null,"bid_sz":0,"ask_sz":0,"bid_ct":0,"ask_ct":0},{"bid_px":null,"ask_px":null,"bid_sz":0,"ask_sz":0,"bid_ct":0,"ask_ct":0}],"symbol":"TSLA"}
{"ts_recv":"2024-11-01T08:00:01.164347156Z","hd":{"ts_event":"2024-11-01T08:00:01.164180860Z","rtype":10,"publisher_id":2,"instrument_id":16244},"action":"A","side":"A","depth":1,"price":"251.440000000","size":50,"flags":130,"ts_in_delta":166296,"sequence":289643,"levels":[{"bid_px":"249.600000000","ask_px":"251.140000000","bid_sz":1000,"ask_sz":100,"bid_ct":1,"ask_ct":1},{"bid_px":"247.150000000","ask_px":"251.440000000","bid_sz":400,"ask_sz":50,"bid_ct":1,"ask_ct":1},{"bid_px":"235.000000000","ask_px":"252.400000000","bid_sz":100,"ask_sz":1000,"bid_ct":1,"ask_ct":1},{"bid_px":null,"ask_px":"253.650000000","bid_sz":0,"ask_sz":400,"bid_ct":0,"ask_ct":1},{"bid_px":null,"ask_px":"960.000000000","bid_sz":0,"ask_sz":25,"bid_ct":0,"ask_ct":1},{"bid_px":null,"ask_px":null,"bid_sz":0,"ask_sz":0,"bid_ct":0,"ask_ct":0},{"bid_px":null,"ask_px":null,"bid_sz":0,"ask_sz":0,"bid_ct":0,"ask_ct":0},{"bid_px":null,"ask_px":null,"bid_sz":0,"ask_sz":0,"bid_ct":0,"ask_ct":0},{"bid_px":null,"ask_px":null,"bid_sz":0,"ask_sz":0,"bid_ct":0,"ask_ct":0},{"bid_px":null,"ask_px":null,"bid_sz":0,"ask_sz":0,"bid_ct":0,"ask_ct":0}],"symbol":"TSLA"}
{"ts_recv":"2024-11-01T08:00:01.174029238Z","hd":{"ts_event":"2024-11-01T08:00:01.173863038Z","rtype":10,"publisher_id":2,"instrument_id":16244},"action":"A","side":"B","depth":0,"price":"250.240000000","size":50,"flags":130,"ts_in_delta":166200,"sequence":289666,"levels":[{"bid_px":"250.240000000","ask_px":"251.140000000","bid_sz":50,"ask_sz":100,"bid_ct":1,"ask_ct":1},{"bid_px":"249.600000000","ask_px":"251.440000000","bid_sz":1000,"ask_sz":50,"bid_ct":1,"ask_ct":1},{"bid_px":"247.150000000","ask_px":"252.400000000","bid_sz":400,"ask_sz":1000,"bid_ct":1,"ask_ct":1},{"bid_px":"235.000000000","ask_px":"253.650000000","bid_sz":100,"ask_sz":400,"bid_ct":1,"ask_ct":1},{"bid_px":null,"ask_px":"960.000000000","bid_sz":0,"ask_sz":25,"bid_ct":0,"ask_ct":1},{"bid_px":null,"ask_px":null,"bid_sz":0,"ask_sz":0,"bid_ct":0,"ask_ct":0},{"bid_px":null,"ask_px":null,"bid_sz":0,"ask_sz":0,"bid_ct":0,"ask_ct":0},{"bid_px":null,"ask_px":null,"bid_sz":0,"ask_sz":0,"bid_ct":0,"ask_ct":0},{"bid_px":null,"ask_px":null,"bid_sz":0,"ask_sz":0,"bid_ct":0,"ask_ct":0},{"bid_px":null,"ask_px":null,"bid_sz":0,"ask_sz":0,"bid_ct":0,"ask_ct":0}],"symbol":"TSLA"}
{"ts_recv":"2024-11-01T08:00:01.194416923Z","hd":{"ts_event":"2024-11-01T08:00:01.194251316Z","rtype":10,"publisher_id":2,"instrument_id":16244},"action":"C","side":"A","depth":1,"price":"251.440000000","size":50,"flags":130,"ts_in_delta":165607,"sequence":289700,"levels":[{"bid_px":"250.240000000","ask_px":"251.140000000","bid_sz":50,"ask_sz":100,"bid_ct":1,"ask_ct":1},{"bid_px":"249.600000000","ask_px":"252.400000000","bid_sz":1000,"ask_sz":1000,"bid_ct":1,"ask_ct":1},{"bid_px":"247.150000000","ask_px":"253.650000000","bid_sz":400,"ask_sz":400,"bid_ct":1,"ask_ct":1},{"bid_px":"235.000000000","ask_px":"960.000000000","bid_sz":100,"ask_sz":25,"bid_ct":1,"ask_ct":1},{"bid_px":null,"ask_px":null,"bid_sz":0,"ask_sz":0,"bid_ct":0,"ask_ct":0},{"bid_px":null,"ask_px":null,"bid_sz":0,"ask_sz":0,"bid_ct":0,"ask_ct":0},{"bid_px":null,"ask_px":null,"bid_sz":0,"ask_sz":0,"bid_ct":0,"ask_ct":0},{"bid_px":null,"ask_px":null,"bid_sz":0,"ask_sz":0,"bid_ct":0,"ask_ct":0},{"bid_px":null,"ask_px":null,"bid_sz":0,"ask_sz":0,"bid_ct":0,"ask_ct":0},{"bid_px":null,"ask_px":null,"bid_sz":0,"ask_sz":0,"bid_ct":0,"ask_ct":0}],"symbol":"TSLA"}
{"ts_recv":"2024-11-01T08:00:01.194428947Z","hd":{"ts_event":"2024-11-01T08:00:01.194262835Z","rtype":10,"publisher_id":2,"instrument_id":16244},"action":"A","side":"A","depth":1,"price":"251.490000000","size":50,"flags":130,"ts_in_delta":166112,"sequence":289701,"levels":[{"bid_px":"250.240000000","ask_px":"251.140000000","bid_sz":50,"ask_sz":100,"bid_ct":1,"ask_ct":1},{"bid_px":"249.600000000","ask_px":"251.490000000","bid_sz":1000,"ask_sz":50,"bid_ct":1,"ask_ct":1},{"bid_px":"247.150000000","ask_px":"252.400000000","bid_sz":400,"ask_sz":1000,"bid_ct":1,"ask_ct":1},{"bid_px":"235.000000000","ask_px":"253.650000000","bid_sz":100,"ask_sz":400,"bid_ct":1,"ask_ct":1},{"bid_px":null,"ask_px":"960.000000000","bid_sz":0,"ask_sz":25,"bid_ct":0,"ask_ct":1},{"bid_px":null,"ask_px":null,"bid_sz":0,"ask_sz":0,"bid_ct":0,"ask_ct":0},{"bid_px":null,"ask_px":null,"bid_sz":0,"ask_sz":0,"bid_ct":0,"ask_ct":0},{"bid_px":null,"ask_px":null,"bid_sz":0,"ask_sz":0,"bid_ct":0,"ask_ct":0},{"bid_px":null,"ask_px":null,"bid_sz":0,"ask_sz":0,"bid_ct":0,"ask_ct":0},{"bid_px":null,"ask_px":null,"bid_sz":0,"ask_sz":0,"bid_ct":0,"ask_ct":0}],"symbol":"TSLA"}
{"ts_recv":"2024-11-01T08:00:01.198788725Z","hd":{"ts_event":"2024-11-01T08:00:01.198623132Z","rtype":10,"publisher_id":2,"instrument_id":16244},"action":"C","side":"B","depth":1,"price":"249.600000000","size":1000,"flags":130,"ts_in_delta":165593,"sequence":289709,"levels":[{"bid_px":"250.240000000","ask_px":"251.140000000","bid_sz":50,"ask_sz":100,"bid_ct":1,"ask_ct":1},{"bid_px":"247.150000000","ask_px":"251.490000000","bid_sz":400,"ask_sz":50,"bid_ct":1,"ask_ct":1},{"bid_px":"235.000000000","ask_px":"252.400000000","bid_sz":100,"ask_sz":1000,"bid_ct":1,"ask_ct":1},{"bid_px":null,"ask_px":"253.650000000","bid_sz":0,"ask_sz":400,"bid_ct":0,"ask_ct":1},{"bid_px":null,"ask_px":"960.000000000","bid_sz":0,"ask_sz":25,"bid_ct":0,"ask_ct":1},{"bid_px":null,"ask_px":null,"bid_sz":0,"ask_sz":0,"bid_ct":0,"ask_ct":0},{"bid_px":null,"ask_px":null,"bid_sz":0,"ask_sz":0,"bid_ct":0,"ask_ct":0},{"bid_px":null,"ask_px":null,"bid_sz":0,"ask_sz":0,"bid_ct":0,"ask_ct":0},{"bid_px":null,"ask_px":null,"bid_sz":0,"ask_sz":0,"bid_ct":0,"ask_ct":0},{"bid_px":null,"ask_px":null,"bid_sz":0,"ask_sz":0,"bid_ct":0,"ask_ct":0}],"symbol":"TSLA"}
{"ts_recv":"2024-11-01T08:00:01.210385512Z","hd":{"ts_event":"2024-11-01T08:00:01.210218950Z","rtype":10,"publisher_id":2,"instrument_id":16244},"action":"A","side":"B","depth":1,"price":"249.100000000","size":1000,"flags":130,"ts_in_delta":166562,"sequence":289727,"levels":[{"bid_px":"250.240000000","ask_px":"251.140000000","bid_sz":50,"ask_sz":100,"bid_ct":1,"ask_ct":1},{"bid_px":"249.100000000","ask_px":"251.490000000","bid_sz":1000,"ask_sz":50,"bid_ct":1,"ask_ct":1},{"bid_px":"247.150000000","ask_px":"252.400000000","bid_sz":400,"ask_sz":1000,"bid_ct":1,"ask_ct":1},{"bid_px":"235.000000000","ask_px":"253.650000000","bid_sz":100,"ask_sz":400,"bid_ct":1,"ask_ct":1},{"bid_px":null,"ask_px":"960.000000000","bid_sz":0,"ask_sz":25,"bid_ct":0,"ask_ct":1},{"bid_px":null,"ask_px":null,"bid_sz":0,"ask_sz":0,"bid_ct":0,"ask_ct":0},{"bid_px":null,"ask_px":null,"bid_sz":0,"ask_sz":0,"bid_ct":0,"ask_ct":0},{"bid_px":null,"ask_px":null,"bid_sz":0,"ask_sz":0,"bid_ct":0,"ask_ct":0},{"bid_px":null,"ask_px":null,"bid_sz":0,"ask_sz":0,"bid_ct":0,"ask_ct":0},{"bid_px":null,"ask_px":null,"bid_sz":0,"ask_sz":0,"bid_ct":0,"ask_ct":0}],"symbol":"TSLA"}
{"ts_recv":"2024-11-01T08:00:01.251765817Z","hd":{"ts_event":"2024-11-01T08:00:01.251599819Z","rtype":10,"publisher_id":2,"instrument_id":16244},"action":"A","side":"B","depth":0,"price":"250.250000000","size":50,"flags":130,"ts_in_delta":165998,"sequence":289765,"levels":[{"bid_px":"250.250000000","ask_px":"251.140000000","bid_sz":50,"ask_sz":100,"bid_ct":1,"ask_ct":1},{"bid_px":"249.100000000","ask_px":"251.490000000","bid_sz":1000,"ask_sz":50,"bid_ct":1,"ask_ct":1},{"bid_px":"247.150000000","ask_px":"252.400000000","bid_sz":400,"ask_sz":1000,"bid_ct":1,"ask_ct":1},{"bid_px":"235.000000000","ask_px":"253.650000000","bid_sz":100,"ask_sz":400,"bid_ct":1,"ask_ct":1},{"bid_px":null,"ask_px":"960.000000000","bid_sz":0,"ask_sz":25,"bid_ct":0,"ask_ct":1},{"bid_px":null,"ask_px":null,"bid_sz":0,"ask_sz":0,"bid_ct":0,"ask_ct":0},{"bid_px":null,"ask_px":null,"bid_sz":0,"ask_sz":0,"bid_ct":0,"ask_ct":0},{"bid_px":null,"ask_px":null,"bid_sz":0,"ask_sz":0,"bid_ct":0,"ask_ct":0},{"bid_px":null,"ask_px":null,"bid_sz":0,"ask_sz":0,"bid_ct":0,"ask_ct":0},{"bid_px":null,"ask_px":null,"bid_sz":0,"ask_sz":0,"bid_ct":0,"ask_ct":0}],"symbol":"TSLA"}
{"ts_recv":"2024-11-01T08:00:01.251881540Z","hd":{"ts_event":"2024-11-01T08:00:01.251715874Z","rtype":10,"publisher_id":2,"instrument_id":16244},"action":"C","side":"A","depth":1,"price":"251.490000000","size":50,"flags":130,"ts_in_delta":165666,"sequence":289767,"levels":[{"bid_px":"250.250000000","ask_px":"251.140000000","bid_sz":50,"ask_sz":100,"bid_ct":1,"ask_ct":1},{"bid_px":"249.100000000","ask_px":"252.400000000","bid_sz":1000,"ask_sz":1000,"bid_ct":1,"ask_ct":1},{"bid_px":"247.150000000","ask_px":"253.650000000","bid_sz":400,"ask_sz":400,"bid_ct":1,"ask_ct":1},{"bid_px":"235.000000000","ask_px":"960.000000000","bid_sz":100,"ask_sz":25,"bid_ct":1,"ask_ct":1},{"bid_px":null,"ask_px":null,"bid_sz":0,"ask_sz":0,"bid_ct":0,"ask_ct":0},{"bid_px":null,"ask_px":null,"bid_sz":0,"ask_sz":0,"bid_ct":0,"ask_ct":0},{"bid_px":null,"ask_px":null,"bid_sz":0,"ask_sz":0,"bid_ct":0,"ask_ct":0},{"bid_px":null,"ask_px":null,"bid_sz":0,"ask_sz":0,"bid_ct":0,"ask_ct":0},{"bid_px":null,"ask_px":null,"bid_sz":0,"ask_sz":0,"bid_ct":0,"ask_ct":0},{"bid_px":null,"ask_px":null,"bid_sz":0,"ask_sz":0,"bid_ct":0,"ask_ct":0}],"symbol":"TSLA"}
{"ts_recv":"2024-11-01T08:00:01.257626533Z","hd":{"ts_event":"2024-11-01T08:00:01.257461044Z","rtype":10,"publisher_id":2,"instrument_id":16244},"action":"C","side":"B","depth":0,"price":"250.250000000","size":50,"flags":130,"ts_in_delta":165489,"sequence":289773,"levels":[{"bid_px":"249.100000000","ask_px":"251.140000000","bid_sz":1000,"ask_sz":100,"bid_ct":1,"ask_ct":1},{"bid_px":"247.150000000","ask_px":"252.400000000","bid_sz":400,"ask_sz":1000,"bid_ct":1,"ask_ct":1},{"bid_px":"235.000000000","ask_px":"253.650000000","bid_sz":100,"ask_sz":400,"bid_ct":1,"ask_ct":1},{"bid_px":null,"ask_px":"960.000000000","bid_sz":0,"ask_sz":25,"bid_ct":0,"ask_ct":1},{"bid_px":null,"ask_px":null,"bid_sz":0,"ask_sz":0,"bid_ct":0,"ask_ct":0},{"bid_px":null,"ask_px":null,"bid_sz":0,"ask_sz":0,"bid_ct":0,"ask_ct":0},{"bid_px":null,"ask_px":null,"bid_sz":0,"ask_sz":0,"bid_ct":0,"ask_ct":0},{"bid_px":null,"ask_px":null,"bid_sz":0,"ask_sz":0,"bid_ct":0,"ask_ct":0},{"bid_px":null,"ask_px":null,"bid_sz":0,"ask_sz":0,"bid_ct":0,"ask_ct":0},{"bid_px":null,"ask_px":null,"bid_sz":0,"ask_sz":0,"bid_ct":0,"ask_ct":0}],"symbol":"TSLA"}
{"ts_recv":"2024-11-01T08:00:01.257640258Z","hd":{"ts_event":"2024-11-01T08:00:01.257474236Z","rtype":10,"publisher_id":2,"instrument_id":16244},"action":"A","side":"B","depth":0,"price":"250.180000000","size":50,"flags":130,"ts_in_delta":166022,"sequence":289774,"levels":[{"bid_px":"250.180000000","ask_px":"251.140000000","bid_sz":50,"ask_sz":100,"bid_ct":1,"ask_ct":1},{"bid_px":"249.100000000","ask_px":"252.400000000","bid_sz":1000,"ask_sz":1000,"bid_ct":1,"ask_ct":1},{"bid_px":"247.150000000","ask_px":"253.650000000","bid_sz":400,"ask_sz":400,"bid_ct":1,"ask_ct":1},{"bid_px":"235.000000000","ask_px":"960.000000000","bid_sz":100,"ask_sz":25,"bid_ct":1,"ask_ct":1},{"bid_px":null,"ask_px":null,"bid_sz":0,"ask_sz":0,"bid_ct":0,"ask_ct":0},{"bid_px":null,"ask_px":null,"bid_sz":0,"ask_sz":0,"bid_ct":0,"ask_ct":0},{"bid_px":null,"ask_px":null,"bid_sz":0,"ask_sz":0,"bid_ct":0,"ask_ct":0},{"bid_px":null,"ask_px":null,"bid_sz":0,"ask_sz":0,"bid_ct":0,"ask_ct":0},{"bid_px":null,"ask_px":null,"bid_sz":0,"ask_sz":0,"bid_ct":0,"ask_ct":0},{"bid_px":null,"ask_px":null,"bid_sz":0,"ask_sz":0,"bid_ct":0,"ask_ct":0}],"symbol":"TSLA"}
{"ts_recv":"2024-11-01T08:00:01.257711873Z","hd":{"ts_event":"2024-11-01T08:00:01.257546474Z","rtype":10,"publisher_id":2,"instrument_id":16244},"action":"C","side":"B","depth":0,"price":"250.180000000","size":50,"flags":130,"ts_in_delta":165399,"sequence":289776,"levels":[{"bid_px":"249.100000000","ask_px":"251.140000000","bid_sz":1000,"ask_sz":100,"bid_ct":1,"ask_ct":1},{"bid_px":"247.150000000","ask_px":"252.400000000","bid_sz":400,"ask_sz":1000,"bid_ct":1,"ask_ct":1},{"bid_px":"235.000000000","ask_px":"253.650000000","bid_sz":100,"ask_sz":400,"bid_ct":1,"ask_ct":1},{"bid_px":null,"ask_px":"960.000000000","bid_sz":0,"ask_sz":25,"bid_ct":0,"ask_ct":1},{"bid_px":null,"ask_px":null,"bid_sz":0,"ask_sz":0,"bid_ct":0,"ask_ct":0},{"bid_px":null,"ask_px":null,"bid_sz":0,"ask_sz":0,"bid_ct":0,"ask_ct":0},{"bid_px":null,"ask_px":null,"bid_sz":0,"ask_sz":0,"bid_ct":0,"ask_ct":0},{"bid_px":null,"ask_px":null,"bid_sz":0,"ask_sz":0,"bid_ct":0,"ask_ct":0},{"bid_px":null,"ask_px":null,"bid_sz":0,"ask_sz":0,"bid_ct":0,"ask_ct":0},{"bid_px":null,"ask_px":null,"bid_sz":0,"ask_sz":0,"bid_ct":0,"ask_ct":0}],"symbol":"TSLA"}
{"ts_recv":"2024-11-01T08:00:01.260575799Z","hd":{"ts_event":"2024-11-01T08:00:01.260409723Z","rtype":10,"publisher_id":2,"instrument_id":16244},"action":"A","side":"B","depth":0,"price":"249.400000000","size":1000,"flags":130,"ts_in_delta":166076,"sequence":289780,"levels":[{"bid_px":"249.400000000","ask_px":"251.140000000","bid_sz":1000,"ask_sz":100,"bid_ct":1,"ask_ct":1},{"bid_px":"249.100000000","ask_px":"252.400000000","bid_sz":1000,"ask_sz":1000,"bid_ct":1,"ask_ct":1},{"bid_px":"247.150000000","ask_px":"253.650000000","bid_sz":400,"ask_sz":400,"bid_ct":1,"ask_ct":1},{"bid_px":"235.000000000","ask_px":"960.000000000","bid_sz":100,"ask_sz":25,"bid_ct":1,"ask_ct":1},{"bid_px":null,"ask_px":null,"bid_sz":0,"ask_sz":0,"bid_ct":0,"ask_ct":0},{"bid_px":null,"ask_px":null,"bid_sz":0,"ask_sz":0,"bid_ct":0,"ask_ct":0},{"bid_px":null,"ask_px":null,"bid_sz":0,"ask_sz":0,"bid_ct":0,"ask_ct":0},{"bid_px":null,"ask_px":null,"bid_sz":0,"ask_sz":0,"bid_ct":0,"ask_ct":0},{"bid_px":null,"ask_px":null,"bid_sz":0,"ask_sz":0,"bid_ct":0,"ask_ct":0},{"bid_px":null,"ask_px":null,"bid_sz":0,"ask_sz":0,"bid_ct":0,"ask_ct":0}],"symbol":"TSLA"}
{"ts_recv":"2024-11-01T08:00:01.260754015Z","hd":{"ts_event":"2024-11-01T08:00:01.260588405Z","rtype":10,"publisher_id":2,"instrument_id":16244},"action":"C","side":"B","depth":1,"price":"249.100000000","size":1000,"flags":130,"ts_in_delta":165610,"sequence":289784,"levels":[{"bid_px":"249.400000000","ask_px":"251.140000000","bid_sz":1000,"ask_sz":100,"bid_ct":1,"ask_ct":1},{"bid_px":"247.150000000","ask_px":"252.400000000","bid_sz":400,"ask_sz":1000,"bid_ct":1,"ask_ct":1},{"bid_px":"235.000000000","ask_px":"253.650000000","bid_sz":100,"ask_sz":400,"bid_ct":1,"ask_ct":1},{"bid_px":null,"ask_px":"960.000000000","bid_sz":0,"ask_sz":25,"bid_ct":0,"ask_ct":1},{"bid_px":null,"ask_px":null,"bid_sz":0,"ask_sz":0,"bid_ct":0,"ask_ct":0},{"bid_px":null,"ask_px":null,"bid_sz":0,"ask_sz":0,"bid_ct":0,"ask_ct":0},{"bid_px":null,"ask_px":null,"bid_sz":0,"ask_sz":0,"bid_ct":0,"ask_ct":0},{"bid_px":null,"ask_px":null,"bid_sz":0,"ask_sz":0,"bid_ct":0,"ask_ct":0},{"bid_px":null,"ask_px":null,"bid_sz":0,"ask_sz":0,"bid_ct":0,"ask_ct":0},{"bid_px":null,"ask_px":null,"bid_sz":0,"ask_sz":0,"bid_ct":0,"ask_ct":0}],"symbol":"TSLA"}
{"ts_recv":"2024-11-01T08:00:01.299802595Z","hd":{"ts_event":"2024-11-01T08:00:01.299636583Z","rtype":10,"publisher_id":2,"instrument_id":16244},"action":"A","side":"B","depth":0,"price":"249.500000000","size":1000,"flags":130,"ts_in_delta":166012,"sequence":289822,"levels":[{"bid_px":"249.500000000","ask_px":"251.140000000","bid_sz":1000,"ask_sz":100,"bid_ct":1,"ask_ct":1},{"bid_px":"249.400000000","ask_px":"252.400000000","bid_sz":1000,"ask_sz":1000,"bid_ct":1,"ask_ct":1},{"bid_px":"247.150000000","ask_px":"253.650000000","bid_sz":400,"ask_sz":400,"bid_ct":1,"ask_ct":1},{"bid_px":"235.000000000","ask_px":"960.000000000","bid_sz":100,"ask_sz":25,"bid_ct":1,"ask_ct":1},{"bid_px":null,"ask_px":null,"bid_sz":0,"ask_sz":0,"bid_ct":0,"ask_ct":0},{"bid_px":null,"ask_px":null,"bid_sz":0,"ask_sz":0,"bid_ct":0,"ask_ct":0},{"bid_px":null,"ask_px":null,"bid_sz":0,"ask_sz":0,"bid_ct":0,"ask_ct":0},{"bid_px":null,"ask_px":null,"bid_sz":0,"ask_sz":0,"bid_ct":0,"ask_ct":0},{"bid_px":null,"ask_px":null,"bid_sz":0,"ask_sz":0,"bid_ct":0,"ask_ct":0},{"bid_px":null,"ask_px":null,"bid_sz":0,"ask_sz":0,"bid_ct":0,"ask_ct":0}],"symbol":"TSLA"}
{"ts_recv":"2024-11-01T08:00:01.299887425Z","hd":{"ts_event":"2024-11-01T08:00:01.299721582Z","rtype":10,"publisher_id":2,"instrument_id":16244},"action":"C","side":"B","depth":1,"price":"249.400000000","size":1000,"flags":130,"ts_in_delta":165843,"sequence":289823,"levels":[{"bid_px":"249.500000000","ask_px":"251.140000000","bid_sz":1000,"ask_sz":100,"bid_ct":1,"ask_ct":1},{"bid_px":"247.150000000","ask_px":"252.400000000","bid_sz":400,"ask_sz":1000,"bid_ct":1,"ask_ct":1},{"bid_px":"235.000000000","ask_px":"253.650000000","bid_sz":100,"ask_sz":400,"bid_ct":1,"ask_ct":1},{"bid_px":null,"ask_px":"960.000000000","bid_sz":0,"ask_sz":25,"bid_ct":0,"ask_ct":1},{"bid_px":null,"ask_px":null,"bid_sz":0,"ask_sz":0,"bid_ct":0,"ask_ct":0},{"bid_px":null,"ask_px":null,"bid_sz":0,"ask_sz":0,"bid_ct":0,"ask_ct":0},{"bid_px":null,"ask_px":null,"bid_sz":0,"ask_sz":0,"bid_ct":0,"ask_ct":0},{"bid_px":null,"ask_px":null,"bid_sz":0,"ask_sz":0,"bid_ct":0,"ask_ct":0},{"bid_px":null,"ask_px":null,"bid_sz":0,"ask_sz":0,"bid_ct":0,"ask_ct":0},{"bid_px":null,"ask_px":null,"bid_sz":0,"ask_sz":0,"bid_ct":0,"ask_ct":0}],"symbol":"TSLA"}
{"ts_recv":"2024-11-01T08:00:01.334757259Z","hd":{"ts_event":"2024-11-01T08:00:01.334591004Z","rtype":10,"publisher_id":2,"instrument_id":16244},"action":"A","side":"B","depth":0,"price":"249.600000000","size":1000,"flags":130,"ts_in_delta":166255,"sequence":289876,"levels":[{"bid_px":"249.600000000","ask_px":"251.140000000","bid_sz":1000,"ask_sz":100,"bid_ct":1,"ask_ct":1},{"bid_px":"249.500000000","ask_px":"252.400000000","bid_sz":1000,"ask_sz":1000,"bid_ct":1,"ask_ct":1},{"bid_px":"247.150000000","ask_px":"253.650000000","bid_sz":400,"ask_sz":400,"bid_ct":1,"ask_ct":1},{"bid_px":"235.000000000","ask_px":"960.000000000","bid_sz":100,"ask_sz":25,"bid_ct":1,"ask_ct":1},{"bid_px":null,"ask_px":null,"bid_sz":0,"ask_sz":0,"bid_ct":0,"ask_ct":0},{"bid_px":null,"ask_px":null,"bid_sz":0,"ask_sz":0,"bid_ct":0,"ask_ct":0},{"bid_px":null,"ask_px":null,"bid_sz":0,"ask_sz":0,"bid_ct":0,"ask_ct":0},{"bid_px":null,"ask_px":null,"bid_sz":0,"ask_sz":0,"bid_ct":0,"ask_ct":0},{"bid_px":null,"ask_px":null,"bid_sz":0,"ask_sz":0,"bid_ct":0,"ask_ct":0},{"bid_px":null,"ask_px":null,"bid_sz":0,"ask_sz":0,"bid_ct":0,"ask_ct":0}],"symbol":"TSLA"}
{"ts_recv":"2024-11-01T08:00:01.334873314Z","hd":{"ts_event":"2024-11-01T08:00:01.334707574Z","rtype":10,"publisher_id":2,"instrument_id":16244},"action":"C","side":"B","depth":1,"price":"249.500000000","size":1000,"flags":130,"ts_in_delta":165740,"sequence":289877,"levels":[{"bid_px":"249.600000000","ask_px":"251.140000000","bid_sz":1000,"ask_sz":100,"bid_ct":1,"ask_ct":1},{"bid_px":"247.150000000","ask_px":"252.400000000","bid_sz":400,"ask_sz":1000,"bid_ct":1,"ask_ct":1},{"bid_px":"235.000000000","ask_px":"253.650000000","bid_sz":100,"ask_sz":400,"bid_ct":1,"ask_ct":1},{"bid_px":null,"ask_px":"960.000000000","bid_sz":0,"ask_sz":25,"bid_ct":0,"ask_ct":1},{"bid_px":null,"ask_px":null,"bid_sz":0,"ask_sz":0,"bid_ct":0,"ask_ct":0},{"bid_px":null,"ask_px":null,"bid_sz":0,"ask_sz":0,"bid_ct":0,"ask_ct":0},{"bid_px":null,"ask_px":null,"bid_sz":0,"ask_sz":0,"bid_ct":0,"ask_ct":0},{"bid_px":null,"ask_px":null,"bid_sz":0,"ask_sz":0,"bid_ct":0,"ask_ct":0},{"bid_px":null,"ask_px":null,"bid_sz":0,"ask_sz":0,"bid_ct":0,"ask_ct":0},{"bid_px":null,"ask_px":null,"bid_sz":0,"ask_sz":0,"bid_ct":0,"ask_ct":0}],"symbol":"TSLA"}
{"ts_recv":"2024-11-01T08:00:01.421607851Z","hd":{"ts_event":"2024-11-01T08:00:01.421441589Z","rtype":10,"publisher_id":2,"instrument_id":16244},"action":"A","side":"B","depth":0,"price":"250.310000000","size":50,"flags":130,"ts_in_delta":166262,"sequence":290276,"levels":[{"bid_px":"250.310000000","ask_px":"251.140000000","bid_sz":50,"ask_sz":100,"bid_ct":1,"ask_ct":1},{"bid_px":"249.600000000","ask_px":"252.400000000","bid_sz":1000,"ask_sz":1000,"bid_ct":1,"ask_ct":1},{"bid_px":"247.150000000","ask_px":"253.650000000","bid_sz":400,"ask_sz":400,"bid_ct":1,"ask_ct":1},{"bid_px":"235.000000000","ask_px":"960.000000000","bid_sz":100,"ask_sz":25,"bid_ct":1,"ask_ct":1},{"bid_px":null,"ask_px":null,"bid_sz":0,"ask_sz":0,"bid_ct":0,"ask_ct":0},{"bid_px":null,"ask_px":null,"bid_sz":0,"ask_sz":0,"bid_ct":0,"ask_ct":0},{"bid_px":null,"ask_px":null,"bid_sz":0,"ask_sz":0,"bid_ct":0,"ask_ct":0},{"bid_px":null,"ask_px":null,"bid_sz":0,"ask_sz":0,"bid_ct":0,"ask_ct":0},{"bid_px":null,"ask_px":null,"bid_sz":0,"ask_sz":0,"bid_ct":0,"ask_ct":0},{"bid_px":null,"ask_px":null,"bid_sz":0,"ask_sz":0,"bid_ct":0,"ask_ct":0}],"symbol":"TSLA"}
{"ts_recv":"2024-11-01T08:00:01.472376727Z","hd":{"ts_event":"2024-11-01T08:00:01.472210778Z","rtype":10,"publisher_id":2,"instrument_id":16244},"action":"A","side":"B","depth":0,"price":"250.340000000","size":50,"flags":130,"ts_in_delta":165949,"sequence":290611,"levels":[{"bid_px":"250.340000000","ask_px":"251.140000000","bid_sz":50,"ask_sz":100,"bid_ct":1,"ask_ct":1},{"bid_px":"249.600000000","ask_px":"252.400000000","bid_sz":1000,"ask_sz":1000,"bid_ct":1,"ask_ct":1},{"bid_px":"247.150000000","ask_px":"253.650000000","bid_sz":400,"ask_sz":400,"bid_ct":1,"ask_ct":1},{"bid_px":"235.000000000","ask_px":"960.000000000","bid_sz":100,"ask_sz":25,"bid_ct":1,"ask_ct":1},{"bid_px":null,"ask_px":null,"bid_sz":0,"ask_sz":0,"bid_ct":0,"ask_ct":0},{"bid_px":null,"ask_px":null,"bid_sz":0,"ask_sz":0,"bid_ct":0,"ask_ct":0},{"bid_px":null,"ask_px":null,"bid_sz":0,"ask_sz":0,"bid_ct":0,"ask_ct":0},{"bid_px":null,"ask_px":null,"bid_sz":0,"ask_sz":0,"bid_ct":0,"ask_ct":0},{"bid_px":null,"ask_px":null,"bid_sz":0,"ask_sz":0,"bid_ct":0,"ask_ct":0},{"bid_px":null,"ask_px":null,"bid_sz":0,"ask_sz":0,"bid_ct":0,"ask_ct":0}],"symbol":"TSLA"}
{"ts_recv":"2024-11-01T08:00:01.472941909Z","hd":{"ts_event":"2024-11-01T08:00:01.472776285Z","rtype":10,"publisher_id":2,"instrument_id":16244},"action":"C","side":"B","depth":1,"price":"249.600000000","size":1000,"flags":130,"ts_in_delta":165624,"sequence":290617,"levels":[{"bid_px":"250.340000000","ask_px":"251.140000000","bid_sz":50,"ask_sz":100,"bid_ct":1,"ask_ct":1},{"bid_px":"247.150000000","ask_px":"252.400000000","bid_sz":400,"ask_sz":1000,"bid_ct":1,"ask_ct":1},{"bid_px":"235.000000000","ask_px":"253.650000000","bid_sz":100,"ask_sz":400,"bid_ct":1,"ask_ct":1},{"bid_px":null,"ask_px":"960.000000000","bid_sz":0,"ask_sz":25,"bid_ct":0,"ask_ct":1},{"bid_px":null,"ask_px":null,"bid_sz":0,"ask_sz":0,"bid_ct":0,"ask_ct":0},{"bid_px":null,"ask_px":null,"bid_sz":0,"ask_sz":0,"bid_ct":0,"ask_ct":0},{"bid_px":null,"ask_px":null,"bid_sz":0,"ask_sz":0,"bid_ct":0,"ask_ct":0},{"bid_px":null,"ask_px":null,"bid_sz":0,"ask_sz":0,"bid_ct":0,"ask_ct":0},{"bid_px":null,"ask_px":null,"bid_sz":0,"ask_sz":0,"bid_ct":0,"ask_ct":0},{"bid_px":null,"ask_px":null,"bid_sz":0,"ask_sz":0,"bid_ct":0,"ask_ct":0}],"symbol":"TSLA"}
{"ts_recv":"2024-11-01T08:00:01.484355921Z","hd":{"ts_event":"2024-11-01T08:00:01.484189995Z","rtype":10,"publisher_id":2,"instrument_id":16244},"action":"A","side":"B","depth":1,"price":"249.100000000","size":1000,"flags":130,"ts_in_delta":165926,"sequence":290642,"levels":[{"bid_px":"250.340000000","ask_px":"251.140000000","bid_sz":50,"ask_sz":100,"bid_ct":1,"ask_ct":1},{"bid_px":"249.100000000","ask_px":"252.400000000","bid_sz":1000,"ask_sz":1000,"bid_ct":1,"ask_ct":1},{"bid_px":"247.150000000","ask_px":"253.650000000","bid_sz":400,"ask_sz":400,"bid_ct":1,"ask_ct":1},{"bid_px":"235.000000000","ask_px":"960.000000000","bid_sz":100,"ask_sz":25,"bid_ct":1,"ask_ct":1},{"bid_px":null,"ask_px":null,"bid_sz":0,"ask_sz":0,"bid_ct":0,"ask_ct":0},{"bid_px":null,"ask_px":null,"bid_sz":0,"ask_sz":0,"bid_ct":0,"ask_ct":0},{"bid_px":null,"ask_px":null,"bid_sz":0,"ask_sz":0,"bid_ct":0,"ask_ct":0},{"bid_px":null,"ask_px":null,"bid_sz":0,"ask_sz":0,"bid_ct":0,"ask_ct":0},{"bid_px":null,"ask_px":null,"bid_sz":0,"ask_sz":0,"bid_ct":0,"ask_ct":0},{"bid_px":null,"ask_px":null,"bid_sz":0,"ask_sz":0,"bid_ct":0,"ask_ct":0}],"symbol":"TSLA"}
{"ts_recv":"2024-11-01T08:00:01.532508123Z","hd":{"ts_event":"2024-11-01T08:00:01.532342419Z","rtype":10,"publisher_id":2,"instrument_id":16244},"action":"C","side":"B","depth":0,"price":"250.340000000","size":50,"flags":130,"ts_in_delta":165704,"sequence":290695,"levels":[{"bid_px":"249.100000000","ask_px":"251.140000000","bid_sz":1000,"ask_sz":100,"bid_ct":1,"ask_ct":1},{"bid_px":"247.150000000","ask_px":"252.400000000","bid_sz":400,"ask_sz":1000,"bid_ct":1,"ask_ct":1},{"bid_px":"235.000000000","ask_px":"253.650000000","bid_sz":100,"ask_sz":400,"bid_ct":1,"ask_ct":1},{"bid_px":null,"ask_px":"960.000000000","bid_sz":0,"ask_sz":25,"bid_ct":0,"ask_ct":1},{"bid_px":null,"ask_px":null,"bid_sz":0,"ask_sz":0,"bid_ct":0,"ask_ct":0},{"bid_px":null,"ask_px":null,"bid_sz":0,"ask_sz":0,"bid_ct":0,"ask_ct":0},{"bid_px":null,"ask_px":null,"bid_sz":0,"ask_sz":0,"bid_ct":0,"ask_ct":0},{"bid_px":null,"ask_px":null,"bid_sz":0,"ask_sz":0,"bid_ct":0,"ask_ct":0},{"bid_px":null,"ask_px":null,"bid_sz":0,"ask_sz":0,"bid_ct":0,"ask_ct":0},{"bid_px":null,"ask_px":null,"bid_sz":0,"ask_sz":0,"bid_ct":0,"ask_ct":0}],"symbol":"TSLA"}
{"ts_recv":"2024-11-01T08:00:01.532521726Z","hd":{"ts_event":"2024-11-01T08:00:01.532355375Z","rtype":10,"publisher_id":2,"instrument_id":16244},"action":"A","side":"B","depth":0,"price":"250.280000000","size":50,"flags":130,"ts_in_delta":166351,"sequence":290696,"levels":[{"bid_px":"250.280000000","ask_px":"251.140000000","bid_sz":50,"ask_sz":100,"bid_ct":1,"ask_ct":1},{"bid_px":"249.100000000","ask_px":"252.400000000","bid_sz":1000,"ask_sz":1000,"bid_ct":1,"ask_ct":1},{"bid_px":"247.150000000","ask_px":"253.650000000","bid_sz":400,"ask_sz":400,"bid_ct":1,"ask_ct":1},{"bid_px":"235.000000000","ask_px":"960.000000000","bid_sz":100,"ask_sz":25,"bid_ct":1,"ask_ct":1},{"bid_px":null,"ask_px":null,"bid_sz":0,"ask_sz":0,"bid_ct":0,"ask_ct":0},{"bid_px":null,"ask_px":null,"bid_sz":0,"ask_sz":0,"bid_ct":0,"ask_ct":0},{"bid_px":null,"ask_px":null,"bid_sz":0,"ask_sz":0,"bid_ct":0,"ask_ct":0},{"bid_px":null,"ask_px":null,"bid_sz":0,"ask_sz":0,"bid_ct":0,"ask_ct":0},{"bid_px":null,"ask_px":null,"bid_sz":0,"ask_sz":0,"bid_ct":0,"ask_ct":0},{"bid_px":null,"ask_px":null,"bid_sz":0,"ask_sz":0,"bid_ct":0,"ask_ct":0}],"symbol":"TSLA"}
{"ts_recv":"2024-11-01T08:00:01.532601371Z","hd":{"ts_event":"2024-11-01T08:00:01.532435839Z","rtype":10,"publisher_id":2,"instrument_id":16244},"action":"C","side":"B","depth":0,"price":"250.280000000","size":50,"flags":130,"ts_in_delta":165532,"sequence":290697,"levels":[{"bid_px":"249.100000000","ask_px":"251.140000000","bid_sz":1000,"ask_sz":100,"bid_ct":1,"ask_ct":1},{"bid_px":"247.150000000","ask_px":"252.400000000","bid_sz":400,"ask_sz":1000,"bid_ct":1,"ask_ct":1},{"bid_px":"235.000000000","ask_px":"253.650000000","bid_sz":100,"ask_sz":400,"bid_ct":1,"ask_ct":1},{"bid_px":null,"ask_px":"960.000000000","bid_sz":0,"ask_sz":25,"bid_ct":0,"ask_ct":1},{"bid_px":null,"ask_px":null,"bid_sz":0,"ask_sz":0,"bid_ct":0,"ask_ct":0},{"bid_px":null,"ask_px":null,"bid_sz":0,"ask_sz":0,"bid_ct":0,"ask_ct":0},{"bid_px":null,"ask_px":null,"bid_sz":0,"ask_sz":0,"bid_ct":0,"ask_ct":0},{"bid_px":null,"ask_px":null,"bid_sz":0,"ask_sz":0,"bid_ct":0,"ask_ct":0},{"bid_px":null,"ask_px":null,"bid_sz":0,"ask_sz":0,"bid_ct":0,"ask_ct":0},{"bid_px":null,"ask_px":null,"bid_sz":0,"ask_sz":0,"bid_ct":0,"ask_ct":0}],"symbol":"TSLA"}
{"ts_recv":"2024-11-01T08:00:01.532647825Z","hd":{"ts_event":"2024-11-01T08:00:01.532481982Z","rtype":10,"publisher_id":2,"instrument_id":16244},"action":"A","side":"B","depth":0,"price":"250.230000000","size":50,"flags":130,"ts_in_delta":165843,"sequence":290698,"levels":[{"bid_px":"250.230000000","ask_px":"251.140000000","bid_sz":50,"ask_sz":100,"bid_ct":1,"ask_ct":1},{"bid_px":"249.100000000","ask_px":"252.400000000","bid_sz":1000,"ask_sz":1000,"bid_ct":1,"ask_ct":1},{"bid_px":"247.150000000","ask_px":"253.650000000","bid_sz":400,"ask_sz":400,"bid_ct":1,"ask_ct":1},{"bid_px":"235.000000000","ask_px":"960.000000000","bid_sz":100,"ask_sz":25,"bid_ct":1,"ask_ct":1},{"bid_px":null,"ask_px":null,"bid_sz":0,"ask_sz":0,"bid_ct":0,"ask_ct":0},{"bid_px":null,"ask_px":null,"bid_sz":0,"ask_sz":0,"bid_ct":0,"ask_ct":0},{"bid_px":null,"ask_px":null,"bid_sz":0,"ask_sz":0,"bid_ct":0,"ask_ct":0},{"bid_px":null,"ask_px":null,"bid_sz":0,"ask_sz":0,"bid_ct":0,"ask_ct":0},{"bid_px":null,"ask_px":null,"bid_sz":0,"ask_sz":0,"bid_ct":0,"ask_ct":0},{"bid_px":null,"ask_px":null,"bid_sz":0,"ask_sz":0,"bid_ct":0,"ask_ct":0}],"symbol":"TSLA"}
{"ts_recv":"2024-11-01T08:00:01.533380248Z","hd":{"ts_event":"2024-11-01T08:00:01.533213887Z","rtype":10,"publisher_id":2,"instrument_id":16244},"action":"A","side":"B","depth":1,"price":"249.400000000","size":1000,"flags":130,"ts_in_delta":166361,"sequence":290700,"levels":[{"bid_px":"250.230000000","ask_px":"251.140000000","bid_sz":50,"ask_sz":100,"bid_ct":1,"ask_ct":1},{"bid_px":"249.400000000","ask_px":"252.400000000","bid_sz":1000,"ask_sz":1000,"bid_ct":1,"ask_ct":1},{"bid_px":"249.100000000","ask_px":"253.650000000","bid_sz":1000,"ask_sz":400,"bid_ct":1,"ask_ct":1},{"bid_px":"247.150000000","ask_px":"960.000000000","bid_sz":400,"ask_sz":25,"bid_ct":1,"ask_ct":1},{"bid_px":"235.000000000","ask_px":null,"bid_sz":100,"ask_sz":0,"bid_ct":1,"ask_ct":0},{"bid_px":null,"ask_px":null,"bid_sz":0,"ask_sz":0,"bid_ct":0,"ask_ct":0},{"bid_px":null,"ask_px":null,"bid_sz":0,"ask_sz":0,"bid_ct":0,"ask_ct":0},{"bid_px":null,"ask_px":null,"bid_sz":0,"ask_sz":0,"bid_ct":0,"ask_ct":0},{"bid_px":null,"ask_px":null,"bid_sz":0,"ask_sz":0,"bid_ct":0,"ask_ct":0},{"bid_px":null,"ask_px":null,"bid_sz":0,"ask_sz":0,"bid_ct":0,"ask_ct":0}],"symbol":"TSLA"}
{"ts_recv":"2024-11-01T08:00:01.533475659Z","hd":{"ts_event":"2024-11-01T08:00:01.533309394Z","rtype":10,"publisher_id":2,"instrument_id":16244},"action":"C","side":"B","depth":2,"price":"249.100000000","size":1000,"flags":130,"ts_in_delta":166265,"sequence":290702,"levels":[{"bid_px":"250.230000000","ask_px":"251.140000000","bid_sz":50,"ask_sz":100,"bid_ct":1,"ask_ct":1},{"bid_px":"249.400000000","ask_px":"252.400000000","bid_sz":1000,"ask_sz":1000,"bid_ct":1,"ask_ct":1},{"bid_px":"247.150000000","ask_px":"253.650000000","bid_sz":400,"ask_sz":400,"bid_ct":1,"ask_ct":1},{"bid_px":"235.000000000","ask_px":"960.000000000","bid_sz":100,"ask_sz":25,"bid_ct":1,"ask_ct":1},{"bid_px":null,"ask_px":null,"bid_sz":0,"ask_sz":0,"bid_ct":0,"ask_ct":0},{"bid_px":null,"ask_px":null,"bid_sz":0,"ask_sz":0,"bid_ct":0,"ask_ct":0},{"bid_px":null,"ask_px":null,"bid_sz":0,"ask_sz":0,"bid_ct":0,"ask_ct":0},{"bid_px":null,"ask_px":null,"bid_sz":0,"ask_sz":0,"bid_ct":0,"ask_ct":0},{"bid_px":null,"ask_px":null,"bid_sz":0,"ask_sz":0,"bid_ct":0,"ask_ct":0},{"bid_px":null,"ask_px":null,"bid_sz":0,"ask_sz":0,"bid_ct":0,"ask_ct":0}],"symbol":"TSLA"}
{"ts_recv":"2024-11-01T08:00:01.579298891Z","hd":{"ts_event":"2024-11-01T08:00:01.579132585Z","rtype":10,"publisher_id":2,"instrument_id":16244},"action":"A","side":"B","depth":1,"price":"249.500000000","size":1000,"flags":130,"ts_in_delta":166306,"sequence":290847,"levels":[{"bid_px":"250.230000000","ask_px":"251.140000000","bid_sz":50,"ask_sz":100,"bid_ct":1,"ask_ct":1},{"bid_px":"249.500000000","ask_px":"252.400000000","bid_sz":1000,"ask_sz":1000,"bid_ct":1,"ask_ct":1},{"bid_px":"249.400000000","ask_px":"253.650000000","bid_sz":1000,"ask_sz":400,"bid_ct":1,"ask_ct":1},{"bid_px":"247.150000000","ask_px":"960.000000000","bid_sz":400,"ask_sz":25,"bid_ct":1,"ask_ct":1},{"bid_px":"235.000000000","ask_px":null,"bid_sz":100,"ask_sz":0,"bid_ct":1,"ask_ct":0},{"bid_px":null,"ask_px":null,"bid_sz":0,"ask_sz":0,"bid_ct":0,"ask_ct":0},{"bid_px":null,"ask_px":null,"bid_sz":0,"ask_sz":0,"bid_ct":0,"ask_ct":0},{"bid_px":null,"ask_px":null,"bid_sz":0,"ask_sz":0,"bid_ct":0,"ask_ct":0},{"bid_px":null,"ask_px":null,"bid_sz":0,"ask_sz":0,"bid_ct":0,"ask_ct":0},{"bid_px":null,"ask_px":null,"bid_sz":0,"ask_sz":0,"bid_ct":0,"ask_ct":0}],"symbol":"TSLA"}
{"ts_recv":"2024-11-01T08:00:01.579386027Z","hd":{"ts_event":"2024-11-01T08:00:01.579220012Z","rtype":10,"publisher_id":2,"instrument_id":16244},"action":"C","side":"B","depth":2,"price":"249.400000000","size":1000,"flags":130,"ts_in_delta":166015,"sequence":290848,"levels":[{"bid_px":"250.230000000","ask_px":"251.140000000","bid_sz":50,"ask_sz":100,"bid_ct":1,"ask_ct":1},{"bid_px":"249.500000000","ask_px":"252.400000000","bid_sz":1000,"ask_sz":1000,"bid_ct":1,"ask_ct":1},{"bid_px":"247.150000000","ask_px":"253.650000000","bid_sz":400,"ask_sz":400,"bid_ct":1,"ask_ct":1},{"bid_px":"235.000000000","ask_px":"960.000000000","bid_sz":100,"ask_sz":25,"bid_ct":1,"ask_ct":1},{"bid_px":null,"ask_px":null,"bid_sz":0,"ask_sz":0,"bid_ct":0,"ask_ct":0},{"bid_px":null,"ask_px":null,"bid_sz":0,"ask_sz":0,"bid_ct":0,"ask_ct":0},{"bid_px":null,"ask_px":null,"bid_sz":0,"ask_sz":0,"bid_ct":0,"ask_ct":0},{"bid_px":null,"ask_px":null,"bid_sz":0,"ask_sz":0,"bid_ct":0,"ask_ct":0},{"bid_px":null,"ask_px":null,"bid_sz":0,"ask_sz":0,"bid_ct":0,"ask_ct":0},{"bid_px":null,"ask_px":null,"bid_sz":0,"ask_sz":0,"bid_ct":0,"ask_ct":0}],"symbol":"TSLA"}
{"ts_recv":"2024-11-01T08:00:01.657474188Z","hd":{"ts_event":"2024-11-01T08:00:01.657307769Z","rtype":10,"publisher_id":2,"instrument_id":16244},"action":"A","side":"B","depth":0,"price":"250.310000000","size":50,"flags":130,"ts_in_delta":166419,"sequence":291006,"levels":[{"bid_px":"250.310000000","ask_px":"251.140000000","bid_sz":50,"ask_sz":100,"bid_ct":1,"ask_ct":1},{"bid_px":"249.500000000","ask_px":"252.400000000","bid_sz":1000,"ask_sz":1000,"bid_ct":1,"ask_ct":1},{"bid_px":"247.150000000","ask_px":"253.650000000","bid_sz":400,"ask_sz":400,"bid_ct":1,"ask_ct":1},{"bid_px":"235.000000000","ask_px":"960.000000000","bid_sz":100,"ask_sz":25,"bid_ct":1,"ask_ct":1},{"bid_px":null,"ask_px":null,"bid_sz":0,"ask_sz":0,"bid_ct":0,"ask_ct":0},{"bid_px":null,"ask_px":null,"bid_sz":0,"ask_sz":0,"bid_ct":0,"ask_ct":0},{"bid_px":null,"ask_px":null,"bid_sz":0,"ask_sz":0,"bid_ct":0,"ask_ct":0},{"bid_px":null,"ask_px":null,"bid_sz":0,"ask_sz":0,"bid_ct":0,"ask_ct":0},{"bid_px":null,"ask_px":null,"bid_sz":0,"ask_sz":0,"bid_ct":0,"ask_ct":0},{"bid_px":null,"ask_px":null,"bid_sz":0,"ask_sz":0,"bid_ct":0,"ask_ct":0}],"symbol":"TSLA"}
{"ts_recv":"2024-11-01T08:00:01.716519672Z","hd":{"ts_event":"2024-11-01T08:00:01.716353332Z","rtype":10,"publisher_id":2,"instrument_id":16244},"action":"A","side":"B","depth":0,"price":"250.330000000","size":50,"flags":130,"ts_in_delta":166340,"sequence":291116,"levels":[{"bid_px":"250.330000000","ask_px":"251.140000000","bid_sz":50,"ask_sz":100,"bid_ct":1,"ask_ct":1},{"bid_px":"249.500000000","ask_px":"252.400000000","bid_sz":1000,"ask_sz":1000,"bid_ct":1,"ask_ct":1},{"bid_px":"247.150000000","ask_px":"253.650000000","bid_sz":400,"ask_sz":400,"bid_ct":1,"ask_ct":1},{"bid_px":"235.000000000","ask_px":"960.000000000","bid_sz":100,"ask_sz":25,"bid_ct":1,"ask_ct":1},{"bid_px":null,"ask_px":null,"bid_sz":0,"ask_sz":0,"bid_ct":0,"ask_ct":0},{"bid_px":null,"ask_px":null,"bid_sz":0,"ask_sz":0,"bid_ct":0,"ask_ct":0},{"bid_px":null,"ask_px":null,"bid_sz":0,"ask_sz":0,"bid_ct":0,"ask_ct":0},{"bid_px":null,"ask_px":null,"bid_sz":0,"ask_sz":0,"bid_ct":0,"ask_ct":0},{"bid_px":null,"ask_px":null,"bid_sz":0,"ask_sz":0,"bid_ct":0,"ask_ct":0},{"bid_px":null,"ask_px":null,"bid_sz":0,"ask_sz":0,"bid_ct":0,"ask_ct":0}],"symbol":"TSLA"}
{"ts_recv":"2024-11-01T08:00:01.887177526Z","hd":{"ts_event":"2024-11-01T08:00:01.887011820Z","rtype":10,"publisher_id":2,"instrument_id":16244},"action":"C","side":"B","depth":0,"price":"250.330000000","size":50,"flags":130,"ts_in_delta":165706,"sequence":291358,"levels":[{"bid_px":"249.500000000","ask_px":"251.140000000","bid_sz":1000,"ask_sz":100,"bid_ct":1,"ask_ct":1},{"bid_px":"247.150000000","ask_px":"252.400000000","bid_sz":400,"ask_sz":1000,"bid_ct":1,"ask_ct":1},{"bid_px":"235.000000000","ask_px":"253.650000000","bid_sz":100,"ask_sz":400,"bid_ct":1,"ask_ct":1},{"bid_px":null,"ask_px":"960.000000000","bid_sz":0,"ask_sz":25,"bid_ct":0,"ask_ct":1},{"bid_px":null,"ask_px":null,"bid_sz":0,"ask_sz":0,"bid_ct":0,"ask_ct":0},{"bid_px":null,"ask_px":null,"bid_sz":0,"ask_sz":0,"bid_ct":0,"ask_ct":0},{"bid_px":null,"ask_px":null,"bid_sz":0,"ask_sz":0,"bid_ct":0,"ask_ct":0},{"bid_px":null,"ask_px":null,"bid_sz":0,"ask_sz":0,"bid_ct":0,"ask_ct":0},{"bid_px":null,"ask_px":null,"bid_sz":0,"ask_sz":0,"bid_ct":0,"ask_ct":0},{"bid_px":null,"ask_px":null,"bid_sz":0,"ask_sz":0,"bid_ct":0,"ask_ct":0}],"symbol":"TSLA"}
{"ts_recv":"2024-11-01T08:00:01.938948169Z","hd":{"ts_event":"2024-11-01T08:00:01.938781736Z","rtype":10,"publisher_id":2,"instrument_id":16244},"action":"A","side":"B","depth":0,"price":"249.600000000","size":1000,"flags":130,"ts_in_delta":166433,"sequence":291441,"levels":[{"bid_px":"249.600000000","ask_px":"251.140000000","bid_sz":1000,"ask_sz":100,"bid_ct":1,"ask_ct":1},{"bid_px":"249.500000000","ask_px":"252.400000000","bid_sz":1000,"ask_sz":1000,"bid_ct":1,"ask_ct":1},{"bid_px":"247.150000000","ask_px":"253.650000000","bid_sz":400,"ask_sz":400,"bid_ct":1,"ask_ct":1},{"bid_px":"235.000000000","ask_px":"960.000000000","bid_sz":100,"ask_sz":25,"bid_ct":1,"ask_ct":1},{"bid_px":null,"ask_px":null,"bid_sz":0,"ask_sz":0,"bid_ct":0,"ask_ct":0},{"bid_px":null,"ask_px":null,"bid_sz":0,"ask_sz":0,"bid_ct":0,"ask_ct":0},{"bid_px":null,"ask_px":null,"bid_sz":0,"ask_sz":0,"bid_ct":0,"ask_ct":0},{"bid_px":null,"ask_px":null,"bid_sz":0,"ask_sz":0,"bid_ct":0,"ask_ct":0},{"bid_px":null,"ask_px":null,"bid_sz":0,"ask_sz":0,"bid_ct":0,"ask_ct":0},{"bid_px":null,"ask_px":null,"bid_sz":0,"ask_sz":0,"bid_ct":0,"ask_ct":0}],"symbol":"TSLA"}
{"ts_recv":"2024-11-01T08:00:01.939568626Z","hd":{"ts_event":"2024-11-01T08:00:01.939402273Z","rtype":10,"publisher_id":2,"instrument_id":16244},"action":"C","side":"B","depth":1,"price":"249.500000000","size":1000,"flags":130,"ts_in_delta":166353,"sequence":291442,"levels":[{"bid_px":"249.600000000","ask_px":"251.140000000","bid_sz":1000,"ask_sz":100,"bid_ct":1,"ask_ct":1},{"bid_px":"247.150000000","ask_px":"252.400000000","bid_sz":400,"ask_sz":1000,"bid_ct":1,"ask_ct":1},{"bid_px":"235.000000000","ask_px":"253.650000000","bid_sz":100,"ask_sz":400,"bid_ct":1,"ask_ct":1},{"bid_px":null,"ask_px":"960.000000000","bid_sz":0,"ask_sz":25,"bid_ct":0,"ask_ct":1},{"bid_px":null,"ask_px":null,"bid_sz":0,"ask_sz":0,"bid_ct":0,"ask_ct":0},{"bid_px":null,"ask_px":null,"bid_sz":0,"ask_sz":0,"bid_ct":0,"ask_ct":0},{"bid_px":null,"ask_px":null,"bid_sz":0,"ask_sz":0,"bid_ct":0,"ask_ct":0},{"bid_px":null,"ask_px":null,"bid_sz":0,"ask_sz":0,"bid_ct":0,"ask_ct":0},{"bid_px":null,"ask_px":null,"bid_sz":0,"ask_sz":0,"bid_ct":0,"ask_ct":0},{"bid_px":null,"ask_px":null,"bid_sz":0,"ask_sz":0,"bid_ct":0,"ask_ct":0}],"symbol":"TSLA"}
{"ts_recv":"2024-11-01T08:00:01.946482277Z","hd":{"ts_event":"2024-11-01T08:00:01.946315842Z","rtype":10,"publisher_id":2,"instrument_id":16244},"action":"A","side":"B","depth":0,"price":"250.200000000","size":50,"flags":130,"ts_in_delta":166435,"sequence":291446,"levels":[{"bid_px":"250.200000000","ask_px":"251.140000000","bid_sz":50,"ask_sz":100,"bid_ct":1,"ask_ct":1},{"bid_px":"249.600000000","ask_px":"252.400000000","bid_sz":1000,"ask_sz":1000,"bid_ct":1,"ask_ct":1},{"bid_px":"247.150000000","ask_px":"253.650000000","bid_sz":400,"ask_sz":400,"bid_ct":1,"ask_ct":1},{"bid_px":"235.000000000","ask_px":"960.000000000","bid_sz":100,"ask_sz":25,"bid_ct":1,"ask_ct":1},{"bid_px":null,"ask_px":null,"bid_sz":0,"ask_sz":0,"bid_ct":0,"ask_ct":0},{"bid_px":null,"ask_px":null,"bid_sz":0,"ask_sz":0,"bid_ct":0,"ask_ct":0},{"bid_px":null,"ask_px":null,"bid_sz":0,"ask_sz":0,"bid_ct":0,"ask_ct":0},{"bid_px":null,"ask_px":null,"bid_sz":0,"ask_sz":0,"bid_ct":0,"ask_ct":0},{"bid_px":null,"ask_px":null,"bid_sz":0,"ask_sz":0,"bid_ct":0,"ask_ct":0},{"bid_px":null,"ask_px":null,"bid_sz":0,"ask_sz":0,"bid_ct":0,"ask_ct":0}],"symbol":"TSLA"}
{"ts_recv":"2024-11-01T08:00:01.946561239Z","hd":{"ts_event":"2024-11-01T08:00:01.946395496Z","rtype":10,"publisher_id":2,"instrument_id":16244},"action":"C","side":"B","depth":0,"price":"250.200000000","size":50,"flags":130,"ts_in_delta":165743,"sequence":291447,"levels":[{"bid_px":"249.600000000","ask_px":"251.140000000","bid_sz":1000,"ask_sz":100,"bid_ct":1,"ask_ct":1},{"bid_px":"247.150000000","ask_px":"252.400000000","bid_sz":400,"ask_sz":1000,"bid_ct":1,"ask_ct":1},{"bid_px":"235.000000000","ask_px":"253.650000000","bid_sz":100,"ask_sz":400,"bid_ct":1,"ask_ct":1},{"bid_px":null,"ask_px":"960.000000000","bid_sz":0,"ask_sz":25,"bid_ct":0,"ask_ct":1},{"bid_px":null,"ask_px":null,"bid_sz":0,"ask_sz":0,"bid_ct":0,"ask_ct":0},{"bid_px":null,"ask_px":null,"bid_sz":0,"ask_sz":0,"bid_ct":0,"ask_ct":0},{"bid_px":null,"ask_px":null,"bid_sz":0,"ask_sz":0,"bid_ct":0,"ask_ct":0},{"bid_px":null,"ask_px":null,"bid_sz":0,"ask_sz":0,"bid_ct":0,"ask_ct":0},{"bid_px":null,"ask_px":null,"bid_sz":0,"ask_sz":0,"bid_ct":0,"ask_ct":0},{"bid_px":null,"ask_px":null,"bid_sz":0,"ask_sz":0,"bid_ct":0,"ask_ct":0}],"symbol":"TSLA"}
{"ts_recv":"2024-11-01T08:00:01.946573797Z","hd":{"ts_event":"2024-11-01T08:00:01.946407831Z","rtype":10,"publisher_id":2,"instrument_id":16244},"action":"A","side":"B","depth":0,"price":"250.170000000","size":50,"flags":130,"ts_in_delta":165966,"sequence":291448,"levels":[{"bid_px":"250.170000000","ask_px":"251.140000000","bid_sz":50,"ask_sz":100,"bid_ct":1,"ask_ct":1},{"bid_px":"249.600000000","ask_px":"252.400000000","bid_sz":1000,"ask_sz":1000,"bid_ct":1,"ask_ct":1},{"bid_px":"247.150000000","ask_px":"253.650000000","bid_sz":400,"ask_sz":400,"bid_ct":1,"ask_ct":1},{"bid_px":"235.000000000","ask_px":"960.000000000","bid_sz":100,"ask_sz":25,"bid_ct":1,"ask_ct":1},{"bid_px":null,"ask_px":null,"bid_sz":0,"ask_sz":0,"bid_ct":0,"ask_ct":0},{"bid_px":null,"ask_px":null,"bid_sz":0,"ask_sz":0,"bid_ct":0,"ask_ct":0},{"bid_px":null,"ask_px":null,"bid_sz":0,"ask_sz":0,"bid_ct":0,"ask_ct":0},{"bid_px":null,"ask_px":null,"bid_sz":0,"ask_sz":0,"bid_ct":0,"ask_ct":0},{"bid_px":null,"ask_px":null,"bid_sz":0,"ask_sz":0,"bid_ct":0,"ask_ct":0},{"bid_px":null,"ask_px":null,"bid_sz":0,"ask_sz":0,"bid_ct":0,"ask_ct":0}],"symbol":"TSLA"}
{"ts_recv":"2024-11-01T08:00:01.946600876Z","hd":{"ts_event":"2024-11-01T08:00:01.946435553Z","rtype":10,"publisher_id":2,"instrument_id":16244},"action":"C","side":"B","depth":0,"price":"250.170000000","size":50,"flags":130,"ts_in_delta":165323,"sequence":291449,"levels":[{"bid_px":"249.600000000","ask_px":"251.140000000","bid_sz":1000,"ask_sz":100,"bid_ct":1,"ask_ct":1},{"bid_px":"247.150000000","ask_px":"252.400000000","bid_sz":400,"ask_sz":1000,"bid_ct":1,"ask_ct":1},{"bid_px":"235.000000000","ask_px":"253.650000000","bid_sz":100,"ask_sz":400,"bid_ct":1,"ask_ct":1},{"bid_px":null,"ask_px":"960.000000000","bid_sz":0,"ask_sz":25,"bid_ct":0,"ask_ct":1},{"bid_px":null,"ask_px":null,"bid_sz":0,"ask_sz":0,"bid_ct":0,"ask_ct":0},{"bid_px":null,"ask_px":null,"bid_sz":0,"ask_sz":0,"bid_ct":0,"ask_ct":0},{"bid_px":null,"ask_px":null,"bid_sz":0,"ask_sz":0,"bid_ct":0,"ask_ct":0},{"bid_px":null,"ask_px":null,"bid_sz":0,"ask_sz":0,"bid_ct":0,"ask_ct":0},{"bid_px":null,"ask_px":null,"bid_sz":0,"ask_sz":0,"bid_ct":0,"ask_ct":0},{"bid_px":null,"ask_px":null,"bid_sz":0,"ask_sz":0,"bid_ct":0,"ask_ct":0}],"symbol":"TSLA"}
{"ts_recv":"2024-11-01T08:00:01.947101210Z","hd":{"ts_event":"2024-11-01T08:00:01.946935533Z","rtype":10,"publisher_id":2,"instrument_id":16244},"action":"C","side":"B","depth":0,"price":"249.600000000","size":1000,"flags":130,"ts_in_delta":165677,"sequence":291450,"levels":[{"bid_px":"247.150000000","ask_px":"251.140000000","bid_sz":400,"ask_sz":100,"bid_ct":1,"ask_ct":1},{"bid_px":"235.000000000","ask_px":"252.400000000","bid_sz":100,"ask_sz":1000,"bid_ct":1,"ask_ct":1},{"bid_px":null,"ask_px":"253.650000000","bid_sz":0,"ask_sz":400,"bid_ct":0,"ask_ct":1},{"bid_px":null,"ask_px":"960.000000000","bid_sz":0,"ask_sz":25,"bid_ct":0,"ask_ct":1},{"bid_px":null,"ask_px":null,"bid_sz":0,"ask_sz":0,"bid_ct":0,"ask_ct":0},{"bid_px":null,"ask_px":null,"bid_sz":0,"ask_sz":0,"bid_ct":0,"ask_ct":0},{"bid_px":null,"ask_px":null,"bid_sz":0,"ask_sz":0,"bid_ct":0,"ask_ct":0},{"bid_px":null,"ask_px":null,"bid_sz":0,"ask_sz":0,"bid_ct":0,"ask_ct":0},{"bid_px":null,"ask_px":null,"bid_sz":0,"ask_sz":0,"bid_ct":0,"ask_ct":0},{"bid_px":null,"ask_px":null,"bid_sz":0,"ask_sz":0,"bid_ct":0,"ask_ct":0}],"symbol":"TSLA"}
{"ts_recv":"2024-11-01T08:00:01.958539201Z","hd":{"ts_event":"2024-11-01T08:00:01.958372688Z","rtype":10,"publisher_id":2,"instrument_id":16244},"action":"A","side":"B","depth":0,"price":"249.400000000","size":1000,"flags":130,"ts_in_delta":166513,"sequence":291461,"levels":[{"bid_px":"249.400000000","ask_px":"251.140000000","bid_sz":1000,"ask_sz":100,"bid_ct":1,"ask_ct":1},{"bid_px":"247.150000000","ask_px":"252.400000000","bid_sz":400,"ask_sz":1000,"bid_ct":1,"ask_ct":1},{"bid_px":"235.000000000","ask_px":"253.650000000","bid_sz":100,"ask_sz":400,"bid_ct":1,"ask_ct":1},{"bid_px":null,"ask_px":"960.000000000","bid_sz":0,"ask_sz":25,"bid_ct":0,"ask_ct":1},{"bid_px":null,"ask_px":null,"bid_sz":0,"ask_sz":0,"bid_ct":0,"ask_ct":0},{"bid_px":null,"ask_px":null,"bid_sz":0,"ask_sz":0,"bid_ct":0,"ask_ct":0},{"bid_px":null,"ask_px":null,"bid_sz":0,"ask_sz":0,"bid_ct":0,"ask_ct":0},{"bid_px":null,"ask_px":null,"bid_sz":0,"ask_sz":0,"bid_ct":0,"ask_ct":0},{"bid_px":null,"ask_px":null,"bid_sz":0,"ask_sz":0,"bid_ct":0,"ask_ct":0},{"bid_px":null,"ask_px":null,"bid_sz":0,"ask_sz":0,"bid_ct":0,"ask_ct":0}],"symbol":"TSLA"}
{"ts_recv":"2024-11-01T08:00:01.987700128Z","hd":{"ts_event":"2024-11-01T08:00:01.987534676Z","rtype":10,"publisher_id":2,"instrument_id":16244},"action":"C","side":"B","depth":0,"price":"249.400000000","size":1000,"flags":130,"ts_in_delta":165452,"sequence":291501,"levels":[{"bid_px":"247.150000000","ask_px":"251.140000000","bid_sz":400,"ask_sz":100,"bid_ct":1,"ask_ct":1},{"bid_px":"235.000000000","ask_px":"252.400000000","bid_sz":100,"ask_sz":1000,"bid_ct":1,"ask_ct":1},{"bid_px":null,"ask_px":"253.650000000","bid_sz":0,"ask_sz":400,"bid_ct":0,"ask_ct":1},{"bid_px":null,"ask_px":"960.000000000","bid_sz":0,"ask_sz":25,"bid_ct":0,"ask_ct":1},{"bid_px":null,"ask_px":null,"bid_sz":0,"ask_sz":0,"bid_ct":0,"ask_ct":0},{"bid_px":null,"ask_px":null,"bid_sz":0,"ask_sz":0,"bid_ct":0,"ask_ct":0},{"bid_px":null,"ask_px":null,"bid_sz":0,"ask_sz":0,"bid_ct":0,"ask_ct":0},{"bid_px":null,"ask_px":null,"bid_sz":0,"ask_sz":0,"bid_ct":0,"ask_ct":0},{"bid_px":null,"ask_px":null,"bid_sz":0,"ask_sz":0,"bid_ct":0,"ask_ct":0},{"bid_px":null,"ask_px":null,"bid_sz":0,"ask_sz":0,"bid_ct":0,"ask_ct":0}],"symbol":"TSLA"}
{"ts_recv":"2024-11-01T08:00:01.997110302Z","hd":{"ts_event":"2024-11-01T08:00:01.996944436Z","rtype":10,"publisher_id":2,"instrument_id":16244},"action":"A","side":"A","depth":1,"price":"251.400000000","size":1000,"flags":130,"ts_in_delta":165866,"sequence":291530,"levels":[{"bid_px":"247.150000000","ask_px":"251.140000000","bid_sz":400,"ask_sz":100,"bid_ct":1,"ask_ct":1},{"bid_px":"235.000000000","ask_px":"251.400000000","bid_sz":100,"ask_sz":1000,"bid_ct":1,"ask_ct":1},{"bid_px":null,"ask_px":"252.400000000","bid_sz":0,"ask_sz":1000,"bid_ct":0,"ask_ct":1},{"bid_px":null,"ask_px":"253.650000000","bid_sz":0,"ask_sz":400,"bid_ct":0,"ask_ct":1},{"bid_px":null,"ask_px":"960.000000000","bid_sz":0,"ask_sz":25,"bid_ct":0,"ask_ct":1},{"bid_px":null,"ask_px":null,"bid_sz":0,"ask_sz":0,"bid_ct":0,"ask_ct":0},{"bid_px":null,"ask_px":null,"bid_sz":0,"ask_sz":0,"bid_ct":0,"ask_ct":0},{"bid_px":null,"ask_px":null,"bid_sz":0,"ask_sz":0,"bid_ct":0,"ask_ct":0},{"bid_px":null,"ask_px":null,"bid_sz":0,"ask_sz":0,"bid_ct":0,"ask_ct":0},{"bid_px":null,"ask_px":null,"bid_sz":0,"ask_sz":0,"bid_ct":0,"ask_ct":0}],"symbol":"TSLA"}
{"ts_recv":"2024-11-01T08:00:01.997612898Z","hd":{"ts_event":"2024-11-01T08:00:01.997446238Z","rtype":10,"publisher_id":2,"instrument_id":16244},"action":"C","side":"A","depth":1,"price":"251.400000000","size":1000,"flags":130,"ts_in_delta":166660,"sequence":291535,"levels":[{"bid_px":"247.150000000","ask_px":"251.140000000","bid_sz":400,"ask_sz":100,"bid_ct":1,"ask_ct":1},{"bid_px":"235.000000000","ask_px":"252.400000000","bid_sz":100,"ask_sz":1000,"bid_ct":1,"ask_ct":1},{"bid_px":null,"ask_px":"253.650000000","bid_sz":0,"ask_sz":400,"bid_ct":0,"ask_ct":1},{"bid_px":null,"ask_px":"960.000000000","bid_sz":0,"ask_sz":25,"bid_ct":0,"ask_ct":1},{"bid_px":null,"ask_px":null,"bid_sz":0,"ask_sz":0,"bid_ct":0,"ask_ct":0},{"bid_px":null,"ask_px":null,"bid_sz":0,"ask_sz":0,"bid_ct":0,"ask_ct":0},{"bid_px":null,"ask_px":null,"bid_sz":0,"ask_sz":0,"bid_ct":0,"ask_ct":0},{"bid_px":null,"ask_px":null,"bid_sz":0,"ask_sz":0,"bid_ct":0,"ask_ct":0},{"bid_px":null,"ask_px":null,"bid_sz":0,"ask_sz":0,"bid_ct":0,"ask_ct":0},{"bid_px":null,"ask_px":null,"bid_sz":0,"ask_sz":0,"bid_ct":0,"ask_ct":0}],"symbol":"TSLA"}
{"ts_recv":"2024-11-01T08:00:02.025313199Z","hd":{"ts_event":"2024-11-01T08:00:02.025146947Z","rtype":10,"publisher_id":2,"instrument_id":16244},"action":"A","side":"B","depth":0,"price":"249.800000000","size":1000,"flags":130,"ts_in_delta":166252,"sequence":291575,"levels":[{"bid_px":"249.800000000","ask_px":"251.140000000","bid_sz":1000,"ask_sz":100,"bid_ct":1,"ask_ct":1},{"bid_px":"247.150000000","ask_px":"252.400000000","bid_sz":400,"ask_sz":1000,"bid_ct":1,"ask_ct":1},{"bid_px":"235.000000000","ask_px":"253.650000000","bid_sz":100,"ask_sz":400,"bid_ct":1,"ask_ct":1},{"bid_px":null,"ask_px":"960.000000000","bid_sz":0,"ask_sz":25,"bid_ct":0,"ask_ct":1},{"bid_px":null,"ask_px":null,"bid_sz":0,"ask_sz":0,"bid_ct":0,"ask_ct":0},{"bid_px":null,"ask_px":null,"bid_sz":0,"ask_sz":0,"bid_ct":0,"ask_ct":0},{"bid_px":null,"ask_px":null,"bid_sz":0,"ask_sz":0,"bid_ct":0,"ask_ct":0},{"bid_px":null,"ask_px":null,"bid_sz":0,"ask_sz":0,"bid_ct":0,"ask_ct":0},{"bid_px":null,"ask_px":null,"bid_sz":0,"ask_sz":0,"bid_ct":0,"ask_ct":0},{"bid_px":null,"ask_px":null,"bid_sz":0,"ask_sz":0,"bid_ct":0,"ask_ct":0}],"symbol":"TSLA"}
{"ts_recv":"2024-11-01T08:00:02.026542310Z","hd":{"ts_event":"2024-11-01T08:00:02.026376594Z","rtype":10,"publisher_id":2,"instrument_id":16244},"action":"C","side":"B","depth":0,"price":"249.800000000","size":1000,"flags":130,"ts_in_delta":165716,"sequence":291578,"levels":[{"bid_px":"247.150000000","ask_px":"251.140000000","bid_sz":400,"ask_sz":100,"bid_ct":1,"ask_ct":1},{"bid_px":"235.000000000","ask_px":"252.400000000","bid_sz":100,"ask_sz":1000,"bid_ct":1,"ask_ct":1},{"bid_px":null,"ask_px":"253.650000000","bid_sz":0,"ask_sz":400,"bid_ct":0,"ask_ct":1},{"bid_px":null,"ask_px":"960.000000000","bid_sz":0,"ask_sz":25,"bid_ct":0,"ask_ct":1},{"bid_px":null,"ask_px":null,"bid_sz":0,"ask_sz":0,"bid_ct":0,"ask_ct":0},{"bid_px":null,"ask_px":null,"bid_sz":0,"ask_sz":0,"bid_ct":0,"ask_ct":0},{"bid_px":null,"ask_px":null,"bid_sz":0,"ask_sz":0,"bid_ct":0,"ask_ct":0},{"bid_px":null,"ask_px":null,"bid_sz":0,"ask_sz":0,"bid_ct":0,"ask_ct":0},{"bid_px":null,"ask_px":null,"bid_sz":0,"ask_sz":0,"bid_ct":0,"ask_ct":0},{"bid_px":null,"ask_px":null,"bid_sz":0,"ask_sz":0,"bid_ct":0,"ask_ct":0}],"symbol":"TSLA"}
{"ts_recv":"2024-11-01T08:00:02.037412574Z","hd":{"ts_event":"2024-11-01T08:00:02.037246234Z","rtype":10,"publisher_id":2,"instrument_id":16244},"action":"A","side":"B","depth":0,"price":"249.800000000","size":1000,"flags":130,"ts_in_delta":166340,"sequence":291588,"levels":[{"bid_px":"249.800000000","ask_px":"251.140000000","bid_sz":1000,"ask_sz":100,"bid_ct":1,"ask_ct":1},{"bid_px":"247.150000000","ask_px":"252.400000000","bid_sz":400,"ask_sz":1000,"bid_ct":1,"ask_ct":1},{"bid_px":"235.000000000","ask_px":"253.650000000","bid_sz":100,"ask_sz":400,"bid_ct":1,"ask_ct":1},{"bid_px":null,"ask_px":"960.000000000","bid_sz":0,"ask_sz":25,"bid_ct":0,"ask_ct":1},{"bid_px":null,"ask_px":null,"bid_sz":0,"ask_sz":0,"bid_ct":0,"ask_ct":0},{"bid_px":null,"ask_px":null,"bid_sz":0,"ask_sz":0,"bid_ct":0,"ask_ct":0},{"bid_px":null,"ask_px":null,"bid_sz":0,"ask_sz":0,"bid_ct":0,"ask_ct":0},{"bid_px":null,"ask_px":null,"bid_sz":0,"ask_sz":0,"bid_ct":0,"ask_ct":0},{"bid_px":null,"ask_px":null,"bid_sz":0,"ask_sz":0,"bid_ct":0,"ask_ct":0},{"bid_px":null,"ask_px":null,"bid_sz":0,"ask_sz":0,"bid_ct":0,"ask_ct":0}],"symbol":"TSLA"}
{"ts_recv":"2024-11-01T08:00:02.059422962Z","hd":{"ts_event":"2024-11-01T08:00:02.059257397Z","rtype":10,"publisher_id":2,"instrument_id":16244},"action":"C","side":"B","depth":0,"price":"249.800000000","size":1000,"flags":130,"ts_in_delta":165565,"sequence":291627,"levels":[{"bid_px":"247.150000000","ask_px":"251.140000000","bid_sz":400,"ask_sz":100,"bid_ct":1,"ask_ct":1},{"bid_px":"235.000000000","ask_px":"252.400000000","bid_sz":100,"ask_sz":1000,"bid_ct":1,"ask_ct":1},{"bid_px":null,"ask_px":"253.650000000","bid_sz":0,"ask_sz":400,"bid_ct":0,"ask_ct":1},{"bid_px":null,"ask_px":"960.000000000","bid_sz":0,"ask_sz":25,"bid_ct":0,"ask_ct":1},{"bid_px":null,"ask_px":null,"bid_sz":0,"ask_sz":0,"bid_ct":0,"ask_ct":0},{"bid_px":null,"ask_px":null,"bid_sz":0,"ask_sz":0,"bid_ct":0,"ask_ct":0},{"bid_px":null,"ask_px":null,"bid_sz":0,"ask_sz":0,"bid_ct":0,"ask_ct":0},{"bid_px":null,"ask_px":null,"bid_sz":0,"ask_sz":0,"bid_ct":0,"ask_ct":0},{"bid_px":null,"ask_px":null,"bid_sz":0,"ask_sz":0,"bid_ct":0,"ask_ct":0},{"bid_px":null,"ask_px":null,"bid_sz":0,"ask_sz":0,"bid_ct":0,"ask_ct":0}],"symbol":"TSLA"}
{"ts_recv":"2024-11-01T08:00:02.070468260Z","hd":{"ts_event":"2024-11-01T08:00:02.070301937Z","rtype":10,"publisher_id":2,"instrument_id":16244},"action":"A","side":"B","depth":0,"price":"249.700000000","size":1000,"flags":130,"ts_in_delta":166323,"sequence":291635,"levels":[{"bid_px":"249.700000000","ask_px":"251.140000000","bid_sz":1000,"ask_sz":100,"bid_ct":1,"ask_ct":1},{"bid_px":"247.150000000","ask_px":"252.400000000","bid_sz":400,"ask_sz":1000,"bid_ct":1,"ask_ct":1},{"bid_px":"235.000000000","ask_px":"253.650000000","bid_sz":100,"ask_sz":400,"bid_ct":1,"ask_ct":1},{"bid_px":null,"ask_px":"960.000000000","bid_sz":0,"ask_sz":25,"bid_ct":0,"ask_ct":1},{"bid_px":null,"ask_px":null,"bid_sz":0,"ask_sz":0,"bid_ct":0,"ask_ct":0},{"bid_px":null,"ask_px":null,"bid_sz":0,"ask_sz":0,"bid_ct":0,"ask_ct":0},{"bid_px":null,"ask_px":null,"bid_sz":0,"ask_sz":0,"bid_ct":0,"ask_ct":0},{"bid_px":null,"ask_px":null,"bid_sz":0,"ask_sz":0,"bid_ct":0,"ask_ct":0},{"bid_px":null,"ask_px":null,"bid_sz":0,"ask_sz":0,"bid_ct":0,"ask_ct":0},{"bid_px":null,"ask_px":null,"bid_sz":0,"ask_sz":0,"bid_ct":0,"ask_ct":0}],"symbol":"TSLA"}
{"ts_recv":"2024-11-01T08:00:02.074574181Z","hd":{"ts_event":"2024-11-01T08:00:02.074408476Z","rtype":10,"publisher_id":2,"instrument_id":16244},"action":"C","side":"B","depth":0,"price":"249.700000000","size":1000,"flags":130,"ts_in_delta":165705,"sequence":291641,"levels":[{"bid_px":"247.150000000","ask_px":"251.140000000","bid_sz":400,"ask_sz":100,"bid_ct":1,"ask_ct":1},{"bid_px":"235.000000000","ask_px":"252.400000000","bid_sz":100,"ask_sz":1000,"bid_ct":1,"ask_ct":1},{"bid_px":null,"ask_px":"253.650000000","bid_sz":0,"ask_sz":400,"bid_ct":0,"ask_ct":1},{"bid_px":null,"ask_px":"960.000000000","bid_sz":0,"ask_sz":25,"bid_ct":0,"ask_ct":1},{"bid_px":null,"ask_px":null,"bid_sz":0,"ask_sz":0,"bid_ct":0,"ask_ct":0},{"bid_px":null,"ask_px":null,"bid_sz":0,"ask_sz":0,"bid_ct":0,"ask_ct":0},{"bid_px":null,"ask_px":null,"bid_sz":0,"ask_sz":0,"bid_ct":0,"ask_ct":0},{"bid_px":null,"ask_px":null,"bid_sz":0,"ask_sz":0,"bid_ct":0,"ask_ct":0},{"bid_px":null,"ask_px":null,"bid_sz":0,"ask_sz":0,"bid_ct":0,"ask_ct":0},{"bid_px":null,"ask_px":null,"bid_sz":0,"ask_sz":0,"bid_ct":0,"ask_ct":0}],"symbol":"TSLA"}
{"ts_recv":"2024-11-01T08:00:02.111309439Z","hd":{"ts_event":"2024-11-01T08:00:02.111143168Z","rtype":10,"publisher_id":2,"instrument_id":16244},"action":"A","side":"B","depth":0,"price":"249.600000000","size":1000,"flags":130,"ts_in_delta":166271,"sequence":291698,"levels":[{"bid_px":"249.600000000","ask_px":"251.140000000","bid_sz":1000,"ask_sz":100,"bid_ct":1,"ask_ct":1},{"bid_px":"247.150000000","ask_px":"252.400000000","bid_sz":400,"ask_sz":1000,"bid_ct":1,"ask_ct":1},{"bid_px":"235.000000000","ask_px":"253.650000000","bid_sz":100,"ask_sz":400,"bid_ct":1,"ask_ct":1},{"bid_px":null,"ask_px":"960.000000000","bid_sz":0,"ask_sz":25,"bid_ct":0,"ask_ct":1},{"bid_px":null,"ask_px":null,"bid_sz":0,"ask_sz":0,"bid_ct":0,"ask_ct":0},{"bid_px":null,"ask_px":null,"bid_sz":0,"ask_sz":0,"bid_ct":0,"ask_ct":0},{"bid_px":null,"ask_px":null,"bid_sz":0,"ask_sz":0,"bid_ct":0,"ask_ct":0},{"bid_px":null,"ask_px":null,"bid_sz":0,"ask_sz":0,"bid_ct":0,"ask_ct":0},{"bid_px":null,"ask_px":null,"bid_sz":0,"ask_sz":0,"bid_ct":0,"ask_ct":0},{"bid_px":null,"ask_px":null,"bid_sz":0,"ask_sz":0,"bid_ct":0,"ask_ct":0}],"symbol":"TSLA"}
{"ts_recv":"2024-11-01T08:00:02.139266720Z","hd":{"ts_event":"2024-11-01T08:00:02.139100235Z","rtype":10,"publisher_id":2,"instrument_id":16244},"action":"A","side":"B","depth":0,"price":"249.900000000","size":1000,"flags":130,"ts_in_delta":166485,"sequence":291729,"levels":[{"bid_px":"249.900000000","ask_px":"251.140000000","bid_sz":1000,"ask_sz":100,"bid_ct":1,"ask_ct":1},{"bid_px":"249.600000000","ask_px":"252.400000000","bid_sz":1000,"ask_sz":1000,"bid_ct":1,"ask_ct":1},{"bid_px":"247.150000000","ask_px":"253.650000000","bid_sz":400,"ask_sz":400,"bid_ct":1,"ask_ct":1},{"bid_px":"235.000000000","ask_px":"960.000000000","bid_sz":100,"ask_sz":25,"bid_ct":1,"ask_ct":1},{"bid_px":null,"ask_px":null,"bid_sz":0,"ask_sz":0,"bid_ct":0,"ask_ct":0},{"bid_px":null,"ask_px":null,"bid_sz":0,"ask_sz":0,"bid_ct":0,"ask_ct":0},{"bid_px":null,"ask_px":null,"bid_sz":0,"ask_sz":0,"bid_ct":0,"ask_ct":0},{"bid_px":null,"ask_px":null,"bid_sz":0,"ask_sz":0,"bid_ct":0,"ask_ct":0},{"bid_px":null,"ask_px":null,"bid_sz":0,"ask_sz":0,"bid_ct":0,"ask_ct":0},{"bid_px":null,"ask_px":null,"bid_sz":0,"ask_sz":0,"bid_ct":0,"ask_ct":0}],"symbol":"TSLA"}
{"ts_recv":"2024-11-01T08:00:02.139322548Z","hd":{"ts_event":"2024-11-01T08:00:02.139155746Z","rtype":10,"publisher_id":2,"instrument_id":16244},"action":"C","side":"B","depth":1,"price":"249.600000000","size":1000,"flags":130,"ts_in_delta":166802,"sequence":291730,"levels":[{"bid_px":"249.900000000","ask_px":"251.140000000","bid_sz":1000,"ask_sz":100,"bid_ct":1,"ask_ct":1},{"bid_px":"247.150000000","ask_px":"252.400000000","bid_sz":400,"ask_sz":1000,"bid_ct":1,"ask_ct":1},{"bid_px":"235.000000000","ask_px":"253.650000000","bid_sz":100,"ask_sz":400,"bid_ct":1,"ask_ct":1},{"bid_px":null,"ask_px":"960.000000000","bid_sz":0,"ask_sz":25,"bid_ct":0,"ask_ct":1},{"bid_px":null,"ask_px":null,"bid_sz":0,"ask_sz":0,"bid_ct":0,"ask_ct":0},{"bid_px":null,"ask_px":null,"bid_sz":0,"ask_sz":0,"bid_ct":0,"ask_ct":0},{"bid_px":null,"ask_px":null,"bid_sz":0,"ask_sz":0,"bid_ct":0,"ask_ct":0},{"bid_px":null,"ask_px":null,"bid_sz":0,"ask_sz":0,"bid_ct":0,"ask_ct":0},{"bid_px":null,"ask_px":null,"bid_sz":0,"ask_sz":0,"bid_ct":0,"ask_ct":0},{"bid_px":null,"ask_px":null,"bid_sz":0,"ask_sz":0,"bid_ct":0,"ask_ct":0}],"symbol":"TSLA"}
{"ts_recv":"2024-11-01T08:00:02.143874005Z","hd":{"ts_event":"2024-11-01T08:00:02.143707801Z","rtype":10,"publisher_id":2,"instrument_id":16244},"action":"A","side":"B","depth":3,"price":"203.000000000","size":2,"flags":130,"ts_in_delta":166204,"sequence":291748,"levels":[{"bid_px":"249.900000000","ask_px":"251.140000000","bid_sz":1000,"ask_sz":100,"bid_ct":1,"ask_ct":1},{"bid_px":"247.150000000","ask_px":"252.400000000","bid_sz":400,"ask_sz":1000,"bid_ct":1,"ask_ct":1},{"bid_px":"235.000000000","ask_px":"253.650000000","bid_sz":100,"ask_sz":400,"bid_ct":1,"ask_ct":1},{"bid_px":"203.000000000","ask_px":"960.000000000","bid_sz":2,"ask_sz":25,"bid_ct":1,"ask_ct":1},{"bid_px":null,"ask_px":null,"bid_sz":0,"ask_sz":0,"bid_ct":0,"ask_ct":0},{"bid_px":null,"ask_px":null,"bid_sz":0,"ask_sz":0,"bid_ct":0,"ask_ct":0},{"bid_px":null,"ask_px":null,"bid_sz":0,"ask_sz":0,"bid_ct":0,"ask_ct":0},{"bid_px":null,"ask_px":null,"bid_sz":0,"ask_sz":0,"bid_ct":0,"ask_ct":0},{"bid_px":null,"ask_px":null,"bid_sz":0,"ask_sz":0,"bid_ct":0,"ask_ct":0},{"bid_px":null,"ask_px":null,"bid_sz":0,"ask_sz":0,"bid_ct":0,"ask_ct":0}],"symbol":"TSLA"}
{"ts_recv":"2024-11-01T08:00:02.150347466Z","hd":{"ts_event":"2024-11-01T08:00:02.150181297Z","rtype":10,"publisher_id":2,"instrument_id":16244},"action":"A","side":"B","depth":1,"price":"248.500000000","size":1000,"flags":130,"ts_in_delta":166169,"sequence":291750,"levels":[{"bid_px":"249.900000000","ask_px":"251.140000000","bid_sz":1000,"ask_sz":100,"bid_ct":1,"ask_ct":1},{"bid_px":"248.500000000","ask_px":"252.400000000","bid_sz":1000,"ask_sz":1000,"bid_ct":1,"ask_ct":1},{"bid_px":"247.150000000","ask_px":"253.650000000","bid_sz":400,"ask_sz":400,"bid_ct":1,"ask_ct":1},{"bid_px":"235.000000000","ask_px":"960.000000000","bid_sz":100,"ask_sz":25,"bid_ct":1,"ask_ct":1},{"bid_px":"203.000000000","ask_px":null,"bid_sz":2,"ask_sz":0,"bid_ct":1,"ask_ct":0},{"bid_px":null,"ask_px":null,"bid_sz":0,"ask_sz":0,"bid_ct":0,"ask_ct":0},{"bid_px":null,"ask_px":null,"bid_sz":0,"ask_sz":0,"bid_ct":0,"ask_ct":0},{"bid_px":null,"ask_px":null,"bid_sz":0,"ask_sz":0,"bid_ct":0,"ask_ct":0},{"bid_px":null,"ask_px":null,"bid_sz":0,"ask_sz":0,"bid_ct":0,"ask_ct":0},{"bid_px":null,"ask_px":null,"bid_sz":0,"ask_sz":0,"bid_ct":0,"ask_ct":0}],"symbol":"TSLA"}
{"ts_recv":"2024-11-01T08:00:02.160208746Z","hd":{"ts_event":"2024-11-01T08:00:02.160042857Z","rtype":10,"publisher_id":2,"instrument_id":16244},"action":"C","side":"B","depth":1,"price":"248.500000000","size":1000,"flags":130,"ts_in_delta":165889,"sequence":291766,"levels":[{"bid_px":"249.900000000","ask_px":"251.140000000","bid_sz":1000,"ask_sz":100,"bid_ct":1,"ask_ct":1},{"bid_px":"247.150000000","ask_px":"252.400000000","bid_sz":400,"ask_sz":1000,"bid_ct":1,"ask_ct":1},{"bid_px":"235.000000000","ask_px":"253.650000000","bid_sz":100,"ask_sz":400,"bid_ct":1,"ask_ct":1},{"bid_px":"203.000000000","ask_px":"960.000000000","bid_sz":2,"ask_sz":25,"bid_ct":1,"ask_ct":1},{"bid_px":null,"ask_px":null,"bid_sz":0,"ask_sz":0,"bid_ct":0,"ask_ct":0},{"bid_px":null,"ask_px":null,"bid_sz":0,"ask_sz":0,"bid_ct":0,"ask_ct":0},{"bid_px":null,"ask_px":null,"bid_sz":0,"ask_sz":0,"bid_ct":0,"ask_ct":0},{"bid_px":null,"ask_px":null,"bid_sz":0,"ask_sz":0,"bid_ct":0,"ask_ct":0},{"bid_px":null,"ask_px":null,"bid_sz":0,"ask_sz":0,"bid_ct":0,"ask_ct":0},{"bid_px":null,"ask_px":null,"bid_sz":0,"ask_sz":0,"bid_ct":0,"ask_ct":0}],"symbol":"TSLA"}
{"ts_recv":"2024-11-01T08:00:02.160509269Z","hd":{"ts_event":"2024-11-01T08:00:02.160343613Z","rtype":10,"publisher_id":2,"instrument_id":16244},"action":"C","side":"B","depth":0,"price":"249.900000000","size":1000,"flags":130,"ts_in_delta":165656,"sequence":291767,"levels":[{"bid_px":"247.150000000","ask_px":"251.140000000","bid_sz":400,"ask_sz":100,"bid_ct":1,"ask_ct":1},{"bid_px":"235.000000000","ask_px":"252.400000000","bid_sz":100,"ask_sz":1000,"bid_ct":1,"ask_ct":1},{"bid_px":"203.000000000","ask_px":"253.650000000","bid_sz":2,"ask_sz":400,"bid_ct":1,"ask_ct":1},{"bid_px":null,"ask_px":"960.000000000","bid_sz":0,"ask_sz":25,"bid_ct":0,"ask_ct":1},{"bid_px":null,"ask_px":null,"bid_sz":0,"ask_sz":0,"bid_ct":0,"ask_ct":0},{"bid_px":null,"ask_px":null,"bid_sz":0,"ask_sz":0,"bid_ct":0,"ask_ct":0},{"bid_px":null,"ask_px":null,"bid_sz":0,"ask_sz":0,"bid_ct":0,"ask_ct":0},{"bid_px":null,"ask_px":null,"bid_sz":0,"ask_sz":0,"bid_ct":0,"ask_ct":0},{"bid_px":null,"ask_px":null,"bid_sz":0,"ask_sz":0,"bid_ct":0,"ask_ct":0},{"bid_px":null,"ask_px":null,"bid_sz":0,"ask_sz":0,"bid_ct":0,"ask_ct":0}],"symbol":"TSLA"}
{"ts_recv":"2024-11-01T08:00:02.171672991Z","hd":{"ts_event":"2024-11-01T08:00:02.171506732Z","rtype":10,"publisher_id":2,"instrument_id":16244},"action":"A","side":"B","depth":0,"price":"249.800000000","size":1000,"flags":130,"ts_in_delta":166259,"sequence":291778,"levels":[{"bid_px":"249.800000000","ask_px":"251.140000000","bid_sz":1000,"ask_sz":100,"bid_ct":1,"ask_ct":1},{"bid_px":"247.150000000","ask_px":"252.400000000","bid_sz":400,"ask_sz":1000,"bid_ct":1,"ask_ct":1},{"bid_px":"235.000000000","ask_px":"253.650000000","bid_sz":100,"ask_sz":400,"bid_ct":1,"ask_ct":1},{"bid_px":"203.000000000","ask_px":"960.000000000","bid_sz":2,"ask_sz":25,"bid_ct":1,"ask_ct":1},{"bid_px":null,"ask_px":null,"bid_sz":0,"ask_sz":0,"bid_ct":0,"ask_ct":0},{"bid_px":null,"ask_px":null,"bid_sz":0,"ask_sz":0,"bid_ct":0,"ask_ct":0},{"bid_px":null,"ask_px":null,"bid_sz":0,"ask_sz":0,"bid_ct":0,"ask_ct":0},{"bid_px":null,"ask_px":null,"bid_sz":0,"ask_sz":0,"bid_ct":0,"ask_ct":0},{"bid_px":null,"ask_px":null,"bid_sz":0,"ask_sz":0,"bid_ct":0,"ask_ct":0},{"bid_px":null,"ask_px":null,"bid_sz":0,"ask_sz":0,"bid_ct":0,"ask_ct":0}],"symbol":"TSLA"}
{"ts_recv":"2024-11-01T08:00:02.189343537Z","hd":{"ts_event":"2024-11-01T08:00:02.189177936Z","rtype":10,"publisher_id":2,"instrument_id":16244},"action":"C","side":"B","depth":0,"price":"249.800000000","size":1000,"flags":130,"ts_in_delta":165601,"sequence":291802,"levels":[{"bid_px":"247.150000000","ask_px":"251.140000000","bid_sz":400,"ask_sz":100,"bid_ct":1,"ask_ct":1},{"bid_px":"235.000000000","ask_px":"252.400000000","bid_sz":100,"ask_sz":1000,"bid_ct":1,"ask_ct":1},{"bid_px":"203.000000000","ask_px":"253.650000000","bid_sz":2,"ask_sz":400,"bid_ct":1,"ask_ct":1},{"bid_px":null,"ask_px":"960.000000000","bid_sz":0,"ask_sz":25,"bid_ct":0,"ask_ct":1},{"bid_px":null,"ask_px":null,"bid_sz":0,"ask_sz":0,"bid_ct":0,"ask_ct":0},{"bid_px":null,"ask_px":null,"bid_sz":0,"ask_sz":0,"bid_ct":0,"ask_ct":0},{"bid_px":null,"ask_px":null,"bid_sz":0,"ask_sz":0,"bid_ct":0,"ask_ct":0},{"bid_px":null,"ask_px":null,"bid_sz":0,"ask_sz":0,"bid_ct":0,"ask_ct":0},{"bid_px":null,"ask_px":null,"bid_sz":0,"ask_sz":0,"bid_ct":0,"ask_ct":0},{"bid_px":null,"ask_px":null,"bid_sz":0,"ask_sz":0,"bid_ct":0,"ask_ct":0}],"symbol":"TSLA"}
{"ts_recv":"2024-11-01T08:00:02.200278583Z","hd":{"ts_event":"2024-11-01T08:00:02.200112430Z","rtype":10,"publisher_id":2,"instrument_id":16244},"action":"A","side":"B","depth":0,"price":"249.700000000","size":1000,"flags":130,"ts_in_delta":166153,"sequence":291816,"levels":[{"bid_px":"249.700000000","ask_px":"251.140000000","bid_sz":1000,"ask_sz":100,"bid_ct":1,"ask_ct":1},{"bid_px":"247.150000000","ask_px":"252.400000000","bid_sz":400,"ask_sz":1000,"bid_ct":1,"ask_ct":1},{"bid_px":"235.000000000","ask_px":"253.650000000","bid_sz":100,"ask_sz":400,"bid_ct":1,"ask_ct":1},{"bid_px":"203.000000000","ask_px":"960.000000000","bid_sz":2,"ask_sz":25,"bid_ct":1,"ask_ct":1},{"bid_px":null,"ask_px":null,"bid_sz":0,"ask_sz":0,"bid_ct":0,"ask_ct":0},{"bid_px":null,"ask_px":null,"bid_sz":0,"ask_sz":0,"bid_ct":0,"ask_ct":0},{"bid_px":null,"ask_px":null,"bid_sz":0,"ask_sz":0,"bid_ct":0,"ask_ct":0},{"bid_px":null,"ask_px":null,"bid_sz":0,"ask_sz":0,"bid_ct":0,"ask_ct":0},{"bid_px":null,"ask_px":null,"bid_sz":0,"ask_sz":0,"bid_ct":0,"ask_ct":0},{"bid_px":null,"ask_px":null,"bid_sz":0,"ask_sz":0,"bid_ct":0,"ask_ct":0}],"symbol":"TSLA"}
{"ts_recv":"2024-11-01T08:00:02.306823519Z","hd":{"ts_event":"2024-11-01T08:00:02.306655672Z","rtype":10,"publisher_id":2,"instrument_id":16244},"action":"A","side":"B","depth":0,"price":"249.930000000","size":50,"flags":130,"ts_in_delta":167847,"sequence":291894,"levels":[{"bid_px":"249.930000000","ask_px":"251.140000000","bid_sz":50,"ask_sz":100,"bid_ct":1,"ask_ct":1},{"bid_px":"249.700000000","ask_px":"252.400000000","bid_sz":1000,"ask_sz":1000,"bid_ct":1,"ask_ct":1},{"bid_px":"247.150000000","ask_px":"253.650000000","bid_sz":400,"ask_sz":400,"bid_ct":1,"ask_ct":1},{"bid_px":"235.000000000","ask_px":"960.000000000","bid_sz":100,"ask_sz":25,"bid_ct":1,"ask_ct":1},{"bid_px":"203.000000000","ask_px":null,"bid_sz":2,"ask_sz":0,"bid_ct":1,"ask_ct":0},{"bid_px":null,"ask_px":null,"bid_sz":0,"ask_sz":0,"bid_ct":0,"ask_ct":0},{"bid_px":null,"ask_px":null,"bid_sz":0,"ask_sz":0,"bid_ct":0,"ask_ct":0},{"bid_px":null,"ask_px":null,"bid_sz":0,"ask_sz":0,"bid_ct":0,"ask_ct":0},{"bid_px":null,"ask_px":null,"bid_sz":0,"ask_sz":0,"bid_ct":0,"ask_ct":0},{"bid_px":null,"ask_px":null,"bid_sz":0,"ask_sz":0,"bid_ct":0,"ask_ct":0}],"symbol":"TSLA"}
{"ts_recv":"2024-11-01T08:00:02.326848147Z","hd":{"ts_event":"2024-11-01T08:00:02.326682484Z","rtype":10,"publisher_id":2,"instrument_id":16244},"action":"C","side":"B","depth":0,"price":"249.930000000","size":50,"flags":130,"ts_in_delta":165663,"sequence":291910,"levels":[{"bid_px":"249.700000000","ask_px":"251.140000000","bid_sz":1000,"ask_sz":100,"bid_ct":1,"ask_ct":1},{"bid_px":"247.150000000","ask_px":"252.400000000","bid_sz":400,"ask_sz":1000,"bid_ct":1,"ask_ct":1},{"bid_px":"235.000000000","ask_px":"253.650000000","bid_sz":100,"ask_sz":400,"bid_ct":1,"ask_ct":1},{"bid_px":"203.000000000","ask_px":"960.000000000","bid_sz":2,"ask_sz":25,"bid_ct":1,"ask_ct":1},{"bid_px":null,"ask_px":null,"bid_sz":0,"ask_sz":0,"bid_ct":0,"ask_ct":0},{"bid_px":null,"ask_px":null,"bid_sz":0,"ask_sz":0,"bid_ct":0,"ask_ct":0},{"bid_px":null,"ask_px":null,"bid_sz":0,"ask_sz":0,"bid_ct":0,"ask_ct":0},{"bid_px":null,"ask_px":null,"bid_sz":0,"ask_sz":0,"bid_ct":0,"ask_ct":0},{"bid_px":null,"ask_px":null,"bid_sz":0,"ask_sz":0,"bid_ct":0,"ask_ct":0},{"bid_px":null,"ask_px":null,"bid_sz":0,"ask_sz":0,"bid_ct":0,"ask_ct":0}],"symbol":"TSLA"}
{"ts_recv":"2024-11-01T08:00:02.429223051Z","hd":{"ts_event":"2024-11-01T08:00:02.429057207Z","rtype":10,"publisher_id":2,"instrument_id":16244},"action":"A","side":"B","depth":0,"price":"250.030000000","size":50,"flags":130,"ts_in_delta":165844,"sequence":292086,"levels":[{"bid_px":"250.030000000","ask_px":"251.140000000","bid_sz":50,"ask_sz":100,"bid_ct":1,"ask_ct":1},{"bid_px":"249.700000000","ask_px":"252.400000000","bid_sz":1000,"ask_sz":1000,"bid_ct":1,"ask_ct":1},{"bid_px":"247.150000000","ask_px":"253.650000000","bid_sz":400,"ask_sz":400,"bid_ct":1,"ask_ct":1},{"bid_px":"235.000000000","ask_px":"960.000000000","bid_sz":100,"ask_sz":25,"bid_ct":1,"ask_ct":1},{"bid_px":"203.000000000","ask_px":null,"bid_sz":2,"ask_sz":0,"bid_ct":1,"ask_ct":0},{"bid_px":null,"ask_px":null,"bid_sz":0,"ask_sz":0,"bid_ct":0,"ask_ct":0},{"bid_px":null,"ask_px":null,"bid_sz":0,"ask_sz":0,"bid_ct":0,"ask_ct":0},{"bid_px":null,"ask_px":null,"bid_sz":0,"ask_sz":0,"bid_ct":0,"ask_ct":0},{"bid_px":null,"ask_px":null,"bid_sz":0,"ask_sz":0,"bid_ct":0,"ask_ct":0},{"bid_px":null,"ask_px":null,"bid_sz":0,"ask_sz":0,"bid_ct":0,"ask_ct":0}],"symbol":"TSLA"}
{"ts_recv":"2024-11-01T08:00:02.432420114Z","hd":{"ts_event":"2024-11-01T08:00:02.432254479Z","rtype":10,"publisher_id":2,"instrument_id":16244},"action":"C","side":"B","depth":0,"price":"250.030000000","size":50,"flags":130,"ts_in_delta":165635,"sequence":292107,"levels":[{"bid_px":"249.700000000","ask_px":"251.140000000","bid_sz":1000,"ask_sz":100,"bid_ct":1,"ask_ct":1},{"bid_px":"247.150000000","ask_px":"252.400000000","bid_sz":400,"ask_sz":1000,"bid_ct":1,"ask_ct":1},{"bid_px":"235.000000000","ask_px":"253.650000000","bid_sz":100,"ask_sz":400,"bid_ct":1,"ask_ct":1},{"bid_px":"203.000000000","ask_px":"960.000000000","bid_sz":2,"ask_sz":25,"bid_ct":1,"ask_ct":1},{"bid_px":null,"ask_px":null,"bid_sz":0,"ask_sz":0,"bid_ct":0,"ask_ct":0},{"bid_px":null,"ask_px":null,"bid_sz":0,"ask_sz":0,"bid_ct":0,"ask_ct":0},{"bid_px":null,"ask_px":null,"bid_sz":0,"ask_sz":0,"bid_ct":0,"ask_ct":0},{"bid_px":null,"ask_px":null,"bid_sz":0,"ask_sz":0,"bid_ct":0,"ask_ct":0},{"bid_px":null,"ask_px":null,"bid_sz":0,"ask_sz":0,"bid_ct":0,"ask_ct":0},{"bid_px":null,"ask_px":null,"bid_sz":0,"ask_sz":0,"bid_ct":0,"ask_ct":0}],"symbol":"TSLA"}
{"ts_recv":"2024-11-01T08:00:02.432433721Z","hd":{"ts_event":"2024-11-01T08:00:02.432267658Z","rtype":10,"publisher_id":2,"instrument_id":16244},"action":"A","side":"B","depth":0,"price":"250.020000000","size":50,"flags":130,"ts_in_delta":166063,"sequence":292108,"levels":[{"bid_px":"250.020000000","ask_px":"251.140000000","bid_sz":50,"ask_sz":100,"bid_ct":1,"ask_ct":1},{"bid_px":"249.700000000","ask_px":"252.400000000","bid_sz":1000,"ask_sz":1000,"bid_ct":1,"ask_ct":1},{"bid_px":"247.150000000","ask_px":"253.650000000","bid_sz":400,"ask_sz":400,"bid_ct":1,"ask_ct":1},{"bid_px":"235.000000000","ask_px":"960.000000000","bid_sz":100,"ask_sz":25,"bid_ct":1,"ask_ct":1},{"bid_px":"203.000000000","ask_px":null,"bid_sz":2,"ask_sz":0,"bid_ct":1,"ask_ct":0},{"bid_px":null,"ask_px":null,"bid_sz":0,"ask_sz":0,"bid_ct":0,"ask_ct":0},{"bid_px":null,"ask_px":null,"bid_sz":0,"ask_sz":0,"bid_ct":0,"ask_ct":0},{"bid_px":null,"ask_px":null,"bid_sz":0,"ask_sz":0,"bid_ct":0,"ask_ct":0},{"bid_px":null,"ask_px":null,"bid_sz":0,"ask_sz":0,"bid_ct":0,"ask_ct":0},{"bid_px":null,"ask_px":null,"bid_sz":0,"ask_sz":0,"bid_ct":0,"ask_ct":0}],"symbol":"TSLA"}
{"ts_recv":"2024-11-01T08:00:02.432505603Z","hd":{"ts_event":"2024-11-01T08:00:02.432340214Z","rtype":10,"publisher_id":2,"instrument_id":16244},"action":"C","side":"B","depth":0,"price":"250.020000000","size":50,"flags":130,"ts_in_delta":165389,"sequence":292110,"levels":[{"bid_px":"249.700000000","ask_px":"251.140000000","bid_sz":1000,"ask_sz":100,"bid_ct":1,"ask_ct":1},{"bid_px":"247.150000000","ask_px":"252.400000000","bid_sz":400,"ask_sz":1000,"bid_ct":1,"ask_ct":1},{"bid_px":"235.000000000","ask_px":"253.650000000","bid_sz":100,"ask_sz":400,"bid_ct":1,"ask_ct":1},{"bid_px":"203.000000000","ask_px":"960.000000000","bid_sz":2,"ask_sz":25,"bid_ct":1,"ask_ct":1},{"bid_px":null,"ask_px":null,"bid_sz":0,"ask_sz":0,"bid_ct":0,"ask_ct":0},{"bid_px":null,"ask_px":null,"bid_sz":0,"ask_sz":0,"bid_ct":0,"ask_ct":0},{"bid_px":null,"ask_px":null,"bid_sz":0,"ask_sz":0,"bid_ct":0,"ask_ct":0},{"bid_px":null,"ask_px":null,"bid_sz":0,"ask_sz":0,"bid_ct":0,"ask_ct":0},{"bid_px":null,"ask_px":null,"bid_sz":0,"ask_sz":0,"bid_ct":0,"ask_ct":0},{"bid_px":null,"ask_px":null,"bid_sz":0,"ask_sz":0,"bid_ct":0,"ask_ct":0}],"symbol":"TSLA"}
{"ts_recv":"2024-11-01T08:00:02.432528850Z","hd":{"ts_event":"2024-11-01T08:00:02.432362700Z","rtype":10,"publisher_id":2,"instrument_id":16244},"action":"A","side":"B","depth":0,"price":"249.880000000","size":50,"flags":130,"ts_in_delta":166150,"sequence":292111,"levels":[{"bid_px":"249.880000000","ask_px":"251.140000000","bid_sz":50,"ask_sz":100,"bid_ct":1,"ask_ct":1},{"bid_px":"249.700000000","ask_px":"252.400000000","bid_sz":1000,"ask_sz":1000,"bid_ct":1,"ask_ct":1},{"bid_px":"247.150000000","ask_px":"253.650000000","bid_sz":400,"ask_sz":400,"bid_ct":1,"ask_ct":1},{"bid_px":"235.000000000","ask_px":"960.000000000","bid_sz":100,"ask_sz":25,"bid_ct":1,"ask_ct":1},{"bid_px":"203.000000000","ask_px":null,"bid_sz":2,"ask_sz":0,"bid_ct":1,"ask_ct":0},{"bid_px":null,"ask_px":null,"bid_sz":0,"ask_sz":0,"bid_ct":0,"ask_ct":0},{"bid_px":null,"ask_px":null,"bid_sz":0,"ask_sz":0,"bid_ct":0,"ask_ct":0},{"bid_px":null,"ask_px":null,"bid_sz":0,"ask_sz":0,"bid_ct":0,"ask_ct":0},{"bid_px":null,"ask_px":null,"bid_sz":0,"ask_sz":0,"bid_ct":0,"ask_ct":0},{"bid_px":null,"ask_px":null,"bid_sz":0,"ask_sz":0,"bid_ct":0,"ask_ct":0}],"symbol":"TSLA"}
{"ts_recv":"2024-11-01T08:00:02.432570044Z","hd":{"ts_event":"2024-11-01T08:00:02.432404499Z","rtype":10,"publisher_id":2,"instrument_id":16244},"action":"C","side":"B","depth":0,"price":"249.880000000","size":50,"flags":130,"ts_in_delta":165545,"sequence":292112,"levels":[{"bid_px":"249.700000000","ask_px":"251.140000000","bid_sz":1000,"ask_sz":100,"bid_ct":1,"ask_ct":1},{"bid_px":"247.150000000","ask_px":"252.400000000","bid_sz":400,"ask_sz":1000,"bid_ct":1,"ask_ct":1},{"bid_px":"235.000000000","ask_px":"253.650000000","bid_sz":100,"ask_sz":400,"bid_ct":1,"ask_ct":1},{"bid_px":"203.000000000","ask_px":"960.000000000","bid_sz":2,"ask_sz":25,"bid_ct":1,"ask_ct":1},{"bid_px":null,"ask_px":null,"bid_sz":0,"ask_sz":0,"bid_ct":0,"ask_ct":0},{"bid_px":null,"ask_px":null,"bid_sz":0,"ask_sz":0,"bid_ct":0,"ask_ct":0},{"bid_px":null,"ask_px":null,"bid_sz":0,"ask_sz":0,"bid_ct":0,"ask_ct":0},{"bid_px":null,"ask_px":null,"bid_sz":0,"ask_sz":0,"bid_ct":0,"ask_ct":0},{"bid_px":null,"ask_px":null,"bid_sz":0,"ask_sz":0,"bid_ct":0,"ask_ct":0},{"bid_px":null,"ask_px":null,"bid_sz":0,"ask_sz":0,"bid_ct":0,"ask_ct":0}],"symbol":"TSLA"}
{"ts_recv":"2024-11-01T08:00:02.432582033Z","hd":{"ts_event":"2024-11-01T08:00:02.432416301Z","rtype":10,"publisher_id":2,"instrument_id":16244},"action":"A","side":"B","depth":1,"price":"249.680000000","size":50,"flags":130,"ts_in_delta":165732,"sequence":292113,"levels":[{"bid_px":"249.700000000","ask_px":"251.140000000","bid_sz":1000,"ask_sz":100,"bid_ct":1,"ask_ct":1},{"bid_px":"249.680000000","ask_px":"252.400000000","bid_sz":50,"ask_sz":1000,"bid_ct":1,"ask_ct":1},{"bid_px":"247.150000000","ask_px":"253.650000000","bid_sz":400,"ask_sz":400,"bid_ct":1,"ask_ct":1},{"bid_px":"235.000000000","ask_px":"960.000000000","bid_sz":100,"ask_sz":25,"bid_ct":1,"ask_ct":1},{"bid_px":"203.000000000","ask_px":null,"bid_sz":2,"ask_sz":0,"bid_ct":1,"ask_ct":0},{"bid_px":null,"ask_px":null,"bid_sz":0,"ask_sz":0,"bid_ct":0,"ask_ct":0},{"bid_px":null,"ask_px":null,"bid_sz":0,"ask_sz":0,"bid_ct":0,"ask_ct":0},{"bid_px":null,"ask_px":null,"bid_sz":0,"ask_sz":0,"bid_ct":0,"ask_ct":0},{"bid_px":null,"ask_px":null,"bid_sz":0,"ask_sz":0,"bid_ct":0,"ask_ct":0},{"bid_px":null,"ask_px":null,"bid_sz":0,"ask_sz":0,"bid_ct":0,"ask_ct":0}],"symbol":"TSLA"}
{"ts_recv":"2024-11-01T08:00:02.432613196Z","hd":{"ts_event":"2024-11-01T08:00:02.432447734Z","rtype":10,"publisher_id":2,"instrument_id":16244},"action":"C","side":"B","depth":1,"price":"249.680000000","size":50,"flags":130,"ts_in_delta":165462,"sequence":292114,"levels":[{"bid_px":"249.700000000","ask_px":"251.140000000","bid_sz":1000,"ask_sz":100,"bid_ct":1,"ask_ct":1},{"bid_px":"247.150000000","ask_px":"252.400000000","bid_sz":400,"ask_sz":1000,"bid_ct":1,"ask_ct":1},{"bid_px":"235.000000000","ask_px":"253.650000000","bid_sz":100,"ask_sz":400,"bid_ct":1,"ask_ct":1},{"bid_px":"203.000000000","ask_px":"960.000000000","bid_sz":2,"ask_sz":25,"bid_ct":1,"ask_ct":1},{"bid_px":null,"ask_px":null,"bid_sz":0,"ask_sz":0,"bid_ct":0,"ask_ct":0},{"bid_px":null,"ask_px":null,"bid_sz":0,"ask_sz":0,"bid_ct":0,"ask_ct":0},{"bid_px":null,"ask_px":null,"bid_sz":0,"ask_sz":0,"bid_ct":0,"ask_ct":0},{"bid_px":null,"ask_px":null,"bid_sz":0,"ask_sz":0,"bid_ct":0,"ask_ct":0},{"bid_px":null,"ask_px":null,"bid_sz":0,"ask_sz":0,"bid_ct":0,"ask_ct":0},{"bid_px":null,"ask_px":null,"bid_sz":0,"ask_sz":0,"bid_ct":0,"ask_ct":0}],"symbol":"TSLA"}
{"ts_recv":"2024-11-01T08:00:02.508790806Z","hd":{"ts_event":"2024-11-01T08:00:02.508624558Z","rtype":10,"publisher_id":2,"instrument_id":16244},"action":"C","side":"B","depth":0,"price":"249.700000000","size":1000,"flags":130,"ts_in_delta":166248,"sequence":292194,"levels":[{"bid_px":"247.150000000","ask_px":"251.140000000","bid_sz":400,"ask_sz":100,"bid_ct":1,"ask_ct":1},{"bid_px":"235.000000000","ask_px":"252.400000000","bid_sz":100,"ask_sz":1000,"bid_ct":1,"ask_ct":1},{"bid_px":"203.000000000","ask_px":"253.650000000","bid_sz":2,"ask_sz":400,"bid_ct":1,"ask_ct":1},{"bid_px":null,"ask_px":"960.000000000","bid_sz":0,"ask_sz":25,"bid_ct":0,"ask_ct":1},{"bid_px":null,"ask_px":null,"bid_sz":0,"ask_sz":0,"bid_ct":0,"ask_ct":0},{"bid_px":null,"ask_px":null,"bid_sz":0,"ask_sz":0,"bid_ct":0,"ask_ct":0},{"bid_px":null,"ask_px":null,"bid_sz":0,"ask_sz":0,"bid_ct":0,"ask_ct":0},{"bid_px":null,"ask_px":null,"bid_sz":0,"ask_sz":0,"bid_ct":0,"ask_ct":0},{"bid_px":null,"ask_px":null,"bid_sz":0,"ask_sz":0,"bid_ct":0,"ask_ct":0},{"bid_px":null,"ask_px":null,"bid_sz":0,"ask_sz":0,"bid_ct":0,"ask_ct":0}],"symbol":"TSLA"}
{"ts_recv":"2024-11-01T08:00:02.519427424Z","hd":{"ts_event":"2024-11-01T08:00:02.519261287Z","rtype":10,"publisher_id":2,"instrument_id":16244},"action":"A","side":"B","depth":0,"price":"249.500000000","size":1000,"flags":130,"ts_in_delta":166137,"sequence":292210,"levels":[{"bid_px":"249.500000000","ask_px":"251.140000000","bid_sz":1000,"ask_sz":100,"bid_ct":1,"ask_ct":1},{"bid_px":"247.150000000","ask_px":"252.400000000","bid_sz":400,"ask_sz":1000,"bid_ct":1,"ask_ct":1},{"bid_px":"235.000000000","ask_px":"253.650000000","bid_sz":100,"ask_sz":400,"bid_ct":1,"ask_ct":1},{"bid_px":"203.000000000","ask_px":"960.000000000","bid_sz":2,"ask_sz":25,"bid_ct":1,"ask_ct":1},{"bid_px":null,"ask_px":null,"bid_sz":0,"ask_sz":0,"bid_ct":0,"ask_ct":0},{"bid_px":null,"ask_px":null,"bid_sz":0,"ask_sz":0,"bid_ct":0,"ask_ct":0},{"bid_px":null,"ask_px":null,"bid_sz":0,"ask_sz":0,"bid_ct":0,"ask_ct":0},{"bid_px":null,"ask_px":null,"bid_sz":0,"ask_sz":0,"bid_ct":0,"ask_ct":0},{"bid_px":null,"ask_px":null,"bid_sz":0,"ask_sz":0,"bid_ct":0,"ask_ct":0},{"bid_px":null,"ask_px":null,"bid_sz":0,"ask_sz":0,"bid_ct":0,"ask_ct":0}],"symbol":"TSLA"}
{"ts_recv":"2024-11-01T08:00:02.542468800Z","hd":{"ts_event":"2024-11-01T08:00:02.542301121Z","rtype":10,"publisher_id":2,"instrument_id":16244},"action":"A","side":"B","depth":0,"price":"249.700000000","size":1000,"flags":130,"ts_in_delta":167679,"sequence":292261,"levels":[{"bid_px":"249.700000000","ask_px":"251.140000000","bid_sz":1000,"ask_sz":100,"bid_ct":1,"ask_ct":1},{"bid_px":"249.500000000","ask_px":"252.400000000","bid_sz":1000,"ask_sz":1000,"bid_ct":1,"ask_ct":1},{"bid_px":"247.150000000","ask_px":"253.650000000","bid_sz":400,"ask_sz":400,"bid_ct":1,"ask_ct":1},{"bid_px":"235.000000000","ask_px":"960.000000000","bid_sz":100,"ask_sz":25,"bid_ct":1,"ask_ct":1},{"bid_px":"203.000000000","ask_px":null,"bid_sz":2,"ask_sz":0,"bid_ct":1,"ask_ct":0},{"bid_px":null,"ask_px":null,"bid_sz":0,"ask_sz":0,"bid_ct":0,"ask_ct":0},{"bid_px":null,"ask_px":null,"bid_sz":0,"ask_sz":0,"bid_ct":0,"ask_ct":0},{"bid_px":null,"ask_px":null,"bid_sz":0,"ask_sz":0,"bid_ct":0,"ask_ct":0},{"bid_px":null,"ask_px":null,"bid_sz":0,"ask_sz":0,"bid_ct":0,"ask_ct":0},{"bid_px":null,"ask_px":null,"bid_sz":0,"ask_sz":0,"bid_ct":0,"ask_ct":0}],"symbol":"TSLA"}
{"ts_recv":"2024-11-01T08:00:02.542514357Z","hd":{"ts_event":"2024-11-01T08:00:02.542348590Z","rtype":10,"publisher_id":2,"instrument_id":16244},"action":"C","side":"B","depth":1,"price":"249.500000000","size":1000,"flags":130,"ts_in_delta":165767,"sequence":292262,"levels":[{"bid_px":"249.700000000","ask_px":"251.140000000","bid_sz":1000,"ask_sz":100,"bid_ct":1,"ask_ct":1},{"bid_px":"247.150000000","ask_px":"252.400000000","bid_sz":400,"ask_sz":1000,"bid_ct":1,"ask_ct":1},{"bid_px":"235.000000000","ask_px":"253.650000000","bid_sz":100,"ask_sz":400,"bid_ct":1,"ask_ct":1},{"bid_px":"203.000000000","ask_px":"960.000000000","bid_sz":2,"ask_sz":25,"bid_ct":1,"ask_ct":1},{"bid_px":null,"ask_px":null,"bid_sz":0,"ask_sz":0,"bid_ct":0,"ask_ct":0},{"bid_px":null,"ask_px":null,"bid_sz":0,"ask_sz":0,"bid_ct":0,"ask_ct":0},{"bid_px":null,"ask_px":null,"bid_sz":0,"ask_sz":0,"bid_ct":0,"ask_ct":0},{"bid_px":null,"ask_px":null,"bid_sz":0,"ask_sz":0,"bid_ct":0,"ask_ct":0},{"bid_px":null,"ask_px":null,"bid_sz":0,"ask_sz":0,"bid_ct":0,"ask_ct":0},{"bid_px":null,"ask_px":null,"bid_sz":0,"ask_sz":0,"bid_ct":0,"ask_ct":0}],"symbol":"TSLA"}
{"ts_recv":"2024-11-01T08:00:02.546283531Z","hd":{"ts_event":"2024-11-01T08:00:02.546117257Z","rtype":10,"publisher_id":2,"instrument_id":16244},"action":"A","side":"A","depth":1,"price":"252.100000000","size":1000,"flags":130,"ts_in_delta":166274,"sequence":292268,"levels":[{"bid_px":"249.700000000","ask_px":"251.140000000","bid_sz":1000,"ask_sz":100,"bid_ct":1,"ask_ct":1},{"bid_px":"247.150000000","ask_px":"252.100000000","bid_sz":400,"ask_sz":1000,"bid_ct":1,"ask_ct":1},{"bid_px":"235.000000000","ask_px":"252.400000000","bid_sz":100,"ask_sz":1000,"bid_ct":1,"ask_ct":1},{"bid_px":"203.000000000","ask_px":"253.650000000","bid_sz":2,"ask_sz":400,"bid_ct":1,"ask_ct":1},{"bid_px":null,"ask_px":"960.000000000","bid_sz":0,"ask_sz":25,"bid_ct":0,"ask_ct":1},{"bid_px":null,"ask_px":null,"bid_sz":0,"ask_sz":0,"bid_ct":0,"ask_ct":0},{"bid_px":null,"ask_px":null,"bid_sz":0,"ask_sz":0,"bid_ct":0,"ask_ct":0},{"bid_px":null,"ask_px":null,"bid_sz":0,"ask_sz":0,"bid_ct":0,"ask_ct":0},{"bid_px":null,"ask_px":null,"bid_sz":0,"ask_sz":0,"bid_ct":0,"ask_ct":0},{"bid_px":null,"ask_px":null,"bid_sz":0,"ask_sz":0,"bid_ct":0,"ask_ct":0}],"symbol":"TSLA"}
{"ts_recv":"2024-11-01T08:00:02.546320207Z","hd":{"ts_event":"2024-11-01T08:00:02.546154333Z","rtype":10,"publisher_id":2,"instrument_id":16244},"action":"C","side":"A","depth":2,"price":"252.400000000","size":1000,"flags":130,"ts_in_delta":165874,"sequence":292269,"levels":[{"bid_px":"249.700000000","ask_px":"251.140000000","bid_sz":1000,"ask_sz":100,"bid_ct":1,"ask_ct":1},{"bid_px":"247.150000000","ask_px":"252.100000000","bid_sz":400,"ask_sz":1000,"bid_ct":1,"ask_ct":1},{"bid_px":"235.000000000","ask_px":"253.650000000","bid_sz":100,"ask_sz":400,"bid_ct":1,"ask_ct":1},{"bid_px":"203.000000000","ask_px":"960.000000000","bid_sz":2,"ask_sz":25,"bid_ct":1,"ask_ct":1},{"bid_px":null,"ask_px":null,"bid_sz":0,"ask_sz":0,"bid_ct":0,"ask_ct":0},{"bid_px":null,"ask_px":null,"bid_sz":0,"ask_sz":0,"bid_ct":0,"ask_ct":0},{"bid_px":null,"ask_px":null,"bid_sz":0,"ask_sz":0,"bid_ct":0,"ask_ct":0},{"bid_px":null,"ask_px":null,"bid_sz":0,"ask_sz":0,"bid_ct":0,"ask_ct":0},{"bid_px":null,"ask_px":null,"bid_sz":0,"ask_sz":0,"bid_ct":0,"ask_ct":0},{"bid_px":null,"ask_px":null,"bid_sz":0,"ask_sz":0,"bid_ct":0,"ask_ct":0}],"symbol":"TSLA"}
{"ts_recv":"2024-11-01T08:00:02.546605793Z","hd":{"ts_event":"2024-11-01T08:00:02.546439522Z","rtype":10,"publisher_id":2,"instrument_id":16244},"action":"A","side":"A","depth":0,"price":"251.140000000","size":100,"flags":130,"ts_in_delta":166271,"sequence":292273,"levels":[{"bid_px":"249.700000000","ask_px":"251.140000000","bid_sz":1000,"ask_sz":200,"bid_ct":1,"ask_ct":2},{"bid_px":"247.150000000","ask_px":"252.100000000","bid_sz":400,"ask_sz":1000,"bid_ct":1,"ask_ct":1},{"bid_px":"235.000000000","ask_px":"253.650000000","bid_sz":100,"ask_sz":400,"bid_ct":1,"ask_ct":1},{"bid_px":"203.000000000","ask_px":"960.000000000","bid_sz":2,"ask_sz":25,"bid_ct":1,"ask_ct":1},{"bid_px":null,"ask_px":null,"bid_sz":0,"ask_sz":0,"bid_ct":0,"ask_ct":0},{"bid_px":null,"ask_px":null,"bid_sz":0,"ask_sz":0,"bid_ct":0,"ask_ct":0},{"bid_px":null,"ask_px":null,"bid_sz":0,"ask_sz":0,"bid_ct":0,"ask_ct":0},{"bid_px":null,"ask_px":null,"bid_sz":0,"ask_sz":0,"bid_ct":0,"ask_ct":0},{"bid_px":null,"ask_px":null,"bid_sz":0,"ask_sz":0,"bid_ct":0,"ask_ct":0},{"bid_px":null,"ask_px":null,"bid_sz":0,"ask_sz":0,"bid_ct":0,"ask_ct":0}],"symbol":"TSLA"}
{"ts_recv":"2024-11-01T08:00:02.553143352Z","hd":{"ts_event":"2024-11-01T08:00:02.552977007Z","rtype":10,"publisher_id":2,"instrument_id":16244},"action":"A","side":"B","depth":1,"price":"249.300000000","size":1000,"flags":130,"ts_in_delta":166345,"sequence":292282,"levels":[{"bid_px":"249.700000000","ask_px":"251.140000000","bid_sz":1000,"ask_sz":200,"bid_ct":1,"ask_ct":2},{"bid_px":"249.300000000","ask_px":"252.100000000","bid_sz":1000,"ask_sz":1000,"bid_ct":1,"ask_ct":1},{"bid_px":"247.150000000","ask_px":"253.650000000","bid_sz":400,"ask_sz":400,"bid_ct":1,"ask_ct":1},{"bid_px":"235.000000000","ask_px":"960.000000000","bid_sz":100,"ask_sz":25,"bid_ct":1,"ask_ct":1},{"bid_px":"203.000000000","ask_px":null,"bid_sz":2,"ask_sz":0,"bid_ct":1,"ask_ct":0},{"bid_px":null,"ask_px":null,"bid_sz":0,"ask_sz":0,"bid_ct":0,"ask_ct":0},{"bid_px":null,"ask_px":null,"bid_sz":0,"ask_sz":0,"bid_ct":0,"ask_ct":0},{"bid_px":null,"ask_px":null,"bid_sz":0,"ask_sz":0,"bid_ct":0,"ask_ct":0},{"bid_px":null,"ask_px":null,"bid_sz":0,"ask_sz":0,"bid_ct":0,"ask_ct":0},{"bid_px":null,"ask_px":null,"bid_sz":0,"ask_sz":0,"bid_ct":0,"ask_ct":0}],"symbol":"TSLA"}
{"ts_recv":"2024-11-01T08:00:02.571609303Z","hd":{"ts_event":"2024-11-01T08:00:02.571443429Z","rtype":10,"publisher_id":2,"instrument_id":16244},"action":"C","side":"A","depth":1,"price":"252.100000000","size":1000,"flags":130,"ts_in_delta":165874,"sequence":292311,"levels":[{"bid_px":"249.700000000","ask_px":"251.140000000","bid_sz":1000,"ask_sz":200,"bid_ct":1,"ask_ct":2},{"bid_px":"249.300000000","ask_px":"253.650000000","bid_sz":1000,"ask_sz":400,"bid_ct":1,"ask_ct":1},{"bid_px":"247.150000000","ask_px":"960.000000000","bid_sz":400,"ask_sz":25,"bid_ct":1,"ask_ct":1},{"bid_px":"235.000000000","ask_px":null,"bid_sz":100,"ask_sz":0,"bid_ct":1,"ask_ct":0},{"bid_px":"203.000000000","ask_px":null,"bid_sz":2,"ask_sz":0,"bid_ct":1,"ask_ct":0},{"bid_px":null,"ask_px":null,"bid_sz":0,"ask_sz":0,"bid_ct":0,"ask_ct":0},{"bid_px":null,"ask_px":null,"bid_sz":0,"ask_sz":0,"bid_ct":0,"ask_ct":0},{"bid_px":null,"ask_px":null,"bid_sz":0,"ask_sz":0,"bid_ct":0,"ask_ct":0},{"bid_px":null,"ask_px":null,"bid_sz":0,"ask_sz":0,"bid_ct":0,"ask_ct":0},{"bid_px":null,"ask_px":null,"bid_sz":0,"ask_sz":0,"bid_ct":0,"ask_ct":0}],"symbol":"TSLA"}
{"ts_recv":"2024-11-01T08:00:02.578965142Z","hd":{"ts_event":"2024-11-01T08:00:02.578798865Z","rtype":10,"publisher_id":2,"instrument_id":16244},"action":"A","side":"B","depth":1,"price":"249.520000000","size":50,"flags":130,"ts_in_delta":166277,"sequence":292318,"levels":[{"bid_px":"249.700000000","ask_px":"251.140000000","bid_sz":1000,"ask_sz":200,"bid_ct":1,"ask_ct":2},{"bid_px":"249.520000000","ask_px":"253.650000000","bid_sz":50,"ask_sz":400,"bid_ct":1,"ask_ct":1},{"bid_px":"249.300000000","ask_px":"960.000000000","bid_sz":1000,"ask_sz":25,"bid_ct":1,"ask_ct":1},{"bid_px":"247.150000000","ask_px":null,"bid_sz":400,"ask_sz":0,"bid_ct":1,"ask_ct":0},{"bid_px":"235.000000000","ask_px":null,"bid_sz":100,"ask_sz":0,"bid_ct":1,"ask_ct":0},{"bid_px":"203.000000000","ask_px":null,"bid_sz":2,"ask_sz":0,"bid_ct":1,"ask_ct":0},{"bid_px":null,"ask_px":null,"bid_sz":0,"ask_sz":0,"bid_ct":0,"ask_ct":0},{"bid_px":null,"ask_px":null,"bid_sz":0,"ask_sz":0,"bid_ct":0,"ask_ct":0},{"bid_px":null,"ask_px":null,"bid_sz":0,"ask_sz":0,"bid_ct":0,"ask_ct":0},{"bid_px":null,"ask_px":null,"bid_sz":0,"ask_sz":0,"bid_ct":0,"ask_ct":0}],"symbol":"TSLA"}
{"ts_recv":"2024-11-01T08:00:02.582249857Z","hd":{"ts_event":"2024-11-01T08:00:02.582083710Z","rtype":10,"publisher_id":2,"instrument_id":16244},"action":"A","side":"A","depth":1,"price":"252.300000000","size":1000,"flags":130,"ts_in_delta":166147,"sequence":292323,"levels":[{"bid_px":"249.700000000","ask_px":"251.140000000","bid_sz":1000,"ask_sz":200,"bid_ct":1,"ask_ct":2},{"bid_px":"249.520000000","ask_px":"252.300000000","bid_sz":50,"ask_sz":1000,"bid_ct":1,"ask_ct":1},{"bid_px":"249.300000000","ask_px":"253.650000000","bid_sz":1000,"ask_sz":400,"bid_ct":1,"ask_ct":1},{"bid_px":"247.150000000","ask_px":"960.000000000","bid_sz":400,"ask_sz":25,"bid_ct":1,"ask_ct":1},{"bid_px":"235.000000000","ask_px":null,"bid_sz":100,"ask_sz":0,"bid_ct":1,"ask_ct":0},{"bid_px":"203.000000000","ask_px":null,"bid_sz":2,"ask_sz":0,"bid_ct":1,"ask_ct":0},{"bid_px":null,"ask_px":null,"bid_sz":0,"ask_sz":0,"bid_ct":0,"ask_ct":0},{"bid_px":null,"ask_px":null,"bid_sz":0,"ask_sz":0,"bid_ct":0,"ask_ct":0},{"bid_px":null,"ask_px":null,"bid_sz":0,"ask_sz":0,"bid_ct":0,"ask_ct":0},{"bid_px":null,"ask_px":null,"bid_sz":0,"ask_sz":0,"bid_ct":0,"ask_ct":0}],"symbol":"TSLA"}
{"ts_recv":"2024-11-01T08:00:02.603637970Z","hd":{"ts_event":"2024-11-01T08:00:02.603472261Z","rtype":10,"publisher_id":2,"instrument_id":16244},"action":"C","side":"B","depth":1,"price":"249.520000000","size":50,"flags":130,"ts_in_delta":165709,"sequence":292342,"levels":[{"bid_px":"249.700000000","ask_px":"251.140000000","bid_sz":1000,"ask_sz":200,"bid_ct":1,"ask_ct":2},{"bid_px":"249.300000000","ask_px":"252.300000000","bid_sz":1000,"ask_sz":1000,"bid_ct":1,"ask_ct":1},{"bid_px":"247.150000000","ask_px":"253.650000000","bid_sz":400,"ask_sz":400,"bid_ct":1,"ask_ct":1},{"bid_px":"235.000000000","ask_px":"960.000000000","bid_sz":100,"ask_sz":25,"bid_ct":1,"ask_ct":1},{"bid_px":"203.000000000","ask_px":null,"bid_sz":2,"ask_sz":0,"bid_ct":1,"ask_ct":0},{"bid_px":null,"ask_px":null,"bid_sz":0,"ask_sz":0,"bid_ct":0,"ask_ct":0},{"bid_px":null,"ask_px":null,"bid_sz":0,"ask_sz":0,"bid_ct":0,"ask_ct":0},{"bid_px":null,"ask_px":null,"bid_sz":0,"ask_sz":0,"bid_ct":0,"ask_ct":0},{"bid_px":null,"ask_px":null,"bid_sz":0,"ask_sz":0,"bid_ct":0,"ask_ct":0},{"bid_px":null,"ask_px":null,"bid_sz":0,"ask_sz":0,"bid_ct":0,"ask_ct":0}],"symbol":"TSLA"}
{"ts_recv":"2024-11-01T08:00:02.607204031Z","hd":{"ts_event":"2024-11-01T08:00:02.607037998Z","rtype":10,"publisher_id":2,"instrument_id":16244},"action":"C","side":"A","depth":0,"price":"251.140000000","size":100,"flags":130,"ts_in_delta":166033,"sequence":292348,"levels":[{"bid_px":"249.700000000","ask_px":"251.140000000","bid_sz":1000,"ask_sz":100,"bid_ct":1,"ask_ct":1},{"bid_px":"249.300000000","ask_px":"252.300000000","bid_sz":1000,"ask_sz":1000,"bid_ct":1,"ask_ct":1},{"bid_px":"247.150000000","ask_px":"253.650000000","bid_sz":400,"ask_sz":400,"bid_ct":1,"ask_ct":1},{"bid_px":"235.000000000","ask_px":"960.000000000","bid_sz":100,"ask_sz":25,"bid_ct":1,"ask_ct":1},{"bid_px":"203.000000000","ask_px":null,"bid_sz":2,"ask_sz":0,"bid_ct":1,"ask_ct":0},{"bid_px":null,"ask_px":null,"bid_sz":0,"ask_sz":0,"bid_ct":0,"ask_ct":0},{"bid_px":null,"ask_px":null,"bid_sz":0,"ask_sz":0,"bid_ct":0,"ask_ct":0},{"bid_px":null,"ask_px":null,"bid_sz":0,"ask_sz":0,"bid_ct":0,"ask_ct":0},{"bid_px":null,"ask_px":null,"bid_sz":0,"ask_sz":0,"bid_ct":0,"ask_ct":0},{"bid_px":null,"ask_px":null,"bid_sz":0,"ask_sz":0,"bid_ct":0,"ask_ct":0}],"symbol":"TSLA"}
{"ts_recv":"2024-11-01T08:00:02.607227477Z","hd":{"ts_event":"2024-11-01T08:00:02.607060809Z","rtype":10,"publisher_id":2,"instrument_id":16244},"action":"A","side":"A","depth":0,"price":"250.940000000","size":100,"flags":130,"ts_in_delta":166668,"sequence":292349,"levels":[{"bid_px":"249.700000000","ask_px":"250.940000000","bid_sz":1000,"ask_sz":100,"bid_ct":1,"ask_ct":1},{"bid_px":"249.300000000","ask_px":"252.300000000","bid_sz":1000,"ask_sz":1000,"bid_ct":1,"ask_ct":1},{"bid_px":"247.150000000","ask_px":"253.650000000","bid_sz":400,"ask_sz":400,"bid_ct":1,"ask_ct":1},{"bid_px":"235.000000000","ask_px":"960.000000000","bid_sz":100,"ask_sz":25,"bid_ct":1,"ask_ct":1},{"bid_px":"203.000000000","ask_px":null,"bid_sz":2,"ask_sz":0,"bid_ct":1,"ask_ct":0},{"bid_px":null,"ask_px":null,"bid_sz":0,"ask_sz":0,"bid_ct":0,"ask_ct":0},{"bid_px":null,"ask_px":null,"bid_sz":0,"ask_sz":0,"bid_ct":0,"ask_ct":0},{"bid_px":null,"ask_px":null,"bid_sz":0,"ask_sz":0,"bid_ct":0,"ask_ct":0},{"bid_px":null,"ask_px":null,"bid_sz":0,"ask_sz":0,"bid_ct":0,"ask_ct":0},{"bid_px":null,"ask_px":null,"bid_sz":0,"ask_sz":0,"bid_ct":0,"ask_ct":0}],"symbol":"TSLA"}
{"ts_recv":"2024-11-01T08:00:02.648988454Z","hd":{"ts_event":"2024-11-01T08:00:02.648822101Z","rtype":10,"publisher_id":2,"instrument_id":16244},"action":"A","side":"B","depth":1,"price":"249.600000000","size":1000,"flags":130,"ts_in_delta":166353,"sequence":292419,"levels":[{"bid_px":"249.700000000","ask_px":"250.940000000","bid_sz":1000,"ask_sz":100,"bid_ct":1,"ask_ct":1},{"bid_px":"249.600000000","ask_px":"252.300000000","bid_sz":1000,"ask_sz":1000,"bid_ct":1,"ask_ct":1},{"bid_px":"249.300000000","ask_px":"253.650000000","bid_sz":1000,"ask_sz":400,"bid_ct":1,"ask_ct":1},{"bid_px":"247.150000000","ask_px":"960.000000000","bid_sz":400,"ask_sz":25,"bid_ct":1,"ask_ct":1},{"bid_px":"235.000000000","ask_px":null,"bid_sz":100,"ask_sz":0,"bid_ct":1,"ask_ct":0},{"bid_px":"203.000000000","ask_px":null,"bid_sz":2,"ask_sz":0,"bid_ct":1,"ask_ct":0},{"bid_px":null,"ask_px":null,"bid_sz":0,"ask_sz":0,"bid_ct":0,"ask_ct":0},{"bid_px":null,"ask_px":null,"bid_sz":0,"ask_sz":0,"bid_ct":0,"ask_ct":0},{"bid_px":null,"ask_px":null,"bid_sz":0,"ask_sz":0,"bid_ct":0,"ask_ct":0},{"bid_px":null,"ask_px":null,"bid_sz":0,"ask_sz":0,"bid_ct":0,"ask_ct":0}],"symbol":"TSLA"}
{"ts_recv":"2024-11-01T08:00:02.649909893Z","hd":{"ts_event":"2024-11-01T08:00:02.649743714Z","rtype":10,"publisher_id":2,"instrument_id":16244},"action":"A","side":"A","depth":0,"price":"250.940000000","size":100,"flags":130,"ts_in_delta":166179,"sequence":292421,"levels":[{"bid_px":"249.700000000","ask_px":"250.940000000","bid_sz":1000,"ask_sz":200,"bid_ct":1,"ask_ct":2},{"bid_px":"249.600000000","ask_px":"252.300000000","bid_sz":1000,"ask_sz":1000,"bid_ct":1,"ask_ct":1},{"bid_px":"249.300000000","ask_px":"253.650000000","bid_sz":1000,"ask_sz":400,"bid_ct":1,"ask_ct":1},{"bid_px":"247.150000000","ask_px":"960.000000000","bid_sz":400,"ask_sz":25,"bid_ct":1,"ask_ct":1},{"bid_px":"235.000000000","ask_px":null,"bid_sz":100,"ask_sz":0,"bid_ct":1,"ask_ct":0},{"bid_px":"203.000000000","ask_px":null,"bid_sz":2,"ask_sz":0,"bid_ct":1,"ask_ct":0},{"bid_px":null,"ask_px":null,"bid_sz":0,"ask_sz":0,"bid_ct":0,"ask_ct":0},{"bid_px":null,"ask_px":null,"bid_sz":0,"ask_sz":0,"bid_ct":0,"ask_ct":0},{"bid_px":null,"ask_px":null,"bid_sz":0,"ask_sz":0,"bid_ct":0,"ask_ct":0},{"bid_px":null,"ask_px":null,"bid_sz":0,"ask_sz":0,"bid_ct":0,"ask_ct":0}],"symbol":"TSLA"}
{"ts_recv":"2024-11-01T08:00:02.659428370Z","hd":{"ts_event":"2024-11-01T08:00:02.659262625Z","rtype":10,"publisher_id":2,"instrument_id":16244},"action":"C","side":"B","depth":2,"price":"249.300000000","size":1000,"flags":130,"ts_in_delta":165745,"sequence":292453,"levels":[{"bid_px":"249.700000000","ask_px":"250.940000000","bid_sz":1000,"ask_sz":200,"bid_ct":1,"ask_ct":2},{"bid_px":"249.600000000","ask_px":"252.300000000","bid_sz":1000,"ask_sz":1000,"bid_ct":1,"ask_ct":1},{"bid_px":"247.150000000","ask_px":"253.650000000","bid_sz":400,"ask_sz":400,"bid_ct":1,"ask_ct":1},{"bid_px":"235.000000000","ask_px":"960.000000000","bid_sz":100,"ask_sz":25,"bid_ct":1,"ask_ct":1},{"bid_px":"203.000000000","ask_px":null,"bid_sz":2,"ask_sz":0,"bid_ct":1,"ask_ct":0},{"bid_px":null,"ask_px":null,"bid_sz":0,"ask_sz":0,"bid_ct":0,"ask_ct":0},{"bid_px":null,"ask_px":null,"bid_sz":0,"ask_sz":0,"bid_ct":0,"ask_ct":0},{"bid_px":null,"ask_px":null,"bid_sz":0,"ask_sz":0,"bid_ct":0,"ask_ct":0},{"bid_px":null,"ask_px":null,"bid_sz":0,"ask_sz":0,"bid_ct":0,"ask_ct":0},{"bid_px":null,"ask_px":null,"bid_sz":0,"ask_sz":0,"bid_ct":0,"ask_ct":0}],"symbol":"TSLA"}
