{"ts_recv":"2024-11-01T08:00:15.218124048Z","hd":{"ts_event":"2024-11-01T08:00:15.217957301Z","rtype":10,"publisher_id":2,"instrument_id":16244},"action":"A","side":"A","depth":4,"price":"251.200000000","size":1000,"flags":130,"ts_in_delta":166747,"sequence":323179,"levels":[{"bid_px":"250.590000000","ask_px":"250.790000000","bid_sz":7,"ask_sz":200,"bid_ct":3,"ask_ct":1},{"bid_px":"250.150000000","ask_px":"250.880000000","bid_sz":50,"ask_sz":14,"bid_ct":1,"ask_ct":1},{"bid_px":"250.000000000","ask_px":"250.940000000","bid_sz":2,"ask_sz":100,"bid_ct":2,"ask_ct":1},{"bid_px":"249.930000000","ask_px":"251.090000000","bid_sz":10,"ask_sz":100,"bid_ct":1,"ask_ct":1},{"bid_px":"249.880000000","ask_px":"251.200000000","bid_sz":4,"ask_sz":1000,"bid_ct":1,"ask_ct":1},{"bid_px":"249.850000000","ask_px":"251.450000000","bid_sz":4,"ask_sz":374,"bid_ct":1,"ask_ct":2},{"bid_px":"249.800000000","ask_px":"251.500000000","bid_sz":199,"ask_sz":10,"bid_ct":1,"ask_ct":1},{"bid_px":"249.770000000","ask_px":"252.300000000","bid_sz":50,"ask_sz":1000,"bid_ct":1,"ask_ct":1},{"bid_px":"249.500000000","ask_px":"253.350000000","bid_sz":1000,"ask_sz":23,"bid_ct":1,"ask_ct":1},{"bid_px":"249.010000000","ask_px":"253.650000000","bid_sz":3,"ask_sz":400,"bid_ct":1,"ask_ct":1}],"symbol":"TSLA"}
{"ts_recv":"2024-11-01T08:00:15.218181241Z","hd":{"ts_event":"2024-11-01T08:00:15.218015156Z","rtype":10,"publisher_id":2,"instrument_id":16244},"action":"C","side":"A","depth":7,"price":"252.300000000","size":1000,"flags":130,"ts_in_delta":166085,"sequence":323180,"levels":[{"bid_px":"250.590000000","ask_px":"250.790000000","bid_sz":7,"ask_sz":200,"bid_ct":3,"ask_ct":1},{"bid_px":"250.150000000","ask_px":"250.880000000","bid_sz":50,"ask_sz":14,"bid_ct":1,"ask_ct":1},{"bid_px":"250.000000000","ask_px":"250.940000000","bid_sz":2,"ask_sz":100,"bid_ct":2,"ask_ct":1},{"bid_px":"249.930000000","ask_px":"251.090000000","bid_sz":10,"ask_sz":100,"bid_ct":1,"ask_ct":1},{"bid_px":"249.880000000","ask_px":"251.200000000","bid_sz":4,"ask_sz":1000,"bid_ct":1,"ask_ct":1},{"bid_px":"249.850000000","ask_px":"251.450000000","bid_sz":4,"ask_sz":374,"bid_ct":1,"ask_ct":2},{"bid_px":"249.800000000","ask_px":"251.500000000","bid_sz":199,"ask_sz":10,"bid_ct":1,"ask_ct":1},{"bid_px":"249.770000000","ask_px":"253.350000000","bid_sz":50,"ask_sz":23,"bid_ct":1,"ask_ct":1},{"bid_px":"249.500000000","ask_px":"253.650000000","bid_sz":1000,"ask_sz":400,"bid_ct":1,"ask_ct":1},{"bid_px":"249.010000000","ask_px":"253.880000000","bid_sz":3,"ask_sz":8,"bid_ct":1,"ask_ct":1}],"symbol":"TSLA"}
{"ts_recv":"2024-11-01T08:00:15.620266829Z","hd":{"ts_event":"2024-11-01T08:00:15.620096684Z","rtype":10,"publisher_id":2,"instrument_id":16244},"action":"T","side":"A","depth":0,"price":"250.590000000","size":2,"flags":0,"ts_in_delta":170145,"sequence":323779,"levels":[{"bid_px":"250.590000000","ask_px":"250.790000000","bid_sz":7,"ask_sz":200,"bid_ct":3,"ask_ct":1},{"bid_px":"250.150000000","ask_px":"250.880000000","bid_sz":50,"ask_sz":14,"bid_ct":1,"ask_ct":1},{"bid_px":"250.000000000","ask_px":"250.940000000","bid_sz":2,"ask_sz":100,"bid_ct":2,"ask_ct":1},{"bid_px":"249.930000000","ask_px":"251.090000000","bid_sz":10,"ask_sz":100,"bid_ct":1,"ask_ct":1},{"bid_px":"249.880000000","ask_px":"251.200000000","bid_sz":4,"ask_sz":1000,"bid_ct":1,"ask_ct":1},{"bid_px":"249.850000000","ask_px":"251.450000000","bid_sz":4,"ask_sz":374,"bid_ct":1,"ask_ct":2},{"bid_px":"249.800000000","ask_px":"251.500000000","bid_sz":199,"ask_sz":10,"bid_ct":1,"ask_ct":1},{"bid_px":"249.770000000","ask_px":"253.350000000","bid_sz":50,"ask_sz":23,"bid_ct":1,"ask_ct":1},{"bid_px":"249.500000000","ask_px":"253.650000000","bid_sz":1000,"ask_sz":400,"bid_ct":1,"ask_ct":1},{"bid_px":"249.010000000","ask_px":"253.880000000","bid_sz":3,"ask_sz":8,"bid_ct":1,"ask_ct":1}],"symbol":"TSLA"}
{"ts_recv":"2024-11-01T08:00:15.620266829Z","hd":{"ts_event":"2024-11-01T08:00:15.620096684Z","rtype":10,"publisher_id":2,"instrument_id":16244},"action":"T","side":"A","depth":0,"price":"250.590000000","size":1,"flags":0,"ts_in_delta":170145,"sequence":323780,"levels":[{"bid_px":"250.590000000","ask_px":"250.790000000","bid_sz":5,"ask_sz":200,"bid_ct":2,"ask_ct":1},{"bid_px":"250.150000000","ask_px":"250.880000000","bid_sz":50,"ask_sz":14,"bid_ct":1,"ask_ct":1},{"bid_px":"250.000000000","ask_px":"250.940000000","bid_sz":2,"ask_sz":100,"bid_ct":2,"ask_ct":1},{"bid_px":"249.930000000","ask_px":"251.090000000","bid_sz":10,"ask_sz":100,"bid_ct":1,"ask_ct":1},{"bid_px":"249.880000000","ask_px":"251.200000000","bid_sz":4,"ask_sz":1000,"bid_ct":1,"ask_ct":1},{"bid_px":"249.850000000","ask_px":"251.450000000","bid_sz":4,"ask_sz":374,"bid_ct":1,"ask_ct":2},{"bid_px":"249.800000000","ask_px":"251.500000000","bid_sz":199,"ask_sz":10,"bid_ct":1,"ask_ct":1},{"bid_px":"249.770000000","ask_px":"253.350000000","bid_sz":50,"ask_sz":23,"bid_ct":1,"ask_ct":1},{"bid_px":"249.500000000","ask_px":"253.650000000","bid_sz":1000,"ask_sz":400,"bid_ct":1,"ask_ct":1},{"bid_px":"249.010000000","ask_px":"253.880000000","bid_sz":3,"ask_sz":8,"bid_ct":1,"ask_ct":1}],"symbol":"TSLA"}
{"ts_recv":"2024-11-01T08:00:15.620266829Z","hd":{"ts_event":"2024-11-01T08:00:15.620096684Z","rtype":10,"publisher_id":2,"instrument_id":16244},"action":"T","side":"A","depth":0,"price":"250.590000000","size":4,"flags":130,"ts_in_delta":170145,"sequence":323781,"levels":[{"bid_px":"250.590000000","ask_px":"250.790000000","bid_sz":4,"ask_sz":200,"bid_ct":1,"ask_ct":1},{"bid_px":"250.150000000","ask_px":"250.880000000","bid_sz":50,"ask_sz":14,"bid_ct":1,"ask_ct":1},{"bid_px":"250.000000000","ask_px":"250.940000000","bid_sz":2,"ask_sz":100,"bid_ct":2,"ask_ct":1},{"bid_px":"249.930000000","ask_px":"251.090000000","bid_sz":10,"ask_sz":100,"bid_ct":1,"ask_ct":1},{"bid_px":"249.880000000","ask_px":"251.200000000","bid_sz":4,"ask_sz":1000,"bid_ct":1,"ask_ct":1},{"bid_px":"249.850000000","ask_px":"251.450000000","bid_sz":4,"ask_sz":374,"bid_ct":1,"ask_ct":2},{"bid_px":"249.800000000","ask_px":"251.500000000","bid_sz":199,"ask_sz":10,"bid_ct":1,"ask_ct":1},{"bid_px":"249.770000000","ask_px":"253.350000000","bid_sz":50,"ask_sz":23,"bid_ct":1,"ask_ct":1},{"bid_px":"249.500000000","ask_px":"253.650000000","bid_sz":1000,"ask_sz":400,"bid_ct":1,"ask_ct":1},{"bid_px":"249.010000000","ask_px":"253.880000000","bid_sz":3,"ask_sz":8,"bid_ct":1,"ask_ct":1}],"symbol":"TSLA"}
{"ts_recv":"2024-11-01T08:00:15.620266829Z","hd":{"ts_event":"2024-11-01T08:00:15.620096684Z","rtype":10,"publisher_id":2,"instrument_id":16244},"action":"C","side":"B","depth":0,"price":"250.590000000","size":4,"flags":130,"ts_in_delta":170145,"sequence":323781,"levels":[{"bid_px":"250.150000000","ask_px":"250.790000000","bid_sz":50,"ask_sz":200,"bid_ct":1,"ask_ct":1},{"bid_px":"250.000000000","ask_px":"250.880000000","bid_sz":2,"ask_sz":14,"bid_ct":2,"ask_ct":1},{"bid_px":"249.930000000","ask_px":"250.940000000","bid_sz":10,"ask_sz":100,"bid_ct":1,"ask_ct":1},{"bid_px":"249.880000000","ask_px":"251.090000000","bid_sz":4,"ask_sz":100,"bid_ct":1,"ask_ct":1},{"bid_px":"249.850000000","ask_px":"251.200000000","bid_sz":4,"ask_sz":1000,"bid_ct":1,"ask_ct":1},{"bid_px":"249.800000000","ask_px":"251.450000000","bid_sz":199,"ask_sz":374,"bid_ct":1,"ask_ct":2},{"bid_px":"249.770000000","ask_px":"251.500000000","bid_sz":50,"ask_sz":10,"bid_ct":1,"ask_ct":1},{"bid_px":"249.500000000","ask_px":"253.350000000","bid_sz":1000,"ask_sz":23,"bid_ct":1,"ask_ct":1},{"bid_px":"249.010000000","ask_px":"253.650000000","bid_sz":3,"ask_sz":400,"bid_ct":1,"ask_ct":1},{"bid_px":"249.000000000","ask_px":"253.880000000","bid_sz":100,"ask_sz":8,"bid_ct":1,"ask_ct":1}],"symbol":"TSLA"}
{"ts_recv":"2024-11-01T08:00:15.620287094Z","hd":{"ts_event":"2024-11-01T08:00:15.620120276Z","rtype":10,"publisher_id":2,"instrument_id":16244},"action":"A","side":"A","depth":0,"price":"250.750000000","size":100,"flags":130,"ts_in_delta":166818,"sequence":323782,"levels":[{"bid_px":"250.150000000","ask_px":"250.750000000","bid_sz":50,"ask_sz":100,"bid_ct":1,"ask_ct":1},{"bid_px":"250.000000000","ask_px":"250.790000000","bid_sz":2,"ask_sz":200,"bid_ct":2,"ask_ct":1},{"bid_px":"249.930000000","ask_px":"250.880000000","bid_sz":10,"ask_sz":14,"bid_ct":1,"ask_ct":1},{"bid_px":"249.880000000","ask_px":"250.940000000","bid_sz":4,"ask_sz":100,"bid_ct":1,"ask_ct":1},{"bid_px":"249.850000000","ask_px":"251.090000000","bid_sz":4,"ask_sz":100,"bid_ct":1,"ask_ct":1},{"bid_px":"249.800000000","ask_px":"251.200000000","bid_sz":199,"ask_sz":1000,"bid_ct":1,"ask_ct":1},{"bid_px":"249.770000000","ask_px":"251.450000000","bid_sz":50,"ask_sz":374,"bid_ct":1,"ask_ct":2},{"bid_px":"249.500000000","ask_px":"251.500000000","bid_sz":1000,"ask_sz":10,"bid_ct":1,"ask_ct":1},{"bid_px":"249.010000000","ask_px":"253.350000000","bid_sz":3,"ask_sz":23,"bid_ct":1,"ask_ct":1},{"bid_px":"249.000000000","ask_px":"253.650000000","bid_sz":100,"ask_sz":400,"bid_ct":1,"ask_ct":1}],"symbol":"TSLA"}
{"ts_recv":"2024-11-01T08:00:15.620300756Z","hd":{"ts_event":"2024-11-01T08:00:15.620135185Z","rtype":10,"publisher_id":2,"instrument_id":16244},"action":"C","side":"A","depth":0,"price":"250.750000000","size":100,"flags":130,"ts_in_delta":165571,"sequence":323783,"levels":[{"bid_px":"250.150000000","ask_px":"250.790000000","bid_sz":50,"ask_sz":200,"bid_ct":1,"ask_ct":1},{"bid_px":"250.000000000","ask_px":"250.880000000","bid_sz":2,"ask_sz":14,"bid_ct":2,"ask_ct":1},{"bid_px":"249.930000000","ask_px":"250.940000000","bid_sz":10,"ask_sz":100,"bid_ct":1,"ask_ct":1},{"bid_px":"249.880000000","ask_px":"251.090000000","bid_sz":4,"ask_sz":100,"bid_ct":1,"ask_ct":1},{"bid_px":"249.850000000","ask_px":"251.200000000","bid_sz":4,"ask_sz":1000,"bid_ct":1,"ask_ct":1},{"bid_px":"249.800000000","ask_px":"251.450000000","bid_sz":199,"ask_sz":374,"bid_ct":1,"ask_ct":2},{"bid_px":"249.770000000","ask_px":"251.500000000","bid_sz":50,"ask_sz":10,"bid_ct":1,"ask_ct":1},{"bid_px":"249.500000000","ask_px":"253.350000000","bid_sz":1000,"ask_sz":23,"bid_ct":1,"ask_ct":1},{"bid_px":"249.010000000","ask_px":"253.650000000","bid_sz":3,"ask_sz":400,"bid_ct":1,"ask_ct":1},{"bid_px":"249.000000000","ask_px":"253.880000000","bid_sz":100,"ask_sz":8,"bid_ct":1,"ask_ct":1}],"symbol":"TSLA"}
{"ts_recv":"2024-11-01T08:00:15.620321114Z","hd":{"ts_event":"2024-11-01T08:00:15.620155302Z","rtype":10,"publisher_id":2,"instrument_id":16244},"action":"A","side":"A","depth":0,"price":"250.690000000","size":26,"flags":130,"ts_in_delta":165812,"sequence":323784,"levels":[{"bid_px":"250.150000000","ask_px":"250.690000000","bid_sz":50,"ask_sz":26,"bid_ct":1,"ask_ct":1},{"bid_px":"250.000000000","ask_px":"250.790000000","bid_sz":2,"ask_sz":200,"bid_ct":2,"ask_ct":1},{"bid_px":"249.930000000","ask_px":"250.880000000","bid_sz":10,"ask_sz":14,"bid_ct":1,"ask_ct":1},{"bid_px":"249.880000000","ask_px":"250.940000000","bid_sz":4,"ask_sz":100,"bid_ct":1,"ask_ct":1},{"bid_px":"249.850000000","ask_px":"251.090000000","bid_sz":4,"ask_sz":100,"bid_ct":1,"ask_ct":1},{"bid_px":"249.800000000","ask_px":"251.200000000","bid_sz":199,"ask_sz":1000,"bid_ct":1,"ask_ct":1},{"bid_px":"249.770000000","ask_px":"251.450000000","bid_sz":50,"ask_sz":374,"bid_ct":1,"ask_ct":2},{"bid_px":"249.500000000","ask_px":"251.500000000","bid_sz":1000,"ask_sz":10,"bid_ct":1,"ask_ct":1},{"bid_px":"249.010000000","ask_px":"253.350000000","bid_sz":3,"ask_sz":23,"bid_ct":1,"ask_ct":1},{"bid_px":"249.000000000","ask_px":"253.650000000","bid_sz":100,"ask_sz":400,"bid_ct":1,"ask_ct":1}],"symbol":"TSLA"}
{"ts_recv":"2024-11-01T08:00:15.620338152Z","hd":{"ts_event":"2024-11-01T08:00:15.620172185Z","rtype":10,"publisher_id":2,"instrument_id":16244},"action":"A","side":"A","depth":1,"price":"250.750000000","size":26,"flags":130,"ts_in_delta":165967,"sequence":323785,"levels":[{"bid_px":"250.150000000","ask_px":"250.690000000","bid_sz":50,"ask_sz":26,"bid_ct":1,"ask_ct":1},{"bid_px":"250.000000000","ask_px":"250.750000000","bid_sz":2,"ask_sz":26,"bid_ct":2,"ask_ct":1},{"bid_px":"249.930000000","ask_px":"250.790000000","bid_sz":10,"ask_sz":200,"bid_ct":1,"ask_ct":1},{"bid_px":"249.880000000","ask_px":"250.880000000","bid_sz":4,"ask_sz":14,"bid_ct":1,"ask_ct":1},{"bid_px":"249.850000000","ask_px":"250.940000000","bid_sz":4,"ask_sz":100,"bid_ct":1,"ask_ct":1},{"bid_px":"249.800000000","ask_px":"251.090000000","bid_sz":199,"ask_sz":100,"bid_ct":1,"ask_ct":1},{"bid_px":"249.770000000","ask_px":"251.200000000","bid_sz":50,"ask_sz":1000,"bid_ct":1,"ask_ct":1},{"bid_px":"249.500000000","ask_px":"251.450000000","bid_sz":1000,"ask_sz":374,"bid_ct":1,"ask_ct":2},{"bid_px":"249.010000000","ask_px":"251.500000000","bid_sz":3,"ask_sz":10,"bid_ct":1,"ask_ct":1},{"bid_px":"249.000000000","ask_px":"253.350000000","bid_sz":100,"ask_sz":23,"bid_ct":1,"ask_ct":1}],"symbol":"TSLA"}
{"ts_recv":"2024-11-01T08:00:15.620353183Z","hd":{"ts_event":"2024-11-01T08:00:15.620187110Z","rtype":10,"publisher_id":2,"instrument_id":16244},"action":"C","side":"B","depth":0,"price":"250.150000000","size":50,"flags":130,"ts_in_delta":166073,"sequence":323788,"levels":[{"bid_px":"250.000000000","ask_px":"250.690000000","bid_sz":2,"ask_sz":26,"bid_ct":2,"ask_ct":1},{"bid_px":"249.930000000","ask_px":"250.750000000","bid_sz":10,"ask_sz":26,"bid_ct":1,"ask_ct":1},{"bid_px":"249.880000000","ask_px":"250.790000000","bid_sz":4,"ask_sz":200,"bid_ct":1,"ask_ct":1},{"bid_px":"249.850000000","ask_px":"250.880000000","bid_sz":4,"ask_sz":14,"bid_ct":1,"ask_ct":1},{"bid_px":"249.800000000","ask_px":"250.940000000","bid_sz":199,"ask_sz":100,"bid_ct":1,"ask_ct":1},{"bid_px":"249.770000000","ask_px":"251.090000000","bid_sz":50,"ask_sz":100,"bid_ct":1,"ask_ct":1},{"bid_px":"249.500000000","ask_px":"251.200000000","bid_sz":1000,"ask_sz":1000,"bid_ct":1,"ask_ct":1},{"bid_px":"249.010000000","ask_px":"251.450000000","bid_sz":3,"ask_sz":374,"bid_ct":1,"ask_ct":2},{"bid_px":"249.000000000","ask_px":"251.500000000","bid_sz":100,"ask_sz":10,"bid_ct":1,"ask_ct":1},{"bid_px":"248.500000000","ask_px":"253.350000000","bid_sz":111,"ask_sz":23,"bid_ct":3,"ask_ct":1}],"symbol":"TSLA"}
{"ts_recv":"2024-11-01T08:00:15.620759338Z","hd":{"ts_event":"2024-11-01T08:00:15.620593416Z","rtype":10,"publisher_id":2,"instrument_id":16244},"action":"C","side":"B","depth":6,"price":"249.500000000","size":1000,"flags":130,"ts_in_delta":165922,"sequence":323793,"levels":[{"bid_px":"250.000000000","ask_px":"250.690000000","bid_sz":2,"ask_sz":26,"bid_ct":2,"ask_ct":1},{"bid_px":"249.930000000","ask_px":"250.750000000","bid_sz":10,"ask_sz":26,"bid_ct":1,"ask_ct":1},{"bid_px":"249.880000000","ask_px":"250.790000000","bid_sz":4,"ask_sz":200,"bid_ct":1,"ask_ct":1},{"bid_px":"249.850000000","ask_px":"250.880000000","bid_sz":4,"ask_sz":14,"bid_ct":1,"ask_ct":1},{"bid_px":"249.800000000","ask_px":"250.940000000","bid_sz":199,"ask_sz":100,"bid_ct":1,"ask_ct":1},{"bid_px":"249.770000000","ask_px":"251.090000000","bid_sz":50,"ask_sz":100,"bid_ct":1,"ask_ct":1},{"bid_px":"249.010000000","ask_px":"251.200000000","bid_sz":3,"ask_sz":1000,"bid_ct":1,"ask_ct":1},{"bid_px":"249.000000000","ask_px":"251.450000000","bid_sz":100,"ask_sz":374,"bid_ct":1,"ask_ct":2},{"bid_px":"248.500000000","ask_px":"251.500000000","bid_sz":111,"ask_sz":10,"bid_ct":3,"ask_ct":1},{"bid_px":"248.010000000","ask_px":"253.350000000","bid_sz":5,"ask_sz":23,"bid_ct":1,"ask_ct":1}],"symbol":"TSLA"}
{"ts_recv":"2024-11-01T08:00:15.631914524Z","hd":{"ts_event":"2024-11-01T08:00:15.631748291Z","rtype":10,"publisher_id":2,"instrument_id":16244},"action":"A","side":"A","depth":6,"price":"251.100000000","size":1000,"flags":130,"ts_in_delta":166233,"sequence":323800,"levels":[{"bid_px":"250.000000000","ask_px":"250.690000000","bid_sz":2,"ask_sz":26,"bid_ct":2,"ask_ct":1},{"bid_px":"249.930000000","ask_px":"250.750000000","bid_sz":10,"ask_sz":26,"bid_ct":1,"ask_ct":1},{"bid_px":"249.880000000","ask_px":"250.790000000","bid_sz":4,"ask_sz":200,"bid_ct":1,"ask_ct":1},{"bid_px":"249.850000000","ask_px":"250.880000000","bid_sz":4,"ask_sz":14,"bid_ct":1,"ask_ct":1},{"bid_px":"249.800000000","ask_px":"250.940000000","bid_sz":199,"ask_sz":100,"bid_ct":1,"ask_ct":1},{"bid_px":"249.770000000","ask_px":"251.090000000","bid_sz":50,"ask_sz":100,"bid_ct":1,"ask_ct":1},{"bid_px":"249.010000000","ask_px":"251.100000000","bid_sz":3,"ask_sz":1000,"bid_ct":1,"ask_ct":1},{"bid_px":"249.000000000","ask_px":"251.200000000","bid_sz":100,"ask_sz":1000,"bid_ct":1,"ask_ct":1},{"bid_px":"248.500000000","ask_px":"251.450000000","bid_sz":111,"ask_sz":374,"bid_ct":3,"ask_ct":2},{"bid_px":"248.010000000","ask_px":"251.500000000","bid_sz":5,"ask_sz":10,"bid_ct":1,"ask_ct":1}],"symbol":"TSLA"}
{"ts_recv":"2024-11-01T08:00:15.631970869Z","hd":{"ts_event":"2024-11-01T08:00:15.631804912Z","rtype":10,"publisher_id":2,"instrument_id":16244},"action":"C","side":"A","depth":7,"price":"251.200000000","size":1000,"flags":130,"ts_in_delta":165957,"sequence":323801,"levels":[{"bid_px":"250.000000000","ask_px":"250.690000000","bid_sz":2,"ask_sz":26,"bid_ct":2,"ask_ct":1},{"bid_px":"249.930000000","ask_px":"250.750000000","bid_sz":10,"ask_sz":26,"bid_ct":1,"ask_ct":1},{"bid_px":"249.880000000","ask_px":"250.790000000","bid_sz":4,"ask_sz":200,"bid_ct":1,"ask_ct":1},{"bid_px":"249.850000000","ask_px":"250.880000000","bid_sz":4,"ask_sz":14,"bid_ct":1,"ask_ct":1},{"bid_px":"249.800000000","ask_px":"250.940000000","bid_sz":199,"ask_sz":100,"bid_ct":1,"ask_ct":1},{"bid_px":"249.770000000","ask_px":"251.090000000","bid_sz":50,"ask_sz":100,"bid_ct":1,"ask_ct":1},{"bid_px":"249.010000000","ask_px":"251.100000000","bid_sz":3,"ask_sz":1000,"bid_ct":1,"ask_ct":1},{"bid_px":"249.000000000","ask_px":"251.450000000","bid_sz":100,"ask_sz":374,"bid_ct":1,"ask_ct":2},{"bid_px":"248.500000000","ask_px":"251.500000000","bid_sz":111,"ask_sz":10,"bid_ct":3,"ask_ct":1},{"bid_px":"248.010000000","ask_px":"253.350000000","bid_sz":5,"ask_sz":23,"bid_ct":1,"ask_ct":1}],"symbol":"TSLA"}
{"ts_recv":"2024-11-01T08:00:15.642559716Z","hd":{"ts_event":"2024-11-01T08:00:15.642393200Z","rtype":10,"publisher_id":2,"instrument_id":16244},"action":"A","side":"A","depth":9,"price":"252.700000000","size":1000,"flags":130,"ts_in_delta":166516,"sequence":323811,"levels":[{"bid_px":"250.000000000","ask_px":"250.690000000","bid_sz":2,"ask_sz":26,"bid_ct":2,"ask_ct":1},{"bid_px":"249.930000000","ask_px":"250.750000000","bid_sz":10,"ask_sz":26,"bid_ct":1,"ask_ct":1},{"bid_px":"249.880000000","ask_px":"250.790000000","bid_sz":4,"ask_sz":200,"bid_ct":1,"ask_ct":1},{"bid_px":"249.850000000","ask_px":"250.880000000","bid_sz":4,"ask_sz":14,"bid_ct":1,"ask_ct":1},{"bid_px":"249.800000000","ask_px":"250.940000000","bid_sz":199,"ask_sz":100,"bid_ct":1,"ask_ct":1},{"bid_px":"249.770000000","ask_px":"251.090000000","bid_sz":50,"ask_sz":100,"bid_ct":1,"ask_ct":1},{"bid_px":"249.010000000","ask_px":"251.100000000","bid_sz":3,"ask_sz":1000,"bid_ct":1,"ask_ct":1},{"bid_px":"249.000000000","ask_px":"251.450000000","bid_sz":100,"ask_sz":374,"bid_ct":1,"ask_ct":2},{"bid_px":"248.500000000","ask_px":"251.500000000","bid_sz":111,"ask_sz":10,"bid_ct":3,"ask_ct":1},{"bid_px":"248.010000000","ask_px":"252.700000000","bid_sz":5,"ask_sz":1000,"bid_ct":1,"ask_ct":1}],"symbol":"TSLA"}
{"ts_recv":"2024-11-01T08:00:15.657693619Z","hd":{"ts_event":"2024-11-01T08:00:15.657527530Z","rtype":10,"publisher_id":2,"instrument_id":16244},"action":"A","side":"B","depth":6,"price":"249.600000000","size":1000,"flags":130,"ts_in_delta":166089,"sequence":323817,"levels":[{"bid_px":"250.000000000","ask_px":"250.690000000","bid_sz":2,"ask_sz":26,"bid_ct":2,"ask_ct":1},{"bid_px":"249.930000000","ask_px":"250.750000000","bid_sz":10,"ask_sz":26,"bid_ct":1,"ask_ct":1},{"bid_px":"249.880000000","ask_px":"250.790000000","bid_sz":4,"ask_sz":200,"bid_ct":1,"ask_ct":1},{"bid_px":"249.850000000","ask_px":"250.880000000","bid_sz":4,"ask_sz":14,"bid_ct":1,"ask_ct":1},{"bid_px":"249.800000000","ask_px":"250.940000000","bid_sz":199,"ask_sz":100,"bid_ct":1,"ask_ct":1},{"bid_px":"249.770000000","ask_px":"251.090000000","bid_sz":50,"ask_sz":100,"bid_ct":1,"ask_ct":1},{"bid_px":"249.600000000","ask_px":"251.100000000","bid_sz":1000,"ask_sz":1000,"bid_ct":1,"ask_ct":1},{"bid_px":"249.010000000","ask_px":"251.450000000","bid_sz":3,"ask_sz":374,"bid_ct":1,"ask_ct":2},{"bid_px":"249.000000000","ask_px":"251.500000000","bid_sz":100,"ask_sz":10,"bid_ct":1,"ask_ct":1},{"bid_px":"248.500000000","ask_px":"252.700000000","bid_sz":111,"ask_sz":1000,"bid_ct":3,"ask_ct":1}],"symbol":"TSLA"}
{"ts_recv":"2024-11-01T08:00:15.720391913Z","hd":{"ts_event":"2024-11-01T08:00:15.720225897Z","rtype":10,"publisher_id":2,"instrument_id":16244},"action":"C","side":"A","depth":1,"price":"250.750000000","size":26,"flags":130,"ts_in_delta":166016,"sequence":323853,"levels":[{"bid_px":"250.000000000","ask_px":"250.690000000","bid_sz":2,"ask_sz":26,"bid_ct":2,"ask_ct":1},{"bid_px":"249.930000000","ask_px":"250.790000000","bid_sz":10,"ask_sz":200,"bid_ct":1,"ask_ct":1},{"bid_px":"249.880000000","ask_px":"250.880000000","bid_sz":4,"ask_sz":14,"bid_ct":1,"ask_ct":1},{"bid_px":"249.850000000","ask_px":"250.940000000","bid_sz":4,"ask_sz":100,"bid_ct":1,"ask_ct":1},{"bid_px":"249.800000000","ask_px":"251.090000000","bid_sz":199,"ask_sz":100,"bid_ct":1,"ask_ct":1},{"bid_px":"249.770000000","ask_px":"251.100000000","bid_sz":50,"ask_sz":1000,"bid_ct":1,"ask_ct":1},{"bid_px":"249.600000000","ask_px":"251.450000000","bid_sz":1000,"ask_sz":374,"bid_ct":1,"ask_ct":2},{"bid_px":"249.010000000","ask_px":"251.500000000","bid_sz":3,"ask_sz":10,"bid_ct":1,"ask_ct":1},{"bid_px":"249.000000000","ask_px":"252.700000000","bid_sz":100,"ask_sz":1000,"bid_ct":1,"ask_ct":1},{"bid_px":"248.500000000","ask_px":"253.350000000","bid_sz":111,"ask_sz":23,"bid_ct":3,"ask_ct":1}],"symbol":"TSLA"}
{"ts_recv":"2024-11-01T08:00:15.729982297Z","hd":{"ts_event":"2024-11-01T08:00:15.729815572Z","rtype":10,"publisher_id":2,"instrument_id":16244},"action":"A","side":"B","depth":3,"price":"249.850000000","size":50,"flags":130,"ts_in_delta":166725,"sequence":323861,"levels":[{"bid_px":"250.000000000","ask_px":"250.690000000","bid_sz":2,"ask_sz":26,"bid_ct":2,"ask_ct":1},{"bid_px":"249.930000000","ask_px":"250.790000000","bid_sz":10,"ask_sz":200,"bid_ct":1,"ask_ct":1},{"bid_px":"249.880000000","ask_px":"250.880000000","bid_sz":4,"ask_sz":14,"bid_ct":1,"ask_ct":1},{"bid_px":"249.850000000","ask_px":"250.940000000","bid_sz":54,"ask_sz":100,"bid_ct":2,"ask_ct":1},{"bid_px":"249.800000000","ask_px":"251.090000000","bid_sz":199,"ask_sz":100,"bid_ct":1,"ask_ct":1},{"bid_px":"249.770000000","ask_px":"251.100000000","bid_sz":50,"ask_sz":1000,"bid_ct":1,"ask_ct":1},{"bid_px":"249.600000000","ask_px":"251.450000000","bid_sz":1000,"ask_sz":374,"bid_ct":1,"ask_ct":2},{"bid_px":"249.010000000","ask_px":"251.500000000","bid_sz":3,"ask_sz":10,"bid_ct":1,"ask_ct":1},{"bid_px":"249.000000000","ask_px":"252.700000000","bid_sz":100,"ask_sz":1000,"bid_ct":1,"ask_ct":1},{"bid_px":"248.500000000","ask_px":"253.350000000","bid_sz":111,"ask_sz":23,"bid_ct":3,"ask_ct":1}],"symbol":"TSLA"}
{"ts_recv":"2024-11-01T08:00:15.730586219Z","hd":{"ts_event":"2024-11-01T08:00:15.730419554Z","rtype":10,"publisher_id":2,"instrument_id":16244},"action":"A","side":"B","depth":6,"price":"249.700000000","size":1000,"flags":130,"ts_in_delta":166665,"sequence":323863,"levels":[{"bid_px":"250.000000000","ask_px":"250.690000000","bid_sz":2,"ask_sz":26,"bid_ct":2,"ask_ct":1},{"bid_px":"249.930000000","ask_px":"250.790000000","bid_sz":10,"ask_sz":200,"bid_ct":1,"ask_ct":1},{"bid_px":"249.880000000","ask_px":"250.880000000","bid_sz":4,"ask_sz":14,"bid_ct":1,"ask_ct":1},{"bid_px":"249.850000000","ask_px":"250.940000000","bid_sz":54,"ask_sz":100,"bid_ct":2,"ask_ct":1},{"bid_px":"249.800000000","ask_px":"251.090000000","bid_sz":199,"ask_sz":100,"bid_ct":1,"ask_ct":1},{"bid_px":"249.770000000","ask_px":"251.100000000","bid_sz":50,"ask_sz":1000,"bid_ct":1,"ask_ct":1},{"bid_px":"249.700000000","ask_px":"251.450000000","bid_sz":1000,"ask_sz":374,"bid_ct":1,"ask_ct":2},{"bid_px":"249.600000000","ask_px":"251.500000000","bid_sz":1000,"ask_sz":10,"bid_ct":1,"ask_ct":1},{"bid_px":"249.010000000","ask_px":"252.700000000","bid_sz":3,"ask_sz":1000,"bid_ct":1,"ask_ct":1},{"bid_px":"249.000000000","ask_px":"253.350000000","bid_sz":100,"ask_sz":23,"bid_ct":1,"ask_ct":1}],"symbol":"TSLA"}
{"ts_recv":"2024-11-01T08:00:15.730657474Z","hd":{"ts_event":"2024-11-01T08:00:15.730491277Z","rtype":10,"publisher_id":2,"instrument_id":16244},"action":"A","side":"A","depth":8,"price":"252.200000000","size":1000,"flags":130,"ts_in_delta":166197,"sequence":323865,"levels":[{"bid_px":"250.000000000","ask_px":"250.690000000","bid_sz":2,"ask_sz":26,"bid_ct":2,"ask_ct":1},{"bid_px":"249.930000000","ask_px":"250.790000000","bid_sz":10,"ask_sz":200,"bid_ct":1,"ask_ct":1},{"bid_px":"249.880000000","ask_px":"250.880000000","bid_sz":4,"ask_sz":14,"bid_ct":1,"ask_ct":1},{"bid_px":"249.850000000","ask_px":"250.940000000","bid_sz":54,"ask_sz":100,"bid_ct":2,"ask_ct":1},{"bid_px":"249.800000000","ask_px":"251.090000000","bid_sz":199,"ask_sz":100,"bid_ct":1,"ask_ct":1},{"bid_px":"249.770000000","ask_px":"251.100000000","bid_sz":50,"ask_sz":1000,"bid_ct":1,"ask_ct":1},{"bid_px":"249.700000000","ask_px":"251.450000000","bid_sz":1000,"ask_sz":374,"bid_ct":1,"ask_ct":2},{"bid_px":"249.600000000","ask_px":"251.500000000","bid_sz":1000,"ask_sz":10,"bid_ct":1,"ask_ct":1},{"bid_px":"249.010000000","ask_px":"252.200000000","bid_sz":3,"ask_sz":1000,"bid_ct":1,"ask_ct":1},{"bid_px":"249.000000000","ask_px":"252.700000000","bid_sz":100,"ask_sz":1000,"bid_ct":1,"ask_ct":1}],"symbol":"TSLA"}
{"ts_recv":"2024-11-01T08:00:15.730682610Z","hd":{"ts_event":"2024-11-01T08:00:15.730516801Z","rtype":10,"publisher_id":2,"instrument_id":16244},"action":"C","side":"A","depth":9,"price":"252.700000000","size":1000,"flags":130,"ts_in_delta":165809,"sequence":323866,"levels":[{"bid_px":"250.000000000","ask_px":"250.690000000","bid_sz":2,"ask_sz":26,"bid_ct":2,"ask_ct":1},{"bid_px":"249.930000000","ask_px":"250.790000000","bid_sz":10,"ask_sz":200,"bid_ct":1,"ask_ct":1},{"bid_px":"249.880000000","ask_px":"250.880000000","bid_sz":4,"ask_sz":14,"bid_ct":1,"ask_ct":1},{"bid_px":"249.850000000","ask_px":"250.940000000","bid_sz":54,"ask_sz":100,"bid_ct":2,"ask_ct":1},{"bid_px":"249.800000000","ask_px":"251.090000000","bid_sz":199,"ask_sz":100,"bid_ct":1,"ask_ct":1},{"bid_px":"249.770000000","ask_px":"251.100000000","bid_sz":50,"ask_sz":1000,"bid_ct":1,"ask_ct":1},{"bid_px":"249.700000000","ask_px":"251.450000000","bid_sz":1000,"ask_sz":374,"bid_ct":1,"ask_ct":2},{"bid_px":"249.600000000","ask_px":"251.500000000","bid_sz":1000,"ask_sz":10,"bid_ct":1,"ask_ct":1},{"bid_px":"249.010000000","ask_px":"252.200000000","bid_sz":3,"ask_sz":1000,"bid_ct":1,"ask_ct":1},{"bid_px":"249.000000000","ask_px":"253.350000000","bid_sz":100,"ask_sz":23,"bid_ct":1,"ask_ct":1}],"symbol":"TSLA"}
{"ts_recv":"2024-11-01T08:00:15.750402676Z","hd":{"ts_event":"2024-11-01T08:00:15.750236208Z","rtype":10,"publisher_id":2,"instrument_id":16244},"action":"A","side":"B","depth":8,"price":"249.100000000","size":1000,"flags":130,"ts_in_delta":166468,"sequence":323882,"levels":[{"bid_px":"250.000000000","ask_px":"250.690000000","bid_sz":2,"ask_sz":26,"bid_ct":2,"ask_ct":1},{"bid_px":"249.930000000","ask_px":"250.790000000","bid_sz":10,"ask_sz":200,"bid_ct":1,"ask_ct":1},{"bid_px":"249.880000000","ask_px":"250.880000000","bid_sz":4,"ask_sz":14,"bid_ct":1,"ask_ct":1},{"bid_px":"249.850000000","ask_px":"250.940000000","bid_sz":54,"ask_sz":100,"bid_ct":2,"ask_ct":1},{"bid_px":"249.800000000","ask_px":"251.090000000","bid_sz":199,"ask_sz":100,"bid_ct":1,"ask_ct":1},{"bid_px":"249.770000000","ask_px":"251.100000000","bid_sz":50,"ask_sz":1000,"bid_ct":1,"ask_ct":1},{"bid_px":"249.700000000","ask_px":"251.450000000","bid_sz":1000,"ask_sz":374,"bid_ct":1,"ask_ct":2},{"bid_px":"249.600000000","ask_px":"251.500000000","bid_sz":1000,"ask_sz":10,"bid_ct":1,"ask_ct":1},{"bid_px":"249.100000000","ask_px":"252.200000000","bid_sz":1000,"ask_sz":1000,"bid_ct":1,"ask_ct":1},{"bid_px":"249.010000000","ask_px":"253.350000000","bid_sz":3,"ask_sz":23,"bid_ct":1,"ask_ct":1}],"symbol":"TSLA"}
{"ts_recv":"2024-11-01T08:00:15.773482621Z","hd":{"ts_event":"2024-11-01T08:00:15.773315620Z","rtype":10,"publisher_id":2,"instrument_id":16244},"action":"A","side":"B","depth":3,"price":"249.850000000","size":50,"flags":130,"ts_in_delta":167001,"sequence":323914,"levels":[{"bid_px":"250.000000000","ask_px":"250.690000000","bid_sz":2,"ask_sz":26,"bid_ct":2,"ask_ct":1},{"bid_px":"249.930000000","ask_px":"250.790000000","bid_sz":10,"ask_sz":200,"bid_ct":1,"ask_ct":1},{"bid_px":"249.880000000","ask_px":"250.880000000","bid_sz":4,"ask_sz":14,"bid_ct":1,"ask_ct":1},{"bid_px":"249.850000000","ask_px":"250.940000000","bid_sz":104,"ask_sz":100,"bid_ct":3,"ask_ct":1},{"bid_px":"249.800000000","ask_px":"251.090000000","bid_sz":199,"ask_sz":100,"bid_ct":1,"ask_ct":1},{"bid_px":"249.770000000","ask_px":"251.100000000","bid_sz":50,"ask_sz":1000,"bid_ct":1,"ask_ct":1},{"bid_px":"249.700000000","ask_px":"251.450000000","bid_sz":1000,"ask_sz":374,"bid_ct":1,"ask_ct":2},{"bid_px":"249.600000000","ask_px":"251.500000000","bid_sz":1000,"ask_sz":10,"bid_ct":1,"ask_ct":1},{"bid_px":"249.100000000","ask_px":"252.200000000","bid_sz":1000,"ask_sz":1000,"bid_ct":1,"ask_ct":1},{"bid_px":"249.010000000","ask_px":"253.350000000","bid_sz":3,"ask_sz":23,"bid_ct":1,"ask_ct":1}],"symbol":"TSLA"}
{"ts_recv":"2024-11-01T08:00:15.783219903Z","hd":{"ts_event":"2024-11-01T08:00:15.783054179Z","rtype":10,"publisher_id":2,"instrument_id":16244},"action":"C","side":"B","depth":3,"price":"249.850000000","size":50,"flags":130,"ts_in_delta":165724,"sequence":323923,"levels":[{"bid_px":"250.000000000","ask_px":"250.690000000","bid_sz":2,"ask_sz":26,"bid_ct":2,"ask_ct":1},{"bid_px":"249.930000000","ask_px":"250.790000000","bid_sz":10,"ask_sz":200,"bid_ct":1,"ask_ct":1},{"bid_px":"249.880000000","ask_px":"250.880000000","bid_sz":4,"ask_sz":14,"bid_ct":1,"ask_ct":1},{"bid_px":"249.850000000","ask_px":"250.940000000","bid_sz":54,"ask_sz":100,"bid_ct":2,"ask_ct":1},{"bid_px":"249.800000000","ask_px":"251.090000000","bid_sz":199,"ask_sz":100,"bid_ct":1,"ask_ct":1},{"bid_px":"249.770000000","ask_px":"251.100000000","bid_sz":50,"ask_sz":1000,"bid_ct":1,"ask_ct":1},{"bid_px":"249.700000000","ask_px":"251.450000000","bid_sz":1000,"ask_sz":374,"bid_ct":1,"ask_ct":2},{"bid_px":"249.600000000","ask_px":"251.500000000","bid_sz":1000,"ask_sz":10,"bid_ct":1,"ask_ct":1},{"bid_px":"249.100000000","ask_px":"252.200000000","bid_sz":1000,"ask_sz":1000,"bid_ct":1,"ask_ct":1},{"bid_px":"249.010000000","ask_px":"253.350000000","bid_sz":3,"ask_sz":23,"bid_ct":1,"ask_ct":1}],"symbol":"TSLA"}
{"ts_recv":"2024-11-01T08:00:15.783236584Z","hd":{"ts_event":"2024-11-01T08:00:15.783070226Z","rtype":10,"publisher_id":2,"instrument_id":16244},"action":"A","side":"B","depth":3,"price":"249.860000000","size":100,"flags":130,"ts_in_delta":166358,"sequence":323924,"levels":[{"bid_px":"250.000000000","ask_px":"250.690000000","bid_sz":2,"ask_sz":26,"bid_ct":2,"ask_ct":1},{"bid_px":"249.930000000","ask_px":"250.790000000","bid_sz":10,"ask_sz":200,"bid_ct":1,"ask_ct":1},{"bid_px":"249.880000000","ask_px":"250.880000000","bid_sz":4,"ask_sz":14,"bid_ct":1,"ask_ct":1},{"bid_px":"249.860000000","ask_px":"250.940000000","bid_sz":100,"ask_sz":100,"bid_ct":1,"ask_ct":1},{"bid_px":"249.850000000","ask_px":"251.090000000","bid_sz":4,"ask_sz":100,"bid_ct":1,"ask_ct":1},{"bid_px":"249.800000000","ask_px":"251.100000000","bid_sz":199,"ask_sz":1000,"bid_ct":1,"ask_ct":1},{"bid_px":"249.770000000","ask_px":"251.450000000","bid_sz":50,"ask_sz":374,"bid_ct":1,"ask_ct":2},{"bid_px":"249.700000000","ask_px":"251.500000000","bid_sz":1000,"ask_sz":10,"bid_ct":1,"ask_ct":1},{"bid_px":"249.600000000","ask_px":"252.200000000","bid_sz":1000,"ask_sz":1000,"bid_ct":1,"ask_ct":1},{"bid_px":"249.100000000","ask_px":"253.350000000","bid_sz":1000,"ask_sz":23,"bid_ct":1,"ask_ct":1}],"symbol":"TSLA"}
{"ts_recv":"2024-11-01T08:00:15.784120100Z","hd":{"ts_event":"2024-11-01T08:00:15.783954349Z","rtype":10,"publisher_id":2,"instrument_id":16244},"action":"C","side":"B","depth":9,"price":"249.100000000","size":1000,"flags":130,"ts_in_delta":165751,"sequence":323928,"levels":[{"bid_px":"250.000000000","ask_px":"250.690000000","bid_sz":2,"ask_sz":26,"bid_ct":2,"ask_ct":1},{"bid_px":"249.930000000","ask_px":"250.790000000","bid_sz":10,"ask_sz":200,"bid_ct":1,"ask_ct":1},{"bid_px":"249.880000000","ask_px":"250.880000000","bid_sz":4,"ask_sz":14,"bid_ct":1,"ask_ct":1},{"bid_px":"249.860000000","ask_px":"250.940000000","bid_sz":100,"ask_sz":100,"bid_ct":1,"ask_ct":1},{"bid_px":"249.850000000","ask_px":"251.090000000","bid_sz":4,"ask_sz":100,"bid_ct":1,"ask_ct":1},{"bid_px":"249.800000000","ask_px":"251.100000000","bid_sz":199,"ask_sz":1000,"bid_ct":1,"ask_ct":1},{"bid_px":"249.770000000","ask_px":"251.450000000","bid_sz":50,"ask_sz":374,"bid_ct":1,"ask_ct":2},{"bid_px":"249.700000000","ask_px":"251.500000000","bid_sz":1000,"ask_sz":10,"bid_ct":1,"ask_ct":1},{"bid_px":"249.600000000","ask_px":"252.200000000","bid_sz":1000,"ask_sz":1000,"bid_ct":1,"ask_ct":1},{"bid_px":"249.010000000","ask_px":"253.350000000","bid_sz":3,"ask_sz":23,"bid_ct":1,"ask_ct":1}],"symbol":"TSLA"}
{"ts_recv":"2024-11-01T08:00:15.824052748Z","hd":{"ts_event":"2024-11-01T08:00:15.823886497Z","rtype":10,"publisher_id":2,"instrument_id":16244},"action":"A","side":"B","depth":1,"price":"249.960000000","size":50,"flags":130,"ts_in_delta":166251,"sequence":323944,"levels":[{"bid_px":"250.000000000","ask_px":"250.690000000","bid_sz":2,"ask_sz":26,"bid_ct":2,"ask_ct":1},{"bid_px":"249.960000000","ask_px":"250.790000000","bid_sz":50,"ask_sz":200,"bid_ct":1,"ask_ct":1},{"bid_px":"249.930000000","ask_px":"250.880000000","bid_sz":10,"ask_sz":14,"bid_ct":1,"ask_ct":1},{"bid_px":"249.880000000","ask_px":"250.940000000","bid_sz":4,"ask_sz":100,"bid_ct":1,"ask_ct":1},{"bid_px":"249.850000000","ask_px":"251.090000000","bid_sz":4,"ask_sz":100,"bid_ct":1,"ask_ct":1},{"bid_px":"249.800000000","ask_px":"251.100000000","bid_sz":199,"ask_sz":1000,"bid_ct":1,"ask_ct":1},{"bid_px":"249.770000000","ask_px":"251.450000000","bid_sz":50,"ask_sz":374,"bid_ct":1,"ask_ct":2},{"bid_px":"249.700000000","ask_px":"251.500000000","bid_sz":1000,"ask_sz":10,"bid_ct":1,"ask_ct":1},{"bid_px":"249.600000000","ask_px":"252.200000000","bid_sz":1000,"ask_sz":1000,"bid_ct":1,"ask_ct":1},{"bid_px":"249.010000000","ask_px":"253.350000000","bid_sz":3,"ask_sz":23,"bid_ct":1,"ask_ct":1}],"symbol":"TSLA"}
{"ts_recv":"2024-11-01T08:00:15.870399197Z","hd":{"ts_event":"2024-11-01T08:00:15.870232935Z","rtype":10,"publisher_id":2,"instrument_id":16244},"action":"C","side":"A","depth":0,"price":"250.690000000","size":26,"flags":130,"ts_in_delta":166262,"sequence":324122,"levels":[{"bid_px":"250.000000000","ask_px":"250.790000000","bid_sz":2,"ask_sz":200,"bid_ct":2,"ask_ct":1},{"bid_px":"249.960000000","ask_px":"250.880000000","bid_sz":50,"ask_sz":14,"bid_ct":1,"ask_ct":1},{"bid_px":"249.930000000","ask_px":"250.940000000","bid_sz":10,"ask_sz":100,"bid_ct":1,"ask_ct":1},{"bid_px":"249.880000000","ask_px":"251.090000000","bid_sz":4,"ask_sz":100,"bid_ct":1,"ask_ct":1},{"bid_px":"249.850000000","ask_px":"251.100000000","bid_sz":4,"ask_sz":1000,"bid_ct":1,"ask_ct":1},{"bid_px":"249.800000000","ask_px":"251.450000000","bid_sz":199,"ask_sz":374,"bid_ct":1,"ask_ct":2},{"bid_px":"249.770000000","ask_px":"251.500000000","bid_sz":50,"ask_sz":10,"bid_ct":1,"ask_ct":1},{"bid_px":"249.700000000","ask_px":"252.200000000","bid_sz":1000,"ask_sz":1000,"bid_ct":1,"ask_ct":1},{"bid_px":"249.600000000","ask_px":"253.350000000","bid_sz":1000,"ask_sz":23,"bid_ct":1,"ask_ct":1},{"bid_px":"249.010000000","ask_px":"253.650000000","bid_sz":3,"ask_sz":400,"bid_ct":1,"ask_ct":1}],"symbol":"TSLA"}
{"ts_recv":"2024-11-01T08:00:15.880193778Z","hd":{"ts_event":"2024-11-01T08:00:15.880027628Z","rtype":10,"publisher_id":2,"instrument_id":16244},"action":"A","side":"B","depth":1,"price":"249.990000000","size":50,"flags":130,"ts_in_delta":166150,"sequence":324138,"levels":[{"bid_px":"250.000000000","ask_px":"250.790000000","bid_sz":2,"ask_sz":200,"bid_ct":2,"ask_ct":1},{"bid_px":"249.990000000","ask_px":"250.880000000","bid_sz":50,"ask_sz":14,"bid_ct":1,"ask_ct":1},{"bid_px":"249.930000000","ask_px":"250.940000000","bid_sz":10,"ask_sz":100,"bid_ct":1,"ask_ct":1},{"bid_px":"249.880000000","ask_px":"251.090000000","bid_sz":4,"ask_sz":100,"bid_ct":1,"ask_ct":1},{"bid_px":"249.850000000","ask_px":"251.100000000","bid_sz":4,"ask_sz":1000,"bid_ct":1,"ask_ct":1},{"bid_px":"249.800000000","ask_px":"251.450000000","bid_sz":199,"ask_sz":374,"bid_ct":1,"ask_ct":2},{"bid_px":"249.770000000","ask_px":"251.500000000","bid_sz":50,"ask_sz":10,"bid_ct":1,"ask_ct":1},{"bid_px":"249.700000000","ask_px":"252.200000000","bid_sz":1000,"ask_sz":1000,"bid_ct":1,"ask_ct":1},{"bid_px":"249.600000000","ask_px":"253.350000000","bid_sz":1000,"ask_sz":23,"bid_ct":1,"ask_ct":1},{"bid_px":"249.010000000","ask_px":"253.650000000","bid_sz":3,"ask_sz":400,"bid_ct":1,"ask_ct":1}],"symbol":"TSLA"}
{"ts_recv":"2024-11-01T08:00:16.094577755Z","hd":{"ts_event":"2024-11-01T08:00:16.094411748Z","rtype":10,"publisher_id":2,"instrument_id":16244},"action":"C","side":"B","depth":8,"price":"249.600000000","size":1000,"flags":130,"ts_in_delta":166007,"sequence":324905,"levels":[{"bid_px":"250.000000000","ask_px":"250.790000000","bid_sz":2,"ask_sz":200,"bid_ct":2,"ask_ct":1},{"bid_px":"249.990000000","ask_px":"250.880000000","bid_sz":50,"ask_sz":14,"bid_ct":1,"ask_ct":1},{"bid_px":"249.930000000","ask_px":"250.940000000","bid_sz":10,"ask_sz":100,"bid_ct":1,"ask_ct":1},{"bid_px":"249.880000000","ask_px":"251.090000000","bid_sz":4,"ask_sz":100,"bid_ct":1,"ask_ct":1},{"bid_px":"249.850000000","ask_px":"251.100000000","bid_sz":4,"ask_sz":1000,"bid_ct":1,"ask_ct":1},{"bid_px":"249.800000000","ask_px":"251.450000000","bid_sz":199,"ask_sz":374,"bid_ct":1,"ask_ct":2},{"bid_px":"249.770000000","ask_px":"251.500000000","bid_sz":50,"ask_sz":10,"bid_ct":1,"ask_ct":1},{"bid_px":"249.700000000","ask_px":"252.200000000","bid_sz":1000,"ask_sz":1000,"bid_ct":1,"ask_ct":1},{"bid_px":"249.010000000","ask_px":"253.350000000","bid_sz":3,"ask_sz":23,"bid_ct":1,"ask_ct":1},{"bid_px":"249.000000000","ask_px":"253.650000000","bid_sz":100,"ask_sz":400,"bid_ct":1,"ask_ct":1}],"symbol":"TSLA"}
{"ts_recv":"2024-11-01T08:00:16.117808231Z","hd":{"ts_event":"2024-11-01T08:00:16.117642394Z","rtype":10,"publisher_id":2,"instrument_id":16244},"action":"C","side":"B","depth":7,"price":"249.700000000","size":1000,"flags":130,"ts_in_delta":165837,"sequence":325017,"levels":[{"bid_px":"250.000000000","ask_px":"250.790000000","bid_sz":2,"ask_sz":200,"bid_ct":2,"ask_ct":1},{"bid_px":"249.990000000","ask_px":"250.880000000","bid_sz":50,"ask_sz":14,"bid_ct":1,"ask_ct":1},{"bid_px":"249.930000000","ask_px":"250.940000000","bid_sz":10,"ask_sz":100,"bid_ct":1,"ask_ct":1},{"bid_px":"249.880000000","ask_px":"251.090000000","bid_sz":4,"ask_sz":100,"bid_ct":1,"ask_ct":1},{"bid_px":"249.850000000","ask_px":"251.100000000","bid_sz":4,"ask_sz":1000,"bid_ct":1,"ask_ct":1},{"bid_px":"249.800000000","ask_px":"251.450000000","bid_sz":199,"ask_sz":374,"bid_ct":1,"ask_ct":2},{"bid_px":"249.770000000","ask_px":"251.500000000","bid_sz":50,"ask_sz":10,"bid_ct":1,"ask_ct":1},{"bid_px":"249.010000000","ask_px":"252.200000000","bid_sz":3,"ask_sz":1000,"bid_ct":1,"ask_ct":1},{"bid_px":"249.000000000","ask_px":"253.350000000","bid_sz":100,"ask_sz":23,"bid_ct":1,"ask_ct":1},{"bid_px":"248.500000000","ask_px":"253.650000000","bid_sz":111,"ask_sz":400,"bid_ct":3,"ask_ct":1}],"symbol":"TSLA"}
{"ts_recv":"2024-11-01T08:00:16.128244721Z","hd":{"ts_event":"2024-11-01T08:00:16.128078622Z","rtype":10,"publisher_id":2,"instrument_id":16244},"action":"A","side":"B","depth":7,"price":"249.400000000","size":1000,"flags":130,"ts_in_delta":166099,"sequence":325050,"levels":[{"bid_px":"250.000000000","ask_px":"250.790000000","bid_sz":2,"ask_sz":200,"bid_ct":2,"ask_ct":1},{"bid_px":"249.990000000","ask_px":"250.880000000","bid_sz":50,"ask_sz":14,"bid_ct":1,"ask_ct":1},{"bid_px":"249.930000000","ask_px":"250.940000000","bid_sz":10,"ask_sz":100,"bid_ct":1,"ask_ct":1},{"bid_px":"249.880000000","ask_px":"251.090000000","bid_sz":4,"ask_sz":100,"bid_ct":1,"ask_ct":1},{"bid_px":"249.850000000","ask_px":"251.100000000","bid_sz":4,"ask_sz":1000,"bid_ct":1,"ask_ct":1},{"bid_px":"249.800000000","ask_px":"251.450000000","bid_sz":199,"ask_sz":374,"bid_ct":1,"ask_ct":2},{"bid_px":"249.770000000","ask_px":"251.500000000","bid_sz":50,"ask_sz":10,"bid_ct":1,"ask_ct":1},{"bid_px":"249.400000000","ask_px":"252.200000000","bid_sz":1000,"ask_sz":1000,"bid_ct":1,"ask_ct":1},{"bid_px":"249.010000000","ask_px":"253.350000000","bid_sz":3,"ask_sz":23,"bid_ct":1,"ask_ct":1},{"bid_px":"249.000000000","ask_px":"253.650000000","bid_sz":100,"ask_sz":400,"bid_ct":1,"ask_ct":1}],"symbol":"TSLA"}
{"ts_recv":"2024-11-01T08:00:16.300584572Z","hd":{"ts_event":"2024-11-01T08:00:16.300417886Z","rtype":10,"publisher_id":2,"instrument_id":16244},"action":"A","side":"B","depth":0,"price":"250.000000000","size":100,"flags":130,"ts_in_delta":166686,"sequence":325389,"levels":[{"bid_px":"250.000000000","ask_px":"250.790000000","bid_sz":102,"ask_sz":200,"bid_ct":3,"ask_ct":1},{"bid_px":"249.930000000","ask_px":"250.880000000","bid_sz":10,"ask_sz":14,"bid_ct":1,"ask_ct":1},{"bid_px":"249.880000000","ask_px":"250.940000000","bid_sz":4,"ask_sz":100,"bid_ct":1,"ask_ct":1},{"bid_px":"249.850000000","ask_px":"251.090000000","bid_sz":4,"ask_sz":100,"bid_ct":1,"ask_ct":1},{"bid_px":"249.800000000","ask_px":"251.100000000","bid_sz":199,"ask_sz":1000,"bid_ct":1,"ask_ct":1},{"bid_px":"249.770000000","ask_px":"251.450000000","bid_sz":50,"ask_sz":374,"bid_ct":1,"ask_ct":2},{"bid_px":"249.400000000","ask_px":"251.500000000","bid_sz":1000,"ask_sz":10,"bid_ct":1,"ask_ct":1},{"bid_px":"249.010000000","ask_px":"252.200000000","bid_sz":3,"ask_sz":1000,"bid_ct":1,"ask_ct":1},{"bid_px":"249.000000000","ask_px":"253.350000000","bid_sz":100,"ask_sz":23,"bid_ct":1,"ask_ct":1},{"bid_px":"248.500000000","ask_px":"253.650000000","bid_sz":111,"ask_sz":400,"bid_ct":3,"ask_ct":1}],"symbol":"TSLA"}
{"ts_recv":"2024-11-01T08:00:16.354028352Z","hd":{"ts_event":"2024-11-01T08:00:16.353862219Z","rtype":10,"publisher_id":2,"instrument_id":16244},"action":"A","side":"B","depth":0,"price":"250.100000000","size":50,"flags":130,"ts_in_delta":166133,"sequence":325445,"levels":[{"bid_px":"250.100000000","ask_px":"250.790000000","bid_sz":50,"ask_sz":200,"bid_ct":1,"ask_ct":1},{"bid_px":"250.000000000","ask_px":"250.880000000","bid_sz":2,"ask_sz":14,"bid_ct":2,"ask_ct":1},{"bid_px":"249.930000000","ask_px":"250.940000000","bid_sz":10,"ask_sz":100,"bid_ct":1,"ask_ct":1},{"bid_px":"249.880000000","ask_px":"251.090000000","bid_sz":4,"ask_sz":100,"bid_ct":1,"ask_ct":1},{"bid_px":"249.850000000","ask_px":"251.100000000","bid_sz":4,"ask_sz":1000,"bid_ct":1,"ask_ct":1},{"bid_px":"249.800000000","ask_px":"251.450000000","bid_sz":199,"ask_sz":374,"bid_ct":1,"ask_ct":2},{"bid_px":"249.770000000","ask_px":"251.500000000","bid_sz":50,"ask_sz":10,"bid_ct":1,"ask_ct":1},{"bid_px":"249.400000000","ask_px":"252.200000000","bid_sz":1000,"ask_sz":1000,"bid_ct":1,"ask_ct":1},{"bid_px":"249.010000000","ask_px":"253.350000000","bid_sz":3,"ask_sz":23,"bid_ct":1,"ask_ct":1},{"bid_px":"249.000000000","ask_px":"253.650000000","bid_sz":100,"ask_sz":400,"bid_ct":1,"ask_ct":1}],"symbol":"TSLA"}
{"ts_recv":"2024-11-01T08:00:16.354053942Z","hd":{"ts_event":"2024-11-01T08:00:16.353887992Z","rtype":10,"publisher_id":2,"instrument_id":16244},"action":"A","side":"B","depth":0,"price":"250.100000000","size":50,"flags":130,"ts_in_delta":165950,"sequence":325446,"levels":[{"bid_px":"250.100000000","ask_px":"250.790000000","bid_sz":100,"ask_sz":200,"bid_ct":2,"ask_ct":1},{"bid_px":"250.000000000","ask_px":"250.880000000","bid_sz":2,"ask_sz":14,"bid_ct":2,"ask_ct":1},{"bid_px":"249.930000000","ask_px":"250.940000000","bid_sz":10,"ask_sz":100,"bid_ct":1,"ask_ct":1},{"bid_px":"249.880000000","ask_px":"251.090000000","bid_sz":4,"ask_sz":100,"bid_ct":1,"ask_ct":1},{"bid_px":"249.850000000","ask_px":"251.100000000","bid_sz":4,"ask_sz":1000,"bid_ct":1,"ask_ct":1},{"bid_px":"249.800000000","ask_px":"251.450000000","bid_sz":199,"ask_sz":374,"bid_ct":1,"ask_ct":2},{"bid_px":"249.770000000","ask_px":"251.500000000","bid_sz":50,"ask_sz":10,"bid_ct":1,"ask_ct":1},{"bid_px":"249.400000000","ask_px":"252.200000000","bid_sz":1000,"ask_sz":1000,"bid_ct":1,"ask_ct":1},{"bid_px":"249.010000000","ask_px":"253.350000000","bid_sz":3,"ask_sz":23,"bid_ct":1,"ask_ct":1},{"bid_px":"249.000000000","ask_px":"253.650000000","bid_sz":100,"ask_sz":400,"bid_ct":1,"ask_ct":1}],"symbol":"TSLA"}
{"ts_recv":"2024-11-01T08:00:16.405561834Z","hd":{"ts_event":"2024-11-01T08:00:16.405396007Z","rtype":10,"publisher_id":2,"instrument_id":16244},"action":"C","side":"B","depth":0,"price":"250.100000000","size":50,"flags":130,"ts_in_delta":165827,"sequence":325580,"levels":[{"bid_px":"250.100000000","ask_px":"250.790000000","bid_sz":50,"ask_sz":200,"bid_ct":1,"ask_ct":1},{"bid_px":"250.000000000","ask_px":"250.880000000","bid_sz":2,"ask_sz":14,"bid_ct":2,"ask_ct":1},{"bid_px":"249.930000000","ask_px":"250.940000000","bid_sz":10,"ask_sz":100,"bid_ct":1,"ask_ct":1},{"bid_px":"249.880000000","ask_px":"251.090000000","bid_sz":4,"ask_sz":100,"bid_ct":1,"ask_ct":1},{"bid_px":"249.850000000","ask_px":"251.100000000","bid_sz":4,"ask_sz":1000,"bid_ct":1,"ask_ct":1},{"bid_px":"249.800000000","ask_px":"251.450000000","bid_sz":199,"ask_sz":374,"bid_ct":1,"ask_ct":2},{"bid_px":"249.770000000","ask_px":"251.500000000","bid_sz":50,"ask_sz":10,"bid_ct":1,"ask_ct":1},{"bid_px":"249.400000000","ask_px":"252.200000000","bid_sz":1000,"ask_sz":1000,"bid_ct":1,"ask_ct":1},{"bid_px":"249.010000000","ask_px":"253.350000000","bid_sz":3,"ask_sz":23,"bid_ct":1,"ask_ct":1},{"bid_px":"249.000000000","ask_px":"253.650000000","bid_sz":100,"ask_sz":400,"bid_ct":1,"ask_ct":1}],"symbol":"TSLA"}
{"ts_recv":"2024-11-01T08:00:16.405576269Z","hd":{"ts_event":"2024-11-01T08:00:16.405409916Z","rtype":10,"publisher_id":2,"instrument_id":16244},"action":"A","side":"B","depth":0,"price":"250.130000000","size":50,"flags":130,"ts_in_delta":166353,"sequence":325581,"levels":[{"bid_px":"250.130000000","ask_px":"250.790000000","bid_sz":50,"ask_sz":200,"bid_ct":1,"ask_ct":1},{"bid_px":"250.000000000","ask_px":"250.880000000","bid_sz":2,"ask_sz":14,"bid_ct":2,"ask_ct":1},{"bid_px":"249.930000000","ask_px":"250.940000000","bid_sz":10,"ask_sz":100,"bid_ct":1,"ask_ct":1},{"bid_px":"249.880000000","ask_px":"251.090000000","bid_sz":4,"ask_sz":100,"bid_ct":1,"ask_ct":1},{"bid_px":"249.850000000","ask_px":"251.100000000","bid_sz":4,"ask_sz":1000,"bid_ct":1,"ask_ct":1},{"bid_px":"249.800000000","ask_px":"251.450000000","bid_sz":199,"ask_sz":374,"bid_ct":1,"ask_ct":2},{"bid_px":"249.770000000","ask_px":"251.500000000","bid_sz":50,"ask_sz":10,"bid_ct":1,"ask_ct":1},{"bid_px":"249.400000000","ask_px":"252.200000000","bid_sz":1000,"ask_sz":1000,"bid_ct":1,"ask_ct":1},{"bid_px":"249.010000000","ask_px":"253.350000000","bid_sz":3,"ask_sz":23,"bid_ct":1,"ask_ct":1},{"bid_px":"249.000000000","ask_px":"253.650000000","bid_sz":100,"ask_sz":400,"bid_ct":1,"ask_ct":1}],"symbol":"TSLA"}
{"ts_recv":"2024-11-01T08:00:16.460379702Z","hd":{"ts_event":"2024-11-01T08:00:16.460213300Z","rtype":10,"publisher_id":2,"instrument_id":16244},"action":"A","side":"B","depth":0,"price":"250.150000000","size":50,"flags":130,"ts_in_delta":166402,"sequence":325836,"levels":[{"bid_px":"250.150000000","ask_px":"250.790000000","bid_sz":50,"ask_sz":200,"bid_ct":1,"ask_ct":1},{"bid_px":"250.000000000","ask_px":"250.880000000","bid_sz":2,"ask_sz":14,"bid_ct":2,"ask_ct":1},{"bid_px":"249.930000000","ask_px":"250.940000000","bid_sz":10,"ask_sz":100,"bid_ct":1,"ask_ct":1},{"bid_px":"249.880000000","ask_px":"251.090000000","bid_sz":4,"ask_sz":100,"bid_ct":1,"ask_ct":1},{"bid_px":"249.850000000","ask_px":"251.100000000","bid_sz":4,"ask_sz":1000,"bid_ct":1,"ask_ct":1},{"bid_px":"249.800000000","ask_px":"251.450000000","bid_sz":199,"ask_sz":374,"bid_ct":1,"ask_ct":2},{"bid_px":"249.770000000","ask_px":"251.500000000","bid_sz":50,"ask_sz":10,"bid_ct":1,"ask_ct":1},{"bid_px":"249.400000000","ask_px":"252.200000000","bid_sz":1000,"ask_sz":1000,"bid_ct":1,"ask_ct":1},{"bid_px":"249.010000000","ask_px":"253.350000000","bid_sz":3,"ask_sz":23,"bid_ct":1,"ask_ct":1},{"bid_px":"249.000000000","ask_px":"253.650000000","bid_sz":100,"ask_sz":400,"bid_ct":1,"ask_ct":1}],"symbol":"TSLA"}
{"ts_recv":"2024-11-01T08:00:16.548950655Z","hd":{"ts_event":"2024-11-01T08:00:16.548784791Z","rtype":10,"publisher_id":2,"instrument_id":16244},"action":"C","side":"A","depth":7,"price":"252.200000000","size":1000,"flags":130,"ts_in_delta":165864,"sequence":325935,"levels":[{"bid_px":"250.150000000","ask_px":"250.790000000","bid_sz":50,"ask_sz":200,"bid_ct":1,"ask_ct":1},{"bid_px":"250.000000000","ask_px":"250.880000000","bid_sz":2,"ask_sz":14,"bid_ct":2,"ask_ct":1},{"bid_px":"249.930000000","ask_px":"250.940000000","bid_sz":10,"ask_sz":100,"bid_ct":1,"ask_ct":1},{"bid_px":"249.880000000","ask_px":"251.090000000","bid_sz":4,"ask_sz":100,"bid_ct":1,"ask_ct":1},{"bid_px":"249.850000000","ask_px":"251.100000000","bid_sz":4,"ask_sz":1000,"bid_ct":1,"ask_ct":1},{"bid_px":"249.800000000","ask_px":"251.450000000","bid_sz":199,"ask_sz":374,"bid_ct":1,"ask_ct":2},{"bid_px":"249.770000000","ask_px":"251.500000000","bid_sz":50,"ask_sz":10,"bid_ct":1,"ask_ct":1},{"bid_px":"249.400000000","ask_px":"253.350000000","bid_sz":1000,"ask_sz":23,"bid_ct":1,"ask_ct":1},{"bid_px":"249.010000000","ask_px":"253.650000000","bid_sz":3,"ask_sz":400,"bid_ct":1,"ask_ct":1},{"bid_px":"249.000000000","ask_px":"253.880000000","bid_sz":100,"ask_sz":8,"bid_ct":1,"ask_ct":1}],"symbol":"TSLA"}
{"ts_recv":"2024-11-01T08:00:16.559669274Z","hd":{"ts_event":"2024-11-01T08:00:16.559503246Z","rtype":10,"publisher_id":2,"instrument_id":16244},"action":"A","side":"A","depth":7,"price":"252.700000000","size":1000,"flags":130,"ts_in_delta":166028,"sequence":325993,"levels":[{"bid_px":"250.150000000","ask_px":"250.790000000","bid_sz":50,"ask_sz":200,"bid_ct":1,"ask_ct":1},{"bid_px":"250.000000000","ask_px":"250.880000000","bid_sz":2,"ask_sz":14,"bid_ct":2,"ask_ct":1},{"bid_px":"249.930000000","ask_px":"250.940000000","bid_sz":10,"ask_sz":100,"bid_ct":1,"ask_ct":1},{"bid_px":"249.880000000","ask_px":"251.090000000","bid_sz":4,"ask_sz":100,"bid_ct":1,"ask_ct":1},{"bid_px":"249.850000000","ask_px":"251.100000000","bid_sz":4,"ask_sz":1000,"bid_ct":1,"ask_ct":1},{"bid_px":"249.800000000","ask_px":"251.450000000","bid_sz":199,"ask_sz":374,"bid_ct":1,"ask_ct":2},{"bid_px":"249.770000000","ask_px":"251.500000000","bid_sz":50,"ask_sz":10,"bid_ct":1,"ask_ct":1},{"bid_px":"249.400000000","ask_px":"252.700000000","bid_sz":1000,"ask_sz":1000,"bid_ct":1,"ask_ct":1},{"bid_px":"249.010000000","ask_px":"253.350000000","bid_sz":3,"ask_sz":23,"bid_ct":1,"ask_ct":1},{"bid_px":"249.000000000","ask_px":"253.650000000","bid_sz":100,"ask_sz":400,"bid_ct":1,"ask_ct":1}],"symbol":"TSLA"}
{"ts_recv":"2024-11-01T08:00:16.878210344Z","hd":{"ts_event":"2024-11-01T08:00:16.878044511Z","rtype":10,"publisher_id":2,"instrument_id":16244},"action":"C","side":"B","depth":2,"price":"249.930000000","size":10,"flags":130,"ts_in_delta":165833,"sequence":327308,"levels":[{"bid_px":"250.150000000","ask_px":"250.790000000","bid_sz":50,"ask_sz":200,"bid_ct":1,"ask_ct":1},{"bid_px":"250.000000000","ask_px":"250.880000000","bid_sz":2,"ask_sz":14,"bid_ct":2,"ask_ct":1},{"bid_px":"249.880000000","ask_px":"250.940000000","bid_sz":4,"ask_sz":100,"bid_ct":1,"ask_ct":1},{"bid_px":"249.850000000","ask_px":"251.090000000","bid_sz":4,"ask_sz":100,"bid_ct":1,"ask_ct":1},{"bid_px":"249.800000000","ask_px":"251.100000000","bid_sz":199,"ask_sz":1000,"bid_ct":1,"ask_ct":1},{"bid_px":"249.770000000","ask_px":"251.450000000","bid_sz":50,"ask_sz":374,"bid_ct":1,"ask_ct":2},{"bid_px":"249.400000000","ask_px":"251.500000000","bid_sz":1000,"ask_sz":10,"bid_ct":1,"ask_ct":1},{"bid_px":"249.010000000","ask_px":"252.700000000","bid_sz":3,"ask_sz":1000,"bid_ct":1,"ask_ct":1},{"bid_px":"249.000000000","ask_px":"253.350000000","bid_sz":100,"ask_sz":23,"bid_ct":1,"ask_ct":1},{"bid_px":"248.500000000","ask_px":"253.650000000","bid_sz":111,"ask_sz":400,"bid_ct":3,"ask_ct":1}],"symbol":"TSLA"}
